Workbook

Sheet  MIs
A2: S.No | B2: NAme | C2: Lacation | D2: Card Number | E2: Card Number | F2: Category | G2: 1st Jan | I2: 2nd Jan | J2: 3rd Jan | K2: 4th Jan | L2: 5th Jan | M2: 6th Jan | N2: 7th Jan | O2: 8th Jan | P2: 9th Jan | Q2: 10th Jan | R2: 11th Jan | S2: 12th Jan | T2: 13th Jan | U2: 14th Jan | V2: 15th Jan | W2: 16th Jan | X2: 17th Jan | Y2: 18th Jan | Z2: 19th Jan | AA2: 20th Jan | AB2: 21st Jan | AC2: 22nd Jan | AD2: 23rd Jan | AE2: 24th Jan | AF2: 25th Jan | AG2: 26th Jan | AH2: 27th Jan | AI2: 28th Jan | AJ2: 29th Jan | AK2: 30th Jan | AL2: 31st Jan | AM2: Total
F3: Diesel
A4: 1 | B4: Rambabu | C4: HO(Two Wheeler) | D4: FC3450563999 | E4: Diesel | F4: 0 | G4: 0 | H4: 0 | I4: 0 | J4: 0 | K4: 0 | L4: 0 | M4: 0 | N4: 0 | O4: 0 | P4: 0 | Q4: 0 | R4: 0 | S4: 0 | T4: 0 | U4: 0 | V4: 0 | W4: 0 | X4: 5.22 | Y4: 0 | Z4: 0 | AA4: 0 | AB4: 0 | AC4: 0 | AD4: 60 | AE4: 0 | AF4: 0 | AG4: 0 | AH4: 4.56 | AI4: 0 | AJ4: 0 | AK4: 0 | AL4: 0 | AM4: =SUM(F4:AL4) -> 69.78
E5: Petrol | F5: 0 | G5: 4.69 | H5: 0 | I5: 0 | J5: 0 | K5: 0 | L5: 0 | M5: 0 | N5: 3.91 | O5: 0 | P5: 6.98 | Q5: 0 | R5: 0 | S5: 0 | T5: 0 | U5: 0 | V5: 0 | W5: 0 | X5: 0 | Y5: 0 | Z5: 0 | AB5: 0 | AC5: 0 | AD5: 0 | AE5: 0 | AF5: 0 | AG5: 0 | AH5: 0 | AI5: 0 | AJ5: 0 | AK5: 0 | AL5: 0 | AM5: =SUM(F5:AL5) -> 15.58
A6: 2 | B6: Hanumanth Rao | C6: HO | D6: FC3450676131 | E6: Diesel | F6: 0 | G6: 0 | H6: 0 | I6: 0 | J6: 0 | K6: 0 | L6: 0 | M6: 0 | N6: 0 | O6: 0 | P6: 0 | Q6: 0 | R6: 0 | S6: 0 | T6: 0 | U6: 0 | V6: 0 | W6: 0 | X6: 0 | Y6: 0 | Z6: 0 | AA6: 0 | AB6: 0 | AC6: 0 | AD6: 0 | AE6: 0 | AF6: 0 | AG6: 0 | AH6: 0 | AI6: 0 | AJ6: 0 | AK6: 0 | AL6: 0 | AM6: =SUM(F6:AL6) -> 0
E7: Petrol | F7: 0 | G7: 0 | H7: 0 | I7: 0 | J7: 0 | K7: 0 | L7: 0 | M7: 0 | N7: 0 | O7: 0 | P7: 0 | Q7: 0 | R7: 0 | S7: 0 | T7: 0 | U7: 0 | V7: 0 | W7: 0 | X7: 0 | Y7: 0 | Z7: 0 | AB7: 0 | AC7: 0 | AD7: 0 | AE7: 0 | AF7: 0 | AG7: 0 | AH7: 0 | AI7: 0 | AJ7: 0 | AK7: 0 | AL7: 0 | AM7: =SUM(F7:AL7) -> 0
A8: 3 | B8: Radhakrishna | C8: HO | D8: FC8000207658 | E8: Diesel | F8: 0 | G8: 0 | H8: 0 | I8: 0 | J8: 33.44 | K8: 0 | L8: 0 | M8: 0 | N8: 0 | O8: 0 | P8: 0 | Q8: 0 | R8: 35.53 | S8: 0 | T8: 0 | U8: 0 | V8: 0 | W8: 0 | X8: 0 | Y8: 0 | Z8: 0 | AA8: 0 | AB8: 33.44 | AC8: 0 | AD8: 0 | AE8: 0 | AF8: 0 | AG8: 0 | AH8: 0 | AI8: 0 | AJ8: 0 | AK8: 0 | AL8: 0 | AM8: =SUM(F8:AL8) -> 102.41
E9: Petrol | F9: 0 | G9: 0 | H9: 0 | I9: 0 | J9: 0 | K9: 0 | L9: 0 | M9: 0 | N9: 0 | O9: 0 | P9: 0 | Q9: 0 | R9: 0 | S9: 0 | T9: 0 | U9: 0 | V9: 0 | W9: 0 | X9: 0 | Y9: 0 | Z9: 0 | AB9: 0 | AC9: 0 | AD9: 0 | AE9: 0 | AF9: 0 | AG9: 0 | AH9: 0 | AI9: 0 | AJ9: 0 | AK9: 0 | AL9: 0 | AM9: =SUM(F9:AL9) -> 0
A10: 4 | B10: VIjay | C10: HO | D10: FC3450698859 | E10: Diesel | F10: 0 | G10: 0 | H10: 0 | I10: 0 | J10: 0 | K10: 0 | L10: 0 | M10: 0 | N10: 0 | O10: 0 | P10: 49.22 | Q10: 0 | R10: 0 | S10: 0 | T10: 0 | U10: 54.57 | V10: 0 | W10: 0 | X10: 0 | Y10: 0 | Z10: 0 | AA10: 0 | AB10: 0 | AC10: 0 | AD10: 49.8 | AE10: 0 | AF10: 0 | AG10: 0 | AH10: 0 | AI10: 0 | AJ10: 0 | AK10: 0 | AL10: 0 | AM10: =SUM(F10:AL10) -> 153.59
E11: Petrol | F11: 0 | G11: 0 | H11: 0 | I11: 0 | J11: 0 | K11: 0 | L11: 0 | M11: 0 | N11: 0 | O11: 0 | P11: 0 | Q11: 0 | R11: 0 | S11: 0 | T11: 0 | U11: 0 | V11: 0 | W11: 0 | X11: 0 | Y11: 0 | Z11: 0 | AB11: 0 | AC11: 0 | AD11: 0 | AE11: 0 | AF11: 0 | AG11: 0 | AH11: 0 | AI11: 0 | AJ11: 0 | AK11: 0 | AL11: 0 | AM11: =SUM(F11:AL11) -> 0
A12: 5 | B12: Client | C12: Hiriyur | D12: FC3450698864 | E12: Diesel | F12: 0 | G12: 0 | H12: 0 | I12: 0 | J12: 0 | K12: 0 | L12: 0 | M12: 0 | N12: 86.29 | O12: 0 | P12: 0 | Q12: 0 | R12: 0 | S12: 0 | T12: 0 | U12: 0 | V12: 0 | W12: 0 | X12: 0 | Y12: 0 | Z12: 0 | AA12: 0 | AB12: 0 | AC12: 0 | AD12: 145.61 | AE12: 0 | AF12: 0 | AG12: 0 | AH12: 0 | AI12: 0 | AJ12: 0 | AK12: 0 | AL12: 0 | AM12: =SUM(F12:AL12) -> 231.9
E13: Petrol | F13: 0 | G13: 0 | H13: 0 | I13: 0 | J13: 0 | K13: 0 | L13: 0 | M13: 0 | N13: 0 | O13: 0 | P13: 0 | Q13: 0 | R13: 0 | S13: 0 | T13: 0 | U13: 0 | V13: 0 | W13: 0 | X13: 0 | Y13: 0 | Z13: 0 | AB13: 0 | AC13: 0 | AD13: 0 | AE13: 0 | AF13: 0 | AG13: 0 | AH13: 0 | AI13: 0 | AJ13: 0 | AK13: 0 | AL13: 0 | AM13: =SUM(F13:AL13) -> 0
A14: 6 | B14: Client | C14: Hosadurga | D14: FC3450698865 | E14: Diesel | F14: 0 | G14: 0 | H14: 0 | I14: 0 | J14: 0 | K14: 0 | L14: 40 | M14: 40 | N14: 0 | O14: 36 | P14: 35 | Q14: 0 | R14: 0 | S14: 0 | T14: 0 | U14: 0 | V14: 0 | W14: 45 | X14: 45 | Y14: 43.53 | Z14: 40 | AA14: 43 | AB14: 0 | AC14: 40 | AD14: 0 | AE14: 40 | AF14: 0 | AG14: 0 | AH14: 0 | AI14: 0 | AJ14: 0 | AK14: 0 | AL14: 0 | AM14: =SUM(F14:AL14) -> 447.53
E15: Petrol | F15: 0 | G15: 0 | H15: 0 | I15: 0 | J15: 0 | K15: 0 | L15: 0 | M15: 0 | N15: 0 | O15: 0 | P15: 0 | Q15: 0 | R15: 0 | S15: 0 | T15: 0 | U15: 0 | V15: 0 | W15: 0 | X15: 0 | Y15: 0 | Z15: 0 | AB15: 0 | AC15: 0 | AD15: 0 | AE15: 0 | AF15: 0 | AG15: 0 | AH15: 0 | AI15: 0 | AJ15: 0 | AK15: 0 | AL15: 0 | AM15: =SUM(F15:AL15) -> 0
G18: Diesel Price

Sheet March-2026
A1: S.no | B1: Site Name | C1: Bunk Name | D1: Diesel(Liters) | E1: Diesel Amount | F1: Petrol(Liters) | G1: Petrol Amount | H1: Total Amount | I1: Opening Blance | J1: Amount Paid | K1: Closing Balances
A2: 1 | B2: Khammam-1 | C2: Divya laxmi ganapathi | D2: =+'Khammam-1'!E38 -> 4500 | E2: =+'Khammam-1'!G38 -> 430560 | F2: =+'Khammam-1'!H38 -> 80 | G2: =+'Khammam-1'!J38 -> 8596.8 | H2: =E2+G2 -> 439156.8 | I2: =+'Khammam-1'!K3 -> 8237254.9 | J2: =+'Khammam-1'!L38 -> 4500000 | K2: =H2+I2-J2 -> 4176411.7 | L2: k
A3: 2 | B3: Khammam-2 | C3: Jayasai union bunk | D3: =+'Khammam-2'!E35 -> 60358.173 | E3: =+'Khammam-2'!G35 -> 5864453.1 | F3: =+'Khammam-2'!H35 -> 1045 | G3: =+'Khammam-2'!J35 -> 112327.05 | H3: =E3+G3 -> 5976780.1 | I3: =+'Khammam-2'!K3 -> 5555857.2 | J3: =+'Khammam-2'!L35 -> 3500000 | K3: =H3+I3-J3 -> 8032637.3 | L3: k
A4: 3 | B4: Khammam-3 | C4: JSASFuel Genie India Pvt.Ltd | D4: =+'Khammam-3'!E35 -> 138043.93 | E4: =+'Khammam-3'!G35 -> 13087760 | F4: =+'Khammam-3'!H35 -> 0 | G4: =+'Khammam-3'!J35 -> 0 | H4: =E4+G4 -> 13087760 | I4: =+'Khammam-3'!M3 -> 1140143.1 | J4: =+'Khammam-3'!L35 -> 6000000 | K4: =H4+I4-J4 -> 8227903.3 | L4: k
A5: 4 | B5: Khammam-4 | C5: Vajra Mahalakshmi filling station | D5: =+'Khammam-4'!E38 -> 3459.76 | E5: =+'Khammam-4'!G38 -> 330407.08 | F5: =+'Khammam-4'!H38 -> 0 | G5: =+'Khammam-4'!J38 -> 0 | H5: =E5+G5 -> 330407.08 | I5: =+'Khammam-4'!M3 -> 0 | J5: =+'Khammam-4'!L38 -> 0 | K5: =H5+I5-J5 -> 330407.08 | L5: k
A6: 5 | B6: Khammam-5 | C6: SR HP Filling Station ( Dhamsalapuram) | D6: =+'Khammam-5'!E38 -> 6273.16 | E6: =+'Khammam-5'!G38 -> 600215.95 | F6: =+'Khammam-5'!H38 -> 0 | G6: =+'Khammam-5'!J38 -> 0 | H6: =E6+G6 -> 600215.95 | I6: =+'Khammam-5'!M3 -> 0 | J6: =+'Khammam-5'!L38 -> 600215.26 | K6: =H6+I6-J6 -> 0.6864
A7: 6 | B7: Jadcherla-3 | C7: JSASFuel Genie India Pvt.Ltd | D7: =+'Jadcherla-3'!E35 -> 25398 | E7: =+'Jadcherla-3'!G35 -> 2426931.1 | F7: =+'Jadcherla-3'!H35 -> 0 | G7: =+'Jadcherla-3'!J35 -> 0 | H7: =E7+G7 -> 2426931.1 | I7: =+'Jadcherla-3'!M3 -> 1026278.2 | J7: =+'Jadcherla-3'!L35 -> 1000000 | K7: =H7+I7-J7 -> 2453209.4 | L7: k
A8: 7 | B8: Jadcherla-4 | C8: Shree Poornima F/S | D8: =+'Jadcherla-4'!E35 -> 0 | E8: =+'Jadcherla-4'!G35 -> 0 | F8: =+'Jadcherla-4'!H35 -> 210 | G8: =+'Jadcherla-4'!J35 -> 22701 | H8: =E8+G8 -> 22701 | I8: =+'Jadcherla-4'!M3 -> 24863 | J8: =+'Jadcherla-4'!L35 -> 37835 | K8: =H8+I8-J8 -> 9729 | L8: k
A9: 8 | B9: Sangareddy-1 | C9: Durga Indhan | D9: =+' Sangareeddy-1'!E35 -> 2727.69 | E9: =+' Sangareeddy-1'!G35 -> 262867.49 | F9: =+' Sangareeddy-1'!H35 -> 153.31 | G9: =+' Sangareeddy-1'!J35 -> 16583.543 | H9: =E9+G9 -> 279451.03 | I9: =+' Sangareeddy-1'!M3 -> 151710.02 | J9: =+' Sangareeddy-1'!L35 -> 360000 | K9: =H9+I9-J9 -> 71161.048 | L9: k
A10: 9 | B10: Sangareddy-2 | C10: Durga Bhavani F/S | D10: =+' Sangareddy-2'!E35 -> 6245.7 | E10: =+' Sangareddy-2'!G35 -> 602335.31 | F10: =+' Sangareddy-2'!H35 -> 205.97 | G10: =+' Sangareddy-2'!J35 -> 22308.611 | H10: =E10+G10 -> 624643.92 | I10: =+' Sangareddy-2'!M3 -> 0 | J10: =+' Sangareddy-2'!L35 -> 300000 | K10: =H10+I10-J10 -> 324643.92 | L10: k
A11: 10 | B11: Dindi | C11: Akarapu Balakistamma Fillling | D11: =+Dindi!E35 -> 35.41 | E11: =+Dindi!G35 -> 3402.1928 | F11: =+Dindi!H35 -> 0 | G11: =+Dindi!J35 -> 0 | H11: =E11+G11 -> 3402.1928 | I11: =+Dindi!M3 -> 0 | J11: =+Dindi!L35 -> 3402.1928 | K11: =H11+I11-J11 -> 0 | L11: k
A12: 11 | B12: Madanapalli | D12: =+'Madana palli'!E36 -> 430.78 | E12: =+'Madana palli'!G36 -> 42114.895 | F12: =+'Madana palli'!H36 -> 20.97 | G12: =+'Madana palli'!J36 -> 2298.7314 | H12: =E12+G12 -> 44413.627 | I12: =+'Madana palli'!M3 -> 0 | J12: =+'Madana palli'!L36 -> 44413.627 | K12: =H12+I12-J12 -> 0 | L12: k
A13: 12 | B13: Kakinada | D13: =+Amalapuram!E38 -> 491.85 | E13: =+Amalapuram!G38 -> 47376.805 | F13: =+Amalapuram!H38 -> 82.93 | G13: =+Amalapuram!J38 -> 8948.87 | H13: =E13+G13 -> 56325.675 | I13: =+Amalapuram!M3 -> 0 | J13: =+Amalapuram!L38 -> 56325.675 | K13: =H13+I13-J13 -> 0 | L13: k
A14: 13 | B14: YG Gudda-2 | C14: Pankaja HP Fuel Center | D14: =+'YG Gudda-2'!E37 -> 8492.77 | E14: =+'YG Gudda-2'!G37 -> 775644.68 | F14: =+'YG Gudda-2'!H37 -> 245 | G14: =+'YG Gudda-2'!J37 -> 25301.15 | H14: =E14+G14 -> 800945.83 | I14: =+'YG Gudda-2'!M3 -> 531383.8 | J14: =+'YG Gudda-2'!L37 -> 1081999.7 | K14: =H14+I14-J14 -> 250329.91 | L14: k
A15: 14 | B15: Hosadurga-2 | C15: Shree Veeraprathap Fuel | D15: =+'Hosadurga -2'!E35 -> 5200.15 | E15: =+'Hosadurga -2'!G35 -> 476023.72 | F15: =+'Hosadurga -2'!H35 -> 245 | G15: =+'Hosadurga -2'!J35 -> 25413.85 | H15: =+'Hosadurga -2'!K35 -> 501437.57 | I15: =+'Hosadurga -2'!K3 -> 197359.4 | J15: =+'Hosadurga -2'!L35 -> 500000 | K15: =H15+I15-J15 -> 198796.97 | L15: k
A16: 15 | B16: Malebennuru(KUWSDB) | C16: Sri Ramanjuneya Service Station | D16: =+'Malebenur(KUWSDB)'!E37 -> 4600 | E16: =+'Malebenur(KUWSDB)'!G37 -> 423982 | F16: =+'Malebenur(KUWSDB)'!H37 -> 205 | G16: =+'Malebenur(KUWSDB)'!J37 -> 21336.95 | H16: =E16+G16 -> 445318.95 | I16: =+'Malebenur(KUWSDB)'!K3 -> 58952.96 | J16: =+'Malebenur(KUWSDB)'!L37 -> 424793.9 | K16: =H16+I16-J16 -> 79478.01 | L16: k
A17: 16 | B17: kadur | C17: Vishal Service Station | D17: =+Kadur!E35 -> 1600 | E17: =+Kadur!G35 -> 147440 | F17: =+Kadur!H35 -> 140 | G17: =+Kadur!J35 -> 14593.6 | H17: =E17+G17 -> 162033.6 | I17: =+Kadur!K3 -> 240937.03 | J17: =+Kadur!L35 -> 300000 | K17: =H17+I17-J17 -> 102970.63 | L17: k
A18: 17 | B18: Hiriyur(VJNL) | C18: Sri Balaji Agencies | D18: =+'Hiriyur(VJNL)'!E35 -> 4700 | E18: =+'Hiriyur(VJNL)'!G35 -> 433622 | F18: =+'Hiriyur(VJNL)'!H35 -> 245 | G18: =+'Hiriyur(VJNL)'!J35 -> 25511.85 | H18: =E18+G18 -> 459133.85 | I18: =+'Hiriyur(VJNL)'!K3 -> 6935.95 | J18: =+'Hiriyur(VJNL)'!L35 -> 466000 | K18: =H18+I18-J18 -> 69.8 | L18: k
A19: 18 | B19: Chellakere(KUWSDB) | C19: Shivaganga Service Station | D19: =+'Chellakere -1'!E35 -> 4199.64 | E19: =+'Chellakere -1'!G35 -> 387332.8 | F19: =+'Chellakere -1'!H35 -> 140 | G19: =+'Chellakere -1'!J35 -> 14572.6 | H19: =E19+G19 -> 401905.4 | I19: =+'Chellakere -1'!K3 -> 268656.68 | J19: =+'Chellakere -1'!L35 -> 455000 | K19: =H19+I19-J19 -> 215562.07 | L19: k
A20: 19 | B20: Chellakere(KUWSDB)-09 | D20: =+' Chellakere-PKG-9'!E35 -> 215.05 | E20: =+' Chellakere-PKG-9'!G35 -> 19834.061 | F20: =+' Chellakere-PKG-9'!H35 -> 38.99 | G20: =+' Chellakere-PKG-9'!J35 -> 4058.4691 | H20: =E20+G20 -> 23892.531 | I20: =+' Chellakere-PKG-9'!M3 -> 0 | J20: =+' Chellakere-PKG-9'!L35 -> 23892.531 | K20: =H20+I20-J20 -> 0 | L20: k
A21: 20 | B21: Molakalmuru | C21: Sri Lakshmi Venkateshwara Filling Station | D21: =+Molakamuru!E35 -> 200 | E21: =+Molakamuru!G35 -> 18444 | F21: =+Molakamuru!H35 -> 95 | G21: =+Molakamuru!J35 -> 9904.1 | H21: =E21+G21 -> 28348.1 | I21: =+Molakamuru!K3 -> 22607.215 | J21: =+Molakamuru!L35 -> 46775.6 | K21: =H21+I21-J21 -> 4179.7152 | L21: k
A22: 21 | B22: Chennagiri | D22: =+' Chennagiri'!E35 -> 210 | E22: =+' Chennagiri'!G35 -> 19330.5 | F22: =+' Chennagiri'!H35 -> 72 | G22: =+' Chennagiri'!J35 -> 7498.08 | H22: =E22+G22 -> 26828.58 | I22: =+' Chennagiri'!K3 -> 0 | J22: =+' Chennagiri'!L35 -> 26828.58 | K22: =H22+I22-J22 -> 0 | L22: k
A23: 22 | B23: Khanapur(PKG-3) | C23: V.V.Varde | D23: =+Khanapur!E35 -> 2052.69 | E23: =+Khanapur!G35 -> 186548.47 | F23: =+Khanapur!H35 -> 81 | G23: =+Khanapur!J35 -> 8324.37 | H23: =E23+G23 -> 194872.84 | I23: =+Khanapur!M3 -> 68785.913 | J23: =+Khanapur!L35 -> 110000 | K23: =H23+I23-J23 -> 153658.75 | L23: k
A24: 23 | B24: Munavalli(PKG-3)-1 | C24: Shri Daneshwari | D24: =+Munavali!E37 -> 0 | E24: =+Munavali!G37 -> 0 | F24: =+Munavali!H37 -> 0 | G24: =+Munavali!J37 -> 0 | H24: =E24+G24 -> 0 | I24: =+Munavali!M3 -> 0 | J24: =+Munavali!L37 -> 0 | K24: =H24+I24-J24 -> 0 | L24: k
A25: 24 | B25: Munavalli(PKG-3)-2 | C25: Shre Shiva Petroleum | D25: =+'Munavali-2'!E37 -> 15520 | E25: =+'Munavali-2'!G37 -> 1420700.8 | F25: =+'Munavali-2'!H37 -> 165.47 | G25: =+'Munavali-2'!J37 -> 18179.927 | H25: =E25+G25 -> 1438880.7 | I25: =+'Munavali-2'!M3 -> 738510.09 | J25: =+'Munavali-2'!L37 -> 1570331.3 | K25: =H25+I25-J25 -> 607059.51 | L25: 597732 | M25: =K25-L25 -> 9327.5079
A26: 25 | B26: Borgaon(PKG-3) | C26: Aadisagar Petrolium | D26: =+Borgaon!E35 -> 5405 | E26: =+Borgaon!G35 -> 496016.85 | F26: =+Borgaon!H35 -> 95.8 | G26: =+Borgaon!J35 -> 9937.334 | H26: =E26+G26 -> 505954.18 | I26: =+Borgaon!K3 -> 29558.904 | J26: =+Borgaon!L35 -> 450000 | K26: =H26+I26-J26 -> 85513.088 | L26: k
A27: 26 | B27: Ugar,Kudichi(PKG-3) | C27: Shiri Bhrhmanath Petrolium | D27: =+'Ugar,Khagwad,Kudichi'!E35 -> 7528.79 | E27: =+'Ugar,Khagwad,Kudichi'!G35 -> 692121.66 | F27: =+'Ugar,Khagwad,Kudichi'!H35 -> 265 | G27: =+'Ugar,Khagwad,Kudichi'!J35 -> 27860.2 | H27: =E27+G27 -> 719981.86 | I27: =+'Ugar,Khagwad,Kudichi'!M3 -> 215407.75 | J27: =+'Ugar,Khagwad,Kudichi'!L35 -> 500974 | K27: =H27+I27-J27 -> 434415.61 | L27: k
A28: 27 | B28: Kabbur(PKG-3) | C28: Shri Jai Hanuman Petrolium | D28: =+Kabbur!E35 -> 375 | E28: =+Kabbur!G35 -> 34350 | F28: =+Kabbur!H35 -> 34 | G28: =+Kabbur!J35 -> 3520.31 | H28: =E28+G28 -> 37870.31 | I28: 0 | J28: =+Kabbur!L35 -> 37870.31 | K28: =H28+I28-J28 -> 0 | L28: k
A29: 28 | B29: Kumta (PKG-1) | C29: V.M.MIRJANKAR (KUMTA) BHARAT | D29: =+kumta!E35 -> 2115 | E29: =+kumta!G35 -> 194516.55 | F29: =+kumta!H35 -> 185 | G29: =+kumta!J35 -> 19241.85 | H29: =E29+G29 -> 213758.4 | I29: =kumta!M3 -> 27054.7 | J29: =+kumta!L35 -> 206053.8 | K29: =H29+I29-J29 -> 34759.3 | L29: k
A30: 29 | B30: Jalgaon | C30: Jai Bajarang Sarvo Center Bodwad | D30: =+Jalgaon!E55 -> 17988.96 | E30: =+Jalgaon!G55 -> 1649851.5 | F30: =+Jalgaon!H55 -> 112.74 | G30: =+Jalgaon!J55 -> 11859.121 | H30: =E30+G30 -> 1661710.6 | I30: =+Jalgaon!K3 -> 337793.25 | J30: =+Jalgaon!L55 -> 348495.99 | K30: =H30+I30-J30 -> 1651007.9 | L30: k
A31: 30 | B31: Jalgaon-2 | C31: Agrawal Petrol Pump | D31: =+'Jalgoan-2'!E55 -> 56137.39 | E31: ='Jalgoan-2'!G55 -> 5180158.8 | F31: =+'Jalgoan-2'!H55 -> 360 | G31: =+'Jalgoan-2'!J55 -> 38558.4 | H31: =E31+G31 -> 5218717.2 | I31: =+'Jalgoan-2'!M3 -> 2953127.8 | J31: =+'Jalgoan-2'!L55 -> 2700000 | K31: =H31+I31-J31 -> 5471845 | L31: k
A32: 31 | B32: Jalgaon-3 | C32: T R KAPOOR AND CO | D32: =+' Jalgoan-3'!E55 -> 2500 | E32: =+' Jalgoan-3'!G55 -> 229925 | F32: =+' Jalgoan-3'!H55 -> 0 | G32: =+' Jalgoan-3'!J55 -> 0 | H32: =E32+G32 -> 229925 | I32: =+' Jalgoan-3'!M3 -> 0 | J32: =+' Jalgoan-3'!L55 -> 229925 | K32: =H32+I32-J32 -> 0 | L32: k
A33: 32 | B33: Jalgaon-4 | C33: RAKSHA AUTO FUELS BPCL OTP | D33: =+' Jalgoan-4'!E55 -> 4000 | E33: =+' Jalgoan-4'!G55 -> 366680 | F33: =+' Jalgoan-4'!H55 -> 0 | G33: =+' Jalgoan-4'!J55 -> 0 | H33: =E33+G33 -> 366680 | I33: =+' Jalgoan-4'!M3 -> 0 | J33: =+' Jalgoan-4'!L55 -> 366680 | K33: =H33+I33-J33 -> 0 | L33: k
A34: 33 | B34: MKBD | C34: Shree Sai Samarth Petroleum | D34: =+MKBD!E38 -> 14800 | E34: =+MKBD!G38 -> 1348872 | F34: =+MKBD!H38 -> 110.21 | G34: =+MKBD!J38 -> 11527.966 | H34: =E34+G34 -> 1360400 | I34: =+MKBD!K3 -> 103006.58 | J34: =+MKBD!L38 -> 0 | K34: =H34+I34-J34 -> 1463406.5 | L34: k
A35: 34 | B35: Haveri | C35: M/s Magavi City Fuels | D35: =' Haveri-2'!E38 -> 1427.77 | E35: =' Haveri-2'!G38 -> 130626.34 | F35: =' Haveri-2'!H38 -> 75.11 | G35: =' Haveri-2'!J38 -> 7809.1713 | H35: =E35+G35 -> 138435.51 | I35: =' Haveri-2'!M3 -> 90409.199 | J35: =+' Haveri-2'!L38 -> 151559.56 | K35: =H35+I35-J35 -> 77285.143 | L35: k
A36: 35 | B36: Guttal-2 | C36: Himagiri Petroleum | D36: =+' Guttal-2'!E35 -> 4113.96 | E36: =+' Guttal-2'!G35 -> 377579.25 | F36: =+' Guttal-2'!H35 -> 171 | G36: =+' Guttal-2'!J35 -> 17739.54 | H36: =E36+G36 -> 395318.79 | I36: =+' Guttal-2'!M3 -> 118610.55 | J36: =+' Guttal-2'!L35 -> 310000 | K36: =H36+I36-J36 -> 203929.33 | L36: k
A37: 36 | B37: Rattihali | C37: Shree Siri Gowari petroliam | D37: =+Rattihali!E35 -> 0 | E37: =+Rattihali!G35 -> 0 | F37: =+Rattihali!H35 -> 0 | G37: =+Rattihali!J35 -> 0 | H37: =E37+G37 -> 0 | I37: =+Rattihali!M3 -> 6442.724 | J37: =+Rattihali!L35 -> 6442.72 | K37: =H37+I37-J37 -> 0.004 | L37: k
A38: 37 | B38: Rattihali-2 | C38: Shiva Oil Traders | D38: =+'Rattihali-2'!E37 -> 4383.61 | E38: =+'Rattihali-2'!G37 -> 402809.92 | F38: =+'Rattihali-2'!H37 -> 110 | G38: =+'Rattihali-2'!J37 -> 11423.5 | H38: =E38+G38 -> 414233.42 | I38: =+'Rattihali-2'!M3 -> 149508.67 | J38: =+'Rattihali-2'!L37 -> 300000 | K38: =H38+I38-J38 -> 263742.1 | L38: k
A39: 38 | B39: Gajendragada | C39: Vanasri Petrol Pump | D39: =+Gajendragada!E35 -> 1151 | E39: =+Gajendragada!G35 -> 105696.33 | F39: =+Gajendragada!H35 -> 149.96 | G39: =+Gajendragada!J35 -> 15565.848 | H39: =E39+G39 -> 121262.18 | I39: =+Gajendragada!K3 -> 126102.9 | J39: =+Gajendragada!L35 -> 200000 | K39: =H39+I39-J39 -> 47365.079 | L39: k
A40: 39 | B40: Gokak(PKG-3) | C40: AJ Petrolinks | D40: =+'Gokak Dharwad PKG 3'!E40 -> 11542.14 | E40: =+'Gokak Dharwad PKG 3'!G40 -> 1055875 | F40: =+'Gokak Dharwad PKG 3'!H40 -> 330 | G40: =+'Gokak Dharwad PKG 3'!J40 -> 34311.54 | H40: =E40+G40 -> 1090186.5 | I40: =+'Gokak Dharwad PKG 3'!K3 -> 227750.48 | J40: =+'Gokak Dharwad PKG 3'!L40 -> 950000 | K40: =H40+I40-J40 -> 367936.99 | L40: k
...

Sheet HO(DG)
A1: JSASFuel Genie India Pvt.Ltd
A2: S.No | B2: Date | C2: GRN No | D2: Ind No/Bill No | E2: Diesel (Lts) | F2: Price | G2: Amount | H2: Petrol (Lts) | I2: Price | J2: Amount | K2: Total amount | L2: Amount paid | M2: As on date | N2: Remarks
A3: Opening Balance | M3: 89488.582 | O3: 2623243.4
A4: 1 | B4: 46082 | G4: =E4*F4 -> 0 | H4: 0 | I4: 0 | J4: =H4*I4 -> 0 | K4: =G4+J4 -> 0 | L4: 0 | M4: =M3+K4-L4 -> 89488.582
A5: 2 | B5: 46083 | G5: =E5*F5 -> 0 | H5: 0 | I5: 0 | J5: =H5*I5 -> 0 | K5: =G5+J5 -> 0 | L5: 0 | M5: =M4+K5-L5 -> 89488.582 | S5: 16291
A6: 3 | B6: 46084 | G6: =E6*F6 -> 0 | H6: 0 | I6: 0 | J6: =H6*I6 -> 0 | K6: =G6+J6 -> 0 | L6: 0 | M6: =M5+K6-L6 -> 89488.582 | S6: 16291
A7: 4 | B7: 46085 | E7: 170 | F7: 95.83 | G7: =E7*F7 -> 16291.1 | H7: 0 | I7: 0 | J7: =H7*I7 -> 0 | K7: =G7+J7 -> 16291.1 | L7: 0 | M7: =M6+K7-L7 -> 105779.68 | P7: 5679 | S7: 17249
A8: 5 | B8: 46086 | G8: =E8*F8 -> 0 | H8: 0 | I8: 0 | J8: =H8*I8 -> 0 | K8: =G8+J8 -> 0 | L8: 0 | M8: =M7+K8-L8 -> 105779.68 | S8: 17249
A9: 6 | B9: 46087 | G9: =E9*F9 -> 0 | K9: =G9+J9 -> 0 | L9: 0 | M9: =M8+K9-L9 -> 105779.68 | S9: 14894
A10: 7 | B10: 46088 | G10: =E10*F10 -> 0 | H10: 0 | I10: 0 | J10: =H10*I10 -> 0 | K10: =G10+J10 -> 0 | L10: 0 | M10: =M9+K10-L10 -> 105779.68 | S10: 16578 | T10: 122085
A11: 8 | B11: 46089 | E11: 170 | F11: 95.83 | G11: =E11*F11 -> 16291.1 | H11: 0 | I11: 0 | J11: =H11*I11 -> 0 | K11: =G11+J11 -> 16291.1 | L11: 0 | M11: =M10+K11-L11 -> 122070.78 | S11: =SUM(S5:S10) -> 98552 | T11: =T10+S11 -> 220637
A12: 9 | B12: 46090 | G12: =E12*F12 -> 0 | H12: 0 | I12: 0 | J12: =H12*I12 -> 0 | K12: =G12+J12 -> 0 | L12: 0 | M12: =M11+K12-L12 -> 122070.78
A13: 10 | B13: 46091 | G13: =E13*F13 -> 0 | H13: 0 | I13: 0 | K13: =G13+J13 -> 0 | L13: 0 | M13: =M12+K13-L13 -> 122070.78
A14: 11 | B14: 46092 | G14: =E14*F14 -> 0 | H14: 0 | I14: 0 | K14: =G14+J14 -> 0 | L14: 0 | M14: =M13+K14-L14 -> 122070.78
A15: 12 | B15: 46093 | G15: =E15*F15 -> 0 | H15: 0 | I15: 0 | K15: =G15+J15 -> 0 | L15: 0 | M15: =M14+K15-L15 -> 122070.78 | P15: 1905988 | Q15: =P15-M15 -> 1783917.2
A16: 13 | B16: 46094 | E16: 180 | F16: 95.83 | G16: =E16*F16 -> 17249.4 | H16: 0 | I16: 0 | K16: =G16+J16 -> 17249.4 | L16: 0 | M16: =M15+K16-L16 -> 139320.18
A17: 14 | B17: 46095 | G17: =E17*F17 -> 0 | H17: 0 | I17: 0 | J17: =H17*I17 -> 0 | K17: =G17+J17 -> 0 | L17: 0 | M17: =M16+K17-L17 -> 139320.18
A18: 15 | B18: 46096 | G18: =E18*F18 -> 0 | H18: 0 | I18: 0 | J18: =H18*I18 -> 0 | K18: =G18+J18 -> 0 | L18: 0 | M18: =M17+K18-L18 -> 139320.18
A19: 16 | B19: 46097 | G19: =E19*F19 -> 0 | H19: 0 | I19: 0 | J19: =H19*I19 -> 0 | K19: =G19+J19 -> 0 | L19: 0 | M19: =M18+K19-L19 -> 139320.18
A20: 17 | B20: 46098 | E20: 185 | F20: 95.83 | G20: =E20*F20 -> 17728.55 | H20: 0 | I20: 0 | J20: =H20*I20 -> 0 | K20: =G20+J20 -> 17728.55 | L20: 0 | M20: =M19+K20-L20 -> 157048.73
A21: 18 | B21: 46099 | G21: =E21*F21 -> 0 | J21: =H21*I21 -> 0 | K21: =G21+J21 -> 0 | L21: 0 | M21: =M20+K21-L21 -> 157048.73
A22: 19 | B22: 46100 | G22: =E22*F22 -> 0 | J22: =H22*I22 -> 0 | K22: =G22+J22 -> 0 | L22: 0 | M22: =M21+K22-L22 -> 157048.73
A23: 20 | B23: 46101 | G23: =E23*F23 -> 0 | J23: =H23*I23 -> 0 | K23: =G23+J23 -> 0 | L23: 0 | M23: =M22+K23-L23 -> 157048.73
A24: 21 | B24: 46102 | G24: =E24*F24 -> 0 | J24: =H24*I24 -> 0 | K24: =G24+J24 -> 0 | L24: 0 | M24: =M23+K24-L24 -> 157048.73
A25: 22 | B25: 46103 | G25: =E25*F25 -> 0 | J25: =H25*I25 -> 0 | K25: =G25+J25 -> 0 | L25: 0 | M25: =M24+K25-L25 -> 157048.73
A26: 23 | B26: 46104 | M26: =M25+K26-L26 -> 157048.73
A27: 24 | B27: 46105 | E27: 35 | F27: 95.7 | G27: =E27*F27 -> 3349.5 | J27: =H27*I27 -> 0 | K27: =G27+J27 -> 3349.5 | L27: =H27+K27 -> 3349.5 | M27: =M26+K27-L27 -> 157048.73
B28: 46105 | E28: 173 | F28: 95.83 | G28: =E28*F28 -> 16578.59 | K28: =G28+J28 -> 16578.59 | L28: 0 | M28: =M27+K28-L28 -> 173627.32
A29: 25 | B29: 46106 | G29: =E29*F29 -> 0 | J29: =H29*I29 -> 0 | K29: =G29+J29 -> 0 | L29: 0 | M29: =M28+K29-L29 -> 173627.32
A30: 26 | B30: 46107 | G30: =E30*F30 -> 0 | J30: =H30*I30 -> 0 | K30: =G30+J30 -> 0 | L30: 0 | M30: =M29+K30-L30 -> 173627.32
A31: 27 | B31: 46108 | G31: =E31*F31 -> 0 | J31: =H31*I31 -> 0 | K31: =G31+J31 -> 0 | L31: 0 | M31: =M30+K31-L31 -> 173627.32
A32: 28 | B32: 46109 | E32: 155.42 | F32: 95.83 | G32: =E32*F32 -> 14893.899 | J32: =H32*I32 -> 0 | K32: =G32+J32 -> 14893.899 | L32: 0 | M32: =M31+K32-L32 -> 188521.22
A33: 29 | B33: 46110 | G33: =E33*F33 -> 0 | J33: =H33*I33 -> 0 | K33: =G33+J33 -> 0 | M33: =M32+K33-L33 -> 188521.22
A34: 30 | B34: 46111 | G34: =E34*F34 -> 0 | J34: =H34*I34 -> 0 | K34: =G34+J34 -> 0 | M34: =M33+K34-L34 -> 188521.22
A35: 31 | B35: 46112 | G35: =E35*F35 -> 0 | J35: =H35*I35 -> 0 | K35: =G35+J35 -> 0 | M35: =M34+K35-L35 -> 188521.22
A36: 32 | G36: =E36*F36 -> 0 | J36: =H36*I36 -> 0 | K36: =G36+J36 -> 0 | M36: =M35+K36-L36 -> 188521.22
A37: 33 | G37: =E37*F37 -> 0 | J37: =H37*I37 -> 0 | K37: =G37+J37 -> 0 | L37: 0 | M37: =M36+K37-L37 -> 188521.22 | O37: 2669494 | P37: =O37-M37 -> 2480972.8
E38: 0 | F38: 0 | G38: =E38*F38 -> 0 | J38: =H38*I38 -> 0 | K38: =G38+J38 -> 0 | M38: =M37+K38-L38 -> 188521.22
E39: =SUM(E4:E37) -> 1068.42 | G39: =SUM(G4:G37) -> 102382.14 | H39: =SUM(H4:H37) -> 0 | J39: =SUM(J4:J37) -> 0 | K39: =SUM(K4:K37) -> 102382.14 | L39: =SUM(L4:L37) -> 3349.5
M48: 2408309
...

Sheet Khammam-1
A1: Divya laxmi ganapathi
A2: S.No | B2: Date | C2: GRN No | D2: Ind No/Bill No | E2: Diesel (Lts) | F2: Price | G2: Amount | H2: Petrol (Lts) | I2: Price | J2: Amount | K2: Total amount | L2: Amount paid | M2: As 0n Date | N2: Remarks
A3: Opening Balance | K3: 8237254.9 | M3: 8237254.9
A4: 1 | B4: 46082 | G4: =E4*F4 -> 0 | K4: =G4+J4 -> 0 | L4: 0 | M4: =M3+K4-L4 -> 8237254.9
A5: 2 | B5: 46083 | E5: 1800 | F5: 95.68 | G5: =E5*F5 -> 172224 | H5: 60 | I5: 107.46 | J5: =H5*I5 -> 6447.6 | K5: =G5+J5 -> 178671.6 | L5: 0 | M5: =M4+K5-L5 -> 8415926.5
A6: 3 | B6: 46084 | G6: =E6*F6 -> 0 | J6: =H6*I6 -> 0 | K6: =G6+J6 -> 0 | L6: 0 | M6: =M5+K6-L6 -> 8415926.5
A7: 4 | B7: 46085 | G7: =E7*F7 -> 0 | J7: =H7*I7 -> 0 | K7: =G7+J7 -> 0 | L7: 0 | M7: =M6+K7-L7 -> 8415926.5
A8: 5 | B8: 46086 | G8: =E8*F8 -> 0 | J8: =H8*I8 -> 0 | K8: =G8+J8 -> 0 | L8: 0 | M8: =M7+K8-L8 -> 8415926.5
A9: 6 | B9: 46087 | G9: =E9*F9 -> 0 | J9: =H9*I9 -> 0 | K9: =G9+J9 -> 0 | L9: 0 | M9: =M8+K9-L9 -> 8415926.5
A10: 7 | B10: 46088 | G10: =E10*F10 -> 0 | J10: =H10*I10 -> 0 | K10: =G10+J10 -> 0 | L10: 0 | M10: =M9+K10-L10 -> 8415926.5
A11: 8 | B11: 46089 | G11: =E11*F11 -> 0 | J11: =H11*I11 -> 0 | K11: =G11+J11 -> 0 | L11: 0 | M11: =M10+K11-L11 -> 8415926.5
A12: 9 | B12: 46090 | G12: =E12*F12 -> 0 | J12: =H12*I12 -> 0 | K12: =G12+J12 -> 0 | L12: 0 | M12: =M11+K12-L12 -> 8415926.5
A13: 10 | B13: 46091 | G13: =E13*F13 -> 0 | J13: =H13*I13 -> 0 | K13: =G13+J13 -> 0 | L13: 0 | M13: =M12+K13-L13 -> 8415926.5
A14: 11 | B14: 46092 | G14: =E14*F14 -> 0 | J14: =H14*I14 -> 0 | K14: =G14+J14 -> 0 | L14: 0 | M14: =M13+K14-L14 -> 8415926.5
A15: 12 | B15: 46093 | G15: =E15*F15 -> 0 | J15: =H15*I15 -> 0 | K15: =G15+J15 -> 0 | L15: 0 | M15: =M14+K15-L15 -> 8415926.5
A16: 13 | B16: 46094 | G16: =E16*F16 -> 0 | J16: =H16*I16 -> 0 | K16: =G16+J16 -> 0 | L16: 0 | M16: =M15+K16-L16 -> 8415926.5
A17: 14 | B17: 46095 | G17: =E17*F17 -> 0 | J17: =H17*I17 -> 0 | K17: =G17+J17 -> 0 | L17: 0 | M17: =M16+K17-L17 -> 8415926.5
... A30: 27 | B30: 46108 | G30: =E30*F30 -> 0 | J30: =H30*I30 -> 0 | K30: =G30+J30 -> 0 | L30: 0 | M30: =M29+K30-L30 -> 3915926.5
A31: 28 | B31: 46109 | E31: 2700 | F31: 95.68 | G31: =E31*F31 -> 258336 | H31: 20 | I31: 107.46 | J31: =H31*I31 -> 2149.2 | K31: =G31+J31 -> 260485.2 | L31: 0 | M31: =M30+K31-L31 -> 4176411.7
A32: 29 | B32: 46110 | G32: =E32*F32 -> 0 | J32: =H32*I32 -> 0 | K32: =G32+J32 -> 0 | L32: 0 | M32: =M31+K32-L32 -> 4176411.7
A33: 30 | B33: 46111 | G33: =E33*F33 -> 0 | J33: =H33*I33 -> 0 | K33: =G33+J33 -> 0 | L33: 0 | M33: =M32+K33-L33 -> 4176411.7
A34: 31 | B34: 46112 | G34: =E34*F34 -> 0 | K34: =G34+J34 -> 0 | L34: 0 | M34: =M33+K34-L34 -> 4176411.7
A35: 32 | G35: =E35*F35 -> 0 | J35: =H35*I35 -> 0 | K35: =G35+J35 -> 0 | L35: 0 | M35: =M34+K35-L35 -> 4176411.7
A36: 33 | G36: =E36*F36 -> 0 | J36: =H36*I36 -> 0 | K36: =G36+J36 -> 0 | L36: 0
A37: 34 | G37: =E37*F37 -> 0 | J37: =H37*I37 -> 0 | K37: =G37+J37 -> 0
E38: =SUM(E3:E37) -> 4500 | G38: =SUM(G3:G37) -> 430560 | H38: =SUM(H3:H37) -> 80 | J38: =SUM(J3:J37) -> 8596.8 | K38: =SUM(K4:K37) -> 439156.8 | L38: =SUM(L3:L37) -> 4500000

Sheet Khammam-2
A1: Jayasai union bunk
A2: S.No | B2: Date | C2: GRN No | D2: Ind No/Bill No | E2: Diesel (Lts) | F2: Price | G2: Amount | H2: Petrol (Lts) | I2: Price | J2: Amount | K2: Total amount | L2: Amount paid | M2: As 0n Date | N2: Remarks
A3: Opening Balance | K3: 5555857.2 | M3: 5555857.2
A4: 1 | B4: 46082 | G4: =E4*F4 -> 0 | J4: =H4*I4 -> 0 | K4: =G4+J4 -> 0 | M4: =M3+K4-L4 -> 5555857.2 | O4: =O3+M4-N4 -> 5555857.2
A5: 2 | B5: 46083 | E5: 1600 | F5: 95.71 | G5: =E5*F5 -> 153136 | H5: 40 | I5: 107.49 | J5: =H5*I5 -> 4299.6 | K5: =G5+J5 -> 157435.6 | M5: =M4+K5-L5 -> 5713292.8
A6: 3 | B6: 46084 | E6: 2100 | F6: 95.71 | G6: =E6*F6 -> 200991 | H6: 55 | I6: 107.49 | J6: =H6*I6 -> 5911.95 | K6: =G6+J6 -> 206902.95 | M6: =M5+K6-L6 -> 5920195.7
A7: 4 | B7: 46085 | G7: =E7*F7 -> 0 | J7: =H7*I7 -> 0 | K7: =G7+J7 -> 0 | M7: =M6+K7-L7 -> 5920195.7
A8: 5 | B8: 46086 | E8: 2700 | F8: 95.71 | G8: =E8*F8 -> 258417 | H8: 40 | I8: 107.49 | J8: =H8*I8 -> 4299.6 | K8: =G8+J8 -> 262716.6 | M8: =M7+K8-L8 -> 6182912.3 | O8: 12802499
A9: 6 | B9: 46087 | E9: 2700 | F9: 95.71 | G9: =E9*F9 -> 258417 | H9: 40 | I9: 107.49 | J9: =H9*I9 -> 4299.6 | K9: =G9+J9 -> 262716.6 | M9: =M8+K9-L9 -> 6445628.9
A10: 7 | B10: 46088 | E10: 4755.39 | F10: 95.71 | G10: =E10*F10 -> 455138.38 | J10: =H10*I10 -> 0 | K10: =G10+J10 -> 455138.38 | M10: =M9+K10-L10 -> 6900767.3
A11: 8 | B11: 46089 | G11: =E11*F11 -> 0 | J11: =H11*I11 -> 0 | K11: =G11+J11 -> 0 | M11: =M10+K11-L11 -> 6900767.3
A12: 9 | B12: 46090 | G12: =E12*F12 -> 0 | H12: 80 | I12: 107.49 | J12: =H12*I12 -> 8599.2 | K12: =G12+J12 -> 8599.2 | M12: =M11+K12-L12 -> 6909366.5
A13: 10 | B13: 46091 | E13: 4500 | F13: 95.71 | G13: =E13*F13 -> 430695 | H13: 75 | I13: 107.49 | J13: =H13*I13 -> 8061.75 | K13: =G13+J13 -> 438756.75 | M13: =M12+K13-L13 -> 7348123.2
A14: 11 | B14: 46092 | E14: 5500 | F14: 95.71 | G14: =E14*F14 -> 526405 | H14: 40 | I14: 107.49 | J14: =H14*I14 -> 4299.6 | K14: =G14+J14 -> 530704.6 | M14: =M13+K14-L14 -> 7878827.8
A15: 12 | B15: 46093 | E15: 7830 | F15: 95.71 | G15: =E15*F15 -> 749409.3 | H15: 40 | I15: 107.49 | J15: =H15*I15 -> 4299.6 | K15: =G15+J15 -> 753708.9 | M15: =M14+K15-L15 -> 8632536.7
A16: 13 | B16: 46094 | E16: 1044.823 | F16: 95.71 | G16: =E16*F16 -> 100000.01 | J16: =H16*I16 -> 0 | K16: =G16+J16 -> 100000.01 | L16: 0 | M16: =M15+K16-L16 -> 8732536.8 | N16: 100000 Cash &Carry
A17: 14 | B17: 46095 | G17: =E17*F17 -> 0 | J17: =H17*I17 -> 0 | K17: =G17+J17 -> 0 | M17: =M16+K17-L17 -> 8732536.8
A18: 15 | B18: 46096 | G18: =E18*F18 -> 0 | J18: =H18*I18 -> 0 | K18: =G18+J18 -> 0 | M18: =M17+K18-L18 -> 8732536.8
A19: 16 | B19: 46097 | E19: 5152.96 | F19: 95.71 | G19: =E19*F19 -> 493189.8 | H19: 175 | I19: 107.49 | J19: =H19*I19 -> 18810.75 | K19: =G19+J19 -> 512000.55 | M19: =M18+K19-L19 -> 9244537.3 | N19: 512000 Cash &Carry
A20: 17 | B20: 46098 | G20: =E20*F20 -> 0 | J20: =H20*I20 -> 0 | K20: =G20+J20 -> 0 | L20: 3500000 | M20: =M19+K20-L20 -> 5744537.3
A21: 18 | B21: 46099 | G21: =E21*F21 -> 0 | J21: =H21*I21 -> 0 | K21: =G21+J21 -> 0 | M21: =M20+K21-L21 -> 5744537.3
A22: 19 | B22: 46100 | G22: =E22*F22 -> 0 | J22: =H22*I22 -> 0 | K22: =G22+J22 -> 0 | L22: 0 | M22: =M21+K22-L22 -> 5744537.3
A23: 20 | B23: 46101 | G23: =E23*F23 -> 0 | H23: 115 | I23: 107.49 | J23: =H23*I23 -> 12361.35 | K23: =G23+J23 -> 12361.35 | M23: =M22+K23-L23 -> 5756898.7
A24: 21 | B24: 46102 | E24: 2100 | F24: 95.71 | G24: =E24*F24 -> 200991 | H24: 60 | I24: 107.49 | J24: =H24*I24 -> 6449.4 | K24: =G24+J24 -> 207440.4 | M24: =M23+K24-L24 -> 5964339.1
A25: 22 | B25: 46103 | G25: =E25*F25 -> 0 | J25: =H25*I25 -> 0 | K25: =G25+J25 -> 0 | M25: =M24+K25-L25 -> 5964339.1
A26: 23 | B26: 46104 | E26: 2100 | F26: 95.71 | G26: =E26*F26 -> 200991 | H26: 40 | I26: 107.49 | J26: =H26*I26 -> 4299.6 | K26: =G26+J26 -> 205290.6 | M26: =M25+K26-L26 -> 6169629.7
A27: 24 | B27: 46105 | G27: =E27*F27 -> 0 | J27: =H27*I27 -> 0 | K27: =G27+J27 -> 0 | M27: =M26+K27-L27 -> 6169629.7
A28: 25 | B28: 46106 | E28: 2700 | F28: 95.71 | G28: =E28*F28 -> 258417 | H28: 125 | I28: 107.49 | J28: =H28*I28 -> 13436.25 | K28: =G28+J28 -> 271853.25 | M28: =M27+K28-L28 -> 6441482.9
A29: 26 | B29: 46107 | E29: 2700 | F29: 95.71 | G29: =E29*F29 -> 258417 | H29: 20 | I29: 107.49 | J29: =H29*I29 -> 2149.8 | K29: =G29+J29 -> 260566.8 | M29: =M28+K29-L29 -> 6702049.7
A30: 27 | B30: 46108 | E30: 2800 | F30: 95.71 | G30: =E30*F30 -> 267988 | J30: =H30*I30 -> 0 | K30: =G30+J30 -> 267988 | M30: =M29+K30-L30 -> 6970037.7
A31: 28 | B31: 46109 | D31: 25-26/S4 (MP3 Grease) | E31: 546 | F31: 256.0989 | G31: =E31*F31 -> 139830 | H31: 0 | I31: 0 | J31: =H31*I31 -> 0 | K31: =G31+J31 -> 139830 | M31: =M30+K31-L31 -> 7109867.7
A32: 29 | B32: 46109 | E32: 2800 | F32: 95.71 | G32: =E32*F32 -> 267988 | H32: 40 | I32: 107.49 | J32: =H32*I32 -> 4299.6 | K32: =G32+J32 -> 272287.6 | M32: =M31+K32-L32 -> 7382155.3
A33: 30 | B33: 46111 | E33: 4029 | F33: 95.71 | G33: =E33*F33 -> 385615.59 | H33: 60 | I33: 107.49 | J33: =H33*I33 -> 6449.4 | K33: =G33+J33 -> 392064.99 | M33: =M32+K33-L33 -> 7774220.3
A34: 31 | E34: 2700 | F34: 95.71 | G34: =E34*F34 -> 258417 | J34: =H34*I34 -> 0 | K34: =G34+J34 -> 258417 | M34: =M33+K34-L34 -> 8032637.3
E35: =SUM(E4:E34) -> 60358.173 | G35: =SUM(G4:G34) -> 5864453.1 | H35: =SUM(H4:H34) -> 1045 | J35: =SUM(J4:J34) -> 112327.05 | K35: =SUM(K4:K34) -> 5976780.1 | L35: =SUM(L4:L34) -> 3500000

Sheet Khammam-3
A1: JSASFuel Genie India Pvt.Ltd
A2: S.No | B2: Date | C2: GRN No | D2: Ind No/Bill No | E2: Diesel (Lts) | F2: Price | G2: Amount | H2: Petrol (Lts) | I2: Price | J2: Amount | K2: Total amount | L2: Amount paid | M2: As 0n Date | N2: Remarks
A3: Opening Balance | K3: 1140143.1 | M3: 1140143.1
A4: 1 | B4: 46082 | E4: 6000 | F4: 94.7 | G4: =E4*F4 -> 568200 | J4: =H4*I4 -> 0 | K4: =G4+J4 -> 568200 | M4: =M3+K4-L4 -> 1708343.1
A5: 2 | B5: 46083 | E5: 6000 | F5: 94.7 | G5: =E5*F5 -> 568200 | J5: =H5*I5 -> 0 | K5: =G5+J5 -> 568200 | M5: =M4+K5-L5 -> 2276543.1
A6: 3 | B6: 46084 | E6: 6000 | F6: 94.7 | G6: =E6*F6 -> 568200 | J6: =H6*I6 -> 0 | K6: =G6+J6 -> 568200 | M6: =M5+K6-L6 -> 2844743.1
A7: 4 | B7: 46085 | E7: 6000 | F7: 94.7 | G7: =E7*F7 -> 568200 | J7: =H7*I7 -> 0 | K7: =G7+J7 -> 568200 | M7: =M6+K7-L7 -> 3412943.1
A8: 5 | B8: 46086 | E8: 6000 | F8: 94.7 | G8: =E8*F8 -> 568200 | J8: =H8*I8 -> 0 | K8: =G8+J8 -> 568200 | M8: =M7+K8-L8 -> 3981143.1
A9: 6 | B9: 46087 | E9: 6000 | F9: 94.7 | G9: =E9*F9 -> 568200 | J9: =H9*I9 -> 0 | K9: =G9+J9 -> 568200 | M9: =M8+K9-L9 -> 4549343.1
A10: 7 | B10: 46088 | E10: 6000 | F10: 94.7 | G10: =E10*F10 -> 568200 | J10: =H10*I10 -> 0 | K10: =G10+J10 -> 568200 | M10: =M9+K10-L10 -> 5117543.1
A11: 8 | B11: 46089 | E11: 6000 | F11: 94.7 | G11: =E11*F11 -> 568200 | J11: =H11*I11 -> 0 | K11: =G11+J11 -> 568200 | M11: =M10+K11-L11 -> 5685743.1
A12: 9 | B12: 46090 | E12: 12000 | F12: 94.7 | G12: =E12*F12 -> 1136400 | J12: =H12*I12 -> 0 | K12: =G12+J12 -> 1136400 | M12: =M11+K12-L12 -> 6822143.1
A13: 10 | B13: 46091 | E13: 6000 | F13: 94.7 | G13: =E13*F13 -> 568200 | J13: =H13*I13 -> 0 | K13: =G13+J13 -> 568200 | M13: =M12+K13-L13 -> 7390343.1
A14: 11 | B14: 46092 | E14: 6000 | F14: 94.7 | G14: =E14*F14 -> 568200 | J14: =H14*I14 -> 0 | K14: =G14+J14 -> 568200 | M14: =M13+K14-L14 -> 7958543.1
A15: 12 | B15: 46093 | E15: 6050 | F15: 94.7 | G15: =E15*F15 -> 572935 | J15: =H15*I15 -> 0 | K15: =G15+J15 -> 572935 | M15: =M14+K15-L15 -> 8531478.1
A16: 13 | B16: 46094 | E16: 5993.93 | F16: 94.7 | G16: =E16*F16 -> 567625.17 | J16: =H16*I16 -> 0 | K16: =G16+J16 -> 567625.17 | M16: =M15+K16-L16 -> 9099103.3
A17: 14 | B17: 46095 | G17: =E17*F17 -> 0 | J17: =H17*I17 -> 0 | K17: =G17+J17 -> 0 | M17: =M16+K17-L17 -> 9099103.3
A18: 15 | B18: 46096 | G18: =E18*F18 -> 0 | J18: =H18*I18 -> 0 | K18: =G18+J18 -> 0 | M18: =M17+K18-L18 -> 9099103.3
A19: 16 | B19: 46097 | G19: =E19*F19 -> 0 | J19: =H19*I19 -> 0 | K19: =G19+J19 -> 0 | M19: =M18+K19-L19 -> 9099103.3
A20: 17 | B20: 46098 | E20: 6000 | F20: 94.7 | G20: =E20*F20 -> 568200 | J20: =H20*I20 -> 0 | K20: =G20+J20 -> 568200 | M20: =M19+K20-L20 -> 9667303.3
A21: 18 | B21: 46099 | E21: 6000 | F21: 94.7 | G21: =E21*F21 -> 568200 | J21: =H21*I21 -> 0 | K21: =G21+J21 -> 568200 | M21: =M20+K21-L21 -> 10235503
A22: 19 | B22: 46100 | G22: =E22*F22 -> 0 | J22: =H22*I22 -> 0 | K22: =G22+J22 -> 0 | M22: =M21+K22-L22 -> 10235503
A23: 20 | B23: 46101 | E23: 6000 | F23: 94.7 | G23: =E23*F23 -> 568200 | J23: =H23*I23 -> 0 | K23: =G23+J23 -> 568200 | M23: =M22+K23-L23 -> 10803703
A24: 21 | B24: 46102 | E24: 6000 | F24: 94.7 | G24: =E24*F24 -> 568200 | J24: =H24*I24 -> 0 | K24: =G24+J24 -> 568200 | M24: =M23+K24-L24 -> 11371903
A25: 22 | B25: 46103 | G25: =E25*F25 -> 0 | J25: =H25*I25 -> 0 | K25: =G25+J25 -> 0 | M25: =M24+K25-L25 -> 11371903
A26: 23 | B26: 46104 | E26: 6000 | F26: 95.2 | G26: =E26*F26 -> 571200 | J26: =H26*I26 -> 0 | K26: =G26+J26 -> 571200 | L26: 6000000 | M26: =M25+K26-L26 -> 5943103.3
A27: 24 | B27: 46105 | E27: 6000 | F27: 95.2 | G27: =E27*F27 -> 571200 | J27: =H27*I27 -> 0 | K27: =G27+J27 -> 571200 | M27: =M26+K27-L27 -> 6514303.3
A28: 25 | B28: 46106 | E28: 6000 | F28: 95.2 | G28: =E28*F28 -> 571200 | J28: =H28*I28 -> 0 | K28: =G28+J28 -> 571200 | M28: =M27+K28-L28 -> 7085503.3
A29: 26 | B29: 46107 | G29: =E29*F29 -> 0 | J29: =H29*I29 -> 0 | K29: =G29+J29 -> 0 | M29: =M28+K29-L29 -> 7085503.3
A30: 27 | B30: 46108 | G30: =E30*F30 -> 0 | J30: =H30*I30 -> 0 | K30: =G30+J30 -> 0 | M30: =M29+K30-L30 -> 7085503.3
A31: 28 | B31: 46109 | G31: =E31*F31 -> 0 | J31: =H31*I31 -> 0 | K31: =G31+J31 -> 0 | M31: =M30+K31-L31 -> 7085503.3
A32: 29 | B32: 46110 | E32: 6000 | F32: 95.2 | G32: =E32*F32 -> 571200 | J32: =H32*I32 -> 0 | K32: =G32+J32 -> 571200 | M32: =M31+K32-L32 -> 7656703.3
A33: 30 | B33: 46111 | G33: =E33*F33 -> 0 | J33: =H33*I33 -> 0 | K33: =G33+J33 -> 0 | M33: =M32+K33-L33 -> 7656703.3 | O33: 5486 | P33: TDS194Q
A34: 31 | B34: 46112 | E34: 6000 | F34: 95.2 | G34: =E34*F34 -> 571200 | J34: =H34*I34 -> 0 | K34: =G34+J34 -> 571200 | M34: =M33+K34-L34 -> 8227903.3
E35: =SUM(E4:E34) -> 138043.93 | G35: =SUM(G4:G34) -> 13087760 | H35: =SUM(H4:H34) -> 0 | J35: =SUM(J4:J34) -> 0 | K35: =SUM(K4:K34) -> 13087760 | L35: =SUM(L4:L34) -> 6000000

Sheet Khammam-4
A1: Vajra Mahalakshmi filling station
A2: S.No | B2: Date | C2: GRN No | D2: Ind No/Bill No | E2: Diesel (Lts) | F2: Price | G2: Amount | H2: Petrol (Lts) | I2: Price | J2: Amount | K2: Total amount | L2: Amount paid | M2: As 0n Date | N2: Remarks
A3: Opening Balance | K3: 0 | M3: 0
A4: 1 | B4: 46082 | G4: =E4*F4 -> 0 | K4: =G4+J4 -> 0 | L4: 0 | M4: =M3+K4-L4 -> 0
A5: 2 | B5: 46083 | E5: 0 | F5: 0 | G5: =E5*F5 -> 0 | H5: 0 | I5: 0 | J5: =H5*I5 -> 0 | K5: =G5+J5 -> 0 | L5: 0 | M5: =M4+K5-L5 -> 0
A6: 3 | B6: 46084 | G6: =E6*F6 -> 0 | J6: =H6*I6 -> 0 | K6: =G6+J6 -> 0 | L6: 0 | M6: =M5+K6-L6 -> 0
A7: 4 | B7: 46085 | G7: =E7*F7 -> 0 | J7: =H7*I7 -> 0 | K7: =G7+J7 -> 0 | L7: 0 | M7: =M6+K7-L7 -> 0
A8: 5 | B8: 46086 | G8: =E8*F8 -> 0 | J8: =H8*I8 -> 0 | K8: =G8+J8 -> 0 | L8: 0 | M8: =M7+K8-L8 -> 0
A9: 6 | B9: 46087 | G9: =E9*F9 -> 0 | J9: =H9*I9 -> 0 | K9: =G9+J9 -> 0 | L9: 0 | M9: =M8+K9-L9 -> 0
A10: 7 | B10: 46088 | E10: 2700 | F10: 95.5 | G10: =E10*F10 -> 257850 | J10: =H10*I10 -> 0 | K10: =G10+J10 -> 257850 | L10: 0 | M10: =M9+K10-L10 -> 257850
A11: 8 | B11: 46089 | G11: =E11*F11 -> 0 | J11: =H11*I11 -> 0 | K11: =G11+J11 -> 0 | L11: 0 | M11: =M10+K11-L11 -> 257850
A12: 9 | B12: 46090 | G12: =E12*F12 -> 0 | J12: =H12*I12 -> 0 | K12: =G12+J12 -> 0 | L12: 0 | M12: =M11+K12-L12 -> 257850
A13: 10 | B13: 46091 | E13: 759.76 | F13: 95.5 | G13: =E13*F13 -> 72557.08 | J13: =H13*I13 -> 0 | K13: =G13+J13 -> 72557.08 | L13: 0 | M13: =M12+K13-L13 -> 330407.08
A14: 11 | B14: 46092 | G14: =E14*F14 -> 0 | J14: =H14*I14 -> 0 | K14: =G14+J14 -> 0 | L14: 0 | M14: =M13+K14-L14 -> 330407.08
A15: 12 | B15: 46093 | G15: =E15*F15 -> 0 | J15: =H15*I15 -> 0 | K15: =G15+J15 -> 0 | L15: 0 | M15: =M14+K15-L15 -> 330407.08
A16: 13 | B16: 46094 | G16: =E16*F16 -> 0 | J16: =H16*I16 -> 0 | K16: =G16+J16 -> 0 | L16: 0 | M16: =M15+K16-L16 -> 330407.08
A17: 14 | B17: 46095 | G17: =E17*F17 -> 0 | J17: =H17*I17 -> 0 | K17: =G17+J17 -> 0 | L17: 0 | M17: =M16+K17-L17 -> 330407.08
A18: 15 | B18: 46096 | G18: =E18*F18 -> 0 | J18: =H18*I18 -> 0 | K18: =G18+J18 -> 0 | L18: 0 | M18: =M17+K18-L18 -> 330407.08
A19: 16 | B19: 46097 | G19: =E19*F19 -> 0 | J19: =H19*I19 -> 0 | K19: =G19+J19 -> 0 | L19: 0 | M19: =M18+K19-L19 -> 330407.08
A20: 17 | B20: 46098 | G20: =E20*F20 -> 0 | J20: =H20*I20 -> 0 | K20: =G20+J20 -> 0 | L20: 0 | M20: =M19+K20-L20 -> 330407.08
A21: 18 | B21: 46099 | G21: =E21*F21 -> 0 | J21: =H21*I21 -> 0 | K21: =G21+J21 -> 0 | L21: 0 | M21: =M20+K21-L21 -> 330407.08
A22: 19 | B22: 46100 | G22: =E22*F22 -> 0 | J22: =H22*I22 -> 0 | K22: =G22+J22 -> 0 | L22: 0 | M22: =M21+K22-L22 -> 330407.08
A23: 20 | B23: 46101 | G23: =E23*F23 -> 0 | J23: =H23*I23 -> 0 | K23: =G23+J23 -> 0 | L23: 0 | M23: =M22+K23-L23 -> 330407.08
A24: 21 | B24: 46102 | G24: =E24*F24 -> 0 | J24: =H24*I24 -> 0 | K24: =G24+J24 -> 0 | L24: 0 | M24: =M23+K24-L24 -> 330407.08
A25: 22 | B25: 46103 | G25: =E25*F25 -> 0 | J25: =H25*I25 -> 0 | K25: =G25+J25 -> 0 | L25: 0 | M25: =M24+K25-L25 -> 330407.08
... A33: 30 | B33: 46111 | G33: =E33*F33 -> 0 | J33: =H33*I33 -> 0 | K33: =G33+J33 -> 0 | L33: 0 | M33: =M32+K33-L33 -> 330407.08
A34: 31 | B34: 46112 | G34: =E34*F34 -> 0 | K34: =G34+J34 -> 0 | L34: 0 | M34: =M33+K34-L34 -> 330407.08
A35: 32 | G35: =E35*F35 -> 0 | J35: =H35*I35 -> 0 | K35: =G35+J35 -> 0 | L35: 0 | M35: =M34+K35-L35 -> 330407.08
A36: 33 | G36: =E36*F36 -> 0 | J36: =H36*I36 -> 0 | K36: =G36+J36 -> 0 | L36: 0
A37: 34 | G37: =E37*F37 -> 0 | J37: =H37*I37 -> 0 | K37: =G37+J37 -> 0
E38: =SUM(E3:E37) -> 3459.76 | G38: =SUM(G3:G37) -> 330407.08 | H38: =SUM(H3:H37) -> 0 | J38: =SUM(J3:J37) -> 0 | K38: =SUM(K4:K37) -> 330407.08 | L38: =SUM(L3:L37) -> 0

Sheet Khammam-5
A1: SR HP Filling Station ( Dhamsalapuram)
A2: S.No | B2: Date | C2: GRN No | D2: Ind No/Bill No | E2: Diesel (Lts) | F2: Price | G2: Amount | H2: Petrol (Lts) | I2: Price | J2: Amount | K2: Total amount | L2: Amount paid | M2: As 0n Date | N2: Remarks
A3: Opening Balance | K3: 0 | M3: 0
A4: 1 | B4: 46082 | G4: =E4*F4 -> 0 | K4: =G4+J4 -> 0 | L4: 0 | M4: =M3+K4-L4 -> 0
A5: 2 | B5: 46083 | G5: =E5*F5 -> 0 | J5: =H5*I5 -> 0 | K5: =G5+J5 -> 0 | L5: 0 | M5: =M4+K5-L5 -> 0
A6: 3 | B6: 46084 | G6: =E6*F6 -> 0 | J6: =H6*I6 -> 0 | K6: =G6+J6 -> 0 | L6: 0 | M6: =M5+K6-L6 -> 0
A7: 4 | B7: 46085 | G7: =E7*F7 -> 0 | J7: =H7*I7 -> 0 | K7: =G7+J7 -> 0 | L7: 0 | M7: =M6+K7-L7 -> 0
A8: 5 | B8: 46086 | G8: =E8*F8 -> 0 | J8: =H8*I8 -> 0 | K8: =G8+J8 -> 0 | L8: 0 | M8: =M7+K8-L8 -> 0
A9: 6 | B9: 46087 | G9: =E9*F9 -> 0 | J9: =H9*I9 -> 0 | K9: =G9+J9 -> 0 | L9: 0 | M9: =M8+K9-L9 -> 0
A10: 7 | B10: 46088 | G10: =E10*F10 -> 0 | J10: =H10*I10 -> 0 | K10: =G10+J10 -> 0 | L10: 0 | M10: =M9+K10-L10 -> 0
A11: 8 | B11: 46089 | G11: =E11*F11 -> 0 | J11: =H11*I11 -> 0 | K11: =G11+J11 -> 0 | L11: 0 | M11: =M10+K11-L11 -> 0
A12: 9 | B12: 46090 | G12: =E12*F12 -> 0 | J12: =H12*I12 -> 0 | K12: =G12+J12 -> 0 | L12: 0 | M12: =M11+K12-L12 -> 0
A13: 10 | B13: 46091 | G13: =E13*F13 -> 0 | J13: =H13*I13 -> 0 | K13: =G13+J13 -> 0 | L13: 0 | M13: =M12+K13-L13 -> 0
A14: 11 | B14: 46092 | G14: =E14*F14 -> 0 | J14: =H14*I14 -> 0 | K14: =G14+J14 -> 0 | L14: 0 | M14: =M13+K14-L14 -> 0
A15: 12 | B15: 46093 | G15: =E15*F15 -> 0 | J15: =H15*I15 -> 0 | K15: =G15+J15 -> 0 | L15: 0 | M15: =M14+K15-L15 -> 0
A16: 13 | B16: 46094 | G16: =E16*F16 -> 0 | J16: =H16*I16 -> 0 | K16: =G16+J16 -> 0 | L16: 0 | M16: =M15+K16-L16 -> 0
A17: 14 | B17: 46095 | G17: =E17*F17 -> 0 | J17: =H17*I17 -> 0 | K17: =G17+J17 -> 0 | L17: 0 | M17: =M16+K17-L17 -> 0 | U17: 257315
A18: 15 | B18: 46096 | G18: =E18*F18 -> 0 | J18: =H18*I18 -> 0 | K18: =G18+J18 -> 0 | L18: 0 | M18: =M17+K18-L18 -> 0 | U18: 22996
A19: 16 | B19: 46097 | G19: =E19*F19 -> 0 | J19: =H19*I19 -> 0 | K19: =G19+J19 -> 0 | L19: 0 | M19: =M18+K19-L19 -> 0 | U19: =U17+U18 -> 280311
A20: 17 | B20: 46098 | G20: =E20*F20 -> 0 | J20: =H20*I20 -> 0 | K20: =G20+J20 -> 0 | L20: 0 | M20: =M19+K20-L20 -> 0 | U20: =U19-183340 -> 96971
A21: 18 | B21: 46099 | G21: =E21*F21 -> 0 | J21: =H21*I21 -> 0 | K21: =G21+J21 -> 0 | L21: 0 | M21: =M20+K21-L21 -> 0
A22: 19 | B22: 46100 | G22: =E22*F22 -> 0 | J22: =H22*I22 -> 0 | K22: =G22+J22 -> 0 | L22: 0 | M22: =M21+K22-L22 -> 0 | R22: 91.67
A23: 20 | B23: 46101 | G23: =E23*F23 -> 0 | J23: =H23*I23 -> 0 | K23: =G23+J23 -> 0 | L23: 0 | M23: =M22+K23-L23 -> 0 | R23: 2000 | U23: 197391.46
A24: 21 | B24: 46102 | G24: =E24*F24 -> 0 | J24: =H24*I24 -> 0 | K24: =G24+J24 -> 0 | L24: 0 | M24: =M23+K24-L24 -> 0 | R24: =R23*R22 -> 183340
A25: 22 | B25: 46103 | G25: =E25*F25 -> 0 | J25: =H25*I25 -> 0 | K25: =G25+J25 -> 0 | L25: 0 | M25: =M24+K25-L25 -> 0
A26: 23 | B26: 46104 | G26: =E26*F26 -> 0 | J26: =H26*I26 -> 0 | K26: =G26+J26 -> 0 | L26: 0 | M26: =M25+K26-L26 -> 0
A27: 24 | B27: 46105 | E27: 1569.98 | F27: 95.68 | G27: =E27*F27 -> 150215.69 | J27: =H27*I27 -> 0 | K27: =G27+J27 -> 150215.69 | L27: 150215 | M27: =M26+K27-L27 -> 0.6864
A28: 25 | B28: 46106 | G28: =E28*F28 -> 0 | J28: =H28*I28 -> 0 | K28: =G28+J28 -> 0 | L28: 0 | M28: =M27+K28-L28 -> 0.6864
A29: 26 | B29: 46107 | E29: 2612.88 | F29: 95.68 | G29: =E29*F29 -> 250000.36 | J29: =H29*I29 -> 0 | K29: =G29+J29 -> 250000.36 | L29: =H29+K29 -> 250000.36 | M29: =M28+K29-L29 -> 0.6864
A30: 27 | B30: 46108 | E30: 2090.3 | F30: 95.68 | G30: =E30*F30 -> 199999.9 | J30: =H30*I30 -> 0 | K30: =G30+J30 -> 199999.9 | L30: =H30+K30 -> 199999.9 | M30: =M29+K30-L30 -> 0.6864
A31: 28 | B31: 46109 | G31: =E31*F31 -> 0 | J31: =H31*I31 -> 0 | K31: =G31+J31 -> 0 | L31: 0 | M31: =M30+K31-L31 -> 0.6864
A32: 29 | B32: 46110 | G32: =E32*F32 -> 0 | J32: =H32*I32 -> 0 | K32: =G32+J32 -> 0 | L32: 0 | M32: =M31+K32-L32 -> 0.6864
A33: 30 | B33: 46111 | G33: =E33*F33 -> 0 | J33: =H33*I33 -> 0 | K33: =G33+J33 -> 0 | L33: 0 | M33: =M32+K33-L33 -> 0.6864
A34: 31 | B34: 46112 | G34: =E34*F34 -> 0 | K34: =G34+J34 -> 0 | L34: 0 | M34: =M33+K34-L34 -> 0.6864
A35: 32 | G35: =E35*F35 -> 0 | J35: =H35*I35 -> 0 | K35: =G35+J35 -> 0 | L35: 0 | M35: =M34+K35-L35 -> 0.6864
A36: 33 | G36: =E36*F36 -> 0 | J36: =H36*I36 -> 0 | K36: =G36+J36 -> 0 | L36: 0
A37: 34 | G37: =E37*F37 -> 0 | J37: =H37*I37 -> 0 | K37: =G37+J37 -> 0
E38: =SUM(E3:E37) -> 6273.16 | G38: =SUM(G3:G37) -> 600215.95 | H38: =SUM(H3:H37) -> 0 | J38: =SUM(J3:J37) -> 0 | K38: =SUM(K4:K37) -> 600215.95 | L38: =SUM(L3:L37) -> 600215.26

Sheet Jadcherla-3
A1: JSASFuel Genie India Pvt.Ltd
A2: S.No | B2: Date | C2: GRN No | D2: Ind no/Bill No | E2: Diesel (Lts) | F2: Price | G2: Amount | H2: Petrol (Lts) | I2: Price | J2: Amount | K2: Total amount | L2: Amount paid | M2: As on Date | N2: Remarks
A3: Opening Balance | M3: 1026278.2
A4: 1 | B4: 46082 | E4: 2200 | F4: 95.43 | G4: =E4*F4 -> 209946 | H4: 0 | I4: 0 | J4: =H4*I4 -> 0 | K4: =G4+J4 -> 209946 | L4: 0 | M4: =+M3+K4-L4 -> 1236224.2
A5: 2 | B5: 46083 | E5: 2400 | F5: 95.43 | G5: =E5*F5 -> 229032 | H5: 0 | I5: 0 | J5: =H5*I5 -> 0 | K5: =G5+J5 -> 229032 | L5: 0 | M5: =+M4+K5-L5 -> 1465256.2
A6: 3 | B6: 46084 | G6: =E6*F6 -> 0 | H6: 0 | I6: 0 | J6: =H6*I6 -> 0 | K6: =G6+J6 -> 0 | L6: 0 | M6: =+M5+K6-L6 -> 1465256.2
A7: 4 | B7: 46085 | G7: =E7*F7 -> 0 | H7: 0 | I7: 0 | J7: =H7*I7 -> 0 | K7: =G7+J7 -> 0 | L7: 0 | M7: =+M6+K7-L7 -> 1465256.2
A8: 5 | B8: 46086 | G8: =E8*F8 -> 0 | H8: 0 | I8: 0 | J8: =H8*I8 -> 0 | K8: =G8+J8 -> 0 | L8: 0 | M8: =+M7+K8-L8 -> 1465256.2
A9: 6 | B9: 46087 | G9: =E9*F9 -> 0 | H9: 0 | I9: 0 | J9: =H9*I9 -> 0 | K9: =G9+J9 -> 0 | L9: 0 | M9: =+M8+K9-L9 -> 1465256.2
A10: 7 | B10: 46088 | E10: 2000 | F10: 95.43 | G10: =E10*F10 -> 190860 | H10: 0 | I10: 0 | J10: =H10*I10 -> 0 | K10: =G10+J10 -> 190860 | L10: 0 | M10: =+M9+K10-L10 -> 1656116.2 | R10: 700
A11: 8 | B11: 46089 | G11: =E11*F11 -> 0 | H11: 0 | I11: 0 | J11: =H11*I11 -> 0 | K11: =G11+J11 -> 0 | L11: 0 | M11: =+M10+K11-L11 -> 1656116.2 | S11: 5000
A12: 9 | B12: 46090 | E12: 2000 | F12: 95.43 | G12: =E12*F12 -> 190860 | H12: 0 | I12: 0 | J12: =H12*I12 -> 0 | K12: =G12+J12 -> 190860 | L12: 0 | M12: =+M11+K12-L12 -> 1846976.2 | S12: 1500
A13: 10 | B13: 46091 | G13: =E13*F13 -> 0 | H13: 0 | I13: 0 | J13: =H13*I13 -> 0 | K13: =G13+J13 -> 0 | L13: 0 | M13: =+M12+K13-L13 -> 1846976.2 | S13: 500
A14: 11 | B14: 46092 | E14: 1000 | F14: 95.43 | G14: =E14*F14 -> 95430 | H14: 0 | I14: 0 | J14: =H14*I14 -> 0 | K14: =G14+J14 -> 95430 | L14: 0 | M14: =+M13+K14-L14 -> 1942406.2
A15: 12 | B15: 46093 | G15: =E15*F15 -> 0 | H15: 0 | I15: 0 | J15: =H15*I15 -> 0 | K15: =G15+J15 -> 0 | L15: 0 | M15: =+M14+K15-L15 -> 1942406.2
A16: 13 | B16: 46094 | E16: 1998 | F16: 95.43 | G16: =E16*F16 -> 190669.14 | H16: 0 | I16: 0 | J16: =H16*I16 -> 0 | K16: =G16+J16 -> 190669.14 | L16: 0 | M16: =+M15+K16-L16 -> 2133075.4
A17: 14 | B17: 46095 | E17: 2000 | F17: 95.43 | G17: =E17*F17 -> 190860 | H17: 0 | I17: 0 | J17: =H17*I17 -> 0 | K17: =G17+J17 -> 190860 | L17: 0 | M17: =+M16+K17-L17 -> 2323935.4
A18: 15 | B18: 46096 | G18: =E18*F18 -> 0 | H18: 0 | I18: 0 | J18: =H18*I18 -> 0 | K18: =G18+J18 -> 0 | L18: 0 | M18: =+M17+K18-L18 -> 2323935.4
A19: 16 | B19: 46097 | E19: 2400 | F19: 95.43 | G19: =E19*F19 -> 229032 | H19: 0 | I19: 0 | J19: =H19*I19 -> 0 | K19: =G19+J19 -> 229032 | L19: 0 | M19: =+M18+K19-L19 -> 2552967.4
A20: 17 | B20: 46098 | E20: 2000 | F20: 95.43 | G20: =E20*F20 -> 190860 | H20: 0 | I20: 0 | J20: =H20*I20 -> 0 | K20: =G20+J20 -> 190860 | L20: 0 | M20: =+M19+K20-L20 -> 2743827.4
A21: 18 | B21: 46099 | G21: =E21*F21 -> 0 | H21: 0 | I21: 0 | J21: =H21*I21 -> 0 | K21: =G21+J21 -> 0 | M21: =+M20+K21-L21 -> 2743827.4
A22: 19 | B22: 46100 | G22: =E22*F22 -> 0 | H22: 0 | I22: 0 | J22: =H22*I22 -> 0 | K22: =G22+J22 -> 0 | L22: 1000000 | M22: =+M21+K22-L22 -> 1743827.4
A23: 20 | B23: 46101 | E23: 1000 | F23: 95.43 | G23: =E23*F23 -> 95430 | H23: 0 | I23: 0 | J23: =H23*I23 -> 0 | K23: =G23+J23 -> 95430 | L23: 0 | M23: =+M22+K23-L23 -> 1839257.4
A24: 21 | B24: 46102 | G24: =E24*F24 -> 0 | H24: 0 | I24: 0 | J24: =H24*I24 -> 0 | K24: =G24+J24 -> 0 | L24: 0 | M24: =+M23+K24-L24 -> 1839257.4
A25: 22 | B25: 46103 | G25: =E25*F25 -> 0 | H25: 0 | I25: 0 | J25: =H25*I25 -> 0 | K25: =G25+J25 -> 0 | L25: 0 | M25: =+M24+K25-L25 -> 1839257.4
A26: 23 | B26: 46104 | E26: 2000 | F26: 95.93 | G26: =E26*F26 -> 191860 | H26: 0 | I26: 0 | J26: =H26*I26 -> 0 | K26: =G26+J26 -> 191860 | L26: 0 | M26: =+M25+K26-L26 -> 2031117.4
A27: 24 | B27: 46105 | E27: 2400 | F27: 95.93 | G27: =E27*F27 -> 230232 | H27: 0 | I27: 0 | J27: =H27*I27 -> 0 | K27: =G27+J27 -> 230232 | L27: 0 | M27: =+M26+K27-L27 -> 2261349.4
A28: 25 | B28: 46106 | G28: =E28*F28 -> 0 | H28: 0 | I28: 0 | J28: =H28*I28 -> 0 | K28: =G28+J28 -> 0 | L28: 0 | M28: =+M27+K28-L28 -> 2261349.4
A29: 26 | B29: 46107 | E29: 1000 | F29: 95.93 | G29: =E29*F29 -> 95930 | H29: 0 | I29: 0 | J29: =H29*I29 -> 0 | K29: =G29+J29 -> 95930 | M29: =+M28+K29-L29 -> 2357279.4
A30: 27 | B30: 46108 | G30: =E30*F30 -> 0 | H30: 0 | I30: 0 | J30: =H30*I30 -> 0 | K30: =G30+J30 -> 0 | M30: =+M29+K30-L30 -> 2357279.4
A31: 28 | B31: 46109 | G31: =E31*F31 -> 0 | H31: 0 | I31: 0 | J31: =H31*I31 -> 0 | K31: =G31+J31 -> 0 | M31: =+M30+K31-L31 -> 2357279.4
A32: 29 | B32: 46111 | E32: 1000 | F32: 95.93 | G32: =E32*F32 -> 95930 | H32: 0 | I32: 0 | J32: =H32*I32 -> 0 | K32: =G32+J32 -> 95930 | M32: =+M31+K32-L32 -> 2453209.4
A33: 30 | G33: =E33*F33 -> 0 | H33: 0 | I33: 0 | J33: =H33*I33 -> 0 | K33: =G33+J33 -> 0 | M33: =+M32+K33-L33 -> 2453209.4
A34: 31 | G34: =E34*F34 -> 0 | H34: 0 | I34: 0 | J34: =H34*I34 -> 0 | K34: =G34+J34 -> 0 | L34: 0 | M34: =+M33+K34-L34 -> 2453209.4
E35: =SUM(E4:E34) -> 25398 | G35: =SUM(G4:G34) -> 2426931.1 | H35: =SUM(H4:H34) -> 0 | J35: =SUM(J4:J34) -> 0 | K35: =SUM(K4:K34) -> 2426931.1 | L35: =SUM(L4:L34) -> 1000000
F38: /

Sheet Jadcherla-4
A1: Shree Poornima F/S
A2: S.No | B2: Date | C2: GRN No | D2: Ind No/Bill No | E2: Diesel (Lts) | F2: Price | G2: Amount | H2: Petrol (Lts) | I2: Price | J2: Amount | K2: Total amount | L2: Amount paid | M2: As on date | N2: Remarks
A3: Opening Balance | M3: 24863
A4: 1 | B4: 46082 | G4: =E4*F4 -> 0 | H4: 40 | I4: 108.1 | J4: =H4*I4 -> 4324 | K4: =G4+J4 -> 4324 | L4: 0 | M4: =M3+K4-L4 -> 29187
A5: 2 | B5: 46083 | G5: =E5*F5 -> 0 | H5: 0 | I5: 0 | J5: =H5*I5 -> 0 | K5: =G5+J5 -> 0 | L5: 0 | M5: =M4+K5-L5 -> 29187
A6: 3 | B6: 46084 | G6: =E6*F6 -> 0 | H6: 0 | I6: 0 | J6: =H6*I6 -> 0 | K6: =G6+J6 -> 0 | L6: 0 | M6: =M5+K6-L6 -> 29187
A7: 4 | B7: 46085 | G7: =E7*F7 -> 0 | H7: 0 | I7: 0 | J7: =H7*I7 -> 0 | K7: =G7+J7 -> 0 | L7: 0 | M7: =M6+K7-L7 -> 29187
A8: 5 | B8: 46086 | G8: =E8*F8 -> 0 | H8: 40 | I8: 108.1 | J8: =H8*I8 -> 4324 | K8: =G8+J8 -> 4324 | L8: 0 | M8: =M7+K8-L8 -> 33511
A9: 6 | B9: 46087 | G9: =E9*F9 -> 0 | H9: 0 | I9: 0 | J9: =H9*I9 -> 0 | K9: =G9+J9 -> 0 | L9: 0 | M9: =M8+K9-L9 -> 33511
A10: 7 | B10: 46088 | G10: =E10*F10 -> 0 | H10: 0 | I10: 0 | J10: =H10*I10 -> 0 | K10: =G10+J10 -> 0 | L10: 0 | M10: =M9+K10-L10 -> 33511
A11: 8 | B11: 46089 | G11: =E11*F11 -> 0 | H11: 0 | I11: 0 | J11: =H11*I11 -> 0 | K11: =G11+J11 -> 0 | L11: 0 | M11: =M10+K11-L11 -> 33511
A12: 9 | B12: 46090 | G12: =E12*F12 -> 0 | H12: 0 | I12: 0 | J12: =H12*I12 -> 0 | K12: =G12+J12 -> 0 | L12: 0 | M12: =M11+K12-L12 -> 33511
A13: 10 | B13: 46091 | G13: =E13*F13 -> 0 | H13: 0 | I13: 0 | J13: =H13*I13 -> 0 | K13: =G13+J13 -> 0 | L13: 0 | M13: =M12+K13-L13 -> 33511
A14: 11 | B14: 46092 | G14: =E14*F14 -> 0 | H14: 40 | I14: 108.1 | J14: =H14*I14 -> 4324 | K14: =G14+J14 -> 4324 | L14: 0 | M14: =M13+K14-L14 -> 37835
A15: 12 | B15: 46093 | G15: =E15*F15 -> 0 | H15: 0 | I15: 0 | J15: =H15*I15 -> 0 | K15: =G15+J15 -> 0 | L15: 0 | M15: =M14+K15-L15 -> 37835
... A25: 22 | B25: 46103 | G25: =E25*F25 -> 0 | H25: 0 | I25: 0 | J25: =H25*I25 -> 0 | K25: =G25+J25 -> 0 | L25: 0 | M25: =M24+K25-L25 -> 4324
A26: 23 | B26: 46104 | E26: 0 | F26: 0 | G26: =E26*F26 -> 0 | H26: 0 | I26: 0 | J26: =H26*I26 -> 0 | K26: =G26+J26 -> 0 | L26: 0 | M26: =M25+K26-L26 -> 4324
A27: 24 | B27: 46105 | G27: =E27*F27 -> 0 | H27: 0 | I27: 0 | J27: =H27*I27 -> 0 | K27: =G27+J27 -> 0 | L27: 0 | M27: =M26+K27-L27 -> 4324
A28: 25 | B28: 46106 | G28: =E28*F28 -> 0 | H28: 0 | I28: 0 | J28: =H28*I28 -> 0 | K28: =G28+J28 -> 0 | L28: 0 | M28: =M27+K28-L28 -> 4324
A29: 26 | B29: 46107 | G29: =E29*F29 -> 0 | H29: 50 | I29: 108.1 | J29: =H29*I29 -> 5405 | K29: =G29+J29 -> 5405 | L29: 0 | M29: =M28+K29-L29 -> 9729
A30: 27 | B30: 46108 | G30: =E30*F30 -> 0 | H30: 0 | I30: 0 | J30: =H30*I30 -> 0 | K30: =G30+J30 -> 0 | L30: 0 | M30: =M29+K30-L30 -> 9729
A31: 28 | B31: 46109 | G31: =E31*F31 -> 0 | H31: 0 | I31: 0 | J31: =H31*I31 -> 0 | K31: =G31+J31 -> 0 | M31: =M30+K31-L31 -> 9729
A32: 29 | B32: 46110 | G32: =E32*F32 -> 0 | H32: 0 | I32: 0 | J32: =H32*I32 -> 0 | K32: =G32+J32 -> 0 | M32: =M31+K32-L32 -> 9729
A33: 30 | B33: 46111 | G33: =E33*F33 -> 0 | H33: 0 | I33: 0 | J33: =H33*I33 -> 0 | K33: =G33+J33 -> 0 | M33: =M32+K33-L33 -> 9729
A34: 31 | B34: 46112 | G34: =E34*F34 -> 0 | J34: =H34*I34 -> 0 | K34: =G34+J34 -> 0 | M34: =M33+K34-L34 -> 9729
E35: =SUM(E4:E34) -> 0 | G35: =SUM(G4:G34) -> 0 | H35: =SUM(H4:H34) -> 210 | J35: =SUM(J4:J34) -> 22701 | K35: =SUM(K4:K34) -> 22701 | L35: =SUM(L4:L34) -> 37835

Sheet  Sangareeddy-1
A1: Durga Indhan
A2: S.No | B2: Date | C2: GRN No | D2: Ind no/Bill No | E2: Diesel (Lts) | F2: Price | G2: Amount | H2: Petrol (Lts) | I2: Price | J2: Amount | K2: Total amount | L2: Amount paid | M2: As on Date | N2: Remarks
A3: Opening Balance | M3: 151710.02
A4: 1 | B4: 45717 | E4: 200 | F4: 96.37 | G4: =E4*F4 -> 19274 | H4: 5 | I4: 108.17 | J4: =H4*I4 -> 540.85 | K4: =G4+J4 -> 19814.85 | L4: 0 | M4: =M3+K4-L4 -> 171524.87
A5: 2 | B5: 45718 | E5: 37.67 | F5: 96.37 | G5: =E5*F5 -> 3630.2579 | H5: =4+4+5 -> 13 | I5: 108.17 | J5: =H5*I5 -> 1406.21 | K5: =G5+J5 -> 5036.4679 | L5: 0 | M5: =M4+K5-L5 -> 176561.34
A6: 3 | B6: 45719 | E6: =200+49.72 -> 249.72 | F6: 96.37 | G6: =E6*F6 -> 24065.516 | H6: =5+5+5 -> 15 | I6: 108.17 | J6: =H6*I6 -> 1622.55 | K6: =G6+J6 -> 25688.066 | L6: 0 | M6: =M5+K6-L6 -> 202249.4
A7: 4 | B7: 45720 | E7: 30 | F7: 96.37 | G7: =E7*F7 -> 2891.1 | H7: 0 | I7: 108.17 | J7: =H7*I7 -> 0 | K7: =G7+J7 -> 2891.1 | L7: 0 | M7: =M6+K7-L7 -> 205140.5
A8: 5 | B8: 45721 | E8: =200+200+43.89 -> 443.89 | F8: 96.37 | G8: =E8*F8 -> 42777.679 | H8: =5+45.31 -> 50.31 | I8: 108.17 | J8: =H8*I8 -> 5442.0327 | K8: =G8+J8 -> 48219.712 | L8: 0 | M8: =M7+K8-L8 -> 253360.22
A9: 6 | B9: 45722 | E9: 200 | F9: 96.37 | G9: =E9*F9 -> 19274 | H9: 0 | I9: 108.17 | J9: =H9*I9 -> 0 | K9: =G9+J9 -> 19274 | L9: 0 | M9: =M8+K9-L9 -> 272634.22
A10: 7 | B10: 45723 | E10: =19.18+83.81+100+200 -> 402.99 | F10: 96.37 | G10: =E10*F10 -> 38836.146 | H10: =4+5+5 -> 14 | I10: 108.17 | J10: =H10*I10 -> 1514.38 | K10: =G10+J10 -> 40350.526 | L10: 0 | M10: =M9+K10-L10 -> 312984.74
A11: 8 | B11: 45724 | E11: 0 | F11: 96.37 | G11: =E11*F11 -> 0 | H11: 0 | I11: 108.17 | J11: =H11*I11 -> 0 | K11: =G11+J11 -> 0 | L11: 0 | M11: =M10+K11-L11 -> 312984.74
A12: 9 | B12: 45725 | E12: 0 | F12: 96.37 | G12: =E12*F12 -> 0 | H12: 9 | I12: 108.17 | J12: =H12*I12 -> 973.53 | K12: =G12+J12 -> 973.53 | L12: 0 | M12: =M11+K12-L12 -> 313958.27
A13: 10 | B13: 45726 | E13: =59.13+400+30.73 -> 489.86 | F13: 96.37 | G13: =E13*F13 -> 47207.808 | H13: 0 | I13: 108.17 | J13: =H13*I13 -> 0 | K13: =G13+J13 -> 47207.808 | L13: 360000 | M13: =M12+K13-L13 -> 1166.0808
A14: 11 | B14: 45727 | E14: =42.79+61.28 -> 104.07 | F14: 96.37 | G14: =E14*F14 -> 10029.226 | H14: =5+5 -> 10 | I14: 108.17 | J14: =H14*I14 -> 1081.7 | K14: =G14+J14 -> 11110.926 | L14: 0 | M14: =M13+K14-L14 -> 12277.007
A15: 12 | B15: 45728 | E15: 200 | F15: 96.37 | G15: =E15*F15 -> 19274 | H15: 3 | I15: 108.17 | J15: =H15*I15 -> 324.51 | K15: =G15+J15 -> 19598.51 | L15: 0 | M15: =M14+K15-L15 -> 31875.517
A16: 13 | B16: 45729 | E16: =100+67.66+41.08 -> 208.74 | F16: 96.37 | G16: =E16*F16 -> 20116.274 | H16: =5+5+5+4 -> 19 | I16: 108.17 | J16: =H16*I16 -> 2055.23 | K16: =G16+J16 -> 22171.504 | L16: 0 | M16: =M15+K16-L16 -> 54047.021
A17: 14 | B17: 45730 | G17: =E17*F17 -> 0 | H17: 6 | I17: 108.17 | J17: =H17*I17 -> 649.02 | K17: =G17+J17 -> 649.02 | M17: =M16+K17-L17 -> 54696.041
A18: 15 | B18: 45731 | G18: =E18*F18 -> 0 | H18: 0 | I18: 0 | J18: =H18*I18 -> 0 | K18: =G18+J18 -> 0 | L18: =+K18 -> 0 | M18: =M17+K18-L18 -> 54696.041
A19: 16 | B19: 45732 | G19: =E19*F19 -> 0 | H19: 4 | I19: 108.17 | J19: =H19*I19 -> 432.68 | K19: =G19+J19 -> 432.68 | M19: =M18+K19-L19 -> 55128.721
A20: 17 | B20: 45733 | G20: =E20*F20 -> 0 | H20: 5 | I20: 108.17 | J20: =H20*I20 -> 540.85 | K20: =G20+J20 -> 540.85 | M20: =M19+K20-L20 -> 55669.571
A21: 18 | B21: 45734 | E21: 160.75 | F21: 96.37 | G21: =E21*F21 -> 15491.478 | H21: 0 | I21: 0 | J21: =H21*I21 -> 0 | K21: =G21+J21 -> 15491.478 | L21: 0 | M21: =M20+K21-L21 -> 71161.048
A22: 19 | B22: 45735 | G22: =E22*F22 -> 0 | H22: 0 | I22: 0 | J22: =H22*I22 -> 0 | K22: =G22+J22 -> 0 | L22: =+K22 -> 0 | M22: =M21+K22-L22 -> 71161.048
A23: 20 | B23: 45736 | G23: =E23*F23 -> 0 | H23: 0 | I23: 0 | J23: =H23*I23 -> 0 | K23: =G23+J23 -> 0 | L23: =+K23 -> 0 | M23: =M22+K23-L23 -> 71161.048
A24: 21 | B24: 45737 | G24: =E24*F24 -> 0 | H24: 0 | I24: 0 | J24: =H24*I24 -> 0 | K24: =G24+J24 -> 0 | L24: =+K24 -> 0 | M24: =M23+K24-L24 -> 71161.048
A25: 22 | B25: 45738 | G25: =E25*F25 -> 0 | H25: 0 | I25: 0 | J25: =H25*I25 -> 0 | K25: =G25+J25 -> 0 | L25: =+K25 -> 0 | M25: =M24+K25-L25 -> 71161.048
A26: 23 | B26: 45739 | G26: =E26*F26 -> 0 | H26: 0 | I26: 0 | J26: =H26*I26 -> 0 | K26: =G26+J26 -> 0 | L26: =+K26 -> 0 | M26: 0
A27: 24 | B27: 45740 | G27: =E27*F27 -> 0 | H27: 0 | I27: 0 | J27: =H27*I27 -> 0 | K27: =G27+J27 -> 0 | L27: =+K27 -> 0 | M27: 0
A28: 25 | B28: 45741 | H28: 0 | I28: 0 | J28: =H28*I28 -> 0 | K28: =G28+J28 -> 0 | L28: =+K28 -> 0 | M28: 0
A29: 26 | B29: 45742 | G29: =E29*F29 -> 0 | H29: 0 | I29: 0 | J29: =H29*I29 -> 0 | K29: =G29+J29 -> 0 | L29: =+K29 -> 0 | M29: 0
A30: 27 | B30: 45743 | G30: =E30*F30 -> 0 | H30: 0 | I30: 0 | J30: =H30*I30 -> 0 | K30: =G30+J30 -> 0 | L30: =+K30 -> 0 | M30: 0
A31: 28 | B31: 45744 | G31: =E31*F31 -> 0 | H31: 0 | I31: 0 | J31: =H31*I31 -> 0 | K31: =G31+J31 -> 0 | L31: =+K31 -> 0 | M31: 0
A32: 29 | B32: 45745 | G32: =E32*F32 -> 0 | H32: 0 | I32: 0 | J32: =H32*I32 -> 0 | K32: =G32+J32 -> 0 | L32: =+K32 -> 0 | M32: 0
A33: 30 | B33: 45746 | G33: =E33*F33 -> 0 | H33: 0 | I33: 0 | J33: =H33*I33 -> 0 | K33: =G33+J33 -> 0 | L33: =+K33 -> 0 | M33: 0
A34: 31 | B34: 45747 | G34: =E34*F34 -> 0 | H34: 0 | I34: 0 | J34: =H34*I34 -> 0 | K34: =G34+J34 -> 0 | L34: =+K34 -> 0 | M34: 0
E35: =SUM(E4:E34) -> 2727.69 | G35: =SUM(G4:G34) -> 262867.49 | H35: =SUM(H4:H34) -> 153.31 | J35: =SUM(J4:J34) -> 16583.543 | K35: =SUM(K4:K34) -> 279451.03 | L35: =SUM(L4:L34) -> 360000

Sheet  Sangareddy-2
A1: Durga Bhavani F/S
A2: S.No | B2: Date | C2: GRN No | D2: Ind no/Bill No | E2: Diesel (Lts) | F2: Price | G2: Amount | H2: Petrol (Lts) | I2: Price | J2: Amount | K2: Total amount | L2: Amount paid | M2: As on Date | N2: Remarks
A3: Opening Balance | M3: 0
A4: 1 | B4: 45717 | G4: =E4*F4 -> 0 | H4: 0 | I4: 0 | J4: =H4*I4 -> 0 | K4: =G4+J4 -> 0 | L4: =+K4 -> 0 | M4: =M3+K4-L4 -> 0
A5: 2 | B5: 45718 | G5: =E5*F5 -> 0 | H5: 0 | I5: 0 | J5: =H5*I5 -> 0 | K5: =G5+J5 -> 0 | L5: =+K5 -> 0 | M5: =M4+K5-L5 -> 0
A6: 3 | B6: 45719 | E6: 47.79 | F6: 96.44 | G6: =E6*F6 -> 4608.8676 | H6: 0 | I6: 0 | J6: =H6*I6 -> 0 | K6: =G6+J6 -> 4608.8676 | M6: =M5+K6-L6 -> 4608.8676
