Workbook

Sheet  MIs
A2: S.No | B2: NAme | C2: Lacation | D2: Card Number | E2: Card Number | F2: Category | G2: 1st Jan | I2: 2nd Jan | J2: 3rd Jan | K2: 4th Jan | L2: 5th Jan | M2: 6th Jan | N2: 7th Jan | O2: 8th Jan | P2: 9th Jan | Q2: 10th Jan | R2: 11th Jan | S2: 12th Jan | T2: 13th Jan | U2: 14th Jan | V2: 15th Jan | W2: 16th Jan | X2: 17th Jan | Y2: 18th Jan | Z2: 19th Jan | AA2: 20th Jan | AB2: 21st Jan | AC2: 22nd Jan | AD2: 23rd Jan | AE2: 24th Jan | AF2: 25th Jan | AG2: 26th Jan | AH2: 27th Jan | AI2: 28th Jan | AJ2: 29th Jan | AK2: 30th Jan | AL2: 31st Jan | AM2: Total
F3: Diesel
A4: 1 | B4: Rambabu | C4: HO(Two Wheeler) | D4: FC3450563999 | E4: Diesel | F4: 0 | G4: 0 | H4: 0 | I4: 0 | J4: 0 | K4: 0 | L4: 0 | M4: 0 | N4: 0 | O4: 0 | P4: 0 | Q4: 0 | R4: 0 | S4: 0 | T4: 0 | U4: 0 | V4: 0 | W4: 0 | X4: 5.22 | Y4: 0 | Z4: 0 | AA4: 0 | AB4: 0 | AC4: 0 | AD4: 60 | AE4: 0 | AF4: 0 | AG4: 0 | AH4: 4.56 | AI4: 0 | AJ4: 0 | AK4: 0 | AL4: 0 | AM4: =SUM(F4:AL4) -> 69.78
E5: Petrol | F5: 0 | G5: 4.69 | H5: 0 | I5: 0 | J5: 0 | K5: 0 | L5: 0 | M5: 0 | N5: 3.91 | O5: 0 | P5: 6.98 | Q5: 0 | R5: 0 | S5: 0 | T5: 0 | U5: 0 | V5: 0 | W5: 0 | X5: 0 | Y5: 0 | Z5: 0 | AB5: 0 | AC5: 0 | AD5: 0 | AE5: 0 | AF5: 0 | AG5: 0 | AH5: 0 | AI5: 0 | AJ5: 0 | AK5: 0 | AL5: 0 | AM5: =SUM(F5:AL5) -> 15.58
A6: 2 | B6: Hanumanth Rao | C6: HO | D6: FC3450676131 | E6: Diesel | F6: 0 | G6: 0 | H6: 0 | I6: 0 | J6: 0 | K6: 0 | L6: 0 | M6: 0 | N6: 0 | O6: 0 | P6: 0 | Q6: 0 | R6: 0 | S6: 0 | T6: 0 | U6: 0 | V6: 0 | W6: 0 | X6: 0 | Y6: 0 | Z6: 0 | AA6: 0 | AB6: 0 | AC6: 0 | AD6: 0 | AE6: 0 | AF6: 0 | AG6: 0 | AH6: 0 | AI6: 0 | AJ6: 0 | AK6: 0 | AL6: 0 | AM6: =SUM(F6:AL6) -> 0
E7: Petrol | F7: 0 | G7: 0 | H7: 0 | I7: 0 | J7: 0 | K7: 0 | L7: 0 | M7: 0 | N7: 0 | O7: 0 | P7: 0 | Q7: 0 | R7: 0 | S7: 0 | T7: 0 | U7: 0 | V7: 0 | W7: 0 | X7: 0 | Y7: 0 | Z7: 0 | AB7: 0 | AC7: 0 | AD7: 0 | AE7: 0 | AF7: 0 | AG7: 0 | AH7: 0 | AI7: 0 | AJ7: 0 | AK7: 0 | AL7: 0 | AM7: =SUM(F7:AL7) -> 0
A8: 3 | B8: Radhakrishna | C8: HO | D8: FC8000207658 | E8: Diesel | F8: 0 | G8: 0 | H8: 0 | I8: 0 | J8: 33.44 | K8: 0 | L8: 0 | M8: 0 | N8: 0 | O8: 0 | P8: 0 | Q8: 0 | R8: 35.53 | S8: 0 | T8: 0 | U8: 0 | V8: 0 | W8: 0 | X8: 0 | Y8: 0 | Z8: 0 | AA8: 0 | AB8: 33.44 | AC8: 0 | AD8: 0 | AE8: 0 | AF8: 0 | AG8: 0 | AH8: 0 | AI8: 0 | AJ8: 0 | AK8: 0 | AL8: 0 | AM8: =SUM(F8:AL8) -> 102.41
E9: Petrol | F9: 0 | G9: 0 | H9: 0 | I9: 0 | J9: 0 | K9: 0 | L9: 0 | M9: 0 | N9: 0 | O9: 0 | P9: 0 | Q9: 0 | R9: 0 | S9: 0 | T9: 0 | U9: 0 | V9: 0 | W9: 0 | X9: 0 | Y9: 0 | Z9: 0 | AB9: 0 | AC9: 0 | AD9: 0 | AE9: 0 | AF9: 0 | AG9: 0 | AH9: 0 | AI9: 0 | AJ9: 0 | AK9: 0 | AL9: 0 | AM9: =SUM(F9:AL9) -> 0
A10: 4 | B10: VIjay | C10: HO | D10: FC3450698859 | E10: Diesel | F10: 0 | G10: 0 | H10: 0 | I10: 0 | J10: 0 | K10: 0 | L10: 0 | M10: 0 | N10: 0 | O10: 0 | P10: 49.22 | Q10: 0 | R10: 0 | S10: 0 | T10: 0 | U10: 54.57 | V10: 0 | W10: 0 | X10: 0 | Y10: 0 | Z10: 0 | AA10: 0 | AB10: 0 | AC10: 0 | AD10: 49.8 | AE10: 0 | AF10: 0 | AG10: 0 | AH10: 0 | AI10: 0 | AJ10: 0 | AK10: 0 | AL10: 0 | AM10: =SUM(F10:AL10) -> 153.59
E11: Petrol | F11: 0 | G11: 0 | H11: 0 | I11: 0 | J11: 0 | K11: 0 | L11: 0 | M11: 0 | N11: 0 | O11: 0 | P11: 0 | Q11: 0 | R11: 0 | S11: 0 | T11: 0 | U11: 0 | V11: 0 | W11: 0 | X11: 0 | Y11: 0 | Z11: 0 | AB11: 0 | AC11: 0 | AD11: 0 | AE11: 0 | AF11: 0 | AG11: 0 | AH11: 0 | AI11: 0 | AJ11: 0 | AK11: 0 | AL11: 0 | AM11: =SUM(F11:AL11) -> 0
A12: 5 | B12: Client | C12: Hiriyur | D12: FC3450698864 | E12: Diesel | F12: 0 | G12: 0 | H12: 0 | I12: 0 | J12: 0 | K12: 0 | L12: 0 | M12: 0 | N12: 86.29 | O12: 0 | P12: 0 | Q12: 0 | R12: 0 | S12: 0 | T12: 0 | U12: 0 | V12: 0 | W12: 0 | X12: 0 | Y12: 0 | Z12: 0 | AA12: 0 | AB12: 0 | AC12: 0 | AD12: 145.61 | AE12: 0 | AF12: 0 | AG12: 0 | AH12: 0 | AI12: 0 | AJ12: 0 | AK12: 0 | AL12: 0 | AM12: =SUM(F12:AL12) -> 231.9
E13: Petrol | F13: 0 | G13: 0 | H13: 0 | I13: 0 | J13: 0 | K13: 0 | L13: 0 | M13: 0 | N13: 0 | O13: 0 | P13: 0 | Q13: 0 | R13: 0 | S13: 0 | T13: 0 | U13: 0 | V13: 0 | W13: 0 | X13: 0 | Y13: 0 | Z13: 0 | AB13: 0 | AC13: 0 | AD13: 0 | AE13: 0 | AF13: 0 | AG13: 0 | AH13: 0 | AI13: 0 | AJ13: 0 | AK13: 0 | AL13: 0 | AM13: =SUM(F13:AL13) -> 0
A14: 6 | B14: Client | C14: Hosadurga | D14: FC3450698865 | E14: Diesel | F14: 0 | G14: 0 | H14: 0 | I14: 0 | J14: 0 | K14: 0 | L14: 40 | M14: 40 | N14: 0 | O14: 36 | P14: 35 | Q14: 0 | R14: 0 | S14: 0 | T14: 0 | U14: 0 | V14: 0 | W14: 45 | X14: 45 | Y14: 43.53 | Z14: 40 | AA14: 43 | AB14: 0 | AC14: 40 | AD14: 0 | AE14: 40 | AF14: 0 | AG14: 0 | AH14: 0 | AI14: 0 | AJ14: 0 | AK14: 0 | AL14: 0 | AM14: =SUM(F14:AL14) -> 447.53
E15: Petrol | F15: 0 | G15: 0 | H15: 0 | I15: 0 | J15: 0 | K15: 0 | L15: 0 | M15: 0 | N15: 0 | O15: 0 | P15: 0 | Q15: 0 | R15: 0 | S15: 0 | T15: 0 | U15: 0 | V15: 0 | W15: 0 | X15: 0 | Y15: 0 | Z15: 0 | AB15: 0 | AC15: 0 | AD15: 0 | AE15: 0 | AF15: 0 | AG15: 0 | AH15: 0 | AI15: 0 | AJ15: 0 | AK15: 0 | AL15: 0 | AM15: =SUM(F15:AL15) -> 0
G18: Diesel Price

Sheet June-2026
A1: S.no | B1: Site Name | C1: Bunk Name | D1: Diesel(Liters) | E1: Diesel Amount | F1: Petrol(Liters) | G1: Petrol Amount | H1: Total Amount | I1: Opening Blance | J1: Amount Paid | K1: Closing Balances
A2: 1 | B2: Khammam-1 | C2: Divya laxmi ganapathi | D2: =+'Khammam-1'!E38 -> 66765.22 | E2: =+'Khammam-1'!G38 -> 6930229.8 | F2: =+'Khammam-1'!H38 -> 450 | G2: =+'Khammam-1'!J38 -> 52060.5 | H2: =E2+G2 -> 6982290.3 | I2: =+'Khammam-1'!K3 -> 2654498.9 | J2: =+'Khammam-1'!L38 -> 8021364 | K2: =H2+I2-J2 -> 1615425.2
A3: 2 | B3: Khammam-2 | C3: Jayasai union bunk | D3: =+'Khammam-2'!E38 -> 127541.88 | E3: =+'Khammam-2'!G38 -> 13241398 | F3: =+'Khammam-2'!H38 -> 450 | G3: =+'Khammam-2'!J38 -> 52074 | H3: =E3+G3 -> 13293472 | I3: =+'Khammam-2'!K3 -> 8720097.6 | J3: =+'Khammam-2'!L38 -> 12423326 | K3: =H3+I3-J3 -> 9590244
A4: 3 | B4: Khammam-3 | C4: JSASFuel Genie India Pvt.Ltd | D4: =+'Khammam-3'!E35 -> 0 | E4: =+'Khammam-3'!G35 -> 0 | F4: =+'Khammam-3'!H35 -> 0 | G4: =+'Khammam-3'!J35 -> 0 | H4: =E4+G4 -> 0 | I4: =+'Khammam-3'!M3 -> 1572600 | J4: =+'Khammam-3'!L35 -> 500000 | K4: =H4+I4-J4 -> 1072600
A5: 4 | B5: Khammam-Cash&Carry | C5: NA | D5: =+' Khammam&Cash'!E46 -> 8670.5217 | E5: =+' Khammam&Cash'!G46 -> 900000.15 | F5: =+' Khammam&Cash'!H46 -> 0 | G5: =+' Khammam&Cash'!J46 -> 0 | H5: =E5+G5 -> 900000.15 | I5: =+' Khammam&Cash'!M3 -> 0 | J5: =+' Khammam&Cash'!L46 -> 900000.15 | K5: =H5+I5-J5 -> 0
A6: 5 | B6: Jadcherla-1 | C6: JSASFuel Genie India Pvt.Ltd | D6: =+'Jadcherla-3'!E35 -> 0 | E6: =+'Jadcherla-3'!G35 -> 0 | F6: =+'Jadcherla-3'!H35 -> 0 | G6: =+'Jadcherla-3'!J35 -> 0 | H6: =E6+G6 -> 0 | I6: =+'Jadcherla-3'!M3 -> 1313281.7 | J6: =+'Jadcherla-3'!L35 -> 1313281 | K6: =H6+I6-J6 -> 0.7
A7: 6 | B7: Jadcherla-2 | C7: Shree Poornima F/S | D7: =+'Jadcherla-4'!E35 -> 2500 | E7: =+'Jadcherla-4'!G35 -> 261050 | F7: =+'Jadcherla-4'!H35 -> 80 | G7: =+'Jadcherla-4'!J35 -> 9306.4 | H7: =E7+G7 -> 270356.4 | I7: =+'Jadcherla-4'!M3 -> 15788.08 | J7: =+'Jadcherla-4'!L35 -> 279281 | K7: =H7+I7-J7 -> 6863.48
A8: 7 | B8: Jadcherla-3 | C8: Sai Baba Filling Station | D8: =+' Jadcherla'!E35 -> 0 | E8: =+' Jadcherla'!G35 -> 0 | F8: =+' Jadcherla'!H35 -> 0 | G8: =+' Jadcherla'!J35 -> 0 | H8: =E8+G8 -> 0 | I8: =+' Jadcherla'!M3 -> 171115.11 | J8: =+' Jadcherla'!L35 -> 171115.11 | K8: =H8+I8-J8 -> 0.00040000002
A9: 8 | B9: Sangareddy-2 | C9: Durga Bhavani F/S | D9: =+' Sangareddy-2'!E35 -> 3018.9 | E9: =+' Sangareddy-2'!G35 -> 315656.18 | F9: =+' Sangareddy-2'!H35 -> 109 | G9: =+' Sangareddy-2'!J35 -> 12702.86 | H9: =E9+G9 -> 328359.04 | I9: =+' Sangareddy-2'!M3 -> 108316.17 | J9: =+' Sangareddy-2'!L35 -> 308316 | K9: =H9+I9-J9 -> 128359.22 | M9: VASUDEO NIVRUTTI
A10: 9 | B10: Sangareddy-3 | C10: Shiva Parvathi Filling Station | D10: =+' Sangareddy-3'!E36 -> 13566 | E10: =+' Sangareddy-3'!G36 -> 1415612.1 | F10: =+' Sangareddy-3'!H36 -> 49 | G10: =+' Sangareddy-3'!J36 -> 5882.07 | H10: =E10+G10 -> 1421494.2 | I10: =+' Sangareddy-3'!M3 -> 986125.39 | J10: =+' Sangareddy-3'!L36 -> 2200000 | K10: =H10+I10-J10 -> 207619.56
A11: 10 | B11: NarayanaKhed | C11: Sai Shiva Filling Station | D11: =Narayankhed!E35 -> 2085.65 | E11: =+Narayankhed!G35 -> 225041.64 | F11: =+Narayankhed!H35 -> 0 | G11: =+Narayankhed!J35 -> 0 | H11: =E11+G11 -> 225041.64 | I11: =+Narayankhed!M3 -> 0 | J11: =+Narayankhed!L35 -> 225041.64 | K11: =H11+I11-J11 -> 0
A12: 11 | B12: Dindi | C12: Akarapu Balakistamma Fillling | D12: =+Dindi!E35 -> 0 | E12: =+Dindi!G35 -> 0 | F12: =+Dindi!H35 -> 0 | G12: =+Dindi!J35 -> 0 | H12: =E12+G12 -> 0 | I12: =+Dindi!M3 -> 0 | J12: =+Dindi!L35 -> 0 | K12: =H12+I12-J12 -> 0 | M12: =PROPER(M9) -> Vasudeo Nivrutti
A13: 12 | B13: Madanapalli | C13: NA | D13: =+'Madana palli'!E37 -> 0 | E13: =+'Madana palli'!G37 -> 0 | F13: =+'Madana palli'!H37 -> 18.84 | G13: =+'Madana palli'!J37 -> 2099.6078 | H13: =E13+G13 -> 2099.6078 | I13: =+'Madana palli'!M3 -> 0 | J13: =+'Madana palli'!L37 -> 2099.6078 | K13: =H13+I13-J13 -> 0
A14: 13 | B14: Kakinada | C14: NA | D14: =+Amalapuram!E246 -> 8824.401 | E14: =+Amalapuram!G246 -> 926569.75 | F14: =+Amalapuram!H246 -> 371.17 | G14: =+Amalapuram!J246 -> 43828.7 | H14: =E14+G14 -> 970398.45 | I14: =+Amalapuram!M3 -> 0 | J14: =+Amalapuram!L246 -> 970398.45 | K14: =H14+I14-J14 -> 0
A15: 14 | B15: YG Gudda-2 | C15: Pankaja HP Fuel Center | D15: =+'YG Gudda'!E39 -> 9000 | E15: =+'YG Gudda'!G39 -> 892260 | F15: =+'YG Gudda'!H39 -> 280 | G15: =+'YG Gudda'!J39 -> 31147.2 | H15: =E15+G15 -> 923407.2 | I15: =+'YG Gudda'!M3 -> 189118.96 | J15: =+'YG Gudda'!L39 -> 829742 | K15: =H15+I15-J15 -> 282784.16
A16: 15 | B16: YG Gudda-2 | C16: One stop | D16: =+' YG Gudda-2'!E39 -> 4000 | E16: =+' YG Gudda-2'!G39 -> 396080 | F16: =+' YG Gudda-2'!H39 -> 105 | G16: =+' YG Gudda-2'!J39 -> 11667.6 | H16: =E16+G16 -> 407747.6 | I16: =+' YG Gudda-2'!M3 -> 0 | J16: =+' YG Gudda-2'!L39 -> 200000 | K16: =H16+I16-J16 -> 207747.6
A17: 16 | B17: Hosadurga-2 | C17: Shree Veeraprathap Fuel | D17: =+'Hosadurga -2'!E35 -> 3000 | E17: =+'Hosadurga -2'!G35 -> 298410 | F17: =+'Hosadurga -2'!H35 -> 140 | G17: =+'Hosadurga -2'!J35 -> 15600.2 | H17: =+'Hosadurga -2'!K35 -> 314010.2 | I17: =+'Hosadurga -2'!K3 -> 148201.19 | J17: =+'Hosadurga -2'!L35 -> 347927 | K17: =H17+I17-J17 -> 114284.39
A18: 17 | B18: Malebennuru(KUWSDB) | C18: Sri Ramanjuneya Service Station | D18: =+'Malebenur(KUWSDB)'!E37 -> 5400 | E18: =+'Malebenur(KUWSDB)'!G37 -> 539028 | F18: =+'Malebenur(KUWSDB)'!H37 -> 220 | G18: =+'Malebenur(KUWSDB)'!J37 -> 24580.6 | H18: =E18+G18 -> 563608.6 | I18: =+'Malebenur(KUWSDB)'!K3 -> 95753.51 | J18: =+'Malebenur(KUWSDB)'!L37 -> 527000 | K18: =H18+I18-J18 -> 132362.11
A19: 18 | B19: kadur | C19: Vishal Service Station | D19: =+Kadur!E35 -> 3000 | E19: =+Kadur!G35 -> 308880 | F19: =+Kadur!H35 -> 140 | G19: =+Kadur!J35 -> 16422 | H19: =E19+G19 -> 325302 | I19: =+Kadur!K3 -> 159888.9 | J19: =+Kadur!L35 -> 159889 | K19: =H19+I19-J19 -> 325301.9
A20: 19 | B20: Hiriyur(VJNL) | C20: Sri Balaji Agencies | D20: =+'Hiriyur(VJNL)'!E35 -> 3500 | E20: =+'Hiriyur(VJNL)'!G35 -> 349720 | F20: =+'Hiriyur(VJNL)'!H35 -> 175 | G20: =+'Hiriyur(VJNL)'!J35 -> 19572 | H20: =E20+G20 -> 369292 | I20: =+'Hiriyur(VJNL)'!K3 -> 182925.7 | J20: =+'Hiriyur(VJNL)'!L35 -> 332855 | K20: =H20+I20-J20 -> 219362.7
A21: 20 | B21: Chellakere(KUWSDB) | C21: Shivaganga Service Station | D21: =+'Chellakere -1'!E38 -> 4400.71 | E21: =+'Chellakere -1'!G38 -> 439538.91 | F21: =+'Chellakere -1'!H38 -> 245 | G21: =+'Chellakere -1'!J38 -> 27388.55 | H21: =E21+G21 -> 466927.46 | I21: =+'Chellakere -1'!K3 -> 71615.087 | J21: =+'Chellakere -1'!L38 -> 422486 | K21: =H21+I21-J21 -> 116056.55
A22: 21 | B22: Chellakere(KUWSDB)-09 | C22: Shivaganga Service Station | D22: =+' Chellakere-PKG-9'!E36 -> 942.57 | E22: =+' Chellakere-PKG-9'!G36 -> 94143.892 | F22: =+' Chellakere-PKG-9'!H36 -> 81.01 | G22: =+' Chellakere-PKG-9'!J36 -> 9056.0479 | H22: =E22+G22 -> 103199.94 | I22: =+' Chellakere-PKG-9'!M3 -> 0 | J22: =+' Chellakere-PKG-9'!L36 -> 103199.94 | K22: =H22+I22-J22 -> 0
A23: 22 | B23: Molakalmuru | C23: Sri Lakshmi Venkateshwara Filling Station | D23: =+Molakamuru!E35 -> 1040 | E23: =+Molakamuru!G35 -> 103864.8 | F23: =+Molakamuru!H35 -> 127 | G23: =+Molakamuru!J35 -> 14196.06 | H23: =E23+G23 -> 118060.86 | I23: =+Molakamuru!K3 -> 62820 | J23: =+Molakamuru!L35 -> 172000 | K23: =H23+I23-J23 -> 8880.86
A24: 23 | B24: Chennagiri | C24: NA | D24: =+' Chennagiri'!E35 -> 1920 | E24: =+' Chennagiri'!G35 -> 191424 | F24: =+' Chennagiri'!H35 -> 44 | G24: =+' Chennagiri'!J35 -> 4918.32 | H24: =E24+G24 -> 196342.32 | I24: =+' Chennagiri'!K3 -> 0 | J24: =+' Chennagiri'!L35 -> 196342.32 | K24: =H24+I24-J24 -> 0
A25: 24 | B25: Khanapur(PKG-3) | C25: V.V.Varde | D25: =+Khanapur!E35 -> 1216.09 | E25: =+Khanapur!G35 -> 120083.29 | F25: =+Khanapur!H35 -> 110 | G25: =+Khanapur!J35 -> 12193.8 | H25: =E25+G25 -> 132277.09 | I25: =+Khanapur!M3 -> 59025.654 | J25: =+Khanapur!L35 -> 86235 | K25: =H25+I25-J25 -> 105067.75
A26: 25 | B26: Munavalli(PKG-3) | C26: Shre Shiva Petroleum | D26: =+'Munavali-2'!E40 -> 1500 | E26: =+'Munavali-2'!G40 -> 149025 | F26: =+'Munavali-2'!H40 -> 0 | G26: =+'Munavali-2'!J40 -> 0 | H26: =E26+G26 -> 149025 | I26: =+'Munavali-2'!M3 -> 445001.62 | J26: =+'Munavali-2'!L40 -> 594027 | K26: =H26+I26-J26 -> -0.37954
A27: 26 | B27: Munavalli(PKG-3) | C27: Daneshwari Petroleum | D27: =+' Munavali'!E39 -> 14021.29 | E27: =+' Munavali'!G39 -> 1389930.5 | F27: =+' Munavali'!H39 -> 280 | G27: =+' Munavali'!J39 -> 31138.8 | H27: =E27+G27 -> 1421069.3 | I27: =+' Munavali'!M3 -> 277716.15 | J27: =+' Munavali'!L39 -> 1220350 | K27: =H27+I27-J27 -> 478435.42
A28: 27 | B28: Borgaon(PKG-3) | C28: Aadisagar Petrolium | D28: =+Borgaon!E35 -> 0 | E28: =+Borgaon!G35 -> 0 | F28: =+Borgaon!H35 -> 0 | G28: =+Borgaon!J35 -> 0 | H28: =E28+G28 -> 0 | I28: =+Borgaon!K3 -> 276126.39 | J28: =+Borgaon!L35 -> 275918 | K28: =H28+I28-J28 -> 208.3907
A29: 28 | B29: Ugar,Kudichi(PKG-3) | C29: Shiri Bhrhmanath Petrolium | D29: =+'Ugar,Khagwad,Kudichi'!E37 -> 9414.92 | E29: =+'Ugar,Khagwad,Kudichi'!G37 -> 939044.12 | F29: =+'Ugar,Khagwad,Kudichi'!H37 -> 125 | G29: =+'Ugar,Khagwad,Kudichi'!J37 -> 13982.5 | H29: =E29+G29 -> 953026.62 | I29: =+'Ugar,Khagwad,Kudichi'!M3 -> 476633.25 | J29: =+'Ugar,Khagwad,Kudichi'!L37 -> 900000 | K29: =H29+I29-J29 -> 529659.87
A30: 29 | B30: Shedbal | C30: Varad Petroluem | D30: =+shedbal!E35 -> 8870 | E30: =+shedbal!G35 -> 884605.1 | F30: =+shedbal!H35 -> 379 | G30: =+shedbal!J35 -> 42391.15 | H30: =E30+G30 -> 926996.25 | I30: =+shedbal!M3 -> 167956.75 | J30: =+shedbal!L35 -> 798000 | K30: =H30+I30-J30 -> 296953
A31: 30 | B31: Kabbur(PKG-3) | C31: Shri Jai Hanuman Petrolium | D31: =+Kabbur!E35 -> 105 | E31: =+Kabbur!G35 -> 10438.05 | F31: =+Kabbur!H35 -> 15.34 | G31: =+Kabbur!J35 -> 1710.5634 | H31: =E31+G31 -> 12148.613 | I31: 0 | J31: =+Kabbur!L35 -> 12148.613 | K31: =H31+I31-J31 -> 0
A32: 31 | B32: Kumta (PKG-1) | C32: V.M.Mirjankar (Kumta) Bharat | D32: =+kumta!E41 -> 1307.37 | E32: =+kumta!G41 -> 130439 | F32: =+kumta!H41 -> 86.37 | G32: =+kumta!J41 -> 9671.7126 | H32: =E32+G32 -> 140110.71 | I32: =kumta!M3 -> 71321.75 | J32: =+kumta!L41 -> 196373.96 | K32: =H32+I32-J32 -> 15058.507
A33: 32 | B33: Jalgaon-1 | C33: Jai Bajarang Sarvo Senter Bodwad | D33: =+' Jalgaon-1'!E55 -> 3000 | E33: =+' Jalgaon-1'!G55 -> 298530 | F33: =+' Jalgaon-1'!H55 -> 0 | G33: =+' Jalgaon-1'!J55 -> 0 | H33: =E33+G33 -> 298530 | I33: =+' Jalgaon-1'!K3 -> 0 | J33: =+' Jalgaon-1'!L55 -> 298530 | K33: =H33+I33-J33 -> 0
A34: 33 | B34: Jalgaon-2 | C34: Nayara | D34: =+'Jalgoan-2'!E56 -> 27863.47 | E34: ='Jalgoan-2'!G56 -> 2856284.3 | F34: =+'Jalgoan-2'!H56 -> 180 | G34: =+'Jalgoan-2'!J56 -> 21272.4 | H34: =E34+G34 -> 2877556.7 | I34: =+'Jalgoan-2'!M3 -> 2169469.7 | J34: =+'Jalgoan-2'!L56 -> 2500000 | K34: =H34+I34-J34 -> 2547026.4
A35: 34 | B35: Jalgaon-3 | C35: Vasudeo Nivrutti | D35: =+' Jalgaon-3'!E20 -> 7187.16 | E35: =+' Jalgaon-3'!G20 -> 714906.81 | F35: =+' Jalgaon-3'!H20 -> 0 | G35: =+' Jalgaon-3'!J20 -> 0 | H35: =E35+G35 -> 714906.81 | I35: =+' Jalgaon-3'!M3 -> 494713 | J35: =+' Jalgaon-3'!L20 -> 1209619.8 | K35: =H35+I35-J35 -> 0
A36: 35 | B36: Jalgaon-4 | C36: Raksha Auto Fuels | D36: =+'Jalgaon-4'!E19 -> 0 | E36: =+'Jalgaon-4'!G19 -> 0 | F36: =+'Jalgaon-4'!H19 -> 0 | G36: =+'Jalgaon-4'!J19 -> 0 | H36: =E36+G36 -> 0 | I36: =+'Jalgaon-4'!M3 -> 0 | J36: =+'Jalgaon-4'!L19 -> 0 | K36: =H36+I36-J36 -> 0
A37: 36 | B37: Jalgaon-5 C | C37: NA | D37: =+' Jalgaon-5 c'!E39 -> 10.11 | E37: =+' Jalgaon-5 c'!G39 -> 1000.3845 | F37: =+' Jalgaon-5 c'!H39 -> 0 | G37: =+' Jalgaon-5 c'!J39 -> 0 | H37: =E37+G37 -> 1000.3845 | I37: =+' Jalgaon-5 c'!M3 -> 0 | J37: =+' Jalgaon-5 c'!L39 -> 1000.3845 | K37: =H37+I37-J37 -> 0
A38: 37 | B38: MKBD | C38: Shree Sai Samarth Petroleum | D38: =+MKBD!E42 -> 9454.92 | E38: =+MKBD!G42 -> 938428.08 | F38: =+MKBD!H42 -> 100 | G38: =+MKBD!J42 -> 11227 | H38: =E38+G38 -> 949655.08 | I38: =+MKBD!K3 -> 3890914.7 | J38: =+MKBD!L42 -> 4208999 | K38: =H38+I38-J38 -> 631570.81
A39: 38 | B39: Haveri | C39: M/s Magavi City Fuels | D39: =' Haveri-2'!E42 -> 6428.27 | E39: =' Haveri-2'!G42 -> 638327.21 | F39: =' Haveri-2'!H42 -> 127.02 | G39: =' Haveri-2'!J42 -> 14246.372 | H39: =E39+G39 -> 652573.58 | I39: =' Haveri-2'!M3 -> 206223.97 | J39: =+' Haveri-2'!L42 -> 726000.1 | K39: =H39+I39-J39 -> 132797.45
A40: 39 | B40: Guttal-2 | C40: Himagiri Petroleum | D40: =+' Guttal-2'!E35 -> 4080 | E40: =+' Guttal-2'!G35 -> 406368 | F40: =+' Guttal-2'!H35 -> 177 | G40: =+' Guttal-2'!J35 -> 19772.67 | H40: =E40+G40 -> 426140.67 | I40: =+' Guttal-2'!M3 -> 105890.82 | J40: =+' Guttal-2'!L35 -> 440000 | K40: =H40+I40-J40 -> 92031.494
...

Sheet HO(DG)
A1: JSASFuel Genie India Pvt.Ltd
A2: S.No | B2: Date | C2: GRN No | D2: Ind No/Bill No | E2: Diesel (Lts) | F2: Price | G2: Amount | H2: Petrol (Lts) | I2: Price | J2: Amount | K2: Total amount | L2: Amount paid | M2: As on date | N2: Remarks
A3: Opening Balance | K3: 99797.75 | M3: 99797.75 | O3: 2623243.4
A4: 1 | B4: 46174 | G4: =E4*F4 -> 0 | H4: 0 | I4: 0 | J4: =H4*I4 -> 0 | K4: =G4+J4 -> 0 | L4: 0 | M4: =M3+K4-L4 -> 99797.75
A5: 2 | B5: 46175 | G5: =E5*F5 -> 0 | K5: =G5+J5 -> 0 | M5: =M4+K5-L5 -> 99797.75 | R5: HO | S5: 188521.22
A6: 3 | B6: 46176 | E6: 35 | F6: 103.76 | G6: =E6*F6 -> 3631.6 | K6: =G6+J6 -> 3631.6 | L6: =H6+K6 -> 3631.6 | M6: =M5+K6-L6 -> 99797.75 | R6: Khammam | S6: 8227903
A7: 4 | B7: 46177 | E7: 200 | F7: 103.76 | G7: =E7*F7 -> 20752 | K7: =G7+J7 -> 20752 | M7: =M6+K7-L7 -> 120549.75 | R7: Jadcherla | S7: 2453209.4
A8: 5 | B8: 46178 | G8: =E8*F8 -> 0 | K8: =G8+J8 -> 0 | M8: =M7+K8-L8 -> 120549.75 | P8: 5679 | R8: Total | S8: =SUM(S5:S7) -> 10869634
A9: 6 | B9: 46179 | G9: =E9*F9 -> 0 | K9: =G9+J9 -> 0 | M9: =M8+K9-L9 -> 120549.75 | S9: 10869632
A10: 7 | B10: 46180 | G10: =E10*F10 -> 0 | K10: =G10+J10 -> 0 | L10: =H10+K10 -> 0 | M10: =M9+K10-L10 -> 120549.75 | N10: HPCL | S10: =S9-S8 -> -1.6105
B11: 46181 | G11: =E11*F11 -> 0 | K11: =G11+J11 -> 0 | L11: =H11+K11 -> 0 | M11: =M10+K11-L11 -> 120549.75 | N11: HPCL
A12: 8 | B12: 46182 | E12: 100 | F12: 103.76 | G12: =E12*F12 -> 10376 | K12: =G12+J12 -> 10376 | L12: =H12+K12 -> 10376 | M12: =M11+K12-L12 -> 120549.75 | N12: HPCL
A13: 9 | B13: 46183 | E13: 70 | F13: 103.76 | G13: =E13*F13 -> 7263.2 | K13: =G13+J13 -> 7263.2 | L13: =H13+K13 -> 7263.2 | M13: =M12+K13-L13 -> 120549.75 | Q13: 54.98
A14: 10 | B14: 46184 | E14: 70 | F14: 103.76 | G14: =E14*F14 -> 7263.2 | K14: =G14+J14 -> 7263.2 | L14: =H14+K14 -> 7263.2 | M14: =M13+K14-L14 -> 120549.75 | Q14: 54.98
A15: 11 | B15: 46185 | E15: 200 | F15: 104.2 | G15: =E15*F15 -> 20840 | K15: =G15+J15 -> 20840 | M15: =M14+K15-L15 -> 141389.75
A16: 12 | B16: 46186 | G16: =E16*F16 -> 0 | K16: =G16+J16 -> 0 | L16: =H16+K16 -> 0 | M16: =M15+K16-L16 -> 141389.75 | R16: 19166
A17: 13 | B17: 46187 | G17: =E17*F17 -> 0 | K17: =G17+J17 -> 0 | L17: =H17+K17 -> 0 | M17: =M16+K17-L17 -> 141389.75 | R17: 19645
A18: 14 | B18: 46188 | G18: =E18*F18 -> 0 | K18: =G18+J18 -> 0 | L18: =H18+K18 -> 0 | M18: =M17+K18-L18 -> 141389.75 | P18: 1905988 | Q18: =P18-M18 -> 1764598.2 | R18: 21083
A19: 15 | B19: 46189 | G19: =E19*F19 -> 0 | K19: =G19+J19 -> 0 | L19: =H19+K19 -> 0 | M19: =M18+K19-L19 -> 141389.75 | R19: 19140 | S19: 220637
A20: 16 | B20: 46190 | E20: 70 | F20: 103.76 | G20: =E20*F20 -> 7263.2 | K20: =G20+J20 -> 7263.2 | L20: =H20+K20 -> 7263.2 | M20: =M19+K20-L20 -> 141389.75 | N20: HPCL | R20: =SUM(R16:R19) -> 79034 | S20: =S19+R20 -> 299671
A21: 17 | B21: 46191 | E21: 35 | F21: 103.76 | G21: =E21*F21 -> 3631.6 | K21: =G21+J21 -> 3631.6 | L21: =H21+K21 -> 3631.6 | M21: =M20+K21-L21 -> 141389.75 | N21: HPCL
A22: 18 | B22: 46192 | E22: 70 | F22: 103.76 | G22: =E22*F22 -> 7263.2 | K22: =G22+J22 -> 7263.2 | L22: =H22+K22 -> 7263.2 | M22: =M21+K22-L22 -> 141389.75
A23: 19 | B23: 46193 | E23: 35 | F23: 103.76 | G23: =E23*F23 -> 3631.6 | K23: =G23+J23 -> 3631.6 | L23: =H23+K23 -> 3631.6 | M23: =M22+K23-L23 -> 141389.75
A24: 20 | B24: 46194 | G24: =E24*F24 -> 0 | K24: =G24+J24 -> 0 | L24: =H24+K24 -> 0 | M24: =M23+K24-L24 -> 141389.75
A25: 21 | B25: 46195 | E25: 70 | F25: 103.76 | G25: =E25*F25 -> 7263.2 | K25: =G25+J25 -> 7263.2 | L25: =H25+K25 -> 7263.2 | M25: =M24+K25-L25 -> 141389.75
A26: 22 | B26: 46196 | E26: 50 | F26: 103.76 | G26: =E26*F26 -> 5188 | K26: =G26+J26 -> 5188 | L26: =H26+K26 -> 5188 | M26: =M25+K26-L26 -> 141389.75
A27: 23 | B27: 46197 | E27: 200 | F27: 103.83 | G27: =E27*F27 -> 20766 | K27: =G27+J27 -> 20766 | L27: 0 | M27: =M26+K27-L27 -> 162155.75
A28: 24 | B28: 46198 | G28: =E28*F28 -> 0 | K28: =G28+J28 -> 0 | L28: =H28+K28 -> 0 | M28: =M27+K28-L28 -> 162155.75
A29: 25 | B29: 46199 | G29: =E29*F29 -> 0 | K29: =G29+J29 -> 0 | L29: =H29+K29 -> 0 | M29: =M28+K29-L29 -> 162155.75
A30: 26 | B30: 46200 | G30: =E30*F30 -> 0 | K30: =G30+J30 -> 0 | L30: =H30+K30 -> 0 | M30: =M29+K30-L30 -> 162155.75
A31: 27 | B31: 46201 | G31: =E31*F31 -> 0 | K31: =G31+J31 -> 0 | L31: =H31+K31 -> 0 | M31: =M30+K31-L31 -> 162155.75
A32: 28 | B32: 46202 | E32: 200 | F32: 103.83 | G32: =E32*F32 -> 20766 | K32: =G32+J32 -> 20766 | L32: 0 | M32: =M31+K32-L32 -> 182921.75
B33: 46202 | E33: 35 | F33: 103.76 | G33: =E33*F33 -> 3631.6 | K33: =G33+J33 -> 3631.6 | L33: 3631.6 | M33: =M32+K33-L33 -> 182921.75
A34: 29 | B34: 46203 | G34: =E34*F34 -> 0 | K34: =G34+J34 -> 0 | L34: =H34+K34 -> 0 | M34: =M33+K34-L34 -> 182921.75
G35: =E35*F35 -> 0 | K35: =G35+J35 -> 0 | M35: =M34+K35-L35 -> 182921.75
A36: 30 | K36: =G36+J36 -> 0 | M36: =M35+K36-L36 -> 182921.75
A37: 31 | M37: =M36+K37-L37 -> 182921.75
A38: 32 | M38: =M37+K38-L38 -> 182921.75
A39: 33 | M39: =M38+K39-L39 -> 182921.75
A40: 34 | M40: =M39+K40-L40 -> 182921.75
...

Sheet Khammam-1
A1: Divya laxmi ganapathi
A2: S.No | B2: Date | C2: GRN No | D2: Ind No/Bill No | E2: Diesel (Lts) | F2: Price | G2: Amount | H2: Petrol (Lts) | I2: Price | J2: Amount | K2: Total amount | L2: Amount paid | M2: As 0n Date | N2: Remarks
A3: Opening Balance | K3: 2654498.9 | M3: 2654498.9
A4: 1 | B4: 46174 | E4: 5500 | F4: 103.8 | G4: =E4*F4 -> 570900 | K4: =G4+J4 -> 570900 | L4: 200000 | M4: =M3+K4-L4 -> 3025398.9
A5: 2 | B5: 46175 | G5: =E5*F5 -> 0 | K5: =G5+J5 -> 0 | L5: 100000 | M5: =M4+K5-L5 -> 2925398.9
A6: 3 | B6: 46176 | E6: 2700 | F6: 103.8 | G6: =E6*F6 -> 280260 | J6: =H6*I6 -> 0 | K6: =G6+J6 -> 280260 | M6: =M5+K6-L6 -> 3205658.9
A7: 4 | B7: 46177 | E7: 2800 | F7: 103.8 | G7: =E7*F7 -> 290640 | J7: =H7*I7 -> 0 | K7: =G7+J7 -> 290640 | M7: =M6+K7-L7 -> 3496298.9
A8: 5 | B8: 46178 | G8: =E8*F8 -> 0 | J8: =H8*I8 -> 0 | K8: =G8+J8 -> 0 | M8: =M7+K8-L8 -> 3496298.9
A9: 6 | B9: 46179 | G9: =E9*F9 -> 0 | J9: =H9*I9 -> 0 | K9: =G9+J9 -> 0 | M9: =M8+K9-L9 -> 3496298.9
A10: 7 | B10: 46180 | E10: 2650 | F10: 103.8 | G10: =E10*F10 -> 275070 | J10: =H10*I10 -> 0 | K10: =G10+J10 -> 275070 | M10: =M9+K10-L10 -> 3771368.9
A11: 8 | B11: 46181 | E11: 2800 | F11: 103.8 | G11: =E11*F11 -> 290640 | J11: =H11*I11 -> 0 | K11: =G11+J11 -> 290640 | L11: 3771364 | M11: =M10+K11-L11 -> 290644.86
A12: 9 | B12: 46182 | E12: 2700 | F12: 103.8 | G12: =E12*F12 -> 280260 | J12: =H12*I12 -> 0 | K12: =G12+J12 -> 280260 | M12: =M11+K12-L12 -> 570904.86
A13: 10 | B13: 46183 | E13: 5700 | F13: 103.8 | G13: =E13*F13 -> 591660 | H13: 60 | I13: 115.69 | J13: =H13*I13 -> 6941.4 | K13: =G13+J13 -> 598601.4 | M13: =M12+K13-L13 -> 1169506.3
A14: 11 | B14: 46184 | E14: 2800 | F14: 103.8 | G14: =E14*F14 -> 290640 | J14: =H14*I14 -> 0 | K14: =G14+J14 -> 290640 | M14: =M13+K14-L14 -> 1460146.3
A15: 12 | B15: 46185 | E15: 2000 | F15: 103.8 | G15: =E15*F15 -> 207600 | J15: =H15*I15 -> 0 | K15: =G15+J15 -> 207600 | M15: =M14+K15-L15 -> 1667746.3
A16: 13 | B16: 46186 | E16: 2800 | F16: 103.8 | G16: =E16*F16 -> 290640 | J16: =H16*I16 -> 0 | K16: =G16+J16 -> 290640 | M16: =M15+K16-L16 -> 1958386.3
A17: 14 | B17: 46187 | E17: 2700 | F17: 103.8 | G17: =E17*F17 -> 280260 | J17: =H17*I17 -> 0 | K17: =G17+J17 -> 280260 | M17: =M16+K17-L17 -> 2238646.3
A18: 15 | B18: 46188 | E18: 2000 | F18: 103.8 | G18: =E18*F18 -> 207600 | J18: =H18*I18 -> 0 | K18: =G18+J18 -> 207600 | M18: =M17+K18-L18 -> 2446246.3
A19: 16 | B19: 46189 | E19: 3715.22 | F19: 103.8 | G19: =E19*F19 -> 385639.84 | H19: 60 | I19: 115.69 | J19: =H19*I19 -> 6941.4 | K19: =G19+J19 -> 392581.24 | M19: =M18+K19-L19 -> 2838827.5
A20: 17 | B20: 46190 | E20: 1500 | F20: 103.8 | G20: =E20*F20 -> 155700 | J20: =H20*I20 -> 0 | K20: =G20+J20 -> 155700 | M20: =M19+K20-L20 -> 2994527.5
A21: 18 | B21: 46191 | G21: =E21*F21 -> 0 | J21: =H21*I21 -> 0 | K21: =G21+J21 -> 0 | M21: =M20+K21-L21 -> 2994527.5
A22: 19 | B22: 46192 | G22: =E22*F22 -> 0 | J22: =H22*I22 -> 0 | K22: =G22+J22 -> 0 | M22: =M21+K22-L22 -> 2994527.5
A23: 20 | B23: 46193 | E23: 2000 | F23: 103.8 | G23: =E23*F23 -> 207600 | H23: 35 | I23: 115.69 | J23: =H23*I23 -> 4049.15 | K23: =G23+J23 -> 211649.15 | M23: =M22+K23-L23 -> 3206176.6
A24: 21 | B24: 46194 | G24: =E24*F24 -> 0 | J24: =H24*I24 -> 0 | K24: =G24+J24 -> 0 | M24: =M23+K24-L24 -> 3206176.6
A25: 22 | B25: 46195 | E25: 2500 | F25: 103.8 | G25: =E25*F25 -> 259500 | H25: 40 | I25: 115.69 | J25: =H25*I25 -> 4627.6 | K25: =G25+J25 -> 264127.6 | M25: =M24+K25-L25 -> 3470304.2
A26: 23 | B26: 46196 | G26: =E26*F26 -> 0 | J26: =H26*I26 -> 0 | K26: =G26+J26 -> 0 | M26: =M25+K26-L26 -> 3470304.2
A27: 24 | B27: 46197 | E27: 5500 | F27: 103.8 | G27: =E27*F27 -> 570900 | H27: 60 | I27: 115.69 | J27: =H27*I27 -> 6941.4 | K27: =G27+J27 -> 577841.4 | L27: 550000 | M27: =M26+K27-L27 -> 3498145.6
A28: 25 | B28: 46198 | E28: 4200 | F28: 103.8 | G28: =E28*F28 -> 435960 | H28: 55 | I28: 115.69 | J28: =H28*I28 -> 6362.95 | K28: =G28+J28 -> 442322.95 | L28: 400000 | M28: =M27+K28-L28 -> 3540468.6
A29: 26 | B29: 46199 | E29: 2800 | F29: 103.8 | G29: =E29*F29 -> 290640 | H29: 60 | I29: 115.69 | J29: =H29*I29 -> 6941.4 | K29: =G29+J29 -> 297581.4 | L29: 400000 | M29: =M28+K29-L29 -> 3438050
A30: 27 | B30: 46200 | G30: =E30*F30 -> 0 | J30: =H30*I30 -> 0 | K30: =G30+J30 -> 0 | M30: =M29+K30-L30 -> 3438050
A31: 28 | B31: 46201 | E31: 0 | F31: 103.8 | G31: =E31*F31 -> 0 | H31: 0 | I31: 115.69 | J31: =H31*I31 -> 0 | K31: =G31+J31 -> 0 | L31: 2000000 | M31: =M30+K31-L31 -> 1438050
A32: 29 | B32: 46202 | E32: 2700 | F32: 103.8 | G32: =E32*F32 -> 280260 | H32: 40 | I32: 115.69 | J32: =H32*I32 -> 4627.6 | K32: =G32+J32 -> 284887.6 | L32: 600000 | M32: =M31+K32-L32 -> 1122937.6
A33: 30 | B33: 46203 | E33: 4700 | F33: 103.8 | G33: =E33*F33 -> 487860 | H33: 40 | I33: 115.69 | J33: =H33*I33 -> 4627.6 | K33: =G33+J33 -> 492487.6 | M33: =M32+K33-L33 -> 1615425.2
A34: 31 | G34: =E34*F34 -> 0 | K34: =G34+J34 -> 0 | M34: =M33+K34-L34 -> 1615425.2
A35: 32 | G35: =E35*F35 -> 0 | J35: =H35*I35 -> 0 | K35: =G35+J35 -> 0 | M35: =M34+K35-L35 -> 1615425.2
A36: 33 | G36: =E36*F36 -> 0 | J36: =H36*I36 -> 0 | K36: =G36+J36 -> 0 | L36: 0
A37: 34 | G37: =E37*F37 -> 0 | J37: =H37*I37 -> 0 | K37: =G37+J37 -> 0
E38: =SUM(E3:E37) -> 66765.22 | G38: =SUM(G3:G37) -> 6930229.8 | H38: =SUM(H3:H37) -> 450 | J38: =SUM(J3:J37) -> 52060.5 | K38: =SUM(K4:K37) -> 6982290.3 | L38: =SUM(L3:L37) -> 8021364
N45: 4766880.2
N46: 6982290.3

Sheet Khammam-2
A1: Jayasai union bunk
A2: S.No | B2: Date | C2: GRN No | D2: Ind No/Bill No | E2: Diesel (Lts) | F2: Price | G2: Amount | H2: Petrol (Lts) | I2: Price | J2: Amount | K2: Total amount | L2: Amount paid | M2: As 0n Date | N2: Remarks
A3: Opening Balance | K3: 8720097.6 | M3: 8720097.6
A4: 1 | B4: 46174 | E4: 1581.71 | F4: 103.82 | G4: =E4*F4 -> 164213.13 | H4: 60 | I4: 115.72 | J4: =H4*I4 -> 6943.2 | K4: =G4+J4 -> 171156.33 | M4: =M3+K4-L4 -> 8891253.9 | O4: =O3+M4-N4 -> 8891253.9
A5: 2 | B5: 46175 | E5: 1977.66 | F5: 103.82 | G5: =E5*F5 -> 205320.66 | J5: =H5*I5 -> 0 | K5: =G5+J5 -> 205320.66 | M5: =M4+K5-L5 -> 9096574.6
A6: 3 | B6: 46176 | E6: 2724.32 | F6: 103.82 | G6: =E6*F6 -> 282838.9 | J6: =H6*I6 -> 0 | K6: =G6+J6 -> 282838.9 | M6: =M5+K6-L6 -> 9379413.5
A7: 4 | B7: 46177 | E7: 1852.27 | F7: 103.82 | G7: =E7*F7 -> 192302.67 | H7: 100 | I7: 115.72 | J7: =H7*I7 -> 11572 | K7: =G7+J7 -> 203874.67 | M7: =M6+K7-L7 -> 9583288.1
A8: 5 | B8: 46178 | E8: 877.79 | F8: 103.82 | G8: =E8*F8 -> 91132.158 | J8: =H8*I8 -> 0 | K8: =G8+J8 -> 91132.158 | M8: =M7+K8-L8 -> 9674420.3 | O8: 12802499
A9: 6 | B9: 46179 | E9: 2397.47 | F9: 103.82 | G9: =E9*F9 -> 248905.34 | J9: =H9*I9 -> 0 | K9: =G9+J9 -> 248905.34 | M9: =M8+K9-L9 -> 9923325.6
A10: 7 | B10: 46180 | G10: =E10*F10 -> 0 | J10: =H10*I10 -> 0 | K10: =G10+J10 -> 0 | M10: =M9+K10-L10 -> 9923325.6
A11: 8 | B11: 46181 | E11: 233 | F11: 103.82 | G11: =E11*F11 -> 24190.06 | H11: 75 | I11: 115.72 | J11: =H11*I11 -> 8679 | K11: =G11+J11 -> 32869.06 | L11: 5000000 | M11: =M10+K11-L11 -> 4956194.7 | N11: BT
A12: 9 | B12: 46181 | G12: =E12*F12 -> 0 | J12: =H12*I12 -> 0 | K12: =G12+J12 -> 0 | L12: 6086287 | M12: =M11+K12-L12 -> -1130092.3 | N12: HPCL | O12: 6086287
B13: 46181 | L13: =-(1162961.45) -> -1162961.4 | M13: =M12+K13-L13 -> 32869.139 | N13: Dgm Personal cash
A14: 10 | B14: 46182 | E14: 1155.44 | F14: 103.82 | G14: =E14*F14 -> 119957.78 | J14: =H14*I14 -> 0 | K14: =G14+J14 -> 119957.78 | M14: =M13+K14-L14 -> 152826.92
A15: 11 | B15: 46183 | E15: 5565.26 | F15: 103.82 | G15: =E15*F15 -> 577785.29 | J15: =H15*I15 -> 0 | K15: =G15+J15 -> 577785.29 | M15: =M14+K15-L15 -> 730612.21 | S15: 5000000
A16: 12 | B16: 46184 | E16: 5661.33 | F16: 103.82 | G16: =E16*F16 -> 587759.28 | J16: =H16*I16 -> 0 | K16: =G16+J16 -> 587759.28 | M16: =M15+K16-L16 -> 1318371.5 | Q16: 6086287 | S16: 6086287
A17: 13 | B17: 46185 | E17: 6900 | F17: 103.82 | G17: =E17*F17 -> 716358 | H17: 60 | I17: 115.72 | J17: =H17*I17 -> 6943.2 | K17: =G17+J17 -> 723301.2 | M17: =M16+K17-L17 -> 2041672.7 | S17: =SUM(S15:S16) -> 11086287
A18: 14 | B18: 46186 | E18: 6450 | F18: 103.82 | G18: =E18*F18 -> 669639 | J18: =H18*I18 -> 0 | K18: =G18+J18 -> 669639 | M18: =M17+K18-L18 -> 2711311.7 | S18: 1162961.4
A19: 15 | B19: 46187 | E19: 2500 | F19: 103.82 | G19: =E19*F19 -> 259550 | J19: =H19*I19 -> 0 | K19: =G19+J19 -> 259550 | M19: =M18+K19-L19 -> 2970861.7 | S19: =S17-S18 -> 9923325.6
A20: 16 | B20: 46188 | E20: 3015 | F20: 103.82 | G20: =E20*F20 -> 313017.3 | H20: 75 | I20: 115.72 | J20: =H20*I20 -> 8679 | K20: =G20+J20 -> 321696.3 | M20: =M19+K20-L20 -> 3292558 | S20: 32869.06
A21: 17 | B21: 46189 | E21: 6197.2 | F21: 103.82 | G21: =E21*F21 -> 643393.3 | J21: =H21*I21 -> 0 | K21: =G21+J21 -> 643393.3 | M21: =M20+K21-L21 -> 3935951.3 | S21: =S19+S20 -> 9956194.6
A22: 18 | B22: 46190 | E22: 5103.43 | F22: 103.82 | G22: =E22*F22 -> 529838.1 | J22: =H22*I22 -> 0 | K22: =G22+J22 -> 529838.1 | M22: =M21+K22-L22 -> 4465789.4
A23: 19 | B23: 46191 | E23: 6081.9 | F23: 103.82 | G23: =E23*F23 -> 631422.86 | J23: =H23*I23 -> 0 | K23: =G23+J23 -> 631422.86 | M23: =M22+K23-L23 -> 5097212.3
A24: 20 | B24: 46192 | E24: 6041.95 | F24: 103.82 | G24: =E24*F24 -> 627275.25 | H24: 80 | I24: 115.72 | J24: =H24*I24 -> 9257.6 | K24: =G24+J24 -> 636532.85 | M24: =M23+K24-L24 -> 5733745.1
A25: 21 | B25: 46193 | E25: 6219.57 | F25: 103.82 | G25: =E25*F25 -> 645715.76 | J25: =H25*I25 -> 0 | K25: =G25+J25 -> 645715.76 | M25: =M24+K25-L25 -> 6379460.9
A26: 22 | B26: 46194 | E26: 6250.34 | F26: 103.82 | G26: =E26*F26 -> 648910.3 | J26: =H26*I26 -> 0 | K26: =G26+J26 -> 648910.3 | M26: =M25+K26-L26 -> 7028371.2
A27: 23 | B27: 46195 | E27: 5297.67 | F27: 103.82 | G27: =E27*F27 -> 550004.1 | J27: =H27*I27 -> 0 | K27: =G27+J27 -> 550004.1 | M27: =M26+K27-L27 -> 7578375.3
A28: 24 | B28: 46196 | E28: 5138.12 | F28: 103.82 | G28: =E28*F28 -> 533439.62 | J28: =H28*I28 -> 0 | K28: =G28+J28 -> 533439.62 | M28: =M27+K28-L28 -> 8111814.9
A29: 25 | B29: 46197 | E29: 5011.16 | F29: 103.82 | G29: =E29*F29 -> 520258.63 | J29: =H29*I29 -> 0 | K29: =G29+J29 -> 520258.63 | M29: =M28+K29-L29 -> 8632073.5
A30: 26 | B30: 46198 | E30: 3329.48 | F30: 103.82 | G30: =E30*F30 -> 345666.61 | J30: =H30*I30 -> 0 | K30: =G30+J30 -> 345666.61 | M30: =M29+K30-L30 -> 8977740.1
A31: 27 | B31: 46199 | E31: 6511.21 | F31: 103.82 | G31: =E31*F31 -> 675993.82 | J31: =H31*I31 -> 0 | K31: =G31+J31 -> 675993.82 | M31: =M30+K31-L31 -> 9653733.9
A32: 28 | B32: 46200 | E32: 5957.19 | F32: 103.82 | G32: =E32*F32 -> 618475.47 | J32: =H32*I32 -> 0 | K32: =G32+J32 -> 618475.47 | M32: =M31+K32-L32 -> 10272209
A33: 29 | B33: 46201 | E33: 5284.55 | F33: 103.82 | G33: =E33*F33 -> 548641.98 | J33: =H33*I33 -> 0 | K33: =G33+J33 -> 548641.98 | M33: =M32+K33-L33 -> 10820851
A34: 30 | B34: 46202 | E34: 6019.64 | F34: 103.82 | G34: =E34*F34 -> 624959.02 | J34: =H34*I34 -> 0 | K34: =G34+J34 -> 624959.02 | L34: 2500000 | M34: =M33+K34-L34 -> 8945810.4
A35: 31 | B35: 46203 | E35: 6207.22 | F35: 103.82 | G35: =E35*F35 -> 644433.58 | J35: =H35*I35 -> 0 | K35: =G35+J35 -> 644433.58 | M35: =M34+K35-L35 -> 9590244
A36: 32 | B36: 46204 | G36: =E36*F36 -> 0 | J36: =H36*I36 -> 0 | K36: =G36+J36 -> 0 | M36: =M35+K36-L36 -> 9590244
E38: =SUM(E4:E36) -> 127541.88 | G38: =SUM(G4:G36) -> 13241398 | H38: =SUM(H4:H36) -> 450 | J38: =SUM(J4:J36) -> 52074 | K38: =SUM(K4:K36) -> 13293472 | L38: =SUM(L4:L36) -> 12423326

Sheet Khammam-3
A1: JSASFuel Genie India Pvt.Ltd
A2: S.No | B2: Date | C2: GRN No | D2: Ind No/Bill No | E2: Diesel (Lts) | F2: Price | G2: Amount | H2: Petrol (Lts) | I2: Price | J2: Amount | K2: Total amount | L2: Amount paid | M2: As 0n Date | N2: Remarks
A3: Opening Balance | K3: 1572600 | M3: 1572600
A4: 1 | B4: 46174 | G4: =E4*F4 -> 0 | J4: =H4*I4 -> 0 | K4: =G4+J4 -> 0 | M4: =M3+K4-L4 -> 1572600
A5: 2 | B5: 46175 | G5: =E5*F5 -> 0 | J5: =H5*I5 -> 0 | K5: =G5+J5 -> 0 | M5: =M4+K5-L5 -> 1572600
A6: 3 | B6: 46176 | G6: =E6*F6 -> 0 | J6: =H6*I6 -> 0 | K6: =G6+J6 -> 0 | M6: =M5+K6-L6 -> 1572600
A7: 4 | B7: 46177 | G7: =E7*F7 -> 0 | J7: =H7*I7 -> 0 | K7: =G7+J7 -> 0 | M7: =M6+K7-L7 -> 1572600
A8: 5 | B8: 46178 | G8: =E8*F8 -> 0 | J8: =H8*I8 -> 0 | K8: =G8+J8 -> 0 | M8: =M7+K8-L8 -> 1572600
A9: 6 | B9: 46179 | G9: =E9*F9 -> 0 | J9: =H9*I9 -> 0 | K9: =G9+J9 -> 0 | M9: =M8+K9-L9 -> 1572600
A10: 7 | B10: 46180 | G10: =E10*F10 -> 0 | J10: =H10*I10 -> 0 | K10: =G10+J10 -> 0 | M10: =M9+K10-L10 -> 1572600
A11: 8 | B11: 46181 | G11: =E11*F11 -> 0 | J11: =H11*I11 -> 0 | K11: =G11+J11 -> 0 | M11: =M10+K11-L11 -> 1572600
A12: 9 | B12: 46182 | G12: =E12*F12 -> 0 | J12: =H12*I12 -> 0 | K12: =G12+J12 -> 0 | M12: =M11+K12-L12 -> 1572600
A13: 10 | B13: 46183 | G13: =E13*F13 -> 0 | J13: =H13*I13 -> 0 | K13: =G13+J13 -> 0 | M13: =M12+K13-L13 -> 1572600
A14: 11 | B14: 46184 | G14: =E14*F14 -> 0 | J14: =H14*I14 -> 0 | K14: =G14+J14 -> 0 | M14: =M13+K14-L14 -> 1572600
A15: 12 | B15: 46185 | G15: =E15*F15 -> 0 | J15: =H15*I15 -> 0 | K15: =G15+J15 -> 0 | M15: =M14+K15-L15 -> 1572600
... A28: 25 | B28: 46198 | G28: =E28*F28 -> 0 | J28: =H28*I28 -> 0 | K28: =G28+J28 -> 0 | M28: =M27+K28-L28 -> 1572600
A29: 26 | B29: 46199 | G29: =E29*F29 -> 0 | J29: =H29*I29 -> 0 | K29: =G29+J29 -> 0 | L29: 500000 | M29: =M28+K29-L29 -> 1072600
A30: 27 | B30: 46200 | G30: =E30*F30 -> 0 | J30: =H30*I30 -> 0 | K30: =G30+J30 -> 0 | M30: =M29+K30-L30 -> 1072600
A31: 28 | B31: 46201 | G31: =E31*F31 -> 0 | J31: =H31*I31 -> 0 | K31: =G31+J31 -> 0 | M31: =M30+K31-L31 -> 1072600
A32: 29 | B32: 46202 | G32: =E32*F32 -> 0 | J32: =H32*I32 -> 0 | K32: =G32+J32 -> 0 | M32: =M31+K32-L32 -> 1072600
A33: 30 | B33: 46203 | G33: =E33*F33 -> 0 | J33: =H33*I33 -> 0 | K33: =G33+J33 -> 0 | M33: =M32+K33-L33 -> 1072600
A34: 31 | G34: =E34*F34 -> 0 | J34: =H34*I34 -> 0 | K34: =G34+J34 -> 0 | M34: =M33+K34-L34 -> 1072600
E35: =SUM(E4:E34) -> 0 | G35: =SUM(G4:G34) -> 0 | H35: =SUM(H4:H34) -> 0 | J35: =SUM(J4:J34) -> 0 | K35: =SUM(K4:K34) -> 0 | L35: =SUM(L4:L34) -> 500000

Sheet  Khammam&Cash
A1: Cash &Carry
A2: S.No | B2: Date | D2: Ind No/Bill No | E2: Diesel (Lts) | F2: Price | G2: Amount | H2: Petrol (Lts) | I2: Price | J2: Amount | K2: Total amount | L2: Amount paid | M2: As 0n Date | N2: Remarks
A3: Opening Balance | K3: 0 | M3: 0
A4: 1 | B4: 16.06.2025 | C4: Stambhadri Fuel Park HPCL | E4: 2890.1739 | F4: 103.8 | G4: =E4*F4 -> 300000.05 | K4: =G4+J4 -> 300000.05 | L4: =H4+K4 -> 300000.05 | M4: =M3+K4-L4 -> 0
A5: 2 | B5: 18.06.2025 | C5: Stambhadri Fuel Park HPCL | E5: 2890.1739 | F5: 103.8 | G5: =E5*F5 -> 300000.05 | J5: =H5*I5 -> 0 | K5: =G5+J5 -> 300000.05 | L5: =H5+K5 -> 300000.05 | M5: =M4+K5-L5 -> 0
A6: 3 | B6: 20.06.2025 | C6: Stambhadri Fuel Park HPCL | E6: 2890.1739 | F6: 103.8 | G6: =E6*F6 -> 300000.05 | J6: =H6*I6 -> 0 | K6: =G6+J6 -> 300000.05 | L6: =H6+K6 -> 300000.05 | M6: =M5+K6-L6 -> 0
A7: 4 | G7: =E7*F7 -> 0 | J7: =H7*I7 -> 0 | K7: =G7+J7 -> 0 | L7: =H7+K7 -> 0 | M7: =M6+K7-L7 -> 0
A8: 5 | G8: =E8*F8 -> 0 | J8: =H8*I8 -> 0 | K8: =G8+J8 -> 0 | L8: =H8+K8 -> 0 | M8: =M7+K8-L8 -> 0
A9: 6 | G9: =E9*F9 -> 0 | J9: =H9*I9 -> 0 | K9: =G9+J9 -> 0 | L9: =H9+K9 -> 0 | M9: =M8+K9-L9 -> 0
A10: 7 | G10: =E10*F10 -> 0 | J10: =H10*I10 -> 0 | K10: =G10+J10 -> 0 | L10: =H10+K10 -> 0 | M10: =M9+K10-L10 -> 0
A11: 8 | G11: =E11*F11 -> 0 | J11: =H11*I11 -> 0 | K11: =G11+J11 -> 0 | L11: =H11+K11 -> 0 | M11: =M10+K11-L11 -> 0
A12: 9 | G12: =E12*F12 -> 0 | J12: =H12*I12 -> 0 | K12: =G12+J12 -> 0 | L12: =H12+K12 -> 0 | M12: =M11+K12-L12 -> 0
A13: 10 | G13: =E13*F13 -> 0 | J13: =H13*I13 -> 0 | K13: =G13+J13 -> 0 | L13: =H13+K13 -> 0 | M13: =M12+K13-L13 -> 0
A14: 11 | G14: =E14*F14 -> 0 | J14: =H14*I14 -> 0 | K14: =G14+J14 -> 0 | L14: =H14+K14 -> 0 | M14: =M13+K14-L14 -> 0
A15: 12 | G15: =E15*F15 -> 0 | J15: =H15*I15 -> 0 | K15: =G15+J15 -> 0 | L15: =H15+K15 -> 0 | M15: =M14+K15-L15 -> 0
A16: 13 | G16: =E16*F16 -> 0 | J16: =H16*I16 -> 0 | K16: =G16+J16 -> 0 | L16: =H16+K16 -> 0 | M16: =M15+K16-L16 -> 0
A17: 14 | G17: =E17*F17 -> 0 | J17: =H17*I17 -> 0 | K17: =G17+J17 -> 0 | L17: =H17+K17 -> 0 | M17: =M16+K17-L17 -> 0
A18: 15 | G18: =E18*F18 -> 0 | J18: =H18*I18 -> 0 | K18: =G18+J18 -> 0 | L18: =H18+K18 -> 0 | M18: =M17+K18-L18 -> 0
... A22: 19 | G22: =E22*F22 -> 0 | J22: =H22*I22 -> 0 | K22: =G22+J22 -> 0 | L22: =H22+K22 -> 0 | M22: =M21+K22-L22 -> 0
A23: 20 | G23: =E23*F23 -> 0 | J23: =H23*I23 -> 0 | K23: =G23+J23 -> 0 | L23: 0 | M23: =M22+K23-L23 -> 0
A24: 21 | G24: =E24*F24 -> 0 | J24: =H24*I24 -> 0 | K24: =G24+J24 -> 0 | L24: =H24+K24 -> 0 | M24: =M23+K24-L24 -> 0
A25: 22 | G25: =E25*F25 -> 0 | J25: =H25*I25 -> 0 | K25: =G25+J25 -> 0 | L25: =H25+K25 -> 0 | M25: =M24+K25-L25 -> 0
A26: 23 | G26: =E26*F26 -> 0 | J26: =H26*I26 -> 0 | K26: =G26+J26 -> 0 | L26: =H26+K26 -> 0 | M26: =M25+K26-L26 -> 0
A27: 24 | G27: =E27*F27 -> 0 | K27: =G27+J27 -> 0 | L27: =H27+K27 -> 0 | M27: =M26+K27-L27 -> 0
A28: 25 | G28: =E28*F28 -> 0 | J28: =H28*I28 -> 0 | K28: =G28+J28 -> 0 | L28: =H28+K28 -> 0 | M28: =M26+K28-L28 -> 0
A29: 26 | G29: =E29*F29 -> 0 | J29: =H29*I29 -> 0 | K29: =G29+J29 -> 0 | L29: =H29+K29 -> 0 | M29: =M28+K29-L29 -> 0
A30: 27 | G30: =E30*F30 -> 0 | J30: =H30*I30 -> 0 | K30: =G30+J30 -> 0 | L30: =H30+K30 -> 0 | M30: =M29+K30-L30 -> 0
A31: 28 | G31: =E31*F31 -> 0 | J31: =H31*I31 -> 0 | K31: =G31+J31 -> 0 | L31: =H31+K31 -> 0 | M31: =M30+K31-L31 -> 0
A32: 29 | G32: =E32*F32 -> 0 | J32: =H32*I32 -> 0 | K32: =G32+J32 -> 0 | L32: =H32+K32 -> 0 | M32: =M31+K32-L32 -> 0
A33: 30 | G33: =E33*F33 -> 0 | J33: =H33*I33 -> 0 | K33: =G33+J33 -> 0 | L33: =H33+K33 -> 0 | M33: =M32+K33-L33 -> 0
A34: 31 | G34: =E34*F34 -> 0 | J34: =H34*I34 -> 0 | K34: =G34+J34 -> 0 | L34: =H34+K34 -> 0 | M34: =M33+K34-L34 -> 0
A35: 32 | G35: =E35*F35 -> 0 | K35: =G35+J35 -> 0 | L35: =H35+K35 -> 0 | M35: =M34+K35-L35 -> 0
A36: 33 | G36: =E36*F36 -> 0 | J36: =H36*I36 -> 0 | K36: =G36+J36 -> 0 | L36: =H36+K36 -> 0 | M36: =M35+K36-L36 -> 0
A37: 34 | G37: =E37*F37 -> 0 | J37: =H37*I37 -> 0 | K37: =G37+J37 -> 0 | L37: =H37+K37 -> 0 | M37: =M36+K37-L37 -> 0
G38: =E38*F38 -> 0 | K38: =G38+J38 -> 0 | L38: =H38+K38 -> 0 | M38: =M37+K38-L38 -> 0
G39: =E39*F39 -> 0 | K39: =G39+J39 -> 0 | L39: =H39+K39 -> 0 | M39: =M38+K39-L39 -> 0
G40: =E40*F40 -> 0 | K40: =G40+J40 -> 0 | L40: =H40+K40 -> 0 | M40: =M39+K40-L40 -> 0
M41: =M40+K41-L41 -> 0
A45: 35 | G45: =E45*F45 -> 0 | J45: =H45*I45 -> 0 | K45: =G45+J45 -> 0
E46: =SUM(E3:E45) -> 8670.5217 | G46: =SUM(G3:G45) -> 900000.15 | H46: =SUM(H3:H45) -> 0 | J46: =SUM(J3:J45) -> 0 | K46: =SUM(K4:K45) -> 900000.15 | L46: =SUM(L3:L45) -> 900000.15

Sheet Jadcherla-3
A1: JSASFuel Genie India Pvt.Ltd
A2: S.No | B2: Date | C2: GRN No | D2: Ind no/Bill No | E2: Diesel (Lts) | F2: Price | G2: Amount | H2: Petrol (Lts) | I2: Price | J2: Amount | K2: Total amount | L2: Amount paid | M2: As on Date | N2: Remarks
A3: Opening Balance | M3: 1313281.7
A4: 1 | B4: 46174 | G4: =E4*F4 -> 0 | J4: =H4*I4 -> 0 | K4: =G4+J4 -> 0 | L4: 0 | M4: =+M3+K4-L4 -> 1313281.7
A5: 2 | B5: 46175 | G5: =E5*F5 -> 0 | J5: =H5*I5 -> 0 | K5: =G5+J5 -> 0 | L5: 0 | M5: =+M4+K5-L5 -> 1313281.7
A6: 3 | B6: 46176 | G6: =E6*F6 -> 0 | J6: =H6*I6 -> 0 | K6: =G6+J6 -> 0 | L6: 0 | M6: =+M5+K6-L6 -> 1313281.7 | O6: 8032614 | P6: 2453209.4 | Q6: =SUM(O6:P6) -> 10485823
A7: 4 | B7: 46177 | G7: =E7*F7 -> 0 | J7: =H7*I7 -> 0 | K7: =G7+J7 -> 0 | L7: 0 | M7: =+M6+K7-L7 -> 1313281.7
A8: 5 | B8: 46178 | G8: =E8*F8 -> 0 | J8: =H8*I8 -> 0 | K8: =G8+J8 -> 0 | L8: 0 | M8: =+M7+K8-L8 -> 1313281.7
A9: 6 | B9: 46179 | G9: =E9*F9 -> 0 | J9: =H9*I9 -> 0 | K9: =G9+J9 -> 0 | L9: 0 | M9: =+M8+K9-L9 -> 1313281.7
A10: 7 | B10: 46180 | G10: =E10*F10 -> 0 | J10: =H10*I10 -> 0 | K10: =G10+J10 -> 0 | L10: 0 | M10: =+M9+K10-L10 -> 1313281.7 | R10: 700
A11: 8 | B11: 46181 | G11: =E11*F11 -> 0 | J11: =H11*I11 -> 0 | K11: =G11+J11 -> 0 | L11: 0 | M11: =+M10+K11-L11 -> 1313281.7 | S11: 5000
A12: 9 | B12: 46182 | G12: =E12*F12 -> 0 | J12: =H12*I12 -> 0 | K12: =G12+J12 -> 0 | L12: 1313281 | M12: =+M11+K12-L12 -> 0.7 | S12: 1500
A13: 10 | B13: 46183 | G13: =E13*F13 -> 0 | J13: =H13*I13 -> 0 | K13: =G13+J13 -> 0 | L13: 0 | M13: =+M12+K13-L13 -> 0.7 | S13: 500
A14: 11 | B14: 46184 | G14: =E14*F14 -> 0 | J14: =H14*I14 -> 0 | K14: =G14+J14 -> 0 | L14: 0 | M14: =+M13+K14-L14 -> 0.7
A15: 12 | B15: 46185 | G15: =E15*F15 -> 0 | J15: =H15*I15 -> 0 | K15: =G15+J15 -> 0 | L15: 0 | M15: =+M14+K15-L15 -> 0.7
A16: 13 | B16: 46186 | G16: =E16*F16 -> 0 | J16: =H16*I16 -> 0 | K16: =G16+J16 -> 0 | L16: 0 | M16: =+M15+K16-L16 -> 0.7
A17: 14 | B17: 46187 | G17: =E17*F17 -> 0 | J17: =H17*I17 -> 0 | K17: =G17+J17 -> 0 | L17: 0 | M17: =+M16+K17-L17 -> 0.7
A18: 15 | B18: 46188 | G18: =E18*F18 -> 0 | J18: =H18*I18 -> 0 | K18: =G18+J18 -> 0 | L18: 0 | M18: =+M17+K18-L18 -> 0.7
A19: 16 | B19: 46189 | G19: =E19*F19 -> 0 | J19: =H19*I19 -> 0 | K19: =G19+J19 -> 0 | L19: 0 | M19: =+M18+K19-L19 -> 0.7
A20: 17 | B20: 46190 | G20: =E20*F20 -> 0 | J20: =H20*I20 -> 0 | K20: =G20+J20 -> 0 | L20: 0 | M20: =+M19+K20-L20 -> 0.7
A21: 18 | B21: 46191 | J21: =H21*I21 -> 0 | K21: =G21+J21 -> 0 | L21: 0 | M21: =+M20+K21-L21 -> 0.7
A22: 19 | B22: 46192 | J22: =H22*I22 -> 0 | K22: =G22+J22 -> 0 | L22: 0 | M22: =+M21+K22-L22 -> 0.7
A23: 20 | B23: 46193 | J23: =H23*I23 -> 0 | K23: =G23+J23 -> 0 | L23: 0 | M23: =+M22+K23-L23 -> 0.7
A24: 21 | B24: 46194 | J24: =H24*I24 -> 0 | K24: =G24+J24 -> 0 | L24: 0 | M24: =+M23+K24-L24 -> 0.7
A25: 22 | B25: 46195 | G25: =E25*F25 -> 0 | J25: =H25*I25 -> 0 | K25: =G25+J25 -> 0 | L25: 0 | M25: =+M24+K25-L25 -> 0.7
A26: 23 | B26: 46196 | G26: =E26*F26 -> 0 | J26: =H26*I26 -> 0 | K26: =G26+J26 -> 0 | L26: 0 | M26: =+M25+K26-L26 -> 0.7
A27: 24 | B27: 46197 | G27: =E27*F27 -> 0 | J27: =H27*I27 -> 0 | K27: =G27+J27 -> 0 | L27: 0 | M27: =+M26+K27-L27 -> 0.7
A28: 25 | B28: 46198 | G28: =E28*F28 -> 0 | J28: =H28*I28 -> 0 | K28: =G28+J28 -> 0 | L28: 0 | M28: =+M27+K28-L28 -> 0.7
A29: 26 | B29: 46199 | G29: =E29*F29 -> 0 | J29: =H29*I29 -> 0 | K29: =G29+J29 -> 0 | L29: 0 | M29: =+M28+K29-L29 -> 0.7
A30: 27 | B30: 46200 | G30: =E30*F30 -> 0 | J30: =H30*I30 -> 0 | K30: =G30+J30 -> 0 | L30: 0 | M30: =+M29+K30-L30 -> 0.7
A31: 28 | B31: 46201 | G31: =E31*F31 -> 0 | J31: =H31*I31 -> 0 | K31: =G31+J31 -> 0 | L31: 0 | M31: =+M30+K31-L31 -> 0.7
A32: 29 | B32: 46202 | G32: =E32*F32 -> 0 | J32: =H32*I32 -> 0 | K32: =G32+J32 -> 0 | M32: =+M31+K32-L32 -> 0.7
A33: 30 | B33: 46203 | G33: =E33*F33 -> 0 | J33: =H33*I33 -> 0 | K33: =G33+J33 -> 0 | M33: =+M32+K33-L33 -> 0.7
A34: 31 | G34: =E34*F34 -> 0 | H34: 0 | I34: 0 | J34: =H34*I34 -> 0 | K34: =G34+J34 -> 0 | L34: 0 | M34: =+M33+K34-L34 -> 0.7
E35: =SUM(E4:E34) -> 0 | G35: =SUM(G4:G34) -> 0 | H35: =SUM(H4:H34) -> 0 | J35: =SUM(J4:J34) -> 0 | K35: =SUM(K4:K34) -> 0 | L35: =SUM(L4:L34) -> 1313281
F38: /

Sheet Jadcherla-4
A1: Shree Poornima F/S
A2: S.No | B2: Date | C2: GRN No | D2: Ind No/Bill No | E2: Diesel (Lts) | F2: Price | G2: Amount | H2: Petrol (Lts) | I2: Price | J2: Amount | K2: Total amount | L2: Amount paid | M2: As on date | N2: Remarks
A3: Opening Balance | M3: 15788.08
A4: 1 | B4: 46174 | G4: =E4*F4 -> 0 | J4: =H4*I4 -> 0 | K4: =G4+J4 -> 0 | L4: 0 | M4: =M3+K4-L4 -> 15788.08
A5: 2 | B5: 46175 | E5: 0 | F5: 0 | G5: =E5*F5 -> 0 | H5: 40 | I5: 116.33 | J5: =H5*I5 -> 4653.2 | K5: =G5+J5 -> 4653.2 | L5: 0 | M5: =M4+K5-L5 -> 20441.28
A6: 3 | B6: 46176 | G6: =E6*F6 -> 0 | J6: =H6*I6 -> 0 | K6: =G6+J6 -> 0 | L6: 0 | M6: =M5+K6-L6 -> 20441.28
A7: 4 | B7: 46177 | G7: =E7*F7 -> 0 | J7: =H7*I7 -> 0 | K7: =G7+J7 -> 0 | L7: 0 | M7: =M6+K7-L7 -> 20441.28
A8: 5 | B8: 46178 | E8: 2000 | F8: 104.42 | G8: =E8*F8 -> 208840 | J8: =H8*I8 -> 0 | K8: =G8+J8 -> 208840 | L8: 0 | M8: =M7+K8-L8 -> 229281.28
A9: 6 | B9: 46179 | G9: =E9*F9 -> 0 | J9: =H9*I9 -> 0 | K9: =G9+J9 -> 0 | L9: 229281 | M9: =M8+K9-L9 -> 0.28
A10: 7 | B10: 46180 | G10: =E10*F10 -> 0 | J10: =H10*I10 -> 0 | K10: =G10+J10 -> 0 | L10: 0 | M10: =M9+K10-L10 -> 0.28
A11: 8 | B11: 46181 | G11: =E11*F11 -> 0 | J11: =H11*I11 -> 0 | K11: =G11+J11 -> 0 | L11: 0 | M11: =M10+K11-L11 -> 0.28
A12: 9 | B12: 46182 | G12: =E12*F12 -> 0 | J12: =H12*I12 -> 0 | K12: =G12+J12 -> 0 | M12: =M11+K12-L12 -> 0.28
A13: 10 | B13: 46183 | G13: =E13*F13 -> 0 | J13: =H13*I13 -> 0 | K13: =G13+J13 -> 0 | M13: =M12+K13-L13 -> 0.28
A14: 11 | B14: 46184 | G14: =E14*F14 -> 0 | J14: =H14*I14 -> 0 | K14: =G14+J14 -> 0 | M14: =M13+K14-L14 -> 0.28
A15: 12 | B15: 46185 | G15: =E15*F15 -> 0 | J15: =H15*I15 -> 0 | K15: =G15+J15 -> 0 | M15: =M14+K15-L15 -> 0.28
A16: 13 | B16: 46186 | G16: =E16*F16 -> 0 | J16: =H16*I16 -> 0 | K16: =G16+J16 -> 0 | M16: =M15+K16-L16 -> 0.28
A17: 14 | B17: 46187 | G17: =E17*F17 -> 0 | J17: =H17*I17 -> 0 | K17: =G17+J17 -> 0 | M17: =M16+K17-L17 -> 0.28
A18: 15 | B18: 46188 | G18: =E18*F18 -> 0 | J18: =H18*I18 -> 0 | K18: =G18+J18 -> 0 | M18: =M17+K18-L18 -> 0.28
A19: 16 | B19: 46189 | G19: 0 | J19: 0 | K19: 0 | M19: =M18+K19-L19 -> 0.28
A20: 17 | B20: 46190 | G20: =E20*F20 -> 0 | J20: =H20*I20 -> 0 | K20: =G20+J20 -> 0 | M20: =M19+K20-L20 -> 0.28
A21: 18 | B21: 46191 | E21: 500 | F21: 104.42 | G21: =E21*F21 -> 52210 | J21: =H21*I21 -> 0 | K21: =G21+J21 -> 52210 | M21: =M20+K21-L21 -> 52210.28
A22: 19 | B22: 46192 | G22: =E22*F22 -> 0 | J22: =H22*I22 -> 0 | K22: =G22+J22 -> 0 | L22: 0 | M22: =M21+K22-L22 -> 52210.28
A23: 20 | B23: 46193 | G23: =E23*F23 -> 0 | J23: =H23*I23 -> 0 | K23: =G23+J23 -> 0 | L23: 0 | M23: =M22+K23-L23 -> 52210.28
A24: 21 | B24: 46194 | G24: =E24*F24 -> 0 | J24: =H24*I24 -> 0 | K24: =G24+J24 -> 0 | L24: 0 | M24: =M23+K24-L24 -> 52210.28
A25: 22 | B25: 46195 | G25: =E25*F25 -> 0 | J25: =H25*I25 -> 0 | K25: =G25+J25 -> 0 | L25: 0 | M25: =M24+K25-L25 -> 52210.28
A26: 23 | B26: 46196 | G26: =E26*F26 -> 0 | J26: =H26*I26 -> 0 | K26: =G26+J26 -> 0 | L26: 0 | M26: =M25+K26-L26 -> 52210.28
A27: 24 | B27: 46197 | G27: =E27*F27 -> 0 | H27: 40 | I27: 116.33 | J27: =H27*I27 -> 4653.2 | K27: =G27+J27 -> 4653.2 | L27: 0 | M27: =M26+K27-L27 -> 56863.48
A28: 25 | B28: 46198 | E28: 0 | F28: 0 | G28: =E28*F28 -> 0 | J28: =H28*I28 -> 0 | K28: =G28+J28 -> 0 | L28: 50000 | M28: =M27+K28-L28 -> 6863.48
A29: 26 | B29: 46199 | G29: =E29*F29 -> 0 | J29: =H29*I29 -> 0 | K29: =G29+J29 -> 0 | L29: 0 | M29: =M28+K29-L29 -> 6863.48
A30: 27 | B30: 46200 | G30: =E30*F30 -> 0 | J30: =H30*I30 -> 0 | K30: =G30+J30 -> 0 | L30: 0 | M30: =M29+K30-L30 -> 6863.48
A31: 28 | B31: 46201 | G31: =E31*F31 -> 0 | J31: =H31*I31 -> 0 | K31: =G31+J31 -> 0 | L31: 0 | M31: =M30+K31-L31 -> 6863.48
A32: 29 | B32: 46202 | G32: =E32*F32 -> 0 | J32: =H32*I32 -> 0 | K32: =G32+J32 -> 0 | L32: 0 | M32: =M31+K32-L32 -> 6863.48
A33: 30 | B33: 46203 | G33: =E33*F33 -> 0 | H33: 0 | I33: 0 | J33: =H33*I33 -> 0 | K33: =G33+J33 -> 0 | L33: 0 | M33: =M32+K33-L33 -> 6863.48
A34: 31 | G34: =E34*F34 -> 0 | J34: =H34*I34 -> 0 | K34: =G34+J34 -> 0 | M34: =M33+K34-L34 -> 6863.48
E35: =SUM(E4:E34) -> 2500 | G35: =SUM(G4:G34) -> 261050 | H35: =SUM(H4:H34) -> 80 | J35: =SUM(J4:J34) -> 9306.4 | K35: =SUM(K4:K34) -> 270356.4 | L35: =SUM(L4:L34) -> 279281

Sheet  Jadcherla
A1: Sai baba F/S
A2: S.No | B2: Date | C2: GRN No | D2: Ind No/Bill No | E2: Diesel (Lts) | F2: Price | G2: Amount | H2: Petrol (Lts) | I2: Price | J2: Amount | K2: Total amount | L2: Amount paid | M2: As on date | N2: Remarks
A3: Opening Balance | M3: 171115.11
A4: 1 | B4: 46174 | G4: =E4*F4 -> 0 | J4: =H4*I4 -> 0 | K4: =G4+J4 -> 0 | L4: 169080 | M4: =M3+K4-L4 -> 2035.1104 | N4: BT
A5: 2 | B5: 46175 | G5: =E5*F5 -> 0 | J5: =H5*I5 -> 0 | K5: =G5+J5 -> 0 | L5: 2035.11 | M5: =M4+K5-L5 -> 0.00040000001
A6: 3 | B6: 46176 | G6: =E6*F6 -> 0 | J6: =H6*I6 -> 0 | K6: =G6+J6 -> 0 | M6: =M5+K6-L6 -> 0.00040000001
A7: 4 | B7: 46177 | G7: =E7*F7 -> 0 | J7: =H7*I7 -> 0 | K7: =G7+J7 -> 0 | M7: =M6+K7-L7 -> 0.00040000001 | Q7: =1000*96.42 -> 96420
A8: 5 | B8: 46178 | G8: =E8*F8 -> 0 | J8: =H8*I8 -> 0 | K8: =G8+J8 -> 0 | M8: =M7+K8-L8 -> 0.00040000001
A9: 6 | B9: 46179 | G9: =E9*F9 -> 0 | J9: =H9*I9 -> 0 | K9: =G9+J9 -> 0 | M9: =M8+K9-L9 -> 0.00040000001
A10: 7 | B10: 46180 | G10: =E10*F10 -> 0 | J10: =H10*I10 -> 0 | K10: =G10+J10 -> 0 | M10: =M9+K10-L10 -> 0.00040000001
A11: 8 | B11: 46181 | G11: =E11*F11 -> 0 | J11: =H11*I11 -> 0 | K11: =G11+J11 -> 0 | M11: =M10+K11-L11 -> 0.00040000001
A12: 9 | B12: 46182 | G12: =E12*F12 -> 0 | J12: =H12*I12 -> 0 | K12: =G12+J12 -> 0 | M12: =M11+K12-L12 -> 0.00040000001
A13: 10 | B13: 46183 | G13: =E13*F13 -> 0 | J13: =H13*I13 -> 0 | K13: =G13+J13 -> 0 | M13: =M12+K13-L13 -> 0.00040000001
A14: 11 | B14: 46184 | G14: =E14*F14 -> 0 | J14: =H14*I14 -> 0 | K14: =G14+J14 -> 0 | M14: =M13+K14-L14 -> 0.00040000001
A15: 12 | B15: 46185 | G15: =E15*F15 -> 0 | J15: =H15*I15 -> 0 | K15: =G15+J15 -> 0 | M15: =M14+K15-L15 -> 0.00040000001
A16: 13 | B16: 46186 | G16: =E16*F16 -> 0 | J16: =H16*I16 -> 0 | K16: =G16+J16 -> 0 | M16: =M15+K16-L16 -> 0.00040000001
A17: 14 | B17: 46187 | G17: =E17*F17 -> 0 | J17: =H17*I17 -> 0 | K17: =G17+J17 -> 0 | M17: =M16+K17-L17 -> 0.00040000001
A18: 15 | B18: 46188 | G18: =E18*F18 -> 0 | J18: =H18*I18 -> 0 | K18: =G18+J18 -> 0 | M18: =M17+K18-L18 -> 0.00040000001 | N18: BT
A19: 16 | B19: 46189 | G19: =E19*F19 -> 0 | J19: =H19*I19 -> 0 | K19: =G19+J19 -> 0 | M19: =M18+K19-L19 -> 0.00040000001
A20: 17 | B20: 46190 | G20: =E20*F20 -> 0 | J20: =H20*I20 -> 0 | K20: =G20+J20 -> 0 | M20: =M19+K20-L20 -> 0.00040000001
A21: 18 | B21: 46191 | G21: =E21*F21 -> 0 | J21: =H21*I21 -> 0 | K21: =G21+J21 -> 0 | M21: =M20+K21-L21 -> 0.00040000001 | N21: BT
A22: 19 | B22: 46192 | G22: =E22*F22 -> 0 | J22: =H22*I22 -> 0 | K22: =G22+J22 -> 0 | M22: =M21+K22-L22 -> 0.00040000001
A23: 20 | B23: 46193 | G23: =E23*F23 -> 0 | J23: =H23*I23 -> 0 | K23: =G23+J23 -> 0 | M23: =M22+K23-L23 -> 0.00040000001
A24: 21 | B24: 46194 | G24: =E24*F24 -> 0 | J24: =H24*I24 -> 0 | K24: =G24+J24 -> 0 | M24: =M23+K24-L24 -> 0.00040000001
A25: 22 | B25: 46195 | G25: =E25*F25 -> 0 | J25: =H25*I25 -> 0 | K25: =G25+J25 -> 0 | M25: =M24+K25-L25 -> 0.00040000001
A26: 23 | B26: 46196 | G26: =E26*F26 -> 0 | J26: =H26*I26 -> 0 | K26: =G26+J26 -> 0 | M26: =M25+K26-L26 -> 0.00040000001
A27: 24 | B27: 46197 | G27: =E27*F27 -> 0 | J27: =H27*I27 -> 0 | K27: =G27+J27 -> 0 | M27: =M26+K27-L27 -> 0.00040000001
A28: 25 | B28: 46198 | G28: =E28*F28 -> 0 | J28: =H28*I28 -> 0 | K28: =G28+J28 -> 0 | M28: =M27+K28-L28 -> 0.00040000001
A29: 26 | B29: 46199 | G29: =E29*F29 -> 0 | J29: =H29*I29 -> 0 | K29: =G29+J29 -> 0 | M29: =M28+K29-L29 -> 0.00040000001
A30: 27 | B30: 46200 | G30: =E30*F30 -> 0 | J30: =H30*I30 -> 0 | K30: =G30+J30 -> 0 | M30: =M29+K30-L30 -> 0.00040000001
A31: 28 | B31: 46201 | G31: =E31*F31 -> 0 | J31: =H31*I31 -> 0 | K31: =G31+J31 -> 0 | M31: =M30+K31-L31 -> 0.00040000001
A32: 29 | B32: 46202 | G32: =E32*F32 -> 0 | J32: =H32*I32 -> 0 | K32: =G32+J32 -> 0 | M32: =M31+K32-L32 -> 0.00040000001
A33: 30 | B33: 46203 | G33: =E33*F33 -> 0 | H33: 0 | I33: 0 | J33: =H33*I33 -> 0 | K33: =G33+J33 -> 0 | L33: 0 | M33: =M32+K33-L33 -> 0.00040000001
A34: 31 | G34: =E34*F34 -> 0 | J34: =H34*I34 -> 0 | K34: =G34+J34 -> 0 | M34: =M33+K34-L34 -> 0.00040000001
E35: =SUM(E4:E34) -> 0 | G35: =SUM(G4:G34) -> 0 | H35: =SUM(H4:H34) -> 0 | J35: =SUM(J4:J34) -> 0 | K35: =SUM(K4:K34) -> 0 | L35: =SUM(L4:L34) -> 171115.11

Sheet  Sangareddy-2
A1: Durga Bhavani F/S
A2: S.No | B2: Date | C2: GRN No | D2: Ind no/Bill No | E2: Diesel (Lts) | F2: Price | G2: Amount | H2: Petrol (Lts) | I2: Price | J2: Amount | K2: Total amount | L2: Amount paid | M2: As on Date | N2: Remarks
A3: Opening Balance | M3: 108316.17
A4: 1 | B4: 45809 | G4: =E4*F4 -> 0 | J4: =H4*I4 -> 0 | K4: =G4+J4 -> 0 | M4: =M3+K4-L4 -> 108316.17
A5: 2 | B5: 45810 | G5: =E5*F5 -> 0 | J5: =H5*I5 -> 0 | K5: =G5+J5 -> 0 | M5: =M4+K5-L5 -> 108316.17
A6: 3 | B6: 45811 | G6: =E6*F6 -> 0 | J6: =H6*I6 -> 0 | K6: =G6+J6 -> 0 | M6: =M5+K6-L6 -> 108316.17
A7: 4 | B7: 45812 | G7: =E7*F7 -> 0 | J7: =H7*I7 -> 0 | K7: =G7+J7 -> 0 | M7: =M6+K7-L7 -> 108316.17
A8: 5 | B8: 45813 | G8: =E8*F8 -> 0 | J8: =H8*I8 -> 0 | K8: =G8+J8 -> 0 | M8: =M7+K8-L8 -> 108316.17
A9: 6 | B9: 45814 | G9: =E9*F9 -> 0 | J9: =H9*I9 -> 0 | K9: =G9+J9 -> 0 | M9: =M8+K9-L9 -> 108316.17
A10: 7 | B10: 45815 | G10: =E10*F10 -> 0 | J10: =H10*I10 -> 0 | K10: =G10+J10 -> 0 | M10: =M9+K10-L10 -> 108316.17
A11: 8 | B11: 45816 | G11: =E11*F11 -> 0 | J11: =H11*I11 -> 0 | K11: =G11+J11 -> 0 | L11: 108316 | M11: =M10+K11-L11 -> 0.1714
A12: 9 | B12: 45817 | E12: 47.24 | F12: 104.56 | G12: =E12*F12 -> 4939.4144 | J12: =H12*I12 -> 0 | K12: =G12+J12 -> 4939.4144 | M12: =M11+K12-L12 -> 4939.5858
A13: 10 | B13: 45818 | G13: =E13*F13 -> 0 | J13: =H13*I13 -> 0 | K13: =G13+J13 -> 0 | M13: =M12+K13-L13 -> 4939.5858
A14: 11 | B14: 45819 | G14: =E14*F14 -> 0 | J14: =H14*I14 -> 0 | K14: =G14+J14 -> 0 | M14: =M13+K14-L14 -> 4939.5858
A15: 12 | B15: 45820 | E15: 190.32 | F15: 104.56 | G15: =E15*F15 -> 19899.859 | H15: 15 | I15: 116.54 | J15: =H15*I15 -> 1748.1 | K15: =G15+J15 -> 21647.959 | M15: =M14+K15-L15 -> 26587.545
A16: 13 | B16: 45821 | E16: 112 | F16: 104.56 | G16: =E16*F16 -> 11710.72 | J16: =H16*I16 -> 0 | K16: =G16+J16 -> 11710.72 | M16: =M15+K16-L16 -> 38298.265
A17: 14 | B17: 45822 | E17: 0 | F17: 104.56 | G17: =E17*F17 -> 0 | H17: 8 | I17: 116.54 | J17: =H17*I17 -> 932.32 | K17: =G17+J17 -> 932.32 | M17: =M16+K17-L17 -> 39230.585
A18: 15 | B18: 45823 | E18: 564.77 | F18: 104.56 | G18: =E18*F18 -> 59052.351 | H18: 10 | I18: 116.54 | J18: =H18*I18 -> 1165.4 | K18: =G18+J18 -> 60217.751 | M18: =M17+K18-L18 -> 99448.336
A19: 16 | B19: 45824 | E19: 34.9 | F19: 104.56 | G19: =E19*F19 -> 3649.144 | H19: 3 | I19: 116.54 | J19: =H19*I19 -> 349.62 | K19: =G19+J19 -> 3998.764 | M19: =M18+K19-L19 -> 103447.1
A20: 17 | B20: 45825 | E20: 1379.47 | F20: 104.56 | G20: =E20*F20 -> 144237.38 | H20: 13 | I20: 116.54 | J20: =H20*I20 -> 1515.02 | K20: =G20+J20 -> 145752.4 | M20: =M19+K20-L20 -> 249199.5
A21: 18 | B21: 45826 | E21: 373.32 | F21: 104.56 | G21: =E21*F21 -> 39034.339 | J21: =H21*I21 -> 0 | K21: =G21+J21 -> 39034.339 | M21: =M20+K21-L21 -> 288233.84
A22: 19 | B22: 45827 | G22: =E22*F22 -> 0 | H22: 10 | I22: 116.54 | J22: =H22*I22 -> 1165.4 | K22: =G22+J22 -> 1165.4 | M22: =M21+K22-L22 -> 289399.24
A23: 20 | B23: 45828 | E23: 37.2 | F23: 104.56 | G23: =E23*F23 -> 3889.632 | J23: =H23*I23 -> 0 | K23: =G23+J23 -> 3889.632 | M23: =M22+K23-L23 -> 293288.87 | Q23: 96.44
A24: 21 | B24: 45829 | G24: =E24*F24 -> 0 | J24: =H24*I24 -> 0 | K24: =G24+J24 -> 0 | M24: =M23+K24-L24 -> 293288.87
A25: 22 | B25: 45830 | E25: 200 | F25: 104.56 | G25: =E25*F25 -> 20912 | H25: 5 | I25: 116.54 | J25: =H25*I25 -> 582.7 | K25: =G25+J25 -> 21494.7 | M25: =M24+K25-L25 -> 314783.57
A26: 23 | B26: 45831 | E26: 41.93 | F26: 104.56 | G26: =E26*F26 -> 4384.2008 | H26: 5 | I26: 116.54 | J26: =H26*I26 -> 582.7 | K26: =G26+J26 -> 4966.9008 | M26: =M25+K26-L26 -> 319750.48
A27: 24 | B27: 45832 | G27: =E27*F27 -> 0 | H27: 20 | I27: 116.54 | J27: =H27*I27 -> 2330.8 | K27: =G27+J27 -> 2330.8 | M27: =M26+K27-L27 -> 322081.28
A28: 25 | B28: 45833 | E28: 37.75 | F28: 104.56 | G28: =E28*F28 -> 3947.14 | J28: 0 | K28: =G28+J28 -> 3947.14 | L28: 200000 | M28: =M27+K28-L28 -> 126028.42
A29: 26 | B29: 45834 | G29: =E29*F29 -> 0 | J29: =H29*I29 -> 0 | K29: =G29+J29 -> 0 | M29: =M28+K29-L29 -> 126028.42
A30: 27 | B30: 45835 | G30: =E30*F30 -> 0 | H30: 5 | I30: 116.54 | J30: =H30*I30 -> 582.7 | K30: =G30+J30 -> 582.7 | M30: =M29+K30-L30 -> 126611.12
A31: 28 | B31: 45836 | G31: =E31*F31 -> 0 | J31: =H31*I31 -> 0 | K31: =G31+J31 -> 0 | M31: =M30+K31-L31 -> 126611.12
A32: 29 | B32: 45837 | G32: =E32*F32 -> 0 | J32: =H32*I32 -> 0 | K32: =G32+J32 -> 0 | M32: =M31+K32-L32 -> 126611.12
A33: 30 | B33: 45838 | G33: =E33*F33 -> 0 | H33: 15 | I33: 116.54 | J33: =H33*I33 -> 1748.1 | K33: =G33+J33 -> 1748.1 | L33: 0 | M33: =M32+K33-L33 -> 128359.22
A34: 31 | G34: =E34*F34 -> 0 | J34: =H34*I34 -> 0 | K34: =G34+J34 -> 0 | L34: 0 | M34: =M33+K34-L34 -> 128359.22
E35: =SUM(E4:E34) -> 3018.9 | G35: =SUM(G4:G34) -> 315656.18 | H35: =SUM(H4:H34) -> 109 | J35: =SUM(J4:J34) -> 12702.86 | K35: =SUM(K4:K34) -> 328359.04 | L35: =SUM(L4:L34) -> 308316

Sheet  Sangareddy-3
A1: SHIVA PARVATHI FILLING STATION SADASHIVPET
A2: S.No | B2: Date | C2: GRN No | D2: Ind no/Bill No | E2: Diesel (Lts) | F2: Price | G2: Amount | H2: Petrol (Lts) | I2: Price | J2: Amount | K2: Total amount | L2: Amount paid | M2: As on Date | N2: Remarks
A3: Opening Balance | M3: 986125.39
A4: 1 | B4: 45809 | E4: 690 | F4: 104.35 | G4: =E4*F4 -> 72001.5 | J4: =H4*I4 -> 0 | K4: =G4+J4 -> 72001.5 | L4: 300000 | M4: =M3+K4-L4 -> 758126.89
A5: 2 | B5: 45810 | E5: 690 | F5: 104.35 | G5: =E5*F5 -> 72001.5 | H5: 6 | I5: 116.25 | J5: =H5*I5 -> 697.5 | K5: =G5+J5 -> 72699 | L5: 0 | M5: =M4+K5-L5 -> 830825.89
A6: 3 | B6: 45811 | E6: 490 | F6: 104.35 | G6: =E6*F6 -> 51131.5 | J6: =H6*I6 -> 0 | K6: =G6+J6 -> 51131.5 | L6: 0 | M6: =M5+K6-L6 -> 881957.39
A7: 4 | B7: 45812 | G7: =E7*F7 -> 0 | H7: 8 | I7: 126.03 | J7: =H7*I7 -> 1008.24 | K7: =G7+J7 -> 1008.24 | L7: 0 | M7: =M6+K7-L7 -> 882965.63
A8: 5 | B8: 45813 | E8: 690 | F8: 104.35 | G8: =E8*F8 -> 72001.5 | H8: 7 | I8: 116.25 | J8: =H8*I8 -> 813.75 | K8: =G8+J8 -> 72815.25 | L8: 0 | M8: =M7+K8-L8 -> 955780.88
A9: 6 | B9: 45814 | E9: 690 | F9: 104.35 | G9: =E9*F9 -> 72001.5 | H9: 6 | I9: 116.25 | J9: =H9*I9 -> 697.5 | K9: =G9+J9 -> 72699 | L9: 0 | M9: =M8+K9-L9 -> 1028479.9
A10: 7 | B10: 45815 | E10: 690 | F10: 104.35 | G10: =E10*F10 -> 72001.5 | J10: =H10*I10 -> 0 | K10: =G10+J10 -> 72001.5 | L10: 0 | M10: =M9+K10-L10 -> 1100481.4
