Workbook

Sheet  MIs
A2: S.No | B2: NAme | C2: Lacation | D2: Card Number | E2: Card Number | F2: Category | G2: 1st Jan | I2: 2nd Jan | J2: 3rd Jan | K2: 4th Jan | L2: 5th Jan | M2: 6th Jan | N2: 7th Jan | O2: 8th Jan | P2: 9th Jan | Q2: 10th Jan | R2: 11th Jan | S2: 12th Jan | T2: 13th Jan | U2: 14th Jan | V2: 15th Jan | W2: 16th Jan | X2: 17th Jan | Y2: 18th Jan | Z2: 19th Jan | AA2: 20th Jan | AB2: 21st Jan | AC2: 22nd Jan | AD2: 23rd Jan | AE2: 24th Jan | AF2: 25th Jan | AG2: 26th Jan | AH2: 27th Jan | AI2: 28th Jan | AJ2: 29th Jan | AK2: 30th Jan | AL2: 31st Jan | AM2: Total
F3: Diesel
A4: 1 | B4: Rambabu | C4: HO(Two Wheeler) | D4: FC3450563999 | E4: Diesel | F4: 0 | G4: 0 | H4: 0 | I4: 0 | J4: 0 | K4: 0 | L4: 0 | M4: 0 | N4: 0 | O4: 0 | P4: 0 | Q4: 0 | R4: 0 | S4: 0 | T4: 0 | U4: 0 | V4: 0 | W4: 0 | X4: 5.22 | Y4: 0 | Z4: 0 | AA4: 0 | AB4: 0 | AC4: 0 | AD4: 60 | AE4: 0 | AF4: 0 | AG4: 0 | AH4: 4.56 | AI4: 0 | AJ4: 0 | AK4: 0 | AL4: 0 | AM4: =SUM(F4:AL4) -> 69.78
E5: Petrol | F5: 0 | G5: 4.69 | H5: 0 | I5: 0 | J5: 0 | K5: 0 | L5: 0 | M5: 0 | N5: 3.91 | O5: 0 | P5: 6.98 | Q5: 0 | R5: 0 | S5: 0 | T5: 0 | U5: 0 | V5: 0 | W5: 0 | X5: 0 | Y5: 0 | Z5: 0 | AB5: 0 | AC5: 0 | AD5: 0 | AE5: 0 | AF5: 0 | AG5: 0 | AH5: 0 | AI5: 0 | AJ5: 0 | AK5: 0 | AL5: 0 | AM5: =SUM(F5:AL5) -> 15.58
A6: 2 | B6: Hanumanth Rao | C6: HO | D6: FC3450676131 | E6: Diesel | F6: 0 | G6: 0 | H6: 0 | I6: 0 | J6: 0 | K6: 0 | L6: 0 | M6: 0 | N6: 0 | O6: 0 | P6: 0 | Q6: 0 | R6: 0 | S6: 0 | T6: 0 | U6: 0 | V6: 0 | W6: 0 | X6: 0 | Y6: 0 | Z6: 0 | AA6: 0 | AB6: 0 | AC6: 0 | AD6: 0 | AE6: 0 | AF6: 0 | AG6: 0 | AH6: 0 | AI6: 0 | AJ6: 0 | AK6: 0 | AL6: 0 | AM6: =SUM(F6:AL6) -> 0
E7: Petrol | F7: 0 | G7: 0 | H7: 0 | I7: 0 | J7: 0 | K7: 0 | L7: 0 | M7: 0 | N7: 0 | O7: 0 | P7: 0 | Q7: 0 | R7: 0 | S7: 0 | T7: 0 | U7: 0 | V7: 0 | W7: 0 | X7: 0 | Y7: 0 | Z7: 0 | AB7: 0 | AC7: 0 | AD7: 0 | AE7: 0 | AF7: 0 | AG7: 0 | AH7: 0 | AI7: 0 | AJ7: 0 | AK7: 0 | AL7: 0 | AM7: =SUM(F7:AL7) -> 0
A8: 3 | B8: Radhakrishna | C8: HO | D8: FC8000207658 | E8: Diesel | F8: 0 | G8: 0 | H8: 0 | I8: 0 | J8: 33.44 | K8: 0 | L8: 0 | M8: 0 | N8: 0 | O8: 0 | P8: 0 | Q8: 0 | R8: 35.53 | S8: 0 | T8: 0 | U8: 0 | V8: 0 | W8: 0 | X8: 0 | Y8: 0 | Z8: 0 | AA8: 0 | AB8: 33.44 | AC8: 0 | AD8: 0 | AE8: 0 | AF8: 0 | AG8: 0 | AH8: 0 | AI8: 0 | AJ8: 0 | AK8: 0 | AL8: 0 | AM8: =SUM(F8:AL8) -> 102.41
E9: Petrol | F9: 0 | G9: 0 | H9: 0 | I9: 0 | J9: 0 | K9: 0 | L9: 0 | M9: 0 | N9: 0 | O9: 0 | P9: 0 | Q9: 0 | R9: 0 | S9: 0 | T9: 0 | U9: 0 | V9: 0 | W9: 0 | X9: 0 | Y9: 0 | Z9: 0 | AB9: 0 | AC9: 0 | AD9: 0 | AE9: 0 | AF9: 0 | AG9: 0 | AH9: 0 | AI9: 0 | AJ9: 0 | AK9: 0 | AL9: 0 | AM9: =SUM(F9:AL9) -> 0
A10: 4 | B10: VIjay | C10: HO | D10: FC3450698859 | E10: Diesel | F10: 0 | G10: 0 | H10: 0 | I10: 0 | J10: 0 | K10: 0 | L10: 0 | M10: 0 | N10: 0 | O10: 0 | P10: 49.22 | Q10: 0 | R10: 0 | S10: 0 | T10: 0 | U10: 54.57 | V10: 0 | W10: 0 | X10: 0 | Y10: 0 | Z10: 0 | AA10: 0 | AB10: 0 | AC10: 0 | AD10: 49.8 | AE10: 0 | AF10: 0 | AG10: 0 | AH10: 0 | AI10: 0 | AJ10: 0 | AK10: 0 | AL10: 0 | AM10: =SUM(F10:AL10) -> 153.59
E11: Petrol | F11: 0 | G11: 0 | H11: 0 | I11: 0 | J11: 0 | K11: 0 | L11: 0 | M11: 0 | N11: 0 | O11: 0 | P11: 0 | Q11: 0 | R11: 0 | S11: 0 | T11: 0 | U11: 0 | V11: 0 | W11: 0 | X11: 0 | Y11: 0 | Z11: 0 | AB11: 0 | AC11: 0 | AD11: 0 | AE11: 0 | AF11: 0 | AG11: 0 | AH11: 0 | AI11: 0 | AJ11: 0 | AK11: 0 | AL11: 0 | AM11: =SUM(F11:AL11) -> 0
A12: 5 | B12: Client | C12: Hiriyur | D12: FC3450698864 | E12: Diesel | F12: 0 | G12: 0 | H12: 0 | I12: 0 | J12: 0 | K12: 0 | L12: 0 | M12: 0 | N12: 86.29 | O12: 0 | P12: 0 | Q12: 0 | R12: 0 | S12: 0 | T12: 0 | U12: 0 | V12: 0 | W12: 0 | X12: 0 | Y12: 0 | Z12: 0 | AA12: 0 | AB12: 0 | AC12: 0 | AD12: 145.61 | AE12: 0 | AF12: 0 | AG12: 0 | AH12: 0 | AI12: 0 | AJ12: 0 | AK12: 0 | AL12: 0 | AM12: =SUM(F12:AL12) -> 231.9
E13: Petrol | F13: 0 | G13: 0 | H13: 0 | I13: 0 | J13: 0 | K13: 0 | L13: 0 | M13: 0 | N13: 0 | O13: 0 | P13: 0 | Q13: 0 | R13: 0 | S13: 0 | T13: 0 | U13: 0 | V13: 0 | W13: 0 | X13: 0 | Y13: 0 | Z13: 0 | AB13: 0 | AC13: 0 | AD13: 0 | AE13: 0 | AF13: 0 | AG13: 0 | AH13: 0 | AI13: 0 | AJ13: 0 | AK13: 0 | AL13: 0 | AM13: =SUM(F13:AL13) -> 0
A14: 6 | B14: Client | C14: Hosadurga | D14: FC3450698865 | E14: Diesel | F14: 0 | G14: 0 | H14: 0 | I14: 0 | J14: 0 | K14: 0 | L14: 40 | M14: 40 | N14: 0 | O14: 36 | P14: 35 | Q14: 0 | R14: 0 | S14: 0 | T14: 0 | U14: 0 | V14: 0 | W14: 45 | X14: 45 | Y14: 43.53 | Z14: 40 | AA14: 43 | AB14: 0 | AC14: 40 | AD14: 0 | AE14: 40 | AF14: 0 | AG14: 0 | AH14: 0 | AI14: 0 | AJ14: 0 | AK14: 0 | AL14: 0 | AM14: =SUM(F14:AL14) -> 447.53
E15: Petrol | F15: 0 | G15: 0 | H15: 0 | I15: 0 | J15: 0 | K15: 0 | L15: 0 | M15: 0 | N15: 0 | O15: 0 | P15: 0 | Q15: 0 | R15: 0 | S15: 0 | T15: 0 | U15: 0 | V15: 0 | W15: 0 | X15: 0 | Y15: 0 | Z15: 0 | AB15: 0 | AC15: 0 | AD15: 0 | AE15: 0 | AF15: 0 | AG15: 0 | AH15: 0 | AI15: 0 | AJ15: 0 | AK15: 0 | AL15: 0 | AM15: =SUM(F15:AL15) -> 0
G18: Diesel Price

Sheet  Sep-26
A1: S.no | B1: Site Name | C1: Bunk Name | D1: Diesel(Liters) | E1: Diesel Amount | F1: Petrol(Liters) | G1: Petrol Amount | H1: Total Amount | I1: Opening Blance | J1: Amount Paid | K1: Closing Balances
A2: 1 | B2: Khammam-1 | C2: Divya laxmi ganapathi | D2: =+'Khammam-1'!E38 -> 39800 | E2: =+'Khammam-1'!G38 -> 4131240 | F2: =+'Khammam-1'!H38 -> 185 | G2: =+'Khammam-1'!J38 -> 21402.65 | H2: =E2+G2 -> 4152642.6 | I2: =+'Khammam-1'!K3 -> 2805565.2 | J2: =+'Khammam-1'!L38 -> 2826324 | K2: =H2+I2-J2 -> 4131883.8
A3: 2 | B3: Khammam-2 | C3: Jayasai union bunk | D3: =+'Khammam-2'!E39 -> 39546 | E3: =+'Khammam-2'!G39 -> 4230667 | F3: =+'Khammam-2'!H39 -> 155 | G3: =+'Khammam-2'!J39 -> 17936.6 | H3: =E3+G3 -> 4248603.6 | I3: =+'Khammam-2'!K3 -> 0 | J3: =+'Khammam-2'!L39 -> 0 | K3: =H3+I3-J3 -> 4248603.6
A4: 3 | B4: Khammam | C4: Sai Madeana Filling Station | D4: =+'Khammam-4'!E35 -> 27000 | E4: =+'Khammam-4'!G35 -> 2797740 | F4: =+'Khammam-4'!H35 -> 595 | G4: =+'Khammam-4'!J35 -> 68716.55 | H4: =E4+G4 -> 2866456.5 | I4: =+'Khammam-4'!M3 -> 843364.3 | J4: =+'Khammam-4'!L35 -> 568209.75 | K4: =H4+I4-J4 -> 3141611.1
A5: 4 | B5: Khammam | C5: Vajra mahalakshmi filling station | D5: =+' Khammam-5'!E35 -> 8200 | E5: =+' Khammam-5'!G35 -> 849684 | F5: =+' Khammam-5'!H35 -> 145 | G5: =+' Khammam-5'!J35 -> 16746.05 | H5: =E5+G5 -> 866430.05 | I5: =+' Khammam-5'!M3 -> 578571.8 | J5: =+' Khammam-5'!L35 -> 0 | K5: =H5+I5-J5 -> 1445001.9
A6: 5 | B6: Khammam-Cash&Carry | C6: NA | D6: =+' Khammam&Cash'!E46 -> 0 | E6: =+' Khammam&Cash'!G46 -> 0 | F6: =+' Khammam&Cash'!H46 -> 0 | G6: =+' Khammam&Cash'!J46 -> 0 | H6: =E6+G6 -> 0 | I6: =+' Khammam&Cash'!M3 -> 0 | J6: =+' Khammam&Cash'!L46 -> 0 | K6: =H6+I6-J6 -> 0
A7: 6 | B7: Jadcherla-2 | C7: Shree Poornima F/S | D7: =+'Jadcherla-4'!E35 -> 400 | E7: =+'Jadcherla-4'!G35 -> 41768 | F7: =+'Jadcherla-4'!H35 -> 30 | G7: =+'Jadcherla-4'!J35 -> 3489.9 | H7: =E7+G7 -> 45257.9 | I7: =+'Jadcherla-4'!M3 -> 2600.28 | J7: =+'Jadcherla-4'!L35 -> 0 | K7: =H7+I7-J7 -> 47858.18
A8: 7 | B8: Sangareddy-2 | C8: Durga Bhavani F/S | D8: =+' Sangareddy-2'!E35 -> 0 | E8: =+' Sangareddy-2'!G35 -> 0 | F8: =+' Sangareddy-2'!H35 -> 0 | G8: =+' Sangareddy-2'!J35 -> 0 | H8: =E8+G8 -> 0 | I8: =+' Sangareddy-2'!M3 -> 0 | J8: =+' Sangareddy-2'!L35 -> 0 | K8: =H8+I8-J8 -> 0
A9: 8 | B9: Sangareddy-3 | C9: Shiva Parvathi Filling Station | D9: =+' Sangareddy-3'!E36 -> 6120 | E9: =+' Sangareddy-3'!G36 -> 638622 | F9: =+' Sangareddy-3'!H36 -> 82 | G9: =+' Sangareddy-3'!J36 -> 9532.5 | H9: =E9+G9 -> 648154.5 | I9: =+' Sangareddy-3'!M3 -> 146154.99 | J9: =+' Sangareddy-3'!L36 -> 427500 | K9: =H9+I9-J9 -> 366809.49
A10: 9 | B10: NarayanaKhed | C10: Sai Shiva Filling Station | D10: =Narayankhed!E35 -> 2046.27 | E10: =+Narayankhed!G35 -> 214943.35 | F10: =+Narayankhed!H35 -> 0 | G10: =+Narayankhed!J35 -> 0 | H10: =E10+G10 -> 214943.35 | I10: =+Narayankhed!M3 -> 0 | J10: =+Narayankhed!L35 -> 214943.35 | K10: =H10+I10-J10 -> 0
A11: 10 | B11: Dindi | C11: Akarapu Balakistamma Fillling | D11: =+Dindi!E35 -> 91.45 | E11: =+Dindi!G35 -> 9597.6775 | F11: =+Dindi!H35 -> 0 | G11: =+Dindi!J35 -> 0 | H11: =E11+G11 -> 9597.6775 | I11: =+Dindi!M3 -> 0 | J11: =+Dindi!L35 -> 9597.6775 | K11: =H11+I11-J11 -> 0
A12: 11 | B12: Madanapalli | C12: NA | D12: =+'Madana palli'!E37 -> 0 | E12: =+'Madana palli'!G37 -> 0 | F12: =+'Madana palli'!H37 -> 0 | G12: =+'Madana palli'!J37 -> 0 | H12: =E12+G12 -> 0 | I12: =+'Madana palli'!M3 -> 0 | J12: =+'Madana palli'!L37 -> 0 | K12: =H12+I12-J12 -> 0
A13: 12 | B13: Kakinada | C13: Raja Filling Station | D13: =+' Raja Filling Statuion'!E35 -> 119 | E13: =+' Raja Filling Statuion'!G35 -> 12565.21 | F13: =+' Raja Filling Statuion'!H35 -> 14 | G13: =+' Raja Filling Statuion'!J35 -> 1651.72 | H13: =E13+G13 -> 14216.93 | I13: =+' Raja Filling Statuion'!M3 -> 0 | J13: =+' Raja Filling Statuion'!L35 -> 0 | K13: =H13+I13-J13 -> 14216.93
A14: 13 | B14: Kovvur | C14: Sri Venkateshwara Services | D14: =+'Sri Venkateshwara Services'!E37 -> 1621.364 | E14: =+'Sri Venkateshwara Services'!G37 -> 169724.38 | F14: =+'Sri Venkateshwara Services'!H37 -> 245.02 | G14: =+'Sri Venkateshwara Services'!J37 -> 28657.539 | H14: =E14+G14 -> 198381.92 | I14: =+'Sri Venkateshwara Services'!M3 -> 17037.915 | J14: =+'Sri Venkateshwara Services'!L37 -> 100000 | K14: =H14+I14-J14 -> 115419.84
A15: 14 | B15: Jangareddygudem | C15: Solasa Krishna Oil Company | D15: =+' Solasa Krishna OIl'!E37 -> 1795.41 | E15: =+' Solasa Krishna OIl'!G37 -> 189236.21 | F15: =+' Solasa Krishna OIl'!H37 -> 28.05 | G15: =+' Solasa Krishna OIl'!J37 -> 3302.607 | H15: =E15+G15 -> 192538.82 | I15: =+' Solasa Krishna OIl'!M3 -> 46362.715 | J15: =+' Solasa Krishna OIl'!L37 -> 0 | K15: =H15+I15-J15 -> 238901.54
A16: 15 | B16: Amalapuram | C16: Royal Fill 'N' Fly | D16: =+'Amalapuram(KKD)'!E37 -> 10406.79 | E16: =+'Amalapuram(KKD)'!G37 -> 1095314.6 | F16: =+'Amalapuram(KKD)'!H37 -> 106 | G16: =+'Amalapuram(KKD)'!J37 -> 12463.48 | H16: =E16+G16 -> 1107778.1 | I16: =+'Amalapuram(KKD)'!M3 -> 426859.64 | J16: =+'Amalapuram(KKD)'!L37 -> 1015000 | K16: =H16+I16-J16 -> 519637.76
A17: 16 | B17: Yeleshwaram | C17: Sri sathya Filling Station | D17: =+'Yeleshwaram(KKD)'!E37 -> 812.02 | E17: =+'Yeleshwaram(KKD)'!G37 -> 85635.629 | F17: =+'Yeleshwaram(KKD)'!H37 -> 25 | G17: =+'Yeleshwaram(KKD)'!J37 -> 2946 | H17: =E17+G17 -> 88581.629 | I17: =+'Yeleshwaram(KKD)'!M3 -> 8498.7136 | J17: =+'Yeleshwaram(KKD)'!L37 -> 80000 | K17: =H17+I17-J17 -> 17080.343
A18: 17 | B18: Pitapuam | C18: Satya Siva Durga Agencies, Chebrolu | D18: =+' Pitapram(KKD)'!E37 -> 5710.3 | E18: =+' Pitapram(KKD)'!G37 -> 600780.66 | F18: =+' Pitapram(KKD)'!H37 -> 516.23 | G18: =+' Pitapram(KKD)'!J37 -> 60698.323 | H18: =E18+G18 -> 661478.99 | I18: =+' Pitapram(KKD)'!M3 -> 124354 | J18: =+' Pitapram(KKD)'!L37 -> 494000 | K18: =H18+I18-J18 -> 291832.98
A19: 18 | B19: Kakinada | C19: Multiple bunks | D19: =+' Pitapram(KKD)'!E38 -> 0 | E19: =+' Pitapram(KKD)'!G38 -> 0 | F19: =+' Pitapram(KKD)'!H38 -> 0 | G19: =+' Pitapram(KKD)'!J38 -> 0 | H19: =E19+G19 -> 0 | I19: =+'Multiple bunks(KKD)'!M3 -> 0 | J19: =+' Pitapram(KKD)'!L38 -> 0 | K19: =H19+I19-J19 -> 0
A20: 19 | B20: YG Gudda-2 | C20: Pankaja HP Fuel Center | D20: =+'YG Gudda'!E39 -> 8000 | E20: =+'YG Gudda'!G39 -> 793120 | F20: =+'YG Gudda'!H39 -> 315 | G20: =+'YG Gudda'!J39 -> 35040.6 | H20: =E20+G20 -> 828160.6 | I20: =+'YG Gudda'!M3 -> 127791.16 | J20: =+'YG Gudda'!L39 -> 650000 | K20: =H20+I20-J20 -> 305951.76
A21: 20 | B21: YG Gudda-2 | C21: One stop | D21: =+' YG Gudda-2'!E39 -> 2400 | E21: =+' YG Gudda-2'!G39 -> 237648 | F21: =+' YG Gudda-2'!H39 -> 105 | G21: =+' YG Gudda-2'!J39 -> 11667.6 | H21: =E21+G21 -> 249315.6 | I21: =+' YG Gudda-2'!M3 -> 156607.72 | J21: =+' YG Gudda-2'!L39 -> 150000 | K21: =H21+I21-J21 -> 255923.32
A22: 21 | B22: Hosadurga-2 | C22: Shree Veeraprathap Fuel | D22: =+'Hosadurga -2'!E35 -> 1000 | E22: =+'Hosadurga -2'!G35 -> 99380 | F22: =+'Hosadurga -2'!H35 -> 70 | G22: =+'Hosadurga -2'!J35 -> 7820.4 | H22: =+'Hosadurga -2'!K35 -> 107200.4 | I22: =+'Hosadurga -2'!M3 -> 118809.59 | J22: =+'Hosadurga -2'!L35 -> 100000 | K22: =H22+I22-J22 -> 126009.99
A23: 22 | B23: Malebennuru(KUWSDB) | C23: Sri Ramanjuneya Service Station | D23: =+'Malebenur(KUWSDB)'!E38 -> 6099.92 | E23: =+'Malebenur(KUWSDB)'!G38 -> 609939.99 | F23: =+'Malebenur(KUWSDB)'!H38 -> 185 | G23: =+'Malebenur(KUWSDB)'!J38 -> 20723.7 | H23: =E23+G23 -> 630663.69 | I23: =+'Malebenur(KUWSDB)'!M3 -> 122228.41 | J23: =+'Malebenur(KUWSDB)'!L38 -> 461999.99 | K23: =H23+I23-J23 -> 290892.11
A24: 23 | B24: kadur | C24: Vishal Service Station | D24: =+Kadur!E35 -> 1600 | E24: =+Kadur!G35 -> 159936 | F24: =+Kadur!H35 -> 140 | G24: =+Kadur!J35 -> 15722 | H24: =E24+G24 -> 175658 | I24: =+Kadur!K3 -> 0 | J24: =+Kadur!L35 -> 0 | K24: =H24+I24-J24 -> 175658
A25: 24 | B25: Hiriyur(VJNL) | C25: Sri Balaji Agencies | D25: =+'Hiriyur(VJNL)'!E35 -> 4700 | E25: =+'Hiriyur(VJNL)'!G35 -> 470423 | F25: =+'Hiriyur(VJNL)'!H35 -> 295 | G25: =+'Hiriyur(VJNL)'!J35 -> 33075.4 | H25: =E25+G25 -> 503498.4 | I25: =+'Hiriyur(VJNL)'!K3 -> 219945.7 | J25: =+'Hiriyur(VJNL)'!L35 -> 511000 | K25: =H25+I25-J25 -> 212444.1
A26: 25 | B26: Chellakere(KUWSDB) | C26: Shivaganga Service Station | D26: =+'Chellakere -1'!E38 -> 3600 | E26: =+'Chellakere -1'!G38 -> 360180 | F26: =+'Chellakere -1'!H38 -> 175 | G26: =+'Chellakere -1'!J38 -> 19612.25 | H26: =E26+G26 -> 379792.25 | I26: =+'Chellakere -1'!K3 -> 0 | J26: =+'Chellakere -1'!L38 -> 191000 | K26: =H26+I26-J26 -> 188792.25
A27: 26 | B27: Chellakere(KUWSDB)-09 | C27: Shivaganga Service Station | D27: =+' Chellakere-PKG-9'!E38 -> 983.15 | E27: =+' Chellakere-PKG-9'!G38 -> 98364.158 | F27: =+' Chellakere-PKG-9'!H38 -> 48.24 | G27: =+' Chellakere-PKG-9'!J38 -> 5406.2568 | H27: =E27+G27 -> 103770.41 | I27: =+' Chellakere-PKG-9'!M3 -> 0 | J27: =+' Chellakere-PKG-9'!L38 -> 103769.42 | K27: =H27+I27-J27 -> 0.999
A28: 27 | B28: Molakalmuru | C28: Sri Lakshmi Venkateshwara Filling Station | D28: =+Molakamuru!E35 -> 700 | E28: =+Molakamuru!G35 -> 70028 | F28: =+Molakamuru!H35 -> 40 | G28: =+Molakamuru!J35 -> 4482.4 | H28: =E28+G28 -> 74510.4 | I28: =+Molakamuru!K3 -> 35260.26 | J28: =+Molakamuru!L35 -> 65000 | K28: =H28+I28-J28 -> 44770.66
A29: 28 | B29: Chennagiri | C29: NA | D29: =+' Chennagiri'!E35 -> 1290 | E29: =+' Chennagiri'!G35 -> 128858.1 | F29: =+' Chennagiri'!H35 -> 70 | G29: =+' Chennagiri'!J35 -> 7844.2 | H29: =E29+G29 -> 136702.3 | I29: =+' Chennagiri'!K3 -> 0 | J29: =+' Chennagiri'!L35 -> 136702.3 | K29: =H29+I29-J29 -> 0
A30: 29 | B30: Khanapur(PKG-3) | C30: V.V.Varde | D30: =+Khanapur!E35 -> 705.07 | E30: =+Khanapur!G35 -> 69583.358 | F30: =+Khanapur!H35 -> 85 | G30: =+Khanapur!J35 -> 9412.9 | H30: =E30+G30 -> 78996.258 | I30: =+Khanapur!M3 -> 41788.871 | J30: =+Khanapur!L35 -> 0 | K30: =H30+I30-J30 -> 120785.13
A31: 30 | B31: Munavalli(PKG-3) | C31: Shre Shiva Petroleum | D31: =+'Munavali-2'!E40 -> 5200 | E31: =+'Munavali-2'!G40 -> 516620 | F31: =+'Munavali-2'!H40 -> 0 | G31: =+'Munavali-2'!J40 -> 0 | H31: =E31+G31 -> 516620 | I31: =+'Munavali-2'!M3 -> 346801.5 | J31: =+'Munavali-2'!L40 -> 600000 | K31: =H31+I31-J31 -> 263421.5
A32: 31 | B32: Munavalli(PKG-3) | C32: Daneshwari Petroleum | D32: =+' Munavali'!E39 -> 27.13 | E32: =+' Munavali'!G39 -> 2689.3969 | F32: =+' Munavali'!H39 -> 240 | G32: =+' Munavali'!J39 -> 26690.4 | H32: =E32+G32 -> 29379.797 | I32: =+' Munavali'!M3 -> 665.2699 | J32: =+' Munavali'!L39 -> 0 | K32: =H32+I32-J32 -> 30045.067
A33: 32 | B33: Ugar,Kudichi(PKG-3) | C33: Shiri Bhrhmanath Petrolium | D33: =+'Ugar,Khagwad,Kudichi'!E37 -> 7865.62 | E33: =+'Ugar,Khagwad,Kudichi'!G37 -> 784516.94 | F33: =+'Ugar,Khagwad,Kudichi'!H37 -> 411 | G33: =+'Ugar,Khagwad,Kudichi'!J37 -> 45971.2 | H33: =E33+G33 -> 830488.14 | I33: =+'Ugar,Khagwad,Kudichi'!M3 -> 583834.37 | J33: =+'Ugar,Khagwad,Kudichi'!L37 -> 1113666.7 | K33: =H33+I33-J33 -> 300655.8
A34: 33 | B34: Shedbal | C34: Varad Petroluem | D34: =+shedbal!E38 -> 2070.14 | E34: =+shedbal!G38 -> 206443.91 | F34: =+shedbal!H38 -> 112 | G34: =+shedbal!J38 -> 12527.2 | H34: =E34+G34 -> 218971.11 | I34: =+shedbal!M3 -> 170641.05 | J34: =+shedbal!L38 -> 231000.11 | K34: =H34+I34-J34 -> 158612.05
A35: 34 | B35: Kabbur(PKG-3) | C35: Shri Jai Hanuman Petrolium | D35: =+Kabbur!E35 -> 21.58 | E35: =+Kabbur!G35 -> 2145.2678 | F35: =+Kabbur!H35 -> 14.23 | G35: =+Kabbur!J35 -> 1586.7873 | H35: =E35+G35 -> 3732.0551 | I35: 0 | J35: =+Kabbur!L35 -> 3732.0551 | K35: =H35+I35-J35 -> 0
A36: 35 | B36: Kumta (PKG-1) | C36: V.M.Mirjankar (Kumta) Bharat | D36: =+kumta!E41 -> 1518.04 | E36: =+kumta!G41 -> 151470.03 | F36: =+kumta!H41 -> 80 | G36: =+kumta!J41 -> 8958.4 | H36: =E36+G36 -> 160428.43 | I36: =kumta!M3 -> 24092.227 | J36: =+kumta!L41 -> 100000 | K36: =H36+I36-J36 -> 84520.658
A37: 36 | B37: Jalgaon-2 | C37: Nayara | D37: =+'Jalgoan-2'!E56 -> 5431 | E37: ='Jalgoan-2'!G56 -> 540438.81 | F37: =+'Jalgoan-2'!H56 -> 130 | G37: =+'Jalgoan-2'!J56 -> 14713.4 | H37: =E37+G37 -> 555152.21 | I37: =+'Jalgoan-2'!M3 -> 50000.028 | J37: =+'Jalgoan-2'!L56 -> 0 | K37: =H37+I37-J37 -> 605152.24
A38: 37 | B38: MKBD | C38: Shree Sai Samarth Petroleum | D38: =+MKBD!E42 -> 2500 | E38: =+MKBD!G42 -> 247350 | F38: =+MKBD!H42 -> 40 | G38: =+MKBD!J42 -> 4490.8 | H38: =E38+G38 -> 251840.8 | I38: =+MKBD!K3 -> 90567.01 | J38: =+MKBD!L42 -> 0 | K38: =H38+I38-J38 -> 342407.81
A39: 38 | B39: Haveri | C39: M/s Magavi City Fuels | D39: =' Haveri-2'!E42 -> 3322.91 | E39: =' Haveri-2'!G42 -> 329964.96 | F39: =' Haveri-2'!H42 -> 105.81 | G39: =' Haveri-2'!J42 -> 11806.054 | H39: =E39+G39 -> 341771.02 | I39: =' Haveri-2'!M3 -> 41052.548 | J39: =+' Haveri-2'!L42 -> 300000 | K39: =H39+I39-J39 -> 82823.565
A40: 39 | B40: Guttal-2 | C40: Himagiri Petroleum | D40: =+' Guttal-2'!E35 -> 8814 | E40: =+' Guttal-2'!G35 -> 877874.4 | F40: =+' Guttal-2'!H35 -> 208 | G40: =+' Guttal-2'!J35 -> 23235.68 | H40: =E40+G40 -> 901110.08 | I40: =+' Guttal-2'!M3 -> 408499.98 | J40: =+' Guttal-2'!L35 -> 850000 | K40: =H40+I40-J40 -> 459610.06
...

Sheet HO(DG)
A2: S.No | B2: Date | C2: GRN No | D2: Ind No/Bill No | E2: Diesel (Lts) | F2: Price | G2: Amount | H2: Petrol (Lts) | I2: Price | J2: Amount | K2: Total amount | L2: Amount paid | M2: As on date | N2: Remarks
A3: Opening Balance | K3: 0 | M3: 0
A4: 1 | B4: 46266 | G4: =E4*F4 -> 0 | H4: 0 | I4: 0 | J4: =H4*I4 -> 0 | K4: =G4+J4 -> 0 | L4: 0 | M4: =M3+K4-L4 -> 0
A5: 2 | B5: 46267 | E5: 100 | F5: 103.76 | G5: =E5*F5 -> 10376 | K5: =G5+J5 -> 10376 | L5: 10376 | M5: =M4+K5-L5 -> 0
A6: 3 | B6: 46268 | G6: =E6*F6 -> 0 | K6: =G6+J6 -> 0 | M6: =M5+K6-L6 -> 0
A7: 4 | B7: 46269 | E7: 50 | F7: 103.76 | G7: =E7*F7 -> 5188 | K7: =G7+J7 -> 5188 | L7: =H7+K7 -> 5188 | M7: =M6+K7-L7 -> 0
A8: 5 | B8: 46270 | E8: 50 | F8: 103.76 | G8: =E8*F8 -> 5188 | K8: =G8+J8 -> 5188 | L8: 5188 | M8: =M7+K8-L8 -> 0
A9: 6 | B9: 46271 | G9: =E9*F9 -> 0 | K9: =G9+J9 -> 0 | M9: =M8+K9-L9 -> 0
A10: 7 | B10: 46272 | E10: 100 | F10: 103.76 | G10: =E10*F10 -> 10376 | K10: =G10+J10 -> 10376 | L10: =H10+K10 -> 10376 | M10: =M9+K10-L10 -> 0
A11: 8 | B11: 46273 | G11: =E11*F11 -> 0 | K11: =G11+J11 -> 0 | M11: =M10+K11-L11 -> 0
A12: 9 | B12: 46274 | E12: 50 | F12: 103.76 | G12: =E12*F12 -> 5188 | K12: =G12+J12 -> 5188 | L12: 5188 | M12: =M11+K12-L12 -> 0
A13: 10 | B13: 46275 | E13: 100 | F13: 103.76 | G13: =E13*F13 -> 10376 | K13: =G13+J13 -> 10376 | L13: 10376 | M13: =M12+K13-L13 -> 0
A14: 11 | B14: 46276 | G14: =E14*F14 -> 0 | K14: =G14+J14 -> 0 | M14: =M13+K14-L14 -> 0
A15: 12 | B15: 46277 | E15: 50 | F15: 103.76 | G15: =E15*F15 -> 5188 | K15: =G15+J15 -> 5188 | L15: =H15+K15 -> 5188 | M15: =M14+K15-L15 -> 0
A16: 13 | B16: 46278 | G16: =E16*F16 -> 0 | K16: =G16+J16 -> 0 | M16: =M15+K16-L16 -> 0
A17: 14 | B17: 46279 | G17: =E17*F17 -> 0 | K17: =G17+J17 -> 0 | M17: =M16+K17-L17 -> 0
A18: 15 | B18: 46280 | E18: 50 | F18: 103.76 | G18: =E18*F18 -> 5188 | K18: =G18+J18 -> 5188 | L18: 5188 | M18: =M17+K18-L18 -> 0
A19: 16 | B19: 46281 | G19: =E19*F19 -> 0 | K19: =G19+J19 -> 0 | L19: =H19+K19 -> 0 | M19: =M18+K19-L19 -> 0
A20: 17 | B20: 46282 | E20: 100 | F20: 103.76 | G20: =E20*F20 -> 10376 | K20: =G20+J20 -> 10376 | L20: 10376 | M20: =M19+K20-L20 -> 0
A21: 18 | B21: 46283 | G21: =E21*F21 -> 0 | K21: =G21+J21 -> 0 | M21: =M20+K21-L21 -> 0
A22: 19 | B22: 46284 | E22: 90 | F22: 103.76 | G22: =E22*F22 -> 9338.4 | K22: =G22+J22 -> 9338.4 | L22: 9338.4 | M22: =M21+K22-L22 -> 0
A23: 20 | B23: 46285 | G23: =E23*F23 -> 0 | K23: =G23+J23 -> 0 | M23: =M22+K23-L23 -> 0
A24: 21 | B24: 46286 | E24: 40 | F24: 103.76 | G24: =E24*F24 -> 4150.4 | K24: =G24+J24 -> 4150.4 | L24: =H24+K24 -> 4150.4 | M24: =M23+K24-L24 -> 0
A25: 22 | B25: 46287 | E25: 100 | F25: 103.76 | G25: =E25*F25 -> 10376 | K25: =G25+J25 -> 10376 | L25: =H25+K25 -> 10376 | M25: =M24+K25-L25 -> 0
A26: 23 | B26: 46288 | E26: 50 | F26: 103.76 | G26: =E26*F26 -> 5188 | K26: =G26+J26 -> 5188 | L26: =H26+K26 -> 5188 | M26: =M25+K26-L26 -> 0
A27: 24 | B27: 46289 | E27: 33.73 | F27: 103.76 | G27: =E27*F27 -> 3499.8248 | K27: =G27+J27 -> 3499.8248 | L27: =H27+K27 -> 3499.8248 | M27: =M26+K27-L27 -> 0
A28: 25 | B28: 46290 | E28: 50 | F28: 103.76 | G28: =E28*F28 -> 5188 | K28: =G28+J28 -> 5188 | L28: =H28+K28 -> 5188 | M28: =M27+K28-L28 -> 0
A29: 26 | B29: 46291 | E29: 50 | F29: 103.76 | G29: =E29*F29 -> 5188 | K29: =G29+J29 -> 5188 | L29: =H29+K29 -> 5188 | M29: =M28+K29-L29 -> 0
A30: 27 | B30: 46292 | G30: =E30*F30 -> 0 | K30: =G30+J30 -> 0 | L30: =H30+K30 -> 0 | M30: =M29+K30-L30 -> 0
A31: 28 | B31: 46293 | E31: 50 | F31: 103.76 | G31: =E31*F31 -> 5188 | K31: =G31+J31 -> 5188 | L31: =H31+K31 -> 5188 | M31: =M30+K31-L31 -> 0
B32: 46293 | E32: 50 | F32: 103.76 | G32: =E32*F32 -> 5188 | K32: =G32+J32 -> 5188 | L32: =H32+K32 -> 5188
A33: 29 | B33: 46294 | G33: =E33*F33 -> 0 | K33: =G33+J33 -> 0 | L33: =H33+K33 -> 0 | M33: =M31+K33-L33 -> 0
A34: 30 | B34: 46295 | E34: 100 | F34: 103.76 | G34: =E34*F34 -> 10376 | K34: =G34+J34 -> 10376 | L34: =H34+K34 -> 10376 | M34: =M33+K34-L34 -> 0
A35: 31 | B35: 46296 | G35: =E35*F35 -> 0 | K35: =G35+J35 -> 0 | L35: =H35+K35 -> 0 | M35: =M34+K35-L35 -> 0
A36: 32 | B36: 46297 | G36: =E36*F36 -> 0 | K36: =G36+J36 -> 0 | L36: =H36+K36 -> 0 | M36: =M35+K36-L36 -> 0
A37: 33 | G37: =E37*F37 -> 0 | K37: =G37+J37 -> 0 | M37: =M36+K37-L37 -> 0
A38: 34 | K38: =G38+J38 -> 0 | M38: =M37+K38-L38 -> 0
A39: 35 | M39: =M38+K39-L39 -> 0
A40: 36 | M40: =M39+K40-L40 -> 0
A41: 37
...

Sheet Khammam-1
A1: Divya laxmi ganapathi
A2: S.No | B2: Date | C2: GRN No | D2: Ind No/Bill No | E2: Diesel (Lts) | F2: Price | G2: Amount | H2: Petrol (Lts) | I2: Price | J2: Amount | K2: Total amount | L2: Amount paid | M2: As 0n Date | N2: Remarks
A3: Opening Balance | K3: 2805565.2 | M3: 2805565.2 | O3: =K3-M3 -> 0
A4: 1 | B4: 46266 | E4: 2700 | F4: 103.8 | G4: =E4*F4 -> 280260 | K4: =G4+J4 -> 280260 | L4: 2826324 | M4: =M3+K4-L4 -> 259501.16
A5: 2 | B5: 46267 | G5: =E5*F5 -> 0 | J5: =H5*I5 -> 0 | K5: =G5+J5 -> 0 | M5: =M4+K5-L5 -> 259501.16
A6: 3 | B6: 46268 | G6: =E6*F6 -> 0 | J6: =H6*I6 -> 0 | K6: =G6+J6 -> 0 | M6: =M5+K6-L6 -> 259501.16
A7: 4 | B7: 46269 | E7: 2700 | F7: 103.8 | G7: =E7*F7 -> 280260 | J7: =H7*I7 -> 0 | K7: =G7+J7 -> 280260 | M7: =M6+K7-L7 -> 539761.16
A8: 5 | B8: 46270 | G8: =E8*F8 -> 0 | J8: =H8*I8 -> 0 | K8: =G8+J8 -> 0 | M8: =M7+K8-L8 -> 539761.16
A9: 6 | B9: 46271 | G9: =E9*F9 -> 0 | J9: =H9*I9 -> 0 | K9: =G9+J9 -> 0 | M9: =M8+K9-L9 -> 539761.16
A10: 7 | B10: 46272 | E10: 2700 | F10: 103.8 | G10: =E10*F10 -> 280260 | H10: 55 | I10: 115.69 | J10: =H10*I10 -> 6362.95 | K10: =G10+J10 -> 286622.95 | M10: =M9+K10-L10 -> 826384.11
A11: 8 | B11: 46273 | E11: 2800 | F11: 103.8 | G11: =E11*F11 -> 290640 | J11: =H11*I11 -> 0 | K11: =G11+J11 -> 290640 | M11: =M10+K11-L11 -> 1117024.1
A12: 9 | B12: 46274 | G12: =E12*F12 -> 0 | J12: =H12*I12 -> 0 | K12: =G12+J12 -> 0 | M12: =M11+K12-L12 -> 1117024.1
A13: 10 | B13: 46275 | E13: 2700 | F13: 103.8 | G13: =E13*F13 -> 280260 | J13: =H13*I13 -> 0 | K13: =G13+J13 -> 280260 | M13: =M12+K13-L13 -> 1397284.1
A14: 11 | B14: 46276 | E14: 2700 | F14: 103.8 | G14: =E14*F14 -> 280260 | J14: =H14*I14 -> 0 | K14: =G14+J14 -> 280260 | M14: =M13+K14-L14 -> 1677544.1
A15: 12 | B15: 46277 | G15: =E15*F15 -> 0 | J15: =H15*I15 -> 0 | K15: =G15+J15 -> 0 | M15: =M14+K15-L15 -> 1677544.1
A16: 13 | B16: 46278 | G16: =E16*F16 -> 0 | H16: 130 | I16: 115.69 | J16: =H16*I16 -> 15039.7 | K16: =G16+J16 -> 15039.7 | M16: =M15+K16-L16 -> 1692583.8
A17: 14 | B17: 46279 | G17: =E17*F17 -> 0 | J17: =H17*I17 -> 0 | K17: =G17+J17 -> 0 | M17: =M16+K17-L17 -> 1692583.8
A18: 15 | B18: 46280 | G18: =E18*F18 -> 0 | J18: =H18*I18 -> 0 | K18: =G18+J18 -> 0 | M18: =M17+K18-L18 -> 1692583.8
A19: 16 | B19: 46281 | E19: 2700 | F19: 103.8 | G19: =E19*F19 -> 280260 | J19: =H19*I19 -> 0 | K19: =G19+J19 -> 280260 | M19: =M18+K19-L19 -> 1972843.8
A20: 17 | B20: 46282 | G20: =E20*F20 -> 0 | J20: =H20*I20 -> 0 | K20: =G20+J20 -> 0 | M20: =M19+K20-L20 -> 1972843.8
A21: 18 | B21: 46283 | E21: 2700 | F21: 103.8 | G21: =E21*F21 -> 280260 | J21: =H21*I21 -> 0 | K21: =G21+J21 -> 280260 | M21: =M20+K21-L21 -> 2253103.8
A22: 19 | B22: 46284 | E22: 3000 | F22: 103.8 | G22: =E22*F22 -> 311400 | J22: =H22*I22 -> 0 | K22: =G22+J22 -> 311400 | M22: =M21+K22-L22 -> 2564503.8
A23: 20 | B23: 46285 | G23: =E23*F23 -> 0 | J23: =H23*I23 -> 0 | K23: =G23+J23 -> 0 | M23: =M22+K23-L23 -> 2564503.8
A24: 21 | B24: 46286 | E24: 2700 | F24: 103.8 | G24: =E24*F24 -> 280260 | J24: =H24*I24 -> 0 | K24: =G24+J24 -> 280260 | M24: =M23+K24-L24 -> 2844763.8
A25: 22 | B25: 46287 | E25: 800 | F25: 103.8 | G25: =E25*F25 -> 83040 | J25: =H25*I25 -> 0 | K25: =G25+J25 -> 83040 | M25: =M24+K25-L25 -> 2927803.8
A26: 23 | B26: 46288 | G26: =E26*F26 -> 0 | J26: =H26*I26 -> 0 | K26: =G26+J26 -> 0 | M26: =M25+K26-L26 -> 2927803.8
A27: 24 | B27: 46289 | E27: 2500 | F27: 103.8 | G27: =E27*F27 -> 259500 | J27: =H27*I27 -> 0 | K27: =G27+J27 -> 259500 | M27: =M26+K27-L27 -> 3187303.8
A28: 25 | B28: 46290 | E28: 3700 | F28: 103.8 | G28: =E28*F28 -> 384060 | J28: =H28*I28 -> 0 | K28: =G28+J28 -> 384060 | M28: =M27+K28-L28 -> 3571363.8
A29: 26 | B29: 46291 | G29: =E29*F29 -> 0 | J29: =H29*I29 -> 0 | K29: =G29+J29 -> 0 | M29: =M28+K29-L29 -> 3571363.8
A30: 27 | B30: 46292 | G30: =E30*F30 -> 0 | J30: =H30*I30 -> 0 | K30: =G30+J30 -> 0 | M30: =M29+K30-L30 -> 3571363.8
A31: 28 | B31: 46293 | G31: =E31*F31 -> 0 | J31: =H31*I31 -> 0 | K31: =G31+J31 -> 0 | M31: =M30+K31-L31 -> 3571363.8
A32: 29 | B32: 46294 | E32: 2700 | F32: 103.8 | G32: =E32*F32 -> 280260 | J32: =H32*I32 -> 0 | K32: =G32+J32 -> 280260 | M32: =M31+K32-L32 -> 3851623.8
A33: 30 | B33: 46295 | E33: 2700 | F33: 103.8 | G33: =E33*F33 -> 280260 | J33: =H33*I33 -> 0 | K33: =G33+J33 -> 280260 | M33: =M32+K33-L33 -> 4131883.8
A34: 31 | B34: 46296 | G34: =E34*F34 -> 0 | K34: =G34+J34 -> 0 | M34: =M33+K34-L34 -> 4131883.8
A35: 32 | G35: =E35*F35 -> 0 | J35: =H35*I35 -> 0 | K35: =G35+J35 -> 0 | M35: =M34+K35-L35 -> 4131883.8
A36: 33 | G36: =E36*F36 -> 0 | J36: =H36*I36 -> 0 | K36: =G36+J36 -> 0
A37: 34 | G37: =E37*F37 -> 0 | J37: =H37*I37 -> 0 | K37: =G37+J37 -> 0
E38: =SUM(E3:E37) -> 39800 | G38: =SUM(G3:G37) -> 4131240 | H38: =SUM(H3:H37) -> 185 | J38: =SUM(J3:J37) -> 21402.65 | K38: =SUM(K4:K37) -> 4152642.6 | L38: =SUM(L3:L37) -> 2826324

Sheet Khammam-2
A1: Jayasai union bunk
A2: S.No | B2: Date | C2: GRN No | D2: Ind No/Bill No | E2: Diesel (Lts) | F2: Price | G2: Amount | H2: Petrol (Lts) | I2: Price | J2: Amount | K2: Total amount | L2: Amount paid | M2: As 0n Date | N2: Remarks
A3: Opening Balance | K3: 0 | M3: 0
A4: 1 | B4: 46266 | G4: =E4*F4 -> 0 | J4: =H4*I4 -> 0 | K4: =G4+J4 -> 0 | M4: =M3+K4-L4 -> 0
A5: 2 | B5: 46267 | E5: 2500 | F5: 103.82 | G5: =E5*F5 -> 259550 | J5: =H5*I5 -> 0 | K5: =G5+J5 -> 259550 | M5: =M4+K5-L5 -> 259550
A6: 3 | B6: 46268 | G6: =E6*F6 -> 0 | J6: =H6*I6 -> 0 | K6: =G6+J6 -> 0 | M6: =M5+K6-L6 -> 259550
A7: 4 | B7: 46269 | G7: =E7*F7 -> 0 | J7: =H7*I7 -> 0 | K7: =G7+J7 -> 0 | M7: =M6+K7-L7 -> 259550
A8: 5 | B8: 46270 | E8: 2800 | F8: 103.82 | G8: =E8*F8 -> 290696 | J8: =H8*I8 -> 0 | K8: =G8+J8 -> 290696 | M8: =M7+K8-L8 -> 550246
A9: 6 | B9: 46271 | G9: =E9*F9 -> 0 | J9: =H9*I9 -> 0 | K9: =G9+J9 -> 0 | M9: =M8+K9-L9 -> 550246
A10: 7 | B10: 46272 | E10: 2700 | F10: 103.82 | G10: =E10*F10 -> 280314 | J10: =H10*I10 -> 0 | K10: =G10+J10 -> 280314 | M10: =M9+K10-L10 -> 830560
A11: 8 | B11: 46273 | E11: 2700 | F11: 103.82 | G11: =E11*F11 -> 280314 | H11: 50 | I11: 115.72 | J11: =H11*I11 -> 5786 | K11: =G11+J11 -> 286100 | M11: =M10+K11-L11 -> 1116660
A12: 9 | B12: 46274 | G12: =E12*F12 -> 0 | J12: =H12*I12 -> 0 | K12: =G12+J12 -> 0 | M12: =M11+K12-L12 -> 1116660
A13: 10 | B13: 46275 | E13: 2700 | F13: 103.82 | G13: =E13*F13 -> 280314 | J13: =H13*I13 -> 0 | K13: =G13+J13 -> 280314 | M13: =M12+K13-L13 -> 1396974 | V13: 250000
A14: 11 | B14: 46276 | E14: 2700 | F14: 103.82 | G14: =E14*F14 -> 280314 | J14: =H14*I14 -> 0 | K14: =G14+J14 -> 280314 | M14: =M13+K14-L14 -> 1677288 | V14: 70000
A15: 12 | B15: 46277 | E15: 3900 | F15: 103.82 | G15: =E15*F15 -> 404898 | J15: =H15*I15 -> 0 | K15: =G15+J15 -> 404898 | M15: =M14+K15-L15 -> 2082186 | V15: 46366
A16: 13 | B16: 46278 | G16: =E16*F16 -> 0 | J16: =H16*I16 -> 0 | K16: =G16+J16 -> 0 | M16: =M15+K16-L16 -> 2082186
A17: 14 | B17: 46279 | E17: 1200 | F17: 103.82 | G17: =E17*F17 -> 124584 | J17: =H17*I17 -> 0 | K17: =G17+J17 -> 124584 | M17: =M16+K17-L17 -> 2206770
A18: 15 | B18: 46280 | G18: =E18*F18 -> 0 | J18: =H18*I18 -> 0 | K18: =G18+J18 -> 0 | M18: =M17+K18-L18 -> 2206770
A19: 16 | B19: 46281 | E19: 2700 | F19: 103.82 | G19: =E19*F19 -> 280314 | J19: =H19*I19 -> 0 | K19: =G19+J19 -> 280314 | M19: =M18+K19-L19 -> 2487084
A20: 17 | B20: 46282 | G20: =E20*F20 -> 0 | J20: =H20*I20 -> 0 | K20: =G20+J20 -> 0 | M20: =M19+K20-L20 -> 2487084
A21: 18 | B21: 46283 | G21: =E21*F21 -> 0 | J21: =H21*I21 -> 0 | K21: =G21+J21 -> 0 | M21: =M20+K21-L21 -> 2487084
A22: 19 | B22: 46284 | G22: =E22*F22 -> 0 | J22: =H22*I22 -> 0 | K22: =G22+J22 -> 0 | M22: =M21+K22-L22 -> 2487084
A23: 20 | B23: 46285 | G23: =E23*F23 -> 0 | J23: =H23*I23 -> 0 | K23: =G23+J23 -> 0 | M23: =M22+K23-L23 -> 2487084
A24: 21 | B24: 46286 | E24: 5400 | F24: 103.82 | G24: =E24*F24 -> 560628 | J24: =H24*I24 -> 0 | K24: =G24+J24 -> 560628 | M24: =M23+K24-L24 -> 3047712
B25: 46286 | D25: 26-27/S1 (MP3 Grease) | E25: 546 | F25: 332.76 | G25: =E25*F25 -> 181686.96 | K25: =G25+J25 -> 181686.96 | M25: =M24+K25-L25 -> 3229399
A26: 22 | B26: 46287 | G26: =E26*F26 -> 0 | J26: =H26*I26 -> 0 | K26: =G26+J26 -> 0 | M26: =M25+K26-L26 -> 3229399
A27: 23 | B27: 46288 | E27: 2700 | F27: 103.82 | G27: =E27*F27 -> 280314 | J27: =H27*I27 -> 0 | K27: =G27+J27 -> 280314 | M27: =M26+K27-L27 -> 3509713
A28: 24 | B28: 46289 | E28: 2700 | F28: 103.82 | G28: =E28*F28 -> 280314 | H28: 55 | I28: 115.72 | J28: =H28*I28 -> 6364.6 | K28: =G28+J28 -> 286678.6 | M28: =M27+K28-L28 -> 3796391.6
A29: 25 | B29: 46290 | G29: =E29*F29 -> 0 | J29: =H29*I29 -> 0 | K29: =G29+J29 -> 0 | M29: =M28+K29-L29 -> 3796391.6
A30: 26 | B30: 46291 | E30: 2700 | F30: 103.82 | G30: =E30*F30 -> 280314 | H30: 50 | I30: 115.72 | J30: =H30*I30 -> 5786 | K30: =G30+J30 -> 286100 | M30: =M29+K30-L30 -> 4082491.6
A31: 27 | B31: 46292 | E31: 800 | F31: 103.82 | G31: =E31*F31 -> 83056 | J31: =H31*I31 -> 0 | K31: =G31+J31 -> 83056 | M31: =M30+K31-L31 -> 4165547.6
A32: 28 | B32: 46293 | E32: 800 | F32: 103.82 | G32: =E32*F32 -> 83056 | J32: =H32*I32 -> 0 | K32: =G32+J32 -> 83056 | M32: =M31+K32-L32 -> 4248603.6
A33: 29 | B33: 46294 | G33: =E33*F33 -> 0 | J33: =H33*I33 -> 0 | K33: =G33+J33 -> 0 | M33: =M32+K33-L33 -> 4248603.6
A34: 30 | B34: 46295 | G34: =E34*F34 -> 0 | J34: =H34*I34 -> 0 | K34: =G34+J34 -> 0 | M34: =M33+K34-L34 -> 4248603.6
A35: 31 | B35: 46296 | G35: =E35*F35 -> 0 | J35: =H35*I35 -> 0 | K35: =G35+J35 -> 0 | M35: =M34+K35-L35 -> 4248603.6
A36: 32 | G36: =E36*F36 -> 0 | J36: =H36*I36 -> 0 | K36: =G36+J36 -> 0 | M36: =M35+K36-L36 -> 4248603.6
A37: 33 | G37: =E37*F37 -> 0 | J37: =H37*I37 -> 0 | K37: =G37+J37 -> 0 | M37: =M36+K37-L37 -> 4248603.6
E39: =SUM(E4:E37) -> 39546 | G39: =SUM(G4:G37) -> 4230667 | H39: =SUM(H4:H37) -> 155 | J39: =SUM(J4:J37) -> 17936.6 | K39: =SUM(K4:K37) -> 4248603.6 | L39: =SUM(L4:L37) -> 0

Sheet Khammam-4
A1: Sai Madeana Filling Station
A2: S.No | B2: Date | C2: GRN No | D2: Ind No/Bill No | E2: Diesel (Lts) | F2: Price | G2: Amount | H2: Petrol (Lts) | I2: Price | J2: Amount | K2: Total amount | L2: Amount paid | M2: As 0n Date | N2: Remarks
A3: Opening Balance | K3: 843364.3 | M3: 843364.3
A4: 1 | B4: 46235 | G4: =E4*F4 -> 0 | J4: =H4*I4 -> 0 | K4: =G4+J4 -> 0 | M4: =M3+K4-L4 -> 843364.3
A5: 2 | B5: 46236 | G5: =E5*F5 -> 0 | J5: =H5*I5 -> 0 | K5: =G5+J5 -> 0 | M5: =M4+K5-L5 -> 843364.3
A6: 3 | B6: 46237 | E6: 2700 | F6: 103.62 | G6: =E6*F6 -> 279774 | H6: 40 | I6: 115.49 | J6: =H6*I6 -> 4619.6 | K6: =G6+J6 -> 284393.6 | M6: =M5+K6-L6 -> 1127757.9
A7: 4 | B7: 46238 | G7: =E7*F7 -> 0 | J7: =H7*I7 -> 0 | K7: =G7+J7 -> 0 | M7: =M6+K7-L7 -> 1127757.9
A8: 5 | B8: 46239 | G8: =E8*F8 -> 0 | J8: =H8*I8 -> 0 | K8: =G8+J8 -> 0 | M8: =M7+K8-L8 -> 1127757.9
A9: 6 | B9: 46240 | E9: 2700 | F9: 103.62 | G9: =E9*F9 -> 279774 | H9: 90 | I9: 115.49 | J9: =H9*I9 -> 10394.1 | K9: =G9+J9 -> 290168.1 | M9: =M8+K9-L9 -> 1417926
A10: 7 | B10: 46241 | G10: =E10*F10 -> 0 | J10: =H10*I10 -> 0 | K10: =G10+J10 -> 0 | M10: =M9+K10-L10 -> 1417926
A11: 8 | B11: 46242 | E11: 2700 | F11: 103.62 | G11: =E11*F11 -> 279774 | H11: 35 | I11: 115.49 | J11: =H11*I11 -> 4042.15 | K11: =G11+J11 -> 283816.15 | M11: =M10+K11-L11 -> 1701742.1
A12: 9 | B12: 46243 | G12: =E12*F12 -> 0 | J12: =H12*I12 -> 0 | K12: =G12+J12 -> 0 | M12: =M11+K12-L12 -> 1701742.1
A13: 10 | B13: 46244 | E13: 2700 | F13: 103.62 | G13: =E13*F13 -> 279774 | H13: 55 | I13: 115.49 | J13: =H13*I13 -> 6351.95 | K13: =G13+J13 -> 286125.95 | M13: =M12+K13-L13 -> 1987868.1
A14: 11 | B14: 46245 | G14: =E14*F14 -> 0 | J14: =H14*I14 -> 0 | K14: =G14+J14 -> 0 | M14: =M13+K14-L14 -> 1987868.1
A15: 12 | B15: 46246 | G15: =E15*F15 -> 0 | J15: =H15*I15 -> 0 | K15: =G15+J15 -> 0 | M15: =M14+K15-L15 -> 1987868.1
A16: 13 | B16: 46247 | G16: =E16*F16 -> 0 | J16: =H16*I16 -> 0 | K16: =G16+J16 -> 0 | M16: =M15+K16-L16 -> 1987868.1
A17: 14 | B17: 46248 | G17: =E17*F17 -> 0 | J17: =H17*I17 -> 0 | K17: =G17+J17 -> 0 | M17: =M16+K17-L17 -> 1987868.1
A18: 15 | B18: 46249 | G18: =E18*F18 -> 0 | J18: =H18*I18 -> 0 | K18: =G18+J18 -> 0 | M18: =M17+K18-L18 -> 1987868.1
A19: 16 | B19: 46250 | G19: =E19*F19 -> 0 | J19: =H19*I19 -> 0 | K19: =G19+J19 -> 0 | M19: =M18+K19-L19 -> 1987868.1
A20: 17 | B20: 46251 | E20: 2700 | F20: 103.62 | G20: =E20*F20 -> 279774 | H20: 75 | I20: 115.49 | J20: =H20*I20 -> 8661.75 | K20: =G20+J20 -> 288435.75 | M20: =M19+K20-L20 -> 2276303.8
A21: 18 | B21: 46252 | G21: =E21*F21 -> 0 | J21: =H21*I21 -> 0 | K21: =G21+J21 -> 0 | M21: =M20+K21-L21 -> 2276303.8
A22: 19 | B22: 46253 | E22: 2700 | F22: 103.62 | G22: =E22*F22 -> 279774 | H22: 75 | I22: 115.49 | J22: =H22*I22 -> 8661.75 | K22: =G22+J22 -> 288435.75 | M22: =M21+K22-L22 -> 2564739.6
A23: 20 | B23: 46254 | G23: =E23*F23 -> 0 | J23: =H23*I23 -> 0 | K23: =G23+J23 -> 0 | M23: =M22+K23-L23 -> 2564739.6
A24: 21 | B24: 46255 | G24: =E24*F24 -> 0 | J24: =H24*I24 -> 0 | K24: =G24+J24 -> 0 | M24: =M23+K24-L24 -> 2564739.6
A25: 22 | B25: 46256 | E25: 2700 | F25: 103.62 | G25: =E25*F25 -> 279774 | H25: 75 | I25: 115.49 | J25: =H25*I25 -> 8661.75 | K25: =G25+J25 -> 288435.75 | M25: =M24+K25-L25 -> 2853175.3
A26: 23 | B26: 46257 | G26: =E26*F26 -> 0 | J26: =H26*I26 -> 0 | K26: =G26+J26 -> 0 | M26: =M25+K26-L26 -> 2853175.3
A27: 24 | B27: 46258 | G27: =E27*F27 -> 0 | J27: =H27*I27 -> 0 | K27: =G27+J27 -> 0 | M27: =M26+K27-L27 -> 2853175.3
A28: 25 | B28: 46259 | G28: =E28*F28 -> 0 | J28: =H28*I28 -> 0 | K28: =G28+J28 -> 0 | M28: =M27+K28-L28 -> 2853175.3
A29: 26 | B29: 46260 | G29: =E29*F29 -> 0 | J29: =H29*I29 -> 0 | K29: =G29+J29 -> 0 | M29: =M28+K29-L29 -> 2853175.3
A30: 27 | B30: 46261 | G30: =E30*F30 -> 0 | J30: =H30*I30 -> 0 | K30: =G30+J30 -> 0 | M30: =M29+K30-L30 -> 2853175.3
A31: 28 | B31: 46262 | E31: 2700 | F31: 103.62 | G31: =E31*F31 -> 279774 | H31: 75 | I31: 115.49 | J31: =H31*I31 -> 8661.75 | K31: =G31+J31 -> 288435.75 | M31: =M30+K31-L31 -> 3141611.1
A32: 29 | B32: 46263 | E32: 2700 | F32: 103.62 | G32: =E32*F32 -> 279774 | H32: 20 | I32: 115.49 | J32: =H32*I32 -> 2309.8 | K32: =G32+J32 -> 282083.8 | L32: 282083.8 | M32: =M31+K32-L32 -> 3141611.1
A33: 30 | B33: 46264 | E33: 2700 | F33: 103.62 | G33: =E33*F33 -> 279774 | H33: 55 | I33: 115.49 | J33: =H33*I33 -> 6351.95 | K33: =G33+J33 -> 286125.95 | L33: 286125.95 | M33: =M32+K33-L33 -> 3141611.1
A34: 31 | B34: 46265 | G34: =E34*F34 -> 0 | J34: =H34*I34 -> 0 | K34: =G34+J34 -> 0 | M34: =M33+K34-L34 -> 3141611.1
E35: =SUM(E4:E34) -> 27000 | G35: =SUM(G4:G34) -> 2797740 | H35: =SUM(H4:H34) -> 595 | J35: =SUM(J4:J34) -> 68716.55 | K35: =SUM(K4:K34) -> 2866456.5 | L35: =SUM(L4:L34) -> 568209.75

Sheet  Khammam-5
A1: Vajra mahalakshmi filling station
A2: S.No | B2: Date | C2: GRN No | D2: Ind No/Bill No | E2: Diesel (Lts) | F2: Price | G2: Amount | H2: Petrol (Lts) | I2: Price | J2: Amount | K2: Total amount | L2: Amount paid | M2: As 0n Date | N2: Remarks
A3: Opening Balance | K3: 578571.8 | M3: 578571.8
A4: 1 | B4: 46266 | E4: 2800 | F4: 103.62 | G4: =E4*F4 -> 290136 | H4: 75 | I4: 115.49 | J4: =H4*I4 -> 8661.75 | K4: =G4+J4 -> 298797.75 | M4: =M3+K4-L4 -> 877369.55
A5: 2 | B5: 46267 | E5: 2700 | F5: 103.62 | G5: =E5*F5 -> 279774 | H5: 35 | I5: 115.49 | J5: =H5*I5 -> 4042.15 | K5: =G5+J5 -> 283816.15 | M5: =M4+K5-L5 -> 1161185.7
A6: 3 | B6: 46268 | G6: =E6*F6 -> 0 | J6: =H6*I6 -> 0 | K6: =G6+J6 -> 0 | M6: =M5+K6-L6 -> 1161185.7
A7: 4 | B7: 46269 | G7: =E7*F7 -> 0 | J7: =H7*I7 -> 0 | K7: =G7+J7 -> 0 | M7: =M6+K7-L7 -> 1161185.7
A8: 5 | B8: 46270 | G8: =E8*F8 -> 0 | J8: =H8*I8 -> 0 | K8: =G8+J8 -> 0 | M8: =M7+K8-L8 -> 1161185.7
A9: 6 | B9: 46271 | G9: =E9*F9 -> 0 | J9: =H9*I9 -> 0 | K9: =G9+J9 -> 0 | M9: =M8+K9-L9 -> 1161185.7
A10: 7 | B10: 46272 | G10: =E10*F10 -> 0 | J10: =H10*I10 -> 0 | K10: =G10+J10 -> 0 | M10: =M9+K10-L10 -> 1161185.7
A11: 8 | B11: 46273 | G11: =E11*F11 -> 0 | J11: =H11*I11 -> 0 | K11: =G11+J11 -> 0 | M11: =M10+K11-L11 -> 1161185.7
A12: 9 | B12: 46274 | G12: =E12*F12 -> 0 | J12: =H12*I12 -> 0 | K12: =G12+J12 -> 0 | M12: =M11+K12-L12 -> 1161185.7
A13: 10 | B13: 46275 | G13: =E13*F13 -> 0 | J13: =H13*I13 -> 0 | K13: =G13+J13 -> 0 | M13: =M12+K13-L13 -> 1161185.7
A14: 11 | B14: 46276 | G14: =E14*F14 -> 0 | J14: =H14*I14 -> 0 | K14: =G14+J14 -> 0 | M14: =M13+K14-L14 -> 1161185.7
A15: 12 | B15: 46277 | G15: =E15*F15 -> 0 | J15: =H15*I15 -> 0 | K15: =G15+J15 -> 0 | M15: =M14+K15-L15 -> 1161185.7
A16: 13 | B16: 46278 | G16: =E16*F16 -> 0 | J16: =H16*I16 -> 0 | K16: =G16+J16 -> 0 | M16: =M15+K16-L16 -> 1161185.7
A17: 14 | B17: 46279 | G17: =E17*F17 -> 0 | J17: =H17*I17 -> 0 | K17: =G17+J17 -> 0 | M17: =M16+K17-L17 -> 1161185.7
A18: 15 | B18: 46280 | E18: 2700 | F18: 103.62 | G18: =E18*F18 -> 279774 | H18: 35 | I18: 115.49 | J18: =H18*I18 -> 4042.15 | K18: =G18+J18 -> 283816.15 | M18: =M17+K18-L18 -> 1445001.9
A19: 16 | B19: 46281 | G19: =E19*F19 -> 0 | J19: =H19*I19 -> 0 | K19: =G19+J19 -> 0 | M19: =M18+K19-L19 -> 1445001.9
A20: 17 | B20: 46282 | G20: =E20*F20 -> 0 | J20: =H20*I20 -> 0 | K20: =G20+J20 -> 0 | M20: =M19+K20-L20 -> 1445001.9
A21: 18 | B21: 46283 | G21: =E21*F21 -> 0 | J21: =H21*I21 -> 0 | K21: =G21+J21 -> 0 | M21: =M20+K21-L21 -> 1445001.9
A22: 19 | B22: 46284 | G22: =E22*F22 -> 0 | J22: =H22*I22 -> 0 | K22: =G22+J22 -> 0 | M22: =M21+K22-L22 -> 1445001.9
A23: 20 | B23: 46285 | G23: =E23*F23 -> 0 | J23: =H23*I23 -> 0 | K23: =G23+J23 -> 0 | M23: =M22+K23-L23 -> 1445001.9
A24: 21 | B24: 46286 | G24: =E24*F24 -> 0 | J24: =H24*I24 -> 0 | K24: =G24+J24 -> 0 | M24: =M23+K24-L24 -> 1445001.9
A25: 22 | B25: 46287 | G25: =E25*F25 -> 0 | J25: =H25*I25 -> 0 | K25: =G25+J25 -> 0 | M25: =M24+K25-L25 -> 1445001.9
A26: 23 | B26: 46288 | G26: =E26*F26 -> 0 | J26: =H26*I26 -> 0 | K26: =G26+J26 -> 0 | M26: =M25+K26-L26 -> 1445001.9
A27: 24 | B27: 46289 | G27: =E27*F27 -> 0 | J27: =H27*I27 -> 0 | K27: =G27+J27 -> 0 | M27: =M26+K27-L27 -> 1445001.9
A28: 25 | B28: 46290 | G28: =E28*F28 -> 0 | J28: =H28*I28 -> 0 | K28: =G28+J28 -> 0 | M28: =M27+K28-L28 -> 1445001.9
A29: 26 | B29: 46291 | G29: =E29*F29 -> 0 | J29: =H29*I29 -> 0 | K29: =G29+J29 -> 0 | M29: =M28+K29-L29 -> 1445001.9
A30: 27 | B30: 46292 | G30: =E30*F30 -> 0 | J30: =H30*I30 -> 0 | K30: =G30+J30 -> 0 | M30: =M29+K30-L30 -> 1445001.9
... A33: 30 | B33: 46295 | G33: =E33*F33 -> 0 | J33: =H33*I33 -> 0 | K33: =G33+J33 -> 0 | M33: =M32+K33-L33 -> 1445001.9
A34: 31 | G34: =E34*F34 -> 0 | J34: =H34*I34 -> 0 | K34: =G34+J34 -> 0 | M34: =M33+K34-L34 -> 1445001.9
E35: =SUM(E4:E34) -> 8200 | G35: =SUM(G4:G34) -> 849684 | H35: =SUM(H4:H34) -> 145 | J35: =SUM(J4:J34) -> 16746.05 | K35: =SUM(K4:K34) -> 866430.05 | L35: =SUM(L4:L34) -> 0

Sheet  Khammam&Cash
A1: Cash &Carry
A2: S.No | B2: Date | D2: Ind No/Bill No | E2: Diesel (Lts) | F2: Price | G2: Amount | H2: Petrol (Lts) | I2: Price | J2: Amount | K2: Total amount | L2: Amount paid | M2: As 0n Date | N2: Remarks
A3: Opening Balance | K3: 0 | M3: 0
A4: 1 | G4: =E4*F4 -> 0 | K4: =G4+J4 -> 0 | L4: =H4+K4 -> 0 | M4: =M3+K4-L4 -> 0
A5: 2 | G5: =E5*F5 -> 0 | J5: =H5*I5 -> 0 | K5: =G5+J5 -> 0 | L5: =H5+K5 -> 0 | M5: =M4+K5-L5 -> 0
A6: 3 | G6: =E6*F6 -> 0 | J6: =H6*I6 -> 0 | K6: =G6+J6 -> 0 | L6: =H6+K6 -> 0 | M6: =M5+K6-L6 -> 0
A7: 4 | G7: =E7*F7 -> 0 | J7: =H7*I7 -> 0 | K7: =G7+J7 -> 0 | L7: =H7+K7 -> 0 | M7: =M6+K7-L7 -> 0
A8: 5 | G8: =E8*F8 -> 0 | J8: =H8*I8 -> 0 | K8: =G8+J8 -> 0 | L8: =H8+K8 -> 0 | M8: =M7+K8-L8 -> 0
A9: 6 | G9: =E9*F9 -> 0 | J9: =H9*I9 -> 0 | K9: =G9+J9 -> 0 | L9: =H9+K9 -> 0 | M9: =M8+K9-L9 -> 0
A10: 7 | G10: =E10*F10 -> 0 | J10: =H10*I10 -> 0 | K10: =G10+J10 -> 0 | L10: =H10+K10 -> 0 | M10: =M9+K10-L10 -> 0
A11: 8 | G11: =E11*F11 -> 0 | J11: =H11*I11 -> 0 | K11: =G11+J11 -> 0 | L11: =H11+K11 -> 0 | M11: =M10+K11-L11 -> 0
A12: 9 | G12: =E12*F12 -> 0 | J12: =H12*I12 -> 0 | K12: =G12+J12 -> 0 | L12: =H12+K12 -> 0 | M12: =M11+K12-L12 -> 0
A13: 10 | G13: =E13*F13 -> 0 | J13: =H13*I13 -> 0 | K13: =G13+J13 -> 0 | L13: =H13+K13 -> 0 | M13: =M12+K13-L13 -> 0
A14: 11 | G14: =E14*F14 -> 0 | J14: =H14*I14 -> 0 | K14: =G14+J14 -> 0 | L14: =H14+K14 -> 0 | M14: =M13+K14-L14 -> 0
A15: 12 | G15: =E15*F15 -> 0 | J15: =H15*I15 -> 0 | K15: =G15+J15 -> 0 | L15: =H15+K15 -> 0 | M15: =M14+K15-L15 -> 0
A16: 13 | G16: =E16*F16 -> 0 | J16: =H16*I16 -> 0 | K16: =G16+J16 -> 0 | L16: =H16+K16 -> 0 | M16: =M15+K16-L16 -> 0
... A22: 19 | G22: =E22*F22 -> 0 | J22: =H22*I22 -> 0 | K22: =G22+J22 -> 0 | L22: =H22+K22 -> 0 | M22: =M21+K22-L22 -> 0
A23: 20 | G23: =E23*F23 -> 0 | J23: =H23*I23 -> 0 | K23: =G23+J23 -> 0 | L23: 0 | M23: =M22+K23-L23 -> 0
A24: 21 | G24: =E24*F24 -> 0 | J24: =H24*I24 -> 0 | K24: =G24+J24 -> 0 | L24: =H24+K24 -> 0 | M24: =M23+K24-L24 -> 0
A25: 22 | G25: =E25*F25 -> 0 | J25: =H25*I25 -> 0 | K25: =G25+J25 -> 0 | L25: =H25+K25 -> 0 | M25: =M24+K25-L25 -> 0
A26: 23 | G26: =E26*F26 -> 0 | J26: =H26*I26 -> 0 | K26: =G26+J26 -> 0 | L26: =H26+K26 -> 0 | M26: =M25+K26-L26 -> 0
A27: 24 | G27: =E27*F27 -> 0 | K27: =G27+J27 -> 0 | L27: =H27+K27 -> 0 | M27: =M26+K27-L27 -> 0
A28: 25 | G28: =E28*F28 -> 0 | J28: =H28*I28 -> 0 | K28: =G28+J28 -> 0 | L28: =H28+K28 -> 0 | M28: =M26+K28-L28 -> 0
A29: 26 | G29: =E29*F29 -> 0 | J29: =H29*I29 -> 0 | K29: =G29+J29 -> 0 | L29: =H29+K29 -> 0 | M29: =M28+K29-L29 -> 0
A30: 27 | G30: =E30*F30 -> 0 | J30: =H30*I30 -> 0 | K30: =G30+J30 -> 0 | L30: =H30+K30 -> 0 | M30: =M29+K30-L30 -> 0
A31: 28 | G31: =E31*F31 -> 0 | J31: =H31*I31 -> 0 | K31: =G31+J31 -> 0 | L31: =H31+K31 -> 0 | M31: =M30+K31-L31 -> 0
A32: 29 | G32: =E32*F32 -> 0 | J32: =H32*I32 -> 0 | K32: =G32+J32 -> 0 | L32: =H32+K32 -> 0 | M32: =M31+K32-L32 -> 0
A33: 30 | G33: =E33*F33 -> 0 | J33: =H33*I33 -> 0 | K33: =G33+J33 -> 0 | L33: =H33+K33 -> 0 | M33: =M32+K33-L33 -> 0
A34: 31 | G34: =E34*F34 -> 0 | J34: =H34*I34 -> 0 | K34: =G34+J34 -> 0 | L34: =H34+K34 -> 0 | M34: =M33+K34-L34 -> 0
A35: 32 | G35: =E35*F35 -> 0 | K35: =G35+J35 -> 0 | L35: =H35+K35 -> 0 | M35: =M34+K35-L35 -> 0
A36: 33 | G36: =E36*F36 -> 0 | J36: =H36*I36 -> 0 | K36: =G36+J36 -> 0 | L36: =H36+K36 -> 0 | M36: =M35+K36-L36 -> 0
A37: 34 | G37: =E37*F37 -> 0 | J37: =H37*I37 -> 0 | K37: =G37+J37 -> 0 | L37: =H37+K37 -> 0 | M37: =M36+K37-L37 -> 0
G38: =E38*F38 -> 0 | K38: =G38+J38 -> 0 | L38: =H38+K38 -> 0 | M38: =M37+K38-L38 -> 0
G39: =E39*F39 -> 0 | K39: =G39+J39 -> 0 | L39: =H39+K39 -> 0 | M39: =M38+K39-L39 -> 0
G40: =E40*F40 -> 0 | K40: =G40+J40 -> 0 | L40: =H40+K40 -> 0 | M40: =M39+K40-L40 -> 0
M41: =M40+K41-L41 -> 0
A45: 35 | G45: =E45*F45 -> 0 | J45: =H45*I45 -> 0 | K45: =G45+J45 -> 0
E46: =SUM(E3:E45) -> 0 | G46: =SUM(G3:G45) -> 0 | H46: =SUM(H3:H45) -> 0 | J46: =SUM(J3:J45) -> 0 | K46: =SUM(K4:K45) -> 0 | L46: =SUM(L3:L45) -> 0

Sheet Jadcherla-4
A1: Shree Poornima F/S
A2: S.No | B2: Date | C2: GRN No | D2: Ind No/Bill No | E2: Diesel (Lts) | F2: Price | G2: Amount | H2: Petrol (Lts) | I2: Price | J2: Amount | K2: Total amount | L2: Amount paid | M2: As on date | N2: Remarks
A3: Opening Balance | M3: 2600.28
A4: 1 | B4: 46266 | G4: =E4*F4 -> 0 | J4: =H4*I4 -> 0 | K4: =G4+J4 -> 0 | L4: 0 | M4: =M3+K4-L4 -> 2600.28
A5: 2 | B5: 46267 | E5: 200 | F5: 104.42 | G5: =E5*F5 -> 20884 | J5: =H5*I5 -> 0 | K5: =G5+J5 -> 20884 | L5: 0 | M5: =M4+K5-L5 -> 23484.28
A6: 3 | B6: 46268 | G6: =E6*F6 -> 0 | J6: =H6*I6 -> 0 | K6: =G6+J6 -> 0 | L6: 0 | M6: =M5+K6-L6 -> 23484.28
A7: 4 | B7: 46269 | G7: =E7*F7 -> 0 | J7: =H7*I7 -> 0 | K7: =G7+J7 -> 0 | L7: 0 | M7: =M6+K7-L7 -> 23484.28
A8: 5 | B8: 46270 | G8: =E8*F8 -> 0 | J8: =H8*I8 -> 0 | K8: =G8+J8 -> 0 | L8: 0 | M8: =M7+K8-L8 -> 23484.28
A9: 6 | B9: 46271 | G9: =E9*F9 -> 0 | J9: =H9*I9 -> 0 | K9: =G9+J9 -> 0 | L9: 0 | M9: =M8+K9-L9 -> 23484.28
A10: 7 | B10: 46272 | G10: =E10*F10 -> 0 | J10: =H10*I10 -> 0 | K10: =G10+J10 -> 0 | L10: 0 | M10: =M9+K10-L10 -> 23484.28
A11: 8 | B11: 46273 | G11: =E11*F11 -> 0 | J11: =H11*I11 -> 0 | K11: =G11+J11 -> 0 | L11: 0 | M11: =M10+K11-L11 -> 23484.28
A12: 9 | B12: 46274 | G12: =E12*F12 -> 0 | J12: =H12*I12 -> 0 | K12: =G12+J12 -> 0 | L12: 0 | M12: =M11+K12-L12 -> 23484.28
A13: 10 | B13: 46275 | G13: =E13*F13 -> 0 | J13: =H13*I13 -> 0 | K13: =G13+J13 -> 0 | L13: 0 | M13: =M12+K13-L13 -> 23484.28
A14: 11 | B14: 46276 | G14: =E14*F14 -> 0 | H14: 10 | I14: 116.33 | J14: =H14*I14 -> 1163.3 | K14: =G14+J14 -> 1163.3 | L14: 0 | M14: =M13+K14-L14 -> 24647.58
A15: 12 | B15: 46277 | G15: =E15*F15 -> 0 | J15: =H15*I15 -> 0 | K15: =G15+J15 -> 0 | L15: 0 | M15: =M14+K15-L15 -> 24647.58
A16: 13 | B16: 46278 | G16: =E16*F16 -> 0 | J16: =H16*I16 -> 0 | K16: =G16+J16 -> 0 | L16: 0 | M16: =M15+K16-L16 -> 24647.58
A17: 14 | B17: 46279 | G17: =E17*F17 -> 0 | J17: =H17*I17 -> 0 | K17: =G17+J17 -> 0 | L17: 0 | M17: =M16+K17-L17 -> 24647.58
A18: 15 | B18: 46280 | G18: =E18*F18 -> 0 | J18: =H18*I18 -> 0 | K18: =G18+J18 -> 0 | L18: 0 | M18: =M17+K18-L18 -> 24647.58
A19: 16 | B19: 46281 | G19: 0 | J19: 0 | K19: 0 | L19: 0 | M19: =M18+K19-L19 -> 24647.58
A20: 17 | B20: 46282 | G20: =E20*F20 -> 0 | J20: =H20*I20 -> 0 | K20: =G20+J20 -> 0 | L20: 0 | M20: =M19+K20-L20 -> 24647.58
A21: 18 | B21: 46283 | G21: =E21*F21 -> 0 | J21: =H21*I21 -> 0 | K21: =G21+J21 -> 0 | L21: 0 | M21: =M20+K21-L21 -> 24647.58
A22: 19 | B22: 46284 | G22: =E22*F22 -> 0 | J22: =H22*I22 -> 0 | K22: =G22+J22 -> 0 | L22: 0 | M22: =M21+K22-L22 -> 24647.58
A23: 20 | B23: 46285 | G23: =E23*F23 -> 0 | J23: =H23*I23 -> 0 | K23: =G23+J23 -> 0 | L23: 0 | M23: =M22+K23-L23 -> 24647.58
A24: 21 | B24: 46286 | G24: =E24*F24 -> 0 | J24: =H24*I24 -> 0 | K24: =G24+J24 -> 0 | L24: 0 | M24: =M23+K24-L24 -> 24647.58
A25: 22 | B25: 46287 | G25: =E25*F25 -> 0 | J25: =H25*I25 -> 0 | K25: =G25+J25 -> 0 | L25: 0 | M25: =M24+K25-L25 -> 24647.58
A26: 23 | B26: 46288 | G26: =E26*F26 -> 0 | J26: =H26*I26 -> 0 | K26: =G26+J26 -> 0 | L26: 0 | M26: =M25+K26-L26 -> 24647.58
A27: 24 | B27: 46289 | G27: =E27*F27 -> 0 | J27: =H27*I27 -> 0 | K27: =G27+J27 -> 0 | L27: 0 | M27: =M26+K27-L27 -> 24647.58
A28: 25 | B28: 46290 | G28: =E28*F28 -> 0 | J28: =H28*I28 -> 0 | K28: =G28+J28 -> 0 | L28: 0 | M28: =M27+K28-L28 -> 24647.58
A29: 26 | B29: 46291 | G29: =E29*F29 -> 0 | J29: =H29*I29 -> 0 | K29: =G29+J29 -> 0 | L29: 0 | M29: =M28+K29-L29 -> 24647.58
A30: 27 | B30: 46292 | G30: =E30*F30 -> 0 | J30: =H30*I30 -> 0 | K30: =G30+J30 -> 0 | L30: 0 | M30: =M29+K30-L30 -> 24647.58
A31: 28 | B31: 46293 | G31: =E31*F31 -> 0 | J31: =H31*I31 -> 0 | K31: =G31+J31 -> 0 | L31: 0 | M31: =M30+K31-L31 -> 24647.58
A32: 29 | B32: 46294 | G32: =E32*F32 -> 0 | J32: =H32*I32 -> 0 | K32: =G32+J32 -> 0 | L32: 0 | M32: =M31+K32-L32 -> 24647.58
A33: 30 | B33: 46295 | E33: 200 | F33: 104.42 | G33: =E33*F33 -> 20884 | H33: 20 | I33: 116.33 | J33: =H33*I33 -> 2326.6 | K33: =G33+J33 -> 23210.6 | L33: 0 | M33: =M32+K33-L33 -> 47858.18
A34: 31 | G34: =E34*F34 -> 0 | J34: =H34*I34 -> 0 | K34: =G34+J34 -> 0 | M34: =M33+K34-L34 -> 47858.18
E35: =SUM(E4:E34) -> 400 | G35: =SUM(G4:G34) -> 41768 | H35: =SUM(H4:H34) -> 30 | J35: =SUM(J4:J34) -> 3489.9 | K35: =SUM(K4:K34) -> 45257.9 | L35: =SUM(L4:L34) -> 0

Sheet  Sangareddy-2
A1: Durga Bhavani F/S
A2: S.No | B2: Date | C2: GRN No | D2: Ind no/Bill No | E2: Diesel (Lts) | F2: Price | G2: Amount | H2: Petrol (Lts) | I2: Price | J2: Amount | K2: Total amount | L2: Amount paid | M2: As on Date | N2: Remarks
A3: Opening Balance | M3: 0
A4: 1 | B4: 46266 | G4: =E4*F4 -> 0 | J4: =H4*I4 -> 0 | K4: =G4+J4 -> 0 | M4: =M3+K4-L4 -> 0
A5: 2 | B5: 46267 | G5: =E5*F5 -> 0 | J5: =H5*I5 -> 0 | K5: =G5+J5 -> 0 | M5: =M4+K5-L5 -> 0
A6: 3 | B6: 46268 | G6: =E6*F6 -> 0 | J6: =H6*I6 -> 0 | K6: =G6+J6 -> 0 | M6: =M5+K6-L6 -> 0
A7: 4 | B7: 46269 | G7: =E7*F7 -> 0 | J7: =H7*I7 -> 0 | K7: =G7+J7 -> 0 | M7: =M6+K7-L7 -> 0
A8: 5 | B8: 46270 | G8: =E8*F8 -> 0 | J8: =H8*I8 -> 0 | K8: =G8+J8 -> 0 | M8: =M7+K8-L8 -> 0
A9: 6 | B9: 46271 | G9: =E9*F9 -> 0 | J9: =H9*I9 -> 0 | K9: =G9+J9 -> 0 | M9: =M8+K9-L9 -> 0
A10: 7 | B10: 46272 | G10: =E10*F10 -> 0 | J10: =H10*I10 -> 0 | K10: =G10+J10 -> 0 | M10: =M9+K10-L10 -> 0
A11: 8 | B11: 46273 | G11: =E11*F11 -> 0 | J11: =H11*I11 -> 0 | K11: =G11+J11 -> 0 | M11: =M10+K11-L11 -> 0
A12: 9 | B12: 46274 | G12: =E12*F12 -> 0 | J12: =H12*I12 -> 0 | K12: =G12+J12 -> 0 | M12: =M11+K12-L12 -> 0
A13: 10 | B13: 46275 | G13: =E13*F13 -> 0 | J13: =H13*I13 -> 0 | K13: =G13+J13 -> 0 | M13: =M12+K13-L13 -> 0
A14: 11 | B14: 46276 | G14: =E14*F14 -> 0 | J14: =H14*I14 -> 0 | K14: =G14+J14 -> 0 | M14: =M13+K14-L14 -> 0
A15: 12 | B15: 46277 | G15: =E15*F15 -> 0 | J15: =H15*I15 -> 0 | K15: =G15+J15 -> 0 | M15: =M14+K15-L15 -> 0
... A32: 29 | B32: 46294 | G32: =E32*F32 -> 0 | J32: =H32*I32 -> 0 | K32: =G32+J32 -> 0 | M32: =M31+K32-L32 -> 0
A33: 30 | B33: 46295 | G33: =E33*F33 -> 0 | J33: =H33*I33 -> 0 | K33: =G33+J33 -> 0 | L33: 0 | M33: =M32+K33-L33 -> 0
A34: 31 | G34: =E34*F34 -> 0 | J34: =H34*I34 -> 0 | K34: =G34+J34 -> 0 | L34: 0 | M34: =M33+K34-L34 -> 0
E35: =SUM(E4:E34) -> 0 | G35: =SUM(G4:G34) -> 0 | H35: =SUM(H4:H34) -> 0 | J35: =SUM(J4:J34) -> 0 | K35: =SUM(K4:K34) -> 0 | L35: =SUM(L4:L34) -> 0

Sheet  Sangareddy-3
A1: SHIVA PARVATHI FILLING STATION SADASHIVPET
A2: S.No | B2: Date | C2: GRN No | D2: Ind no/Bill No | E2: Diesel (Lts) | F2: Price | G2: Amount | H2: Petrol (Lts) | I2: Price | J2: Amount | K2: Total amount | L2: Amount paid | M2: As on Date | N2: Remarks
A3: Opening Balance | M3: 146154.99
A4: 1 | B4: 45901 | G4: =E4*F4 -> 0 | H4: 6 | I4: 116.25 | J4: =H4*I4 -> 697.5 | K4: =G4+J4 -> 697.5 | M4: =M3+K4-L4 -> 146852.49
A5: 2 | B5: 45902 | G5: =E5*F5 -> 0 | J5: =H5*I5 -> 0 | K5: =G5+J5 -> 0 | M5: =M4+K5-L5 -> 146852.49
A6: 3 | B6: 45903 | E6: 690 | F6: 104.35 | G6: =E6*F6 -> 72001.5 | H6: 4 | I6: 116.25 | J6: =H6*I6 -> 465 | K6: =G6+J6 -> 72466.5 | M6: =M5+K6-L6 -> 219318.99
A7: 4 | B7: 45904 | G7: =E7*F7 -> 0 | J7: =H7*I7 -> 0 | K7: =G7+J7 -> 0 | M7: =M6+K7-L7 -> 219318.99
A8: 5 | B8: 45905 | G8: =E8*F8 -> 0 | J8: =H8*I8 -> 0 | K8: =G8+J8 -> 0 | M8: =M7+K8-L8 -> 219318.99
A9: 6 | B9: 45906 | E9: 690 | F9: 104.35 | G9: =E9*F9 -> 72001.5 | J9: =H9*I9 -> 0 | K9: =G9+J9 -> 72001.5 | M9: =M8+K9-L9 -> 291320.49
A10: 7 | B10: 45907 | G10: =E10*F10 -> 0 | J10: =H10*I10 -> 0 | K10: =G10+J10 -> 0 | M10: =M9+K10-L10 -> 291320.49
A11: 8 | B11: 45908 | G11: =E11*F11 -> 0 | H11: 6 | I11: 116.25 | J11: =H11*I11 -> 697.5 | K11: =G11+J11 -> 697.5 | M11: =M10+K11-L11 -> 292017.99
A12: 9 | B12: 45909 | E12: 600 | F12: 104.35 | G12: =E12*F12 -> 62610 | J12: =H12*I12 -> 0 | K12: =G12+J12 -> 62610 | M12: =M11+K12-L12 -> 354627.99
A13: 10 | B13: 45910 | G13: =E13*F13 -> 0 | H13: 6 | I13: 116.25 | J13: =H13*I13 -> 697.5 | K13: =G13+J13 -> 697.5 | M13: =M12+K13-L13 -> 355325.49
A14: 11 | B14: 45911 | E14: 690 | F14: 104.35 | G14: =E14*F14 -> 72001.5 | H14: 20 | I14: 116.25 | J14: =H14*I14 -> 2325 | K14: =G14+J14 -> 74326.5 | M14: =M13+K14-L14 -> 429651.99
A15: 12 | B15: 45912 | G15: =E15*F15 -> 0 | K15: =G15+J15 -> 0 | M15: =M14+K15-L15 -> 429651.99
A16: 13 | B16: 45913 | G16: =E16*F16 -> 0 | J16: =H16*I16 -> 0 | K16: =G16+J16 -> 0 | M16: =M15+K16-L16 -> 429651.99
A17: 14 | B17: 45914 | G17: =E17*F17 -> 0 | J17: =H17*I17 -> 0 | K17: =G17+J17 -> 0 | M17: =M16+K17-L17 -> 429651.99
A18: 15 | B18: 45915 | G18: =E18*F18 -> 0 | J18: =H18*I18 -> 0 | K18: =G18+J18 -> 0 | M18: =M17+K18-L18 -> 429651.99
A19: 16 | B19: 45916 | E19: 690 | F19: 104.35 | G19: =E19*F19 -> 72001.5 | J19: =H19*I19 -> 0 | K19: =G19+J19 -> 72001.5 | M19: =M18+K19-L19 -> 501653.49
A20: 17 | B20: 45917 | G20: =E20*F20 -> 0 | J20: =H20*I20 -> 0 | K20: =G20+J20 -> 0 | M20: =M19+K20-L20 -> 501653.49
A21: 18 | B21: 45918 | G21: =E21*F21 -> 0 | J21: =H21*I21 -> 0 | K21: =G21+J21 -> 0 | M21: =M20+K21-L21 -> 501653.49
A22: 19 | B22: 45919 | G22: =E22*F22 -> 0 | J22: =H22*I22 -> 0 | K22: =G22+J22 -> 0 | M22: =M21+K22-L22 -> 501653.49
A23: 20 | B23: 45920 | G23: =E23*F23 -> 0 | J23: =H23*I23 -> 0 | K23: =G23+J23 -> 0 | M23: =M22+K23-L23 -> 501653.49
A24: 21 | B24: 45921 | E24: 690 | F24: 104.35 | G24: =E24*F24 -> 72001.5 | J24: =H24*I24 -> 0 | K24: =G24+J24 -> 72001.5 | M24: =M23+K24-L24 -> 573654.99
A25: 22 | B25: 45922 | G25: =E25*F25 -> 0 | J25: =H25*I25 -> 0 | K25: =G25+J25 -> 0 | M25: =M24+K25-L25 -> 573654.99
A26: 23 | B26: 45923 | G26: =E26*F26 -> 0 | J26: =H26*I26 -> 0 | K26: =G26+J26 -> 0 | L26: 427500 | M26: =M25+K26-L26 -> 146154.99
A27: 24 | B27: 45924 | E27: 690 | F27: 104.35 | G27: =E27*F27 -> 72001.5 | H27: 20 | I27: 116.25 | J27: =H27*I27 -> 2325 | K27: =G27+J27 -> 74326.5 | M27: =M26+K27-L27 -> 220481.49
A28: 25 | B28: 45925 | G28: =E28*F28 -> 0 | J28: =H28*I28 -> 0 | K28: =G28+J28 -> 0 | M28: =M27+K28-L28 -> 220481.49
A29: 26 | B29: 45926 | E29: 690 | F29: 104.35 | G29: =E29*F29 -> 72001.5 | H29: 20 | I29: 116.25 | J29: =H29*I29 -> 2325 | K29: =G29+J29 -> 74326.5 | M29: =M28+K29-L29 -> 294807.99
A30: 27 | B30: 45927 | G30: =E30*F30 -> 0 | J30: =H30*I30 -> 0 | K30: =G30+J30 -> 0 | M30: =M29+K30-L30 -> 294807.99
A31: 28 | B31: 45928 | G31: =E31*F31 -> 0 | J31: =H31*I31 -> 0 | K31: =G31+J31 -> 0 | M31: =M30+K31-L31 -> 294807.99
A32: 29 | B32: 45929 | E32: 690 | F32: 104.35 | G32: =E32*F32 -> 72001.5 | J32: =H32*I32 -> 0 | K32: =G32+J32 -> 72001.5 | M32: =M31+K32-L32 -> 366809.49
A33: 30 | B33: 45930 | G33: =E33*F33 -> 0 | J33: =H33*I33 -> 0 | K33: =G33+J33 -> 0 | M33: =M32+K33-L33 -> 366809.49
A34: 31 | G34: =E34*F34 -> 0 | J34: =H34*I34 -> 0 | K34: =G34+J34 -> 0 | M34: =M33+K34-L34 -> 366809.49
A35: 32 | G35: =E35*F35 -> 0 | J35: =H35*I35 -> 0 | K35: =G35+J35 -> 0 | M35: =M34+K35-L35 -> 366809.49
E36: =SUM(E4:E35) -> 6120 | G36: =SUM(G4:G35) -> 638622 | H36: =SUM(H4:H35) -> 82 | J36: =SUM(J4:J35) -> 9532.5 | K36: =SUM(K4:K35) -> 648154.5 | L36: =SUM(L4:L35) -> 427500

Sheet Narayankhed
A2: S.No | B2: Date | C2: GRN No | D2: Ind no/Bill No | E2: Diesel (Lts) | F2: Price | G2: Amount | H2: Petrol (Lts) | I2: Price | J2: Amount | K2: Total amount | L2: Amount paid | M2: As on Date | N2: Remarks
A3: Opening Balance | M3: 0
A4: 1 | B4: 46266 | G4: =E4*F4 -> 0 | J4: =H4*I4 -> 0 | K4: =G4+J4 -> 0 | L4: =H4+K4 -> 0 | M4: =M3+K4-L4 -> 0
A5: 2 | B5: 46267 | G5: =E5*F5 -> 0 | J5: =H5*I5 -> 0 | K5: =G5+J5 -> 0 | L5: =H5+K5 -> 0 | M5: =M4+K5-L5 -> 0
A6: 3 | B6: 46268 | G6: =E6*F6 -> 0 | J6: =H6*I6 -> 0 | K6: =G6+J6 -> 0 | L6: =H6+K6 -> 0 | M6: =M5+K6-L6 -> 0
A7: 4 | B7: 46269 | G7: =E7*F7 -> 0 | J7: =H7*I7 -> 0 | K7: =G7+J7 -> 0 | L7: =H7+K7 -> 0 | M7: =M6+K7-L7 -> 0
A8: 5 | B8: 46270 | G8: =E8*F8 -> 0 | J8: =H8*I8 -> 0 | K8: =G8+J8 -> 0 | L8: =H8+K8 -> 0 | M8: =M7+K8-L8 -> 0
A9: 6 | B9: 46271 | E9: 476.64 | F9: 104.9 | G9: =E9*F9 -> 49999.536 | J9: =H9*I9 -> 0 | K9: =G9+J9 -> 49999.536 | L9: 49999.536 | M9: =M8+K9-L9 -> 0 | N9: BT
A10: 7 | B10: 46272 | G10: =E10*F10 -> 0 | J10: =H10*I10 -> 0 | K10: =G10+J10 -> 0 | L10: 0 | M10: =M9+K10-L10 -> 0
A11: 8 | B11: 46273 | G11: =E11*F11 -> 0 | J11: =H11*I11 -> 0 | K11: =G11+J11 -> 0 | L11: =H11+K11 -> 0 | M11: =M10+K11-L11 -> 0
A12: 9 | B12: 46274 | G12: =E12*F12 -> 0 | J12: =H12*I12 -> 0 | K12: =G12+J12 -> 0 | L12: 0 | M12: =M11+K12-L12 -> 0
A13: 10 | B13: 46275 | G13: =E13*F13 -> 0 | J13: =H13*I13 -> 0 | K13: =G13+J13 -> 0 | L13: =H13+K13 -> 0 | M13: =M12+K13-L13 -> 0
A14: 11 | B14: 46276 | G14: =E14*F14 -> 0 | J14: =H14*I14 -> 0 | K14: =G14+J14 -> 0 | L14: =H14+K14 -> 0 | M14: =M13+K14-L14 -> 0
A15: 12 | B15: 46277 | G15: =E15*F15 -> 0 | J15: =H15*I15 -> 0 | K15: =G15+J15 -> 0 | L15: =H15+K15 -> 0 | M15: =M14+K15-L15 -> 0
A16: 13 | B16: 46278 | G16: =E16*F16 -> 0 | J16: =H16*I16 -> 0 | K16: =G16+J16 -> 0 | L16: =H16+K16 -> 0 | M16: =M15+K16-L16 -> 0
A17: 14 | B17: 46279 | G17: =E17*F17 -> 0 | J17: =H17*I17 -> 0 | K17: =G17+J17 -> 0 | L17: =H17+K17 -> 0 | M17: =M16+K17-L17 -> 0
A18: 15 | B18: 46280 | G18: =E18*F18 -> 0 | J18: =H18*I18 -> 0 | K18: =G18+J18 -> 0 | L18: =H18+K18 -> 0 | M18: =M17+K18-L18 -> 0
A19: 16 | B19: 46281 | G19: =E19*F19 -> 0 | J19: =H19*I19 -> 0 | K19: =G19+J19 -> 0 | L19: =H19+K19 -> 0 | M19: =M18+K19-L19 -> 0
A20: 17 | B20: 46282 | E20: 238.03 | F20: 105.03 | G20: =E20*F20 -> 25000.291 | J20: =H20*I20 -> 0 | K20: =G20+J20 -> 25000.291 | L20: =H20+K20 -> 25000.291 | M20: =M19+K20-L20 -> 0 | N20: HPCLCard
A21: 18 | B21: 46283 | G21: =E21*F21 -> 0 | J21: =H21*I21 -> 0 | K21: =G21+J21 -> 0 | L21: =H21+K21 -> 0 | M21: =M20+K21-L21 -> 0
A22: 19 | B22: 46284 | G22: =E22*F22 -> 0 | J22: =H22*I22 -> 0 | K22: =G22+J22 -> 0 | L22: =H22+K22 -> 0 | M22: =M21+K22-L22 -> 0
A23: 20 | B23: 46285 | G23: =E23*F23 -> 0 | J23: =H23*I23 -> 0 | K23: =G23+J23 -> 0 | L23: =H23+K23 -> 0 | M23: =M22+K23-L23 -> 0
A24: 21 | B24: 46286 | E24: 142.82 | F24: 105.03 | G24: =E24*F24 -> 15000.385 | J24: =H24*I24 -> 0 | K24: =G24+J24 -> 15000.385 | L24: =H24+K24 -> 15000.385 | M24: =M23+K24-L24 -> 0 | N24: HPCL Card
A25: 22 | B25: 46287 | G25: =E25*F25 -> 0 | J25: =H25*I25 -> 0 | K25: =G25+J25 -> 0 | L25: =H25+K25 -> 0 | M25: =M24+K25-L25 -> 0
A26: 23 | B26: 46288 | G26: =E26*F26 -> 0 | J26: =H26*I26 -> 0 | K26: =G26+J26 -> 0 | L26: =+K26 -> 0 | M26: =M25+K26-L26 -> 0
A27: 24 | B27: 46289 | E27: 238 | F27: 105.03 | G27: =E27*F27 -> 24997.14 | J27: =H27*I27 -> 0 | K27: =G27+J27 -> 24997.14 | L27: =+K27 -> 24997.14 | M27: =M26+K27-L27 -> 0
A28: 25 | B28: 46290 | G28: =E28*F28 -> 0 | J28: =H28*I28 -> 0 | K28: =G28+J28 -> 0 | L28: =+K28 -> 0 | M28: =M27+K28-L28 -> 0
A29: 26 | B29: 46291 | E29: 380 | F29: 105.12 | G29: =E29*F29 -> 39945.6 | J29: =H29*I29 -> 0 | K29: =G29+J29 -> 39945.6 | L29: =+K29 -> 39945.6 | M29: =M28+K29-L29 -> 0 | N29: BPCL
A30: 27 | B30: 46292 | G30: =E30*F30 -> 0 | J30: =H30*I30 -> 0 | K30: =G30+J30 -> 0 | L30: =+K30 -> 0 | M30: =M29+K30-L30 -> 0
A31: 28 | B31: 46293 | E31: 285.39 | F31: 105.12 | G31: =E31*F31 -> 30000.197 | J31: =H31*I31 -> 0 | K31: =G31+J31 -> 30000.197 | L31: =+K31 -> 30000.197 | M31: =M30+K31-L31 -> 0 | N31: BPCL
A32: 29 | B32: 46294 | G32: =E32*F32 -> 0 | J32: =H32*I32 -> 0 | K32: =G32+J32 -> 0 | L32: =+K32 -> 0 | M32: =M31+K32-L32 -> 0
