Workbook

Sheet Feb-2026
A1: S.no | B1: Site Name | C1: Bunk Name | D1: Diesel(Liters) | E1: Diesel Amount | F1: Petrol(Liters) | G1: Petrol Amount | H1: Total Amount | I1: Opening Blance | J1: Amount Paid | K1: Closing Balances
A2: 1 | B2: Khammam-1 | C2: Divya laxmi ganapathi | D2: =+'Khammam-1'!E38 -> 87280.64 | E2: =+'Khammam-1'!G38 -> 8351011.6 | F2: =+'Khammam-1'!H38 -> 455 | G2: =+'Khammam-1'!J38 -> 48894.3 | H2: =E2+G2 -> 8399905.9 | I2: =+'Khammam-1'!K3 -> 2836061 | J2: =+'Khammam-1'!L38 -> 2998712 | K2: =H2+I2-J2 -> 8237254.9
A3: 2 | B3: Khammam-2 | C3: Jayasai union bunk | D3: =+'Khammam-2'!E35 -> 81063.05 | E3: =+'Khammam-2'!G35 -> 7758252 | F3: =+'Khammam-2'!H35 -> 630 | G3: =+'Khammam-2'!J35 -> 67714.35 | H3: =E3+G3 -> 7825966.4 | I3: =+'Khammam-2'!K3 -> 4435776.8 | J3: =+'Khammam-2'!L35 -> 6705886 | K3: =H3+I3-J3 -> 5555857.2
A4: 3 | B4: Khammam-3 | C4: JSASFuel Genie India Pvt.Ltd | D4: =+'Khammam-3'!E35 -> 101973 | E4: =+'Khammam-3'!G35 -> 9656843.1 | F4: =+'Khammam-3'!H35 -> 0 | G4: =+'Khammam-3'!J35 -> 0 | H4: =E4+G4 -> 9656843.1 | I4: =+'Khammam-3'!M3 -> 120400 | J4: =+'Khammam-3'!L35 -> 8637100 | K4: =H4+I4-J4 -> 1140143.1
A5: 4 | B5: Jadcherla-3 | C5: JSASFuel Genie India Pvt.Ltd | D5: =+'Jadcherla-3'!E35 -> 25225 | E5: =+'Jadcherla-3'!G35 -> 2407221.8 | F5: =+'Jadcherla-3'!H35 -> 0 | G5: =+'Jadcherla-3'!J35 -> 0 | H5: =E5+G5 -> 2407221.8 | I5: =+'Jadcherla-3'!M3 -> 299056.5 | J5: =+'Jadcherla-3'!L35 -> 1680000 | K5: =H5+I5-J5 -> 1026278.2
A6: 5 | B6: Jadcherla-4 | C6: Shree Poornima F/S | D6: =+'Jadcherla-4'!E35 -> 0 | E6: =+'Jadcherla-4'!G35 -> 0 | F6: =+'Jadcherla-4'!H35 -> 180 | G6: =+'Jadcherla-4'!J35 -> 19458 | H6: =E6+G6 -> 19458 | I6: =+'Jadcherla-4'!M3 -> 5405 | J6: =+'Jadcherla-4'!L35 -> 0 | K6: =H6+I6-J6 -> 24863
A7: 6 | B7: Dindi | C7: Akarapu Balakistamma Fillling | D7: =+Dindi!E35 -> 0 | E7: =+Dindi!G35 -> 0 | F7: =+Dindi!H35 -> 0 | G7: =+Dindi!J35 -> 0 | H7: =E7+G7 -> 0 | I7: =+Dindi!M3 -> 0 | J7: =+Dindi!L35 -> 0 | K7: =H7+I7-J7 -> 0
A8: 7 | B8: Devarkhadra-1 | C8: Kurumurthy Swami F/S | D8: =+Devarakhadra!E35 -> 10 | E8: =+Devarakhadra!G35 -> 971 | F8: =+Devarakhadra!H35 -> 13 | G8: =+Devarakhadra!J35 -> 1414.79 | H8: =E8+G8 -> 2385.79 | I8: =+Devarakhadra!M3 -> 5856.2924 | J8: =+Devarakhadra!L35 -> 8242.08 | K8: =H8+I8-J8 -> 0.0023999999
A9: 8 | B9: Sangareddy | C9: Durga indhan | D9: =+' Sanga reddy-1'!E35 -> 1553.08 | E9: =+' Sanga reddy-1'!G35 -> 149654.79 | F9: =+' Sanga reddy-1'!H35 -> 19 | G9: =+' Sanga reddy-1'!J35 -> 2055.23 | H9: =E9+G9 -> 151710.02 | I9: =+' Sanga reddy-1'!M3 -> 0 | J9: =+' Sanga reddy-1'!L35 -> 0 | K9: =H9+I9-J9 -> 151710.02
A10: 9 | B10: Madanapalli | D10: =+'Madana palli'!E35 -> 215.39 | E10: =+'Madana palli'!G35 -> 21057.448 | F10: =+'Madana palli'!H35 -> 23.33 | G10: =+'Madana palli'!J35 -> 2557.2013 | H10: =E10+G10 -> 23614.649 | I10: =+'Madana palli'!M3 -> 0 | J10: =+'Madana palli'!L35 -> 23614.649 | K10: =H10+I10-J10 -> 0
A11: 10 | B11: Amalapuram | C11: Sathya Filling Station | D11: =+Amalapuram!E38 -> 530.07 | E11: =+Amalapuram!G38 -> 49919.954 | F11: =+Amalapuram!H38 -> 171.5 | G11: =+Amalapuram!J38 -> 18448.05 | H11: =E11+G11 -> 68368.004 | I11: =+Amalapuram!M3 -> 0 | J11: =+Amalapuram!L38 -> 68366.97 | K11: =H11+I11-J11 -> 1.0336
A12: 11 | B12: YG Gudda-2 | C12: Pankaja HP Fuel Center | D12: =+'YG Gudda-2'!E36 -> 12500 | E12: =+'YG Gudda-2'!G36 -> 1141625 | F12: =+'YG Gudda-2'!H36 -> 385 | G12: =+'YG Gudda-2'!J36 -> 39758.95 | H12: =E12+G12 -> 1181383.9 | I12: =+'YG Gudda-2'!M3 -> 478336.85 | J12: =+'YG Gudda-2'!L36 -> 1128337 | K12: =H12+I12-J12 -> 531383.8
A13: 12 | B13: Hosadurga-1 | C13: Merchant Petroliums | D13: =+Hosadurga!E35 -> 0 | E13: =+Hosadurga!G35 -> 0 | F13: =+Hosadurga!H35 -> 0 | G13: =+Hosadurga!J35 -> 0 | H13: =E13+G13 -> 0 | I13: =+Hosadurga!K3 -> 2258.6 | J13: =+Hosadurga!L35 -> 2260 | K13: =H13+I13-J13 -> -1.4
A14: 13 | B14: Hosadurga-2 | C14: Shree Veeraprathap Fuel | D14: =+'Hosadurga -2'!E35 -> 7300 | E14: =+'Hosadurga -2'!G35 -> 668315 | F14: =+'Hosadurga -2'!H35 -> 280 | G14: =+'Hosadurga -2'!J35 -> 29044.4 | H14: =+'Hosadurga -2'!K35 -> 697359.4 | I14: =+'Hosadurga -2'!K3 -> 325898.2 | J14: =+'Hosadurga -2'!L35 -> 825898.2 | K14: =H14+I14-J14 -> 197359.4
A15: 14 | B15: Malebennuru(KUWSDB) | C15: Sri Ramanjuneya Service Station | D15: =+'Malebenur(KUWSDB)'!E37 -> 4200 | E15: =+'Malebenur(KUWSDB)'!G37 -> 387114 | F15: =+'Malebenur(KUWSDB)'!H37 -> 180 | G15: =+'Malebenur(KUWSDB)'!J37 -> 18725.4 | H15: =E15+G15 -> 405839.4 | I15: =+'Malebenur(KUWSDB)'!K3 -> 213698.56 | J15: =+'Malebenur(KUWSDB)'!L37 -> 560585 | K15: =H15+I15-J15 -> 58952.96
A16: 15 | B16: kadur | C16: Vishal Service Station | D16: =+Kadur!E35 -> 2500 | E16: =+Kadur!G35 -> 230375 | F16: =+Kadur!H35 -> 100 | G16: =+Kadur!J35 -> 10427 | H16: =E16+G16 -> 240802 | I16: =+Kadur!K3 -> 14627.031 | J16: =+Kadur!L35 -> 14492 | K16: =H16+I16-J16 -> 240937.03
A17: 16 | B17: Hiriyur(VJNL) | C17: Sri Balaji Agencies | D17: =+'Hiriyur(VJNL)'!E35 -> 2400 | E17: =+'Hiriyur(VJNL)'!G35 -> 221424 | F17: =+'Hiriyur(VJNL)'!H35 -> 245 | G17: =+'Hiriyur(VJNL)'!J35 -> 25511.85 | H17: =E17+G17 -> 246935.85 | I17: =+'Hiriyur(VJNL)'!K3 -> 219486.1 | J17: =+'Hiriyur(VJNL)'!L35 -> 459486 | K17: =H17+I17-J17 -> 6935.95
A18: 17 | B18: Chellakere(KUWSDB) | C18: Shivaganga Service Station | D18: =+'Chellakere -1'!E35 -> 5000 | E18: =+'Chellakere -1'!G35 -> 461150 | F18: =+'Chellakere -1'!H35 -> 195.04 | G18: =+'Chellakere -1'!J35 -> 20301.714 | H18: =E18+G18 -> 481451.71 | I18: =+'Chellakere -1'!K3 -> 161104.96 | J18: =+'Chellakere -1'!L35 -> 373900 | K18: =H18+I18-J18 -> 268656.68
A19: 18 | B19: Chellakere(KUWSDB)-09 | D19: =+' Chellakere-PKG-9'!E35 -> 410.01 | E19: =+' Chellakere-PKG-9'!G35 -> 37777.422 | F19: =+' Chellakere-PKG-9'!H35 -> 18.04 | G19: =+' Chellakere-PKG-9'!J35 -> 1877.7836 | H19: =E19+G19 -> 39655.206 | I19: =+' Chellakere-PKG-9'!M3 -> 0 | J19: =+' Chellakere-PKG-9'!L35 -> 39655.206 | K19: =H19+I19-J19 -> 0
A20: 19 | B20: Molakalmuru | C20: Sri Lakshmi Venkateshwara Filling Station | D20: =+Molakamuru!E35 -> 600 | E20: =+Molakamuru!G35 -> 55332 | F20: =+Molakamuru!H35 -> 100 | G20: =+Molakamuru!J35 -> 10408 | H20: =E20+G20 -> 65740 | I20: =+Molakamuru!K3 -> 27990.595 | J20: =+Molakamuru!L35 -> 71123.38 | K20: =H20+I20-J20 -> 22607.215
A21: 20 | B21: Chennagiri | D21: =+' Chennagiri'!E35 -> 427.27 | E21: =+' Chennagiri'!G35 -> 39330.204 | F21: =+' Chennagiri'!H35 -> 68 | G21: =+' Chennagiri'!J35 -> 7078.88 | H21: =E21+G21 -> 46409.084 | I21: =+' Chennagiri'!K3 -> 0 | J21: =+' Chennagiri'!L35 -> 46409.084 | K21: =H21+I21-J21 -> 0
A22: 21 | B22: Khanapur(PKG-3) | C22: V.V.Varde | D22: =+Khanapur!E35 -> 1766.61 | E22: =+Khanapur!G35 -> 160549.52 | F22: =+Khanapur!H35 -> 79.78 | G22: =+Khanapur!J35 -> 8198.9906 | H22: =E22+G22 -> 168748.51 | I22: =+Khanapur!M3 -> 103942.75 | J22: =+Khanapur!L35 -> 203905.34 | K22: =H22+I22-J22 -> 68785.913
A23: 22 | B23: Munavalli(PKG-3)-1 | C23: Shri Daneshwari | D23: =+Munavali!E37 -> 0 | E23: =+Munavali!G37 -> 0 | F23: =+Munavali!H37 -> 0 | G23: =+Munavali!J37 -> 0 | H23: =E23+G23 -> 0 | I23: =+Munavali!M3 -> 0 | J23: =+Munavali!L37 -> 0 | K23: =H23+I23-J23 -> 0
A24: 23 | B24: Munavalli(PKG-3)-2 | C24: Shre Shiva Petroleum | D24: =+'Munavali-2'!E38 -> 17172.676 | E24: =+'Munavali-2'!G38 -> 1571967.1 | F24: =+'Munavali-2'!H38 -> 261 | G24: =+'Munavali-2'!J38 -> 27163.48 | H24: =E24+G24 -> 1599130.6 | I24: =+'Munavali-2'!M3 -> 343617.68 | J24: =+'Munavali-2'!L38 -> 1204238.2 | K24: =H24+I24-J24 -> 738510.09
A25: 24 | B25: Borgaon(PKG-3) | C25: Aadisagar Petrolium | D25: =+Borgaon!E35 -> 1395.17 | E25: =+Borgaon!G35 -> 128034.75 | F25: =+Borgaon!H35 -> 117.74 | G25: =+Borgaon!J35 -> 12213.17 | H25: =E25+G25 -> 140247.92 | I25: =+Borgaon!K3 -> 115310.98 | J25: =+Borgaon!L35 -> 226000 | K25: =H25+I25-J25 -> 29558.904
A26: 25 | B26: Ugar,Kudichi(PKG-3) | C26: Shiri Bhrhmanath Petrolium | D26: =+'Ugar,Khagwad,Kudichi'!E35 -> 4214.84 | E26: =+'Ugar,Khagwad,Kudichi'!G35 -> 387470.24 | F26: =+'Ugar,Khagwad,Kudichi'!H35 -> 264 | G26: =+'Ugar,Khagwad,Kudichi'!J35 -> 27426.96 | H26: =E26+G26 -> 414897.2 | I26: =+'Ugar,Khagwad,Kudichi'!M3 -> 151510.55 | J26: =+'Ugar,Khagwad,Kudichi'!L35 -> 351000 | K26: =H26+I26-J26 -> 215407.75
A27: 26 | B27: Kabbur(PKG-3) | C27: Shri Jai Hanuman Petrolium | D27: =+Kabbur!E35 -> 444.44 | E27: =+Kabbur!G35 -> 40798.574 | F27: =+Kabbur!H35 -> 11.66 | G27: =+Kabbur!J35 -> 1207.1598 | H27: =E27+G27 -> 42005.734 | I27: 0 | J27: =+Kabbur!L35 -> 42005.734 | K27: =H27+I27-J27 -> 0
A28: 27 | B28: Kumta (PKG-1) | C28: V.M.MIRJANKAR (KUMTA) BHARAT | D28: =+kumta!E35 -> 2040 | E28: =+kumta!G35 -> 187618.8 | F28: =+kumta!H35 -> 90 | G28: =+kumta!J35 -> 9360.9 | H28: =E28+G28 -> 196979.7 | I28: 0 | J28: =+kumta!L35 -> 169925 | K28: =H28+I28-J28 -> 27054.7
A29: 28 | B29: Jalgaon | C29: Sri Sai Petrol Pump | D29: =+Jalgaon!E54 -> 15971.286 | E29: =+Jalgaon!G54 -> 1464609.4 | F29: =+Jalgaon!H54 -> 140 | G29: =+Jalgaon!J54 -> 14726.6 | H29: =E29+G29 -> 1479336 | I29: =+Jalgaon!K3 -> 1368586.5 | J29: =+Jalgaon!L54 -> 2510129.2 | K29: =H29+I29-J29 -> 337793.25
A30: 29 | B30: Jalgaon-2 | C30: Nayara | D30: =+'Jalgoan-2'!E55 -> 42840.22 | E30: ='Jalgoan-2'!G55 -> 3928876.6 | F30: =+'Jalgoan-2'!H55 -> 230 | G30: =+'Jalgoan-2'!J55 -> 24251.2 | H30: =E30+G30 -> 3953127.8 | I30: =+'Jalgoan-2'!M3 -> 0 | J30: =+'Jalgoan-2'!L55 -> 1000000 | K30: =H30+I30-J30 -> 2953127.8
A31: 30 | B31: MKBD | C31: Shree Sai Samarth Petroleum | D31: =+MKBD!E38 -> 8000 | E31: =+MKBD!G38 -> 729120 | F31: =+MKBD!H38 -> 75 | G31: =+MKBD!J38 -> 7845 | H31: =E31+G31 -> 736965 | I31: =+MKBD!K3 -> 366041.65 | J31: =+MKBD!L38 -> 1000000 | K31: =H31+I31-J31 -> 103006.65
A32: 31 | B32: Haveri | C32: M/s Magavi City Fuels | D32: =' Haveri-2'!E37 -> 2590.84 | E32: =' Haveri-2'!G37 -> 237035.95 | F32: =' Haveri-2'!H37 -> 107.73 | G32: =' Haveri-2'!J37 -> 11142.514 | H32: =E32+G32 -> 248178.47 | I32: =' Haveri-2'!M3 -> 150830.73 | J32: =+' Haveri-2'!L37 -> 308600 | K32: =H32+I32-J32 -> 90409.199
A33: 32 | B33: Guttal-2 | C33: Himagiri Petroleum | D33: =+' Guttal-2'!E35 -> 5890.6 | E33: =+' Guttal-2'!G35 -> 540639.27 | F33: =+' Guttal-2'!H35 -> 160 | G33: =+' Guttal-2'!J35 -> 16598.4 | H33: =E33+G33 -> 557237.67 | I33: =+' Guttal-2'!M3 -> 532276.88 | J33: =+' Guttal-2'!L35 -> 970904 | K33: =H33+I33-J33 -> 118610.55
A34: 33 | B34: Rattihali | C34: Shree Siri Gowari petroliam | D34: =+Rattihali!E35 -> 0 | E34: =+Rattihali!G35 -> 0 | F34: =+Rattihali!H35 -> 0 | G34: =+Rattihali!J35 -> 0 | H34: =E34+G34 -> 0 | I34: =+Rattihali!M3 -> 6442.724 | J34: =+Rattihali!L35 -> 0 | K34: =H34+I34-J34 -> 6442.724
A35: 34 | B35: Rattihali-2 | C35: Shiva Oil Traders | D35: =+'Rattihali-2'!E37 -> 3706.11 | E35: =+'Rattihali-2'!G37 -> 340554.45 | F35: =+'Rattihali-2'!H37 -> 129 | G35: =+'Rattihali-2'!J37 -> 13474.35 | H35: =E35+G35 -> 354028.8 | I35: =+'Rattihali-2'!M3 -> 162379.88 | J35: =+'Rattihali-2'!L37 -> 366900 | K35: =H35+I35-J35 -> 149508.67
A36: 35 | B36: Gajendragada | C36: Vanasri Petrol Pump | D36: =+Gajendragada!E35 -> 1238 | E36: =+Gajendragada!G35 -> 113685.54 | F36: =+Gajendragada!H35 -> 120 | G36: =+Gajendragada!J35 -> 12456 | H36: =E36+G36 -> 126141.54 | I36: =+Gajendragada!K3 -> 10249.402 | J36: =+Gajendragada!L35 -> 10288.04 | K36: =H36+I36-J36 -> 126102.9
A37: 36 | B37: Gokak(PKG-3) | C37: AJ Petrolinks | D37: =+'Gokak Dharwad PKG 3'!E40 -> 10361.89 | E37: =+'Gokak Dharwad PKG 3'!G40 -> 947905.7 | F37: =+'Gokak Dharwad PKG 3'!H40 -> 289 | G37: =+'Gokak Dharwad PKG 3'!J40 -> 29885.49 | H37: =E37+G37 -> 977791.19 | I37: =+'Gokak Dharwad PKG 3'!K3 -> 437987.29 | J37: =+'Gokak Dharwad PKG 3'!L40 -> 1188028 | K37: =H37+I37-J37 -> 227750.48
A38: 37 | B38: Hukkere | C38: TR Assocites | D38: =+' TR Associates'!E35 -> 9861.75 | E38: =+' TR Associates'!G35 -> 900575.01 | F38: =+' TR Associates'!H35 -> 12.02 | G38: =+' TR Associates'!J35 -> 1240.8848 | H38: =E38+G38 -> 901815.89 | I38: =+' TR Associates'!M3 -> 647689.79 | J38: =+' TR Associates'!L35 -> 1247689 | K38: =H38+I38-J38 -> 301816.69
A39: 38 | B39: Ankaligi | C39: Shivaganga | D39: =+Ankalgi!E35 -> 4209.09 | E39: =+Ankalgi!G35 -> 384332.01 | F39: =+Ankalgi!H35 -> 102 | G39: =+Ankalgi!J35 -> 10529.46 | H39: =E39+G39 -> 394861.47 | I39: =+Ankalgi!M3 -> 306662.51 | J39: =+Ankalgi!L35 -> 606663 | K39: =H39+I39-J39 -> 94860.976
A40: 39 | B40: ShankeshWAR | C40: SR Patil | D40: =+' Shankeshwar'!E35 -> 590.04 | E40: =+' Shankeshwar'!G35 -> 53871.752 | F40: =+' Shankeshwar'!H35 -> 135 | G40: =+' Shankeshwar'!J35 -> 13934.7 | H40: =E40+G40 -> 67806.452 | J40: =+' Shankeshwar'!L35 -> 67806.452 | K40: =H40+I40-J40 -> 0
...

Sheet Sheet2
A2: S.No | B2: NAme | C2: Lacation | D2: Card Number | E2: Card Number | F2: Category | G2: 1st Jan | I2: 2nd Jan | J2: 3rd Jan | K2: 4th Jan | L2: 5th Jan | M2: 6th Jan | N2: 7th Jan | O2: 8th Jan | P2: 9th Jan | Q2: 10th Jan | R2: 11th Jan | S2: 12th Jan | T2: 13th Jan | U2: 14th Jan | V2: 15th Jan | W2: 16th Jan | X2: 17th Jan | Y2: 18th Jan | Z2: 19th Jan | AA2: 20th Jan | AB2: 21st Jan | AC2: 22nd Jan | AD2: 23rd Jan | AE2: 24th Jan | AF2: 25th Jan | AG2: 26th Jan | AH2: 27th Jan | AI2: 28th Jan | AJ2: 29th Jan | AK2: 30th Jan | AL2: 31st Jan | AM2: Total
F3: Diesel
A4: 1 | B4: Rambabu | C4: HO(Two Wheeler) | D4: FC3450563999 | E4: Diesel | F4: 0 | G4: 0 | H4: 0 | I4: 0 | J4: 0 | K4: 0 | L4: 0 | M4: 0 | N4: 0 | O4: 0 | P4: 0 | Q4: 0 | R4: 0 | S4: 0 | T4: 0 | U4: 0 | V4: 0 | W4: 0 | X4: 5.22 | Y4: 0 | Z4: 0 | AA4: 0 | AB4: 0 | AC4: 0 | AD4: 60 | AE4: 0 | AF4: 0 | AG4: 0 | AH4: 4.56 | AI4: 0 | AJ4: 0 | AK4: 0 | AL4: 0 | AM4: =SUM(F4:AL4) -> 69.78
E5: Petrol | F5: 0 | G5: 4.69 | H5: 0 | I5: 0 | J5: 0 | K5: 0 | L5: 0 | M5: 0 | N5: 3.91 | O5: 0 | P5: 6.98 | Q5: 0 | R5: 0 | S5: 0 | T5: 0 | U5: 0 | V5: 0 | W5: 0 | X5: 0 | Y5: 0 | Z5: 0 | AB5: 0 | AC5: 0 | AD5: 0 | AE5: 0 | AF5: 0 | AG5: 0 | AH5: 0 | AI5: 0 | AJ5: 0 | AK5: 0 | AL5: 0 | AM5: =SUM(F5:AL5) -> 15.58
A6: 2 | B6: Hanumanth Rao | C6: HO | D6: FC3450676131 | E6: Diesel | F6: 0 | G6: 0 | H6: 0 | I6: 0 | J6: 0 | K6: 0 | L6: 0 | M6: 0 | N6: 0 | O6: 0 | P6: 0 | Q6: 0 | R6: 0 | S6: 0 | T6: 0 | U6: 0 | V6: 0 | W6: 0 | X6: 0 | Y6: 0 | Z6: 0 | AA6: 0 | AB6: 0 | AC6: 0 | AD6: 0 | AE6: 0 | AF6: 0 | AG6: 0 | AH6: 0 | AI6: 0 | AJ6: 0 | AK6: 0 | AL6: 0 | AM6: =SUM(F6:AL6) -> 0
E7: Petrol | F7: 0 | G7: 0 | H7: 0 | I7: 0 | J7: 0 | K7: 0 | L7: 0 | M7: 0 | N7: 0 | O7: 0 | P7: 0 | Q7: 0 | R7: 0 | S7: 0 | T7: 0 | U7: 0 | V7: 0 | W7: 0 | X7: 0 | Y7: 0 | Z7: 0 | AB7: 0 | AC7: 0 | AD7: 0 | AE7: 0 | AF7: 0 | AG7: 0 | AH7: 0 | AI7: 0 | AJ7: 0 | AK7: 0 | AL7: 0 | AM7: =SUM(F7:AL7) -> 0
A8: 3 | B8: Radhakrishna | C8: HO | D8: FC8000207658 | E8: Diesel | F8: 0 | G8: 0 | H8: 0 | I8: 0 | J8: 33.44 | K8: 0 | L8: 0 | M8: 0 | N8: 0 | O8: 0 | P8: 0 | Q8: 0 | R8: 35.53 | S8: 0 | T8: 0 | U8: 0 | V8: 0 | W8: 0 | X8: 0 | Y8: 0 | Z8: 0 | AA8: 0 | AB8: 33.44 | AC8: 0 | AD8: 0 | AE8: 0 | AF8: 0 | AG8: 0 | AH8: 0 | AI8: 0 | AJ8: 0 | AK8: 0 | AL8: 0 | AM8: =SUM(F8:AL8) -> 102.41
E9: Petrol | F9: 0 | G9: 0 | H9: 0 | I9: 0 | J9: 0 | K9: 0 | L9: 0 | M9: 0 | N9: 0 | O9: 0 | P9: 0 | Q9: 0 | R9: 0 | S9: 0 | T9: 0 | U9: 0 | V9: 0 | W9: 0 | X9: 0 | Y9: 0 | Z9: 0 | AB9: 0 | AC9: 0 | AD9: 0 | AE9: 0 | AF9: 0 | AG9: 0 | AH9: 0 | AI9: 0 | AJ9: 0 | AK9: 0 | AL9: 0 | AM9: =SUM(F9:AL9) -> 0
A10: 4 | B10: VIjay | C10: HO | D10: FC3450698859 | E10: Diesel | F10: 0 | G10: 0 | H10: 0 | I10: 0 | J10: 0 | K10: 0 | L10: 0 | M10: 0 | N10: 0 | O10: 0 | P10: 49.22 | Q10: 0 | R10: 0 | S10: 0 | T10: 0 | U10: 54.57 | V10: 0 | W10: 0 | X10: 0 | Y10: 0 | Z10: 0 | AA10: 0 | AB10: 0 | AC10: 0 | AD10: 49.8 | AE10: 0 | AF10: 0 | AG10: 0 | AH10: 0 | AI10: 0 | AJ10: 0 | AK10: 0 | AL10: 0 | AM10: =SUM(F10:AL10) -> 153.59
E11: Petrol | F11: 0 | G11: 0 | H11: 0 | I11: 0 | J11: 0 | K11: 0 | L11: 0 | M11: 0 | N11: 0 | O11: 0 | P11: 0 | Q11: 0 | R11: 0 | S11: 0 | T11: 0 | U11: 0 | V11: 0 | W11: 0 | X11: 0 | Y11: 0 | Z11: 0 | AB11: 0 | AC11: 0 | AD11: 0 | AE11: 0 | AF11: 0 | AG11: 0 | AH11: 0 | AI11: 0 | AJ11: 0 | AK11: 0 | AL11: 0 | AM11: =SUM(F11:AL11) -> 0
A12: 5 | B12: Client | C12: Hiriyur | D12: FC3450698864 | E12: Diesel | F12: 0 | G12: 0 | H12: 0 | I12: 0 | J12: 0 | K12: 0 | L12: 0 | M12: 0 | N12: 86.29 | O12: 0 | P12: 0 | Q12: 0 | R12: 0 | S12: 0 | T12: 0 | U12: 0 | V12: 0 | W12: 0 | X12: 0 | Y12: 0 | Z12: 0 | AA12: 0 | AB12: 0 | AC12: 0 | AD12: 145.61 | AE12: 0 | AF12: 0 | AG12: 0 | AH12: 0 | AI12: 0 | AJ12: 0 | AK12: 0 | AL12: 0 | AM12: =SUM(F12:AL12) -> 231.9
E13: Petrol | F13: 0 | G13: 0 | H13: 0 | I13: 0 | J13: 0 | K13: 0 | L13: 0 | M13: 0 | N13: 0 | O13: 0 | P13: 0 | Q13: 0 | R13: 0 | S13: 0 | T13: 0 | U13: 0 | V13: 0 | W13: 0 | X13: 0 | Y13: 0 | Z13: 0 | AB13: 0 | AC13: 0 | AD13: 0 | AE13: 0 | AF13: 0 | AG13: 0 | AH13: 0 | AI13: 0 | AJ13: 0 | AK13: 0 | AL13: 0 | AM13: =SUM(F13:AL13) -> 0
A14: 6 | B14: Client | C14: Hosadurga | D14: FC3450698865 | E14: Diesel | F14: 0 | G14: 0 | H14: 0 | I14: 0 | J14: 0 | K14: 0 | L14: 40 | M14: 40 | N14: 0 | O14: 36 | P14: 35 | Q14: 0 | R14: 0 | S14: 0 | T14: 0 | U14: 0 | V14: 0 | W14: 45 | X14: 45 | Y14: 43.53 | Z14: 40 | AA14: 43 | AB14: 0 | AC14: 40 | AD14: 0 | AE14: 40 | AF14: 0 | AG14: 0 | AH14: 0 | AI14: 0 | AJ14: 0 | AK14: 0 | AL14: 0 | AM14: =SUM(F14:AL14) -> 447.53
E15: Petrol | F15: 0 | G15: 0 | H15: 0 | I15: 0 | J15: 0 | K15: 0 | L15: 0 | M15: 0 | N15: 0 | O15: 0 | P15: 0 | Q15: 0 | R15: 0 | S15: 0 | T15: 0 | U15: 0 | V15: 0 | W15: 0 | X15: 0 | Y15: 0 | Z15: 0 | AB15: 0 | AC15: 0 | AD15: 0 | AE15: 0 | AF15: 0 | AG15: 0 | AH15: 0 | AI15: 0 | AJ15: 0 | AK15: 0 | AL15: 0 | AM15: =SUM(F15:AL15) -> 0
G18: Diesel Price

Sheet HO(DG)
A1: JSASFuel Genie India Pvt.Ltd
A2: S.No | B2: Date | C2: GRN No | D2: Ind No/Bill No | E2: Diesel (Lts) | F2: Price | G2: Amount | H2: Petrol (Lts) | I2: Price | J2: Amount | K2: Total amount | L2: Amount paid | M2: As on date | N2: Remarks
A3: Opening Balance | M3: 32600.613
A4: 1 | B4: 46054 | G4: =E4*F4 -> 0 | H4: 0 | I4: 0 | J4: =H4*I4 -> 0 | K4: =G4+J4 -> 0 | L4: 0 | M4: =M3+K4-L4 -> 32600.613
A5: 2 | B5: 46055 | G5: =E5*F5 -> 0 | H5: 0 | I5: 0 | J5: =H5*I5 -> 0 | K5: =G5+J5 -> 0 | L5: 0 | M5: =M4+K5-L5 -> 32600.613
A6: 3 | B6: 46056 | G6: =E6*F6 -> 0 | H6: 0 | I6: 0 | J6: =H6*I6 -> 0 | K6: =G6+J6 -> 0 | L6: 0 | M6: =M5+K6-L6 -> 32600.613
A7: 4 | B7: 46057 | E7: 55.14 | F7: 95.64 | G7: =E7*F7 -> 5273.5896 | H7: 0 | I7: 0 | J7: =H7*I7 -> 0 | K7: =G7+J7 -> 5273.5896 | L7: 5273.59 | M7: =M6+K7-L7 -> 32600.612 | N7: HPCL
B8: 46057 | L8: 32600 | M8: =M7+K8-L8 -> 0.6123
A9: 5 | B9: 46058 | E9: 170 | F9: 95.83 | G9: =E9*F9 -> 16291.1 | H9: 0 | I9: 0 | J9: =H9*I9 -> 0 | K9: =G9+J9 -> 16291.1 | L9: 0 | M9: =M8+K9-L9 -> 16291.712
A10: 6 | B10: 46058 | E10: 68.97 | F10: 95.7 | G10: =E10*F10 -> 6600.429 | K10: =G10+J10 -> 6600.429 | L10: 6600.43 | M10: =M9+K10-L10 -> 16291.711 | N10: BPCL
A11: 7 | B11: 46058 | E11: 0 | F11: 0 | G11: =E11*F11 -> 0 | H11: 0 | I11: 0 | J11: =H11*I11 -> 0 | K11: =G11+J11 -> 0 | L11: =H11+K11 -> 0 | M11: =M10+K11-L11 -> 16291.711
A12: 8 | B12: 46060 | G12: =E12*F12 -> 0 | H12: 0 | I12: 0 | J12: =H12*I12 -> 0 | K12: =G12+J12 -> 0 | L12: 0 | M12: =M11+K12-L12 -> 16291.711
A13: 9 | B13: 46061 | G13: =E13*F13 -> 0 | H13: 0 | I13: 0 | J13: =H13*I13 -> 0 | K13: =G13+J13 -> 0 | L13: 0 | M13: =M12+K13-L13 -> 16291.711
A14: 10 | B14: 46062 | G14: =E14*F14 -> 0 | H14: 0 | I14: 0 | K14: =G14+J14 -> 0 | L14: 0 | M14: =M13+K14-L14 -> 16291.711
A15: 11 | B15: 46063 | G15: =E15*F15 -> 0 | H15: 0 | I15: 0 | K15: =G15+J15 -> 0 | L15: 0 | M15: =M14+K15-L15 -> 16291.711
A16: 12 | B16: 46064 | E16: 200 | F16: 95.83 | G16: =E16*F16 -> 19166 | H16: 0 | I16: 0 | K16: =G16+J16 -> 19166 | L16: 0 | M16: =M15+K16-L16 -> 35457.711
A17: 13 | B17: 46065 | G17: =E17*F17 -> 0 | H17: 0 | I17: 0 | K17: =G17+J17 -> 0 | L17: 0 | M17: =M16+K17-L17 -> 35457.711
A18: 14 | B18: 46066 | G18: =E18*F18 -> 0 | H18: 0 | I18: 0 | J18: =H18*I18 -> 0 | K18: =G18+J18 -> 0 | L18: 0 | M18: =M17+K18-L18 -> 35457.711
A19: 15 | B19: 46067 | G19: =E19*F19 -> 0 | H19: 0 | I19: 0 | J19: =H19*I19 -> 0 | K19: =G19+J19 -> 0 | L19: 0 | M19: =M18+K19-L19 -> 35457.711
A20: 16 | B20: 46068 | G20: =E20*F20 -> 0 | H20: 0 | I20: 0 | J20: =H20*I20 -> 0 | K20: =G20+J20 -> 0 | L20: 0 | M20: =M19+K20-L20 -> 35457.711 | S20: 16291
A21: 17 | B21: 46069 | G21: =E21*F21 -> 0 | H21: 0 | I21: 0 | J21: =H21*I21 -> 0 | K21: =G21+J21 -> 0 | L21: 0 | M21: =M20+K21-L21 -> 35457.711 | S21: 19166
A22: 18 | B22: 46070 | E22: 190.1 | F22: 95.83 | G22: =E22*F22 -> 18217.283 | J22: =H22*I22 -> 0 | K22: =G22+J22 -> 18217.283 | L22: 0 | M22: =M21+K22-L22 -> 53674.994 | S22: 18217
A23: 19 | B23: 46071 | G23: =E23*F23 -> 0 | J23: =H23*I23 -> 0 | K23: =G23+J23 -> 0 | L23: 0 | M23: =M22+K23-L23 -> 53674.994 | S23: 16291
A24: 20 | B24: 46072 | G24: =E24*F24 -> 0 | J24: =H24*I24 -> 0 | K24: =G24+J24 -> 0 | L24: 0 | M24: =M23+K24-L24 -> 53674.994 | S24: 19522 | T24: 32598
A25: 21 | B25: 46073 | E25: 0 | G25: =E25*F25 -> 0 | J25: =H25*I25 -> 0 | K25: =G25+J25 -> 0 | L25: 0 | M25: =M24+K25-L25 -> 53674.994 | S25: =SUM(S20:S24) -> 89487 | T25: =T24+S25 -> 122085
A26: 22 | B26: 46074 | E26: 170 | F26: 95.83 | G26: =E26*F26 -> 16291.1 | J26: =H26*I26 -> 0 | K26: =G26+J26 -> 16291.1 | L26: 0 | M26: =M25+K26-L26 -> 69966.094
A27: 23 | B27: 46075 | G27: =E27*F27 -> 0 | J27: =H27*I27 -> 0 | K27: =G27+J27 -> 0 | L27: 0 | M27: =M26+K27-L27 -> 69966.094
A28: 24 | B28: 46076 | G28: =E28*F28 -> 0 | J28: =H28*I28 -> 0 | K28: =G28+J28 -> 0 | L28: 0 | M28: =M27+K28-L28 -> 69966.094
A29: 25 | B29: 46077 | G29: =E29*F29 -> 0 | J29: =H29*I29 -> 0 | K29: =G29+J29 -> 0 | L29: 0 | M29: =M28+K29-L29 -> 69966.094
A30: 26 | B30: 46078 | G30: =E30*F30 -> 0 | J30: =H30*I30 -> 0 | K30: =G30+J30 -> 0 | L30: 0 | M30: =M29+K30-L30 -> 69966.094
A31: 27 | B31: 46079 | G31: =E31*F31 -> 0 | J31: =H31*I31 -> 0 | K31: =G31+J31 -> 0 | L31: 0 | M31: =M30+K31-L31 -> 69966.094
A32: 28 | B32: 46080 | G32: =E32*F32 -> 0 | J32: =H32*I32 -> 0 | K32: =G32+J32 -> 0 | M32: =M31+K32-L32 -> 69966.094 | R32: 203.72 | S32: 95.83 | T32: 19522.488
A33: 29 | B33: 46080 | E33: 203.72 | F33: 95.83 | G33: =E33*F33 -> 19522.488 | K33: =G33+J33 -> 19522.488 | L33: 0 | M33: =M32+K33-L33 -> 89488.582 | R33: 30 | S33: 95.7 | T33: 2871
A34: 30 | B34: 46081 | E34: 30 | F34: 95.7 | G34: =E34*F34 -> 2871 | J34: =H34*I34 -> 0 | K34: =G34+J34 -> 2871 | L34: =H34+K34 -> 2871 | M34: =M33+K34-L34 -> 89488.582
A35: 31 | G35: =E35*F35 -> 0 | J35: =H35*I35 -> 0 | K35: =G35+J35 -> 0 | M35: =M34+K35-L35 -> 89488.582
A36: 32 | G36: =E36*F36 -> 0 | J36: =H36*I36 -> 0 | K36: =G36+J36 -> 0 | M36: =M35+K36-L36 -> 89488.582
A37: 33 | G37: =E37*F37 -> 0 | J37: =H37*I37 -> 0 | K37: =G37+J37 -> 0 | L37: 0 | M37: =M36+K37-L37 -> 89488.582 | O37: 2669494 | P37: =O37-M37 -> 2580005.4
E38: 0 | F38: 0 | G38: =E38*F38 -> 0 | J38: =H38*I38 -> 0 | K38: =G38+J38 -> 0 | M38: =M37+K38-L38 -> 89488.582
E39: =SUM(E4:E37) -> 1087.93 | G39: =SUM(G4:G37) -> 104232.99 | H39: =SUM(H4:H37) -> 0 | J39: =SUM(J4:J37) -> 0 | K39: =SUM(K4:K37) -> 104232.99 | L39: =SUM(L4:L37) -> 47345.02
M48: 2408309
...

Sheet Khammam-1
A1: Divya Lakshmi Ganapathi Auto Services
A2: S.No | B2: Date | C2: GRN No | D2: Ind No/Bill No | E2: Diesel (Lts) | F2: Price | G2: Amount | H2: Petrol (Lts) | I2: Price | J2: Amount | K2: Total amount | L2: Amount paid | M2: As 0n Date | N2: Remarks
A3: Opening Balance | K3: 2836061 | M3: 2836061 | O3: 11178224
A4: 1 | B4: 46054 | E4: 4200 | F4: 95.68 | G4: =E4*F4 -> 401856 | K4: =G4+J4 -> 401856 | L4: 0 | M4: =M3+K4-L4 -> 3237917
A5: 2 | B5: 46055 | E5: 5300 | F5: 95.68 | G5: =E5*F5 -> 507104 | H5: 40 | I5: 107.46 | J5: =H5*I5 -> 4298.4 | K5: =G5+J5 -> 511402.4 | L5: 2998712 | M5: =M4+K5-L5 -> 750607.35
A6: 3 | B6: 46056 | E6: 5200 | F6: 95.68 | G6: =E6*F6 -> 497536 | J6: =H6*I6 -> 0 | K6: =G6+J6 -> 497536 | L6: 0 | M6: =M5+K6-L6 -> 1248143.4
A7: 4 | B7: 46057 | E7: 1000 | F7: 95.68 | G7: =E7*F7 -> 95680 | J7: =H7*I7 -> 0 | K7: =G7+J7 -> 95680 | L7: 0 | M7: =M6+K7-L7 -> 1343823.4
A8: 5 | B8: 46058 | E8: 1000 | F8: 95.68 | G8: =E8*F8 -> 95680 | J8: =H8*I8 -> 0 | K8: =G8+J8 -> 95680 | L8: 0 | M8: =M7+K8-L8 -> 1439503.4
A9: 6 | B9: 46059 | E9: 4900 | F9: 95.68 | G9: =E9*F9 -> 468832 | H9: 75 | I9: 107.46 | J9: =H9*I9 -> 8059.5 | K9: =G9+J9 -> 476891.5 | L9: 0 | M9: =M8+K9-L9 -> 1916394.9
A10: 7 | B10: 46060 | E10: 1200 | F10: 95.68 | G10: =E10*F10 -> 114816 | J10: =H10*I10 -> 0 | K10: =G10+J10 -> 114816 | L10: 0 | M10: =M9+K10-L10 -> 2031210.9
A11: 8 | B11: 46061 | E11: 1200 | F11: 95.68 | G11: =E11*F11 -> 114816 | J11: =H11*I11 -> 0 | K11: =G11+J11 -> 114816 | L11: 0 | M11: =M10+K11-L11 -> 2146026.9
A12: 9 | B12: 46062 | E12: 4400 | F12: 95.68 | G12: =E12*F12 -> 420992 | H12: 40 | I12: 107.46 | J12: =H12*I12 -> 4298.4 | K12: =G12+J12 -> 425290.4 | L12: 0 | M12: =M11+K12-L12 -> 2571317.3
A13: 10 | B13: 46063 | E13: 1200 | F13: 95.68 | G13: =E13*F13 -> 114816 | J13: =H13*I13 -> 0 | K13: =G13+J13 -> 114816 | L13: 0 | M13: =M12+K13-L13 -> 2686133.3
A14: 11 | B14: 46064 | E14: 3900 | F14: 95.68 | G14: =E14*F14 -> 373152 | H14: 20 | I14: 107.46 | J14: =H14*I14 -> 2149.2 | K14: =G14+J14 -> 375301.2 | L14: 0 | M14: =M13+K14-L14 -> 3061434.5
A15: 12 | B15: 46065 | E15: 4900 | F15: 95.68 | G15: =E15*F15 -> 468832 | H15: 20 | I15: 107.46 | J15: =H15*I15 -> 2149.2 | K15: =G15+J15 -> 470981.2 | L15: 0 | M15: =M14+K15-L15 -> 3532415.7
A16: 13 | B16: 46066 | E16: 1200 | F16: 95.68 | G16: =E16*F16 -> 114816 | J16: =H16*I16 -> 0 | K16: =G16+J16 -> 114816 | L16: 0 | M16: =M15+K16-L16 -> 3647231.7
A17: 14 | B17: 46067 | E17: 1200 | F17: 95.68 | G17: =E17*F17 -> 114816 | J17: =H17*I17 -> 0 | K17: =G17+J17 -> 114816 | L17: 0 | M17: =M16+K17-L17 -> 3762047.7
A18: 15 | B18: 46068 | G18: =E18*F18 -> 0 | J18: =H18*I18 -> 0 | K18: =G18+J18 -> 0 | L18: 0 | M18: =M17+K18-L18 -> 3762047.7
A19: 16 | B19: 46069 | E19: 2000 | F19: 95.68 | G19: =E19*F19 -> 191360 | J19: =H19*I19 -> 0 | K19: =G19+J19 -> 191360 | L19: 0 | M19: =M18+K19-L19 -> 3953407.7
A20: 17 | B20: 46070 | E20: 2000 | F20: 95.68 | G20: =E20*F20 -> 191360 | J20: =H20*I20 -> 0 | K20: =G20+J20 -> 191360 | L20: 0 | M20: =M19+K20-L20 -> 4144767.7
A21: 18 | B21: 46071 | E21: 4780.64 | F21: 95.68 | G21: =E21*F21 -> 457411.64 | J21: =H21*I21 -> 0 | K21: =G21+J21 -> 457411.64 | L21: 0 | M21: =M20+K21-L21 -> 4602179.3
A22: 19 | B22: 46072 | E22: 4200 | F22: 95.68 | G22: =E22*F22 -> 401856 | H22: 60 | I22: 107.46 | J22: =H22*I22 -> 6447.6 | K22: =G22+J22 -> 408303.6 | L22: 0 | M22: =M21+K22-L22 -> 5010482.9
A23: 20 | B23: 46073 | E23: 4100 | F23: 95.68 | G23: =E23*F23 -> 392288 | J23: =H23*I23 -> 0 | K23: =G23+J23 -> 392288 | L23: 0 | M23: =M22+K23-L23 -> 5402770.9
A24: 21 | B24: 46074 | E24: 4900 | F24: 95.68 | G24: =E24*F24 -> 468832 | J24: =H24*I24 -> 0 | K24: =G24+J24 -> 468832 | L24: 0 | M24: =M23+K24-L24 -> 5871602.9
A25: 22 | B25: 46075 | E25: 1500 | F25: 95.68 | G25: =E25*F25 -> 143520 | J25: =H25*I25 -> 0 | K25: =G25+J25 -> 143520 | L25: 0 | M25: =M24+K25-L25 -> 6015122.9
A26: 23 | B26: 46076 | E26: 4700 | F26: 95.68 | G26: =E26*F26 -> 449696 | H26: 60 | I26: 107.46 | J26: =H26*I26 -> 6447.6 | K26: =G26+J26 -> 456143.6 | L26: 0 | M26: =M25+K26-L26 -> 6471266.5
A27: 24 | B27: 46077 | E27: 4900 | F27: 95.68 | G27: =E27*F27 -> 468832 | H27: 40 | I27: 107.46 | J27: =H27*I27 -> 4298.4 | K27: =G27+J27 -> 473130.4 | L27: 0 | M27: =M26+K27-L27 -> 6944396.9
A28: 25 | B28: 46078 | E28: 3600 | F28: 95.68 | G28: =E28*F28 -> 344448 | H28: 20 | I28: 107.46 | J28: =H28*I28 -> 2149.2 | K28: =G28+J28 -> 346597.2 | L28: 0 | M28: =M27+K28-L28 -> 7290994.1
A29: 26 | B29: 46079 | E29: 4400 | F29: 95.68 | G29: =E29*F29 -> 420992 | H29: 40 | I29: 107.46 | J29: =H29*I29 -> 4298.4 | K29: =G29+J29 -> 425290.4 | L29: 0 | M29: =M28+K29-L29 -> 7716284.5
A30: 27 | B30: 46080 | E30: 3800 | F30: 95.68 | G30: =E30*F30 -> 363584 | H30: 40 | I30: 107.46 | J30: =H30*I30 -> 4298.4 | K30: =G30+J30 -> 367882.4 | L30: 0 | M30: =M29+K30-L30 -> 8084166.9
A31: 28 | B31: 46081 | E31: 1600 | F31: 95.68 | G31: =E31*F31 -> 153088 | J31: =H31*I31 -> 0 | K31: =G31+J31 -> 153088 | L31: 0 | M31: =M30+K31-L31 -> 8237254.9
A32: 29 | G32: =E32*F32 -> 0 | J32: =H32*I32 -> 0 | K32: =G32+J32 -> 0 | L32: 0 | M32: =M31+K32-L32 -> 8237254.9
A33: 30 | G33: =E33*F33 -> 0 | J33: =H33*I33 -> 0 | K33: =G33+J33 -> 0 | L33: 0 | M33: =M32+K33-L33 -> 8237254.9
A34: 31 | G34: =E34*F34 -> 0 | K34: =G34+J34 -> 0 | L34: 0 | M34: =M33+K34-L34 -> 8237254.9
A35: 32 | G35: =E35*F35 -> 0 | J35: =H35*I35 -> 0 | K35: =G35+J35 -> 0 | L35: 0 | M35: =M34+K35-L35 -> 8237254.9
A36: 33 | G36: =E36*F36 -> 0 | J36: =H36*I36 -> 0 | K36: =G36+J36 -> 0 | L36: 0
A37: 34 | G37: =E37*F37 -> 0 | J37: =H37*I37 -> 0 | K37: =G37+J37 -> 0
E38: =SUM(E3:E37) -> 87280.64 | G38: =SUM(G3:G37) -> 8351011.6 | H38: =SUM(H3:H37) -> 455 | J38: =SUM(J3:J37) -> 48894.3 | K38: =SUM(K4:K37) -> 8399905.9 | L38: =SUM(L3:L37) -> 2998712

Sheet Khammam-2
A1: Jayasai union bunk
A2: S.No | B2: Date | C2: GRN No | D2: Ind No/Bill No | E2: Diesel (Lts) | F2: Price | G2: Amount | H2: Petrol (Lts) | I2: Price | J2: Amount | K2: Total amount | L2: Amount paid | M2: As 0n Date | N2: Remarks
A3: Opening Balance | K3: 4435776.8 | M3: 4435776.8
A4: 1 | B4: 46054 | E4: 2800 | F4: 95.7 | G4: =E4*F4 -> 267960 | H4: 20 | I4: 107.48 | J4: =H4*I4 -> 2149.6 | K4: =G4+J4 -> 270109.6 | M4: =M3+K4-L4 -> 4705886.4 | O4: =O3+M4-N4 -> 4705886.4
A5: 2 | B5: 46055 | E5: 2700 | F5: 95.7 | G5: =E5*F5 -> 258390 | J5: =H5*I5 -> 0 | K5: =G5+J5 -> 258390 | M5: =M4+K5-L5 -> 4964276.4
A6: 3 | B6: 46056 | E6: 2800 | F6: 95.7 | G6: =E6*F6 -> 267960 | H6: 60 | I6: 107.48 | J6: =H6*I6 -> 6448.8 | K6: =G6+J6 -> 274408.8 | L6: 4705886 | M6: =M5+K6-L6 -> 532799.2
A7: 4 | B7: 46057 | E7: 2800 | F7: 95.7 | G7: =E7*F7 -> 267960 | H7: 40 | I7: 107.48 | J7: =H7*I7 -> 4299.2 | K7: =G7+J7 -> 272259.2 | M7: =M6+K7-L7 -> 805058.4
A8: 5 | B8: 46058 | G8: =E8*F8 -> 0 | J8: =H8*I8 -> 0 | K8: =G8+J8 -> 0 | M8: =M7+K8-L8 -> 805058.4 | O8: 12802499
A9: 6 | B9: 46059 | G9: =E9*F9 -> 0 | J9: =H9*I9 -> 0 | K9: =G9+J9 -> 0 | M9: =M8+K9-L9 -> 805058.4
A10: 7 | B10: 46060 | E10: 2800 | F10: 95.7 | G10: =E10*F10 -> 267960 | H10: 40 | I10: 107.48 | J10: =H10*I10 -> 4299.2 | K10: =G10+J10 -> 272259.2 | L10: 0 | M10: =M9+K10-L10 -> 1077317.6
A11: 8 | B11: 46061 | G11: =E11*F11 -> 0 | J11: =H11*I11 -> 0 | K11: =G11+J11 -> 0 | M11: =M10+K11-L11 -> 1077317.6
A12: 9 | B12: 46062 | G12: =E12*F12 -> 0 | J12: =H12*I12 -> 0 | K12: =G12+J12 -> 0 | M12: =M11+K12-L12 -> 1077317.6
A13: 10 | B13: 46063 | E13: 5400 | F13: 95.7 | G13: =E13*F13 -> 516780 | H13: 75 | I13: 107.48 | J13: =H13*I13 -> 8061 | K13: =G13+J13 -> 524841 | M13: =M12+K13-L13 -> 1602158.6
A14: 11 | B14: 46064 | E14: 2800 | F14: 95.7 | G14: =E14*F14 -> 267960 | H14: 40 | I14: 107.48 | J14: =H14*I14 -> 4299.2 | K14: =G14+J14 -> 272259.2 | M14: =M13+K14-L14 -> 1874417.8
A15: 12 | B15: 46065 | E15: 2500 | F15: 95.7 | G15: =E15*F15 -> 239250 | J15: =H15*I15 -> 0 | K15: =G15+J15 -> 239250 | M15: =M14+K15-L15 -> 2113667.8
A16: 13 | B16: 46066 | G16: =E16*F16 -> 0 | J16: =H16*I16 -> 0 | K16: =G16+J16 -> 0 | M16: =M15+K16-L16 -> 2113667.8
A17: 14 | B17: 46067 | E17: 2650 | F17: 95.7 | G17: =E17*F17 -> 253605 | H17: 60 | I17: 107.48 | J17: =H17*I17 -> 6448.8 | K17: =G17+J17 -> 260053.8 | M17: =M16+K17-L17 -> 2373721.6
A18: 15 | B18: 46068 | E18: 2000 | F18: 95.7 | G18: =E18*F18 -> 191400 | H18: 40 | I18: 107.48 | J18: =H18*I18 -> 4299.2 | K18: =G18+J18 -> 195699.2 | M18: =M17+K18-L18 -> 2569420.8
A19: 16 | B19: 46069 | E19: 9030.29 | F19: 95.71 | G19: =E19*F19 -> 864289.06 | H19: 60 | I19: 107.48 | J19: =H19*I19 -> 6448.8 | K19: =G19+J19 -> 870737.86 | M19: =M18+K19-L19 -> 3440158.7
A20: 17 | B20: 46070 | E20: 2700 | F20: 95.71 | G20: =E20*F20 -> 258417 | H20: 40 | I20: 107.49 | J20: =H20*I20 -> 4299.6 | K20: =G20+J20 -> 262716.6 | M20: =M19+K20-L20 -> 3702875.3
A21: 18 | B21: 46071 | E21: 9336.48 | F21: 95.71 | G21: =E21*F21 -> 893594.5 | H21: 20 | I21: 107.49 | J21: =H21*I21 -> 2149.8 | K21: =G21+J21 -> 895744.3 | M21: =M20+K21-L21 -> 4598619.6
A22: 19 | B22: 46072 | G22: =E22*F22 -> 0 | J22: =H22*I22 -> 0 | K22: =G22+J22 -> 0 | L22: 0 | M22: =M21+K22-L22 -> 4598619.6
A23: 20 | B23: 46073 | E23: 6863.58 | F23: 95.71 | G23: =E23*F23 -> 656913.24 | H23: 60 | I23: 107.49 | J23: =H23*I23 -> 6449.4 | K23: =G23+J23 -> 663362.64 | M23: =M22+K23-L23 -> 5261982.2
A24: 21 | B24: 46074 | E24: 5500 | F24: 95.71 | G24: =E24*F24 -> 526405 | H24: 75 | I24: 107.49 | J24: =H24*I24 -> 8061.75 | K24: =G24+J24 -> 534466.75 | M24: =M23+K24-L24 -> 5796449
A25: 22 | B25: 46075 | E25: 2200 | F25: 95.71 | G25: =E25*F25 -> 210562 | J25: =H25*I25 -> 0 | K25: =G25+J25 -> 210562 | M25: =M24+K25-L25 -> 6007011
A26: 23 | B26: 46076 | G26: =E26*F26 -> 0 | J26: =H26*I26 -> 0 | K26: =G26+J26 -> 0 | M26: =M25+K26-L26 -> 6007011
A27: 24 | B27: 46077 | E27: 5896.01 | F27: 95.71 | G27: =E27*F27 -> 564307.12 | J27: =H27*I27 -> 0 | K27: =G27+J27 -> 564307.12 | M27: =M26+K27-L27 -> 6571318.1
A28: 25 | B28: 46078 | E28: 4173.42 | F28: 95.71 | G28: =E28*F28 -> 399438.03 | J28: =H28*I28 -> 0 | K28: =G28+J28 -> 399438.03 | M28: =M27+K28-L28 -> 6970756.1
A29: 26 | B29: 46079 | E29: 6113.27 | F29: 95.71 | G29: =E29*F29 -> 585101.07 | J29: =H29*I29 -> 0 | K29: =G29+J29 -> 585101.07 | L29: 2000000 | M29: =M28+K29-L29 -> 5555857.2
A30: 27 | B30: 46080 | G30: =E30*F30 -> 0 | J30: =H30*I30 -> 0 | K30: =G30+J30 -> 0 | M30: =M29+K30-L30 -> 5555857.2
A31: 28 | B31: 46081 | G31: =E31*F31 -> 0 | J31: =H31*I31 -> 0 | K31: =G31+J31 -> 0 | M31: =M30+K31-L31 -> 5555857.2
A32: 29 | G32: =E32*F32 -> 0 | J32: =H32*I32 -> 0 | K32: =G32+J32 -> 0 | M32: =M31+K32-L32 -> 5555857.2
A33: 30 | G33: =E33*F33 -> 0 | J33: =H33*I33 -> 0 | K33: =G33+J33 -> 0 | M33: =M32+K33-L33 -> 5555857.2
A34: 31 | G34: =E34*F34 -> 0 | J34: =H34*I34 -> 0 | K34: =G34+J34 -> 0 | M34: =M33+K34-L34 -> 5555857.2
E35: =SUM(E4:E34) -> 81063.05 | G35: =SUM(G4:G34) -> 7758252 | H35: =SUM(H4:H34) -> 630 | J35: =SUM(J4:J34) -> 67714.35 | K35: =SUM(K4:K34) -> 7825966.4 | L35: =SUM(L4:L34) -> 6705886

Sheet Khammam-3
A1: JSASFuel Genie India Pvt.Ltd
A2: S.No | B2: Date | C2: GRN No | D2: Ind No/Bill No | E2: Diesel (Lts) | F2: Price | G2: Amount | H2: Petrol (Lts) | I2: Price | J2: Amount | K2: Total amount | L2: Amount paid | M2: As 0n Date | N2: Remarks
A3: Opening Balance | K3: 0 | M3: 120400
A4: 1 | B4: 46054 | G4: =E4*F4 -> 0 | J4: =H4*I4 -> 0 | K4: =G4+J4 -> 0 | M4: =M3+K4-L4 -> 120400 | O4: =O3+M4-N4 -> 120400
A5: 2 | B5: 46055 | G5: =E5*F5 -> 0 | J5: =H5*I5 -> 0 | K5: =G5+J5 -> 0 | L5: 0 | M5: =M4+K5-L5 -> 120400
A6: 3 | B6: 46056 | G6: =E6*F6 -> 0 | J6: =H6*I6 -> 0 | K6: =G6+J6 -> 0 | M6: =M5+K6-L6 -> 120400
A7: 4 | B7: 46057 | E7: 6000 | F7: 94.7 | G7: =E7*F7 -> 568200 | J7: =H7*I7 -> 0 | K7: =G7+J7 -> 568200 | L7: 117100 | M7: =M6+K7-L7 -> 571500
A8: 5 | B8: 46058 | E8: 6000 | F8: 94.7 | G8: =E8*F8 -> 568200 | J8: =H8*I8 -> 0 | K8: =G8+J8 -> 568200 | M8: =M7+K8-L8 -> 1139700
A9: 6 | B9: 46059 | E9: 6000 | F9: 94.7 | G9: =E9*F9 -> 568200 | J9: =H9*I9 -> 0 | K9: =G9+J9 -> 568200 | M9: =M8+K9-L9 -> 1707900
A10: 7 | B10: 46060 | E10: 6000 | F10: 94.7 | G10: =E10*F10 -> 568200 | J10: =H10*I10 -> 0 | K10: =G10+J10 -> 568200 | M10: =M9+K10-L10 -> 2276100
A11: 8 | B11: 46061 | E11: 6000 | F11: 94.7 | G11: =E11*F11 -> 568200 | J11: =H11*I11 -> 0 | K11: =G11+J11 -> 568200 | M11: =M10+K11-L11 -> 2844300
A12: 9 | B12: 46062 | E12: 6000 | F12: 94.7 | G12: =E12*F12 -> 568200 | J12: =H12*I12 -> 0 | K12: =G12+J12 -> 568200 | M12: =M11+K12-L12 -> 3412500
A13: 10 | B13: 46063 | E13: 5973 | F13: 94.7 | G13: =E13*F13 -> 565643.1 | J13: =H13*I13 -> 0 | K13: =G13+J13 -> 565643.1 | M13: =M12+K13-L13 -> 3978143.1
A14: 11 | B14: 46064 | E14: 0 | G14: =E14*F14 -> 0 | J14: =H14*I14 -> 0 | K14: =G14+J14 -> 0 | M14: =M13+K14-L14 -> 3978143.1
A15: 12 | B15: 46065 | E15: 6000 | F15: 94.7 | G15: =E15*F15 -> 568200 | J15: =H15*I15 -> 0 | K15: =G15+J15 -> 568200 | M15: =M14+K15-L15 -> 4546343.1
A16: 13 | B16: 46066 | E16: 6000 | F16: 94.7 | G16: =E16*F16 -> 568200 | J16: =H16*I16 -> 0 | K16: =G16+J16 -> 568200 | M16: =M15+K16-L16 -> 5114543.1
A17: 14 | B17: 46067 | E17: 6000 | F17: 94.7 | G17: =E17*F17 -> 568200 | J17: =H17*I17 -> 0 | K17: =G17+J17 -> 568200 | M17: =M16+K17-L17 -> 5682743.1
A18: 15 | B18: 46068 | E18: 6000 | F18: 94.7 | G18: =E18*F18 -> 568200 | J18: =H18*I18 -> 0 | K18: =G18+J18 -> 568200 | M18: =M17+K18-L18 -> 6250943.1
A19: 16 | B19: 46069 | G19: =E19*F19 -> 0 | J19: =H19*I19 -> 0 | K19: =G19+J19 -> 0 | M19: =M18+K19-L19 -> 6250943.1
A20: 17 | B20: 46070 | E20: 6000 | F20: 94.7 | G20: =E20*F20 -> 568200 | J20: =H20*I20 -> 0 | K20: =G20+J20 -> 568200 | M20: =M19+K20-L20 -> 6819143.1
A21: 18 | B21: 46071 | G21: =E21*F21 -> 0 | J21: =H21*I21 -> 0 | K21: =G21+J21 -> 0 | M21: =M20+K21-L21 -> 6819143.1
A22: 19 | B22: 46072 | E22: 6000 | F22: 94.7 | G22: =E22*F22 -> 568200 | J22: =H22*I22 -> 0 | K22: =G22+J22 -> 568200 | M22: =M21+K22-L22 -> 7387343.1
A23: 20 | B23: 46073 | G23: =E23*F23 -> 0 | J23: =H23*I23 -> 0 | K23: =G23+J23 -> 0 | M23: =M22+K23-L23 -> 7387343.1
A24: 21 | B24: 46074 | G24: =E24*F24 -> 0 | J24: =H24*I24 -> 0 | K24: =G24+J24 -> 0 | M24: =M23+K24-L24 -> 7387343.1
A25: 22 | B25: 46075 | E25: 6000 | F25: 94.7 | G25: =E25*F25 -> 568200 | J25: =H25*I25 -> 0 | K25: =G25+J25 -> 568200 | M25: =M24+K25-L25 -> 7955543.1
A26: 23 | B26: 46076 | E26: 6000 | F26: 94.7 | G26: =E26*F26 -> 568200 | J26: =H26*I26 -> 0 | K26: =G26+J26 -> 568200 | M26: =M25+K26-L26 -> 8523743.1
A27: 24 | B27: 46077 | G27: =E27*F27 -> 0 | J27: =H27*I27 -> 0 | K27: =G27+J27 -> 0 | M27: =M26+K27-L27 -> 8523743.1
A28: 25 | B28: 46078 | G28: =E28*F28 -> 0 | J28: =H28*I28 -> 0 | K28: =G28+J28 -> 0 | M28: =M27+K28-L28 -> 8523743.1
A29: 26 | B29: 46079 | G29: =E29*F29 -> 0 | J29: =H29*I29 -> 0 | K29: =G29+J29 -> 0 | L29: 8520000 | M29: =M28+K29-L29 -> 3743.1
A30: 27 | B30: 46080 | E30: 6000 | F30: 94.7 | G30: =E30*F30 -> 568200 | J30: =H30*I30 -> 0 | K30: =G30+J30 -> 568200 | M30: =M29+K30-L30 -> 571943.1
A31: 28 | B31: 46081 | E31: 6000 | F31: 94.7 | G31: =E31*F31 -> 568200 | J31: =H31*I31 -> 0 | K31: =G31+J31 -> 568200 | M31: =M30+K31-L31 -> 1140143.1
A32: 29 | G32: =E32*F32 -> 0 | J32: =H32*I32 -> 0 | K32: =G32+J32 -> 0 | M32: =M31+K32-L32 -> 1140143.1
A33: 30 | G33: =E33*F33 -> 0 | J33: =H33*I33 -> 0 | K33: =G33+J33 -> 0 | M33: =M32+K33-L33 -> 1140143.1
A34: 31 | G34: =E34*F34 -> 0 | J34: =H34*I34 -> 0 | K34: =G34+J34 -> 0 | M34: =M33+K34-L34 -> 1140143.1
E35: =SUM(E4:E34) -> 101973 | G35: =SUM(G4:G34) -> 9656843.1 | H35: =SUM(H4:H34) -> 0 | J35: =SUM(J4:J34) -> 0 | K35: =SUM(K4:K34) -> 9656843.1 | L35: =SUM(L4:L34) -> 8637100

Sheet  Sanga reddy-1
A1: Durga indhan
A2: S.No | B2: Date | C2: GRN No | D2: Ind No/Bill No | E2: Diesel (Lts) | F2: Price | G2: Amount | H2: Petrol (Lts) | I2: Price | J2: Amount | K2: Total amount | L2: Amount paid | M2: As 0n Date | N2: Remarks
A3: Opening Balance
A4: 1 | B4: 46054 | G4: =E4*F4 -> 0 | J4: =H4*I4 -> 0 | K4: =G4+J4 -> 0 | M4: =M3+K4-L4 -> 0 | O4: =O3+M4-N4 -> 0
A5: 2 | B5: 46055 | G5: =E5*F5 -> 0 | J5: =H5*I5 -> 0 | K5: =G5+J5 -> 0 | L5: 0 | M5: =M4+K5-L5 -> 0
A6: 3 | B6: 46056 | G6: =E6*F6 -> 0 | J6: =H6*I6 -> 0 | K6: =G6+J6 -> 0 | M6: =M5+K6-L6 -> 0
A7: 4 | B7: 46057 | G7: =E7*F7 -> 0 | J7: =H7*I7 -> 0 | K7: =G7+J7 -> 0 | M7: =M6+K7-L7 -> 0
A8: 5 | B8: 46058 | G8: =E8*F8 -> 0 | J8: =H8*I8 -> 0 | K8: =G8+J8 -> 0 | M8: =M7+K8-L8 -> 0
A9: 6 | B9: 46059 | G9: =E9*F9 -> 0 | J9: =H9*I9 -> 0 | K9: =G9+J9 -> 0 | M9: =M8+K9-L9 -> 0
A10: 7 | B10: 46060 | G10: =E10*F10 -> 0 | J10: =H10*I10 -> 0 | K10: =G10+J10 -> 0 | M10: =M9+K10-L10 -> 0
A11: 8 | B11: 46061 | G11: =E11*F11 -> 0 | J11: =H11*I11 -> 0 | K11: =G11+J11 -> 0 | M11: =M10+K11-L11 -> 0
A12: 9 | B12: 46062 | G12: =E12*F12 -> 0 | J12: =H12*I12 -> 0 | K12: =G12+J12 -> 0 | M12: =M11+K12-L12 -> 0
A13: 10 | B13: 46063 | G13: =E13*F13 -> 0 | J13: =H13*I13 -> 0 | K13: =G13+J13 -> 0 | M13: =M12+K13-L13 -> 0
A14: 11 | B14: 46064 | G14: =E14*F14 -> 0 | J14: =H14*I14 -> 0 | K14: =G14+J14 -> 0 | M14: =M13+K14-L14 -> 0
A15: 12 | B15: 46065 | G15: =E15*F15 -> 0 | J15: =H15*I15 -> 0 | K15: =G15+J15 -> 0 | M15: =M14+K15-L15 -> 0
A16: 13 | B16: 46066 | G16: =E16*F16 -> 0 | J16: =H16*I16 -> 0 | K16: =G16+J16 -> 0 | M16: =M15+K16-L16 -> 0
A17: 14 | B17: 46067 | G17: =E17*F17 -> 0 | J17: =H17*I17 -> 0 | K17: =G17+J17 -> 0 | M17: =M16+K17-L17 -> 0
... A20: 17 | B20: 46070 | G20: =E20*F20 -> 0 | J20: =H20*I20 -> 0 | K20: =G20+J20 -> 0 | M20: =M19+K20-L20 -> 0
A21: 18 | B21: 46071 | E21: 200 | F21: 96.36 | G21: =E21*F21 -> 19272 | H21: 5 | I21: 108.17 | J21: =H21*I21 -> 540.85 | K21: =G21+J21 -> 19812.85 | M21: =M20+K21-L21 -> 19812.85
A22: 19 | B22: 46072 | E22: 50 | F22: 96.36 | G22: =E22*F22 -> 4818 | H22: 4 | I22: 108.17 | J22: =H22*I22 -> 432.68 | K22: =G22+J22 -> 5250.68 | M22: =M21+K22-L22 -> 25063.53
A23: 20 | B23: 46073 | E23: 67.47 | F23: 96.36 | G23: =E23*F23 -> 6501.4092 | H23: 0 | I23: 108.17 | J23: =H23*I23 -> 0 | K23: =G23+J23 -> 6501.4092 | M23: =M22+K23-L23 -> 31564.939
A24: 21 | B24: 46074 | E24: 200 | F24: 96.36 | G24: =E24*F24 -> 19272 | H24: 0 | I24: 108.17 | J24: =H24*I24 -> 0 | K24: =G24+J24 -> 19272 | M24: =M23+K24-L24 -> 50836.939
A25: 22 | B25: 46075 | E25: 0 | F25: 96.36 | G25: =E25*F25 -> 0 | H25: 0 | I25: 108.17 | J25: =H25*I25 -> 0 | K25: =G25+J25 -> 0 | M25: =M24+K25-L25 -> 50836.939
A26: 23 | B26: 46076 | E26: 0 | F26: 96.36 | G26: =E26*F26 -> 0 | H26: 0 | I26: 108.17 | J26: =H26*I26 -> 0 | K26: =G26+J26 -> 0 | M26: =M25+K26-L26 -> 50836.939
A27: 24 | B27: 46077 | E27: 435.61 | F27: 96.36 | G27: =E27*F27 -> 41975.38 | H27: 5 | I27: 108.17 | J27: =H27*I27 -> 540.85 | K27: =G27+J27 -> 42516.23 | M27: =M26+K27-L27 -> 93353.169
A28: 25 | B28: 46078 | E28: 0 | F28: 96.36 | G28: =E28*F28 -> 0 | H28: 0 | I28: 108.17 | J28: =H28*I28 -> 0 | K28: =G28+J28 -> 0 | M28: =M27+K28-L28 -> 93353.169
A29: 26 | B29: 46079 | E29: 400 | F29: 96.36 | G29: =E29*F29 -> 38544 | H29: 0 | I29: 108.17 | J29: =H29*I29 -> 0 | K29: =G29+J29 -> 38544 | M29: =M28+K29-L29 -> 131897.17
A30: 27 | B30: 46080 | E30: 0 | F30: 96.36 | G30: =E30*F30 -> 0 | H30: 5 | I30: 108.17 | J30: =H30*I30 -> 540.85 | K30: =G30+J30 -> 540.85 | M30: =M29+K30-L30 -> 132438.02
A31: 28 | B31: 46081 | E31: 200 | F31: 96.36 | G31: =E31*F31 -> 19272 | H31: 0 | I31: 108.17 | J31: =H31*I31 -> 0 | K31: =G31+J31 -> 19272 | M31: =M30+K31-L31 -> 151710.02
A32: 29 | G32: =E32*F32 -> 0 | J32: =H32*I32 -> 0 | K32: =G32+J32 -> 0 | M32: =M31+K32-L32 -> 151710.02
A33: 30 | G33: =E33*F33 -> 0 | J33: =H33*I33 -> 0 | K33: =G33+J33 -> 0 | M33: =M32+K33-L33 -> 151710.02
A34: 31 | G34: =E34*F34 -> 0 | J34: =H34*I34 -> 0 | K34: =G34+J34 -> 0 | M34: =M33+K34-L34 -> 151710.02
E35: =SUM(E4:E34) -> 1553.08 | G35: =SUM(G4:G34) -> 149654.79 | H35: =SUM(H4:H34) -> 19 | J35: =SUM(J4:J34) -> 2055.23 | K35: =SUM(K4:K34) -> 151710.02 | L35: =SUM(L4:L34) -> 0

Sheet Sangareddy -2

Sheet Jadcherla-3
A1: JSASFuel Genie India Pvt.Ltd
A2: S.No | B2: Date | C2: GRN No | D2: Ind no/Bill No | E2: Diesel (Lts) | F2: Price | G2: Amount | H2: Petrol (Lts) | I2: Price | J2: Amount | K2: Total amount | L2: Amount paid | M2: As on Date | N2: Remarks
A3: Opening Balance | M3: 299056.5
A4: 1 | B4: 46054 | G4: =E4*F4 -> 0 | H4: 0 | I4: 0 | J4: =H4*I4 -> 0 | K4: =G4+J4 -> 0 | L4: 0 | M4: =+M3+K4-L4 -> 299056.5
A5: 2 | B5: 46055 | G5: =E5*F5 -> 0 | H5: 0 | I5: 0 | J5: =H5*I5 -> 0 | K5: =G5+J5 -> 0 | L5: 0 | M5: =+M4+K5-L5 -> 299056.5
A6: 3 | B6: 46056 | G6: =E6*F6 -> 0 | H6: 0 | I6: 0 | J6: =H6*I6 -> 0 | K6: =G6+J6 -> 0 | M6: =+M5+K6-L6 -> 299056.5
A7: 4 | B7: 46057 | G7: =E7*F7 -> 0 | H7: 0 | I7: 0 | J7: =H7*I7 -> 0 | K7: =G7+J7 -> 0 | L7: 200000 | M7: =+M6+K7-L7 -> 99056.5
A8: 5 | B8: 46058 | G8: =E8*F8 -> 0 | H8: 0 | I8: 0 | J8: =H8*I8 -> 0 | K8: =G8+J8 -> 0 | M8: =+M7+K8-L8 -> 99056.5
A9: 6 | B9: 46059 | E9: 2000 | F9: 95.43 | G9: =E9*F9 -> 190860 | H9: 0 | I9: 0 | J9: =H9*I9 -> 0 | K9: =G9+J9 -> 190860 | M9: =+M8+K9-L9 -> 289916.5
A10: 7 | B10: 46060 | G10: =E10*F10 -> 0 | H10: 0 | I10: 0 | J10: =H10*I10 -> 0 | K10: =G10+J10 -> 0 | M10: =+M9+K10-L10 -> 289916.5 | R10: 700
A11: 8 | B11: 46061 | E11: 1500 | F11: 95.43 | G11: =E11*F11 -> 143145 | H11: 0 | I11: 0 | J11: =H11*I11 -> 0 | K11: =G11+J11 -> 143145 | M11: =+M10+K11-L11 -> 433061.5 | S11: 5000
A12: 9 | B12: 46062 | G12: =E12*F12 -> 0 | H12: 0 | I12: 0 | J12: =H12*I12 -> 0 | K12: =G12+J12 -> 0 | M12: =+M11+K12-L12 -> 433061.5 | S12: 1500
A13: 10 | B13: 46063 | E13: 2500 | F13: 95.43 | G13: =E13*F13 -> 238575 | H13: 0 | I13: 0 | J13: =H13*I13 -> 0 | K13: =G13+J13 -> 238575 | M13: =+M12+K13-L13 -> 671636.5 | S13: 500
A14: 11 | B14: 46064 | G14: =E14*F14 -> 0 | H14: 0 | I14: 0 | J14: =H14*I14 -> 0 | K14: =G14+J14 -> 0 | M14: =+M13+K14-L14 -> 671636.5
A15: 12 | B15: 46065 | G15: =E15*F15 -> 0 | H15: 0 | I15: 0 | J15: =H15*I15 -> 0 | K15: =G15+J15 -> 0 | M15: =+M14+K15-L15 -> 671636.5
A16: 13 | B16: 46066 | E16: 2000 | F16: 95.43 | G16: =E16*F16 -> 190860 | H16: 0 | I16: 0 | J16: =H16*I16 -> 0 | K16: =G16+J16 -> 190860 | M16: =+M15+K16-L16 -> 862496.5
A17: 14 | B17: 46067 | E17: 2400 | F17: 95.43 | G17: =E17*F17 -> 229032 | H17: 0 | I17: 0 | J17: =H17*I17 -> 0 | K17: =G17+J17 -> 229032 | M17: =+M16+K17-L17 -> 1091528.5
A18: 15 | B18: 46068 | G18: =E18*F18 -> 0 | H18: 0 | I18: 0 | J18: =H18*I18 -> 0 | K18: =G18+J18 -> 0 | M18: =+M17+K18-L18 -> 1091528.5
A19: 16 | B19: 46069 | G19: =E19*F19 -> 0 | H19: 0 | I19: 0 | J19: =H19*I19 -> 0 | K19: =G19+J19 -> 0 | M19: =+M18+K19-L19 -> 1091528.5
A20: 17 | B20: 46070 | E20: 2192 | F20: 95.43 | G20: =E20*F20 -> 209182.56 | H20: 0 | I20: 0 | J20: =H20*I20 -> 0 | K20: =G20+J20 -> 209182.56 | M20: =+M19+K20-L20 -> 1300711.1
A21: 18 | B21: 46071 | E21: 2033 | F21: 95.43 | G21: =E21*F21 -> 194009.19 | H21: 0 | I21: 0 | J21: =H21*I21 -> 0 | K21: =G21+J21 -> 194009.19 | M21: =+M20+K21-L21 -> 1494720.2
A22: 19 | B22: 46072 | G22: =E22*F22 -> 0 | H22: 0 | I22: 0 | J22: =H22*I22 -> 0 | K22: =G22+J22 -> 0 | M22: =+M21+K22-L22 -> 1494720.2
A23: 20 | B23: 46073 | E23: 2000 | F23: 95.43 | G23: =E23*F23 -> 190860 | H23: 0 | I23: 0 | J23: =H23*I23 -> 0 | K23: =G23+J23 -> 190860 | L23: 1000000 | M23: =+M22+K23-L23 -> 685580.25
A24: 21 | B24: 46074 | E24: 2000 | F24: 95.43 | G24: =E24*F24 -> 190860 | H24: 0 | I24: 0 | J24: =H24*I24 -> 0 | K24: =G24+J24 -> 190860 | M24: =+M23+K24-L24 -> 876440.25
A25: 22 | B25: 46075 | F25: 95.43 | G25: =E25*F25 -> 0 | H25: 0 | I25: 0 | J25: =H25*I25 -> 0 | K25: =G25+J25 -> 0 | M25: =+M24+K25-L25 -> 876440.25
A26: 23 | B26: 46076 | E26: 2200 | F26: 95.43 | G26: =E26*F26 -> 209946 | H26: 0 | I26: 0 | J26: =H26*I26 -> 0 | K26: =G26+J26 -> 209946 | M26: =+M25+K26-L26 -> 1086386.2
A27: 24 | B27: 46077 | G27: =E27*F27 -> 0 | H27: 0 | I27: 0 | J27: =H27*I27 -> 0 | K27: =G27+J27 -> 0 | M27: =+M26+K27-L27 -> 1086386.2
A28: 25 | B28: 46078 | E28: 2200 | F28: 95.43 | G28: =E28*F28 -> 209946 | H28: 0 | I28: 0 | J28: =H28*I28 -> 0 | K28: =G28+J28 -> 209946 | M28: =+M27+K28-L28 -> 1296332.2
A29: 26 | B29: 46079 | E29: 2200 | F29: 95.43 | G29: =E29*F29 -> 209946 | H29: 0 | I29: 0 | J29: =H29*I29 -> 0 | K29: =G29+J29 -> 209946 | L29: 480000 | M29: =+M28+K29-L29 -> 1026278.2
A30: 27 | B30: 46080 | G30: =E30*F30 -> 0 | H30: 0 | I30: 0 | J30: =H30*I30 -> 0 | K30: =G30+J30 -> 0 | M30: =+M29+K30-L30 -> 1026278.2
A31: 28 | B31: 46081 | G31: =E31*F31 -> 0 | H31: 0 | I31: 0 | J31: =H31*I31 -> 0 | K31: =G31+J31 -> 0 | M31: =+M30+K31-L31 -> 1026278.2
A32: 29 | G32: =E32*F32 -> 0 | H32: 0 | I32: 0 | J32: =H32*I32 -> 0 | K32: =G32+J32 -> 0 | M32: =+M31+K32-L32 -> 1026278.2
A33: 30 | E33: 0 | F33: 0 | G33: =E33*F33 -> 0 | H33: 0 | I33: 0 | J33: =H33*I33 -> 0 | K33: =G33+J33 -> 0 | M33: =+M32+K33-L33 -> 1026278.2
A34: 31 | G34: =E34*F34 -> 0 | H34: 0 | I34: 0 | J34: =H34*I34 -> 0 | K34: =G34+J34 -> 0 | L34: 0 | M34: =+M33+K34-L34 -> 1026278.2
E35: =SUM(E4:E34) -> 25225 | G35: =SUM(G4:G34) -> 2407221.8 | H35: =SUM(H4:H34) -> 0 | J35: =SUM(J4:J34) -> 0 | K35: =SUM(K4:K34) -> 2407221.8 | L35: =SUM(L4:L34) -> 1680000
F38: /

Sheet Jadcherla-4
A1: Poornima Filling Station
A2: S.No | B2: Date | C2: GRN No | D2: Ind No/Bill No | E2: Diesel (Lts) | F2: Price | G2: Amount | H2: Petrol (Lts) | I2: Price | J2: Amount | K2: Total amount | L2: Amount paid | M2: As on date | N2: Remarks
A3: Opening Balance | M3: 5405
A4: 1 | B4: 46054 | G4: =E4*F4 -> 0 | H4: 0 | I4: 0 | J4: =H4*I4 -> 0 | K4: =G4+J4 -> 0 | L4: 0 | M4: =M3+K4-L4 -> 5405
A5: 2 | B5: 46055 | G5: =E5*F5 -> 0 | H5: 0 | I5: 0 | J5: =H5*I5 -> 0 | K5: =G5+J5 -> 0 | L5: 0 | M5: =M4+K5-L5 -> 5405
A6: 3 | B6: 46056 | G6: =E6*F6 -> 0 | H6: 0 | I6: 0 | J6: =H6*I6 -> 0 | K6: =G6+J6 -> 0 | L6: 0 | M6: =M5+K6-L6 -> 5405
A7: 4 | B7: 46057 | G7: =E7*F7 -> 0 | H7: 0 | I7: 0 | J7: =H7*I7 -> 0 | K7: =G7+J7 -> 0 | L7: 0 | M7: =M6+K7-L7 -> 5405
A8: 5 | B8: 46058 | G8: =E8*F8 -> 0 | H8: 0 | I8: 0 | J8: =H8*I8 -> 0 | K8: =G8+J8 -> 0 | L8: 0 | M8: =M7+K8-L8 -> 5405
A9: 6 | B9: 46059 | G9: =E9*F9 -> 0 | H9: 40 | I9: 108.1 | J9: =H9*I9 -> 4324 | K9: =G9+J9 -> 4324 | L9: 0 | M9: =M8+K9-L9 -> 9729
A10: 7 | B10: 46060 | G10: =E10*F10 -> 0 | H10: 0 | I10: 0 | J10: =H10*I10 -> 0 | K10: =G10+J10 -> 0 | L10: 0 | M10: =M9+K10-L10 -> 9729
A11: 8 | B11: 46061 | G11: =E11*F11 -> 0 | H11: 0 | I11: 0 | J11: =H11*I11 -> 0 | K11: =G11+J11 -> 0 | L11: 0 | M11: =M10+K11-L11 -> 9729
A12: 9 | B12: 46062 | G12: =E12*F12 -> 0 | H12: 0 | I12: 0 | J12: =H12*I12 -> 0 | K12: =G12+J12 -> 0 | L12: 0 | M12: =M11+K12-L12 -> 9729
A13: 10 | B13: 46063 | G13: =E13*F13 -> 0 | H13: 0 | I13: 0 | J13: =H13*I13 -> 0 | K13: =G13+J13 -> 0 | L13: 0 | M13: =M12+K13-L13 -> 9729
A14: 11 | B14: 46064 | G14: =E14*F14 -> 0 | H14: 0 | I14: 0 | J14: =H14*I14 -> 0 | K14: =G14+J14 -> 0 | L14: 0 | M14: =M13+K14-L14 -> 9729
A15: 12 | B15: 46065 | G15: =E15*F15 -> 0 | H15: 50 | I15: 108.1 | J15: =H15*I15 -> 5405 | K15: =G15+J15 -> 5405 | L15: 0 | M15: =M14+K15-L15 -> 15134
... A25: 22 | B25: 46075 | G25: =E25*F25 -> 0 | H25: 0 | I25: 0 | J25: =H25*I25 -> 0 | K25: =G25+J25 -> 0 | L25: 0 | M25: =M24+K25-L25 -> 20539
A26: 23 | B26: 46076 | E26: 0 | F26: 0 | G26: =E26*F26 -> 0 | H26: 40 | I26: 108.1 | J26: =H26*I26 -> 4324 | K26: =G26+J26 -> 4324 | L26: 0 | M26: =M25+K26-L26 -> 24863
A27: 24 | B27: 46077 | G27: =E27*F27 -> 0 | H27: 0 | I27: 0 | J27: =H27*I27 -> 0 | K27: =G27+J27 -> 0 | L27: 0 | M27: =M26+K27-L27 -> 24863
A28: 25 | B28: 46078 | G28: =E28*F28 -> 0 | H28: 0 | I28: 0 | J28: =H28*I28 -> 0 | K28: =G28+J28 -> 0 | L28: 0 | M28: =M27+K28-L28 -> 24863
A29: 26 | B29: 46079 | G29: =E29*F29 -> 0 | H29: 0 | I29: 0 | J29: =H29*I29 -> 0 | K29: =G29+J29 -> 0 | L29: 0 | M29: =M28+K29-L29 -> 24863
A30: 27 | B30: 46080 | G30: =E30*F30 -> 0 | H30: 0 | I30: 0 | J30: =H30*I30 -> 0 | K30: =G30+J30 -> 0 | L30: 0 | M30: =M29+K30-L30 -> 24863
A31: 28 | B31: 46081 | G31: =E31*F31 -> 0 | H31: 0 | I31: 0 | J31: =H31*I31 -> 0 | K31: =G31+J31 -> 0 | M31: =M30+K31-L31 -> 24863
A32: 28 | G32: =E32*F32 -> 0 | H32: 0 | I32: 0 | J32: =H32*I32 -> 0 | K32: =G32+J32 -> 0 | M32: =M31+K32-L32 -> 24863
A33: 28 | G33: =E33*F33 -> 0 | H33: 0 | I33: 0 | J33: =H33*I33 -> 0 | K33: =G33+J33 -> 0 | M33: =M32+K33-L33 -> 24863
A34: 28 | G34: =E34*F34 -> 0 | J34: =H34*I34 -> 0 | K34: =G34+J34 -> 0 | M34: =M33+K34-L34 -> 24863
E35: =SUM(E4:E34) -> 0 | G35: =SUM(G4:G34) -> 0 | H35: =SUM(H4:H34) -> 180 | J35: =SUM(J4:J34) -> 19458 | K35: =SUM(K4:K34) -> 19458 | L35: =SUM(L4:L34) -> 0

Sheet Devarakhadra
A1: Kurumurthy Swami F/S
A2: S.No | B2: Date | C2: GRN No | D2: Ind no/Bill No | E2: Diesel (Lts) | F2: Price | G2: Amount | H2: Petrol (Lts) | I2: Price | J2: Amount | K2: Total amount | L2: Amount paid | M2: As on Date | N2: Remarks
A3: Opening Balance | M3: 5856.2924 | O3: 121213.37
A4: 1 | B4: 46054 | E4: 10 | F4: 97.1 | G4: =E4*F4 -> 971 | H4: 0 | I4: 0 | J4: =H4*I4 -> 0 | K4: =G4+J4 -> 971 | M4: =+M3+K4-L4 -> 6827.2924
A5: 2 | B5: 46055 | E5: 0 | F5: 0 | G5: =E5*F5 -> 0 | J5: =H5*I5 -> 0 | K5: =G5+J5 -> 0 | L5: 7000 | M5: =+M4+K5-L5 -> -172.7076
A6: 3 | B6: 46056 | E6: 0 | F6: 0 | G6: =E6*F6 -> 0 | J6: =H6*I6 -> 0 | K6: =G6+J6 -> 0 | M6: =+M5+K6-L6 -> -172.7076
A7: 4 | B7: 46057 | E7: 0 | F7: 0 | G7: =E7*F7 -> 0 | H7: 13 | I7: 108.83 | J7: =H7*I7 -> 1414.79 | K7: =G7+J7 -> 1414.79 | M7: =+M6+K7-L7 -> 1242.0824 | O7: 1307 | P7: =O7-M7 -> 64.9176
A8: 5 | B8: 46058 | E8: 0 | F8: 0 | G8: =E8*F8 -> 0 | J8: =H8*I8 -> 0 | K8: =G8+J8 -> 0 | M8: =+M7+K8-L8 -> 1242.0824
A9: 6 | B9: 46059 | E9: 0 | F9: 0 | G9: =E9*F9 -> 0 | J9: =H9*I9 -> 0 | K9: =G9+J9 -> 0 | M9: =+M8+K9-L9 -> 1242.0824
A10: 7 | B10: 46060 | E10: 0 | F10: 0 | G10: =E10*F10 -> 0 | J10: =H10*I10 -> 0 | K10: =G10+J10 -> 0 | M10: =+M9+K10-L10 -> 1242.0824
A11: 8 | B11: 46061 | E11: 0 | F11: 0 | G11: =E11*F11 -> 0 | J11: =H11*I11 -> 0 | K11: =G11+J11 -> 0 | M11: =+M10+K11-L11 -> 1242.0824
A12: 9 | B12: 46062 | E12: 0 | F12: 0 | G12: =E12*F12 -> 0 | J12: =H12*I12 -> 0 | K12: =G12+J12 -> 0 | M12: =+M11+K12-L12 -> 1242.0824
A13: 10 | B13: 46063 | E13: 0 | F13: 0 | G13: =E13*F13 -> 0 | J13: =H13*I13 -> 0 | K13: =G13+J13 -> 0 | M13: =+M12+K13-L13 -> 1242.0824
A14: 11 | B14: 46064 | E14: 0 | F14: 0 | G14: =E14*F14 -> 0 | J14: =H14*I14 -> 0 | K14: =G14+J14 -> 0 | L14: 1307 | M14: =+M13+K14-L14 -> -64.9176
A15: 12 | B15: 46065 | E15: 0 | F15: 0 | G15: =E15*F15 -> 0 | J15: =H15*I15 -> 0 | K15: =G15+J15 -> 0 | L15: -64.92 | M15: =+M14+K15-L15 -> 0.0023999999 | N15: rounoff
A16: 13 | B16: 46066 | E16: 0 | F16: 0 | G16: =E16*F16 -> 0 | J16: =H16*I16 -> 0 | K16: =G16+J16 -> 0 | M16: =+M15+K16-L16 -> 0.0023999999
A17: 14 | B17: 46067 | E17: 0 | F17: 0 | G17: =E17*F17 -> 0 | J17: =H17*I17 -> 0 | K17: =G17+J17 -> 0 | M17: =+M16+K17-L17 -> 0.0023999999
A18: 15 | B18: 46068 | E18: 0 | F18: 0 | G18: =E18*F18 -> 0 | J18: =H18*I18 -> 0 | K18: =G18+J18 -> 0 | M18: =+M17+K18-L18 -> 0.0023999999
A19: 16 | B19: 46069 | E19: 0 | F19: 0 | G19: =E19*F19 -> 0 | J19: =H19*I19 -> 0 | K19: =G19+J19 -> 0 | M19: =+M18+K19-L19 -> 0.0023999999 | N19: Fuel bills
A20: 17 | B20: 46070 | E20: 0 | F20: 0 | G20: =E20*F20 -> 0 | J20: =H20*I20 -> 0 | K20: =G20+J20 -> 0 | M20: =+M19+K20-L20 -> 0.0023999999
A21: 18 | B21: 46071 | E21: 0 | F21: 0 | G21: =E21*F21 -> 0 | J21: =H21*I21 -> 0 | K21: =G21+J21 -> 0 | M21: =+M20+K21-L21 -> 0.0023999999
A22: 19 | B22: 46072 | E22: 0 | F22: 0 | G22: =E22*F22 -> 0 | J22: =H22*I22 -> 0 | K22: =G22+J22 -> 0 | M22: =+M21+K22-L22 -> 0.0023999999
A23: 20 | B23: 46073 | E23: 0 | F23: 0 | G23: =E23*F23 -> 0 | J23: =H23*I23 -> 0 | K23: =G23+J23 -> 0 | M23: =+M22+K23-L23 -> 0.0023999999
A24: 21 | B24: 46074 | E24: 0 | F24: 0 | G24: =E24*F24 -> 0 | J24: =H24*I24 -> 0 | K24: =G24+J24 -> 0 | M24: =+M23+K24-L24 -> 0.0023999999
A25: 22 | B25: 46075 | E25: 0 | F25: 0 | G25: =E25*F25 -> 0 | J25: =H25*I25 -> 0 | K25: =G25+J25 -> 0 | M25: =+M24+K25-L25 -> 0.0023999999
A26: 23 | B26: 46076 | E26: 0 | F26: 0 | G26: =E26*F26 -> 0 | J26: =H26*I26 -> 0 | K26: =G26+J26 -> 0 | M26: =+M25+K26-L26 -> 0.0023999999
A27: 24 | B27: 46077 | E27: 0 | F27: 0 | G27: =E27*F27 -> 0 | J27: =H27*I27 -> 0 | K27: =G27+J27 -> 0 | M27: =+M26+K27-L27 -> 0.0023999999
A28: 25 | B28: 46078 | E28: 0 | F28: 0 | G28: =E28*F28 -> 0 | J28: =H28*I28 -> 0 | K28: =G28+J28 -> 0 | M28: =+M27+K28-L28 -> 0.0023999999
A29: 26 | B29: 46079 | E29: 0 | F29: 0 | G29: =E29*F29 -> 0 | J29: =H29*I29 -> 0 | K29: =G29+J29 -> 0 | M29: =+M28+K29-L29 -> 0.0023999999
A30: 27 | B30: 46080 | E30: 0 | F30: 0 | G30: =E30*F30 -> 0 | J30: =H30*I30 -> 0 | K30: =G30+J30 -> 0 | M30: =+M29+K30-L30 -> 0.0023999999
A31: 28 | B31: 46081 | E31: 0 | F31: 0 | G31: =E31*F31 -> 0 | J31: =H31*I31 -> 0 | K31: =G31+J31 -> 0 | M31: =+M30+K31-L31 -> 0.0023999999
A32: 29 | E32: 0 | F32: 0 | G32: =E32*F32 -> 0 | J32: =H32*I32 -> 0 | K32: =G32+J32 -> 0 | M32: =+M31+K32-L32 -> 0.0023999999
A33: 30 | E33: 0 | F33: 0 | G33: =E33*F33 -> 0 | J33: =H33*I33 -> 0 | K33: =G33+J33 -> 0 | M33: =+M32+K33-L33 -> 0.0023999999
A34: 31 | G34: =E34*F34 -> 0 | J34: =H34*I34 -> 0 | K34: =G34+J34 -> 0 | M34: =+M33+K34-L34 -> 0.0023999999
E35: =SUM(E4:E34) -> 10 | G35: =SUM(G4:G34) -> 971 | H35: =SUM(H4:H34) -> 13 | J35: =SUM(J4:J34) -> 1414.79 | K35: =SUM(K4:K34) -> 2385.79 | L35: =SUM(L4:L34) -> 8242.08

Sheet Dindi
A1: Akarapu Balakistamma Fillling
A2: S.No | B2: Date | C2: GRN No | D2: Ind no/Bill No | E2: Diesel (Lts) | F2: Price | G2: Amount | H2: Petrol (Lts) | I2: Price | J2: Amount | K2: Total amount | L2: Amount paid | M2: As on Date | N2: Remarks
A3: Opening Balance | M3: 0
A4: 1 | B4: 45689 | G4: =E4*F4 -> 0 | H4: 0 | I4: 0 | J4: =H4*I4 -> 0 | K4: =G4+J4 -> 0 | L4: =+K4 -> 0 | M4: 0
A5: 2 | B5: 45690 | G5: =E5*F5 -> 0 | H5: 0 | I5: 0 | J5: =H5*I5 -> 0 | K5: =G5+J5 -> 0 | L5: =+K5 -> 0 | M5: 0
A6: 3 | B6: 45691 | G6: =E6*F6 -> 0 | H6: 0 | I6: 0 | J6: =H6*I6 -> 0 | K6: =G6+J6 -> 0 | L6: =+K6 -> 0 | M6: 0
A7: 4 | B7: 45692 | G7: =E7*F7 -> 0 | H7: 0 | I7: 0 | J7: =H7*I7 -> 0 | K7: =G7+J7 -> 0 | L7: =+K7 -> 0 | M7: 0
A8: 5 | B8: 45693 | G8: =E8*F8 -> 0 | H8: 0 | I8: 0 | J8: =H8*I8 -> 0 | K8: =G8+J8 -> 0 | L8: =+K8 -> 0 | M8: 0
A9: 6 | B9: 45694 | G9: =E9*F9 -> 0 | H9: 0 | I9: 0 | J9: =H9*I9 -> 0 | K9: =G9+J9 -> 0 | L9: =+K9 -> 0 | M9: 0
A10: 7 | B10: 45695 | G10: =E10*F10 -> 0 | H10: 0 | I10: 0 | J10: =H10*I10 -> 0 | K10: =G10+J10 -> 0 | L10: =+K10 -> 0 | M10: 0
A11: 8 | B11: 45696 | G11: =E11*F11 -> 0 | H11: 0 | I11: 0 | J11: =H11*I11 -> 0 | K11: =G11+J11 -> 0 | L11: =+K11 -> 0 | M11: 0
A12: 9 | B12: 45697 | G12: =E12*F12 -> 0 | H12: 0 | I12: 0 | J12: =H12*I12 -> 0 | K12: =G12+J12 -> 0 | L12: =+K12 -> 0 | M12: 0
A13: 10 | B13: 45698 | G13: =E13*F13 -> 0 | H13: 0 | I13: 0 | J13: =H13*I13 -> 0 | K13: =G13+J13 -> 0 | L13: =+K13 -> 0 | M13: 0
A14: 11 | B14: 45699 | G14: =E14*F14 -> 0 | H14: 0 | I14: 0 | J14: =H14*I14 -> 0 | K14: =G14+J14 -> 0 | L14: =+K14 -> 0 | M14: 0
A15: 12 | B15: 45700 | G15: =E15*F15 -> 0 | H15: 0 | I15: 0 | J15: =H15*I15 -> 0 | K15: =G15+J15 -> 0 | L15: =+K15 -> 0 | M15: 0
... A27: 24 | B27: 45712 | G27: =E27*F27 -> 0 | H27: 0 | I27: 0 | J27: =H27*I27 -> 0 | K27: =G27+J27 -> 0 | L27: =+K27 -> 0 | M27: 0
A28: 25 | B28: 45713 | H28: 0 | I28: 0 | J28: =H28*I28 -> 0 | K28: =G28+J28 -> 0 | L28: =+K28 -> 0 | M28: 0
A29: 26 | B29: 45714 | G29: =E29*F29 -> 0 | H29: 0 | I29: 0 | J29: =H29*I29 -> 0 | K29: =G29+J29 -> 0 | L29: =+K29 -> 0 | M29: 0
A30: 27 | B30: 45715 | G30: =E30*F30 -> 0 | H30: 0 | I30: 0 | J30: =H30*I30 -> 0 | K30: =G30+J30 -> 0 | L30: =+K30 -> 0 | M30: 0
A31: 28 | B31: 45716 | G31: =E31*F31 -> 0 | H31: 0 | I31: 0 | J31: =H31*I31 -> 0 | K31: =G31+J31 -> 0 | L31: =+K31 -> 0 | M31: 0
A32: 29 | G32: =E32*F32 -> 0 | H32: 0 | I32: 0 | J32: =H32*I32 -> 0 | K32: =G32+J32 -> 0 | L32: =+K32 -> 0 | M32: 0
A33: 30 | G33: =E33*F33 -> 0 | H33: 0 | I33: 0 | J33: =H33*I33 -> 0 | K33: =G33+J33 -> 0 | L33: =+K33 -> 0 | M33: 0
A34: 31 | G34: =E34*F34 -> 0 | H34: 0 | I34: 0 | J34: =H34*I34 -> 0 | K34: =G34+J34 -> 0 | L34: =+K34 -> 0 | M34: 0
E35: =SUM(E4:E34) -> 0 | G35: =SUM(G4:G34) -> 0 | H35: =SUM(H4:H34) -> 0 | J35: =SUM(J4:J34) -> 0 | K35: =SUM(K4:K34) -> 0 | L35: =SUM(L4:L34) -> 0

Sheet Amalapuram
A2: S.No | B2: Date | C2: GRN No | D2: Ind no/Bill No | E2: Diesel (Lts) | F2: Price | G2: Amount | H2: Petrol (Lts) | I2: Price | J2: Amount | K2: Total amount | L2: Amount paid | M2: As on Date | N2: Remarks
A3: Opening Balance | M3: 0
A4: 1 | B4: 01.02.2026 | C4: Sri Sathya Dattha Aparna -BPCL | D4: Chendurthi(Yeleswaram) | E4: 0 | G4: 0 | H4: 20.63 | I4: 97.28 | J4: 2006.55 | K4: =G4+J4 -> 2006.55 | L4: 2006.55 | M4: =+M3+K4-L4 -> 0
A5: 2 | B5: 02.02.2026 | C5: BP Lala Cheruvu Bharat Petroleum | D5: Rajahmundry | E5: 46.14 | F5: 96.74 | G5: =E5*F5 -> 4463.5836 | H5: 5 | I5: 108.86 | J5: 544.3 | K5: =G5+J5 -> 5007.8836 | L5: 5007.88 | M5: =+M4+K5-L5 -> 0.0036
A6: 3 | B6: 05.02.2026 | C6: Sri Venkateswara Enterprises | D6: Yanam | E6: 46.69 | F6: 86.75 | G6: =E6*F6 -> 4050.3575 | H6: 0 | I6: 0 | J6: 0 | K6: =G6+J6 -> 4050.3575 | L6: 4050 | M6: =+M5+K6-L6 -> 0.3611
A7: 4 | B7: 05.02.2026 | C7: Sri Radha krishna Agencies | D7: Kakinada | H7: 10 | I7: 110.05 | J7: 1100.5 | K7: =G7+J7 -> 1100.5 | L7: 1100.5 | M7: =+M6+K7-L7 -> 0.3611
