Workbook

Sheet  MIs
A2: S.No | B2: NAme | C2: Lacation | D2: Card Number | E2: Card Number | F2: Category | G2: 1st Jan | I2: 2nd Jan | J2: 3rd Jan | K2: 4th Jan | L2: 5th Jan | M2: 6th Jan | N2: 7th Jan | O2: 8th Jan | P2: 9th Jan | Q2: 10th Jan | R2: 11th Jan | S2: 12th Jan | T2: 13th Jan | U2: 14th Jan | V2: 15th Jan | W2: 16th Jan | X2: 17th Jan | Y2: 18th Jan | Z2: 19th Jan | AA2: 20th Jan | AB2: 21st Jan | AC2: 22nd Jan | AD2: 23rd Jan | AE2: 24th Jan | AF2: 25th Jan | AG2: 26th Jan | AH2: 27th Jan | AI2: 28th Jan | AJ2: 29th Jan | AK2: 30th Jan | AL2: 31st Jan | AM2: Total
F3: Diesel
A4: 1 | B4: Rambabu | C4: HO(Two Wheeler) | D4: FC3450563999 | E4: Diesel | F4: 0 | G4: 0 | H4: 0 | I4: 0 | J4: 0 | K4: 0 | L4: 0 | M4: 0 | N4: 0 | O4: 0 | P4: 0 | Q4: 0 | R4: 0 | S4: 0 | T4: 0 | U4: 0 | V4: 0 | W4: 0 | X4: 5.22 | Y4: 0 | Z4: 0 | AA4: 0 | AB4: 0 | AC4: 0 | AD4: 60 | AE4: 0 | AF4: 0 | AG4: 0 | AH4: 4.56 | AI4: 0 | AJ4: 0 | AK4: 0 | AL4: 0 | AM4: =SUM(F4:AL4) -> 69.78
E5: Petrol | F5: 0 | G5: 4.69 | H5: 0 | I5: 0 | J5: 0 | K5: 0 | L5: 0 | M5: 0 | N5: 3.91 | O5: 0 | P5: 6.98 | Q5: 0 | R5: 0 | S5: 0 | T5: 0 | U5: 0 | V5: 0 | W5: 0 | X5: 0 | Y5: 0 | Z5: 0 | AB5: 0 | AC5: 0 | AD5: 0 | AE5: 0 | AF5: 0 | AG5: 0 | AH5: 0 | AI5: 0 | AJ5: 0 | AK5: 0 | AL5: 0 | AM5: =SUM(F5:AL5) -> 15.58
A6: 2 | B6: Hanumanth Rao | C6: HO | D6: FC3450676131 | E6: Diesel | F6: 0 | G6: 0 | H6: 0 | I6: 0 | J6: 0 | K6: 0 | L6: 0 | M6: 0 | N6: 0 | O6: 0 | P6: 0 | Q6: 0 | R6: 0 | S6: 0 | T6: 0 | U6: 0 | V6: 0 | W6: 0 | X6: 0 | Y6: 0 | Z6: 0 | AA6: 0 | AB6: 0 | AC6: 0 | AD6: 0 | AE6: 0 | AF6: 0 | AG6: 0 | AH6: 0 | AI6: 0 | AJ6: 0 | AK6: 0 | AL6: 0 | AM6: =SUM(F6:AL6) -> 0
E7: Petrol | F7: 0 | G7: 0 | H7: 0 | I7: 0 | J7: 0 | K7: 0 | L7: 0 | M7: 0 | N7: 0 | O7: 0 | P7: 0 | Q7: 0 | R7: 0 | S7: 0 | T7: 0 | U7: 0 | V7: 0 | W7: 0 | X7: 0 | Y7: 0 | Z7: 0 | AB7: 0 | AC7: 0 | AD7: 0 | AE7: 0 | AF7: 0 | AG7: 0 | AH7: 0 | AI7: 0 | AJ7: 0 | AK7: 0 | AL7: 0 | AM7: =SUM(F7:AL7) -> 0
A8: 3 | B8: Radhakrishna | C8: HO | D8: FC8000207658 | E8: Diesel | F8: 0 | G8: 0 | H8: 0 | I8: 0 | J8: 33.44 | K8: 0 | L8: 0 | M8: 0 | N8: 0 | O8: 0 | P8: 0 | Q8: 0 | R8: 35.53 | S8: 0 | T8: 0 | U8: 0 | V8: 0 | W8: 0 | X8: 0 | Y8: 0 | Z8: 0 | AA8: 0 | AB8: 33.44 | AC8: 0 | AD8: 0 | AE8: 0 | AF8: 0 | AG8: 0 | AH8: 0 | AI8: 0 | AJ8: 0 | AK8: 0 | AL8: 0 | AM8: =SUM(F8:AL8) -> 102.41
E9: Petrol | F9: 0 | G9: 0 | H9: 0 | I9: 0 | J9: 0 | K9: 0 | L9: 0 | M9: 0 | N9: 0 | O9: 0 | P9: 0 | Q9: 0 | R9: 0 | S9: 0 | T9: 0 | U9: 0 | V9: 0 | W9: 0 | X9: 0 | Y9: 0 | Z9: 0 | AB9: 0 | AC9: 0 | AD9: 0 | AE9: 0 | AF9: 0 | AG9: 0 | AH9: 0 | AI9: 0 | AJ9: 0 | AK9: 0 | AL9: 0 | AM9: =SUM(F9:AL9) -> 0
A10: 4 | B10: VIjay | C10: HO | D10: FC3450698859 | E10: Diesel | F10: 0 | G10: 0 | H10: 0 | I10: 0 | J10: 0 | K10: 0 | L10: 0 | M10: 0 | N10: 0 | O10: 0 | P10: 49.22 | Q10: 0 | R10: 0 | S10: 0 | T10: 0 | U10: 54.57 | V10: 0 | W10: 0 | X10: 0 | Y10: 0 | Z10: 0 | AA10: 0 | AB10: 0 | AC10: 0 | AD10: 49.8 | AE10: 0 | AF10: 0 | AG10: 0 | AH10: 0 | AI10: 0 | AJ10: 0 | AK10: 0 | AL10: 0 | AM10: =SUM(F10:AL10) -> 153.59
E11: Petrol | F11: 0 | G11: 0 | H11: 0 | I11: 0 | J11: 0 | K11: 0 | L11: 0 | M11: 0 | N11: 0 | O11: 0 | P11: 0 | Q11: 0 | R11: 0 | S11: 0 | T11: 0 | U11: 0 | V11: 0 | W11: 0 | X11: 0 | Y11: 0 | Z11: 0 | AB11: 0 | AC11: 0 | AD11: 0 | AE11: 0 | AF11: 0 | AG11: 0 | AH11: 0 | AI11: 0 | AJ11: 0 | AK11: 0 | AL11: 0 | AM11: =SUM(F11:AL11) -> 0
A12: 5 | B12: Client | C12: Hiriyur | D12: FC3450698864 | E12: Diesel | F12: 0 | G12: 0 | H12: 0 | I12: 0 | J12: 0 | K12: 0 | L12: 0 | M12: 0 | N12: 86.29 | O12: 0 | P12: 0 | Q12: 0 | R12: 0 | S12: 0 | T12: 0 | U12: 0 | V12: 0 | W12: 0 | X12: 0 | Y12: 0 | Z12: 0 | AA12: 0 | AB12: 0 | AC12: 0 | AD12: 145.61 | AE12: 0 | AF12: 0 | AG12: 0 | AH12: 0 | AI12: 0 | AJ12: 0 | AK12: 0 | AL12: 0 | AM12: =SUM(F12:AL12) -> 231.9
E13: Petrol | F13: 0 | G13: 0 | H13: 0 | I13: 0 | J13: 0 | K13: 0 | L13: 0 | M13: 0 | N13: 0 | O13: 0 | P13: 0 | Q13: 0 | R13: 0 | S13: 0 | T13: 0 | U13: 0 | V13: 0 | W13: 0 | X13: 0 | Y13: 0 | Z13: 0 | AB13: 0 | AC13: 0 | AD13: 0 | AE13: 0 | AF13: 0 | AG13: 0 | AH13: 0 | AI13: 0 | AJ13: 0 | AK13: 0 | AL13: 0 | AM13: =SUM(F13:AL13) -> 0
A14: 6 | B14: Client | C14: Hosadurga | D14: FC3450698865 | E14: Diesel | F14: 0 | G14: 0 | H14: 0 | I14: 0 | J14: 0 | K14: 0 | L14: 40 | M14: 40 | N14: 0 | O14: 36 | P14: 35 | Q14: 0 | R14: 0 | S14: 0 | T14: 0 | U14: 0 | V14: 0 | W14: 45 | X14: 45 | Y14: 43.53 | Z14: 40 | AA14: 43 | AB14: 0 | AC14: 40 | AD14: 0 | AE14: 40 | AF14: 0 | AG14: 0 | AH14: 0 | AI14: 0 | AJ14: 0 | AK14: 0 | AL14: 0 | AM14: =SUM(F14:AL14) -> 447.53
E15: Petrol | F15: 0 | G15: 0 | H15: 0 | I15: 0 | J15: 0 | K15: 0 | L15: 0 | M15: 0 | N15: 0 | O15: 0 | P15: 0 | Q15: 0 | R15: 0 | S15: 0 | T15: 0 | U15: 0 | V15: 0 | W15: 0 | X15: 0 | Y15: 0 | Z15: 0 | AB15: 0 | AC15: 0 | AD15: 0 | AE15: 0 | AF15: 0 | AG15: 0 | AH15: 0 | AI15: 0 | AJ15: 0 | AK15: 0 | AL15: 0 | AM15: =SUM(F15:AL15) -> 0
G18: Diesel Price

Sheet  May-2026
A1: S.no | B1: Site Name | C1: Bunk Name | D1: Diesel(Liters) | E1: Diesel Amount | F1: Petrol(Liters) | G1: Petrol Amount | H1: Total Amount | I1: Opening Blance | J1: Amount Paid | K1: Closing Balances
A2: 1 | B2: Khammam-1 | C2: Divya laxmi ganapathi | D2: =+'Khammam-1'!E38 -> 48265.34 | E2: =+'Khammam-1'!G38 -> 4766880.2 | F2: =+'Khammam-1'!H38 -> 0 | G2: =+'Khammam-1'!J38 -> 0 | H2: =E2+G2 -> 4766880.2 | I2: =+'Khammam-1'!K3 -> 1769630.7 | J2: =+'Khammam-1'!L38 -> 3882012 | K2: =H2+I2-J2 -> 2654498.9
A3: 2 | B3: Khammam-2 | C3: Jayasai union bunk | D3: =+'Khammam-2'!E36 -> 49055.57 | E3: =+'Khammam-2'!G36 -> 4879543.5 | F3: =+'Khammam-2'!H36 -> 1040 | G3: =+'Khammam-2'!J36 -> 114901.15 | H3: =E3+G3 -> 4994444.6 | I3: =+'Khammam-2'!K3 -> 3725653 | J3: =+'Khammam-2'!L36 -> 0 | K3: =H3+I3-J3 -> 8720097.6
A4: 3 | B4: Khammam-3 | C4: JSASFuel Genie India Pvt.Ltd | D4: =+'Khammam-3'!E35 -> 0 | E4: =+'Khammam-3'!G35 -> 0 | F4: =+'Khammam-3'!H35 -> 0 | G4: =+'Khammam-3'!J35 -> 0 | H4: =E4+G4 -> 0 | I4: =+'Khammam-3'!M3 -> 2572600.3 | J4: =+'Khammam-3'!L35 -> 1000000 | K4: =H4+I4-J4 -> 1572600.3
A5: 4 | B5: Khammam-Cash&Carry | C5: NA | D5: =+' Khammam&Cash'!E46 -> 22238.479 | E5: =+' Khammam&Cash'!G46 -> 2148660 | F5: =+' Khammam&Cash'!H46 -> 0 | G5: =+' Khammam&Cash'!J46 -> 0 | H5: =E5+G5 -> 2148660 | I5: =+' Khammam&Cash'!M3 -> 0 | J5: =+' Khammam&Cash'!L46 -> 2148660 | K5: =H5+I5-J5 -> 0
A6: 5 | B6: Jadcherla-1 | C6: JSASFuel Genie India Pvt.Ltd | D6: =+'Jadcherla-3'!E35 -> 0 | E6: =+'Jadcherla-3'!G35 -> 0 | F6: =+'Jadcherla-3'!H35 -> 0 | G6: =+'Jadcherla-3'!J35 -> 0 | H6: =E6+G6 -> 0 | I6: =+'Jadcherla-3'!M3 -> 1313281.7 | J6: =+'Jadcherla-3'!L35 -> 0 | K6: =H6+I6-J6 -> 1313281.7
A7: 6 | B7: Jadcherla-2 | C7: Shree Poornima F/S | D7: =+'Jadcherla-4'!E35 -> 1000 | E7: =+'Jadcherla-4'!G35 -> 96300 | F7: =+'Jadcherla-4'!H35 -> 112 | G7: =+'Jadcherla-4'!J35 -> 12264.88 | H7: =E7+G7 -> 108564.88 | I7: =+'Jadcherla-4'!M3 -> 3523.2 | J7: =+'Jadcherla-4'!L35 -> 96300 | K7: =H7+I7-J7 -> 15788.08
A8: 7 | B8: Jadcherla-3 | C8: Sai Baba Filling Station | D8: =+' Jadcherla'!E35 -> 10537.12 | E8: =+' Jadcherla'!G35 -> 1049374.1 | F8: =+' Jadcherla'!H35 -> 0 | G8: =+' Jadcherla'!J35 -> 0 | H8: =E8+G8 -> 1049374.1 | I8: =+' Jadcherla'!M3 -> 44630 | J8: =+' Jadcherla'!L35 -> 922889 | K8: =H8+I8-J8 -> 171115.11
A9: 8 | B9: Sangareddy-2 | C9: Durga Bhavani F/S | D9: =+' Sangareddy-2'!E35 -> 6343.62 | E9: =+' Sangareddy-2'!G35 -> 620418.55 | F9: =+' Sangareddy-2'!H35 -> 261.72 | G9: =+' Sangareddy-2'!J35 -> 28902.223 | H9: =E9+G9 -> 649320.78 | I9: =+' Sangareddy-2'!M3 -> 258995.39 | J9: =+' Sangareddy-2'!L35 -> 800000 | K9: =H9+I9-J9 -> 108316.17 | M9: VASUDEO NIVRUTTI
A10: 9 | B10: Sangareddy-3 | C10: Shiva Parvathi Filling Station | D10: =+' Sangareddy-3'!E35 -> 18194.62 | E10: =+' Sangareddy-3'!G35 -> 1819638.1 | F10: =+' Sangareddy-3'!H35 -> 25.36 | G10: =+' Sangareddy-3'!J35 -> 2948.1 | H10: =E10+G10 -> 1822586.2 | I10: =+' Sangareddy-3'!M3 -> 163539.24 | J10: =+' Sangareddy-3'!L35 -> 1000000 | K10: =H10+I10-J10 -> 986125.39
A11: 10 | B11: NarayanaKhed | C11: Sai Shiva Filling Station | D11: =Narayankhed!E35 -> 1537.82 | E11: =+Narayankhed!G35 -> 152799.64 | F11: =+Narayankhed!H35 -> 0 | G11: =+Narayankhed!J35 -> 0 | H11: =E11+G11 -> 152799.64 | I11: =+Narayankhed!M3 -> 0 | J11: =+Narayankhed!L35 -> 152799.64 | K11: =H11+I11-J11 -> 0
A12: 11 | B12: Dindi | C12: Akarapu Balakistamma Fillling | D12: =+Dindi!E35 -> 0 | E12: =+Dindi!G35 -> 0 | F12: =+Dindi!H35 -> 0 | G12: =+Dindi!J35 -> 0 | H12: =E12+G12 -> 0 | I12: =+Dindi!M3 -> 0 | J12: =+Dindi!L35 -> 0 | K12: =H12+I12-J12 -> 0 | M12: =PROPER(M9) -> Vasudeo Nivrutti
A13: 12 | B13: Madanapalli | C13: NA | D13: =+'Madana palli'!E36 -> 18.98 | E13: =+'Madana palli'!G36 -> 1998.9736 | F13: =+'Madana palli'!H36 -> 4.25 | G13: =+'Madana palli'!J36 -> 500.055 | H13: =E13+G13 -> 2499.0286 | I13: =+'Madana palli'!M3 -> 0 | J13: =+'Madana palli'!L36 -> 2499.0286 | K13: =H13+I13-J13 -> 0
A14: 13 | B14: Kakinada | C14: NA | D14: =+Amalapuram!E102 -> 3362.44 | E14: =+Amalapuram!G102 -> 340456.85 | F14: =+Amalapuram!H102 -> 258.11 | G14: =+Amalapuram!J102 -> 29399.14 | H14: =E14+G14 -> 369855.99 | I14: =+Amalapuram!M3 -> 0 | J14: =+Amalapuram!L102 -> 369855.99 | K14: =H14+I14-J14 -> 0.00049999991
A15: 14 | B15: YG Gudda-2 | C15: Pankaja HP Fuel Center | D15: =+'YG Gudda-2'!E38 -> 9000 | E15: =+'YG Gudda-2'!G38 -> 848355 | F15: =+'YG Gudda-2'!H38 -> 280 | G15: =+'YG Gudda-2'!J38 -> 29456 | H15: =E15+G15 -> 877811 | I15: =+'YG Gudda-2'!M3 -> 194105.96 | J15: =+'YG Gudda-2'!L38 -> 882798 | K15: =H15+I15-J15 -> 189118.96
A16: 15 | B16: Hosadurga-2 | C16: Shree Veeraprathap Fuel | D16: =+'Hosadurga -2'!E35 -> 2700.44 | E16: =+'Hosadurga -2'!G35 -> 260751.02 | F16: =+'Hosadurga -2'!H35 -> 155.43 | G16: =+'Hosadurga -2'!J35 -> 16960.59 | H16: =+'Hosadurga -2'!K35 -> 277711.61 | I16: =+'Hosadurga -2'!K3 -> 248489.28 | J16: =+'Hosadurga -2'!L35 -> 377999.69 | K16: =H16+I16-J16 -> 148201.19
A17: 16 | B17: Malebennuru(KUWSDB) | C17: Sri Ramanjuneya Service Station | D17: =+'Malebenur(KUWSDB)'!E37 -> 4600 | E17: =+'Malebenur(KUWSDB)'!G37 -> 434664 | F17: =+'Malebenur(KUWSDB)'!H37 -> 145 | G17: =+'Malebenur(KUWSDB)'!J37 -> 15440.3 | H17: =E17+G17 -> 450104.3 | I17: =+'Malebenur(KUWSDB)'!K3 -> 193649.21 | J17: =+'Malebenur(KUWSDB)'!L37 -> 548000 | K17: =H17+I17-J17 -> 95753.51
A18: 17 | B18: kadur | C18: Vishal Service Station | D18: =+Kadur!E35 -> 1600 | E18: =+Kadur!G35 -> 152240 | F18: =+Kadur!H35 -> 70 | G18: =+Kadur!J35 -> 7648.9 | H18: =E18+G18 -> 159888.9 | I18: =+Kadur!K3 -> 0 | J18: =+Kadur!L35 -> 0 | K18: =H18+I18-J18 -> 159888.9
A19: 18 | B19: Hiriyur(VJNL) | C19: Sri Balaji Agencies | D19: =+'Hiriyur(VJNL)'!E35 -> 3500 | E19: =+'Hiriyur(VJNL)'!G35 -> 328440 | F19: =+'Hiriyur(VJNL)'!H35 -> 245 | G19: =+'Hiriyur(VJNL)'!J35 -> 25740.4 | H19: =E19+G19 -> 354180.4 | I19: =+'Hiriyur(VJNL)'!K3 -> 278745.3 | J19: =+'Hiriyur(VJNL)'!L35 -> 450000 | K19: =H19+I19-J19 -> 182925.7
A20: 19 | B20: Chellakere(KUWSDB) | C20: Shivaganga Service Station | D20: =+'Chellakere -1'!E38 -> 3200.08 | E20: =+'Chellakere -1'!G38 -> 305200.07 | F20: =+'Chellakere -1'!H38 -> 210.03 | G20: =+'Chellakere -1'!J38 -> 22624.204 | H20: =E20+G20 -> 327824.27 | I20: =+'Chellakere -1'!K3 -> 249803.37 | J20: =+'Chellakere -1'!L38 -> 506012.56 | K20: =H20+I20-J20 -> 71615.087
A21: 20 | B21: Chellakere(KUWSDB)-09 | C21: Shivaganga Service Station | D21: =+' Chellakere-PKG-9'!E36 -> 600.65 | E21: =+' Chellakere-PKG-9'!G36 -> 57117.949 | F21: =+' Chellakere-PKG-9'!H36 -> 46 | G21: =+' Chellakere-PKG-9'!J36 -> 4960.94 | H21: =E21+G21 -> 62078.889 | I21: =+' Chellakere-PKG-9'!M3 -> 0 | J21: =+' Chellakere-PKG-9'!L36 -> 62078.889 | K21: =H21+I21-J21 -> 0
A22: 21 | B22: Molakalmuru | C22: Sri Lakshmi Venkateshwara Filling Station | D22: =+Molakamuru!E35 -> 1200 | E22: =+Molakamuru!G35 -> 114030 | F22: =+Molakamuru!H35 -> 45 | G22: =+Molakamuru!J35 -> 4876.8 | H22: =E22+G22 -> 118906.8 | I22: =+Molakamuru!K3 -> 56291.815 | J22: =+Molakamuru!L35 -> 112377.94 | K22: =H22+I22-J22 -> 62820.675
A23: 22 | B23: Chennagiri | C23: NA | D23: =+' Chennagiri'!E35 -> 965 | E23: =+' Chennagiri'!G35 -> 92635.8 | F23: =+' Chennagiri'!H35 -> 44.73 | G23: =+' Chennagiri'!J35 -> 4999.9194 | H23: =E23+G23 -> 97635.719 | I23: =+' Chennagiri'!K3 -> 0 | J23: =+' Chennagiri'!L35 -> 97635.719 | K23: =H23+I23-J23 -> 0
A24: 23 | B24: Khanapur(PKG-3) | C24: V.V.Varde | D24: =+Khanapur!E35 -> 1755.95 | E24: =+Khanapur!G35 -> 164273.6 | F24: =+Khanapur!H35 -> 85 | G24: =+Khanapur!J35 -> 8971.5 | H24: =E24+G24 -> 173245.1 | I24: =+Khanapur!M3 -> 114295.13 | J24: =+Khanapur!L35 -> 228514.58 | K24: =H24+I24-J24 -> 59025.654
A25: 24 | B25: Munavalli(PKG-3) | C25: Shre Shiva Petroleum | D25: =+'Munavali-2'!E40 -> 9550 | E25: =+'Munavali-2'!G40 -> 899267 | F25: =+'Munavali-2'!H40 -> 162.75 | G25: =+'Munavali-2'!J40 -> 17029.498 | H25: =E25+G25 -> 916296.5 | I25: =+'Munavali-2'!M3 -> 567608.01 | J25: =+'Munavali-2'!L40 -> 1038902.9 | K25: =H25+I25-J25 -> 445001.62
A26: 25 | B26: Munavalli(PKG-3) | C26: Daneshwari Petroleum | D26: =+' Munavali'!E39 -> 5841.67 | E26: =+' Munavali'!G39 -> 564521.75 | F26: =+' Munavali'!H39 -> 120 | G26: =+' Munavali'!J39 -> 13194.4 | H26: =E26+G26 -> 577716.15 | I26: =+' Munavali'!M3 -> 0 | J26: =+' Munavali'!L39 -> 300000 | K26: =H26+I26-J26 -> 277716.15
A27: 26 | B27: Borgaon(PKG-3) | C27: Aadisagar Petrolium | D27: =+Borgaon!E35 -> 5710.55 | E27: =+Borgaon!G35 -> 546400.84 | F27: =+Borgaon!H35 -> 76 | G27: =+Borgaon!J35 -> 8070.16 | H27: =E27+G27 -> 554471 | I27: =+Borgaon!K3 -> 106655.39 | J27: =+Borgaon!L35 -> 385000 | K27: =H27+I27-J27 -> 276126.39
A28: 27 | B28: Ugar,Kudichi(PKG-3) | C28: Shiri Bhrhmanath Petrolium | D28: =+'Ugar,Khagwad,Kudichi'!E37 -> 12026.84 | E28: =+'Ugar,Khagwad,Kudichi'!G37 -> 1132213.3 | F28: =+'Ugar,Khagwad,Kudichi'!H37 -> 241 | G28: =+'Ugar,Khagwad,Kudichi'!J37 -> 26148.23 | H28: =E28+G28 -> 1158361.5 | I28: =+'Ugar,Khagwad,Kudichi'!M3 -> 584214.75 | J28: =+'Ugar,Khagwad,Kudichi'!L37 -> 1265943 | K28: =H28+I28-J28 -> 476633.25
A29: 28 | B29: Shedbal | C29: Varad Petroluem | D29: =+shedbal!E35 -> 1600 | E29: =+shedbal!G35 -> 159568 | F29: =+shedbal!H35 -> 75 | G29: =+shedbal!J35 -> 8388.75 | H29: =E29+G29 -> 167956.75 | I29: =+shedbal!M3 -> 0 | J29: =+shedbal!L35 -> 0 | K29: =H29+I29-J29 -> 167956.75
A30: 29 | B30: Kabbur(PKG-3) | C30: Shri Jai Hanuman Petrolium | D30: =+Kabbur!E35 -> 1179.59 | E30: =+Kabbur!G35 -> 114899.78 | F30: =+Kabbur!H35 -> 24.95 | G30: =+Kabbur!J35 -> 2650.523 | H30: =E30+G30 -> 117550.31 | I30: 0 | J30: =+Kabbur!L35 -> 117550.31 | K30: =H30+I30-J30 -> 0
A31: 30 | B31: Kumta (PKG-1) | C31: V.M.MIRJANKAR (KUMTA) BHARAT | D31: =+kumta!E39 -> 1445 | E31: =+kumta!G39 -> 137309.75 | F31: =+kumta!H39 -> 179.62 | G31: =+kumta!J39 -> 19391.78 | H31: =E31+G31 -> 156701.53 | I31: =kumta!M3 -> 2607.22 | J31: =+kumta!L39 -> 87987 | K31: =H31+I31-J31 -> 71321.75
A32: 31 | B32: Jalgaon-1 | C32: Jai Bajarang Sarvo Senter Bodwad | D32: =+' Jalgaon-1'!E55 -> 0 | E32: =+' Jalgaon-1'!G55 -> 0 | F32: =+' Jalgaon-1'!H55 -> 0 | G32: =+' Jalgaon-1'!J55 -> 0 | H32: =E32+G32 -> 0 | I32: =+' Jalgaon-1'!K3 -> 93813.679 | J32: =+' Jalgaon-1'!L55 -> 93813 | K32: =H32+I32-J32 -> 0.6791
A33: 32 | B33: Jalgaon-2 | C33: Nayara | D33: =+'Jalgoan-2'!E56 -> 21903.53 | E33: ='Jalgoan-2'!G56 -> 2088961 | F33: =+'Jalgoan-2'!H56 -> 415 | G33: =+'Jalgoan-2'!J56 -> 46926.1 | H33: =E33+G33 -> 2135887.1 | I33: =+'Jalgoan-2'!M3 -> 2665456 | J33: =+'Jalgoan-2'!L56 -> 2631873.3 | K33: =H33+I33-J33 -> 2169469.7
A34: 33 | B34: Jalgaon-3 | C34: Vasudeo Nivrutti | D34: =+' Jalgaon-3'!E19 -> 20133.17 | E34: =+' Jalgaon-3'!G19 -> 1896800.9 | F34: =+' Jalgaon-3'!H19 -> 0 | G34: =+' Jalgaon-3'!J19 -> 0 | H34: =E34+G34 -> 1896800.9 | I34: =+' Jalgaon-3'!M3 -> 0 | J34: =+' Jalgaon-3'!L19 -> 1402087.9 | K34: =H34+I34-J34 -> 494713.05
A35: 34 | B35: Jalgaon-4 | C35: Raksha Auto Fuels | D35: =+'Jalgaon-4'!E19 -> 12037.21 | E35: =+'Jalgaon-4'!G19 -> 1108054.6 | F35: =+'Jalgaon-4'!H19 -> 0 | G35: =+'Jalgaon-4'!J19 -> 0 | H35: =E35+G35 -> 1108054.6 | I35: =+'Jalgaon-4'!M3 -> 0 | J35: =+'Jalgaon-4'!L19 -> 1108054.6 | K35: =H35+I35-J35 -> 0
A36: 35 | B36: Jalgaon-5 C | C36: NA | D36: =+' Jalgaon-5 c'!E39 -> 39436.77 | E36: =+' Jalgaon-5 c'!G39 -> 3690231.3 | F36: =+' Jalgaon-5 c'!H39 -> 0 | G36: =+' Jalgaon-5 c'!J39 -> 0 | H36: =E36+G36 -> 3690231.3 | I36: =+' Jalgaon-5 c'!M3 -> 0 | J36: =+' Jalgaon-5 c'!L39 -> 3690231.3 | K36: =H36+I36-J36 -> 0.0039999997
A37: 36 | B37: MKBD | C37: Shree Sai Samarth Petroleum | D37: =+MKBD!E41 -> 24319.62 | E37: =+MKBD!G41 -> 2308313.2 | F37: =+MKBD!H41 -> 115 | G37: =+MKBD!J41 -> 12326 | H37: =E37+G37 -> 2320639.2 | I37: =+MKBD!K3 -> 2570275.5 | J37: =+MKBD!L41 -> 1000000 | K37: =H37+I37-J37 -> 3890914.7
A38: 37 | B38: Haveri | C38: M/s Magavi City Fuels | D38: =' Haveri-2'!E42 -> 8690.58 | E38: =' Haveri-2'!G42 -> 817553.99 | F38: =' Haveri-2'!H42 -> 196.08 | G38: =' Haveri-2'!J42 -> 21168.399 | H38: =E38+G38 -> 838722.38 | I38: =' Haveri-2'!M3 -> 60112.508 | J38: =+' Haveri-2'!L42 -> 692610.93 | K38: =H38+I38-J38 -> 206223.97
A39: 38 | B39: Guttal-2 | C39: Himagiri Petroleum | D39: =+' Guttal-2'!E35 -> 3290 | E39: =+' Guttal-2'!G35 -> 310419.4 | F39: =+' Guttal-2'!H35 -> 137 | G39: =+' Guttal-2'!J35 -> 14876.32 | H39: =E39+G39 -> 325295.72 | I39: =+' Guttal-2'!M3 -> 200595.1 | J39: =+' Guttal-2'!L35 -> 420000 | K39: =H39+I39-J39 -> 105890.82
A40: 39 | B40: Rattihali-2 | C40: Shiva Oil Traders | D40: =+'Rattihali-2'!E37 -> 5535.6 | E40: =+'Rattihali-2'!G37 -> 529300.29 | F40: =+'Rattihali-2'!H37 -> 100 | G40: =+'Rattihali-2'!J37 -> 10687.53 | H40: =E40+G40 -> 539987.82 | I40: =+'Rattihali-2'!M3 -> 266017.9 | J40: =+'Rattihali-2'!L37 -> 450000 | K40: =H40+I40-J40 -> 356005.72
...

Sheet HO(DG)
A1: JSASFuel Genie India Pvt.Ltd
A2: S.No | B2: Date | C2: GRN No | D2: Ind No/Bill No | E2: Diesel (Lts) | F2: Price | G2: Amount | H2: Petrol (Lts) | I2: Price | J2: Amount | K2: Total amount | L2: Amount paid | M2: As on date | N2: Remarks
A3: Opening Balance | K3: 79033.75 | M3: 79033.75 | O3: 2623243.4
A4: 1 | B4: 46143 | G4: =E4*F4 -> 0 | H4: 0 | I4: 0 | J4: =H4*I4 -> 0 | K4: =G4+J4 -> 0 | L4: 0 | M4: =M3+K4-L4 -> 79033.75
A5: 2 | B5: 46144 | G5: =E5*F5 -> 0 | K5: =G5+J5 -> 0 | M5: =M4+K5-L5 -> 79033.75 | R5: HO | S5: 188521.22
A6: 3 | B6: 46145 | G6: =E6*F6 -> 0 | K6: =G6+J6 -> 0 | M6: =M5+K6-L6 -> 79033.75 | R6: Khammam | S6: 8227903
A7: 4 | B7: 46146 | E7: 110 | F7: 95.64 | G7: =E7*F7 -> 10520.4 | K7: =G7+J7 -> 10520.4 | L7: =H7+K7 -> 10520.4 | M7: =M6+K7-L7 -> 79033.75 | R7: Jadcherla | S7: 2453209.4
A8: 5 | B8: 46147 | G8: =E8*F8 -> 0 | K8: =G8+J8 -> 0 | M8: =M7+K8-L8 -> 79033.75 | P8: 5679 | R8: Total | S8: =SUM(S5:S7) -> 10869634
A9: 6 | B9: 46148 | G9: =E9*F9 -> 0 | K9: =G9+J9 -> 0 | M9: =M8+K9-L9 -> 79033.75 | S9: 10869632
A10: 7 | B10: 46149 | E10: 35 | F10: 95.64 | G10: =E10*F10 -> 3347.4 | K10: =G10+J10 -> 3347.4 | L10: =H10+K10 -> 3347.4 | M10: =M9+K10-L10 -> 79033.75 | N10: HPCL | S10: =S9-S8 -> -1.6105
B11: 46149 | E11: 70 | F11: 95.64 | G11: =E11*F11 -> 6694.8 | K11: =G11+J11 -> 6694.8 | L11: =H11+K11 -> 6694.8 | M11: =M10+K11-L11 -> 79033.75 | N11: HPCL
A12: 8 | B12: 46150 | E12: 120 | F12: 95.64 | G12: =E12*F12 -> 11476.8 | K12: =G12+J12 -> 11476.8 | L12: =H12+K12 -> 11476.8 | M12: =M11+K12-L12 -> 79033.75
A13: 9 | B13: 46151 | G13: =E13*F13 -> 0 | K13: =G13+J13 -> 0 | M13: =M12+K13-L13 -> 79033.75 | Q13: 54.98
A14: 10 | B14: 46152 | G14: =E14*F14 -> 0 | K14: =G14+J14 -> 0 | M14: =M13+K14-L14 -> 79033.75 | Q14: 54.98
A15: 11 | B15: 46153 | E15: 110 | F15: 95.64 | G15: =E15*F15 -> 10520.4 | K15: =G15+J15 -> 10520.4 | L15: =H15+K15 -> 10520.4 | M15: =M14+K15-L15 -> 79033.75
A16: 12 | B16: 46154 | G16: =E16*F16 -> 0 | K16: =G16+J16 -> 0 | L16: =H16+K16 -> 0 | M16: =M15+K16-L16 -> 79033.75 | R16: 19166
A17: 13 | B17: 46155 | G17: =E17*F17 -> 0 | K17: =G17+J17 -> 0 | L17: =H17+K17 -> 0 | M17: =M16+K17-L17 -> 79033.75 | R17: 19645
A18: 14 | B18: 46156 | E18: 109.96 | F18: 95.64 | G18: =E18*F18 -> 10516.574 | K18: =G18+J18 -> 10516.574 | L18: =H18+K18 -> 10516.574 | M18: =M17+K18-L18 -> 79033.75 | P18: 1905988 | Q18: =P18-M18 -> 1826954.2 | R18: 21083
A19: 15 | B19: 46157 | G19: =E19*F19 -> 0 | K19: =G19+J19 -> 0 | L19: =H19+K19 -> 0 | M19: =M18+K19-L19 -> 79033.75 | R19: 19140 | S19: 220637
A20: 16 | B20: 46158 | K20: =G20+J20 -> 0 | L20: =H20+K20 -> 0 | M20: =M19+K20-L20 -> 79033.75 | N20: HPCL | R20: =SUM(R16:R19) -> 79034 | S20: =S19+R20 -> 299671
A21: 17 | B21: 46159 | K21: =G21+J21 -> 0 | L21: =H21+K21 -> 0 | M21: =M20+K21-L21 -> 79033.75 | N21: HPCL
A22: 18 | B22: 46160 | E22: 70 | F22: 98.9 | G22: =E22*F22 -> 6923 | K22: =G22+J22 -> 6923 | L22: =H22+K22 -> 6923 | M22: =M21+K22-L22 -> 79033.75 | N22: Credit Card
A23: 19 | B23: 46161 | E23: 70 | F23: 99.89 | G23: =E23*F23 -> 6992.3 | K23: =G23+J23 -> 6992.3 | L23: =H23+K23 -> 6992.3 | M23: =M22+K23-L23 -> 79033.75
A24: 20 | B24: 46162 | E24: 70 | F24: 99.89 | G24: =E24*F24 -> 6992.3 | K24: =G24+J24 -> 6992.3 | L24: =H24+K24 -> 6992.3 | M24: =M23+K24-L24 -> 79033.75
A25: 21 | B25: 46163 | E25: 95 | F25: 99.89 | G25: =E25*F25 -> 9489.55 | K25: =G25+J25 -> 9489.55 | L25: =H25+K25 -> 9489.55 | M25: =M24+K25-L25 -> 79033.75
A26: 22 | B26: 46164 | E26: 70 | F26: 99.89 | G26: =E26*F26 -> 6992.3 | K26: =G26+J26 -> 6992.3 | L26: =H26+K26 -> 6992.3 | M26: =M25+K26-L26 -> 79033.75
A27: 23 | B27: 46165 | E27: 70 | F27: 99.89 | G27: =E27*F27 -> 6992.3 | K27: =G27+J27 -> 6992.3 | L27: =H27+K27 -> 6992.3 | M27: =M26+K27-L27 -> 79033.75
A28: 24 | B28: 46166 | G28: =E28*F28 -> 0 | K28: =G28+J28 -> 0 | L28: =H28+K28 -> 0 | M28: =M27+K28-L28 -> 79033.75
A29: 25 | B29: 46167 | E29: 70 | F29: 103.76 | G29: =E29*F29 -> 7263.2 | K29: =G29+J29 -> 7263.2 | L29: =H29+K29 -> 7263.2 | M29: =M28+K29-L29 -> 79033.75
A30: 26 | B30: 46168 | E30: 110 | F30: 103.76 | G30: =E30*F30 -> 11413.6 | K30: =G30+J30 -> 11413.6 | L30: =H30+K30 -> 11413.6 | M30: =M29+K30-L30 -> 79033.75
A31: 27 | B31: 46169 | G31: =E31*F31 -> 0 | K31: =G31+J31 -> 0 | L31: =H31+K31 -> 0 | M31: =M30+K31-L31 -> 79033.75
A32: 28 | B32: 46170 | G32: =E32*F32 -> 0 | K32: =G32+J32 -> 0 | L32: =H32+K32 -> 0 | M32: =M31+K32-L32 -> 79033.75
A33: 29 | B33: 46171 | E33: 35 | F33: 103.76 | G33: =E33*F33 -> 3631.6 | K33: =G33+J33 -> 3631.6 | L33: =H33+K33 -> 3631.6 | M33: =M32+K33-L33 -> 79033.75
B34: 46171 | E34: 200 | F34: 103.82 | G34: =E34*F34 -> 20764 | K34: =G34+J34 -> 20764 | M34: =M33+K34-L34 -> 99797.75
A35: 30 | B35: 46172 | K35: =G35+J35 -> 0 | M35: =M34+K35-L35 -> 99797.75
A36: 31 | B36: 46173 | M36: =M35+K36-L36 -> 99797.75
A37: 32 | B37: 46174
A38: 33 | B38: 46175
A39: 34 | B39: 46176
A40: 35
...

Sheet Khammam-1
A1: Divya laxmi ganapathi
A2: S.No | B2: Date | C2: GRN No | D2: Ind No/Bill No | E2: Diesel (Lts) | F2: Price | G2: Amount | H2: Petrol (Lts) | I2: Price | J2: Amount | K2: Total amount | L2: Amount paid | M2: As 0n Date | N2: Remarks
A3: Opening Balance | K3: 1769630.7 | M3: 1769630.7
A4: 1 | B4: 46143 | G4: =E4*F4 -> 0 | K4: =G4+J4 -> 0 | L4: 0 | M4: =M3+K4-L4 -> 1769630.7
A5: 2 | B5: 46144 | E5: 2700 | F5: 95.68 | G5: =E5*F5 -> 258336 | K5: =G5+J5 -> 258336 | L5: =H5+K5 -> 258336 | M5: =M4+K5-L5 -> 1769630.7
A6: 3 | B6: 46145 | E6: 2000 | F6: 95.68 | G6: =E6*F6 -> 191360 | J6: =H6*I6 -> 0 | K6: =G6+J6 -> 191360 | L6: =H6+K6 -> 191360 | M6: =M5+K6-L6 -> 1769630.7
A7: 4 | B7: 46146 | E7: 1500 | F7: 95.68 | G7: =E7*F7 -> 143520 | J7: =H7*I7 -> 0 | K7: =G7+J7 -> 143520 | L7: =H7+K7 -> 143520 | M7: =M6+K7-L7 -> 1769630.7
A8: 5 | B8: 46147 | E8: 2700 | F8: 95.68 | G8: =E8*F8 -> 258336 | J8: =H8*I8 -> 0 | K8: =G8+J8 -> 258336 | L8: =H8+K8 -> 258336 | M8: =M7+K8-L8 -> 1769630.7
A9: 6 | B9: 46148 | E9: 1400 | F9: 95.68 | G9: =E9*F9 -> 133952 | J9: =H9*I9 -> 0 | K9: =G9+J9 -> 133952 | L9: =H9+K9 -> 133952 | M9: =M8+K9-L9 -> 1769630.7
A10: 7 | B10: 46149 | G10: =E10*F10 -> 0 | J10: =H10*I10 -> 0 | K10: =G10+J10 -> 0 | L10: 0 | M10: =M9+K10-L10 -> 1769630.7
A11: 8 | B11: 46150 | E11: 2800 | F11: 95.68 | G11: =E11*F11 -> 267904 | J11: =H11*I11 -> 0 | K11: =G11+J11 -> 267904 | L11: 267904 | M11: =M10+K11-L11 -> 1769630.7
A12: 9 | B12: 46151 | G12: =E12*F12 -> 0 | J12: =H12*I12 -> 0 | K12: =G12+J12 -> 0 | L12: 0 | M12: =M11+K12-L12 -> 1769630.7
A13: 10 | B13: 46152 | E13: 2500 | F13: 95.68 | G13: =E13*F13 -> 239200 | J13: =H13*I13 -> 0 | K13: =G13+J13 -> 239200 | L13: =H13+K13 -> 239200 | M13: =M12+K13-L13 -> 1769630.7
A14: 11 | B14: 46153 | G14: =E14*F14 -> 0 | J14: =H14*I14 -> 0 | K14: =G14+J14 -> 0 | L14: 0 | M14: =M13+K14-L14 -> 1769630.7
A15: 12 | B15: 46154 | G15: =E15*F15 -> 0 | J15: =H15*I15 -> 0 | K15: =G15+J15 -> 0 | L15: 0 | M15: =M14+K15-L15 -> 1769630.7
A16: 13 | B16: 46155 | E16: 4875.88 | F16: 95.68 | G16: =E16*F16 -> 466524.2 | J16: =H16*I16 -> 0 | K16: =G16+J16 -> 466524.2 | L16: 466524 | M16: =M15+K16-L16 -> 1769630.9
A17: 14 | B17: 46156 | G17: =E17*F17 -> 0 | J17: =H17*I17 -> 0 | K17: =G17+J17 -> 0 | L17: 0 | M17: =M16+K17-L17 -> 1769630.9
A18: 15 | B18: 46157 | E18: 2728.93 | F18: 98.94 | G18: =E18*F18 -> 270000.33 | K18: =G18+J18 -> 270000.33 | L18: 270000 | M18: =M17+K18-L18 -> 1769631.2
A19: 16 | B19: 46158 | E19: 2800 | F19: 98.94 | G19: =E19*F19 -> 277032 | K19: =G19+J19 -> 277032 | L19: 0 | M19: =M18+K19-L19 -> 2046663.2
A20: 17 | B20: 46159 | E20: 2080.53 | F20: 98.94 | G20: =E20*F20 -> 205847.64 | K20: =G20+J20 -> 205847.64 | L20: 285000 | M20: =M19+K20-L20 -> 1967510.9
A21: 18 | B21: 46160 | E21: 2800 | F21: 98.94 | G21: =E21*F21 -> 277032 | K21: =G21+J21 -> 277032 | L21: 197880 | M21: =M20+K21-L21 -> 2046662.9
A22: 19 | B22: 46161 | G22: =E22*F22 -> 0 | K22: =G22+J22 -> 0 | L22: 0 | M22: =M21+K22-L22 -> 2046662.9
A23: 20 | B23: 46162 | E23: 2800 | F23: 99.93 | G23: =E23*F23 -> 279804 | K23: =G23+J23 -> 279804 | L23: 200000 | M23: =M22+K23-L23 -> 2126466.9
A24: 21 | B24: 46163 | E24: 2000 | F24: 99.93 | G24: =E24*F24 -> 199860 | K24: =G24+J24 -> 199860 | L24: 250000 | M24: =M23+K24-L24 -> 2076326.9
A25: 22 | B25: 46164 | G25: =E25*F25 -> 0 | K25: =G25+J25 -> 0 | L25: 0 | M25: =M24+K25-L25 -> 2076326.9
A26: 23 | B26: 46165 | G26: =E26*F26 -> 0 | K26: =G26+J26 -> 0 | L26: 0 | M26: =M25+K26-L26 -> 2076326.9
A27: 24 | B27: 46166 | E27: 2650 | F27: 100.92 | G27: =E27*F27 -> 267438 | K27: =G27+J27 -> 267438 | M27: =M26+K27-L27 -> 2343764.9 | O27: 250000 | P27: CASH DG Sir
A28: 25 | B28: 46167 | E28: 2000 | F28: 103.8 | G28: =E28*F28 -> 207600 | K28: =G28+J28 -> 207600 | L28: 0 | M28: =M27+K28-L28 -> 2551364.9
A29: 26 | B29: 46168 | E29: 2700 | F29: 103.8 | G29: =E29*F29 -> 280260 | K29: =G29+J29 -> 280260 | L29: 600000 | M29: =M28+K29-L29 -> 2231624.9
A30: 27 | B30: 46169 | G30: =E30*F30 -> 0 | K30: =G30+J30 -> 0 | L30: 0 | M30: =M29+K30-L30 -> 2231624.9
A31: 28 | B31: 46170 | E31: 1000 | F31: 103.8 | G31: =E31*F31 -> 103800 | K31: =G31+J31 -> 103800 | L31: 120000 | M31: =M30+K31-L31 -> 2215424.9
A32: 29 | B32: 46171 | E32: 2000 | F32: 103.8 | G32: =E32*F32 -> 207600 | K32: =G32+J32 -> 207600 | L32: 0 | M32: =M31+K32-L32 -> 2423024.9
A33: 30 | B33: 46172 | G33: =E33*F33 -> 0 | K33: =G33+J33 -> 0 | L33: 0 | M33: =M32+K33-L33 -> 2423024.9
A34: 31 | B34: 46173 | E34: 2230 | F34: 103.8 | G34: =E34*F34 -> 231474 | K34: =G34+J34 -> 231474 | M34: =M33+K34-L34 -> 2654498.9 | O34: 156000 | P34: CASH DG Sir
A35: 32 | G35: =E35*F35 -> 0 | J35: =H35*I35 -> 0 | K35: =G35+J35 -> 0 | L35: 0 | M35: =M34+K35-L35 -> 2654498.9
A36: 33 | G36: =E36*F36 -> 0 | J36: =H36*I36 -> 0 | K36: =G36+J36 -> 0 | L36: 0
A37: 34 | G37: =E37*F37 -> 0 | J37: =H37*I37 -> 0 | K37: =G37+J37 -> 0
E38: =SUM(E3:E37) -> 48265.34 | G38: =SUM(G3:G37) -> 4766880.2 | H38: =SUM(H3:H37) -> 0 | J38: =SUM(J3:J37) -> 0 | K38: =SUM(K4:K37) -> 4766880.2 | L38: =SUM(L3:L37) -> 3882012

Sheet Khammam-2
A1: Jayasai union bunk
A2: S.No | B2: Date | C2: GRN No | D2: Ind No/Bill No | E2: Diesel (Lts) | F2: Price | G2: Amount | H2: Petrol (Lts) | I2: Price | J2: Amount | K2: Total amount | L2: Amount paid | M2: As 0n Date | N2: Remarks
A3: Opening Balance | K3: 3725653 | M3: 3725653
A4: 1 | B4: 46143 | G4: =E4*F4 -> 0 | J4: =H4*I4 -> 0 | K4: =G4+J4 -> 0 | M4: =M3+K4-L4 -> 3725653 | O4: =O3+M4-N4 -> 3725653
A5: 2 | B5: 46144 | G5: =E5*F5 -> 0 | H5: 100 | I5: 107.49 | J5: =H5*I5 -> 10749 | K5: =G5+J5 -> 10749 | M5: =M4+K5-L5 -> 3736402
A6: 3 | B6: 46145 | G6: =E6*F6 -> 0 | J6: =H6*I6 -> 0 | K6: =G6+J6 -> 0 | M6: =M5+K6-L6 -> 3736402
A7: 4 | B7: 46146 | G7: =E7*F7 -> 0 | J7: =H7*I7 -> 0 | K7: =G7+J7 -> 0 | M7: =M6+K7-L7 -> 3736402
A8: 5 | B8: 46147 | G8: =E8*F8 -> 0 | H8: 95 | I8: 107.49 | J8: =H8*I8 -> 10211.55 | K8: =G8+J8 -> 10211.55 | M8: =M7+K8-L8 -> 3746613.5 | O8: 12802499
A9: 6 | B9: 46148 | E9: 2994.21 | F9: 95.71 | G9: =E9*F9 -> 286575.84 | H9: 80 | I9: 107.49 | J9: =H9*I9 -> 8599.2 | K9: =G9+J9 -> 295175.04 | M9: =M8+K9-L9 -> 4041788.5
A10: 7 | B10: 46149 | E10: 1744.02 | F10: 95.71 | G10: =E10*F10 -> 166920.15 | J10: =H10*I10 -> 0 | K10: =G10+J10 -> 166920.15 | M10: =M9+K10-L10 -> 4208708.7
A11: 8 | B11: 46150 | E11: 1742.41 | F11: 95.71 | G11: =E11*F11 -> 166766.06 | H11: 60 | I11: 107.49 | J11: =H11*I11 -> 6449.4 | K11: =G11+J11 -> 173215.46 | M11: =M10+K11-L11 -> 4381924.2
A12: 9 | B12: 46151 | E12: 2760.94 | F12: 95.71 | G12: =E12*F12 -> 264249.57 | J12: =H12*I12 -> 0 | K12: =G12+J12 -> 264249.57 | M12: =M11+K12-L12 -> 4646173.7 | O12: 166834
A13: 10 | B13: 46152 | E13: 747 | F13: 95.71 | G13: =E13*F13 -> 71495.37 | J13: =H13*I13 -> 0 | K13: =G13+J13 -> 71495.37 | M13: =M12+K13-L13 -> 4717669.1 | O13: =K10-O12 -> 86.1542
A14: 11 | B14: 46153 | E14: 2145.86 | F14: 95.71 | G14: =E14*F14 -> 205380.26 | H14: 80 | I14: 107.49 | J14: =H14*I14 -> 8599.2 | K14: =G14+J14 -> 213979.46 | M14: =M13+K14-L14 -> 4931648.6
A15: 12 | B15: 46154 | E15: 2517.61 | F15: 95.71 | G15: =E15*F15 -> 240960.45 | J15: =H15*I15 -> 0 | K15: =G15+J15 -> 240960.45 | M15: =M14+K15-L15 -> 5172609
A16: 13 | B16: 46155 | E16: 3076.46 | F16: 95.71 | G16: =E16*F16 -> 294447.99 | H16: 85 | I16: 107.49 | J16: =H16*I16 -> 9136.65 | K16: =G16+J16 -> 303584.64 | M16: =M15+K16-L16 -> 5476193.6
A17: 14 | B17: 46156 | E17: 1699.85 | F17: 95.71 | G17: =E17*F17 -> 162692.64 | J17: =H17*I17 -> 0 | K17: =G17+J17 -> 162692.64 | M17: =M16+K17-L17 -> 5638886.3
A18: 15 | B18: 46157 | E18: 1878.23 | F18: 98.97 | G18: =E18*F18 -> 185888.42 | H18: 80 | I18: 110.88 | J18: =H18*I18 -> 8870.4 | K18: =G18+J18 -> 194758.82 | M18: =M17+K18-L18 -> 5833645.1
A19: 16 | B19: 46158 | G19: =E19*F19 -> 0 | J19: =H19*I19 -> 0 | K19: =G19+J19 -> 0 | M19: =M18+K19-L19 -> 5833645.1
A20: 17 | B20: 46159 | G20: =E20*F20 -> 0 | J20: =H20*I20 -> 0 | K20: =G20+J20 -> 0 | M20: =M19+K20-L20 -> 5833645.1
A21: 18 | B21: 46160 | E21: 1200 | F21: 98.97 | G21: =E21*F21 -> 118764 | H21: 80 | I21: 110.88 | J21: =H21*I21 -> 8870.4 | K21: =G21+J21 -> 127634.4 | M21: =M20+K21-L21 -> 5961279.5
A22: 19 | B22: 46161 | E22: 1500 | F22: 99.95 | G22: =E22*F22 -> 149925 | J22: =H22*I22 -> 0 | K22: =G22+J22 -> 149925 | M22: =M21+K22-L22 -> 6111204.5
A23: 20 | B23: 46162 | E23: 3001 | F23: 99.95 | G23: =E23*F23 -> 299949.95 | H23: 95 | I23: 111.87 | J23: =H23*I23 -> 10627.65 | K23: =G23+J23 -> 310577.6 | M23: =M22+K23-L23 -> 6421782.1
A24: 21 | B24: 46163 | E24: 1670 | F24: 99.95 | G24: =E24*F24 -> 166916.5 | J24: =H24*I24 -> 0 | K24: =G24+J24 -> 166916.5 | M24: =M23+K24-L24 -> 6588698.6
A25: 22 | B25: 46164 | E25: 2466.77 | F25: 99.95 | G25: =E25*F25 -> 246553.66 | H25: 50 | I25: 111.87 | J25: =H25*I25 -> 5593.5 | K25: =G25+J25 -> 252147.16 | M25: =M24+K25-L25 -> 6840845.8
A26: 23 | B26: 46165 | E26: 2598.69 | F26: 100.94 | G26: =E26*F26 -> 262311.77 | J26: =H26*I26 -> 0 | K26: =G26+J26 -> 262311.77 | M26: =M25+K26-L26 -> 7103157.5
A27: 24 | B27: 46166 | G27: =E27*F27 -> 0 | J27: =H27*I27 -> 0 | K27: =G27+J27 -> 0 | M27: =M26+K27-L27 -> 7103157.5
A28: 25 | B28: 46167 | E28: 3590.27 | F28: 103.82 | G28: =E28*F28 -> 372741.83 | H28: 100 | I28: 115.72 | J28: =H28*I28 -> 11572 | K28: =G28+J28 -> 384313.83 | M28: =M27+K28-L28 -> 7487471.4
A29: 26 | B29: 46168 | E29: 1239.03 | F29: 103.82 | G29: =E29*F29 -> 128636.09 | J29: =H29*I29 -> 0 | K29: =G29+J29 -> 128636.09 | M29: =M28+K29-L29 -> 7616107.5
A30: 27 | B30: 46169 | E30: 2313.22 | F30: 103.82 | G30: =E30*F30 -> 240158.5 | H30: 55 | I30: 115.72 | J30: =H30*I30 -> 6364.6 | K30: =G30+J30 -> 246523.1 | M30: =M29+K30-L30 -> 7862630.6
A31: 28 | B31: 46170 | E31: 2138.07 | F31: 103.82 | G31: =E31*F31 -> 221974.43 | J31: =H31*I31 -> 0 | K31: =G31+J31 -> 221974.43 | M31: =M30+K31-L31 -> 8084605
A32: 29 | B32: 46171 | E32: 1662.76 | F32: 103.82 | G32: =E32*F32 -> 172627.74 | H32: 80 | I32: 115.72 | J32: =H32*I32 -> 9257.6 | K32: =G32+J32 -> 181885.34 | M32: =M31+K32-L32 -> 8266490.3
A33: 30 | B33: 46172 | E33: 1073.79 | F33: 103.82 | G33: =E33*F33 -> 111480.88 | J33: =H33*I33 -> 0 | K33: =G33+J33 -> 111480.88 | M33: =M32+K33-L33 -> 8377971.2
A34: 31 | B34: 46173 | E34: 3295.38 | F34: 103.82 | G34: =E34*F34 -> 342126.35 | J34: =H34*I34 -> 0 | K34: =G34+J34 -> 342126.35 | M34: =M33+K34-L34 -> 8720097.6
E36: =SUM(E4:E34) -> 49055.57 | G36: =SUM(G4:G34) -> 4879543.5 | H36: =SUM(H4:H34) -> 1040 | J36: =SUM(J4:J34) -> 114901.15 | K36: =SUM(K4:K34) -> 4994444.6 | L36: =SUM(L4:L34) -> 0
M39: 4994360
M40: =K36-M39 -> 84.6152

Sheet Khammam-3
A1: JSASFuel Genie India Pvt.Ltd
A2: S.No | B2: Date | C2: GRN No | D2: Ind No/Bill No | E2: Diesel (Lts) | F2: Price | G2: Amount | H2: Petrol (Lts) | I2: Price | J2: Amount | K2: Total amount | L2: Amount paid | M2: As 0n Date | N2: Remarks
A3: Opening Balance | K3: 2572600.3 | M3: 2572600.3
A4: 1 | B4: 46143 | G4: =E4*F4 -> 0 | J4: =H4*I4 -> 0 | K4: =G4+J4 -> 0 | M4: =M3+K4-L4 -> 2572600.3
A5: 2 | B5: 46144 | G5: =E5*F5 -> 0 | J5: =H5*I5 -> 0 | K5: =G5+J5 -> 0 | M5: =M4+K5-L5 -> 2572600.3
A6: 3 | B6: 46145 | G6: =E6*F6 -> 0 | J6: =H6*I6 -> 0 | K6: =G6+J6 -> 0 | M6: =M5+K6-L6 -> 2572600.3
A7: 4 | B7: 46146 | G7: =E7*F7 -> 0 | J7: =H7*I7 -> 0 | K7: =G7+J7 -> 0 | L7: 1000000 | M7: =M6+K7-L7 -> 1572600.3
A8: 5 | B8: 46147 | G8: =E8*F8 -> 0 | J8: =H8*I8 -> 0 | K8: =G8+J8 -> 0 | M8: =M7+K8-L8 -> 1572600.3
A9: 6 | B9: 46148 | G9: =E9*F9 -> 0 | J9: =H9*I9 -> 0 | K9: =G9+J9 -> 0 | M9: =M8+K9-L9 -> 1572600.3
A10: 7 | B10: 46149 | G10: =E10*F10 -> 0 | J10: =H10*I10 -> 0 | K10: =G10+J10 -> 0 | M10: =M9+K10-L10 -> 1572600.3
A11: 8 | B11: 46150 | G11: =E11*F11 -> 0 | J11: =H11*I11 -> 0 | K11: =G11+J11 -> 0 | M11: =M10+K11-L11 -> 1572600.3
A12: 9 | B12: 46151 | G12: =E12*F12 -> 0 | J12: =H12*I12 -> 0 | K12: =G12+J12 -> 0 | M12: =M11+K12-L12 -> 1572600.3
A13: 10 | B13: 46152 | G13: =E13*F13 -> 0 | J13: =H13*I13 -> 0 | K13: =G13+J13 -> 0 | M13: =M12+K13-L13 -> 1572600.3
A14: 11 | B14: 46153 | G14: =E14*F14 -> 0 | J14: =H14*I14 -> 0 | K14: =G14+J14 -> 0 | M14: =M13+K14-L14 -> 1572600.3
A15: 12 | B15: 46154 | G15: =E15*F15 -> 0 | J15: =H15*I15 -> 0 | K15: =G15+J15 -> 0 | M15: =M14+K15-L15 -> 1572600.3
A16: 13 | B16: 46155 | G16: =E16*F16 -> 0 | J16: =H16*I16 -> 0 | K16: =G16+J16 -> 0 | M16: =M15+K16-L16 -> 1572600.3
A17: 14 | B17: 46156 | G17: =E17*F17 -> 0 | J17: =H17*I17 -> 0 | K17: =G17+J17 -> 0 | M17: =M16+K17-L17 -> 1572600.3
A18: 15 | B18: 46157 | G18: =E18*F18 -> 0 | J18: =H18*I18 -> 0 | K18: =G18+J18 -> 0 | M18: =M17+K18-L18 -> 1572600.3
A19: 16 | B19: 46158 | G19: =E19*F19 -> 0 | J19: =H19*I19 -> 0 | K19: =G19+J19 -> 0 | M19: =M18+K19-L19 -> 1572600.3
... A33: 30 | B33: 46172 | G33: =E33*F33 -> 0 | J33: =H33*I33 -> 0 | K33: =G33+J33 -> 0 | M33: =M32+K33-L33 -> 1572600.3
A34: 31 | G34: =E34*F34 -> 0 | J34: =H34*I34 -> 0 | K34: =G34+J34 -> 0 | M34: =M33+K34-L34 -> 1572600.3
E35: =SUM(E4:E34) -> 0 | G35: =SUM(G4:G34) -> 0 | H35: =SUM(H4:H34) -> 0 | J35: =SUM(J4:J34) -> 0 | K35: =SUM(K4:K34) -> 0 | L35: =SUM(L4:L34) -> 1000000

Sheet  Khammam&Cash
A1: Cash &Carry
A2: S.No | B2: Date | D2: Ind No/Bill No | E2: Diesel (Lts) | F2: Price | G2: Amount | H2: Petrol (Lts) | I2: Price | J2: Amount | K2: Total amount | L2: Amount paid | M2: As 0n Date | N2: Remarks
A3: Opening Balance | K3: 0 | M3: 0
A4: 1 | G4: =E4*F4 -> 0 | K4: =G4+J4 -> 0 | L4: 0 | M4: =M3+K4-L4 -> 0
A5: 2 | B5: 02.05.2026 | C5: Stambhadri Fuel Park (HP) | E5: 2800 | F5: 95.68 | G5: =E5*F5 -> 267904 | J5: =H5*I5 -> 0 | K5: =G5+J5 -> 267904 | L5: =H5+K5 -> 267904 | M5: =M4+K5-L5 -> 0
A6: 3 | B6: 04.05.2026 | C6: Sri Sri Sri Filling Station (HP) | E6: 2000 | F6: 95.68 | G6: =E6*F6 -> 191360 | J6: =H6*I6 -> 0 | K6: =G6+J6 -> 191360 | L6: 95680 | M6: =M5+K6-L6 -> 95680
A7: 4 | B7: 05.05.2026 | C7: Sri Sri Sri Filling Station (HP) | G7: =E7*F7 -> 0 | J7: =H7*I7 -> 0 | K7: =G7+J7 -> 0 | L7: 95680 | M7: =M6+K7-L7 -> 0
A8: 5 | B8: 05.05.2026 | C8: Stambhadri Fuel Park (HP) | E8: 2800 | F8: 95.68 | G8: =E8*F8 -> 267904 | J8: =H8*I8 -> 0 | K8: =G8+J8 -> 267904 | L8: =H8+K8 -> 267904 | M8: =M7+K8-L8 -> 0
A9: 6 | B9: 06.05.2026 | C9: Stambhadri Fuel Park (HP) | E9: 2800 | F9: 95.68 | G9: =E9*F9 -> 267904 | J9: =H9*I9 -> 0 | K9: =G9+J9 -> 267904 | L9: =H9+K9 -> 267904 | M9: =M8+K9-L9 -> 0
A10: 7 | B10: 07.05.2026 | C10: Stambhadri Fuel Park (HP) | E10: 2597.199 | F10: 95.68 | G10: =E10*F10 -> 248500 | J10: =H10*I10 -> 0 | K10: =G10+J10 -> 248500 | L10: =H10+K10 -> 248500 | M10: =M9+K10-L10 -> 0
A11: 8 | B11: 09.05.2026 | C11: Stambhadri Fuel Park (HP) | E11: 2800 | F11: 95.68 | G11: =E11*F11 -> 267904 | J11: =H11*I11 -> 0 | K11: =G11+J11 -> 267904 | L11: =H11+K11 -> 267904 | M11: =M10+K11-L11 -> 0
A12: 9 | B12: 12.05.2026 | C12: Stambhadri Fuel Park (HP) | E12: 3020 | F12: 95.68 | G12: =E12*F12 -> 288953.6 | J12: =H12*I12 -> 0 | K12: =G12+J12 -> 288953.6 | L12: =H12+K12 -> 288953.6 | M12: =M11+K12-L12 -> 0
A13: 10 | B13: 46160 | C13: Stambhadri Fuel Park (HP) | E13: 1021.28 | F13: 98.94 | G13: =E13*F13 -> 101045.44 | J13: =H13*I13 -> 0 | K13: =G13+J13 -> 101045.44 | L13: =H13+K13 -> 101045.44 | M13: =M12+K13-L13 -> 0
A14: 11 | B14: 46163 | C14: Sri Sri Sri Filling Station (HPCL) | E14: 500 | F14: 99.93 | G14: =E14*F14 -> 49965 | J14: =H14*I14 -> 0 | K14: =G14+J14 -> 49965 | L14: =H14+K14 -> 49965 | M14: =M13+K14-L14 -> 0
A15: 12 | B15: 46170 | C15: Stambhadri Fuel Park (HPCL) | E15: 1200 | F15: 103.8 | G15: =E15*F15 -> 124560 | J15: =H15*I15 -> 0 | K15: =G15+J15 -> 124560 | L15: =H15+K15 -> 124560 | M15: =M14+K15-L15 -> 0
A16: 13 | B16: 46170 | C16: Sri Sri Sri Filling Station (HPCL) | E16: 700 | F16: 103.8 | G16: =E16*F16 -> 72660 | J16: =H16*I16 -> 0 | K16: =G16+J16 -> 72660 | L16: =H16+K16 -> 72660 | M16: =M15+K16-L16 -> 0
A17: 14 | G17: =E17*F17 -> 0 | J17: =H17*I17 -> 0 | K17: =G17+J17 -> 0 | L17: 0 | M17: =M16+K17-L17 -> 0
A18: 15 | G18: =E18*F18 -> 0 | J18: =H18*I18 -> 0 | K18: =G18+J18 -> 0 | L18: 0 | M18: =M17+K18-L18 -> 0
A19: 16 | G19: =E19*F19 -> 0 | J19: =H19*I19 -> 0 | K19: =G19+J19 -> 0 | L19: 0 | M19: =M18+K19-L19 -> 0
A20: 17 | G20: =E20*F20 -> 0 | J20: =H20*I20 -> 0 | K20: =G20+J20 -> 0 | L20: 0 | M20: =M19+K20-L20 -> 0
A21: 18 | G21: =E21*F21 -> 0 | J21: =H21*I21 -> 0 | K21: =G21+J21 -> 0 | L21: 0 | M21: =M20+K21-L21 -> 0
A22: 19 | G22: =E22*F22 -> 0 | J22: =H22*I22 -> 0 | K22: =G22+J22 -> 0 | L22: 0 | M22: =M21+K22-L22 -> 0
A23: 20 | G23: =E23*F23 -> 0 | J23: =H23*I23 -> 0 | K23: =G23+J23 -> 0 | L23: 0 | M23: =M22+K23-L23 -> 0
A24: 21 | G24: =E24*F24 -> 0 | J24: =H24*I24 -> 0 | K24: =G24+J24 -> 0 | L24: =H24+K24 -> 0 | M24: =M23+K24-L24 -> 0
A25: 22 | G25: =E25*F25 -> 0 | J25: =H25*I25 -> 0 | K25: =G25+J25 -> 0 | L25: =H25+K25 -> 0 | M25: =M24+K25-L25 -> 0
A26: 23 | G26: =E26*F26 -> 0 | J26: =H26*I26 -> 0 | K26: =G26+J26 -> 0 | L26: =H26+K26 -> 0 | M26: =M25+K26-L26 -> 0
A27: 24 | G27: =E27*F27 -> 0 | K27: =G27+J27 -> 0 | L27: =H27+K27 -> 0 | M27: =M26+K27-L27 -> 0
A28: 25 | G28: =E28*F28 -> 0 | J28: =H28*I28 -> 0 | K28: =G28+J28 -> 0 | L28: =H28+K28 -> 0 | M28: =M26+K28-L28 -> 0
A29: 26 | G29: =E29*F29 -> 0 | J29: =H29*I29 -> 0 | K29: =G29+J29 -> 0 | L29: =H29+K29 -> 0 | M29: =M28+K29-L29 -> 0 | O29: 354016 paid to dted 24.04.2026
A30: 27 | G30: =E30*F30 -> 0 | J30: =H30*I30 -> 0 | K30: =G30+J30 -> 0 | L30: =H30+K30 -> 0 | M30: =M29+K30-L30 -> 0
A31: 28 | G31: =E31*F31 -> 0 | J31: =H31*I31 -> 0 | K31: =G31+J31 -> 0 | L31: =H31+K31 -> 0 | M31: =M30+K31-L31 -> 0
A32: 29 | G32: =E32*F32 -> 0 | J32: =H32*I32 -> 0 | K32: =G32+J32 -> 0 | L32: =H32+K32 -> 0 | M32: =M31+K32-L32 -> 0
A33: 30 | G33: =E33*F33 -> 0 | J33: =H33*I33 -> 0 | K33: =G33+J33 -> 0 | L33: =H33+K33 -> 0 | M33: =M32+K33-L33 -> 0
A34: 31 | G34: =E34*F34 -> 0 | J34: =H34*I34 -> 0 | K34: =G34+J34 -> 0 | L34: =H34+K34 -> 0 | M34: =M33+K34-L34 -> 0
A35: 32 | G35: =E35*F35 -> 0 | K35: =G35+J35 -> 0 | L35: =H35+K35 -> 0 | M35: =M34+K35-L35 -> 0
A36: 33 | G36: =E36*F36 -> 0 | J36: =H36*I36 -> 0 | K36: =G36+J36 -> 0 | L36: =H36+K36 -> 0 | M36: =M35+K36-L36 -> 0
A37: 34 | G37: =E37*F37 -> 0 | J37: =H37*I37 -> 0 | K37: =G37+J37 -> 0 | L37: =H37+K37 -> 0 | M37: =M36+K37-L37 -> 0
G38: =E38*F38 -> 0 | K38: =G38+J38 -> 0 | L38: =H38+K38 -> 0 | M38: =M37+K38-L38 -> 0
G39: =E39*F39 -> 0 | K39: =G39+J39 -> 0 | L39: =H39+K39 -> 0 | M39: =M38+K39-L39 -> 0
G40: =E40*F40 -> 0 | K40: =G40+J40 -> 0 | L40: =H40+K40 -> 0 | M40: =M39+K40-L40 -> 0
...

Sheet Jadcherla-3
A1: JSASFuel Genie India Pvt.Ltd
A2: S.No | B2: Date | C2: GRN No | D2: Ind no/Bill No | E2: Diesel (Lts) | F2: Price | G2: Amount | H2: Petrol (Lts) | I2: Price | J2: Amount | K2: Total amount | L2: Amount paid | M2: As on Date | N2: Remarks
A3: Opening Balance | M3: 1313281.7
A4: 1 | B4: 46143 | G4: =E4*F4 -> 0 | J4: =H4*I4 -> 0 | K4: =G4+J4 -> 0 | L4: 0 | M4: =+M3+K4-L4 -> 1313281.7
A5: 2 | B5: 46144 | G5: =E5*F5 -> 0 | J5: =H5*I5 -> 0 | K5: =G5+J5 -> 0 | L5: 0 | M5: =+M4+K5-L5 -> 1313281.7
A6: 3 | B6: 46145 | G6: =E6*F6 -> 0 | J6: =H6*I6 -> 0 | K6: =G6+J6 -> 0 | L6: 0 | M6: =+M5+K6-L6 -> 1313281.7 | O6: 8032614 | P6: 2453209.4 | Q6: =SUM(O6:P6) -> 10485823
A7: 4 | B7: 46146 | G7: =E7*F7 -> 0 | J7: =H7*I7 -> 0 | K7: =G7+J7 -> 0 | L7: 0 | M7: =+M6+K7-L7 -> 1313281.7
A8: 5 | B8: 46147 | G8: =E8*F8 -> 0 | J8: =H8*I8 -> 0 | K8: =G8+J8 -> 0 | L8: 0 | M8: =+M7+K8-L8 -> 1313281.7
A9: 6 | B9: 46148 | G9: =E9*F9 -> 0 | J9: =H9*I9 -> 0 | K9: =G9+J9 -> 0 | L9: 0 | M9: =+M8+K9-L9 -> 1313281.7
A10: 7 | B10: 46149 | G10: =E10*F10 -> 0 | J10: =H10*I10 -> 0 | K10: =G10+J10 -> 0 | L10: 0 | M10: =+M9+K10-L10 -> 1313281.7 | R10: 700
A11: 8 | B11: 46150 | G11: =E11*F11 -> 0 | J11: =H11*I11 -> 0 | K11: =G11+J11 -> 0 | L11: 0 | M11: =+M10+K11-L11 -> 1313281.7 | S11: 5000
A12: 9 | B12: 46151 | G12: =E12*F12 -> 0 | J12: =H12*I12 -> 0 | K12: =G12+J12 -> 0 | L12: 0 | M12: =+M11+K12-L12 -> 1313281.7 | S12: 1500
A13: 10 | B13: 46152 | G13: =E13*F13 -> 0 | J13: =H13*I13 -> 0 | K13: =G13+J13 -> 0 | L13: 0 | M13: =+M12+K13-L13 -> 1313281.7 | S13: 500
A14: 11 | B14: 46153 | G14: =E14*F14 -> 0 | J14: =H14*I14 -> 0 | K14: =G14+J14 -> 0 | L14: 0 | M14: =+M13+K14-L14 -> 1313281.7
A15: 12 | B15: 46154 | G15: =E15*F15 -> 0 | J15: =H15*I15 -> 0 | K15: =G15+J15 -> 0 | L15: 0 | M15: =+M14+K15-L15 -> 1313281.7
A16: 13 | B16: 46155 | G16: =E16*F16 -> 0 | J16: =H16*I16 -> 0 | K16: =G16+J16 -> 0 | L16: 0 | M16: =+M15+K16-L16 -> 1313281.7
A17: 14 | B17: 46156 | G17: =E17*F17 -> 0 | J17: =H17*I17 -> 0 | K17: =G17+J17 -> 0 | L17: 0 | M17: =+M16+K17-L17 -> 1313281.7
A18: 15 | B18: 46157 | G18: =E18*F18 -> 0 | J18: =H18*I18 -> 0 | K18: =G18+J18 -> 0 | L18: 0 | M18: =+M17+K18-L18 -> 1313281.7
A19: 16 | B19: 46158 | G19: =E19*F19 -> 0 | J19: =H19*I19 -> 0 | K19: =G19+J19 -> 0 | L19: 0 | M19: =+M18+K19-L19 -> 1313281.7
A20: 17 | B20: 46159 | G20: =E20*F20 -> 0 | J20: =H20*I20 -> 0 | K20: =G20+J20 -> 0 | L20: 0 | M20: =+M19+K20-L20 -> 1313281.7
A21: 18 | B21: 46160 | G21: =E21*F21 -> 0 | J21: =H21*I21 -> 0 | K21: =G21+J21 -> 0 | L21: 0 | M21: =+M20+K21-L21 -> 1313281.7
A22: 19 | B22: 46161 | G22: =E22*F22 -> 0 | J22: =H22*I22 -> 0 | K22: =G22+J22 -> 0 | L22: 0 | M22: =+M21+K22-L22 -> 1313281.7
A23: 20 | B23: 46162 | G23: =E23*F23 -> 0 | J23: =H23*I23 -> 0 | K23: =G23+J23 -> 0 | L23: 0 | M23: =+M22+K23-L23 -> 1313281.7
A24: 21 | B24: 46163 | G24: =E24*F24 -> 0 | J24: =H24*I24 -> 0 | K24: =G24+J24 -> 0 | L24: 0 | M24: =+M23+K24-L24 -> 1313281.7
A25: 22 | B25: 46164 | G25: =E25*F25 -> 0 | J25: =H25*I25 -> 0 | K25: =G25+J25 -> 0 | L25: 0 | M25: =+M24+K25-L25 -> 1313281.7
... A31: 28 | B31: 46170 | G31: =E31*F31 -> 0 | J31: =H31*I31 -> 0 | K31: =G31+J31 -> 0 | L31: 0 | M31: =+M30+K31-L31 -> 1313281.7
A32: 29 | B32: 46171 | G32: =E32*F32 -> 0 | J32: =H32*I32 -> 0 | K32: =G32+J32 -> 0 | M32: =+M31+K32-L32 -> 1313281.7
A33: 30 | B33: 46172 | G33: =E33*F33 -> 0 | J33: =H33*I33 -> 0 | K33: =G33+J33 -> 0 | M33: =+M32+K33-L33 -> 1313281.7
A34: 31 | G34: =E34*F34 -> 0 | H34: 0 | I34: 0 | J34: =H34*I34 -> 0 | K34: =G34+J34 -> 0 | L34: 0 | M34: =+M33+K34-L34 -> 1313281.7
E35: =SUM(E4:E34) -> 0 | G35: =SUM(G4:G34) -> 0 | H35: =SUM(H4:H34) -> 0 | J35: =SUM(J4:J34) -> 0 | K35: =SUM(K4:K34) -> 0 | L35: =SUM(L4:L34) -> 0
F38: /

Sheet Jadcherla-4
A1: Shree Poornima F/S
A2: S.No | B2: Date | C2: GRN No | D2: Ind No/Bill No | E2: Diesel (Lts) | F2: Price | G2: Amount | H2: Petrol (Lts) | I2: Price | J2: Amount | K2: Total amount | L2: Amount paid | M2: As on date | N2: Remarks
A3: Opening Balance | M3: 3523.2
A4: 1 | B4: 46143 | G4: =E4*F4 -> 0 | J4: =H4*I4 -> 0 | K4: =G4+J4 -> 0 | L4: 0 | M4: =M3+K4-L4 -> 3523.2
A5: 2 | B5: 46144 | G5: =E5*F5 -> 0 | H5: 40 | I5: 108.1 | J5: =H5*I5 -> 4324 | K5: =G5+J5 -> 4324 | L5: 0 | M5: =M4+K5-L5 -> 7847.2
A6: 3 | B6: 46145 | G6: =E6*F6 -> 0 | J6: =H6*I6 -> 0 | K6: =G6+J6 -> 0 | L6: 0 | M6: =M5+K6-L6 -> 7847.2
A7: 4 | B7: 46146 | G7: =E7*F7 -> 0 | J7: =H7*I7 -> 0 | K7: =G7+J7 -> 0 | L7: 0 | M7: =M6+K7-L7 -> 7847.2
A8: 5 | B8: 46147 | G8: =E8*F8 -> 0 | J8: =H8*I8 -> 0 | K8: =G8+J8 -> 0 | L8: 0 | M8: =M7+K8-L8 -> 7847.2
A9: 6 | B9: 46148 | G9: =E9*F9 -> 0 | J9: =H9*I9 -> 0 | K9: =G9+J9 -> 0 | L9: 0 | M9: =M8+K9-L9 -> 7847.2
A10: 7 | B10: 46149 | G10: =E10*F10 -> 0 | J10: =H10*I10 -> 0 | K10: =G10+J10 -> 0 | L10: 0 | M10: =M9+K10-L10 -> 7847.2
A11: 8 | B11: 46150 | G11: =E11*F11 -> 0 | J11: =H11*I11 -> 0 | K11: =G11+J11 -> 0 | L11: 0 | M11: =M10+K11-L11 -> 7847.2
A12: 9 | B12: 46151 | G12: =E12*F12 -> 0 | J12: =H12*I12 -> 0 | K12: =G12+J12 -> 0 | L12: 0 | M12: =M11+K12-L12 -> 7847.2
A13: 10 | B13: 46152 | G13: =E13*F13 -> 0 | J13: =H13*I13 -> 0 | K13: =G13+J13 -> 0 | L13: 0 | M13: =M12+K13-L13 -> 7847.2
A14: 11 | B14: 46153 | G14: =E14*F14 -> 0 | J14: =H14*I14 -> 0 | K14: =G14+J14 -> 0 | L14: 0 | M14: =M13+K14-L14 -> 7847.2
A15: 12 | B15: 46154 | E15: 500 | F15: 96.3 | G15: =E15*F15 -> 48150 | H15: 36 | I15: 108.1 | J15: =H15*I15 -> 3891.6 | K15: =G15+J15 -> 52041.6 | L15: 48150 | M15: =M14+K15-L15 -> 11738.8
A16: 13 | B16: 46155 | E16: 500 | F16: 96.3 | G16: =E16*F16 -> 48150 | J16: =H16*I16 -> 0 | K16: =G16+J16 -> 48150 | L16: 48150 | M16: =M15+K16-L16 -> 11738.8
A17: 14 | B17: 46156 | G17: =E17*F17 -> 0 | J17: =H17*I17 -> 0 | K17: =G17+J17 -> 0 | L17: 0 | M17: =M16+K17-L17 -> 11738.8
A18: 15 | B18: 46157 | G18: =E18*F18 -> 0 | J18: =H18*I18 -> 0 | K18: =G18+J18 -> 0 | L18: 0 | M18: =M17+K18-L18 -> 11738.8
A19: 16 | B19: 46158 | E19: 0 | F19: 0 | G19: 0 | H19: 0 | I19: 0 | J19: 0 | K19: 0 | L19: 0 | M19: =M18+K19-L19 -> 11738.8
A20: 17 | B20: 46159 | G20: =E20*F20 -> 0 | J20: =H20*I20 -> 0 | K20: =G20+J20 -> 0 | L20: 0 | M20: =M19+K20-L20 -> 11738.8
A21: 18 | B21: 46160 | G21: =E21*F21 -> 0 | J21: =H21*I21 -> 0 | K21: =G21+J21 -> 0 | L21: 0 | M21: =M20+K21-L21 -> 11738.8
A22: 19 | B22: 46161 | G22: =E22*F22 -> 0 | J22: =H22*I22 -> 0 | K22: =G22+J22 -> 0 | L22: 0 | M22: =M21+K22-L22 -> 11738.8
A23: 20 | B23: 46162 | G23: =E23*F23 -> 0 | J23: =H23*I23 -> 0 | K23: =G23+J23 -> 0 | L23: 0 | M23: =M22+K23-L23 -> 11738.8
A24: 21 | B24: 46163 | E24: 0 | F24: 100.67 | G24: =E24*F24 -> 0 | H24: 36 | I24: 112.48 | J24: =H24*I24 -> 4049.28 | K24: =G24+J24 -> 4049.28 | L24: 0 | M24: =M23+K24-L24 -> 15788.08
A25: 22 | B25: 46164 | E25: 0 | F25: 0 | G25: =E25*F25 -> 0 | J25: =H25*I25 -> 0 | K25: =G25+J25 -> 0 | L25: 0 | M25: =M24+K25-L25 -> 15788.08
A26: 23 | B26: 46165 | E26: 0 | F26: 0 | G26: =E26*F26 -> 0 | J26: =H26*I26 -> 0 | K26: =G26+J26 -> 0 | L26: 0 | M26: =M25+K26-L26 -> 15788.08
A27: 24 | B27: 46166 | E27: 0 | F27: 0 | G27: =E27*F27 -> 0 | J27: =H27*I27 -> 0 | K27: =G27+J27 -> 0 | L27: 0 | M27: =M26+K27-L27 -> 15788.08
A28: 25 | B28: 46167 | E28: 0 | F28: 0 | G28: =E28*F28 -> 0 | J28: =H28*I28 -> 0 | K28: =G28+J28 -> 0 | L28: 0 | M28: =M27+K28-L28 -> 15788.08
A29: 26 | B29: 46168 | G29: =E29*F29 -> 0 | J29: =H29*I29 -> 0 | K29: =G29+J29 -> 0 | L29: 0 | M29: =M28+K29-L29 -> 15788.08
A30: 27 | B30: 46169 | G30: =E30*F30 -> 0 | J30: =H30*I30 -> 0 | K30: =G30+J30 -> 0 | L30: 0 | M30: =M29+K30-L30 -> 15788.08
A31: 28 | B31: 46170 | G31: =E31*F31 -> 0 | J31: =H31*I31 -> 0 | K31: =G31+J31 -> 0 | L31: 0 | M31: =M30+K31-L31 -> 15788.08
A32: 29 | B32: 46171 | G32: =E32*F32 -> 0 | J32: =H32*I32 -> 0 | K32: =G32+J32 -> 0 | L32: 0 | M32: =M31+K32-L32 -> 15788.08
A33: 30 | B33: 46172 | G33: =E33*F33 -> 0 | H33: 0 | I33: 0 | J33: =H33*I33 -> 0 | K33: =G33+J33 -> 0 | L33: 0 | M33: =M32+K33-L33 -> 15788.08
A34: 31 | B34: 46173 | G34: =E34*F34 -> 0 | J34: =H34*I34 -> 0 | K34: =G34+J34 -> 0 | M34: =M33+K34-L34 -> 15788.08
E35: =SUM(E4:E34) -> 1000 | G35: =SUM(G4:G34) -> 96300 | H35: =SUM(H4:H34) -> 112 | J35: =SUM(J4:J34) -> 12264.88 | K35: =SUM(K4:K34) -> 108564.88 | L35: =SUM(L4:L34) -> 96300

Sheet  Jadcherla
A1: Sai baba F/S
A2: S.No | B2: Date | C2: GRN No | D2: Ind No/Bill No | E2: Diesel (Lts) | F2: Price | G2: Amount | H2: Petrol (Lts) | I2: Price | J2: Amount | K2: Total amount | L2: Amount paid | M2: As on date | N2: Remarks
A3: Opening Balance | M3: 44630
A4: 1 | B4: 46143 | G4: =E4*F4 -> 0 | J4: =H4*I4 -> 0 | K4: =G4+J4 -> 0 | L4: 0 | M4: =M3+K4-L4 -> 44630
A5: 2 | B5: 46144 | G5: =E5*F5 -> 0 | J5: =H5*I5 -> 0 | K5: =G5+J5 -> 0 | L5: 0 | M5: =M4+K5-L5 -> 44630
A6: 3 | B6: 46145 | G6: =E6*F6 -> 0 | J6: =H6*I6 -> 0 | K6: =G6+J6 -> 0 | L6: 0 | M6: =M5+K6-L6 -> 44630
A7: 4 | B7: 46146 | E7: 1500 | F7: 96.42 | G7: =E7*F7 -> 144630 | J7: =H7*I7 -> 0 | K7: =G7+J7 -> 144630 | L7: =H7+K7 -> 144630 | M7: =M6+K7-L7 -> 44630
A8: 5 | B8: 46147 | G8: =E8*F8 -> 0 | J8: =H8*I8 -> 0 | K8: =G8+J8 -> 0 | L8: 0 | M8: =M7+K8-L8 -> 44630
A9: 6 | B9: 46148 | E9: 1037.12 | F9: 96.42 | G9: =E9*F9 -> 99999.11 | J9: =H9*I9 -> 0 | K9: =G9+J9 -> 99999.11 | L9: 100000 | M9: =M8+K9-L9 -> 44629.11
A10: 7 | B10: 46149 | G10: =E10*F10 -> 0 | J10: =H10*I10 -> 0 | K10: =G10+J10 -> 0 | L10: 0 | M10: =M9+K10-L10 -> 44629.11
A11: 8 | B11: 46150 | E11: 1000 | F11: 96.42 | G11: =E11*F11 -> 96420 | J11: =H11*I11 -> 0 | K11: =G11+J11 -> 96420 | L11: 0 | M11: =M10+K11-L11 -> 141049.11
A12: 9 | B12: 46151 | G12: =E12*F12 -> 0 | J12: =H12*I12 -> 0 | K12: =G12+J12 -> 0 | L12: 0 | M12: =M11+K12-L12 -> 141049.11
A13: 10 | B13: 46152 | G13: =E13*F13 -> 0 | J13: =H13*I13 -> 0 | K13: =G13+J13 -> 0 | L13: 0 | M13: =M12+K13-L13 -> 141049.11
A14: 11 | B14: 46153 | G14: =E14*F14 -> 0 | J14: =H14*I14 -> 0 | K14: =G14+J14 -> 0 | L14: 0 | M14: =M13+K14-L14 -> 141049.11
A15: 12 | B15: 46154 | G15: =E15*F15 -> 0 | J15: =H15*I15 -> 0 | K15: =G15+J15 -> 0 | L15: =H15+K15 -> 0 | M15: =M14+K15-L15 -> 141049.11
A16: 13 | B16: 46155 | G16: =E16*F16 -> 0 | J16: =H16*I16 -> 0 | K16: =G16+J16 -> 0 | L16: 141049 | M16: =M15+K16-L16 -> 0.1104
A17: 14 | B17: 46156 | E17: 500 | F17: 96.42 | G17: =E17*F17 -> 48210 | J17: =H17*I17 -> 0 | K17: =G17+J17 -> 48210 | L17: 0 | M17: =M16+K17-L17 -> 48210.11
A18: 15 | B18: 46157 | E18: 1000 | F18: 99.68 | G18: =E18*F18 -> 99680 | J18: =H18*I18 -> 0 | K18: =G18+J18 -> 99680 | L18: 48210 | M18: =M17+K18-L18 -> 99680.11 | N18: BT
A19: 16 | B19: 46158 | G19: =E19*F19 -> 0 | J19: =H19*I19 -> 0 | K19: =G19+J19 -> 0 | L19: 0 | M19: =M18+K19-L19 -> 99680.11
A20: 17 | B20: 46159 | G20: =E20*F20 -> 0 | J20: =H20*I20 -> 0 | K20: =G20+J20 -> 0 | L20: 0 | M20: =M19+K20-L20 -> 99680.11
A21: 18 | B21: 46160 | E21: 1500 | F21: 99.68 | G21: =E21*F21 -> 149520 | J21: =H21*I21 -> 0 | K21: =G21+J21 -> 149520 | L21: 100000 | M21: =M20+K21-L21 -> 149200.11 | N21: BT
A22: 19 | B22: 46161 | G22: =E22*F22 -> 0 | J22: =H22*I22 -> 0 | K22: =G22+J22 -> 0 | L22: 0 | M22: =M21+K22-L22 -> 149200.11
A23: 20 | B23: 46162 | G23: =E23*F23 -> 0 | J23: =H23*I23 -> 0 | K23: =G23+J23 -> 0 | L23: 0 | M23: =M22+K23-L23 -> 149200.11
A24: 21 | B24: 46163 | E24: 500 | F24: 100.67 | G24: =E24*F24 -> 50335 | J24: =H24*I24 -> 0 | K24: =G24+J24 -> 50335 | L24: 149000 | M24: =M23+K24-L24 -> 50535.11
A25: 22 | B25: 46164 | E25: 1000 | F25: 100.67 | G25: =E25*F25 -> 100670 | J25: =H25*I25 -> 0 | K25: =G25+J25 -> 100670 | L25: 0 | M25: =M24+K25-L25 -> 151205.11
A26: 23 | B26: 46165 | E26: 500 | F26: 101.66 | G26: =E26*F26 -> 50830 | J26: =H26*I26 -> 0 | K26: =G26+J26 -> 50830 | M26: =M25+K26-L26 -> 202035.11
A27: 24 | B27: 46166 | G27: =E27*F27 -> 0 | J27: =H27*I27 -> 0 | K27: =G27+J27 -> 0 | L27: 0 | M27: =M26+K27-L27 -> 202035.11
A28: 25 | B28: 46167 | E28: 1000 | F28: 104.54 | G28: =E28*F28 -> 104540 | J28: =H28*I28 -> 0 | K28: =G28+J28 -> 104540 | L28: 200000 | M28: =M27+K28-L28 -> 106575.11
A29: 26 | B29: 46168 | E29: 500 | F29: 104.54 | G29: =E29*F29 -> 52270 | J29: =H29*I29 -> 0 | K29: =G29+J29 -> 52270 | L29: 0 | M29: =M28+K29-L29 -> 158845.11
A30: 27 | B30: 46169 | G30: =E30*F30 -> 0 | J30: =H30*I30 -> 0 | K30: =G30+J30 -> 0 | L30: 40000 | M30: =M29+K30-L30 -> 118845.11
A31: 28 | B31: 46170 | E31: 500 | F31: 104.54 | G31: =E31*F31 -> 52270 | J31: =H31*I31 -> 0 | K31: =G31+J31 -> 52270 | L31: 0 | M31: =M30+K31-L31 -> 171115.11
A32: 29 | B32: 46171 | G32: =E32*F32 -> 0 | J32: =H32*I32 -> 0 | K32: =G32+J32 -> 0 | L32: 0 | M32: =M31+K32-L32 -> 171115.11
A33: 30 | B33: 46172 | G33: =E33*F33 -> 0 | H33: 0 | I33: 0 | J33: =H33*I33 -> 0 | K33: =G33+J33 -> 0 | L33: 0 | M33: =M32+K33-L33 -> 171115.11
A34: 31 | B34: 46173 | G34: =E34*F34 -> 0 | J34: =H34*I34 -> 0 | K34: =G34+J34 -> 0 | M34: =M33+K34-L34 -> 171115.11
E35: =SUM(E4:E34) -> 10537.12 | G35: =SUM(G4:G34) -> 1049374.1 | H35: =SUM(H4:H34) -> 0 | J35: =SUM(J4:J34) -> 0 | K35: =SUM(K4:K34) -> 1049374.1 | L35: =SUM(L4:L34) -> 922889

Sheet  Sangareddy-2
A1: Durga Bhavani F/S
A2: S.No | B2: Date | C2: GRN No | D2: Ind no/Bill No | E2: Diesel (Lts) | F2: Price | G2: Amount | H2: Petrol (Lts) | I2: Price | J2: Amount | K2: Total amount | L2: Amount paid | M2: As on Date | N2: Remarks
A3: Opening Balance | M3: 258995.39
A4: 1 | B4: 45778 | G4: =E4*F4 -> 0 | J4: =H4*I4 -> 0 | K4: =G4+J4 -> 0 | M4: =M3+K4-L4 -> 258995.39
A5: 2 | B5: 45779 | F5: 96.44 | G5: =E5*F5 -> 0 | H5: 47.1 | I5: 108.31 | J5: =H5*I5 -> 5101.401 | K5: =G5+J5 -> 5101.401 | M5: =M4+K5-L5 -> 264096.8
A6: 3 | B6: 45780 | G6: =E6*F6 -> 0 | J6: =H6*I6 -> 0 | K6: =G6+J6 -> 0 | M6: =M5+K6-L6 -> 264096.8
A7: 4 | B7: 45781 | G7: =E7*F7 -> 0 | J7: =H7*I7 -> 0 | K7: =G7+J7 -> 0 | L7: 250000 | M7: =M6+K7-L7 -> 14096.795
A8: 5 | B8: 45782 | G8: =E8*F8 -> 0 | H8: 5 | I8: 108.31 | J8: =H8*I8 -> 541.55 | K8: =G8+J8 -> 541.55 | M8: =M7+K8-L8 -> 14638.345
A9: 6 | B9: 45783 | E9: 810.61 | F9: 96.44 | G9: =E9*F9 -> 78175.228 | H9: 23 | I9: 108.31 | J9: =H9*I9 -> 2491.13 | K9: =G9+J9 -> 80666.358 | M9: =M8+K9-L9 -> 95304.704
A10: 7 | B10: 45784 | E10: 651.32 | F10: 96.44 | G10: =E10*F10 -> 62813.301 | H10: 5 | I10: 108.31 | J10: =H10*I10 -> 541.55 | K10: =G10+J10 -> 63354.851 | M10: =M9+K10-L10 -> 158659.55
A11: 8 | B11: 45785 | E11: 2.26 | F11: 96.44 | G11: =E11*F11 -> 217.9544 | H11: 5 | I11: 108.31 | J11: =H11*I11 -> 541.55 | K11: =G11+J11 -> 759.5044 | M11: =M10+K11-L11 -> 159419.06
A12: 9 | B12: 45786 | G12: =E12*F12 -> 0 | J12: =H12*I12 -> 0 | K12: =G12+J12 -> 0 | M12: =M11+K12-L12 -> 159419.06
A13: 10 | B13: 45787 | G13: =E13*F13 -> 0 | J13: =H13*I13 -> 0 | K13: =G13+J13 -> 0 | M13: =M12+K13-L13 -> 159419.06
A14: 11 | B14: 45788 | G14: =E14*F14 -> 0 | H14: 10 | I14: 108.31 | J14: =H14*I14 -> 1083.1 | K14: =G14+J14 -> 1083.1 | M14: =M13+K14-L14 -> 160502.16
A15: 12 | B15: 45789 | E15: 970.94 | F15: 96.44 | G15: =E15*F15 -> 93637.454 | H15: 15 | I15: 108.31 | J15: =H15*I15 -> 1624.65 | K15: =G15+J15 -> 95262.104 | M15: =M14+K15-L15 -> 255764.26
A16: 13 | B16: 45790 | E16: 908.44 | F16: 96.44 | G16: =E16*F16 -> 87609.954 | H16: 3 | I16: 108.31 | J16: =H16*I16 -> 324.93 | K16: =G16+J16 -> 87934.884 | M16: =M15+K16-L16 -> 343699.15
A17: 14 | B17: 45791 | E17: 646.95 | F17: 96.44 | G17: =E17*F17 -> 62391.858 | H17: 5 | I17: 108.31 | J17: =H17*I17 -> 541.55 | K17: =G17+J17 -> 62933.408 | M17: =M16+K17-L17 -> 406632.55
A18: 15 | B18: 45792 | E18: 163.58 | F18: 99.7 | G18: =E18*F18 -> 16308.926 | H18: 3 | I18: 111.71 | J18: =H18*I18 -> 335.13 | K18: =G18+J18 -> 16644.056 | L18: 300000 | M18: =M17+K18-L18 -> 123276.61
A19: 16 | B19: 45793 | E19: 763.64 | F19: 99.7 | G19: =E19*F19 -> 76134.908 | H19: 54.23 | I19: 111.71 | J19: =H19*I19 -> 6058.0333 | K19: =G19+J19 -> 82192.941 | M19: =M18+K19-L19 -> 205469.55
A20: 17 | B20: 45794 | E20: 447.36 | F20: 99.7 | G20: =E20*F20 -> 44601.792 | H20: 18 | I20: 111.71 | J20: =H20*I20 -> 2010.78 | K20: =G20+J20 -> 46612.572 | M20: =M19+K20-L20 -> 252082.12
A21: 18 | B21: 45795 | G21: =E21*F21 -> 0 | J21: =H21*I21 -> 0 | K21: =G21+J21 -> 0 | M21: =M20+K21-L21 -> 252082.12
A22: 19 | B22: 45796 | G22: =E22*F22 -> 0 | H22: 10 | I22: 112.69 | J22: =H22*I22 -> 1126.9 | K22: =G22+J22 -> 1126.9 | M22: =M21+K22-L22 -> 253209.02
A23: 20 | B23: 45797 | E23: 133.08 | F23: 100.69 | G23: =E23*F23 -> 13399.825 | J23: =H23*I23 -> 0 | K23: =G23+J23 -> 13399.825 | M23: =M22+K23-L23 -> 266608.85
A24: 21 | B24: 45798 | E24: 845.44 | F24: 100.69 | G24: =E24*F24 -> 85127.354 | H24: 5 | I24: 112.69 | J24: =H24*I24 -> 563.45 | K24: =G24+J24 -> 85690.804 | M24: =M23+K24-L24 -> 352299.65
A25: 22 | B25: 45799 | G25: =E25*F25 -> 0 | H25: 43.39 | I25: 112.69 | J25: =H25*I25 -> 4889.6191 | K25: =G25+J25 -> 4889.6191 | M25: =M24+K25-L25 -> 357189.27
A26: 23 | B26: 45800 | G26: =E26*F26 -> 0 | J26: =H26*I26 -> 0 | K26: =G26+J26 -> 0 | M26: =M25+K26-L26 -> 357189.27
A27: 24 | B27: 45801 | G27: =E27*F27 -> 0 | H27: 10 | I27: 112.69 | J27: =H27*I27 -> 1126.9 | K27: =G27+J27 -> 1126.9 | M27: =M26+K27-L27 -> 358316.17
A28: 25 | B28: 45802 | G28: =E28*F28 -> 0 | J28: 0 | K28: =G28+J28 -> 0 | L28: 250000 | M28: =M27+K28-L28 -> 108316.17
A29: 26 | B29: 45803 | G29: =E29*F29 -> 0 | J29: =H29*I29 -> 0 | K29: =G29+J29 -> 0 | M29: =M28+K29-L29 -> 108316.17
A30: 27 | B30: 45804 | G30: =E30*F30 -> 0 | J30: =H30*I30 -> 0 | K30: =G30+J30 -> 0 | M30: =M29+K30-L30 -> 108316.17
A31: 28 | B31: 45805 | G31: =E31*F31 -> 0 | J31: =H31*I31 -> 0 | K31: =G31+J31 -> 0 | M31: =M30+K31-L31 -> 108316.17
A32: 29 | B32: 45806 | G32: =E32*F32 -> 0 | J32: =H32*I32 -> 0 | K32: =G32+J32 -> 0 | M32: =M31+K32-L32 -> 108316.17
A33: 30 | B33: 45807 | G33: =E33*F33 -> 0 | J33: =H33*I33 -> 0 | K33: =G33+J33 -> 0 | L33: 0 | M33: =M32+K33-L33 -> 108316.17
A34: 31 | B34: 45808 | G34: =E34*F34 -> 0 | J34: =H34*I34 -> 0 | K34: =G34+J34 -> 0 | L34: 0 | M34: =M33+K34-L34 -> 108316.17
E35: =SUM(E4:E34) -> 6343.62 | G35: =SUM(G4:G34) -> 620418.55 | H35: =SUM(H4:H34) -> 261.72 | J35: =SUM(J4:J34) -> 28902.223 | K35: =SUM(K4:K34) -> 649320.78 | L35: =SUM(L4:L34) -> 800000

Sheet  Sangareddy-3
A1: SHIVA PARVATHI FILLING STATION SADASHIVPET
A2: S.No | B2: Date | C2: GRN No | D2: Ind no/Bill No | E2: Diesel (Lts) | F2: Price | G2: Amount | H2: Petrol (Lts) | I2: Price | J2: Amount | K2: Total amount | L2: Amount paid | M2: As on Date | N2: Remarks
A3: Opening Balance | M3: 163539.24
A4: 1 | B4: 45778 | E4: 600 | F4: 96.23 | G4: =E4*F4 -> 57738 | J4: =H4*I4 -> 0 | K4: =G4+J4 -> 57738 | L4: 0 | M4: =M3+K4-L4 -> 221277.24
A5: 2 | B5: 45779 | E5: 690 | F5: 96.23 | G5: =E5*F5 -> 66398.7 | J5: =H5*I5 -> 0 | K5: =G5+J5 -> 66398.7 | L5: 0 | M5: =M4+K5-L5 -> 287675.94
A6: 3 | B6: 45780 | E6: 690 | F6: 96.23 | G6: =E6*F6 -> 66398.7 | J6: =H6*I6 -> 0 | K6: =G6+J6 -> 66398.7 | L6: 0 | M6: =M5+K6-L6 -> 354074.64
A7: 4 | B7: 45781 | E7: 690 | F7: 96.23 | G7: =E7*F7 -> 66398.7 | J7: =H7*I7 -> 0 | K7: =G7+J7 -> 66398.7 | L7: 0 | M7: =M6+K7-L7 -> 420473.34
