Workbook

Sheet  MIs
A2: S.No | B2: NAme | C2: Lacation | D2: Card Number | E2: Card Number | F2: Category | G2: 1st Jan | I2: 2nd Jan | J2: 3rd Jan | K2: 4th Jan | L2: 5th Jan | M2: 6th Jan | N2: 7th Jan | O2: 8th Jan | P2: 9th Jan | Q2: 10th Jan | R2: 11th Jan | S2: 12th Jan | T2: 13th Jan | U2: 14th Jan | V2: 15th Jan | W2: 16th Jan | X2: 17th Jan | Y2: 18th Jan | Z2: 19th Jan | AA2: 20th Jan | AB2: 21st Jan | AC2: 22nd Jan | AD2: 23rd Jan | AE2: 24th Jan | AF2: 25th Jan | AG2: 26th Jan | AH2: 27th Jan | AI2: 28th Jan | AJ2: 29th Jan | AK2: 30th Jan | AL2: 31st Jan | AM2: Total
F3: Diesel
A4: 1 | B4: Rambabu | C4: HO(Two Wheeler) | D4: FC3450563999 | E4: Diesel | F4: 0 | G4: 0 | H4: 0 | I4: 0 | J4: 0 | K4: 0 | L4: 0 | M4: 0 | N4: 0 | O4: 0 | P4: 0 | Q4: 0 | R4: 0 | S4: 0 | T4: 0 | U4: 0 | V4: 0 | W4: 0 | X4: 5.22 | Y4: 0 | Z4: 0 | AA4: 0 | AB4: 0 | AC4: 0 | AD4: 60 | AE4: 0 | AF4: 0 | AG4: 0 | AH4: 4.56 | AI4: 0 | AJ4: 0 | AK4: 0 | AL4: 0 | AM4: =SUM(F4:AL4) -> 69.78
E5: Petrol | F5: 0 | G5: 4.69 | H5: 0 | I5: 0 | J5: 0 | K5: 0 | L5: 0 | M5: 0 | N5: 3.91 | O5: 0 | P5: 6.98 | Q5: 0 | R5: 0 | S5: 0 | T5: 0 | U5: 0 | V5: 0 | W5: 0 | X5: 0 | Y5: 0 | Z5: 0 | AB5: 0 | AC5: 0 | AD5: 0 | AE5: 0 | AF5: 0 | AG5: 0 | AH5: 0 | AI5: 0 | AJ5: 0 | AK5: 0 | AL5: 0 | AM5: =SUM(F5:AL5) -> 15.58
A6: 2 | B6: Hanumanth Rao | C6: HO | D6: FC3450676131 | E6: Diesel | F6: 0 | G6: 0 | H6: 0 | I6: 0 | J6: 0 | K6: 0 | L6: 0 | M6: 0 | N6: 0 | O6: 0 | P6: 0 | Q6: 0 | R6: 0 | S6: 0 | T6: 0 | U6: 0 | V6: 0 | W6: 0 | X6: 0 | Y6: 0 | Z6: 0 | AA6: 0 | AB6: 0 | AC6: 0 | AD6: 0 | AE6: 0 | AF6: 0 | AG6: 0 | AH6: 0 | AI6: 0 | AJ6: 0 | AK6: 0 | AL6: 0 | AM6: =SUM(F6:AL6) -> 0
E7: Petrol | F7: 0 | G7: 0 | H7: 0 | I7: 0 | J7: 0 | K7: 0 | L7: 0 | M7: 0 | N7: 0 | O7: 0 | P7: 0 | Q7: 0 | R7: 0 | S7: 0 | T7: 0 | U7: 0 | V7: 0 | W7: 0 | X7: 0 | Y7: 0 | Z7: 0 | AB7: 0 | AC7: 0 | AD7: 0 | AE7: 0 | AF7: 0 | AG7: 0 | AH7: 0 | AI7: 0 | AJ7: 0 | AK7: 0 | AL7: 0 | AM7: =SUM(F7:AL7) -> 0
A8: 3 | B8: Radhakrishna | C8: HO | D8: FC8000207658 | E8: Diesel | F8: 0 | G8: 0 | H8: 0 | I8: 0 | J8: 33.44 | K8: 0 | L8: 0 | M8: 0 | N8: 0 | O8: 0 | P8: 0 | Q8: 0 | R8: 35.53 | S8: 0 | T8: 0 | U8: 0 | V8: 0 | W8: 0 | X8: 0 | Y8: 0 | Z8: 0 | AA8: 0 | AB8: 33.44 | AC8: 0 | AD8: 0 | AE8: 0 | AF8: 0 | AG8: 0 | AH8: 0 | AI8: 0 | AJ8: 0 | AK8: 0 | AL8: 0 | AM8: =SUM(F8:AL8) -> 102.41
E9: Petrol | F9: 0 | G9: 0 | H9: 0 | I9: 0 | J9: 0 | K9: 0 | L9: 0 | M9: 0 | N9: 0 | O9: 0 | P9: 0 | Q9: 0 | R9: 0 | S9: 0 | T9: 0 | U9: 0 | V9: 0 | W9: 0 | X9: 0 | Y9: 0 | Z9: 0 | AB9: 0 | AC9: 0 | AD9: 0 | AE9: 0 | AF9: 0 | AG9: 0 | AH9: 0 | AI9: 0 | AJ9: 0 | AK9: 0 | AL9: 0 | AM9: =SUM(F9:AL9) -> 0
A10: 4 | B10: VIjay | C10: HO | D10: FC3450698859 | E10: Diesel | F10: 0 | G10: 0 | H10: 0 | I10: 0 | J10: 0 | K10: 0 | L10: 0 | M10: 0 | N10: 0 | O10: 0 | P10: 49.22 | Q10: 0 | R10: 0 | S10: 0 | T10: 0 | U10: 54.57 | V10: 0 | W10: 0 | X10: 0 | Y10: 0 | Z10: 0 | AA10: 0 | AB10: 0 | AC10: 0 | AD10: 49.8 | AE10: 0 | AF10: 0 | AG10: 0 | AH10: 0 | AI10: 0 | AJ10: 0 | AK10: 0 | AL10: 0 | AM10: =SUM(F10:AL10) -> 153.59
E11: Petrol | F11: 0 | G11: 0 | H11: 0 | I11: 0 | J11: 0 | K11: 0 | L11: 0 | M11: 0 | N11: 0 | O11: 0 | P11: 0 | Q11: 0 | R11: 0 | S11: 0 | T11: 0 | U11: 0 | V11: 0 | W11: 0 | X11: 0 | Y11: 0 | Z11: 0 | AB11: 0 | AC11: 0 | AD11: 0 | AE11: 0 | AF11: 0 | AG11: 0 | AH11: 0 | AI11: 0 | AJ11: 0 | AK11: 0 | AL11: 0 | AM11: =SUM(F11:AL11) -> 0
A12: 5 | B12: Client | C12: Hiriyur | D12: FC3450698864 | E12: Diesel | F12: 0 | G12: 0 | H12: 0 | I12: 0 | J12: 0 | K12: 0 | L12: 0 | M12: 0 | N12: 86.29 | O12: 0 | P12: 0 | Q12: 0 | R12: 0 | S12: 0 | T12: 0 | U12: 0 | V12: 0 | W12: 0 | X12: 0 | Y12: 0 | Z12: 0 | AA12: 0 | AB12: 0 | AC12: 0 | AD12: 145.61 | AE12: 0 | AF12: 0 | AG12: 0 | AH12: 0 | AI12: 0 | AJ12: 0 | AK12: 0 | AL12: 0 | AM12: =SUM(F12:AL12) -> 231.9
E13: Petrol | F13: 0 | G13: 0 | H13: 0 | I13: 0 | J13: 0 | K13: 0 | L13: 0 | M13: 0 | N13: 0 | O13: 0 | P13: 0 | Q13: 0 | R13: 0 | S13: 0 | T13: 0 | U13: 0 | V13: 0 | W13: 0 | X13: 0 | Y13: 0 | Z13: 0 | AB13: 0 | AC13: 0 | AD13: 0 | AE13: 0 | AF13: 0 | AG13: 0 | AH13: 0 | AI13: 0 | AJ13: 0 | AK13: 0 | AL13: 0 | AM13: =SUM(F13:AL13) -> 0
A14: 6 | B14: Client | C14: Hosadurga | D14: FC3450698865 | E14: Diesel | F14: 0 | G14: 0 | H14: 0 | I14: 0 | J14: 0 | K14: 0 | L14: 40 | M14: 40 | N14: 0 | O14: 36 | P14: 35 | Q14: 0 | R14: 0 | S14: 0 | T14: 0 | U14: 0 | V14: 0 | W14: 45 | X14: 45 | Y14: 43.53 | Z14: 40 | AA14: 43 | AB14: 0 | AC14: 40 | AD14: 0 | AE14: 40 | AF14: 0 | AG14: 0 | AH14: 0 | AI14: 0 | AJ14: 0 | AK14: 0 | AL14: 0 | AM14: =SUM(F14:AL14) -> 447.53
E15: Petrol | F15: 0 | G15: 0 | H15: 0 | I15: 0 | J15: 0 | K15: 0 | L15: 0 | M15: 0 | N15: 0 | O15: 0 | P15: 0 | Q15: 0 | R15: 0 | S15: 0 | T15: 0 | U15: 0 | V15: 0 | W15: 0 | X15: 0 | Y15: 0 | Z15: 0 | AB15: 0 | AC15: 0 | AD15: 0 | AE15: 0 | AF15: 0 | AG15: 0 | AH15: 0 | AI15: 0 | AJ15: 0 | AK15: 0 | AL15: 0 | AM15: =SUM(F15:AL15) -> 0
G18: Diesel Price

Sheet  April-2026
A1: S.no | B1: Site Name | C1: Bunk Name | D1: Diesel(Liters) | E1: Diesel Amount | F1: Petrol(Liters) | G1: Petrol Amount | H1: Total Amount | I1: Opening Blance | J1: Amount Paid | K1: Closing Balances
A2: 1 | B2: Khammam-1 | C2: Divya laxmi ganapathi | D2: =+'Khammam-1'!E38 -> 26600.49 | E2: =+'Khammam-1'!G38 -> 2545134.9 | F2: =+'Khammam-1'!H38 -> 351.49 | G2: =+'Khammam-1'!J38 -> 37771.115 | H2: =E2+G2 -> 2582906 | I2: =+'Khammam-1'!K3 -> 4176411.7 | J2: =+'Khammam-1'!L38 -> 4989687 | K2: =H2+I2-J2 -> 1769630.7
A3: 2 | B3: Khammam-2 | C3: Jayasai union bunk | D3: =+'Khammam-2'!E35 -> 39552.56 | E3: =+'Khammam-2'!G35 -> 3785575.5 | F3: =+'Khammam-2'!H35 -> 561 | G3: =+'Khammam-2'!J35 -> 60301.89 | H3: =E3+G3 -> 3845877.4 | I3: =+'Khammam-2'!K3 -> 8032637.3 | J3: =+'Khammam-2'!L35 -> 8152861.8 | K3: =H3+I3-J3 -> 3725653
A4: 3 | B4: Khammam-3 | C4: JSASFuel Genie India Pvt.Ltd | D4: =+'Khammam-3'!E35 -> 48000 | E4: =+'Khammam-3'!G35 -> 4572600 | F4: =+'Khammam-3'!H35 -> 0 | G4: =+'Khammam-3'!J35 -> 0 | H4: =E4+G4 -> 4572600 | I4: =+'Khammam-3'!M3 -> 8227903.3 | J4: =+'Khammam-3'!L35 -> 10227903 | K4: =H4+I4-J4 -> 2572600.3
A5: 4 | B5: Khammam-4 | C5: Vajra Mahalakshmi filling station | D5: =+'Khammam-4'!E38 -> 0 | E5: =+'Khammam-4'!G38 -> 0 | F5: =+'Khammam-4'!H38 -> 0 | G5: =+'Khammam-4'!J38 -> 0 | H5: =E5+G5 -> 0 | I5: =+'Khammam-4'!M3 -> 330407.08 | J5: =+'Khammam-4'!L38 -> 330407 | K5: =H5+I5-J5 -> 0.08
A6: 5 | B6: Khammam-5 | C6: SR HP Filling Station | D6: =+'Khammam-5'!E38 -> 3135.46 | E6: =+'Khammam-5'!G38 -> 300000.81 | F6: =+'Khammam-5'!H38 -> 0 | G6: =+'Khammam-5'!J38 -> 0 | H6: =E6+G6 -> 300000.81 | I6: =+'Khammam-5'!M3 -> 0 | J6: =+'Khammam-5'!L38 -> 300000.81 | K6: =H6+I6-J6 -> 0
A7: 6 | B7: Khammam-6 | C7: NA | D7: =+' Khammam&Cash'!E46 -> 24857.48 | E7: =+' Khammam&Cash'!G46 -> 2378764.7 | F7: =+' Khammam&Cash'!H46 -> 95 | G7: =+' Khammam&Cash'!J46 -> 10208.7 | H7: =E7+G7 -> 2388973.4 | I7: =+' Khammam&Cash'!M3 -> 0 | J7: =+' Khammam&Cash'!L46 -> 2388973.4 | K7: =H7+I7-J7 -> 0.0020000003
A8: 7 | B8: Jadcherla-1 | C8: JSASFuel Genie India Pvt.Ltd | D8: =+'Jadcherla-3'!E35 -> 13690 | E8: =+'Jadcherla-3'!G35 -> 1313281.7 | F8: =+'Jadcherla-3'!H35 -> 0 | G8: =+'Jadcherla-3'!J35 -> 0 | H8: =E8+G8 -> 1313281.7 | I8: =+'Jadcherla-3'!M3 -> 2453209.4 | J8: =+'Jadcherla-3'!L35 -> 2453209.4 | K8: =H8+I8-J8 -> 1313281.7
A9: 8 | B9: Jadcherla-2 | C9: Shree Poornima F/S | D9: =+'Jadcherla-4'!E35 -> 4020 | E9: =+'Jadcherla-4'!G35 -> 387246 | F9: =+'Jadcherla-4'!H35 -> 80 | G9: =+'Jadcherla-4'!J35 -> 8653.2 | H9: =E9+G9 -> 395899.2 | I9: =+'Jadcherla-4'!M3 -> 9729 | J9: =+'Jadcherla-4'!L35 -> 402105 | K9: =H9+I9-J9 -> 3523.2
A10: 9 | B10: Jadcherla-3 | C10: Sai Baba Filling Station | D10: =+' Jadcherla'!E35 -> 3000 | E10: =+' Jadcherla'!G35 -> 289260 | F10: =+' Jadcherla'!H35 -> 0 | G10: =+' Jadcherla'!J35 -> 0 | H10: =E10+G10 -> 289260 | I10: =+' Jadcherla'!M3 -> 0 | J10: =+' Jadcherla'!L35 -> 244630 | K10: =H10+I10-J10 -> 44630
A11: 10 | B11: Sangareddy-1 | C11: Durga Indhan | D11: =+' Sangareeddy-1'!E35 -> 0 | E11: =+' Sangareeddy-1'!G35 -> 0 | F11: =+' Sangareeddy-1'!H35 -> 0 | G11: =+' Sangareeddy-1'!J35 -> 0 | H11: =E11+G11 -> 0 | I11: =+' Sangareeddy-1'!M3 -> 71161.048 | J11: =+' Sangareeddy-1'!L35 -> 71161.05 | K11: =H11+I11-J11 -> -0.0019999999
A12: 11 | B12: Sangareddy-2 | C12: Durga Bhavani F/S | D12: =+' Sangareddy-2'!E35 -> 18689.16 | E12: =+' Sangareddy-2'!G35 -> 1802382.6 | F12: =+' Sangareddy-2'!H35 -> 315.63 | G12: =+' Sangareddy-2'!J35 -> 34185.885 | H12: =E12+G12 -> 1836568.5 | I12: =+' Sangareddy-2'!M3 -> 324643.92 | J12: =+' Sangareddy-2'!L35 -> 1902217 | K12: =H12+I12-J12 -> 258995.39
A13: 12 | B13: Sangareddy-3 | C13: Shiva Parvathi Filling Station | D13: =+' Sangareddy-3'!E35 -> 5856.17 | E13: =+' Sangareddy-3'!G35 -> 563539.24 | F13: =+' Sangareddy-3'!H35 -> 0 | G13: =+' Sangareddy-3'!J35 -> 0 | H13: =E13+G13 -> 563539.24 | I13: =+' Sangareddy-3'!M3 -> 0 | J13: =+' Sangareddy-3'!L35 -> 400000 | K13: =H13+I13-J13 -> 163539.24
A14: 13 | B14: NarayanKhed | C14: Sai Shiva Filling Station | D14: =+' Narayankhed'!E35 -> 300 | E14: =+' Narayankhed'!G35 -> 29100 | F14: =+' Narayankhed'!H35 -> 0 | G14: =+' Narayankhed'!J35 -> 0 | H14: =E14+G14 -> 29100 | I14: =+' Narayankhed'!M3 -> 0 | J14: =+' Narayankhed'!L35 -> 29100 | K14: =H14+I14-J14 -> 0
A15: 14 | B15: Dindi | C15: Akarapu Balakistamma Fillling | D15: =+Dindi!E35 -> 0 | E15: =+Dindi!G35 -> 0 | F15: =+Dindi!H35 -> 0 | G15: =+Dindi!J35 -> 0 | H15: =E15+G15 -> 0 | I15: =+Dindi!M3 -> 0 | J15: =+Dindi!L35 -> 0 | K15: =H15+I15-J15 -> 0
A16: 15 | B16: Madanapalli | C16: NA | D16: =+'Madana palli'!E36 -> 0 | E16: =+'Madana palli'!G36 -> 0 | F16: =+'Madana palli'!H36 -> 0 | G16: =+'Madana palli'!J36 -> 0 | H16: =E16+G16 -> 0 | I16: =+'Madana palli'!M3 -> 0 | J16: =+'Madana palli'!L36 -> 0 | K16: =H16+I16-J16 -> 0
A17: 16 | B17: Kakinada | C17: NA | D17: =+Amalapuram!E48 -> 1141.65 | E17: =+Amalapuram!G48 -> 110749.41 | F17: =+Amalapuram!H48 -> 105 | G17: =+Amalapuram!J48 -> 11422.35 | H17: =E17+G17 -> 122171.76 | I17: =+Amalapuram!M3 -> 0 | J17: =+Amalapuram!L48 -> 122171.34 | K17: =H17+I17-J17 -> 0.424
A18: 17 | B18: YG Gudda-2 | C18: Pankaja HP Fuel Center | D18: =+'YG Gudda-2'!E37 -> 7200 | E18: =+'YG Gudda-2'!G37 -> 657576 | F18: =+'YG Gudda-2'!H37 -> 315 | G18: =+'YG Gudda-2'!J37 -> 32530.05 | H18: =E18+G18 -> 690106.05 | I18: =+'YG Gudda-2'!M3 -> 250329.91 | J18: =+'YG Gudda-2'!L37 -> 746330 | K18: =H18+I18-J18 -> 194105.96
A19: 18 | B19: Hosadurga-2 | C19: Shree Veeraprathap Fuel | D19: =+'Hosadurga -2'!E35 -> 6599.13 | E19: =+'Hosadurga -2'!G35 -> 603734.35 | F19: =+'Hosadurga -2'!H35 -> 210 | G19: =+'Hosadurga -2'!J35 -> 21754.95 | H19: =+'Hosadurga -2'!K35 -> 625489.3 | I19: =+'Hosadurga -2'!K3 -> 198796.97 | J19: =+'Hosadurga -2'!L35 -> 575797 | K19: =H19+I19-J19 -> 248489.28
A20: 19 | B20: Malebennuru(KUWSDB) | C20: Sri Ramanjuneya Service Station | D20: =+'Malebenur(KUWSDB)'!E37 -> 3600 | E20: =+'Malebenur(KUWSDB)'!G37 -> 331236 | F20: =+'Malebenur(KUWSDB)'!H37 -> 195 | G20: =+'Malebenur(KUWSDB)'!J37 -> 20233.2 | H20: =E20+G20 -> 351469.2 | I20: =+'Malebenur(KUWSDB)'!K3 -> 79478.01 | J20: =+'Malebenur(KUWSDB)'!L37 -> 237298 | K20: =H20+I20-J20 -> 193649.21
A21: 20 | B21: kadur | C21: Vishal Service Station | D21: =+Kadur!E35 -> 1800 | E21: =+Kadur!G35 -> 171270 | F21: =+Kadur!H35 -> 140 | G21: =+Kadur!J35 -> 15297.8 | H21: =E21+G21 -> 186567.8 | I21: =+Kadur!K3 -> 102970.63 | J21: =+Kadur!L35 -> 289538 | K21: =H21+I21-J21 -> 0.431
A22: 21 | B22: Hiriyur(VJNL) | C22: Sri Balaji Agencies | D22: =+'Hiriyur(VJNL)'!E35 -> 5000 | E22: =+'Hiriyur(VJNL)'!G35 -> 460500 | F22: =+'Hiriyur(VJNL)'!H35 -> 175 | G22: =+'Hiriyur(VJNL)'!J35 -> 18175.5 | H22: =E22+G22 -> 478675.5 | I22: =+'Hiriyur(VJNL)'!K3 -> 69.8 | J22: =+'Hiriyur(VJNL)'!L35 -> 200000 | K22: =H22+I22-J22 -> 278745.3
A23: 22 | B23: Chellakere(KUWSDB) | C23: Shivaganga Service Station | D23: =+'Chellakere -1'!E35 -> 4600 | E23: =+'Chellakere -1'!G35 -> 423520.2 | F23: =+'Chellakere -1'!H35 -> 205 | G23: =+'Chellakere -1'!J35 -> 21283.1 | H23: =E23+G23 -> 444803.3 | I23: =+'Chellakere -1'!K3 -> 215562.07 | J23: =+'Chellakere -1'!L35 -> 410562 | K23: =H23+I23-J23 -> 249803.37
A24: 23 | B24: Chellakere(KUWSDB)-09 | C24: Shivaganga Service Station | D24: =+' Chellakere-PKG-9'!E35 -> 325.38 | E24: =+' Chellakere-PKG-9'!G35 -> 29957.387 | F24: =+' Chellakere-PKG-9'!H35 -> 38 | G24: =+' Chellakere-PKG-9'!J35 -> 3945.16 | H24: =E24+G24 -> 33902.547 | I24: =+' Chellakere-PKG-9'!M3 -> 0 | J24: =+' Chellakere-PKG-9'!L35 -> 33902.547 | K24: =H24+I24-J24 -> 0
A25: 24 | B25: Molakalmuru | C25: Sri Lakshmi Venkateshwara Filling Station | D25: =+Molakamuru!E35 -> 1300 | E25: =+Molakamuru!G35 -> 119678 | F25: =+Molakamuru!H35 -> 50 | G25: =+Molakamuru!J35 -> 5190.5 | H25: =E25+G25 -> 124868.5 | I25: =+Molakamuru!K3 -> 4179.7152 | J25: =+Molakamuru!L35 -> 72756.4 | K25: =H25+I25-J25 -> 56291.815
A26: 25 | B26: Chennagiri | C26: NA | D26: =+' Chennagiri'!E35 -> 360 | E26: =+' Chennagiri'!G35 -> 33084.4 | F26: =+' Chennagiri'!H35 -> 49 | G26: =+' Chennagiri'!J35 -> 5087.89 | H26: =E26+G26 -> 38172.29 | I26: =+' Chennagiri'!K3 -> 0 | J26: =+' Chennagiri'!L35 -> 38172.29 | K26: =H26+I26-J26 -> 0
A27: 26 | B27: Khanapur(PKG-3) | C27: V.V.Varde | D27: =+Khanapur!E35 -> 2008.49 | E27: =+Khanapur!G35 -> 182531.57 | F27: =+Khanapur!H35 -> 153 | G27: =+Khanapur!J35 -> 15723.81 | H27: =E27+G27 -> 198255.38 | I27: =+Khanapur!M3 -> 153658.75 | J27: =+Khanapur!L35 -> 237619 | K27: =H27+I27-J27 -> 114295.13
A28: 27 | B28: Munavalli(PKG-3)-2 | C28: Shre Shiva Petroleum | D28: =+'Munavali-2'!E38 -> 12432.9 | E28: =+'Munavali-2'!G38 -> 1138087.2 | F28: =+'Munavali-2'!H38 -> 204.77 | G28: =+'Munavali-2'!J38 -> 21291.852 | H28: =E28+G28 -> 1159379 | I28: =+'Munavali-2'!M3 -> 607059.51 | J28: =+'Munavali-2'!L38 -> 1198830.9 | K28: =H28+I28-J28 -> 567607.62
A29: 28 | B29: Borgaon(PKG-3) | C29: Aadisagar Petrolium | D29: =+Borgaon!E35 -> 4710.57 | E29: =+Borgaon!G35 -> 432289.01 | F29: =+Borgaon!H35 -> 99.81 | G29: =+Borgaon!J35 -> 10353.291 | H29: =E29+G29 -> 442642.3 | I29: =+Borgaon!K3 -> 85513.088 | J29: =+Borgaon!L35 -> 421500 | K29: =H29+I29-J29 -> 106655.39
A30: 29 | B30: Ugar,Kudichi(PKG-3) | C30: Shiri Bhrhmanath Petrolium | D30: =+'Ugar,Khagwad,Kudichi'!E35 -> 10909.45 | E30: =+'Ugar,Khagwad,Kudichi'!G35 -> 1002905.7 | F30: =+'Ugar,Khagwad,Kudichi'!H35 -> 300 | G30: =+'Ugar,Khagwad,Kudichi'!J35 -> 31543.4 | H30: =E30+G30 -> 1034449.1 | I30: =+'Ugar,Khagwad,Kudichi'!M3 -> 434415.61 | J30: =+'Ugar,Khagwad,Kudichi'!L35 -> 884650 | K30: =H30+I30-J30 -> 584214.75
A31: 30 | B31: Kabbur(PKG-3) | C31: Shri Jai Hanuman Petrolium | D31: =+Kabbur!E35 -> 436.01 | E31: =+Kabbur!G35 -> 39938.516 | F31: =+Kabbur!H35 -> 20.83 | G31: =+Kabbur!J35 -> 2156.7382 | H31: =E31+G31 -> 42095.254 | I31: 0 | J31: =+Kabbur!L35 -> 42095.254 | K31: =H31+I31-J31 -> 0
A32: 31 | B32: Kumta (PKG-1) | C32: V.M.MIRJANKAR (KUMTA) BHARAT | D32: =+kumta!E36 -> 2145 | E32: =+kumta!G36 -> 197273.15 | F32: =+kumta!H36 -> 177 | G32: =+kumta!J36 -> 18409.77 | H32: =E32+G32 -> 215682.92 | I32: =kumta!M3 -> 34759.3 | J32: =+kumta!L36 -> 247835 | K32: =H32+I32-J32 -> 2607.22
A33: 32 | B33: Jalgaon | C33: Jai Bajarang Sarvo Senter Bodwad | D33: =+Jalgaon!E55 -> 9000 | E33: =+Jalgaon!G55 -> 825390 | F33: =+Jalgaon!H55 -> 60 | G33: =+Jalgaon!J55 -> 6311.4 | H33: =E33+G33 -> 831701.4 | I33: =+Jalgaon!K3 -> 1651007.9 | J33: =+Jalgaon!L55 -> 2388895.6 | K33: =H33+I33-J33 -> 93813.679
A34: 33 | B34: Jalgaon-2 | C34: Nayara | D34: =+'Jalgoan-2'!E55 -> 64300.61 | E34: ='Jalgoan-2'!G55 -> 6089910.8 | F34: =+'Jalgoan-2'!H55 -> 405 | G34: =+'Jalgoan-2'!J55 -> 44728.2 | H34: =E34+G34 -> 6134639 | I34: =+'Jalgoan-2'!M3 -> 5471845 | J34: =+'Jalgoan-2'!L55 -> 8941028 | K34: =H34+I34-J34 -> 2665456
A35: 34 | B35: Jalgaon-3 | C35: T R KAPOOR AND CO | D35: =+' Jalgoan-3'!E55 -> 2500 | E35: =+' Jalgoan-3'!G55 -> 229925 | F35: =+' Jalgoan-3'!H55 -> 0 | G35: =+' Jalgoan-3'!J55 -> 0 | H35: =E35+G35 -> 229925 | I35: =+' Jalgoan-3'!M3 -> 0 | J35: =+' Jalgoan-3'!L55 -> 229925 | K35: =H35+I35-J35 -> 0
A36: 35 | B36: Jalgaon-4 | C36: NA | D36: =+' Jalgoan-4'!E60 -> 40913.03 | E36: =+' Jalgoan-4'!G60 -> 3753069.7 | F36: =+' Jalgoan-4'!H60 -> 0 | G36: =+' Jalgoan-4'!J60 -> 0 | H36: =E36+G36 -> 3753069.7 | I36: =+' Jalgoan-4'!M3 -> 0 | J36: =+' Jalgoan-4'!L60 -> 3753069.7 | K36: =H36+I36-J36 -> 0
A37: 36 | B37: MKBD | C37: Shree Sai Samarth Petroleum | D37: =+MKBD!E39 -> 27000 | E37: =+MKBD!G39 -> 2460780 | F37: =+MKBD!H39 -> 166 | G37: =+MKBD!J39 -> 18929 | H37: =E37+G37 -> 2479709 | I37: =+MKBD!K3 -> 1463406.5 | J37: =+MKBD!L39 -> 1372840 | K37: =H37+I37-J37 -> 2570275.5
A38: 37 | B38: Haveri | C38: M/s Magavi City Fuels | D38: =' Haveri-2'!E38 -> 2758.19 | E38: =' Haveri-2'!G38 -> 252346.8 | F38: =' Haveri-2'!H38 -> 101.33 | G38: =' Haveri-2'!J38 -> 10480.562 | H38: =E38+G38 -> 262827.36 | I38: =' Haveri-2'!M3 -> 77285.143 | J38: =+' Haveri-2'!L38 -> 280000 | K38: =H38+I38-J38 -> 60112.508
A39: 38 | B39: Guttal-2 | C39: Himagiri Petroleum | D39: =+' Guttal-2'!E35 -> 7724.14 | E39: =+' Guttal-2'!G35 -> 708921.57 | F39: =+' Guttal-2'!H35 -> 180 | G39: =+' Guttal-2'!J35 -> 18673.2 | H39: =E39+G39 -> 727594.77 | I39: =+' Guttal-2'!M3 -> 203929.33 | J39: =+' Guttal-2'!L35 -> 730929 | K39: =H39+I39-J39 -> 200595.1
A40: 39 | B40: Rattihali-2 | C40: Shiva Oil Traders | D40: =+'Rattihali-2'!E37 -> 3860.03 | E40: =+'Rattihali-2'!G37 -> 354698.16 | F40: =+'Rattihali-2'!H37 -> 109 | G40: =+'Rattihali-2'!J37 -> 11319.65 | H40: =E40+G40 -> 366017.81 | I40: =+'Rattihali-2'!M3 -> 263742.1 | J40: =+'Rattihali-2'!L37 -> 363742 | K40: =H40+I40-J40 -> 266017.9
...

Sheet HO(DG)
A1: JSASFuel Genie India Pvt.Ltd
A2: S.No | B2: Date | C2: GRN No | D2: Ind No/Bill No | E2: Diesel (Lts) | F2: Price | G2: Amount | H2: Petrol (Lts) | I2: Price | J2: Amount | K2: Total amount | L2: Amount paid | M2: As on date | N2: Remarks
A3: Opening Balance | M3: 188521.22 | O3: 2623243.4
A4: 1 | B4: 46113 | G4: =E4*F4 -> 0 | H4: 0 | I4: 0 | J4: =H4*I4 -> 0 | K4: =G4+J4 -> 0 | L4: 0 | M4: =M3+K4-L4 -> 188521.22
A5: 2 | B5: 46114 | G5: =E5*F5 -> 0 | H5: 0 | I5: 0 | J5: =H5*I5 -> 0 | K5: =G5+J5 -> 0 | L5: 0 | M5: =M4+K5-L5 -> 188521.22 | R5: HO | S5: 188521.22
A6: 3 | B6: 46115 | G6: =E6*F6 -> 0 | H6: 0 | I6: 0 | J6: =H6*I6 -> 0 | K6: 0 | L6: 188521.22 | M6: =M5+K6-L6 -> 0 | R6: Khammam | S6: 8227903
B7: 46115 | E7: 20.47 | F7: 95.64 | G7: =E7*F7 -> 1957.7508 | H7: 0 | I7: 0 | J7: =H7*I7 -> 0 | K7: =G7+J7 -> 1957.7508 | L7: =H7+K7 -> 1957.7508 | M7: =M6+K7-L7 -> 0 | R7: Jadcherla | S7: 2453209.4
A8: 4 | B8: 46115 | E8: 35 | F8: 95.64 | G8: =E8*F8 -> 3347.4 | H8: 0 | I8: 0 | J8: =H8*I8 -> 0 | K8: =G8+J8 -> 3347.4 | L8: =H8+K8 -> 3347.4 | M8: =M7+K8-L8 -> 0 | P8: 5679 | R8: Total | S8: =SUM(S5:S7) -> 10869634
A9: 5 | B9: 46116 | E9: 200 | F9: 95.83 | G9: =E9*F9 -> 19166 | H9: 0 | I9: 0 | J9: =H9*I9 -> 0 | K9: =G9+J9 -> 19166 | L9: 0 | M9: =M8+K9-L9 -> 19166 | S9: 10869632
B10: 46116 | E10: 36.59 | F10: 95.64 | G10: =E10*F10 -> 3499.4676 | K10: =G10+J10 -> 3499.4676 | L10: =H10+K10 -> 3499.4676 | M10: =M9+K10-L10 -> 19166 | S10: =S9-S8 -> -1.6105
A11: 6 | B11: 46118 | G11: =E11*F11 -> 0 | H11: 0 | I11: 0 | J11: =H11*I11 -> 0 | K11: =G11+J11 -> 0 | L11: 0 | M11: =M10+K11-L11 -> 19166
A12: 7 | B12: 46119 | G12: =E12*F12 -> 0 | H12: 0 | I12: 0 | J12: =H12*I12 -> 0 | K12: =G12+J12 -> 0 | L12: 0 | M12: =M11+K12-L12 -> 19166
A13: 8 | B13: 46120 | G13: =E13*F13 -> 0 | H13: 0 | I13: 0 | J13: =H13*I13 -> 0 | K13: =G13+J13 -> 0 | L13: 0 | M13: =M12+K13-L13 -> 19166
A14: 9 | B14: 46121 | E14: 205 | F14: 95.83 | G14: =E14*F14 -> 19645.15 | H14: 0 | I14: 0 | J14: =H14*I14 -> 0 | K14: =G14+J14 -> 19645.15 | L14: 0 | M14: =M13+K14-L14 -> 38811.15
A15: 10 | B15: 46122 | G15: =E15*F15 -> 0 | H15: 0 | I15: 0 | J15: =H15*I15 -> 0 | K15: =G15+J15 -> 0 | L15: 0 | M15: =M14+K15-L15 -> 38811.15 | R15: 19166
A16: 11 | B16: 46123 | G16: =E16*F16 -> 0 | H16: 0 | I16: 0 | J16: =H16*I16 -> 0 | K16: =G16+J16 -> 0 | L16: 0 | M16: =M15+K16-L16 -> 38811.15 | R16: 19645
A17: 12 | B17: 46124 | G17: =E17*F17 -> 0 | H17: 0 | I17: 0 | J17: =H17*I17 -> 0 | K17: =G17+J17 -> 0 | L17: 0 | M17: =M16+K17-L17 -> 38811.15 | P17: 1905988 | Q17: =P17-M17 -> 1867176.9 | R17: 21083
A18: 13 | B18: 46125 | G18: =E18*F18 -> 0 | H18: 0 | I18: 0 | J18: =H18*I18 -> 0 | K18: =G18+J18 -> 0 | L18: 0 | M18: =M17+K18-L18 -> 38811.15 | R18: 19140 | S18: 220637
A19: 14 | B19: 46126 | E19: 70 | F19: 95.64 | G19: =E19*F19 -> 6694.8 | H19: 0 | I19: 0 | J19: =H19*I19 -> 0 | K19: =G19+J19 -> 6694.8 | L19: =H19+K19 -> 6694.8 | M19: =M18+K19-L19 -> 38811.15 | N19: HPCL | R19: =SUM(R15:R18) -> 79034 | S19: =S18+R19 -> 299671
A20: 15 | B20: 46127 | E20: 35 | F20: 95.64 | G20: =E20*F20 -> 3347.4 | H20: 0 | I20: 0 | J20: =H20*I20 -> 0 | K20: =G20+J20 -> 3347.4 | L20: =H20+K20 -> 3347.4 | M20: =M19+K20-L20 -> 38811.15 | N20: HPCL
A21: 16 | B21: 46128 | E21: 35 | F21: 95.64 | G21: =E21*F21 -> 3347.4 | H21: 0 | I21: 0 | J21: =H21*I21 -> 0 | K21: =G21+J21 -> 3347.4 | L21: =H21+K21 -> 3347.4 | M21: =M20+K21-L21 -> 38811.15
A22: 16 | B22: 46128 | E22: 220 | F22: 95.83 | G22: =E22*F22 -> 21082.6 | H22: 0 | I22: 0 | J22: =H22*I22 -> 0 | K22: =G22+J22 -> 21082.6 | L22: 0 | M22: =M21+K22-L22 -> 59893.75
A23: 17 | B23: 46129 | G23: =E23*F23 -> 0 | H23: 0 | I23: 0 | J23: =H23*I23 -> 0 | K23: =G23+J23 -> 0 | L23: 0 | M23: =M22+K23-L23 -> 59893.75
A24: 18 | B24: 46130 | G24: =E24*F24 -> 0 | H24: 0 | I24: 0 | J24: =H24*I24 -> 0 | K24: =G24+J24 -> 0 | L24: 0 | M24: =M23+K24-L24 -> 59893.75
A25: 19 | B25: 46131 | G25: =E25*F25 -> 0 | H25: 0 | I25: 0 | J25: =H25*I25 -> 0 | K25: =G25+J25 -> 0 | L25: 0 | M25: =M24+K25-L25 -> 59893.75
A26: 20 | B26: 46132 | G26: =E26*F26 -> 0 | H26: 0 | I26: 0 | J26: =H26*I26 -> 0 | K26: =G26+J26 -> 0 | L26: 0 | M26: =M25+K26-L26 -> 59893.75
A27: 21 | B27: 46133 | E27: 59.08 | F27: 95.64 | G27: =E27*F27 -> 5650.4112 | H27: 0 | I27: 0 | J27: =H27*I27 -> 0 | K27: =G27+J27 -> 5650.4112 | L27: =H27+K27 -> 5650.4112 | M27: =M26+K27-L27 -> 59893.75
A28: 22 | B28: 46134 | E28: 77.73 | F28: 95.64 | G28: =E28*F28 -> 7434.0972 | H28: 0 | I28: 0 | J28: =H28*I28 -> 0 | K28: =G28+J28 -> 7434.0972 | L28: =H28+K28 -> 7434.0972 | M28: =M27+K28-L28 -> 59893.75
A29: 23 | B29: 46135 | E29: 200 | F29: 95.7 | G29: =E29*F29 -> 19140 | H29: 0 | I29: 0 | J29: =H29*I29 -> 0 | K29: =G29+J29 -> 19140 | L29: 0 | M29: =M28+K29-L29 -> 79033.75
A30: 24 | B30: 46136 | G30: =E30*F30 -> 0 | H30: 0 | I30: 0 | J30: =H30*I30 -> 0 | K30: =G30+J30 -> 0 | L30: 0 | M30: =M29+K30-L30 -> 79033.75
B31: 46137 | G31: =E31*F31 -> 0 | H31: 0 | I31: 0 | J31: =H31*I31 -> 0 | K31: =G31+J31 -> 0 | L31: 0 | M31: =M30+K31-L31 -> 79033.75
A32: 25 | B32: 46138 | G32: =E32*F32 -> 0 | H32: 0 | I32: 0 | J32: =H32*I32 -> 0 | K32: =G32+J32 -> 0 | L32: 0 | M32: =M31+K32-L32 -> 79033.75
A33: 26 | B33: 46139 | D33: Ganga Fuel F/S | E33: 114.18 | F33: 95.64 | G33: =E33*F33 -> 10920.175 | H33: 0 | I33: 0 | J33: =H33*I33 -> 0 | K33: =G33+J33 -> 10920.175 | L33: =H33+K33 -> 10920.175 | M33: =M32+K33-L33 -> 79033.75
B34: 46139 | D34: COCO Hitech City IOCL | E34: 110 | F34: 95.7 | G34: =E34*F34 -> 10527 | K34: =G34+J34 -> 10527 | L34: =H34+K34 -> 10527 | M34: =M33+K34-L34 -> 79033.75
A35: 27 | B35: 46140 | G35: =E35*F35 -> 0 | H35: 0 | I35: 0 | J35: =H35*I35 -> 0 | K35: =G35+J35 -> 0 | L35: 0 | M35: =M33+K35-L35 -> 79033.75
A36: 28 | B36: 46141 | G36: =E36*F36 -> 0 | H36: 0 | I36: 0 | J36: =H36*I36 -> 0 | K36: =G36+J36 -> 0 | L36: 0 | M36: =M35+K36-L36 -> 79033.75
A37: 29 | B37: 46142 | D37: Venkatadri Fueles | E37: 165 | F37: 95.64 | G37: =E37*F37 -> 15780.6 | H37: 0 | I37: 0 | J37: =H37*I37 -> 0 | K37: =G37+J37 -> 15780.6 | L37: =H37+K37 -> 15780.6 | M37: =M36+K37-L37 -> 79033.75
A38: 30 | E38: 0 | G38: =E38*F38 -> 0 | H38: 0 | I38: 0 | J38: =H38*I38 -> 0 | K38: =G38+J38 -> 0 | L38: 0 | M38: =M37+K38-L38 -> 79033.75
A39: 31 | G39: =E39*F39 -> 0 | H39: 0 | I39: 0 | J39: =H39*I39 -> 0 | K39: =G39+J39 -> 0 | L39: 0 | M39: =M38+K39-L39 -> 79033.75
A40: 32 | G40: =E40*F40 -> 0 | J40: =H40*I40 -> 0 | K40: =G40+J40 -> 0 | M40: =M39+K40-L40 -> 79033.75
...

Sheet Khammam-1
A1: Divya laxmi ganapathi
A2: S.No | B2: Date | C2: GRN No | D2: Ind No/Bill No | E2: Diesel (Lts) | F2: Price | G2: Amount | H2: Petrol (Lts) | I2: Price | J2: Amount | K2: Total amount | L2: Amount paid | M2: As 0n Date | N2: Remarks
A3: Opening Balance | K3: 4176411.7 | M3: 4176411.7
A4: 1 | B4: 46113 | G4: =E4*F4 -> 0 | K4: =G4+J4 -> 0 | L4: 0 | M4: =M3+K4-L4 -> 4176411.7
A5: 2 | B5: 46114 | G5: =E5*F5 -> 0 | K5: =G5+J5 -> 0 | L5: 4176407 | M5: =M4+K5-L5 -> 4.6869
A6: 3 | B6: 46115 | E6: 2700.49 | F6: 95.68 | G6: =E6*F6 -> 258382.88 | H6: 55 | I6: 107.46 | J6: =H6*I6 -> 5910.3 | K6: =G6+J6 -> 264293.18 | L6: 0 | M6: =M5+K6-L6 -> 264297.87
A7: 4 | B7: 46116 | G7: =E7*F7 -> 0 | J7: =H7*I7 -> 0 | K7: =G7+J7 -> 0 | L7: 0 | M7: =M6+K7-L7 -> 264297.87
A8: 5 | B8: 46117 | E8: 2700 | F8: 95.68 | G8: =E8*F8 -> 258336 | H8: 60 | I8: 107.46 | J8: =H8*I8 -> 6447.6 | K8: =G8+J8 -> 264783.6 | L8: 0 | M8: =M7+K8-L8 -> 529081.47
A9: 6 | B9: 46118 | G9: =E9*F9 -> 0 | J9: =H9*I9 -> 0 | K9: =G9+J9 -> 0 | L9: 0 | M9: =M8+K9-L9 -> 529081.47
A10: 7 | B10: 46119 | E10: 2700 | F10: 95.68 | G10: =E10*F10 -> 258336 | H10: 60 | I10: 107.46 | J10: =H10*I10 -> 6447.6 | K10: =G10+J10 -> 264783.6 | L10: 0 | M10: =M9+K10-L10 -> 793865.07
A11: 8 | B11: 46120 | G11: =E11*F11 -> 0 | J11: =H11*I11 -> 0 | K11: =G11+J11 -> 0 | L11: 0 | M11: =M10+K11-L11 -> 793865.07
A12: 9 | B12: 46121 | G12: =E12*F12 -> 0 | J12: =H12*I12 -> 0 | K12: =G12+J12 -> 0 | L12: 0 | M12: =M11+K12-L12 -> 793865.07
A13: 10 | B13: 46122 | E13: 2500 | F13: 95.68 | G13: =E13*F13 -> 239200 | H13: 95 | I13: 107.46 | J13: =H13*I13 -> 10208.7 | K13: =G13+J13 -> 249408.7 | L13: 0 | M13: =M12+K13-L13 -> 1043273.8
A14: 11 | B14: 46123 | G14: =E14*F14 -> 0 | J14: =H14*I14 -> 0 | K14: =G14+J14 -> 0 | L14: 0 | M14: =M13+K14-L14 -> 1043273.8
A15: 12 | B15: 46124 | G15: =E15*F15 -> 0 | J15: =H15*I15 -> 0 | K15: =G15+J15 -> 0 | L15: 0 | M15: =M14+K15-L15 -> 1043273.8
A16: 13 | B16: 46125 | E16: 2500 | F16: 95.68 | G16: =E16*F16 -> 239200 | H16: 60 | I16: 107.46 | J16: =H16*I16 -> 6447.6 | K16: =G16+J16 -> 245647.6 | L16: 0 | M16: =M15+K16-L16 -> 1288921.4
A17: 14 | B17: 46126 | E17: 1500 | F17: 95.68 | G17: =E17*F17 -> 143520 | H17: 21.49 | I17: 107.46 | J17: =H17*I17 -> 2309.3154 | K17: =G17+J17 -> 145829.32 | L17: 0 | M17: =M16+K17-L17 -> 1434750.7
A18: 15 | B18: 46127 | G18: =E18*F18 -> 0 | K18: =G18+J18 -> 0 | L18: 0 | M18: =M17+K18-L18 -> 1434750.7
A19: 16 | B19: 46128 | G19: =E19*F19 -> 0 | K19: =G19+J19 -> 0 | L19: 0 | M19: =M18+K19-L19 -> 1434750.7
A20: 17 | B20: 46129 | G20: =E20*F20 -> 0 | K20: =G20+J20 -> 0 | L20: 0 | M20: =M19+K20-L20 -> 1434750.7
A21: 18 | B21: 46130 | G21: =E21*F21 -> 0 | K21: =G21+J21 -> 0 | L21: 0 | M21: =M20+K21-L21 -> 1434750.7
A22: 19 | B22: 46131 | G22: =E22*F22 -> 0 | K22: =G22+J22 -> 0 | L22: 0 | M22: =M21+K22-L22 -> 1434750.7
A23: 20 | B23: 46132 | G23: =E23*F23 -> 0 | K23: =G23+J23 -> 0 | L23: 0 | M23: =M22+K23-L23 -> 1434750.7
A24: 21 | B24: 46133 | E24: 2000 | F24: 95.68 | G24: =E24*F24 -> 191360 | K24: =G24+J24 -> 191360 | L24: 0 | M24: =M23+K24-L24 -> 1626110.7
A25: 22 | B25: 46134 | E25: 1500 | F25: 95.68 | G25: =E25*F25 -> 143520 | K25: =G25+J25 -> 143520 | L25: 0 | M25: =M24+K25-L25 -> 1769630.7
A26: 23 | B26: 46135 | G26: =E26*F26 -> 0 | K26: =G26+J26 -> 0 | L26: 0 | M26: =M25+K26-L26 -> 1769630.7
A27: 24 | B27: 46136 | G27: =E27*F27 -> 0 | K27: =G27+J27 -> 0 | L27: 0 | M27: =M26+K27-L27 -> 1769630.7
A28: 25 | B28: 46137 | G28: =E28*F28 -> 0 | K28: =G28+J28 -> 0 | L28: 0 | M28: =M27+K28-L28 -> 1769630.7
A29: 26 | B29: 46138 | G29: =E29*F29 -> 0 | K29: =G29+J29 -> 0 | L29: 0 | M29: =M28+K29-L29 -> 1769630.7
A30: 27 | B30: 46139 | E30: 2000 | F30: 95.68 | G30: =E30*F30 -> 191360 | K30: =G30+J30 -> 191360 | L30: 267904 | M30: =M29+K30-L30 -> 1693086.7
A31: 28 | B31: 46140 | E31: 2000 | F31: 95.68 | G31: =E31*F31 -> 191360 | K31: =G31+J31 -> 191360 | L31: 114816 | M31: =M30+K31-L31 -> 1769630.7
A32: 29 | B32: 46141 | E32: 2000 | F32: 95.68 | G32: =E32*F32 -> 191360 | K32: =G32+J32 -> 191360 | L32: =H32+K32 -> 191360 | M32: =M31+K32-L32 -> 1769630.7
A33: 30 | B33: 46142 | E33: 2500 | F33: 95.68 | G33: =E33*F33 -> 239200 | K33: =G33+J33 -> 239200 | L33: =H33+K33 -> 239200 | M33: =M32+K33-L33 -> 1769630.7
A34: 31 | G34: =E34*F34 -> 0 | K34: =G34+J34 -> 0 | L34: 0 | M34: =M33+K34-L34 -> 1769630.7
A35: 32 | G35: =E35*F35 -> 0 | J35: =H35*I35 -> 0 | K35: =G35+J35 -> 0 | L35: 0 | M35: =M34+K35-L35 -> 1769630.7
A36: 33 | G36: =E36*F36 -> 0 | J36: =H36*I36 -> 0 | K36: =G36+J36 -> 0 | L36: 0
A37: 34 | G37: =E37*F37 -> 0 | J37: =H37*I37 -> 0 | K37: =G37+J37 -> 0
E38: =SUM(E3:E37) -> 26600.49 | G38: =SUM(G3:G37) -> 2545134.9 | H38: =SUM(H3:H37) -> 351.49 | J38: =SUM(J3:J37) -> 37771.115 | K38: =SUM(K4:K37) -> 2582906 | L38: =SUM(L3:L37) -> 4989687

Sheet Khammam-2
A1: Jayasai union bunk
A2: S.No | B2: Date | C2: GRN No | D2: Ind No/Bill No | E2: Diesel (Lts) | F2: Price | G2: Amount | H2: Petrol (Lts) | I2: Price | J2: Amount | K2: Total amount | L2: Amount paid | M2: As 0n Date | N2: Remarks
A3: Opening Balance | K3: 8032637.3 | M3: 8032637.3
A4: 1 | B4: 46113 | G4: =E4*F4 -> 0 | J4: =H4*I4 -> 0 | K4: =G4+J4 -> 0 | M4: =M3+K4-L4 -> 8032637.3 | O4: =O3+M4-N4 -> 8032637.3
A5: 2 | B5: 46114 | E5: 2800 | F5: 95.71 | G5: =E5*F5 -> 267988 | H5: 80 | I5: 107.49 | J5: =H5*I5 -> 8599.2 | K5: =G5+J5 -> 276587.2 | L5: 8032614 | M5: =M4+K5-L5 -> 276610.5
A6: 3 | B6: 46115 | E6: 2800 | F6: 95.71 | G6: =E6*F6 -> 267988 | H6: 20 | I6: 107.49 | J6: =H6*I6 -> 2149.8 | K6: =G6+J6 -> 270137.8 | M6: =M5+K6-L6 -> 546748.3
A7: 4 | B7: 46116 | G7: =E7*F7 -> 0 | J7: =H7*I7 -> 0 | K7: =G7+J7 -> 0 | M7: =M6+K7-L7 -> 546748.3
A8: 5 | B8: 46117 | G8: =E8*F8 -> 0 | J8: =H8*I8 -> 0 | K8: =G8+J8 -> 0 | M8: =M7+K8-L8 -> 546748.3 | O8: 12802499
A9: 6 | B9: 46118 | G9: =E9*F9 -> 0 | J9: =H9*I9 -> 0 | K9: =G9+J9 -> 0 | M9: =M8+K9-L9 -> 546748.3
A10: 7 | B10: 46119 | G10: =E10*F10 -> 0 | J10: =H10*I10 -> 0 | K10: =G10+J10 -> 0 | M10: =M9+K10-L10 -> 546748.3
A11: 8 | B11: 46120 | G11: =E11*F11 -> 0 | J11: =H11*I11 -> 0 | K11: =G11+J11 -> 0 | M11: =M10+K11-L11 -> 546748.3
A12: 9 | B12: 46121 | G12: =E12*F12 -> 0 | J12: =H12*I12 -> 0 | K12: =G12+J12 -> 0 | M12: =M11+K12-L12 -> 546748.3
A13: 10 | B13: 46122 | G13: =E13*F13 -> 0 | J13: =H13*I13 -> 0 | K13: =G13+J13 -> 0 | M13: =M12+K13-L13 -> 546748.3
A14: 11 | B14: 46123 | E14: 4550 | F14: 95.71 | G14: =E14*F14 -> 435480.5 | H14: 40 | I14: 107.49 | J14: =H14*I14 -> 4299.6 | K14: =G14+J14 -> 439780.1 | M14: =M13+K14-L14 -> 986528.4
A15: 12 | B15: 46124 | G15: =E15*F15 -> 0 | J15: =H15*I15 -> 0 | K15: =G15+J15 -> 0 | M15: =M14+K15-L15 -> 986528.4
A16: 13 | B16: 46125 | G16: =E16*F16 -> 0 | J16: =H16*I16 -> 0 | K16: =G16+J16 -> 0 | M16: =M15+K16-L16 -> 986528.4
A17: 14 | B17: 46126 | E17: 2500 | F17: 95.71 | G17: =E17*F17 -> 239275 | H17: 20 | I17: 107.49 | J17: =H17*I17 -> 2149.8 | K17: =G17+J17 -> 241424.8 | M17: =M16+K17-L17 -> 1227953.2
A18: 15 | B18: 46127 | E18: 5500 | F18: 95.71 | G18: =E18*F18 -> 526405 | H18: 40 | I18: 107.49 | J18: =H18*I18 -> 4299.6 | K18: =G18+J18 -> 530704.6 | M18: =M17+K18-L18 -> 1758657.8
A19: 16 | B19: 46128 | E19: 1800 | F19: 95.71 | G19: =E19*F19 -> 172278 | H19: 40 | I19: 107.49 | J19: =H19*I19 -> 4299.6 | K19: =G19+J19 -> 176577.6 | M19: =M18+K19-L19 -> 1935235.4
A20: 17 | B20: 46129 | E20: 5600 | F20: 95.71 | G20: =E20*F20 -> 535976 | H20: 40 | I20: 107.49 | J20: =H20*I20 -> 4299.6 | K20: =G20+J20 -> 540275.6 | M20: =M19+K20-L20 -> 2475511
A21: 18 | B21: 46130 | E21: 2800 | F21: 95.71 | G21: =E21*F21 -> 267988 | I21: 107.49 | J21: =H21*I21 -> 0 | K21: =G21+J21 -> 267988 | M21: =M20+K21-L21 -> 2743499
A22: 19 | B22: 46131 | E22: 3900 | F22: 95.71 | G22: =E22*F22 -> 373269 | H22: 60 | I22: 107.49 | J22: =H22*I22 -> 6449.4 | K22: =G22+J22 -> 379718.4 | M22: =M21+K22-L22 -> 3123217.4
A23: 20 | B23: 46132 | E23: 4000 | F23: 95.71 | G23: =E23*F23 -> 382840 | H23: 20 | I23: 107.49 | J23: =H23*I23 -> 2149.8 | K23: =G23+J23 -> 384989.8 | M23: =M22+K23-L23 -> 3508207.2
A24: 21 | B24: 46133 | G24: =E24*F24 -> 0 | H24: 95 | I24: 107.49 | J24: =H24*I24 -> 10211.55 | K24: =G24+J24 -> 10211.55 | M24: =M23+K24-L24 -> 3518418.7
A25: 22 | B25: 46134 | G25: =E25*F25 -> 0 | J25: =H25*I25 -> 0 | K25: =G25+J25 -> 0 | M25: =M24+K25-L25 -> 3518418.7
A26: 23 | B26: 46135 | G26: =E26*F26 -> 0 | J26: =H26*I26 -> 0 | K26: =G26+J26 -> 0 | M26: =M25+K26-L26 -> 3518418.7
A27: 24 | B27: 46136 | E27: 525 | F27: 95.71 | G27: =E27*F27 -> 50247.75 | J27: =H27*I27 -> 0 | K27: =G27+J27 -> 50247.75 | L27: =H27+K27 -> 50247.75 | M27: =M26+K27-L27 -> 3518418.7
A28: 25 | B28: 46137 | E28: 731.37 | F28: 95.71 | G28: =E28*F28 -> 69999.423 | H28: 106 | I28: 107.49 | J28: =H28*I28 -> 11393.94 | K28: =G28+J28 -> 81393.363 | L28: 70000 | M28: =M27+K28-L28 -> 3529812.1
A29: 26 | B29: 46138 | G29: =E29*F29 -> 0 | J29: =H29*I29 -> 0 | K29: =G29+J29 -> 0 | M29: =M28+K29-L29 -> 3529812.1
A30: 27 | B30: 46139 | E30: 309.38 | F30: 95.71 | G30: =E30*F30 -> 29610.76 | J30: =H30*I30 -> 0 | K30: =G30+J30 -> 29610.76 | M30: =M29+K30-L30 -> 3559422.9
A31: 28 | B31: 46140 | E31: 200 | F31: 95.71 | G31: =E31*F31 -> 19142 | J31: =H31*I31 -> 0 | K31: =G31+J31 -> 19142 | M31: =M30+K31-L31 -> 3578564.9
A32: 29 | B32: 46141 | E32: 1536.81 | F32: 95.71 | G32: =E32*F32 -> 147088.09 | J32: =H32*I32 -> 0 | K32: =G32+J32 -> 147088.09 | M32: =M31+K32-L32 -> 3725653
A33: 30 | B33: 46142 | G33: =E33*F33 -> 0 | J33: =H33*I33 -> 0 | K33: =G33+J33 -> 0 | M33: =M32+K33-L33 -> 3725653
A34: 31 | G34: =E34*F34 -> 0 | J34: =H34*I34 -> 0 | K34: =G34+J34 -> 0 | M34: =M33+K34-L34 -> 3725653
E35: =SUM(E4:E34) -> 39552.56 | G35: =SUM(G4:G34) -> 3785575.5 | H35: =SUM(H4:H34) -> 561 | J35: =SUM(J4:J34) -> 60301.89 | K35: =SUM(K4:K34) -> 3845877.4 | L35: =SUM(L4:L34) -> 8152861.8

Sheet Khammam-3
A1: JSASFuel Genie India Pvt.Ltd
A2: S.No | B2: Date | C2: GRN No | D2: Ind No/Bill No | E2: Diesel (Lts) | F2: Price | G2: Amount | H2: Petrol (Lts) | I2: Price | J2: Amount | K2: Total amount | L2: Amount paid | M2: As 0n Date | N2: Remarks
A3: Opening Balance | K3: 8227903.3 | M3: 8227903.3
A4: 1 | B4: 46113 | E4: 6000 | F4: 95.2 | G4: =E4*F4 -> 571200 | J4: =H4*I4 -> 0 | K4: =G4+J4 -> 571200 | M4: =M3+K4-L4 -> 8799103.3
A5: 2 | B5: 46114 | G5: =E5*F5 -> 0 | J5: =H5*I5 -> 0 | K5: =G5+J5 -> 0 | M5: =M4+K5-L5 -> 8799103.3
A6: 3 | B6: 46115 | G6: =E6*F6 -> 0 | J6: =H6*I6 -> 0 | K6: =G6+J6 -> 0 | L6: 8227903 | M6: =M5+K6-L6 -> 571200.27
A7: 4 | B7: 46116 | E7: 6000 | F7: 95.2 | G7: =E7*F7 -> 571200 | J7: =H7*I7 -> 0 | K7: =G7+J7 -> 571200 | M7: =M6+K7-L7 -> 1142400.3
A8: 5 | B8: 46117 | G8: =E8*F8 -> 0 | J8: =H8*I8 -> 0 | K8: =G8+J8 -> 0 | M8: =M7+K8-L8 -> 1142400.3 | P8: 8227903
A9: 6 | B9: 46118 | E9: 6000 | F9: 95.2 | G9: =E9*F9 -> 571200 | J9: =H9*I9 -> 0 | K9: =G9+J9 -> 571200 | M9: =M8+K9-L9 -> 1713600.3 | P9: 188521.22
A10: 7 | B10: 46119 | E10: 6000 | F10: 95.2 | G10: =E10*F10 -> 571200 | J10: =H10*I10 -> 0 | K10: =G10+J10 -> 571200 | M10: =M9+K10-L10 -> 2284800.3 | P10: 2453209.4
A11: 8 | B11: 46120 | E11: 6000 | F11: 95.2 | G11: =E11*F11 -> 571200 | J11: =H11*I11 -> 0 | K11: =G11+J11 -> 571200 | M11: =M10+K11-L11 -> 2856000.3 | P11: =SUM(P8:P10) -> 10869634
A12: 9 | B12: 46121 | E12: 6000 | F12: 95.2 | G12: =E12*F12 -> 571200 | J12: =H12*I12 -> 0 | K12: =G12+J12 -> 571200 | M12: =M11+K12-L12 -> 3427200.3
A13: 10 | B13: 46122 | G13: =E13*F13 -> 0 | J13: =H13*I13 -> 0 | K13: =G13+J13 -> 0 | M13: =M12+K13-L13 -> 3427200.3
A14: 11 | B14: 46123 | G14: =E14*F14 -> 0 | J14: =H14*I14 -> 0 | K14: =G14+J14 -> 0 | L14: 2000000 | M14: =M13+K14-L14 -> 1427200.3
A15: 12 | B15: 46124 | E15: 6000 | F15: 95.2 | G15: =E15*F15 -> 571200 | J15: =H15*I15 -> 0 | K15: =G15+J15 -> 571200 | M15: =M14+K15-L15 -> 1998400.3
A16: 13 | B16: 46125 | G16: =E16*F16 -> 0 | J16: =H16*I16 -> 0 | K16: =G16+J16 -> 0 | M16: =M15+K16-L16 -> 1998400.3
A17: 14 | B17: 46126 | G17: =E17*F17 -> 0 | J17: =H17*I17 -> 0 | K17: =G17+J17 -> 0 | M17: =M16+K17-L17 -> 1998400.3
A18: 15 | B18: 46127 | G18: =E18*F18 -> 0 | J18: =H18*I18 -> 0 | K18: =G18+J18 -> 0 | M18: =M17+K18-L18 -> 1998400.3
A19: 16 | B19: 46128 | E19: 6000 | F19: 95.7 | G19: =E19*F19 -> 574200 | J19: =H19*I19 -> 0 | K19: =G19+J19 -> 574200 | M19: =M18+K19-L19 -> 2572600.3
A20: 17 | B20: 46129 | G20: =E20*F20 -> 0 | J20: =H20*I20 -> 0 | K20: =G20+J20 -> 0 | M20: =M19+K20-L20 -> 2572600.3
A21: 18 | B21: 46130 | G21: =E21*F21 -> 0 | J21: =H21*I21 -> 0 | K21: =G21+J21 -> 0 | M21: =M20+K21-L21 -> 2572600.3
A22: 19 | B22: 46131 | G22: =E22*F22 -> 0 | J22: =H22*I22 -> 0 | K22: =G22+J22 -> 0 | M22: =M21+K22-L22 -> 2572600.3
A23: 20 | B23: 46132 | G23: =E23*F23 -> 0 | J23: =H23*I23 -> 0 | K23: =G23+J23 -> 0 | M23: =M22+K23-L23 -> 2572600.3
A24: 21 | B24: 46133 | G24: =E24*F24 -> 0 | J24: =H24*I24 -> 0 | K24: =G24+J24 -> 0 | M24: =M23+K24-L24 -> 2572600.3
A25: 22 | B25: 46134 | G25: =E25*F25 -> 0 | J25: =H25*I25 -> 0 | K25: =G25+J25 -> 0 | M25: =M24+K25-L25 -> 2572600.3
A26: 23 | B26: 46135 | G26: =E26*F26 -> 0 | J26: =H26*I26 -> 0 | K26: =G26+J26 -> 0 | M26: =M25+K26-L26 -> 2572600.3
A27: 24 | B27: 46136 | G27: =E27*F27 -> 0 | J27: =H27*I27 -> 0 | K27: =G27+J27 -> 0 | M27: =M26+K27-L27 -> 2572600.3
A28: 25 | B28: 46137 | G28: =E28*F28 -> 0 | J28: =H28*I28 -> 0 | K28: =G28+J28 -> 0 | M28: =M27+K28-L28 -> 2572600.3
A29: 26 | B29: 46138 | G29: =E29*F29 -> 0 | J29: =H29*I29 -> 0 | K29: =G29+J29 -> 0 | M29: =M28+K29-L29 -> 2572600.3
A30: 27 | B30: 46139 | G30: =E30*F30 -> 0 | J30: =H30*I30 -> 0 | K30: =G30+J30 -> 0 | M30: =M29+K30-L30 -> 2572600.3
A31: 28 | B31: 46140 | G31: =E31*F31 -> 0 | J31: =H31*I31 -> 0 | K31: =G31+J31 -> 0 | M31: =M30+K31-L31 -> 2572600.3
... A33: 30 | B33: 46142 | G33: =E33*F33 -> 0 | J33: =H33*I33 -> 0 | K33: =G33+J33 -> 0 | M33: =M32+K33-L33 -> 2572600.3
A34: 31 | G34: =E34*F34 -> 0 | J34: =H34*I34 -> 0 | K34: =G34+J34 -> 0 | M34: =M33+K34-L34 -> 2572600.3
E35: =SUM(E4:E34) -> 48000 | G35: =SUM(G4:G34) -> 4572600 | H35: =SUM(H4:H34) -> 0 | J35: =SUM(J4:J34) -> 0 | K35: =SUM(K4:K34) -> 4572600 | L35: =SUM(L4:L34) -> 10227903

Sheet Khammam-4
A1: Vajra Mahalakshmi filling station
A2: S.No | B2: Date | C2: GRN No | D2: Ind No/Bill No | E2: Diesel (Lts) | F2: Price | G2: Amount | H2: Petrol (Lts) | I2: Price | J2: Amount | K2: Total amount | L2: Amount paid | M2: As 0n Date | N2: Remarks
A3: Opening Balance | K3: 330407.08 | M3: 330407.08
A4: 1 | B4: 46113 | G4: =E4*F4 -> 0 | K4: =G4+J4 -> 0 | L4: 0 | M4: =M3+K4-L4 -> 330407.08
A5: 2 | B5: 46114 | E5: 0 | F5: 0 | G5: =E5*F5 -> 0 | H5: 0 | I5: 0 | J5: =H5*I5 -> 0 | K5: =G5+J5 -> 0 | L5: 0 | M5: =M4+K5-L5 -> 330407.08
A6: 3 | B6: 46115 | E6: 0 | F6: 0 | G6: =E6*F6 -> 0 | H6: 0 | I6: 0 | J6: =H6*I6 -> 0 | K6: =G6+J6 -> 0 | L6: 330407 | M6: =M5+K6-L6 -> 0.08
A7: 4 | B7: 46116 | E7: 0 | F7: 0 | G7: =E7*F7 -> 0 | H7: 0 | I7: 0 | J7: =H7*I7 -> 0 | K7: =G7+J7 -> 0 | L7: 0 | M7: =M6+K7-L7 -> 0.08
A8: 5 | B8: 46117 | E8: 0 | F8: 0 | G8: =E8*F8 -> 0 | H8: 0 | I8: 0 | J8: =H8*I8 -> 0 | K8: =G8+J8 -> 0 | L8: 0 | M8: =M7+K8-L8 -> 0.08
A9: 6 | B9: 46118 | E9: 0 | F9: 0 | G9: =E9*F9 -> 0 | H9: 0 | I9: 0 | J9: =H9*I9 -> 0 | K9: =G9+J9 -> 0 | L9: 0 | M9: =M8+K9-L9 -> 0.08
A10: 7 | B10: 46119 | E10: 0 | F10: 0 | G10: =E10*F10 -> 0 | H10: 0 | I10: 0 | J10: =H10*I10 -> 0 | K10: =G10+J10 -> 0 | L10: 0 | M10: =M9+K10-L10 -> 0.08
A11: 8 | B11: 46120 | E11: 0 | F11: 0 | G11: =E11*F11 -> 0 | H11: 0 | I11: 0 | J11: =H11*I11 -> 0 | K11: =G11+J11 -> 0 | L11: 0 | M11: =M10+K11-L11 -> 0.08
A12: 9 | B12: 46121 | E12: 0 | F12: 0 | G12: =E12*F12 -> 0 | H12: 0 | I12: 0 | J12: =H12*I12 -> 0 | K12: =G12+J12 -> 0 | L12: 0 | M12: =M11+K12-L12 -> 0.08
A13: 10 | B13: 46122 | E13: 0 | F13: 0 | G13: =E13*F13 -> 0 | H13: 0 | I13: 0 | J13: =H13*I13 -> 0 | K13: =G13+J13 -> 0 | L13: 0 | M13: =M12+K13-L13 -> 0.08
A14: 11 | B14: 46123 | E14: 0 | F14: 0 | G14: =E14*F14 -> 0 | H14: 0 | I14: 0 | J14: =H14*I14 -> 0 | K14: =G14+J14 -> 0 | L14: 0 | M14: =M13+K14-L14 -> 0.08
A15: 12 | B15: 46124 | E15: 0 | F15: 0 | G15: =E15*F15 -> 0 | H15: 0 | I15: 0 | J15: =H15*I15 -> 0 | K15: =G15+J15 -> 0 | L15: 0 | M15: =M14+K15-L15 -> 0.08
A16: 13 | B16: 46125 | E16: 0 | F16: 0 | G16: =E16*F16 -> 0 | H16: 0 | I16: 0 | J16: =H16*I16 -> 0 | K16: =G16+J16 -> 0 | L16: 0 | M16: =M15+K16-L16 -> 0.08
... A19: 16 | B19: 46128 | E19: 0 | F19: 0 | G19: =E19*F19 -> 0 | H19: 0 | I19: 0 | J19: =H19*I19 -> 0 | K19: =G19+J19 -> 0 | L19: 0 | M19: =M18+K19-L19 -> 0.08
A20: 17 | B20: 46129 | G20: =E20*F20 -> 0 | J20: =H20*I20 -> 0 | K20: =G20+J20 -> 0 | L20: 0 | M20: =M19+K20-L20 -> 0.08
A21: 18 | B21: 46130 | G21: =E21*F21 -> 0 | J21: =H21*I21 -> 0 | K21: =G21+J21 -> 0 | L21: 0 | M21: =M20+K21-L21 -> 0.08
A22: 19 | B22: 46131 | G22: =E22*F22 -> 0 | J22: =H22*I22 -> 0 | K22: =G22+J22 -> 0 | L22: 0 | M22: =M21+K22-L22 -> 0.08
A23: 20 | B23: 46132 | G23: =E23*F23 -> 0 | J23: =H23*I23 -> 0 | K23: =G23+J23 -> 0 | L23: 0 | M23: =M22+K23-L23 -> 0.08
A24: 21 | B24: 46133 | G24: =E24*F24 -> 0 | J24: =H24*I24 -> 0 | K24: =G24+J24 -> 0 | L24: 0 | M24: =M23+K24-L24 -> 0.08
A25: 22 | B25: 46134 | G25: =E25*F25 -> 0 | J25: =H25*I25 -> 0 | K25: =G25+J25 -> 0 | L25: 0 | M25: =M24+K25-L25 -> 0.08
A26: 23 | B26: 46135 | G26: =E26*F26 -> 0 | J26: =H26*I26 -> 0 | K26: =G26+J26 -> 0 | L26: 0 | M26: =M25+K26-L26 -> 0.08
A27: 24 | B27: 46136 | G27: =E27*F27 -> 0 | J27: =H27*I27 -> 0 | K27: =G27+J27 -> 0 | L27: 0 | M27: =M26+K27-L27 -> 0.08
A28: 25 | B28: 46137 | G28: =E28*F28 -> 0 | J28: =H28*I28 -> 0 | K28: =G28+J28 -> 0 | L28: 0 | M28: =M27+K28-L28 -> 0.08
A29: 26 | B29: 46138 | G29: =E29*F29 -> 0 | J29: =H29*I29 -> 0 | K29: =G29+J29 -> 0 | L29: 0 | M29: =M28+K29-L29 -> 0.08
A30: 27 | B30: 46139 | G30: =E30*F30 -> 0 | J30: =H30*I30 -> 0 | K30: =G30+J30 -> 0 | L30: 0 | M30: =M29+K30-L30 -> 0.08
A31: 28 | B31: 46140 | G31: =E31*F31 -> 0 | J31: =H31*I31 -> 0 | K31: =G31+J31 -> 0 | L31: 0 | M31: =M30+K31-L31 -> 0.08
... A33: 30 | B33: 46142 | G33: =E33*F33 -> 0 | J33: =H33*I33 -> 0 | K33: =G33+J33 -> 0 | L33: 0 | M33: =M32+K33-L33 -> 0.08
A34: 31 | G34: =E34*F34 -> 0 | K34: =G34+J34 -> 0 | L34: 0 | M34: =M33+K34-L34 -> 0.08
A35: 32 | G35: =E35*F35 -> 0 | J35: =H35*I35 -> 0 | K35: =G35+J35 -> 0 | L35: 0 | M35: =M34+K35-L35 -> 0.08
A36: 33 | G36: =E36*F36 -> 0 | J36: =H36*I36 -> 0 | K36: =G36+J36 -> 0 | L36: 0
A37: 34 | G37: =E37*F37 -> 0 | J37: =H37*I37 -> 0 | K37: =G37+J37 -> 0
E38: =SUM(E3:E37) -> 0 | G38: =SUM(G3:G37) -> 0 | H38: =SUM(H3:H37) -> 0 | J38: =SUM(J3:J37) -> 0 | K38: =SUM(K4:K37) -> 0 | L38: =SUM(L3:L37) -> 330407

Sheet Khammam-5
A1: SR HP Filling Station ( Dhamsalapuram)
A2: S.No | B2: Date | C2: GRN No | D2: Ind No/Bill No | E2: Diesel (Lts) | F2: Price | G2: Amount | H2: Petrol (Lts) | I2: Price | J2: Amount | K2: Total amount | L2: Amount paid | M2: As 0n Date | N2: Remarks
A3: Opening Balance | K3: 0 | M3: 0
A4: 1 | B4: 46113 | G4: =E4*F4 -> 0 | K4: =G4+J4 -> 0 | L4: 0 | M4: =M3+K4-L4 -> 0
A5: 2 | B5: 46114 | G5: =E5*F5 -> 0 | J5: =H5*I5 -> 0 | K5: =G5+J5 -> 0 | L5: 0 | M5: =M4+K5-L5 -> 0
A6: 3 | B6: 46115 | G6: =E6*F6 -> 0 | J6: =H6*I6 -> 0 | K6: =G6+J6 -> 0 | L6: 0 | M6: =M5+K6-L6 -> 0
A7: 4 | B7: 46116 | G7: =E7*F7 -> 0 | J7: =H7*I7 -> 0 | K7: =G7+J7 -> 0 | L7: 0 | M7: =M6+K7-L7 -> 0
A8: 5 | B8: 46117 | G8: =E8*F8 -> 0 | J8: =H8*I8 -> 0 | K8: =G8+J8 -> 0 | L8: 0 | M8: =M7+K8-L8 -> 0
A9: 6 | B9: 46118 | G9: =E9*F9 -> 0 | J9: =H9*I9 -> 0 | K9: =G9+J9 -> 0 | L9: 0 | M9: =M8+K9-L9 -> 0
A10: 7 | B10: 46119 | G10: =E10*F10 -> 0 | J10: =H10*I10 -> 0 | K10: =G10+J10 -> 0 | L10: 0 | M10: =M9+K10-L10 -> 0
A11: 8 | B11: 46120 | G11: =E11*F11 -> 0 | J11: =H11*I11 -> 0 | K11: =G11+J11 -> 0 | L11: 0 | M11: =M10+K11-L11 -> 0
A12: 9 | B12: 46121 | G12: =E12*F12 -> 0 | J12: =H12*I12 -> 0 | K12: =G12+J12 -> 0 | L12: 0 | M12: =M11+K12-L12 -> 0
A13: 10 | B13: 46122 | G13: =E13*F13 -> 0 | J13: =H13*I13 -> 0 | K13: =G13+J13 -> 0 | L13: 0 | M13: =M12+K13-L13 -> 0
A14: 11 | B14: 46123 | G14: =E14*F14 -> 0 | J14: =H14*I14 -> 0 | K14: =G14+J14 -> 0 | L14: 0 | M14: =M13+K14-L14 -> 0
A15: 12 | B15: 46124 | G15: =E15*F15 -> 0 | J15: =H15*I15 -> 0 | K15: =G15+J15 -> 0 | L15: 0 | M15: =M14+K15-L15 -> 0
A16: 13 | B16: 46125 | G16: =E16*F16 -> 0 | J16: =H16*I16 -> 0 | K16: =G16+J16 -> 0 | L16: 0 | M16: =M15+K16-L16 -> 0
A17: 14 | B17: 46126 | G17: =E17*F17 -> 0 | J17: =H17*I17 -> 0 | K17: =G17+J17 -> 0 | L17: 0 | M17: =M16+K17-L17 -> 0 | U17: 257315
A18: 15 | B18: 46127 | G18: =E18*F18 -> 0 | J18: =H18*I18 -> 0 | K18: =G18+J18 -> 0 | L18: 0 | M18: =M17+K18-L18 -> 0 | U18: 22996
A19: 16 | B19: 46128 | G19: =E19*F19 -> 0 | J19: =H19*I19 -> 0 | K19: =G19+J19 -> 0 | L19: 0 | M19: =M18+K19-L19 -> 0 | U19: =U17+U18 -> 280311
A20: 17 | B20: 46129 | G20: =E20*F20 -> 0 | J20: =H20*I20 -> 0 | K20: =G20+J20 -> 0 | L20: 0 | M20: =M19+K20-L20 -> 0 | U20: =U19-183340 -> 96971
A21: 18 | B21: 46130 | G21: =E21*F21 -> 0 | J21: =H21*I21 -> 0 | K21: =G21+J21 -> 0 | L21: 0 | M21: =M20+K21-L21 -> 0
A22: 19 | B22: 46131 | G22: =E22*F22 -> 0 | J22: =H22*I22 -> 0 | K22: =G22+J22 -> 0 | L22: 0 | M22: =M21+K22-L22 -> 0 | R22: 91.67
A23: 20 | B23: 46132 | G23: =E23*F23 -> 0 | J23: =H23*I23 -> 0 | K23: =G23+J23 -> 0 | L23: 0 | M23: =M22+K23-L23 -> 0 | R23: 2000 | U23: 197391.46
A24: 21 | B24: 46133 | E24: 3135.46 | F24: 95.68 | G24: =E24*F24 -> 300000.81 | J24: =H24*I24 -> 0 | K24: =G24+J24 -> 300000.81 | L24: =H24+K24 -> 300000.81 | M24: =M23+K24-L24 -> 0 | R24: =R23*R22 -> 183340
A25: 22 | B25: 46134 | G25: =E25*F25 -> 0 | J25: =H25*I25 -> 0 | K25: =G25+J25 -> 0 | L25: 0 | M25: =M24+K25-L25 -> 0
A26: 23 | B26: 46135 | G26: =E26*F26 -> 0 | J26: =H26*I26 -> 0 | K26: =G26+J26 -> 0 | L26: 0 | M26: =M25+K26-L26 -> 0
A27: 24 | B27: 46136 | G27: =E27*F27 -> 0 | J27: =H27*I27 -> 0 | K27: =G27+J27 -> 0 | L27: 0 | M27: =M26+K27-L27 -> 0
A28: 25 | B28: 46137 | G28: =E28*F28 -> 0 | J28: =H28*I28 -> 0 | K28: =G28+J28 -> 0 | L28: 0 | M28: =M27+K28-L28 -> 0
A29: 26 | B29: 46138 | G29: =E29*F29 -> 0 | J29: =H29*I29 -> 0 | K29: =G29+J29 -> 0 | L29: 0 | M29: =M28+K29-L29 -> 0
A30: 27 | B30: 46139 | G30: =E30*F30 -> 0 | J30: =H30*I30 -> 0 | K30: =G30+J30 -> 0 | L30: 0 | M30: =M29+K30-L30 -> 0
A31: 28 | B31: 46140 | G31: =E31*F31 -> 0 | J31: =H31*I31 -> 0 | K31: =G31+J31 -> 0 | L31: 0 | M31: =M30+K31-L31 -> 0
A32: 29 | B32: 46141 | G32: =E32*F32 -> 0 | J32: =H32*I32 -> 0 | K32: =G32+J32 -> 0 | L32: 0 | M32: =M31+K32-L32 -> 0
A33: 30 | B33: 46142 | G33: =E33*F33 -> 0 | J33: =H33*I33 -> 0 | K33: =G33+J33 -> 0 | L33: 0 | M33: =M32+K33-L33 -> 0
A34: 31 | G34: =E34*F34 -> 0 | K34: =G34+J34 -> 0 | L34: 0 | M34: =M33+K34-L34 -> 0
A35: 32 | G35: =E35*F35 -> 0 | J35: =H35*I35 -> 0 | K35: =G35+J35 -> 0 | L35: 0 | M35: =M34+K35-L35 -> 0
A36: 33 | G36: =E36*F36 -> 0 | J36: =H36*I36 -> 0 | K36: =G36+J36 -> 0 | L36: 0
A37: 34 | G37: =E37*F37 -> 0 | J37: =H37*I37 -> 0 | K37: =G37+J37 -> 0
E38: =SUM(E3:E37) -> 3135.46 | G38: =SUM(G3:G37) -> 300000.81 | H38: =SUM(H3:H37) -> 0 | J38: =SUM(J3:J37) -> 0 | K38: =SUM(K4:K37) -> 300000.81 | L38: =SUM(L3:L37) -> 300000.81

Sheet  Khammam&Cash
A1: Cash &Carry
A2: S.No | B2: Date | D2: Ind No/Bill No | E2: Diesel (Lts) | F2: Price | G2: Amount | H2: Petrol (Lts) | I2: Price | J2: Amount | K2: Total amount | L2: Amount paid | M2: As 0n Date | N2: Remarks
A3: Opening Balance | K3: 0 | M3: 0
A4: 1 | G4: =E4*F4 -> 0 | K4: =G4+J4 -> 0 | L4: 0 | M4: =M3+K4-L4 -> 0
A5: 2 | G5: =E5*F5 -> 0 | J5: =H5*I5 -> 0 | K5: =G5+J5 -> 0 | L5: 0 | M5: =M4+K5-L5 -> 0
A6: 3 | G6: =E6*F6 -> 0 | J6: =H6*I6 -> 0 | K6: =G6+J6 -> 0 | L6: 0 | M6: =M5+K6-L6 -> 0
A7: 4 | G7: =E7*F7 -> 0 | J7: =H7*I7 -> 0 | K7: =G7+J7 -> 0 | L7: 0 | M7: =M6+K7-L7 -> 0
A8: 5 | G8: =E8*F8 -> 0 | J8: =H8*I8 -> 0 | K8: =G8+J8 -> 0 | L8: 0 | M8: =M7+K8-L8 -> 0
A9: 6 | G9: =E9*F9 -> 0 | J9: =H9*I9 -> 0 | K9: =G9+J9 -> 0 | L9: 0 | M9: =M8+K9-L9 -> 0
A10: 7 | G10: =E10*F10 -> 0 | J10: =H10*I10 -> 0 | K10: =G10+J10 -> 0 | L10: 0 | M10: =M9+K10-L10 -> 0
A11: 8 | G11: =E11*F11 -> 0 | J11: =H11*I11 -> 0 | K11: =G11+J11 -> 0 | L11: 0 | M11: =M10+K11-L11 -> 0
A12: 9 | G12: =E12*F12 -> 0 | J12: =H12*I12 -> 0 | K12: =G12+J12 -> 0 | L12: 0 | M12: =M11+K12-L12 -> 0
A13: 10 | G13: =E13*F13 -> 0 | J13: =H13*I13 -> 0 | K13: =G13+J13 -> 0 | L13: 0 | M13: =M12+K13-L13 -> 0
A14: 11 | G14: =E14*F14 -> 0 | J14: =H14*I14 -> 0 | K14: =G14+J14 -> 0 | L14: 0 | M14: =M13+K14-L14 -> 0
A15: 12 | G15: =E15*F15 -> 0 | J15: =H15*I15 -> 0 | K15: =G15+J15 -> 0 | L15: 0 | M15: =M14+K15-L15 -> 0
A16: 13 | G16: =E16*F16 -> 0 | J16: =H16*I16 -> 0 | K16: =G16+J16 -> 0 | L16: 0 | M16: =M15+K16-L16 -> 0
... A23: 20 | G23: =E23*F23 -> 0 | J23: =H23*I23 -> 0 | K23: =G23+J23 -> 0 | L23: 0 | M23: =M22+K23-L23 -> 0
A24: 21 | G24: =E24*F24 -> 0 | J24: =H24*I24 -> 0 | K24: =G24+J24 -> 0 | L24: =H24+K24 -> 0 | M24: =M23+K24-L24 -> 0
A25: 22 | B25: 22.04.2026 | C25: My Nation Gas Station (Superintendent) | E25: 2900 | F25: 95.71 | G25: =E25*F25 -> 277559 | J25: =H25*I25 -> 0 | K25: =G25+J25 -> 277559 | L25: =H25+K25 -> 277559 | M25: =M24+K25-L25 -> 0 | N25: Cash
A26: 23 | B26: 23.04.2026 | C26: Perumalla Filling Station | E26: 2800 | F26: 95.68 | G26: =E26*F26 -> 267904 | J26: =H26*I26 -> 0 | K26: =G26+J26 -> 267904 | L26: =H26+K26 -> 267904 | M26: =M25+K26-L26 -> 0 | N26: HPCL
A27: 24 | B27: 23.04.2026 | C27: Jai Sreeram Filling Station | E27: 2200 | F27: 95.72 | G27: =E27*F27 -> 210584 | K27: =G27+J27 -> 210584 | L27: =H27+K27 -> 210584 | M27: =M26+K27-L27 -> 0 | N27: Cash
A28: 25 | B28: 23.04.2026 | C28: Sri Sri Sri Filling Station | E28: =170+170+80+80 -> 500 | F28: 95.68 | G28: =E28*F28 -> 47840 | J28: =H28*I28 -> 0 | K28: =G28+J28 -> 47840 | L28: =H28+K28 -> 47840 | M28: =M26+K28-L28 -> 0 | N28: HPCL
A29: 26 | B29: 24.04.2026 | C29: Perumalla Filling Station | E29: 900 | F29: 95.68 | G29: =E29*F29 -> 86112 | J29: =H29*I29 -> 0 | K29: =G29+J29 -> 86112 | L29: =H29+K29 -> 86112 | M29: =M28+K29-L29 -> 0 | N29: HPCL | O29: 354016 paid to dted 24.04.2026
A30: 27 | B30: 24.04.2026 | C30: SR HP Filling Station | E30: 2700 | F30: 95.68 | G30: =E30*F30 -> 258336 | J30: =H30*I30 -> 0 | K30: =G30+J30 -> 258336 | L30: =H30+K30 -> 258336 | M30: =M29+K30-L30 -> 0 | N30: HPCL
A31: 28 | B31: 25.04.2026 | C31: Perumalla Filling Station | E31: 2200 | F31: 95.68 | G31: =E31*F31 -> 210496 | J31: =H31*I31 -> 0 | K31: =G31+J31 -> 210496 | L31: =H31+K31 -> 210496 | M31: =M30+K31-L31 -> 0 | N31: HPCL
A32: 29 | B32: 27.04.2026 | C32: Perumalla Filling Station | E32: 400 | F32: 95.68 | G32: =E32*F32 -> 38272 | J32: =H32*I32 -> 0 | K32: =G32+J32 -> 38272 | L32: =H32+K32 -> 38272 | M32: =M31+K32-L32 -> 0 | N32: HPCL
A33: 30 | B33: 27.04.2026 | C33: Laxmi manikanta filling station | E33: 229.85 | F33: 95.72 | G33: =E33*F33 -> 22001.242 | J33: =H33*I33 -> 0 | K33: =G33+J33 -> 22001.242 | L33: 22001.24 | M33: =M32+K33-L33 -> 0.002 | N33: Cash
A34: 31 | B34: 28.04.2026 | C34: Sri Sri Sri Filling Station ( HP ) | E34: 200 | F34: 95.68 | G34: =E34*F34 -> 19136 | H34: 95 | I34: 107.46 | J34: =H34*I34 -> 10208.7 | K34: =G34+J34 -> 29344.7 | L34: 29344.7 | M34: =M33+K34-L34 -> 0.002 | N34: HPCL
A35: 32 | B35: 28.04.2026 | C35: Quality Service Station ( IOCL) | E35: 570 | F35: 95.71 | G35: =E35*F35 -> 54554.7 | K35: =G35+J35 -> 54554.7 | L35: =H35+K35 -> 54554.7 | M35: =M34+K35-L35 -> 0.002 | N35: Cash
A36: 33 | B36: 28.04.2026 | C36: Laxmi manikanta filling station (BPCL) | E36: 679.11 | F36: 95.72 | G36: =E36*F36 -> 65004.409 | J36: =H36*I36 -> 0 | K36: =G36+J36 -> 65004.409 | L36: =H36+K36 -> 65004.409 | M36: =M35+K36-L36 -> 0.002 | N36: Cash
A37: 34 | B37: 29.04.2026 | C37: Sri Sri Sri Filling Station ( HP ) | E37: 1000 | F37: 95.68 | G37: =E37*F37 -> 95680 | J37: =H37*I37 -> 0 | K37: =G37+J37 -> 95680 | L37: =H37+K37 -> 95680 | M37: =M36+K37-L37 -> 0.002 | N37: HPCL
A38: 35 | B38: 29.04.2026 | C38: Perumalla Filling Station | E38: 200 | F38: 95.68 | G38: =E38*F38 -> 19136 | K38: =G38+J38 -> 19136 | L38: =H38+K38 -> 19136 | M38: =M37+K38-L38 -> 0.002 | N38: HPCL
A39: 36 | B39: 29.04.2026 | C39: Stambhadri Fuel Park | E39: 1813.56 | F39: 95.68 | G39: =E39*F39 -> 173521.42 | K39: =G39+J39 -> 173521.42 | L39: =H39+K39 -> 173521.42 | M39: =M38+K39-L39 -> 0.002 | N39: HPCL
A40: 37 | B40: 29.04.2026 | C40: Laxmi manikanta filling station (BPCL) | E40: 365.68 | F40: 95.72 | G40: =E40*F40 -> 35002.89 | K40: =G40+J40 -> 35002.89 | L40: =H40+K40 -> 35002.89 | M40: =M39+K40-L40 -> 0.002 | N40: Cash
A41: 38 | G41: =E41*F41 -> 0 | K41: =G41+J41 -> 0 | L41: =H41+K41 -> 0 | M41: =M40+K41-L41 -> 0.002
A42: 39 | B42: 30.04.2026 | C42: Stambhadri Fuel Park | E42: 1250 | F42: 95.68 | G42: =E42*F42 -> 119600 | K42: =G42+J42 -> 119600 | L42: =H42+K42 -> 119600 | M42: =M41+K42-L42 -> 0.002 | N42: HPCL
A43: 40 | B43: 30.04.2026 | C43: Jai Sreeram Filling Station BPCL | E43: 2800 | F43: 95.72 | G43: =E43*F43 -> 268016 | K43: =G43+J43 -> 268016 | L43: =H43+K43 -> 268016 | M43: =M42+K43-L43 -> 0.002 | N43: Cash
A44: 41 | B44: 30.04.2026 | C44: Laxmi manikanta filling station (BPCL) | E44: 1149.28 | F44: 95.72 | G44: =E44*F44 -> 110009.08 | K44: =G44+J44 -> 110009.08 | L44: =H44+K44 -> 110009.08 | M44: =M43+K44-L44 -> 0.002 | N44: Cash
A45: 42 | G45: =E45*F45 -> 0 | J45: =H45*I45 -> 0 | K45: =G45+J45 -> 0
E46: =SUM(E3:E45) -> 24857.48 | G46: =SUM(G3:G45) -> 2378764.7 | H46: =SUM(H3:H45) -> 95 | J46: =SUM(J3:J45) -> 10208.7 | K46: =SUM(K4:K45) -> 2388973.4 | L46: =SUM(L3:L45) -> 2388973.4

Sheet  Jadcherla
A1: Sai baba F/S
A2: S.No | B2: Date | C2: GRN No | D2: Ind No/Bill No | E2: Diesel (Lts) | F2: Price | G2: Amount | H2: Petrol (Lts) | I2: Price | J2: Amount | K2: Total amount | L2: Amount paid | M2: As on date | N2: Remarks
A3: Opening Balance | M3: 0
A4: 1 | B4: 46113 | G4: =E4*F4 -> 0 | J4: =H4*I4 -> 0 | K4: =G4+J4 -> 0 | L4: 0 | M4: =M3+K4-L4 -> 0
A5: 2 | B5: 46114 | G5: =E5*F5 -> 0 | J5: =H5*I5 -> 0 | K5: =G5+J5 -> 0 | L5: 0 | M5: =M4+K5-L5 -> 0
A6: 3 | B6: 46115 | G6: =E6*F6 -> 0 | J6: =H6*I6 -> 0 | K6: =G6+J6 -> 0 | L6: 0 | M6: =M5+K6-L6 -> 0
A7: 4 | B7: 46116 | G7: =E7*F7 -> 0 | J7: =H7*I7 -> 0 | K7: =G7+J7 -> 0 | L7: 0 | M7: =M6+K7-L7 -> 0
A8: 5 | B8: 46117 | G8: =E8*F8 -> 0 | J8: =H8*I8 -> 0 | K8: =G8+J8 -> 0 | L8: 0 | M8: =M7+K8-L8 -> 0
A9: 6 | B9: 46118 | G9: =E9*F9 -> 0 | J9: =H9*I9 -> 0 | K9: =G9+J9 -> 0 | L9: 0 | M9: =M8+K9-L9 -> 0
A10: 7 | B10: 46119 | G10: =E10*F10 -> 0 | J10: =H10*I10 -> 0 | K10: =G10+J10 -> 0 | L10: 0 | M10: =M9+K10-L10 -> 0
A11: 8 | B11: 46120 | G11: =E11*F11 -> 0 | J11: =H11*I11 -> 0 | K11: =G11+J11 -> 0 | L11: 0 | M11: =M10+K11-L11 -> 0
A12: 9 | B12: 46121 | G12: =E12*F12 -> 0 | J12: =H12*I12 -> 0 | K12: =G12+J12 -> 0 | L12: 0 | M12: =M11+K12-L12 -> 0
A13: 10 | B13: 46122 | G13: =E13*F13 -> 0 | J13: =H13*I13 -> 0 | K13: =G13+J13 -> 0 | L13: 0 | M13: =M12+K13-L13 -> 0
A14: 11 | B14: 46123 | G14: =E14*F14 -> 0 | J14: =H14*I14 -> 0 | K14: =G14+J14 -> 0 | L14: 0 | M14: =M13+K14-L14 -> 0
A15: 12 | B15: 46124 | G15: =E15*F15 -> 0 | J15: =H15*I15 -> 0 | K15: =G15+J15 -> 0 | L15: =H15+K15 -> 0 | M15: =M14+K15-L15 -> 0
A16: 13 | B16: 46125 | G16: =E16*F16 -> 0 | J16: =H16*I16 -> 0 | K16: =G16+J16 -> 0 | L16: 0 | M16: =M15+K16-L16 -> 0
A17: 14 | B17: 46126 | G17: =E17*F17 -> 0 | J17: =H17*I17 -> 0 | K17: =G17+J17 -> 0 | L17: 0 | M17: =M16+K17-L17 -> 0
A18: 15 | B18: 46127 | G18: =E18*F18 -> 0 | J18: =H18*I18 -> 0 | K18: =G18+J18 -> 0 | L18: 0 | M18: =M17+K18-L18 -> 0
A19: 16 | B19: 46128 | G19: =E19*F19 -> 0 | J19: =H19*I19 -> 0 | K19: =G19+J19 -> 0 | L19: 0 | M19: =M18+K19-L19 -> 0
A20: 17 | B20: 46129 | G20: =E20*F20 -> 0 | J20: =H20*I20 -> 0 | K20: =G20+J20 -> 0 | L20: 0 | M20: =M19+K20-L20 -> 0
A21: 18 | B21: 46130 | G21: =E21*F21 -> 0 | J21: =H21*I21 -> 0 | K21: =G21+J21 -> 0 | L21: 0 | M21: =M20+K21-L21 -> 0
A22: 19 | B22: 46131 | G22: =E22*F22 -> 0 | J22: =H22*I22 -> 0 | K22: =G22+J22 -> 0 | L22: 0 | M22: =M21+K22-L22 -> 0
A23: 20 | B23: 46132 | G23: =E23*F23 -> 0 | J23: =H23*I23 -> 0 | K23: =G23+J23 -> 0 | L23: 0 | M23: =M22+K23-L23 -> 0
A24: 21 | B24: 46133 | G24: =E24*F24 -> 0 | J24: =H24*I24 -> 0 | K24: =G24+J24 -> 0 | L24: 0 | M24: =M23+K24-L24 -> 0
A25: 22 | B25: 46134 | G25: =E25*F25 -> 0 | J25: =H25*I25 -> 0 | K25: =G25+J25 -> 0 | L25: 0 | M25: =M24+K25-L25 -> 0
A26: 23 | B26: 46135 | E26: 1500 | F26: 96.42 | G26: =E26*F26 -> 144630 | J26: =H26*I26 -> 0 | K26: =G26+J26 -> 144630 | L26: =H26+K26 -> 144630 | M26: =M25+K26-L26 -> 0
A27: 24 | B27: 46136 | G27: =E27*F27 -> 0 | J27: =H27*I27 -> 0 | K27: =G27+J27 -> 0 | L27: 0 | M27: =M26+K27-L27 -> 0
A28: 25 | B28: 46137 | G28: =E28*F28 -> 0 | J28: =H28*I28 -> 0 | K28: =G28+J28 -> 0 | L28: 0 | M28: =M27+K28-L28 -> 0
A29: 26 | B29: 46138 | G29: =E29*F29 -> 0 | J29: =H29*I29 -> 0 | K29: =G29+J29 -> 0 | L29: 0 | M29: =M28+K29-L29 -> 0
A30: 27 | B30: 46139 | G30: =E30*F30 -> 0 | J30: =H30*I30 -> 0 | K30: =G30+J30 -> 0 | L30: 0 | M30: =M29+K30-L30 -> 0
A31: 28 | B31: 46140 | G31: =E31*F31 -> 0 | J31: =H31*I31 -> 0 | K31: =G31+J31 -> 0 | L31: 0 | M31: =M30+K31-L31 -> 0
A32: 29 | B32: 46141 | G32: =E32*F32 -> 0 | J32: =H32*I32 -> 0 | K32: =G32+J32 -> 0 | L32: 0 | M32: =M31+K32-L32 -> 0
A33: 30 | B33: 46142 | E33: 1500 | F33: 96.42 | G33: =E33*F33 -> 144630 | H33: 0 | I33: 0 | J33: =H33*I33 -> 0 | K33: =G33+J33 -> 144630 | L33: 100000 | M33: =M32+K33-L33 -> 44630
A34: 31 | B34: 46143 | G34: =E34*F34 -> 0 | J34: =H34*I34 -> 0 | K34: =G34+J34 -> 0 | M34: =M33+K34-L34 -> 44630
E35: =SUM(E4:E34) -> 3000 | G35: =SUM(G4:G34) -> 289260 | H35: =SUM(H4:H34) -> 0 | J35: =SUM(J4:J34) -> 0 | K35: =SUM(K4:K34) -> 289260 | L35: =SUM(L4:L34) -> 244630

Sheet Jadcherla-3
A1: JSASFuel Genie India Pvt.Ltd
A2: S.No | B2: Date | C2: GRN No | D2: Ind no/Bill No | E2: Diesel (Lts) | F2: Price | G2: Amount | H2: Petrol (Lts) | I2: Price | J2: Amount | K2: Total amount | L2: Amount paid | M2: As on Date | N2: Remarks
A3: Opening Balance | M3: 2453209.4
A4: 1 | B4: 46113 | G4: =E4*F4 -> 0 | J4: =H4*I4 -> 0 | K4: =G4+J4 -> 0 | L4: 0 | M4: =+M3+K4-L4 -> 2453209.4
A5: 2 | B5: 46114 | G5: =E5*F5 -> 0 | J5: =H5*I5 -> 0 | K5: =G5+J5 -> 0 | L5: 0 | M5: =+M4+K5-L5 -> 2453209.4
A6: 3 | B6: 46115 | G6: =E6*F6 -> 0 | J6: =H6*I6 -> 0 | K6: =G6+J6 -> 0 | L6: 2453209.4 | M6: =+M5+K6-L6 -> 0 | O6: 8032614 | P6: 2453209.4 | Q6: =SUM(O6:P6) -> 10485823
A7: 4 | B7: 46116 | E7: 990 | F7: 95.93 | G7: =E7*F7 -> 94970.7 | J7: =H7*I7 -> 0 | K7: =G7+J7 -> 94970.7 | L7: 0 | M7: =+M6+K7-L7 -> 94970.7
A8: 5 | B8: 46117 | G8: =E8*F8 -> 0 | J8: =H8*I8 -> 0 | K8: =G8+J8 -> 0 | L8: 0 | M8: =+M7+K8-L8 -> 94970.7
A9: 6 | B9: 46118 | G9: =E9*F9 -> 0 | J9: =H9*I9 -> 0 | K9: =G9+J9 -> 0 | L9: 0 | M9: =+M8+K9-L9 -> 94970.7
A10: 7 | B10: 46119 | E10: 1400 | F10: 95.93 | G10: =E10*F10 -> 134302 | J10: =H10*I10 -> 0 | K10: =G10+J10 -> 134302 | L10: 0 | M10: =+M9+K10-L10 -> 229272.7 | R10: 700
A11: 8 | B11: 46120 | G11: =E11*F11 -> 0 | J11: =H11*I11 -> 0 | K11: =G11+J11 -> 0 | L11: 0 | M11: =+M10+K11-L11 -> 229272.7 | S11: 5000
A12: 9 | B12: 46121 | G12: =E12*F12 -> 0 | J12: =H12*I12 -> 0 | K12: =G12+J12 -> 0 | L12: 0 | M12: =+M11+K12-L12 -> 229272.7 | S12: 1500
A13: 10 | B13: 46122 | G13: =E13*F13 -> 0 | J13: =H13*I13 -> 0 | K13: =G13+J13 -> 0 | L13: 0 | M13: =+M12+K13-L13 -> 229272.7 | S13: 500
A14: 11 | B14: 46123 | E14: 1800 | F14: 95.93 | G14: =E14*F14 -> 172674 | J14: =H14*I14 -> 0 | K14: =G14+J14 -> 172674 | L14: 0 | M14: =+M13+K14-L14 -> 401946.7
A15: 12 | B15: 46124 | E15: 2000 | F15: 95.93 | G15: =E15*F15 -> 191860 | J15: =H15*I15 -> 0 | K15: =G15+J15 -> 191860 | L15: 0 | M15: =+M14+K15-L15 -> 593806.7
A16: 13 | B16: 46125 | G16: =E16*F16 -> 0 | J16: =H16*I16 -> 0 | K16: =G16+J16 -> 0 | L16: 0 | M16: =+M15+K16-L16 -> 593806.7
A17: 14 | B17: 46126 | G17: =E17*F17 -> 0 | J17: =H17*I17 -> 0 | K17: =G17+J17 -> 0 | L17: 0 | M17: =+M16+K17-L17 -> 593806.7
A18: 15 | B18: 46127 | E18: 2000 | F18: 95.93 | G18: =E18*F18 -> 191860 | J18: =H18*I18 -> 0 | K18: =G18+J18 -> 191860 | L18: 0 | M18: =+M17+K18-L18 -> 785666.7
