Workbook

Sheet  MIs
A2: S.No | B2: NAme | C2: Lacation | D2: Card Number | E2: Card Number | F2: Category | G2: 1st Jan | I2: 2nd Jan | J2: 3rd Jan | K2: 4th Jan | L2: 5th Jan | M2: 6th Jan | N2: 7th Jan | O2: 8th Jan | P2: 9th Jan | Q2: 10th Jan | R2: 11th Jan | S2: 12th Jan | T2: 13th Jan | U2: 14th Jan | V2: 15th Jan | W2: 16th Jan | X2: 17th Jan | Y2: 18th Jan | Z2: 19th Jan | AA2: 20th Jan | AB2: 21st Jan | AC2: 22nd Jan | AD2: 23rd Jan | AE2: 24th Jan | AF2: 25th Jan | AG2: 26th Jan | AH2: 27th Jan | AI2: 28th Jan | AJ2: 29th Jan | AK2: 30th Jan | AL2: 31st Jan | AM2: Total
F3: Diesel
A4: 1 | B4: Rambabu | C4: HO(Two Wheeler) | D4: FC3450563999 | E4: Diesel | F4: 0 | G4: 0 | H4: 0 | I4: 0 | J4: 0 | K4: 0 | L4: 0 | M4: 0 | N4: 0 | O4: 0 | P4: 0 | Q4: 0 | R4: 0 | S4: 0 | T4: 0 | U4: 0 | V4: 0 | W4: 0 | X4: 5.22 | Y4: 0 | Z4: 0 | AA4: 0 | AB4: 0 | AC4: 0 | AD4: 60 | AE4: 0 | AF4: 0 | AG4: 0 | AH4: 4.56 | AI4: 0 | AJ4: 0 | AK4: 0 | AL4: 0 | AM4: =SUM(F4:AL4) -> 69.78
E5: Petrol | F5: 0 | G5: 4.69 | H5: 0 | I5: 0 | J5: 0 | K5: 0 | L5: 0 | M5: 0 | N5: 3.91 | O5: 0 | P5: 6.98 | Q5: 0 | R5: 0 | S5: 0 | T5: 0 | U5: 0 | V5: 0 | W5: 0 | X5: 0 | Y5: 0 | Z5: 0 | AB5: 0 | AC5: 0 | AD5: 0 | AE5: 0 | AF5: 0 | AG5: 0 | AH5: 0 | AI5: 0 | AJ5: 0 | AK5: 0 | AL5: 0 | AM5: =SUM(F5:AL5) -> 15.58
A6: 2 | B6: Hanumanth Rao | C6: HO | D6: FC3450676131 | E6: Diesel | F6: 0 | G6: 0 | H6: 0 | I6: 0 | J6: 0 | K6: 0 | L6: 0 | M6: 0 | N6: 0 | O6: 0 | P6: 0 | Q6: 0 | R6: 0 | S6: 0 | T6: 0 | U6: 0 | V6: 0 | W6: 0 | X6: 0 | Y6: 0 | Z6: 0 | AA6: 0 | AB6: 0 | AC6: 0 | AD6: 0 | AE6: 0 | AF6: 0 | AG6: 0 | AH6: 0 | AI6: 0 | AJ6: 0 | AK6: 0 | AL6: 0 | AM6: =SUM(F6:AL6) -> 0
E7: Petrol | F7: 0 | G7: 0 | H7: 0 | I7: 0 | J7: 0 | K7: 0 | L7: 0 | M7: 0 | N7: 0 | O7: 0 | P7: 0 | Q7: 0 | R7: 0 | S7: 0 | T7: 0 | U7: 0 | V7: 0 | W7: 0 | X7: 0 | Y7: 0 | Z7: 0 | AB7: 0 | AC7: 0 | AD7: 0 | AE7: 0 | AF7: 0 | AG7: 0 | AH7: 0 | AI7: 0 | AJ7: 0 | AK7: 0 | AL7: 0 | AM7: =SUM(F7:AL7) -> 0
A8: 3 | B8: Radhakrishna | C8: HO | D8: FC8000207658 | E8: Diesel | F8: 0 | G8: 0 | H8: 0 | I8: 0 | J8: 33.44 | K8: 0 | L8: 0 | M8: 0 | N8: 0 | O8: 0 | P8: 0 | Q8: 0 | R8: 35.53 | S8: 0 | T8: 0 | U8: 0 | V8: 0 | W8: 0 | X8: 0 | Y8: 0 | Z8: 0 | AA8: 0 | AB8: 33.44 | AC8: 0 | AD8: 0 | AE8: 0 | AF8: 0 | AG8: 0 | AH8: 0 | AI8: 0 | AJ8: 0 | AK8: 0 | AL8: 0 | AM8: =SUM(F8:AL8) -> 102.41
E9: Petrol | F9: 0 | G9: 0 | H9: 0 | I9: 0 | J9: 0 | K9: 0 | L9: 0 | M9: 0 | N9: 0 | O9: 0 | P9: 0 | Q9: 0 | R9: 0 | S9: 0 | T9: 0 | U9: 0 | V9: 0 | W9: 0 | X9: 0 | Y9: 0 | Z9: 0 | AB9: 0 | AC9: 0 | AD9: 0 | AE9: 0 | AF9: 0 | AG9: 0 | AH9: 0 | AI9: 0 | AJ9: 0 | AK9: 0 | AL9: 0 | AM9: =SUM(F9:AL9) -> 0
A10: 4 | B10: VIjay | C10: HO | D10: FC3450698859 | E10: Diesel | F10: 0 | G10: 0 | H10: 0 | I10: 0 | J10: 0 | K10: 0 | L10: 0 | M10: 0 | N10: 0 | O10: 0 | P10: 49.22 | Q10: 0 | R10: 0 | S10: 0 | T10: 0 | U10: 54.57 | V10: 0 | W10: 0 | X10: 0 | Y10: 0 | Z10: 0 | AA10: 0 | AB10: 0 | AC10: 0 | AD10: 49.8 | AE10: 0 | AF10: 0 | AG10: 0 | AH10: 0 | AI10: 0 | AJ10: 0 | AK10: 0 | AL10: 0 | AM10: =SUM(F10:AL10) -> 153.59
E11: Petrol | F11: 0 | G11: 0 | H11: 0 | I11: 0 | J11: 0 | K11: 0 | L11: 0 | M11: 0 | N11: 0 | O11: 0 | P11: 0 | Q11: 0 | R11: 0 | S11: 0 | T11: 0 | U11: 0 | V11: 0 | W11: 0 | X11: 0 | Y11: 0 | Z11: 0 | AB11: 0 | AC11: 0 | AD11: 0 | AE11: 0 | AF11: 0 | AG11: 0 | AH11: 0 | AI11: 0 | AJ11: 0 | AK11: 0 | AL11: 0 | AM11: =SUM(F11:AL11) -> 0
A12: 5 | B12: Client | C12: Hiriyur | D12: FC3450698864 | E12: Diesel | F12: 0 | G12: 0 | H12: 0 | I12: 0 | J12: 0 | K12: 0 | L12: 0 | M12: 0 | N12: 86.29 | O12: 0 | P12: 0 | Q12: 0 | R12: 0 | S12: 0 | T12: 0 | U12: 0 | V12: 0 | W12: 0 | X12: 0 | Y12: 0 | Z12: 0 | AA12: 0 | AB12: 0 | AC12: 0 | AD12: 145.61 | AE12: 0 | AF12: 0 | AG12: 0 | AH12: 0 | AI12: 0 | AJ12: 0 | AK12: 0 | AL12: 0 | AM12: =SUM(F12:AL12) -> 231.9
E13: Petrol | F13: 0 | G13: 0 | H13: 0 | I13: 0 | J13: 0 | K13: 0 | L13: 0 | M13: 0 | N13: 0 | O13: 0 | P13: 0 | Q13: 0 | R13: 0 | S13: 0 | T13: 0 | U13: 0 | V13: 0 | W13: 0 | X13: 0 | Y13: 0 | Z13: 0 | AB13: 0 | AC13: 0 | AD13: 0 | AE13: 0 | AF13: 0 | AG13: 0 | AH13: 0 | AI13: 0 | AJ13: 0 | AK13: 0 | AL13: 0 | AM13: =SUM(F13:AL13) -> 0
A14: 6 | B14: Client | C14: Hosadurga | D14: FC3450698865 | E14: Diesel | F14: 0 | G14: 0 | H14: 0 | I14: 0 | J14: 0 | K14: 0 | L14: 40 | M14: 40 | N14: 0 | O14: 36 | P14: 35 | Q14: 0 | R14: 0 | S14: 0 | T14: 0 | U14: 0 | V14: 0 | W14: 45 | X14: 45 | Y14: 43.53 | Z14: 40 | AA14: 43 | AB14: 0 | AC14: 40 | AD14: 0 | AE14: 40 | AF14: 0 | AG14: 0 | AH14: 0 | AI14: 0 | AJ14: 0 | AK14: 0 | AL14: 0 | AM14: =SUM(F14:AL14) -> 447.53
E15: Petrol | F15: 0 | G15: 0 | H15: 0 | I15: 0 | J15: 0 | K15: 0 | L15: 0 | M15: 0 | N15: 0 | O15: 0 | P15: 0 | Q15: 0 | R15: 0 | S15: 0 | T15: 0 | U15: 0 | V15: 0 | W15: 0 | X15: 0 | Y15: 0 | Z15: 0 | AB15: 0 | AC15: 0 | AD15: 0 | AE15: 0 | AF15: 0 | AG15: 0 | AH15: 0 | AI15: 0 | AJ15: 0 | AK15: 0 | AL15: 0 | AM15: =SUM(F15:AL15) -> 0
G18: Diesel Price

Sheet  July-26
A1: S.no | B1: Site Name | C1: Bunk Name | D1: Diesel(Liters) | E1: Diesel Amount | F1: Petrol(Liters) | G1: Petrol Amount | H1: Total Amount | I1: Opening Blance | J1: Amount Paid | K1: Closing Balances
A2: 1 | B2: Khammam-1 | C2: Divya laxmi ganapathi | D2: =+'Khammam-1'!E38 -> 25629.86 | E2: =+'Khammam-1'!G38 -> 2660379.5 | F2: =+'Khammam-1'!H38 -> 245 | G2: =+'Khammam-1'!J38 -> 28344.05 | H2: =E2+G2 -> 2688723.5 | I2: =+'Khammam-1'!K3 -> 1615425.2 | J2: =+'Khammam-1'!L38 -> 470000 | K2: =H2+I2-J2 -> 3834148.7
A3: 2 | B3: Khammam-2 | C3: Jayasai union bunk | D3: =+'Khammam-2'!E38 -> 90723.14 | E3: =+'Khammam-2'!G38 -> 9543877.6 | F3: =+'Khammam-2'!H38 -> 745 | G3: =+'Khammam-2'!J38 -> 86211.4 | H3: =E3+G3 -> 9630089 | I3: =+'Khammam-2'!K3 -> 9590244 | J3: =+'Khammam-2'!L38 -> 290696 | K3: =H3+I3-J3 -> 18929637
A4: 3 | B4: Khammam-3 | C4: JSASFuel Genie India Pvt.Ltd | D4: =+'Khammam-3'!E35 -> 10000 | E4: =+'Khammam-3'!G35 -> 1038080 | F4: =+'Khammam-3'!H35 -> 0 | G4: =+'Khammam-3'!J35 -> 0 | H4: =E4+G4 -> 1038080 | I4: =+'Khammam-3'!M3 -> 1072600 | J4: =+'Khammam-3'!L35 -> 600000 | K4: =H4+I4-J4 -> 1510680
A5: 4 | B5: Khammam-Cash&Carry | C5: NA | D5: =+' Khammam&Cash'!E46 -> 8008.48 | E5: =+' Khammam&Cash'!G46 -> 831280.22 | F5: =+' Khammam&Cash'!H46 -> 0 | G5: =+' Khammam&Cash'!J46 -> 0 | H5: =E5+G5 -> 831280.22 | I5: =+' Khammam&Cash'!M3 -> 0 | J5: =+' Khammam&Cash'!L46 -> 831280.22 | K5: =H5+I5-J5 -> 0
A6: 5 | B6: Jadcherla-2 | C6: Shree Poornima F/S | D6: =+'Jadcherla-4'!E35 -> 850 | E6: =+'Jadcherla-4'!G35 -> 88757 | F6: =+'Jadcherla-4'!H35 -> 40 | G6: =+'Jadcherla-4'!J35 -> 4653.2 | H6: =E6+G6 -> 93410.2 | I6: =+'Jadcherla-4'!M3 -> 6863.48 | J6: =+'Jadcherla-4'!L35 -> 50000 | K6: =H6+I6-J6 -> 50273.68
A7: 6 | B7: Sangareddy-2 | C7: Durga Bhavani F/S | D7: =+' Sangareddy-2'!E35 -> 930.16 | E7: =+' Sangareddy-2'!G35 -> 97257.53 | F7: =+' Sangareddy-2'!H35 -> 60 | G7: =+' Sangareddy-2'!J35 -> 6992.4 | H7: =E7+G7 -> 104249.93 | I7: =+' Sangareddy-2'!M3 -> 128359.22 | J7: =+' Sangareddy-2'!L35 -> 180000 | K7: =H7+I7-J7 -> 52609.145
A8: 7 | B8: Sangareddy-3 | C8: Shiva Parvathi Filling Station | D8: =+' Sangareddy-3'!E36 -> 10935 | E8: =+' Sangareddy-3'!G36 -> 1141067.2 | F8: =+' Sangareddy-3'!H36 -> 53.76 | G8: =+' Sangareddy-3'!J36 -> 6249.6 | H8: =E8+G8 -> 1147316.9 | I8: =+' Sangareddy-3'!M3 -> 207619.56 | J8: =+' Sangareddy-3'!L36 -> 600000 | K8: =H8+I8-J8 -> 754936.41
A9: 8 | B9: NarayanaKhed | C9: Sai Shiva Filling Station | D9: =Narayankhed!E35 -> 2859.86 | E9: =+Narayankhed!G35 -> 299999.31 | F9: =+Narayankhed!H35 -> 0 | G9: =+Narayankhed!J35 -> 0 | H9: =E9+G9 -> 299999.31 | I9: =+Narayankhed!M3 -> 0 | J9: =+Narayankhed!L35 -> 299999.31 | K9: =H9+I9-J9 -> 0
A10: 9 | B10: Dindi | C10: Akarapu Balakistamma Fillling | D10: =+Dindi!E35 -> 162.288 | E10: =+Dindi!G35 -> 17004.489 | F10: =+Dindi!H35 -> 0 | G10: =+Dindi!J35 -> 0 | H10: =E10+G10 -> 17004.489 | I10: =+Dindi!M3 -> 0 | J10: =+Dindi!L35 -> 17004.489 | K10: =H10+I10-J10 -> 0
A11: 10 | B11: Madanapalli | C11: NA | D11: =+'Madana palli'!E37 -> 0 | E11: =+'Madana palli'!G37 -> 0 | F11: =+'Madana palli'!H37 -> 3.4 | G11: =+'Madana palli'!J37 -> 399.364 | H11: =E11+G11 -> 399.364 | I11: =+'Madana palli'!M3 -> 0 | J11: =+'Madana palli'!L37 -> 399.364 | K11: =H11+I11-J11 -> 0
A12: 11 | B12: Yeleshwaram | C12: Sri sathya Filling Station | D12: =+'Yeleshwaram(KKD)'!E37 -> 170 | E12: =+'Yeleshwaram(KKD)'!G37 -> 17928.2 | F12: =+'Yeleshwaram(KKD)'!H37 -> 10 | G12: =+'Yeleshwaram(KKD)'!J37 -> 1178.4 | H12: =E12+G12 -> 19106.6 | I12: =+'Yeleshwaram(KKD)'!M3 -> 0 | J12: =+'Yeleshwaram(KKD)'!L37 -> 0 | K12: =H12+I12-J12 -> 19106.6
A13: 12 | B13: Pitapuam | C13: Satya Siva Durga Agencies, Chebrolu | D13: =+' Pitapram(KKD)'!E37 -> 2262.13 | E13: =+' Pitapram(KKD)'!G37 -> 237998.7 | F13: =+' Pitapram(KKD)'!H37 -> 37 | G13: =+' Pitapram(KKD)'!J37 -> 4350.46 | H13: =E13+G13 -> 242349.16 | I13: =+' Pitapram(KKD)'!M3 -> 0 | J13: =+' Pitapram(KKD)'!L37 -> 150000 | K13: =H13+I13-J13 -> 92349.157
A14: 13 | B14: Kakinada | C14: Multiple bunks | D14: =+'Multiple bunks(KKD)'!E289 -> 9882.089 | E14: =+'Multiple bunks(KKD)'!G289 -> 1038084.8 | F14: =+'Multiple bunks(KKD)'!H289 -> 553.673 | G14: =+'Multiple bunks(KKD)'!J289 -> 67413.977 | H14: =E14+G14 -> 1105498.8 | I14: =+'Multiple bunks(KKD)'!M3 -> 0 | J14: =+'Multiple bunks(KKD)'!L289 -> 1105498.8 | K14: =H14+I14-J14 -> 0
A15: 14 | B15: YG Gudda-2 | C15: Pankaja HP Fuel Center | D15: =+'YG Gudda'!E39 -> 8500 | E15: =+'YG Gudda'!G39 -> 842690 | F15: =+'YG Gudda'!H39 -> 280 | G15: =+'YG Gudda'!J39 -> 31147.2 | H15: =E15+G15 -> 873837.2 | I15: =+'YG Gudda'!M3 -> 282784.16 | J15: =+'YG Gudda'!L39 -> 860000 | K15: =H15+I15-J15 -> 296621.36
A16: 15 | B16: YG Gudda-2 | C16: One stop | D16: =+' YG Gudda-2'!E39 -> 4603.96 | E16: =+' YG Gudda-2'!G39 -> 455884.12 | F16: =+' YG Gudda-2'!H39 -> 105 | G16: =+' YG Gudda-2'!J39 -> 11667.6 | H16: =E16+G16 -> 467551.72 | I16: =+' YG Gudda-2'!M3 -> 207747.6 | J16: =+' YG Gudda-2'!L39 -> 675000 | K16: =H16+I16-J16 -> 299.3192
A17: 16 | B17: Hosadurga-2 | C17: Shree Veeraprathap Fuel | D17: =+'Hosadurga -2'!E35 -> 1000 | E17: =+'Hosadurga -2'!G35 -> 99380 | F17: =+'Hosadurga -2'!H35 -> 70 | G17: =+'Hosadurga -2'!J35 -> 7820.4 | H17: =+'Hosadurga -2'!K35 -> 107200.4 | I17: =+'Hosadurga -2'!K3 -> 114284.39 | J17: =+'Hosadurga -2'!L35 -> 221000 | K17: =H17+I17-J17 -> 484.7941
A18: 17 | B18: Malebennuru(KUWSDB) | C18: Sri Ramanjuneya Service Station | D18: =+'Malebenur(KUWSDB)'!E37 -> 5132.39 | E18: =+'Malebenur(KUWSDB)'!G37 -> 513239.31 | F18: =+'Malebenur(KUWSDB)'!H37 -> 180 | G18: =+'Malebenur(KUWSDB)'!J37 -> 20164.8 | H18: =E18+G18 -> 533404.11 | I18: =+'Malebenur(KUWSDB)'!K3 -> 132362.11 | J18: =+'Malebenur(KUWSDB)'!L37 -> 534999.51 | K18: =H18+I18-J18 -> 130766.71
A19: 18 | B19: kadur | C19: Vishal Service Station | D19: =+Kadur!E35 -> 3400 | E19: =+Kadur!G35 -> 339864 | F19: =+Kadur!H35 -> 70 | G19: =+Kadur!J35 -> 7861 | H19: =E19+G19 -> 347725 | I19: =+Kadur!K3 -> 325301.9 | J19: =+Kadur!L35 -> 0 | K19: =H19+I19-J19 -> 673026.9
A20: 19 | B20: Hiriyur(VJNL) | C20: Sri Balaji Agencies | D20: =+'Hiriyur(VJNL)'!E35 -> 4000 | E20: =+'Hiriyur(VJNL)'!G35 -> 400360 | F20: =+'Hiriyur(VJNL)'!H35 -> 210 | G20: =+'Hiriyur(VJNL)'!J35 -> 23545.2 | H20: =E20+G20 -> 423905.2 | I20: =+'Hiriyur(VJNL)'!K3 -> 219362.7 | J20: =+'Hiriyur(VJNL)'!L35 -> 435000 | K20: =H20+I20-J20 -> 208267.9
A21: 20 | B21: Chellakere(KUWSDB) | C21: Shivaganga Service Station | D21: =+'Chellakere -1'!E38 -> 3600 | E21: =+'Chellakere -1'!G38 -> 360180 | F21: =+'Chellakere -1'!H38 -> 310 | G21: =+'Chellakere -1'!J38 -> 34741.7 | H21: =E21+G21 -> 394921.7 | I21: =+'Chellakere -1'!K3 -> 116056.55 | J21: =+'Chellakere -1'!L38 -> 300000 | K21: =H21+I21-J21 -> 210978.25
A22: 21 | B22: Chellakere(KUWSDB)-09 | C22: Shivaganga Service Station | D22: =+' Chellakere-PKG-9'!E36 -> 715.754 | E22: =+' Chellakere-PKG-9'!G36 -> 71610.788 | F22: =+' Chellakere-PKG-9'!H36 -> 58.34 | G22: =+' Chellakere-PKG-9'!J36 -> 6538.1638 | H22: =E22+G22 -> 78148.952 | I22: =+' Chellakere-PKG-9'!M3 -> 0 | J22: =+' Chellakere-PKG-9'!L36 -> 78148.952 | K22: =H22+I22-J22 -> 0
A23: 22 | B23: Molakalmuru | C23: Sri Lakshmi Venkateshwara Filling Station | D23: =+Molakamuru!E35 -> 1470 | E23: =+Molakamuru!G35 -> 147057.1 | F23: =+Molakamuru!H35 -> 135 | G23: =+Molakamuru!J35 -> 15128.1 | H23: =E23+G23 -> 162185.2 | I23: =+Molakamuru!K3 -> 8880.86 | J23: =+Molakamuru!L35 -> 120366.9 | K23: =H23+I23-J23 -> 50699.16
A24: 23 | B24: Chennagiri | C24: NA | D24: =+' Chennagiri'!E35 -> 1332.17 | E24: =+' Chennagiri'!G35 -> 133046.82 | F24: =+' Chennagiri'!H35 -> 89.99 | G24: =+' Chennagiri'!J35 -> 10084.279 | H24: =E24+G24 -> 143131.1 | I24: =+' Chennagiri'!K3 -> 0 | J24: =+' Chennagiri'!L35 -> 143131.1 | K24: =H24+I24-J24 -> 0
A25: 24 | B25: Khanapur(PKG-3) | C25: V.V.Varde | D25: =+Khanapur!E35 -> 717.32 | E25: =+Khanapur!G35 -> 70792.311 | F25: =+Khanapur!H35 -> 80 | G25: =+Khanapur!J35 -> 8871.6 | H25: =E25+G25 -> 79663.911 | I25: =+Khanapur!M3 -> 105067.75 | J25: =+Khanapur!L35 -> 100000 | K25: =H25+I25-J25 -> 84731.659
A26: 25 | B26: Munavalli(PKG-3) | C26: Shre Shiva Petroleum | D26: =+'Munavali-2'!E40 -> 3400 | E26: =+'Munavali-2'!G40 -> 337790 | F26: =+'Munavali-2'!H40 -> 80 | G26: =+'Munavali-2'!J40 -> 8918 | H26: =E26+G26 -> 346708 | I26: =+'Munavali-2'!M3 -> 0 | J26: =+'Munavali-2'!L40 -> 200000 | K26: =H26+I26-J26 -> 146708
A27: 26 | B27: Munavalli(PKG-3) | C27: Daneshwari Petroleum | D27: =+' Munavali'!E39 -> 4800 | E27: =+' Munavali'!G39 -> 475824 | F27: =+' Munavali'!H39 -> 180 | G27: =+' Munavali'!J39 -> 20017.8 | H27: =E27+G27 -> 495841.8 | I27: =+' Munavali'!M3 -> 478435.42 | J27: =+' Munavali'!L39 -> 700000 | K27: =H27+I27-J27 -> 274277.22
A28: 27 | B28: Borgaon(PKG-3) | C28: Aadisagar Petrolium | D28: =+Borgaon!E35 -> 0 | E28: =+Borgaon!G35 -> 0 | F28: =+Borgaon!H35 -> 0 | G28: =+Borgaon!J35 -> 0 | H28: =E28+G28 -> 0 | I28: =+Borgaon!K3 -> 208.3907 | J28: =+Borgaon!L35 -> 0 | K28: =H28+I28-J28 -> 208.3907
A29: 28 | B29: Ugar,Kudichi(PKG-3) | C29: Shiri Bhrhmanath Petrolium | D29: =+'Ugar,Khagwad,Kudichi'!E37 -> 5853.82 | E29: =+'Ugar,Khagwad,Kudichi'!G37 -> 583860.01 | F29: =+'Ugar,Khagwad,Kudichi'!H37 -> 76 | G29: =+'Ugar,Khagwad,Kudichi'!J37 -> 8500.6 | H29: =E29+G29 -> 592360.61 | I29: =+'Ugar,Khagwad,Kudichi'!M3 -> 529659.87 | J29: =+'Ugar,Khagwad,Kudichi'!L37 -> 780000 | K29: =H29+I29-J29 -> 342020.48
A30: 29 | B30: Shedbal | C30: Varad Petroluem | D30: =+shedbal!E37 -> 5814.96 | E30: =+shedbal!G37 -> 579957.15 | F30: =+shedbal!H37 -> 352 | G30: =+shedbal!J37 -> 39371.2 | H30: =E30+G30 -> 619328.35 | I30: =+shedbal!M3 -> 296953 | J30: =+shedbal!L37 -> 410000.2 | K30: =H30+I30-J30 -> 506281.15
A31: 30 | B31: Kabbur(PKG-3) | C31: Shri Jai Hanuman Petrolium | D31: =+Kabbur!E35 -> 140.48 | E31: =+Kabbur!G35 -> 13965.117 | F31: =+Kabbur!H35 -> 0 | G31: =+Kabbur!J35 -> 0 | H31: =E31+G31 -> 13965.117 | I31: 0 | J31: =+Kabbur!L35 -> 13965.117 | K31: =H31+I31-J31 -> 0
A32: 31 | B32: Kumta (PKG-1) | C32: V.M.Mirjankar (Kumta) Bharat | D32: =+kumta!E41 -> 1060 | E32: =+kumta!G41 -> 105766.8 | F32: =+kumta!H41 -> 85 | G32: =+kumta!J41 -> 9518.3 | H32: =E32+G32 -> 115285.1 | I32: =kumta!M3 -> 15058.507 | J32: =+kumta!L41 -> 70000 | K32: =H32+I32-J32 -> 60343.607
A33: 32 | B33: Jalgaon-1 | C33: Jai Bajarang Sarvo Senter Bodwad | D33: =+' Jalgaon-1'!E55 -> 0 | E33: =+' Jalgaon-1'!G55 -> 0 | F33: =+' Jalgaon-1'!H55 -> 0 | G33: =+' Jalgaon-1'!J55 -> 0 | H33: =E33+G33 -> 0 | I33: =+' Jalgaon-1'!K3 -> 0 | J33: =+' Jalgaon-1'!L55 -> 0 | K33: =H33+I33-J33 -> 0
A34: 33 | B34: Jalgaon-2 | C34: Nayara | D34: =+'Jalgoan-2'!E56 -> 19809.44 | E34: ='Jalgoan-2'!G56 -> 1971173.4 | F34: =+'Jalgoan-2'!H56 -> 150 | G34: =+'Jalgoan-2'!J56 -> 16977 | H34: =E34+G34 -> 1988150.4 | I34: =+'Jalgoan-2'!M3 -> 2547026.4 | J34: =+'Jalgoan-2'!L56 -> 4068.6941 | K34: =H34+I34-J34 -> 4531108.2
A35: 34 | B35: MKBD | C35: Shree Sai Samarth Petroleum | D35: =+MKBD!E42 -> 3000 | E35: =+MKBD!G42 -> 296820 | F35: =+MKBD!H42 -> 10 | G35: =+MKBD!J42 -> 1122.7 | H35: =E35+G35 -> 297942.7 | I35: =+MKBD!K3 -> 631570.81 | J35: =+MKBD!L42 -> 0 | K35: =H35+I35-J35 -> 929513.51
A36: 35 | B36: Haveri | C36: M/s Magavi City Fuels | D36: =' Haveri-2'!E42 -> 3772.15 | E36: =' Haveri-2'!G42 -> 374561.75 | F36: =' Haveri-2'!H42 -> 113.79 | G36: =' Haveri-2'!J42 -> 12676.206 | H36: =E36+G36 -> 387237.96 | I36: =' Haveri-2'!M3 -> 132797.45 | J36: =+' Haveri-2'!L42 -> 401000.02 | K36: =H36+I36-J36 -> 119035.39
A37: 36 | B37: Guttal-2 | C37: Himagiri Petroleum | D37: =+' Guttal-2'!E35 -> 7568.35 | E37: =+' Guttal-2'!G35 -> 753807.66 | F37: =+' Guttal-2'!H35 -> 166.06 | G37: =+' Guttal-2'!J35 -> 18550.563 | H37: =E37+G37 -> 772358.22 | I37: =+' Guttal-2'!M3 -> 92031.494 | J37: =+' Guttal-2'!L35 -> 700000 | K37: =H37+I37-J37 -> 164389.72
A38: 37 | B38: Rattihali-2 | C38: Shiva Oil Traders | D38: =+'Rattihali-2'!E37 -> 5892.11 | E38: =+'Rattihali-2'!G37 -> 587443.37 | F38: =+'Rattihali-2'!H37 -> 119.01 | G38: =+'Rattihali-2'!J37 -> 13357.398 | H38: =E38+G38 -> 600800.77 | I38: =+'Rattihali-2'!M3 -> 393080.16 | J38: =+'Rattihali-2'!L37 -> 650000 | K38: =H38+I38-J38 -> 343880.92
A39: 38 | B39: Gajendragada | C39: Vanasri Petrol Pump | D39: =+Gajendragada!E36 -> 750 | E39: =+Gajendragada!G36 -> 74730 | F39: =+Gajendragada!H36 -> 46.63 | G39: =+Gajendragada!J36 -> 5211.8351 | H39: =E39+G39 -> 79941.835 | I39: =+Gajendragada!K3 -> 79945.408 | J39: =+Gajendragada!L36 -> 100000 | K39: =H39+I39-J39 -> 59887.243
A40: 39 | B40: Gokak(PKG-3) | C40: AJ Petrolinks | D40: =+'Gokak Dharwad PKG 3'!E42 -> 7986.06 | E40: =+'Gokak Dharwad PKG 3'!G42 -> 792935.9 | F40: =+'Gokak Dharwad PKG 3'!H42 -> 45 | G40: =+'Gokak Dharwad PKG 3'!J42 -> 5012.1 | H40: =E40+G40 -> 797948 | I40: =+'Gokak Dharwad PKG 3'!K3 -> 144866.46 | J40: =+'Gokak Dharwad PKG 3'!L42 -> 500000 | K40: =H40+I40-J40 -> 442814.46
...

Sheet HO(DG)
A1: JSASFuel Genie India Pvt.Ltd
A2: S.No | B2: Date | C2: GRN No | D2: Ind No/Bill No | E2: Diesel (Lts) | F2: Price | G2: Amount | H2: Petrol (Lts) | I2: Price | J2: Amount | K2: Total amount | L2: Amount paid | M2: As on date | N2: Remarks
A3: Opening Balance | K3: 182921.75 | M3: 182921.75 | O3: 2623243.4
A4: 1 | B4: 46204 | G4: =E4*F4 -> 0 | H4: 0 | I4: 0 | J4: =H4*I4 -> 0 | K4: =G4+J4 -> 0 | L4: 0 | M4: =M3+K4-L4 -> 182921.75
A5: 2 | B5: 46205 | G5: =E5*F5 -> 0 | K5: =G5+J5 -> 0 | M5: =M4+K5-L5 -> 182921.75 | R5: HO | S5: 188521.22
A6: 3 | B6: 46206 | E6: 200 | F6: 103.82 | G6: =E6*F6 -> 20764 | K6: =G6+J6 -> 20764 | L6: 0 | M6: =M5+K6-L6 -> 203685.75 | R6: Khammam | S6: 8227903
A7: 4 | B7: 46207 | G7: =E7*F7 -> 0 | K7: =G7+J7 -> 0 | M7: =M6+K7-L7 -> 203685.75 | R7: Jadcherla | S7: 2453209.4
A8: 5 | B8: 46208 | G8: =E8*F8 -> 0 | K8: =G8+J8 -> 0 | M8: =M7+K8-L8 -> 203685.75 | P8: 5679 | R8: Total | S8: =SUM(S5:S7) -> 10869634
A9: 6 | B9: 46209 | G9: =E9*F9 -> 0 | K9: =G9+J9 -> 0 | M9: =M8+K9-L9 -> 203685.75 | S9: 10869632
A10: 7 | B10: 46210 | G10: =E10*F10 -> 0 | K10: =G10+J10 -> 0 | L10: =H10+K10 -> 0 | M10: =M9+K10-L10 -> 203685.75 | N10: HPCL | S10: =S9-S8 -> -1.6105
B11: 46211 | G11: =E11*F11 -> 0 | K11: =G11+J11 -> 0 | L11: =H11+K11 -> 0 | M11: =M10+K11-L11 -> 203685.75 | N11: HPCL
A12: 8 | B12: 46212 | G12: =E12*F12 -> 0 | K12: =G12+J12 -> 0 | L12: =H12+K12 -> 0 | M12: =M11+K12-L12 -> 203685.75 | N12: HPCL
A13: 9 | B13: 46213 | E13: 35 | F13: 103.76 | G13: =E13*F13 -> 3631.6 | K13: =G13+J13 -> 3631.6 | L13: =H13+K13 -> 3631.6 | M13: =M12+K13-L13 -> 203685.75 | Q13: 54.98
A14: 10 | B14: 46214 | E14: 35 | F14: 103.76 | G14: =E14*F14 -> 3631.6 | K14: =G14+J14 -> 3631.6 | L14: =H14+K14 -> 3631.6 | M14: =M13+K14-L14 -> 203685.75 | Q14: 54.98
A15: 11 | B15: 46215 | E15: 200 | F15: 103.82 | G15: =E15*F15 -> 20764 | K15: =G15+J15 -> 20764 | M15: =M14+K15-L15 -> 224449.75
A16: 12 | B16: 46216 | G16: =E16*F16 -> 0 | K16: =G16+J16 -> 0 | L16: =H16+K16 -> 0 | M16: =M15+K16-L16 -> 224449.75 | R16: 19166
A17: 13 | B17: 46217 | G17: =E17*F17 -> 0 | K17: =G17+J17 -> 0 | L17: =H17+K17 -> 0 | M17: =M16+K17-L17 -> 224449.75 | R17: 19645
A18: 14 | B18: 46218 | G18: =E18*F18 -> 0 | K18: =G18+J18 -> 0 | L18: =H18+K18 -> 0 | M18: =M17+K18-L18 -> 224449.75 | P18: 1905988 | Q18: =P18-M18 -> 1681538.2 | R18: 21083
A19: 15 | B19: 46219 | E19: 70 | F19: 103.76 | G19: =E19*F19 -> 7263.2 | K19: =G19+J19 -> 7263.2 | L19: =H19+K19 -> 7263.2 | M19: =M18+K19-L19 -> 224449.75 | R19: 19140 | S19: 220637
A20: 16 | B20: 46220 | E20: 200 | F20: 103.82 | G20: =E20*F20 -> 20764 | K20: =G20+J20 -> 20764 | M20: =M19+K20-L20 -> 245213.75 | N20: HPCL | R20: =SUM(R16:R19) -> 79034 | S20: =S19+R20 -> 299671
A21: 17 | B21: 46221 | G21: =E21*F21 -> 0 | K21: =G21+J21 -> 0 | L21: =H21+K21 -> 0 | M21: =M20+K21-L21 -> 245213.75 | N21: HPCL
A22: 18 | B22: 46222 | G22: =E22*F22 -> 0 | K22: =G22+J22 -> 0 | L22: =H22+K22 -> 0 | M22: =M21+K22-L22 -> 245213.75
A23: 19 | B23: 46223 | G23: =E23*F23 -> 0 | K23: =G23+J23 -> 0 | L23: =H23+K23 -> 0 | M23: =M22+K23-L23 -> 245213.75
A24: 20 | B24: 46224 | G24: =E24*F24 -> 0 | K24: =G24+J24 -> 0 | L24: =H24+K24 -> 0 | M24: =M23+K24-L24 -> 245213.75
A25: 21 | B25: 46225 | E25: 200 | F25: 103.82 | G25: =E25*F25 -> 20764 | K25: =G25+J25 -> 20764 | L25: 0 | M25: =M24+K25-L25 -> 265977.75
A26: 22 | B26: 46226 | G26: =E26*F26 -> 0 | K26: =G26+J26 -> 0 | L26: =H26+K26 -> 0 | M26: =M25+K26-L26 -> 265977.75
A27: 23 | B27: 46227 | G27: =E27*F27 -> 0 | K27: =G27+J27 -> 0 | L27: 0 | M27: =M26+K27-L27 -> 265977.75
A28: 24 | B28: 46228 | G28: =E28*F28 -> 0 | K28: =G28+J28 -> 0 | L28: =H28+K28 -> 0 | M28: =M27+K28-L28 -> 265977.75
A29: 25 | B29: 46229 | G29: =E29*F29 -> 0 | K29: =G29+J29 -> 0 | L29: =H29+K29 -> 0 | M29: =M28+K29-L29 -> 265977.75
A30: 26 | B30: 46230 | G30: =E30*F30 -> 0 | K30: =G30+J30 -> 0 | M30: =M29+K30-L30 -> 265977.75
A31: 27 | B31: 46231 | E31: 70 | F31: 103.76 | G31: =E31*F31 -> 7263.2 | K31: =G31+J31 -> 7263.2 | L31: 7263.2 | M31: =M30+K31-L31 -> 265977.75
A32: 28 | B32: 46232 | G32: =E32*F32 -> 0 | K32: =G32+J32 -> 0 | M32: =M31+K32-L32 -> 265977.75
B33: 46233 | G33: =E33*F33 -> 0 | M33: =M32+K33-L33 -> 265977.75
A34: 29 | B34: 46234 | E34: 70 | F34: 103.76 | G34: =E34*F34 -> 7263.2 | K34: =G34+J34 -> 7263.2 | L34: =H34+K34 -> 7263.2 | M34: =M33+K34-L34 -> 265977.75
G35: =E35*F35 -> 0 | K35: =G35+J35 -> 0 | M35: =M34+K35-L35 -> 265977.75
A36: 30 | K36: =G36+J36 -> 0 | M36: =M35+K36-L36 -> 265977.75
A37: 31 | M37: =M36+K37-L37 -> 265977.75
A38: 32 | M38: =M37+K38-L38 -> 265977.75 | O38: 265910 | P38: =M38-O38 -> 67.75
A39: 33
A40: 34
...

Sheet Khammam-1
A1: Divya laxmi ganapathi
A2: S.No | B2: Date | C2: GRN No | D2: Ind No/Bill No | E2: Diesel (Lts) | F2: Price | G2: Amount | H2: Petrol (Lts) | I2: Price | J2: Amount | K2: Total amount | L2: Amount paid | M2: As 0n Date | N2: Remarks
A3: Opening Balance | K3: 1615425.2 | M3: 1615425.2
A4: 1 | B4: 46204 | G4: =E4*F4 -> 0 | K4: =G4+J4 -> 0 | M4: =M3+K4-L4 -> 1615425.2
A5: 2 | B5: 46205 | E5: 2800 | F5: 103.8 | G5: =E5*F5 -> 290640 | H5: 60 | I5: 115.69 | J5: =H5*I5 -> 6941.4 | K5: =G5+J5 -> 297581.4 | M5: =M4+K5-L5 -> 1913006.6
A6: 3 | B6: 46206 | E6: 2892.67 | F6: 103.8 | G6: =E6*F6 -> 300259.15 | H6: 40 | I6: 115.69 | J6: =H6*I6 -> 4627.6 | K6: =G6+J6 -> 304886.75 | M6: =M5+K6-L6 -> 2217893.3
A7: 4 | B7: 46207 | E7: 2000 | F7: 103.8 | G7: =E7*F7 -> 207600 | H7: 50 | I7: 115.69 | J7: =H7*I7 -> 5784.5 | K7: =G7+J7 -> 213384.5 | M7: =M6+K7-L7 -> 2431277.8
A8: 5 | B8: 46208 | E8: 1500 | F8: 103.8 | G8: =E8*F8 -> 155700 | J8: =H8*I8 -> 0 | K8: =G8+J8 -> 155700 | M8: =M7+K8-L8 -> 2586977.8
A9: 6 | B9: 46209 | G9: =E9*F9 -> 0 | J9: =H9*I9 -> 0 | K9: =G9+J9 -> 0 | M9: =M8+K9-L9 -> 2586977.8
A10: 7 | B10: 46210 | E10: 2700 | F10: 103.8 | G10: =E10*F10 -> 280260 | J10: =H10*I10 -> 0 | K10: =G10+J10 -> 280260 | M10: =M9+K10-L10 -> 2867237.8
A11: 8 | B11: 46211 | G11: =E11*F11 -> 0 | J11: =H11*I11 -> 0 | K11: =G11+J11 -> 0 | M11: =M10+K11-L11 -> 2867237.8
A12: 9 | B12: 46212 | G12: =E12*F12 -> 0 | J12: =H12*I12 -> 0 | K12: =G12+J12 -> 0 | M12: =M11+K12-L12 -> 2867237.8
A13: 10 | B13: 46213 | G13: =E13*F13 -> 0 | J13: =H13*I13 -> 0 | K13: =G13+J13 -> 0 | M13: =M12+K13-L13 -> 2867237.8
A14: 11 | B14: 46214 | G14: =E14*F14 -> 0 | J14: =H14*I14 -> 0 | K14: =G14+J14 -> 0 | M14: =M13+K14-L14 -> 2867237.8
A15: 12 | B15: 46215 | G15: =E15*F15 -> 0 | J15: =H15*I15 -> 0 | K15: =G15+J15 -> 0 | M15: =M14+K15-L15 -> 2867237.8
A16: 13 | B16: 46216 | G16: =E16*F16 -> 0 | J16: =H16*I16 -> 0 | K16: =G16+J16 -> 0 | M16: =M15+K16-L16 -> 2867237.8
A17: 14 | B17: 46217 | E17: 3000 | F17: 103.8 | G17: =E17*F17 -> 311400 | H17: 60 | I17: 115.69 | J17: =H17*I17 -> 6941.4 | K17: =G17+J17 -> 318341.4 | M17: =M16+K17-L17 -> 3185579.2 | N17: DGM Sir | O17: 250000
A18: 15 | B18: 46218 | E18: 2500 | F18: 103.8 | G18: =E18*F18 -> 259500 | H18: 35 | I18: 115.69 | J18: =H18*I18 -> 4049.15 | K18: =G18+J18 -> 263549.15 | M18: =M17+K18-L18 -> 3449128.4
A19: 16 | B19: 46219 | E19: 2408.47 | F19: 103.8 | G19: =E19*F19 -> 249999.19 | J19: =H19*I19 -> 0 | K19: =G19+J19 -> 249999.19 | M19: =M18+K19-L19 -> 3699127.6 | N19: DGM Sir | O19: 250000
A20: 17 | B20: 46220 | G20: =E20*F20 -> 0 | J20: =H20*I20 -> 0 | K20: =G20+J20 -> 0 | M20: =M19+K20-L20 -> 3699127.6
A21: 18 | B21: 46221 | G21: =E21*F21 -> 0 | J21: =H21*I21 -> 0 | K21: =G21+J21 -> 0 | M21: =M20+K21-L21 -> 3699127.6
A22: 19 | B22: 46222 | G22: =E22*F22 -> 0 | J22: =H22*I22 -> 0 | K22: =G22+J22 -> 0 | M22: =M21+K22-L22 -> 3699127.6
A23: 20 | B23: 46223 | E23: 1300 | F23: 103.8 | G23: =E23*F23 -> 134940 | J23: =H23*I23 -> 0 | K23: =G23+J23 -> 134940 | M23: =M22+K23-L23 -> 3834067.6 | N23: DGM Sir | O23: 100000
A24: 21 | B24: 46224 | G24: =E24*F24 -> 0 | J24: =H24*I24 -> 0 | K24: =G24+J24 -> 0 | M24: =M23+K24-L24 -> 3834067.6
A25: 22 | B25: 46225 | G25: =E25*F25 -> 0 | J25: =H25*I25 -> 0 | K25: =G25+J25 -> 0 | M25: =M24+K25-L25 -> 3834067.6
A26: 23 | B26: 46226 | G26: =E26*F26 -> 0 | J26: =H26*I26 -> 0 | K26: =G26+J26 -> 0 | M26: =M25+K26-L26 -> 3834067.6 | O26: =SUM(O17:O25) -> 600000
A27: 24 | B27: 46227 | G27: =E27*F27 -> 0 | J27: =H27*I27 -> 0 | K27: =G27+J27 -> 0 | M27: =M26+K27-L27 -> 3834067.6
A28: 25 | B28: 46228 | G28: =E28*F28 -> 0 | J28: =H28*I28 -> 0 | K28: =G28+J28 -> 0 | M28: =M27+K28-L28 -> 3834067.6
A29: 26 | B29: 46229 | G29: =E29*F29 -> 0 | J29: =H29*I29 -> 0 | K29: =G29+J29 -> 0 | M29: =M28+K29-L29 -> 3834067.6
A30: 27 | B30: 46230 | E30: 2120 | F30: 103.8 | G30: =E30*F30 -> 220056 | J30: =H30*I30 -> 0 | K30: =G30+J30 -> 220056 | L30: 220000 | M30: =M29+K30-L30 -> 3834123.6 | N30: HPCL
A31: 28 | B31: 46231 | G31: =E31*F31 -> 0 | J31: =H31*I31 -> 0 | K31: =G31+J31 -> 0 | M31: =M30+K31-L31 -> 3834123.6
A32: 29 | B32: 46232 | E32: 2408.72 | F32: 103.8 | G32: =E32*F32 -> 250025.14 | J32: =H32*I32 -> 0 | K32: =G32+J32 -> 250025.14 | L32: 250000 | M32: =M31+K32-L32 -> 3834148.7 | N32: HPCL
A33: 30 | B33: 46233 | G33: =E33*F33 -> 0 | J33: =H33*I33 -> 0 | K33: =G33+J33 -> 0 | M33: =M32+K33-L33 -> 3834148.7
A34: 31 | G34: =E34*F34 -> 0 | K34: =G34+J34 -> 0 | M34: =M33+K34-L34 -> 3834148.7
A35: 32 | G35: =E35*F35 -> 0 | J35: =H35*I35 -> 0 | K35: =G35+J35 -> 0 | M35: =M34+K35-L35 -> 3834148.7
A36: 33 | G36: =E36*F36 -> 0 | J36: =H36*I36 -> 0 | K36: =G36+J36 -> 0
A37: 34 | G37: =E37*F37 -> 0 | J37: =H37*I37 -> 0 | K37: =G37+J37 -> 0
E38: =SUM(E3:E37) -> 25629.86 | G38: =SUM(G3:G37) -> 2660379.5 | H38: =SUM(H3:H37) -> 245 | J38: =SUM(J3:J37) -> 28344.05 | K38: =SUM(K4:K37) -> 2688723.5 | L38: =SUM(L3:L37) -> 470000

Sheet Khammam-2
A1: Jayasai union bunk
A2: S.No | B2: Date | C2: GRN No | D2: Ind No/Bill No | E2: Diesel (Lts) | F2: Price | G2: Amount | H2: Petrol (Lts) | I2: Price | J2: Amount | K2: Total amount | L2: Amount paid | M2: As 0n Date | N2: Remarks
A3: Opening Balance | K3: 9590244 | M3: 9590244
A4: 1 | B4: 46204 | E4: 6229.42 | F4: 103.82 | G4: =E4*F4 -> 646738.38 | J4: =H4*I4 -> 0 | K4: =G4+J4 -> 646738.38 | M4: =M3+K4-L4 -> 10236982
A5: 2 | B5: 46205 | E5: 6193.54 | F5: 103.82 | G5: =E5*F5 -> 643013.32 | J5: =H5*I5 -> 0 | K5: =G5+J5 -> 643013.32 | M5: =M4+K5-L5 -> 10879996
A6: 3 | B6: 46206 | E6: 7217.38 | F6: 103.82 | G6: =E6*F6 -> 749308.39 | J6: =H6*I6 -> 0 | K6: =G6+J6 -> 749308.39 | M6: =M5+K6-L6 -> 11629304
A7: 4 | B7: 46207 | E7: 6415.09 | F7: 103.82 | G7: =E7*F7 -> 666014.64 | J7: =H7*I7 -> 0 | K7: =G7+J7 -> 666014.64 | M7: =M6+K7-L7 -> 12295319
A8: 5 | B8: 46208 | E8: 6004 | F8: 103.82 | G8: =E8*F8 -> 623335.28 | J8: =H8*I8 -> 0 | K8: =G8+J8 -> 623335.28 | M8: =M7+K8-L8 -> 12918654
A9: 6 | B9: 46209 | E9: 6433.17 | F9: 103.82 | G9: =E9*F9 -> 667891.71 | J9: =H9*I9 -> 0 | K9: =G9+J9 -> 667891.71 | M9: =M8+K9-L9 -> 13586546
A10: 7 | B10: 46210 | E10: 5000 | F10: 103.82 | G10: =E10*F10 -> 519100 | H10: 95 | I10: 115.72 | J10: =H10*I10 -> 10993.4 | K10: =G10+J10 -> 530093.4 | M10: =M9+K10-L10 -> 14116639
A11: 8 | B11: 46211 | E11: 2800 | F11: 103.82 | G11: =E11*F11 -> 290696 | H11: 40 | I11: 115.72 | J11: =H11*I11 -> 4628.8 | K11: =G11+J11 -> 295324.8 | M11: =M10+K11-L11 -> 14411964
A12: 9 | B12: 46212 | E12: 2700 | F12: 103.82 | G12: =E12*F12 -> 280314 | H12: 20 | I12: 115.72 | J12: =H12*I12 -> 2314.4 | K12: =G12+J12 -> 282628.4 | M12: =M11+K12-L12 -> 14694592
A13: 10 | B13: 46213 | E13: 5500 | F13: 103.82 | G13: =E13*F13 -> 571010 | H13: 40 | I13: 115.72 | J13: =H13*I13 -> 4628.8 | K13: =G13+J13 -> 575638.8 | M13: =M12+K13-L13 -> 15270231
A14: 11 | B14: 46214 | E14: 6150 | F14: 103.82 | G14: =E14*F14 -> 638493 | H14: 40 | I14: 115.72 | J14: =H14*I14 -> 4628.8 | K14: =G14+J14 -> 643121.8 | M14: =M13+K14-L14 -> 15913353
A15: 12 | B15: 46215 | E15: 2500 | F15: 103.82 | G15: =E15*F15 -> 259550 | J15: =H15*I15 -> 0 | K15: =G15+J15 -> 259550 | M15: =M14+K15-L15 -> 16172903 | S15: 5000000
A16: 13 | B16: 46216 | E16: 2000 | F16: 103.82 | G16: =E16*F16 -> 207640 | H16: 60 | I16: 115.72 | J16: =H16*I16 -> 6943.2 | K16: =G16+J16 -> 214583.2 | M16: =M15+K16-L16 -> 16387486 | Q16: 6086287 | S16: 6086287
A17: 14 | B17: 46217 | G17: =E17*F17 -> 0 | J17: =H17*I17 -> 0 | K17: =G17+J17 -> 0 | M17: =M16+K17-L17 -> 16387486 | S17: =SUM(S15:S16) -> 11086287
A18: 15 | B18: 46218 | E18: 3000 | F18: 103.82 | G18: =E18*F18 -> 311460 | J18: =H18*I18 -> 0 | K18: =G18+J18 -> 311460 | M18: =M17+K18-L18 -> 16698946 | S18: 1162961.4
A19: 16 | B19: 46219 | E19: 2000 | F19: 103.82 | G19: =E19*F19 -> 207640 | H19: 20 | I19: 115.72 | J19: =H19*I19 -> 2314.4 | K19: =G19+J19 -> 209954.4 | M19: =M18+K19-L19 -> 16908901 | S19: =S17-S18 -> 9923325.6
A20: 17 | B20: 46220 | E20: 2000 | F20: 103.82 | G20: =E20*F20 -> 207640 | H20: 75 | I20: 115.72 | J20: =H20*I20 -> 8679 | K20: =G20+J20 -> 216319 | M20: =M19+K20-L20 -> 17125220 | S20: 32869.06
A21: 18 | B21: 46221 | E21: 4115.59 | F21: 103.82 | G21: =E21*F21 -> 427280.55 | J21: =H21*I21 -> 0 | K21: =G21+J21 -> 427280.55 | M21: =M20+K21-L21 -> 17552500 | N21: DGM Sir | O21: 350000 | S21: =S19+S20 -> 9956194.6
A22: 19 | B22: 46222 | G22: =E22*F22 -> 0 | J22: =H22*I22 -> 0 | K22: =G22+J22 -> 0 | M22: =M21+K22-L22 -> 17552500
A23: 20 | B23: 46223 | E23: 5716.02 | F23: 103.82 | G23: =E23*F23 -> 593437.2 | H23: 80 | I23: 115.72 | J23: =H23*I23 -> 9257.6 | K23: =G23+J23 -> 602694.8 | M23: =M22+K23-L23 -> 18155195 | N23: DGM Sir | O23: 500000
A24: 21 | B24: 46224 | G24: =E24*F24 -> 0 | J24: =H24*I24 -> 0 | K24: =G24+J24 -> 0 | M24: =M23+K24-L24 -> 18155195
A25: 22 | B25: 46225 | E25: 2800 | F25: 103.82 | G25: =E25*F25 -> 290696 | J25: =H25*I25 -> 0 | K25: =G25+J25 -> 290696 | L25: 290696 | M25: =M24+K25-L25 -> 18155195 | N25: IOCL Card
A26: 23 | B26: 46226 | G26: =E26*F26 -> 0 | H26: 75 | I26: 115.72 | J26: =H26*I26 -> 8679 | K26: =G26+J26 -> 8679 | M26: =M25+K26-L26 -> 18163874
A27: 24 | B27: 46227 | D27: 26-27/S1 (MP3 Grease) | E27: 546 | F27: 332.76 | G27: =E27*F27 -> 181686.96 | J27: =H27*I27 -> 0 | K27: =G27+J27 -> 181686.96 | M27: =M26+K27-L27 -> 18345561
A28: 25 | B28: 46228 | G28: =E28*F28 -> 0 | H28: 95 | I28: 115.72 | J28: =H28*I28 -> 10993.4 | K28: =G28+J28 -> 10993.4 | M28: =M27+K28-L28 -> 18356554
A29: 26 | B29: 46229 | G29: =E29*F29 -> 0 | J29: =H29*I29 -> 0 | K29: =G29+J29 -> 0 | M29: =M28+K29-L29 -> 18356554
A30: 27 | B30: 46230 | G30: =E30*F30 -> 0 | J30: =H30*I30 -> 0 | K30: =G30+J30 -> 0 | M30: =M29+K30-L30 -> 18356554
A31: 28 | B31: 46231 | E31: 2802.93 | F31: 103.82 | G31: =E31*F31 -> 291000.19 | H31: 105 | I31: 115.72 | J31: =H31*I31 -> 12150.6 | K31: =G31+J31 -> 303150.79 | M31: =M30+K31-L31 -> 18659705 | N31: DGM Sir | O31: 291000
A32: 29 | B32: 46232 | E32: 2600 | F32: 103.82 | G32: =E32*F32 -> 269932 | J32: =H32*I32 -> 0 | K32: =G32+J32 -> 269932 | M32: =M31+K32-L32 -> 18929637 | N32: DGM Sir | O32: 269932
A33: 30 | B33: 46233 | G33: =E33*F33 -> 0 | J33: =H33*I33 -> 0 | K33: =G33+J33 -> 0 | M33: =M32+K33-L33 -> 18929637 | O33: =SUM(O21:O32) -> 1410932
A34: 31 | B34: 46234 | G34: =E34*F34 -> 0 | J34: =H34*I34 -> 0 | K34: =G34+J34 -> 0 | M34: =M33+K34-L34 -> 18929637
A35: 32 | G35: =E35*F35 -> 0 | J35: =H35*I35 -> 0 | K35: =G35+J35 -> 0 | M35: =M34+K35-L35 -> 18929637
A36: 33 | G36: =E36*F36 -> 0 | J36: =H36*I36 -> 0 | K36: =G36+J36 -> 0 | M36: =M35+K36-L36 -> 18929637
E38: =SUM(E4:E36) -> 90723.14 | G38: =SUM(G4:G36) -> 9543877.6 | H38: =SUM(H4:H36) -> 745 | J38: =SUM(J4:J36) -> 86211.4 | K38: =SUM(K4:K36) -> 9630089 | L38: =SUM(L4:L36) -> 290696

Sheet Khammam-3
A1: JSASFuel Genie India Pvt.Ltd
A2: S.No | B2: Date | C2: GRN No | D2: Ind No/Bill No | E2: Diesel (Lts) | F2: Price | G2: Amount | H2: Petrol (Lts) | I2: Price | J2: Amount | K2: Total amount | L2: Amount paid | M2: As 0n Date | N2: Remarks
A3: Opening Balance | K3: 1072600 | M3: 1072600
A4: 1 | B4: 46204 | G4: =E4*F4 -> 0 | J4: =H4*I4 -> 0 | K4: =G4+J4 -> 0 | M4: =M3+K4-L4 -> 1072600
A5: 2 | B5: 46205 | G5: =E5*F5 -> 0 | J5: =H5*I5 -> 0 | K5: =G5+J5 -> 0 | M5: =M4+K5-L5 -> 1072600
A6: 3 | B6: 46206 | G6: =E6*F6 -> 0 | J6: =H6*I6 -> 0 | K6: =G6+J6 -> 0 | M6: =M5+K6-L6 -> 1072600
A7: 4 | B7: 46207 | G7: =E7*F7 -> 0 | J7: =H7*I7 -> 0 | K7: =G7+J7 -> 0 | M7: =M6+K7-L7 -> 1072600
A8: 5 | B8: 46208 | G8: =E8*F8 -> 0 | J8: =H8*I8 -> 0 | K8: =G8+J8 -> 0 | M8: =M7+K8-L8 -> 1072600
A9: 6 | B9: 46209 | G9: =E9*F9 -> 0 | J9: =H9*I9 -> 0 | K9: =G9+J9 -> 0 | M9: =M8+K9-L9 -> 1072600
A10: 7 | B10: 46210 | G10: =E10*F10 -> 0 | J10: =H10*I10 -> 0 | K10: =G10+J10 -> 0 | M10: =M9+K10-L10 -> 1072600
A11: 8 | B11: 46211 | G11: =E11*F11 -> 0 | J11: =H11*I11 -> 0 | K11: =G11+J11 -> 0 | M11: =M10+K11-L11 -> 1072600
A12: 9 | B12: 46212 | G12: =E12*F12 -> 0 | J12: =H12*I12 -> 0 | K12: =G12+J12 -> 0 | M12: =M11+K12-L12 -> 1072600
A13: 10 | B13: 46213 | G13: =E13*F13 -> 0 | J13: =H13*I13 -> 0 | K13: =G13+J13 -> 0 | M13: =M12+K13-L13 -> 1072600
A14: 11 | B14: 46214 | G14: =E14*F14 -> 0 | J14: =H14*I14 -> 0 | K14: =G14+J14 -> 0 | M14: =M13+K14-L14 -> 1072600
A15: 12 | B15: 46215 | G15: =E15*F15 -> 0 | J15: =H15*I15 -> 0 | K15: =G15+J15 -> 0 | M15: =M14+K15-L15 -> 1072600
... A25: 22 | B25: 46225 | G25: =E25*F25 -> 0 | J25: =H25*I25 -> 0 | K25: =G25+J25 -> 0 | M25: =M24+K25-L25 -> 1072600
A26: 23 | B26: 46226 | E26: 6000 | F26: 103.8 | G26: =E26*F26 -> 622800 | J26: =H26*I26 -> 0 | K26: =G26+J26 -> 622800 | M26: =M25+K26-L26 -> 1695400
A27: 24 | B27: 46227 | E27: 4000 | F27: 103.82 | G27: =E27*F27 -> 415280 | J27: =H27*I27 -> 0 | K27: =G27+J27 -> 415280 | M27: =M26+K27-L27 -> 2110680
A28: 25 | B28: 46228 | G28: =E28*F28 -> 0 | J28: =H28*I28 -> 0 | K28: =G28+J28 -> 0 | L28: 600000 | M28: =M27+K28-L28 -> 1510680
A29: 26 | B29: 46229 | G29: =E29*F29 -> 0 | J29: =H29*I29 -> 0 | K29: =G29+J29 -> 0 | M29: =M28+K29-L29 -> 1510680
A30: 27 | B30: 46230 | G30: =E30*F30 -> 0 | J30: =H30*I30 -> 0 | K30: =G30+J30 -> 0 | M30: =M29+K30-L30 -> 1510680
A31: 28 | B31: 46231 | G31: =E31*F31 -> 0 | J31: =H31*I31 -> 0 | K31: =G31+J31 -> 0 | M31: =M30+K31-L31 -> 1510680
A32: 29 | B32: 46232 | G32: =E32*F32 -> 0 | J32: =H32*I32 -> 0 | K32: =G32+J32 -> 0 | M32: =M31+K32-L32 -> 1510680
A33: 30 | B33: 46233 | G33: =E33*F33 -> 0 | J33: =H33*I33 -> 0 | K33: =G33+J33 -> 0 | M33: =M32+K33-L33 -> 1510680
A34: 31 | G34: =E34*F34 -> 0 | J34: =H34*I34 -> 0 | K34: =G34+J34 -> 0 | M34: =M33+K34-L34 -> 1510680
E35: =SUM(E4:E34) -> 10000 | G35: =SUM(G4:G34) -> 1038080 | H35: =SUM(H4:H34) -> 0 | J35: =SUM(J4:J34) -> 0 | K35: =SUM(K4:K34) -> 1038080 | L35: =SUM(L4:L34) -> 600000

Sheet  Khammam&Cash
A1: Cash &Carry
A2: S.No | B2: Date | D2: Ind No/Bill No | E2: Diesel (Lts) | F2: Price | G2: Amount | H2: Petrol (Lts) | I2: Price | J2: Amount | K2: Total amount | L2: Amount paid | M2: As 0n Date | N2: Remarks
A3: Opening Balance | K3: 0 | M3: 0
A4: 1 | G4: =E4*F4 -> 0 | K4: =G4+J4 -> 0 | L4: =H4+K4 -> 0 | M4: =M3+K4-L4 -> 0
A5: 2 | G5: =E5*F5 -> 0 | J5: =H5*I5 -> 0 | K5: =G5+J5 -> 0 | L5: =H5+K5 -> 0 | M5: =M4+K5-L5 -> 0
A6: 3 | G6: =E6*F6 -> 0 | J6: =H6*I6 -> 0 | K6: =G6+J6 -> 0 | L6: =H6+K6 -> 0 | M6: =M5+K6-L6 -> 0
A7: 4 | G7: =E7*F7 -> 0 | J7: =H7*I7 -> 0 | K7: =G7+J7 -> 0 | L7: =H7+K7 -> 0 | M7: =M6+K7-L7 -> 0
A8: 5 | G8: =E8*F8 -> 0 | J8: =H8*I8 -> 0 | K8: =G8+J8 -> 0 | L8: =H8+K8 -> 0 | M8: =M7+K8-L8 -> 0
A9: 6 | G9: =E9*F9 -> 0 | J9: =H9*I9 -> 0 | K9: =G9+J9 -> 0 | L9: =H9+K9 -> 0 | M9: =M8+K9-L9 -> 0
A10: 7 | G10: =E10*F10 -> 0 | J10: =H10*I10 -> 0 | K10: =G10+J10 -> 0 | L10: =H10+K10 -> 0 | M10: =M9+K10-L10 -> 0
A11: 8 | G11: =E11*F11 -> 0 | J11: =H11*I11 -> 0 | K11: =G11+J11 -> 0 | L11: =H11+K11 -> 0 | M11: =M10+K11-L11 -> 0
A12: 9 | G12: =E12*F12 -> 0 | J12: =H12*I12 -> 0 | K12: =G12+J12 -> 0 | L12: =H12+K12 -> 0 | M12: =M11+K12-L12 -> 0
A13: 10 | G13: =E13*F13 -> 0 | J13: =H13*I13 -> 0 | K13: =G13+J13 -> 0 | L13: =H13+K13 -> 0 | M13: =M12+K13-L13 -> 0
A14: 11 | G14: =E14*F14 -> 0 | J14: =H14*I14 -> 0 | K14: =G14+J14 -> 0 | L14: =H14+K14 -> 0 | M14: =M13+K14-L14 -> 0
A15: 12 | G15: =E15*F15 -> 0 | J15: =H15*I15 -> 0 | K15: =G15+J15 -> 0 | L15: =H15+K15 -> 0 | M15: =M14+K15-L15 -> 0
A16: 13 | G16: =E16*F16 -> 0 | J16: =H16*I16 -> 0 | K16: =G16+J16 -> 0 | L16: =H16+K16 -> 0 | M16: =M15+K16-L16 -> 0
... A22: 19 | G22: =E22*F22 -> 0 | J22: =H22*I22 -> 0 | K22: =G22+J22 -> 0 | L22: =H22+K22 -> 0 | M22: =M21+K22-L22 -> 0
A23: 20 | G23: =E23*F23 -> 0 | J23: =H23*I23 -> 0 | K23: =G23+J23 -> 0 | L23: 0 | M23: =M22+K23-L23 -> 0
A24: 21 | G24: =E24*F24 -> 0 | J24: =H24*I24 -> 0 | K24: =G24+J24 -> 0 | L24: =H24+K24 -> 0 | M24: =M23+K24-L24 -> 0
A25: 22 | G25: =E25*F25 -> 0 | J25: =H25*I25 -> 0 | K25: =G25+J25 -> 0 | L25: =H25+K25 -> 0 | M25: =M24+K25-L25 -> 0
A26: 23 | G26: =E26*F26 -> 0 | J26: =H26*I26 -> 0 | K26: =G26+J26 -> 0 | L26: =H26+K26 -> 0 | M26: =M25+K26-L26 -> 0
A27: 24 | G27: =E27*F27 -> 0 | K27: =G27+J27 -> 0 | L27: =H27+K27 -> 0 | M27: =M26+K27-L27 -> 0
A28: 25 | B28: 46227 | C28: Stambhadri Fuel Park HPCL | E28: 2800 | F28: 103.8 | G28: =E28*F28 -> 290640 | J28: =H28*I28 -> 0 | K28: =G28+J28 -> 290640 | L28: =H28+K28 -> 290640 | M28: =M26+K28-L28 -> 0
A29: 26 | B29: 46228 | C29: Stambhadri Fuel Park HPCL | E29: 2800 | F29: 103.8 | G29: =E29*F29 -> 290640 | J29: =H29*I29 -> 0 | K29: =G29+J29 -> 290640 | L29: =H29+K29 -> 290640 | M29: =M28+K29-L29 -> 0
A30: 27 | B30: 46234 | C30: Stambhadri Fuel Park HPCL | E30: 2408.48 | F30: 103.8 | G30: =E30*F30 -> 250000.22 | J30: =H30*I30 -> 0 | K30: =G30+J30 -> 250000.22 | L30: =H30+K30 -> 250000.22 | M30: =M29+K30-L30 -> 0
A31: 28 | G31: =E31*F31 -> 0 | J31: =H31*I31 -> 0 | K31: =G31+J31 -> 0 | L31: =H31+K31 -> 0 | M31: =M30+K31-L31 -> 0
A32: 29 | G32: =E32*F32 -> 0 | J32: =H32*I32 -> 0 | K32: =G32+J32 -> 0 | L32: =H32+K32 -> 0 | M32: =M31+K32-L32 -> 0
A33: 30 | G33: =E33*F33 -> 0 | J33: =H33*I33 -> 0 | K33: =G33+J33 -> 0 | L33: =H33+K33 -> 0 | M33: =M32+K33-L33 -> 0
A34: 31 | G34: =E34*F34 -> 0 | J34: =H34*I34 -> 0 | K34: =G34+J34 -> 0 | L34: =H34+K34 -> 0 | M34: =M33+K34-L34 -> 0
A35: 32 | G35: =E35*F35 -> 0 | K35: =G35+J35 -> 0 | L35: =H35+K35 -> 0 | M35: =M34+K35-L35 -> 0
A36: 33 | G36: =E36*F36 -> 0 | J36: =H36*I36 -> 0 | K36: =G36+J36 -> 0 | L36: =H36+K36 -> 0 | M36: =M35+K36-L36 -> 0
A37: 34 | G37: =E37*F37 -> 0 | J37: =H37*I37 -> 0 | K37: =G37+J37 -> 0 | L37: =H37+K37 -> 0 | M37: =M36+K37-L37 -> 0
G38: =E38*F38 -> 0 | K38: =G38+J38 -> 0 | L38: =H38+K38 -> 0 | M38: =M37+K38-L38 -> 0
G39: =E39*F39 -> 0 | K39: =G39+J39 -> 0 | L39: =H39+K39 -> 0 | M39: =M38+K39-L39 -> 0
G40: =E40*F40 -> 0 | K40: =G40+J40 -> 0 | L40: =H40+K40 -> 0 | M40: =M39+K40-L40 -> 0
M41: =M40+K41-L41 -> 0
A45: 35 | G45: =E45*F45 -> 0 | J45: =H45*I45 -> 0 | K45: =G45+J45 -> 0
E46: =SUM(E3:E45) -> 8008.48 | G46: =SUM(G3:G45) -> 831280.22 | H46: =SUM(H3:H45) -> 0 | J46: =SUM(J3:J45) -> 0 | K46: =SUM(K4:K45) -> 831280.22 | L46: =SUM(L3:L45) -> 831280.22

Sheet Jadcherla-4
A1: Shree Poornima F/S
A2: S.No | B2: Date | C2: GRN No | D2: Ind No/Bill No | E2: Diesel (Lts) | F2: Price | G2: Amount | H2: Petrol (Lts) | I2: Price | J2: Amount | K2: Total amount | L2: Amount paid | M2: As on date | N2: Remarks
A3: Opening Balance | M3: 6863.48
A4: 1 | B4: 46204 | G4: =E4*F4 -> 0 | J4: =H4*I4 -> 0 | K4: =G4+J4 -> 0 | L4: 0 | M4: =M3+K4-L4 -> 6863.48
A5: 2 | B5: 46205 | G5: =E5*F5 -> 0 | J5: =H5*I5 -> 0 | K5: =G5+J5 -> 0 | L5: 0 | M5: =M4+K5-L5 -> 6863.48
A6: 3 | B6: 46206 | E6: 100 | F6: 104.42 | G6: =E6*F6 -> 10442 | J6: =H6*I6 -> 0 | K6: =G6+J6 -> 10442 | L6: 0 | M6: =M5+K6-L6 -> 17305.48
A7: 4 | B7: 46207 | E7: 500 | F7: 104.42 | G7: =E7*F7 -> 52210 | J7: =H7*I7 -> 0 | K7: =G7+J7 -> 52210 | L7: 0 | M7: =M6+K7-L7 -> 69515.48
A8: 5 | B8: 46208 | G8: =E8*F8 -> 0 | J8: =H8*I8 -> 0 | K8: =G8+J8 -> 0 | L8: 0 | M8: =M7+K8-L8 -> 69515.48
A9: 6 | B9: 46209 | G9: =E9*F9 -> 0 | J9: =H9*I9 -> 0 | K9: =G9+J9 -> 0 | L9: 0 | M9: =M8+K9-L9 -> 69515.48
A10: 7 | B10: 46210 | G10: =E10*F10 -> 0 | J10: =H10*I10 -> 0 | K10: =G10+J10 -> 0 | L10: 0 | M10: =M9+K10-L10 -> 69515.48
A11: 8 | B11: 46211 | G11: =E11*F11 -> 0 | J11: =H11*I11 -> 0 | K11: =G11+J11 -> 0 | L11: 0 | M11: =M10+K11-L11 -> 69515.48
A12: 9 | B12: 46212 | G12: =E12*F12 -> 0 | J12: =H12*I12 -> 0 | K12: =G12+J12 -> 0 | L12: 0 | M12: =M11+K12-L12 -> 69515.48
A13: 10 | B13: 46213 | G13: =E13*F13 -> 0 | J13: =H13*I13 -> 0 | K13: =G13+J13 -> 0 | L13: 0 | M13: =M12+K13-L13 -> 69515.48
A14: 11 | B14: 46214 | G14: =E14*F14 -> 0 | H14: 20 | I14: 116.33 | J14: =H14*I14 -> 2326.6 | K14: =G14+J14 -> 2326.6 | M14: =M13+K14-L14 -> 71842.08
A15: 12 | B15: 46215 | G15: =E15*F15 -> 0 | J15: =H15*I15 -> 0 | K15: =G15+J15 -> 0 | M15: =M14+K15-L15 -> 71842.08
A16: 13 | B16: 46216 | G16: =E16*F16 -> 0 | J16: =H16*I16 -> 0 | K16: =G16+J16 -> 0 | M16: =M15+K16-L16 -> 71842.08
A17: 14 | B17: 46217 | G17: =E17*F17 -> 0 | J17: =H17*I17 -> 0 | K17: =G17+J17 -> 0 | M17: =M16+K17-L17 -> 71842.08
A18: 15 | B18: 46218 | G18: =E18*F18 -> 0 | J18: =H18*I18 -> 0 | K18: =G18+J18 -> 0 | M18: =M17+K18-L18 -> 71842.08
A19: 16 | B19: 46219 | G19: 0 | J19: 0 | K19: 0 | M19: =M18+K19-L19 -> 71842.08
A20: 17 | B20: 46220 | G20: =E20*F20 -> 0 | J20: =H20*I20 -> 0 | K20: =G20+J20 -> 0 | L20: 50000 | M20: =M19+K20-L20 -> 21842.08 | N20: Poornima f/s machine not working swiping the same amont Sri Srinivasa Filling Station
A21: 18 | B21: 46221 | E21: 250 | F21: 104.42 | G21: =E21*F21 -> 26105 | J21: =H21*I21 -> 0 | K21: =G21+J21 -> 26105 | M21: =M20+K21-L21 -> 47947.08
A22: 19 | B22: 46222 | G22: =E22*F22 -> 0 | J22: =H22*I22 -> 0 | K22: =G22+J22 -> 0 | L22: 0 | M22: =M21+K22-L22 -> 47947.08
A23: 20 | B23: 46223 | G23: =E23*F23 -> 0 | J23: =H23*I23 -> 0 | K23: =G23+J23 -> 0 | L23: 0 | M23: =M22+K23-L23 -> 47947.08
A24: 21 | B24: 46224 | G24: =E24*F24 -> 0 | J24: =H24*I24 -> 0 | K24: =G24+J24 -> 0 | L24: 0 | M24: =M23+K24-L24 -> 47947.08
A25: 22 | B25: 46225 | G25: =E25*F25 -> 0 | J25: =H25*I25 -> 0 | K25: =G25+J25 -> 0 | L25: 0 | M25: =M24+K25-L25 -> 47947.08
A26: 23 | B26: 46226 | G26: =E26*F26 -> 0 | J26: =H26*I26 -> 0 | K26: =G26+J26 -> 0 | L26: 0 | M26: =M25+K26-L26 -> 47947.08
A27: 24 | B27: 46227 | G27: =E27*F27 -> 0 | J27: =H27*I27 -> 0 | K27: =G27+J27 -> 0 | L27: 0 | M27: =M26+K27-L27 -> 47947.08
A28: 25 | B28: 46228 | G28: =E28*F28 -> 0 | H28: 20 | I28: 116.33 | J28: =H28*I28 -> 2326.6 | K28: =G28+J28 -> 2326.6 | L28: 0 | M28: =M27+K28-L28 -> 50273.68
A29: 26 | B29: 46229 | G29: =E29*F29 -> 0 | J29: =H29*I29 -> 0 | K29: =G29+J29 -> 0 | L29: 0 | M29: =M28+K29-L29 -> 50273.68
A30: 27 | B30: 46230 | G30: =E30*F30 -> 0 | J30: =H30*I30 -> 0 | K30: =G30+J30 -> 0 | L30: 0 | M30: =M29+K30-L30 -> 50273.68
A31: 28 | B31: 46231 | G31: =E31*F31 -> 0 | J31: =H31*I31 -> 0 | K31: =G31+J31 -> 0 | L31: 0 | M31: =M30+K31-L31 -> 50273.68
A32: 29 | B32: 46232 | G32: =E32*F32 -> 0 | J32: =H32*I32 -> 0 | K32: =G32+J32 -> 0 | L32: 0 | M32: =M31+K32-L32 -> 50273.68
A33: 30 | B33: 46233 | G33: =E33*F33 -> 0 | H33: 0 | I33: 0 | J33: =H33*I33 -> 0 | K33: =G33+J33 -> 0 | L33: 0 | M33: =M32+K33-L33 -> 50273.68
A34: 31 | G34: =E34*F34 -> 0 | J34: =H34*I34 -> 0 | K34: =G34+J34 -> 0 | M34: =M33+K34-L34 -> 50273.68
E35: =SUM(E4:E34) -> 850 | G35: =SUM(G4:G34) -> 88757 | H35: =SUM(H4:H34) -> 40 | J35: =SUM(J4:J34) -> 4653.2 | K35: =SUM(K4:K34) -> 93410.2 | L35: =SUM(L4:L34) -> 50000

Sheet  Sangareddy-2
A1: Durga Bhavani F/S
A2: S.No | B2: Date | C2: GRN No | D2: Ind no/Bill No | E2: Diesel (Lts) | F2: Price | G2: Amount | H2: Petrol (Lts) | I2: Price | J2: Amount | K2: Total amount | L2: Amount paid | M2: As on Date | N2: Remarks
A3: Opening Balance | M3: 128359.22
A4: 1 | B4: 45839 | E4: 438 | F4: 104.56 | G4: =E4*F4 -> 45797.28 | H4: 5 | I4: 116.54 | J4: =H4*I4 -> 582.7 | K4: =G4+J4 -> 46379.98 | M4: =M3+K4-L4 -> 174739.2
A5: 2 | B5: 45840 | E5: 43.8 | F5: 104.56 | G5: =E5*F5 -> 4579.728 | J5: =H5*I5 -> 0 | K5: =G5+J5 -> 4579.728 | M5: =M4+K5-L5 -> 179318.92
A6: 3 | B6: 45841 | E6: 37.65 | F6: 104.56 | G6: =E6*F6 -> 3936.684 | J6: =H6*I6 -> 0 | K6: =G6+J6 -> 3936.684 | M6: =M5+K6-L6 -> 183255.61
A7: 4 | B7: 45842 | G7: =E7*F7 -> 0 | J7: =H7*I7 -> 0 | K7: =G7+J7 -> 0 | M7: =M6+K7-L7 -> 183255.61
A8: 5 | B8: 45843 | G8: =E8*F8 -> 0 | J8: =H8*I8 -> 0 | K8: =G8+J8 -> 0 | M8: =M7+K8-L8 -> 183255.61
A9: 6 | B9: 45844 | G9: =E9*F9 -> 0 | J9: =H9*I9 -> 0 | K9: =G9+J9 -> 0 | M9: =M8+K9-L9 -> 183255.61
A10: 7 | B10: 45845 | G10: =E10*F10 -> 0 | J10: =H10*I10 -> 0 | K10: =G10+J10 -> 0 | M10: =M9+K10-L10 -> 183255.61
A11: 8 | B11: 45846 | G11: =E11*F11 -> 0 | H11: 15 | I11: 116.54 | J11: =H11*I11 -> 1748.1 | K11: =G11+J11 -> 1748.1 | M11: =M10+K11-L11 -> 185003.71
A12: 9 | B12: 45847 | G12: =E12*F12 -> 0 | J12: =H12*I12 -> 0 | K12: =G12+J12 -> 0 | M12: =M11+K12-L12 -> 185003.71
A13: 10 | B13: 45848 | G13: =E13*F13 -> 0 | H13: 5 | I13: 116.54 | J13: =H13*I13 -> 582.7 | K13: =G13+J13 -> 582.7 | M13: =M12+K13-L13 -> 185586.41
A14: 11 | B14: 45849 | G14: =E14*F14 -> 0 | J14: =H14*I14 -> 0 | K14: =G14+J14 -> 0 | M14: =M13+K14-L14 -> 185586.41
A15: 12 | B15: 45850 | G15: =E15*F15 -> 0 | H15: 5 | I15: 116.54 | J15: =H15*I15 -> 582.7 | K15: =G15+J15 -> 582.7 | M15: =M14+K15-L15 -> 186169.11
A16: 13 | B16: 45851 | G16: =E16*F16 -> 0 | J16: =H16*I16 -> 0 | K16: =G16+J16 -> 0 | M16: =M15+K16-L16 -> 186169.11
A17: 14 | B17: 45852 | G17: =E17*F17 -> 0 | J17: =H17*I17 -> 0 | K17: =G17+J17 -> 0 | M17: =M16+K17-L17 -> 186169.11
A18: 15 | B18: 45853 | G18: =E18*F18 -> 0 | J18: =H18*I18 -> 0 | K18: =G18+J18 -> 0 | L18: 180000 | M18: =M17+K18-L18 -> 6169.1074
A19: 16 | B19: 45854 | G19: =E19*F19 -> 0 | J19: =H19*I19 -> 0 | K19: =G19+J19 -> 0 | M19: =M18+K19-L19 -> 6169.1074
A20: 17 | B20: 45855 | G20: =E20*F20 -> 0 | J20: =H20*I20 -> 0 | K20: =G20+J20 -> 0 | M20: =M19+K20-L20 -> 6169.1074
A21: 18 | B21: 45856 | G21: =E21*F21 -> 0 | J21: =H21*I21 -> 0 | K21: =G21+J21 -> 0 | M21: =M20+K21-L21 -> 6169.1074
A22: 19 | B22: 45857 | G22: =E22*F22 -> 0 | J22: =H22*I22 -> 0 | K22: =G22+J22 -> 0 | M22: =M21+K22-L22 -> 6169.1074
A23: 20 | B23: 45858 | G23: =E23*F23 -> 0 | J23: =H23*I23 -> 0 | K23: =G23+J23 -> 0 | M23: =M22+K23-L23 -> 6169.1074 | Q23: 96.44
A24: 21 | B24: 45859 | G24: =E24*F24 -> 0 | J24: =H24*I24 -> 0 | K24: =G24+J24 -> 0 | M24: =M23+K24-L24 -> 6169.1074
A25: 22 | B25: 45860 | G25: =E25*F25 -> 0 | J25: =H25*I25 -> 0 | K25: =G25+J25 -> 0 | M25: =M24+K25-L25 -> 6169.1074
A26: 23 | B26: 45861 | E26: 245 | F26: 104.56 | G26: =E26*F26 -> 25617.2 | J26: =H26*I26 -> 0 | K26: =G26+J26 -> 25617.2 | M26: =M25+K26-L26 -> 31786.307
A27: 24 | B27: 45862 | G27: =E27*F27 -> 0 | H27: 10 | I27: 116.54 | J27: =H27*I27 -> 1165.4 | K27: =G27+J27 -> 1165.4 | M27: =M26+K27-L27 -> 32951.707
A28: 25 | B28: 45863 | E28: 0 | F28: 104.56 | G28: =E28*F28 -> 0 | H28: 15 | I28: 116.54 | J28: =H28*I28 -> 1748.1 | K28: =G28+J28 -> 1748.1 | M28: =M27+K28-L28 -> 34699.807
A29: 26 | B29: 45864 | E29: 130 | F29: 104.56 | G29: =E29*F29 -> 13592.8 | H29: 5 | I29: 116.54 | J29: =H29*I29 -> 582.7 | K29: =G29+J29 -> 14175.5 | M29: =M28+K29-L29 -> 48875.307
A30: 27 | B30: 45865 | G30: =E30*F30 -> 0 | J30: =H30*I30 -> 0 | K30: =G30+J30 -> 0 | M30: =M29+K30-L30 -> 48875.307
A31: 28 | B31: 45866 | E31: 35.71 | F31: 104.56 | G31: =E31*F31 -> 3733.8376 | J31: =H31*I31 -> 0 | K31: =G31+J31 -> 3733.8376 | M31: =M30+K31-L31 -> 52609.145
A32: 29 | B32: 45867 | G32: =E32*F32 -> 0 | J32: =H32*I32 -> 0 | K32: =G32+J32 -> 0 | M32: =M31+K32-L32 -> 52609.145
A33: 30 | B33: 45868 | G33: =E33*F33 -> 0 | J33: =H33*I33 -> 0 | K33: =G33+J33 -> 0 | L33: 0 | M33: =M32+K33-L33 -> 52609.145
A34: 31 | G34: =E34*F34 -> 0 | J34: =H34*I34 -> 0 | K34: =G34+J34 -> 0 | L34: 0 | M34: =M33+K34-L34 -> 52609.145
E35: =SUM(E4:E34) -> 930.16 | G35: =SUM(G4:G34) -> 97257.53 | H35: =SUM(H4:H34) -> 60 | J35: =SUM(J4:J34) -> 6992.4 | K35: =SUM(K4:K34) -> 104249.93 | L35: =SUM(L4:L34) -> 180000

Sheet  Sangareddy-3
A1: SHIVA PARVATHI FILLING STATION SADASHIVPET
A2: S.No | B2: Date | C2: GRN No | D2: Ind no/Bill No | E2: Diesel (Lts) | F2: Price | G2: Amount | H2: Petrol (Lts) | I2: Price | J2: Amount | K2: Total amount | L2: Amount paid | M2: As on Date | N2: Remarks
A3: Opening Balance | M3: 207619.56
A4: 1 | B4: 45839 | E4: 690 | F4: 104.35 | G4: =E4*F4 -> 72001.5 | J4: =H4*I4 -> 0 | K4: =G4+J4 -> 72001.5 | M4: =M3+K4-L4 -> 279621.06
A5: 2 | B5: 45840 | G5: =E5*F5 -> 0 | H5: 5 | I5: 116.25 | J5: =H5*I5 -> 581.25 | K5: =G5+J5 -> 581.25 | M5: =M4+K5-L5 -> 280202.31
A6: 3 | B6: 45841 | E6: 690 | F6: 104.35 | G6: =E6*F6 -> 72001.5 | J6: =H6*I6 -> 0 | K6: =G6+J6 -> 72001.5 | M6: =M5+K6-L6 -> 352203.81
A7: 4 | B7: 45842 | G7: =E7*F7 -> 0 | H7: 5 | I7: 116.25 | J7: =H7*I7 -> 581.25 | K7: =G7+J7 -> 581.25 | M7: =M6+K7-L7 -> 352785.06
A8: 5 | B8: 45843 | E8: 690 | F8: 104.35 | G8: =E8*F8 -> 72001.5 | J8: =H8*I8 -> 0 | K8: =G8+J8 -> 72001.5 | M8: =M7+K8-L8 -> 424786.56
A9: 6 | B9: 45844 | G9: =E9*F9 -> 0 | H9: 5 | I9: 116.25 | J9: =H9*I9 -> 581.25 | K9: =G9+J9 -> 581.25 | M9: =M8+K9-L9 -> 425367.81
A10: 7 | B10: 45845 | E10: 725 | F10: 104.35 | G10: =E10*F10 -> 75653.75 | J10: =H10*I10 -> 0 | K10: =G10+J10 -> 75653.75 | M10: =M9+K10-L10 -> 501021.56
A11: 8 | B11: 45846 | E11: 690 | F11: 104.35 | G11: =E11*F11 -> 72001.5 | J11: =H11*I11 -> 0 | K11: =G11+J11 -> 72001.5 | M11: =M10+K11-L11 -> 573023.06
A12: 9 | B12: 45847 | E12: 730 | F12: 104.35 | G12: =E12*F12 -> 76175.5 | J12: =H12*I12 -> 0 | K12: =G12+J12 -> 76175.5 | M12: =M11+K12-L12 -> 649198.56
A13: 10 | B13: 45848 | E13: 690 | F13: 104.35 | G13: =E13*F13 -> 72001.5 | J13: =H13*I13 -> 0 | K13: =G13+J13 -> 72001.5 | M13: =M12+K13-L13 -> 721200.06
A14: 11 | B14: 45849 | E14: 690 | F14: 104.35 | G14: =E14*F14 -> 72001.5 | J14: =H14*I14 -> 0 | K14: =G14+J14 -> 72001.5 | M14: =M13+K14-L14 -> 793201.56 | N14: BT
A15: 12 | B15: 45850 | E15: 600 | F15: 104.35 | G15: =E15*F15 -> 62610 | K15: =G15+J15 -> 62610 | M15: =M14+K15-L15 -> 855811.56
A16: 13 | B16: 45851 | E16: 690 | F16: 104.35 | G16: =E16*F16 -> 72001.5 | H16: 6 | I16: 116.25 | J16: =H16*I16 -> 697.5 | K16: =G16+J16 -> 72699 | M16: =M15+K16-L16 -> 928510.56
A17: 14 | B17: 45852 | E17: 690 | F17: 104.35 | G17: =E17*F17 -> 72001.5 | J17: =H17*I17 -> 0 | K17: =G17+J17 -> 72001.5 | M17: =M16+K17-L17 -> 1000512.1
A18: 15 | B18: 45853 | E18: 690 | F18: 104.35 | G18: =E18*F18 -> 72001.5 | J18: =H18*I18 -> 0 | K18: =G18+J18 -> 72001.5 | M18: =M17+K18-L18 -> 1072513.6
A19: 16 | B19: 45854 | E19: 600 | F19: 104.35 | G19: =E19*F19 -> 62610 | J19: =H19*I19 -> 0 | K19: =G19+J19 -> 62610 | M19: =M18+K19-L19 -> 1135123.6
A20: 17 | B20: 45855 | G20: =E20*F20 -> 0 | H20: 12 | I20: 116.25 | J20: =H20*I20 -> 1395 | K20: =G20+J20 -> 1395 | M20: =M19+K20-L20 -> 1136518.6
A21: 18 | B21: 45856 | G21: =E21*F21 -> 0 | H21: 6 | I21: 116.25 | J21: =H21*I21 -> 697.5 | K21: =G21+J21 -> 697.5 | M21: =M20+K21-L21 -> 1137216.1
A22: 19 | B22: 45857 | G22: =E22*F22 -> 0 | J22: =H22*I22 -> 0 | K22: =G22+J22 -> 0 | M22: =M21+K22-L22 -> 1137216.1
A23: 20 | B23: 45858 | E23: 690 | F23: 104.35 | G23: =E23*F23 -> 72001.5 | J23: =H23*I23 -> 0 | K23: =G23+J23 -> 72001.5 | L23: 300000 | M23: =M22+K23-L23 -> 909217.56
A24: 21 | B24: 45859 | G24: =E24*F24 -> 0 | H24: 8.76 | I24: 116.25 | J24: =H24*I24 -> 1018.35 | K24: =G24+J24 -> 1018.35 | M24: =M23+K24-L24 -> 910235.91
A25: 22 | B25: 45860 | G25: =E25*F25 -> 0 | J25: =H25*I25 -> 0 | K25: =G25+J25 -> 0 | M25: =M24+K25-L25 -> 910235.91
A26: 23 | B26: 45861 | G26: =E26*F26 -> 0 | J26: =H26*I26 -> 0 | K26: =G26+J26 -> 0 | M26: =M25+K26-L26 -> 910235.91
A27: 24 | B27: 45862 | G27: =E27*F27 -> 0 | J27: =H27*I27 -> 0 | K27: =G27+J27 -> 0 | M27: =M26+K27-L27 -> 910235.91
A28: 25 | B28: 45863 | E28: 690 | F28: 104.35 | G28: =E28*F28 -> 72001.5 | I28: 116.25 | J28: =H28*I28 -> 0 | K28: =G28+J28 -> 72001.5 | M28: =M27+K28-L28 -> 982237.41
A29: 26 | B29: 45864 | G29: =E29*F29 -> 0 | H29: 6 | I29: 116.25 | J29: =H29*I29 -> 697.5 | K29: =G29+J29 -> 697.5 | M29: =M28+K29-L29 -> 982934.91
A30: 27 | B30: 45865 | E30: 690 | F30: 104.35 | G30: =E30*F30 -> 72001.5 | J30: =H30*I30 -> 0 | K30: =G30+J30 -> 72001.5 | M30: =M29+K30-L30 -> 1054936.4
A31: 28 | B31: 45866 | G31: =E31*F31 -> 0 | J31: =H31*I31 -> 0 | K31: =G31+J31 -> 0 | M31: =M30+K31-L31 -> 1054936.4
A32: 29 | B32: 45867 | G32: =E32*F32 -> 0 | J32: =H32*I32 -> 0 | K32: =G32+J32 -> 0 | M32: =M31+K32-L32 -> 1054936.4
A33: 30 | B33: 45868 | G33: =E33*F33 -> 0 | J33: =H33*I33 -> 0 | K33: =G33+J33 -> 0 | M33: =M32+K33-L33 -> 1054936.4
A34: 31 | B34: 45869 | G34: =E34*F34 -> 0 | J34: =H34*I34 -> 0 | K34: =G34+J34 -> 0 | L34: 300000 | M34: =M33+K34-L34 -> 754936.41
A35: 32 | G35: =E35*F35 -> 0 | J35: =H35*I35 -> 0 | K35: =G35+J35 -> 0 | M35: =M34+K35-L35 -> 754936.41
E36: =SUM(E4:E35) -> 10935 | G36: =SUM(G4:G35) -> 1141067.2 | H36: =SUM(H4:H35) -> 53.76 | J36: =SUM(J4:J35) -> 6249.6 | K36: =SUM(K4:K35) -> 1147316.9 | L36: =SUM(L4:L35) -> 600000

Sheet Narayankhed
A2: S.No | B2: Date | C2: GRN No | D2: Ind no/Bill No | E2: Diesel (Lts) | F2: Price | G2: Amount | H2: Petrol (Lts) | I2: Price | J2: Amount | K2: Total amount | L2: Amount paid | M2: As on Date | N2: Remarks
A3: Opening Balance | M3: 0
A4: 1 | B4: 45839 | G4: =E4*F4 -> 0 | J4: =H4*I4 -> 0 | K4: =G4+J4 -> 0 | L4: =H4+K4 -> 0 | M4: =M3+K4-L4 -> 0
A5: 2 | B5: 45840 | E5: 190.66 | F5: 104.9 | G5: =E5*F5 -> 20000.234 | J5: =H5*I5 -> 0 | K5: =G5+J5 -> 20000.234 | L5: =H5+K5 -> 20000.234 | M5: =M4+K5-L5 -> 0 | N5: BT | S5: 185.65
A6: 3 | B6: 45841 | E6: 285.99 | F6: 104.9 | G6: =E6*F6 -> 30000.351 | J6: =H6*I6 -> 0 | K6: =G6+J6 -> 30000.351 | L6: =H6+K6 -> 30000.351 | M6: =M5+K6-L6 -> 0 | N6: BT | S6: 5
A7: 4 | B7: 45842 | G7: =E7*F7 -> 0 | J7: =H7*I7 -> 0 | K7: =G7+J7 -> 0 | L7: =H7+K7 -> 0 | M7: =M6+K7-L7 -> 0 | S7: 95.33
A8: 5 | B8: 45843 | G8: =E8*F8 -> 0 | J8: =H8*I8 -> 0 | K8: =G8+J8 -> 0 | L8: =H8+K8 -> 0 | M8: =M7+K8-L8 -> 0
A9: 6 | B9: 45844 | G9: =E9*F9 -> 0 | J9: =H9*I9 -> 0 | K9: =G9+J9 -> 0 | L9: 0 | M9: =M8+K9-L9 -> 0
A10: 7 | B10: 45845 | G10: =E10*F10 -> 0 | J10: =H10*I10 -> 0 | K10: =G10+J10 -> 0 | L10: 0 | M10: =M9+K10-L10 -> 0
A11: 8 | B11: 45846 | E11: 476.64 | F11: 104.9 | G11: =E11*F11 -> 49999.536 | J11: =H11*I11 -> 0 | K11: =G11+J11 -> 49999.536 | L11: =H11+K11 -> 49999.536 | M11: =M10+K11-L11 -> 0 | N11: BT
A12: 9 | B12: 45847 | G12: =E12*F12 -> 0 | J12: =H12*I12 -> 0 | K12: =G12+J12 -> 0 | L12: 0 | M12: =M11+K12-L12 -> 0
A13: 10 | B13: 45848 | E13: 476.64 | F13: 104.9 | G13: =E13*F13 -> 49999.536 | J13: =H13*I13 -> 0 | K13: =G13+J13 -> 49999.536 | L13: =H13+K13 -> 49999.536 | M13: =M12+K13-L13 -> 0 | N13: BT
A14: 11 | B14: 45849 | G14: =E14*F14 -> 0 | J14: =H14*I14 -> 0 | K14: =G14+J14 -> 0 | L14: =H14+K14 -> 0 | M14: =M13+K14-L14 -> 0
A15: 12 | B15: 45850 | E15: 190.65 | F15: 104.9 | G15: =E15*F15 -> 19999.185 | J15: =H15*I15 -> 0 | K15: =G15+J15 -> 19999.185 | L15: =H15+K15 -> 19999.185 | M15: =M14+K15-L15 -> 0 | N15: BT
A16: 13 | B16: 45851 | E16: 95.33 | F16: 104.9 | G16: =E16*F16 -> 10000.117 | J16: =H16*I16 -> 0 | K16: =G16+J16 -> 10000.117 | L16: =H16+K16 -> 10000.117 | M16: =M15+K16-L16 -> 0 | N16: BT
A17: 14 | B17: 45852 | E17: 190.65 | F17: 104.9 | G17: =E17*F17 -> 19999.185 | J17: =H17*I17 -> 0 | K17: =G17+J17 -> 19999.185 | L17: =H17+K17 -> 19999.185 | M17: =M16+K17-L17 -> 0 | N17: BT
A18: 15 | B18: 45853 | E18: 0 | F18: 0 | G18: =E18*F18 -> 0 | J18: =H18*I18 -> 0 | K18: =G18+J18 -> 0 | L18: =H18+K18 -> 0 | M18: =M17+K18-L18 -> 0
A19: 16 | B19: 45854 | E19: 190.66 | F19: 104.9 | G19: =E19*F19 -> 20000.234 | J19: =H19*I19 -> 0 | K19: =G19+J19 -> 20000.234 | L19: =H19+K19 -> 20000.234 | M19: =M18+K19-L19 -> 0 | N19: BT
A20: 17 | B20: 45855 | E20: 285.99 | F20: 104.9 | G20: =E20*F20 -> 30000.351 | J20: =H20*I20 -> 0 | K20: =G20+J20 -> 30000.351 | L20: =H20+K20 -> 30000.351 | M20: =M19+K20-L20 -> 0 | N20: BT
A21: 18 | B21: 45856 | G21: =E21*F21 -> 0 | J21: =H21*I21 -> 0 | K21: =G21+J21 -> 0 | L21: =H21+K21 -> 0 | M21: =M20+K21-L21 -> 0
A22: 19 | B22: 45857 | G22: =E22*F22 -> 0 | J22: =H22*I22 -> 0 | K22: =G22+J22 -> 0 | L22: =H22+K22 -> 0 | M22: =M21+K22-L22 -> 0
A23: 20 | B23: 45858 | G23: =E23*F23 -> 0 | J23: =H23*I23 -> 0 | K23: =G23+J23 -> 0 | L23: =H23+K23 -> 0 | M23: =M22+K23-L23 -> 0
A24: 21 | B24: 45859 | G24: =E24*F24 -> 0 | J24: =H24*I24 -> 0 | K24: =G24+J24 -> 0 | L24: =H24+K24 -> 0 | M24: =M23+K24-L24 -> 0
A25: 22 | B25: 45860 | E25: 190.66 | F25: 104.9 | G25: =E25*F25 -> 20000.234 | J25: =H25*I25 -> 0 | K25: =G25+J25 -> 20000.234 | L25: =H25+K25 -> 20000.234 | M25: =M24+K25-L25 -> 0 | N25: BT
A26: 23 | B26: 45861 | E26: 190.66 | F26: 104.9 | G26: =E26*F26 -> 20000.234 | J26: =H26*I26 -> 0 | K26: =G26+J26 -> 20000.234 | L26: =+K26 -> 20000.234 | M26: =M25+K26-L26 -> 0 | N26: BT
A27: 24 | B27: 45862 | G27: =E27*F27 -> 0 | J27: =H27*I27 -> 0 | K27: =G27+J27 -> 0 | L27: =+K27 -> 0 | M27: =M26+K27-L27 -> 0
A28: 25 | B28: 45863 | E28: 95.33 | F28: 104.9 | G28: =E28*F28 -> 10000.117 | J28: =H28*I28 -> 0 | K28: =G28+J28 -> 10000.117 | L28: =+K28 -> 10000.117 | M28: =M27+K28-L28 -> 0 | N28: BT
A29: 26 | B29: 45864 | G29: =E29*F29 -> 0 | J29: =H29*I29 -> 0 | K29: =G29+J29 -> 0 | L29: =+K29 -> 0 | M29: =M28+K29-L29 -> 0
A30: 27 | B30: 45865 | G30: =E30*F30 -> 0 | J30: =H30*I30 -> 0 | K30: =G30+J30 -> 0 | L30: =+K30 -> 0 | M30: =M29+K30-L30 -> 0
A31: 28 | B31: 45866 | G31: =E31*F31 -> 0 | J31: =H31*I31 -> 0 | K31: =G31+J31 -> 0 | L31: =+K31 -> 0 | M31: =M30+K31-L31 -> 0
A32: 29 | B32: 45867 | G32: =E32*F32 -> 0 | J32: =H32*I32 -> 0 | K32: =G32+J32 -> 0 | L32: =+K32 -> 0 | M32: =M31+K32-L32 -> 0
A33: 30 | B33: 45868 | G33: =E33*F33 -> 0 | J33: =H33*I33 -> 0 | K33: =G33+J33 -> 0 | L33: =+K33 -> 0 | M33: =M32+K33-L33 -> 0
A34: 31 | G34: =E34*F34 -> 0 | J34: =H34*I34 -> 0 | K34: =G34+J34 -> 0 | L34: =+K34 -> 0 | M34: 0
E35: =SUM(E4:E34) -> 2859.86 | G35: =SUM(G4:G34) -> 299999.31 | H35: =SUM(H4:H34) -> 0 | J35: =SUM(J4:J34) -> 0 | K35: =SUM(K4:K34) -> 299999.31 | L35: =SUM(L4:L34) -> 299999.31

Sheet Dindi
A1: Akarapu Balakistamma Fillling
A2: S.No | B2: Date | C2: GRN No | D2: Ind no/Bill No | E2: Diesel (Lts) | F2: Price | G2: Amount | H2: Petrol (Lts) | I2: Price | J2: Amount | K2: Total amount | L2: Amount paid | M2: As on Date | N2: Remarks
A3: Opening Balance | M3: 0
A4: 1 | B4: 45839 | G4: =E4*F4 -> 0 | H4: 0 | I4: 0 | J4: =H4*I4 -> 0 | K4: =G4+J4 -> 0 | L4: =+K4 -> 0 | M4: 0
A5: 2 | B5: 45840 | G5: =E5*F5 -> 0 | H5: 0 | I5: 0 | J5: =H5*I5 -> 0 | K5: =G5+J5 -> 0 | L5: =+K5 -> 0 | M5: 0
