Workbook

Sheet Jan-26
A1: S.no | B1: Site Name | C1: Bunk Name | D1: Diesel(Liters) | E1: Diesel Amount | F1: Petrol(Liters) | G1: Petrol Amount | H1: Total Amount | I1: Opening Blance | J1: Amount Paid | K1: Closing Balances
A2: 1 | B2: Khammam-1 | C2: Divya laxmi ganapathi | D2: =+'Khammam-1'!E38 -> 55934.28 | E2: =+'Khammam-1'!G38 -> 5351791.9 | F2: =+'Khammam-1'!H38 -> 295 | G2: =+'Khammam-1'!J38 -> 31700.7 | H2: =E2+G2 -> 5383492.6 | I2: =+'Khammam-1'!K3 -> 3956161.3 | J2: =+'Khammam-1'!L38 -> 6503593 | K2: =H2+I2-J2 -> 2836061
A3: 2 | B3: Khammam-2 | C3: Jayasai union bunk | D3: =+'Khammam-2'!E36 -> 62644.369 | E3: =+'Khammam-2'!G36 -> 5995066.1 | F3: =+'Khammam-2'!H36 -> 816.52 | G3: =+'Khammam-2'!J36 -> 87759.57 | H3: =E3+G3 -> 6082825.7 | I3: =+'Khammam-2'!K3 -> 3669815.6 | J3: =+'Khammam-2'!L36 -> 5316864.5 | K3: =H3+I3-J3 -> 4435776.8
A4: 3 | B4: Khammam-3 | C4: JSASFuel Genie India Pvt.Ltd | D4: =+'Khammam-3'!E35 -> 12000 | E4: =+'Khammam-3'!G35 -> 1136400 | F4: =+'Khammam-3'!H35 -> 0 | G4: =+'Khammam-3'!J35 -> 0 | H4: =E4+G4 -> 1136400 | I4: =+'Khammam-3'!M3 -> 0 | J4: =+'Khammam-3'!L35 -> 1016000 | K4: =H4+I4-J4 -> 120400
A5: 4 | B5: Jadcherla-3 | C5: JSASFuel Genie India Pvt.Ltd | D5: =+'Jadcherla-3'!E35 -> 7500 | E5: =+'Jadcherla-3'!G35 -> 715725 | F5: =+'Jadcherla-3'!H35 -> 0 | G5: =+'Jadcherla-3'!J35 -> 0 | H5: =E5+G5 -> 715725 | I5: =+'Jadcherla-3'!M3 -> 1183331.5 | J5: =+'Jadcherla-3'!L35 -> 1600000 | K5: =H5+I5-J5 -> 299056.5
A6: 5 | B6: Jadcherla-4 | C6: Shree Poornima F/S | D6: =+'Jadcherla-4'!E35 -> 0 | E6: =+'Jadcherla-4'!G35 -> 0 | F6: =+'Jadcherla-4'!H35 -> 150 | G6: =+'Jadcherla-4'!J35 -> 16215 | H6: =E6+G6 -> 16215 | I6: =+'Jadcherla-4'!M3 -> 5405 | J6: =+'Jadcherla-4'!L35 -> 16215 | K6: =H6+I6-J6 -> 5405
A7: 6 | B7: Dindi | C7: Akarapu Balakistamma Fillling | D7: =+Dindi!E35 -> 36.13 | E7: =+Dindi!G35 -> 3498.4679 | F7: =+Dindi!H35 -> 0 | G7: =+Dindi!J35 -> 0 | H7: =E7+G7 -> 3498.4679 | I7: =+Dindi!M3 -> 0 | J7: =+Dindi!L35 -> 3498.4679 | K7: =H7+I7-J7 -> 0
A8: 7 | B8: Devarkhadra-1 | C8: Kurumurthy Swami F/S | D8: =+Devarakhadra!E35 -> 90 | E8: =+Devarakhadra!G35 -> 8739 | F8: =+Devarakhadra!H35 -> 42.58 | G8: =+Devarakhadra!J35 -> 4633.9814 | H8: =E8+G8 -> 13372.981 | I8: =+Devarakhadra!M3 -> 5026.311 | J8: =+Devarakhadra!L35 -> 12543 | K8: =H8+I8-J8 -> 5856.2924
A9: 8 | B9: Devarkhadra-3 | C9: JSASFuel Genie India Pvt.Ltd | D9: =+'Devarakhadra-2'!E35 -> 0 | E9: =+'Devarakhadra-2'!G35 -> 0 | F9: =+'Devarakhadra-2'!H35 -> 0 | G9: =+'Devarakhadra-2'!I35 -> 0 | H9: =E9+G9 -> 0 | I9: =+'Devarakhadra-2'!M3 -> 0 | J9: =+'Devarakhadra-2'!L35 -> 0 | K9: =+'Devarakhadra-2'!M34 -> 0
A10: 9 | B10: Madanapalli | D10: =+'Madana palli'!E35 -> 20.52 | E10: =+'Madana palli'!G35 -> 1999.2636 | F10: =+'Madana palli'!H35 -> 16.92 | G10: =+'Madana palli'!J35 -> 1854.6012 | H10: =E10+G10 -> 3853.8648 | I10: =+'Madana palli'!M3 -> 0 | J10: =+'Madana palli'!L35 -> 3853.8648 | K10: =+'Devarakhadra-2'!M35 -> 0
A11: 10 | B11: Amalapuram | C11: Sathya Filling Station | D11: =+Amalapuram!E38 -> 284.37 | E11: =+Amalapuram!G38 -> 26054.425 | F11: =+Amalapuram!H38 -> 67.52 | G11: =+Amalapuram!J38 -> 6736.69 | H11: =E11+G11 -> 32791.115 | I11: =+Amalapuram!M3 -> 0 | J11: =+Amalapuram!L38 -> 32791.44 | K11: =H11+I11-J11 -> -0.325
A12: 11 | B12: YG Gudda-1 | C12: Pallavi Petrolium | D12: =+'YG Gudda '!E36 -> 0 | E12: =+'YG Gudda '!G36 -> 0 | F12: =+'YG Gudda '!H36 -> 0 | G12: =+'YG Gudda '!J36 -> 0 | H12: =E12+G12 -> 0 | I12: ='YG Gudda '!K3 -> 21.541514 | J12: =+'YG Gudda '!L36 -> 21.54 | K12: =H12+I12-J12 -> 0.0015138002
A13: 12 | B13: YG Gudda-2 | C13: Pankaja HP Fuel Center | D13: =+'YG Gudda-2'!E36 -> 9620 | E13: =+'YG Gudda-2'!G36 -> 878594.6 | F13: =+'YG Gudda-2'!H36 -> 365 | G13: =+'YG Gudda-2'!J36 -> 37693.55 | H13: =E13+G13 -> 916288.15 | I13: =+'YG Gudda-2'!M3 -> 713890.2 | J13: =+'YG Gudda-2'!L36 -> 1151841.5 | K13: =H13+I13-J13 -> 478336.85
A14: 13 | B14: Hosadurga-1 | C14: Merchant Petroliums | D14: =+Hosadurga!E35 -> 0 | E14: =+Hosadurga!G35 -> 0 | F14: =+Hosadurga!H35 -> 0 | G14: =+Hosadurga!J35 -> 0 | H14: =E14+G14 -> 0 | I14: =+Hosadurga!K3 -> 2258.6 | J14: =+Hosadurga!L35 -> 0 | K14: =H14+I14-J14 -> 2258.6
A15: 14 | B15: Hosadurga-2 | C15: Shree Veeraprathap Fuel | D15: =+'Hosadurga -2'!E35 -> 6000 | E15: =+'Hosadurga -2'!G35 -> 549300 | F15: =+'Hosadurga -2'!H35 -> 280 | G15: =+'Hosadurga -2'!J35 -> 29044.4 | H15: =+'Hosadurga -2'!K35 -> 578344.4 | I15: =+'Hosadurga -2'!K3 -> 197553.8 | J15: =+'Hosadurga -2'!L35 -> 450000 | K15: =H15+I15-J15 -> 325898.2
A16: 15 | B16: Malebennuru(KUWSDB) | C16: Sri Ramanjuneya Service Station | D16: =+'Malebenur(KUWSDB)'!E37 -> 5549.91 | E16: =+'Malebenur(KUWSDB)'!G37 -> 511543.2 | F16: =+'Malebenur(KUWSDB)'!H37 -> 214 | G16: =+'Malebenur(KUWSDB)'!J37 -> 22263.12 | H16: =E16+G16 -> 533806.32 | I16: =+'Malebenur(KUWSDB)'!K3 -> 202357.36 | J16: =+'Malebenur(KUWSDB)'!L37 -> 522465.12 | K16: =H16+I16-J16 -> 213698.56
A17: 16 | B17: kadur | C17: Vishal Service Station | D17: =+Kadur!E35 -> 0 | E17: =+Kadur!G35 -> 0 | F17: =+Kadur!H35 -> 140 | G17: =+Kadur!J35 -> 14597.8 | H17: =E17+G17 -> 14597.8 | I17: =+Kadur!K3 -> 210029.23 | J17: =+Kadur!L35 -> 210000 | K17: =H17+I17-J17 -> 14627.031
A18: 17 | B18: Hiriyur(VJNL) | C18: Sri Balaji Agencies | D18: =+'Hiriyur(VJNL)'!E35 -> 2300 | E18: =+'Hiriyur(VJNL)'!G35 -> 212198 | F18: =+'Hiriyur(VJNL)'!H35 -> 210 | G18: =+'Hiriyur(VJNL)'!J35 -> 21867.3 | H18: =E18+G18 -> 234065.3 | I18: =+'Hiriyur(VJNL)'!K3 -> 438828.8 | J18: =+'Hiriyur(VJNL)'!L35 -> 453408 | K18: =H18+I18-J18 -> 219486.1
A19: 18 | B19: Chellakere(KUWSDB) | C19: Shivaganga Service Station | D19: =+'Chellakere -1'!E35 -> 3800 | E19: =+'Chellakere -1'!G35 -> 350474 | F19: =+'Chellakere -1'!H35 -> 230.04 | G19: =+'Chellakere -1'!J35 -> 23944.864 | H19: =E19+G19 -> 374418.86 | I19: =+'Chellakere -1'!K3 -> 145403.1 | J19: =+'Chellakere -1'!L35 -> 358717 | K19: =H19+I19-J19 -> 161104.96
A20: 19 | B20: Chellakere(KUWSDB)-09 | D20: =+' Chellakere-PKG-9'!E35 -> 509.99 | E20: =+' Chellakere-PKG-9'!G35 -> 47036.378 | F20: =+' Chellakere-PKG-9'!H35 -> 33.08 | G20: =+' Chellakere-PKG-9'!J35 -> 3442.9972 | H20: =E20+G20 -> 50479.375 | I20: =+' Chellakere-PKG-9'!M3 -> 0 | J20: =+' Chellakere-PKG-9'!L35 -> 50479.375 | K20: =H20+I20-J20 -> 0
A21: 20 | B21: Molakalmuru | C21: Sri Lakshmi Venkateshwara Filling Station | D21: =+Molakamuru!E35 -> 1045 | E21: =+Molakamuru!G35 -> 96369.9 | F21: =+Molakamuru!H35 -> 49.69 | G21: =+Molakamuru!J35 -> 5171.7352 | H21: =E21+G21 -> 101541.64 | I21: =+Molakamuru!K3 -> 53588.5 | J21: =+Molakamuru!L35 -> 127139.54 | K21: =H21+I21-J21 -> 27990.595
A22: 21 | B22: Chennagiri | D22: =+' Chennagiri'!E35 -> 625.92 | E22: =+' Chennagiri'!G35 -> 57616.109 | F22: =+' Chennagiri'!H35 -> 31 | G22: =+' Chennagiri'!J35 -> 3226.48 | H22: =E22+G22 -> 60842.589 | I22: =+' Chennagiri'!K3 -> 0 | J22: =+' Chennagiri'!L35 -> 60842.589 | K22: =H22+I22-J22 -> 0
A23: 22 | B23: Khanapur(PKG-3) | C23: V.V.Varde | D23: =+Khanapur!E35 -> 1989.96 | E23: =+Khanapur!G35 -> 180847.56 | F23: =+Khanapur!H35 -> 84 | G23: =+Khanapur!J35 -> 8632.68 | H23: =E23+G23 -> 189480.24 | I23: =+Khanapur!M3 -> 98982.5 | J23: =+Khanapur!L35 -> 184520 | K23: =H23+I23-J23 -> 103942.75
A24: 23 | B24: Munavalli(PKG-3)-1 | C24: Shri Daneshwari | D24: =+Munavali!E37 -> 135 | E24: =+Munavali!G37 -> 12328.2 | F24: =+Munavali!H37 -> 37 | G24: =+Munavali!J37 -> 3819.88 | H24: =E24+G24 -> 16148.08 | I24: =+Munavali!M3 -> 660530.8 | J24: =+Munavali!L37 -> 676678.88 | K24: =H24+I24-J24 -> 0.0019999997
A25: 24 | B25: Munavalli(PKG-3)-2 | D25: =+'Munavali-2'!E37 -> 6730 | E25: =+'Munavali-2'!G37 -> 616064.2 | F25: =+'Munavali-2'!H37 -> 201 | G25: =+'Munavali-2'!J37 -> 20799.48 | H25: =E25+G25 -> 636863.68 | I25: =+'Munavali-2'!M3 -> 0 | J25: =+'Munavali-2'!L37 -> 293246 | K25: =H25+I25-J25 -> 343617.68
A26: 25 | B26: Borgaon(PKG-3) | C26: Aadisagar Petrolium | D26: =+Borgaon!E35 -> 4415 | E26: =+Borgaon!G35 -> 405164.55 | F26: =+Borgaon!H35 -> 94 | G26: =+Borgaon!J35 -> 9750.62 | H26: =E26+G26 -> 414915.17 | I26: =+Borgaon!K3 -> 120395.81 | J26: =+Borgaon!L35 -> 420000 | K26: =H26+I26-J26 -> 115310.98
A27: 26 | B27: Ugar,Kudichi(PKG-3) | C27: Shiri Bhrhmanath Petrolium | D27: =+'Ugar,Khagwad,Kudichi'!E35 -> 3546.78 | E27: =+'Ugar,Khagwad,Kudichi'!G35 -> 326055.49 | F27: =+'Ugar,Khagwad,Kudichi'!H35 -> 280 | G27: =+'Ugar,Khagwad,Kudichi'!J35 -> 29089.2 | H27: =E27+G27 -> 355144.69 | I27: =+'Ugar,Khagwad,Kudichi'!M3 -> 292365.86 | J27: =+'Ugar,Khagwad,Kudichi'!L35 -> 496000 | K27: =H27+I27-J27 -> 151510.55
A28: 27 | B28: Kabbur(PKG-3) | C28: Shri Jai Hanuman Petrolium | D28: =+Kabbur!E35 -> 103 | E28: =+Kabbur!G35 -> 9433.77 | F28: =+Kabbur!H35 -> 32.8 | G28: =+Kabbur!J35 -> 3395.784 | H28: =E28+G28 -> 12829.554 | I28: 0 | J28: =+Kabbur!L35 -> 12829.554 | K28: =H28+I28-J28 -> 0
A29: 28 | B29: Kumta (PKG-1) | C29: Krishma fuel station | D29: =+kumta!E35 -> 1346.59 | E29: =+kumta!G35 -> 123790.05 | F29: =+kumta!H35 -> 87.41 | G29: =+kumta!J35 -> 9087.1436 | H29: =E29+G29 -> 132877.2 | I29: 0 | J29: =+kumta!L35 -> 132877.2 | K29: =H29+I29-J29 -> 0
A30: 29 | B30: Jalgaon | C30: Sri Sai Petrol Pump | D30: =+Jalgaon!E54 -> 24100 | E30: =+Jalgaon!G54 -> 2209671 | F30: =+Jalgaon!H54 -> 272 | G30: =+Jalgaon!J54 -> 28611.68 | H30: =E30+G30 -> 2238282.7 | I30: =+Jalgaon!K3 -> 730303.78 | J30: =+Jalgaon!L54 -> 1600000 | K30: =H30+I30-J30 -> 1368586.5
A31: 30 | B31: MKBD | C31: Shree Sai Samarth Petroleum | D31: =+MKBD!E38 -> 5600 | E31: =+MKBD!G38 -> 510384 | F31: =+MKBD!H38 -> 103 | G31: =+MKBD!J38 -> 16348.87 | H31: =E31+G31 -> 526732.87 | I31: =+MKBD!K3 -> 362563.78 | J31: =+MKBD!L38 -> 523255 | K31: =H31+I31-J31 -> 366041.65
A32: 31 | B32: Haveri | C32: Shivalingeshwar Petroleum | D32: =+Haveri!E37 -> 0 | E32: =+Haveri!G37 -> 0 | F32: =+Haveri!H37 -> 0 | G32: =+Haveri!J37 -> 0 | H32: =E32+G32 -> 0 | I32: =+Haveri!M3 -> 9461.0769 | J32: =+Haveri!L37 -> 9461.08 | K32: =H32+I32-J32 -> -0.0031000001
A33: 32 | B33: Haveri | C33: M/s Magavi City Fuels | D33: =' Haveri-2'!E37 -> 4555.27 | E33: =' Haveri-2'!G37 -> 416750.85 | F33: =' Haveri-2'!H37 -> 109.93 | G33: =' Haveri-2'!J37 -> 11370.06 | H33: =E33+G33 -> 428120.91 | I33: =' Haveri-2'!M3 -> 164443.72 | J33: =+' Haveri-2'!L37 -> 441733.9 | K33: =H33+I33-J33 -> 150830.73
A34: 33 | B34: Guttal | C34: Taware filling station | D34: =+Guttal!E35 -> 0 | E34: =+Guttal!G35 -> 0 | F34: =+Guttal!H35 -> 0 | G34: =+Guttal!J35 -> 0 | H34: =E34+G34 -> 0 | I34: =+Guttal!M3 -> 336687.37 | J34: =+Guttal!L35 -> 336687.37 | K34: =H34+I34-J34 -> 0.00039999996
A35: 34 | B35: Guttal-2 | C35: Himagiri Petroleum | D35: =+' Guttal-2'!E35 -> 9282.01 | E35: =+' Guttal-2'!G35 -> 851902.88 | F35: =+' Guttal-2'!H35 -> 100 | G35: =+' Guttal-2'!J35 -> 10374 | H35: =E35+G35 -> 862276.88 | I35: =+' Guttal-2'!M3 -> 0 | J35: =+' Guttal-2'!L35 -> 330000 | K35: =H35+I35-J35 -> 532276.88
A36: 35 | B36: Rattihali | C36: Shree Siri Gowari petroliam | D36: =+Rattihali!E35 -> 0 | E36: =+Rattihali!G35 -> 0 | F36: =+Rattihali!H35 -> 0 | G36: =+Rattihali!J35 -> 0 | H36: =E36+G36 -> 0 | I36: =+Rattihali!M3 -> 6442.724 | J36: =+Rattihali!L35 -> 0 | K36: =H36+I36-J36 -> 6442.724
A37: 36 | B37: Rattihali-2 | C37: Shiva Oil Traders | D37: =+'Rattihali-2'!E37 -> 3858.6 | E37: =+'Rattihali-2'!G37 -> 354566.75 | F37: =+'Rattihali-2'!H37 -> 210 | G37: =+'Rattihali-2'!J37 -> 21932.82 | H37: =E37+G37 -> 376499.57 | I37: =+'Rattihali-2'!M3 -> 310880.3 | J37: =+'Rattihali-2'!L37 -> 525000 | K37: =H37+I37-J37 -> 162379.88
A38: 37 | B38: Gajendragada | C38: Vanasri Petrol Pump | D38: =+Gajendragada!E35 -> 40 | E38: =+Gajendragada!G35 -> 3673.2 | F38: =+Gajendragada!H35 -> 20 | G38: =+Gajendragada!J35 -> 2076 | H38: =E38+G38 -> 5749.2 | I38: =+Gajendragada!K3 -> 4500.2015 | J38: =+Gajendragada!L35 -> 0 | K38: =H38+I38-J38 -> 10249.402
A39: 38 | B39: Gokak(PKG-3) | C39: AJ Petrolinks | D39: =+'Gokak Dharwad PKG 3'!E40 -> 11885.35 | E39: =+'Gokak Dharwad PKG 3'!G40 -> 1087271.8 | F39: =+'Gokak Dharwad PKG 3'!H40 -> 339 | G39: =+'Gokak Dharwad PKG 3'!J40 -> 35055.99 | H39: =E39+G39 -> 1122327.8 | I39: =+'Gokak Dharwad PKG 3'!K3 -> 547359.48 | J39: =+'Gokak Dharwad PKG 3'!L40 -> 1231700 | K39: =H39+I39-J39 -> 437987.29
A40: 39 | B40: Hukkere | C40: TR Assocites | D40: =+' TR Associates'!E35 -> 10355.07 | E40: =+' TR Associates'!G35 -> 945624.99 | F40: =+' TR Associates'!H35 -> 20 | G40: =+' TR Associates'!J35 -> 2064.8 | H40: =E40+G40 -> 947689.79 | I40: =+' TR Associates'!M3 -> 0 | J40: =+' TR Associates'!L35 -> 300000 | K40: =H40+I40-J40 -> 647689.79
...

Sheet Sheet1
B2: S.no | C2: Site Name | D2: Bunk Name | E2: Outstannding | F2: Last Payment | G2: L.P Date | H2: Credit period in Days | I2: Next Payment Date
B3: 1 | C3: Khammam-1 | D3: Divya laxmi ganapathi | E3: =+'Jan-26'!K2 -> 2836061 | F3: 7753305 | G3: 15.12.2025 | H3: 45 | I3: 30.01.2025
B4: 2 | C4: Khammam-2 | D4: Jayasai union bunk | E4: =+'Jan-26'!K3 -> 4435776.8 | F4: 9561886 | G4: 15.12.2025 | H4: 45 | I4: 30.01.2025
B5: 3 | C5: Jadcherla-1 | D5: Sai Baba Fuel Station | E5: =+'Jan-26'!#REF! -> #REF! | F5: 307000 | G5: 15.12.2025 | H5: Close | I5: Close
B6: 4 | C6: Jadcherla-2 | D6: ADHOC FILLING STATION STATION | E6: =+'Jan-26'!#REF! -> #REF! | F6: 1123622.9 | G6: 13.12.2025 | H6: Close | I6: Close
B7: 5 | C7: Jadcherla-3 | D7: JSASFuel Genie India Pvt.Ltd | E7: =+'Jan-26'!K5 -> 299056.5 | F7: 2755171 | G7: 16.12.2025 | H7: 15 | I7: 05.01.2026
B8: 6 | C8: Dindi | D8: Akarapu Balakistamma Fillling | E8: =+'Jan-26'!K7 -> 0 | I8: C&C
B9: 7 | C9: Devarkhadra-1 | D9: Kurumurthy Swami F/S | E9: =+'Jan-26'!K8 -> 5856.2924 | F9: 55563 | G9: 16.12.2025 | H9: 10 | I9: 05.01.2026
B10: 8 | C10: Devarkhadra-3 | D10: JSASFuel Genie India Pvt.Ltd | E10: =+'Jan-26'!K9 -> 0 | F10: 66053.77 | G10: 16.12.2025 | H10: 15 | I10: 05.01.2026
B11: 9 | C11: Madanapalli | E11: =+'Jan-26'!K10 -> 0 | I11: C&C
B12: 10 | C12: Amalapuram | D12: Sathya Filling Station | E12: =+'Jan-26'!K11 -> -0.325 | I12: C&C
B13: 11 | C13: YG Gudda-1 | D13: Pallavi Petrolium | E13: =+'Jan-26'!K12 -> 0.0015138002 | F13: 25000 | G13: 16.12.2025 | H13: 10 | I13: 0
B14: 12 | C14: YG Gudda-2 | D14: Pankaja HP Fuel Center | E14: =+'Jan-26'!K13 -> 478336.85 | F14: 205413 | G14: 15.12.2025 | H14: 15 | I14: 05.01.2026
B15: 13 | C15: Hosadurga-1 | D15: Merchant Petroliums | E15: =+'Jan-26'!K14 -> 2258.6 | I15: 0
B16: 14 | C16: Hosadurga-2 | D16: Shree Veeraprathap Fuel | E16: =+'Jan-26'!K15 -> 325898.2 | F16: 551781.84 | G16: 15.12.2025 | H16: 15 | I16: 05.01.2026
B17: 15 | C17: Malebennuru(KUWSDB) | D17: Sri Ramanjuneya Service Station | E17: =+'Jan-26'!K16 -> 213698.56 | F17: 40495 | G17: 15.12.2025 | H17: 10 | I17: 27.12.2025
B18: 16 | C18: kadur | D18: Vishal Service Station | E18: =+'Jan-26'!K17 -> 14627.031 | F18: 175801 | G18: 15.12.2025 | H18: 30 | I18: 15.01.2026
B19: 17 | C19: Hiriyur(VJNL) | D19: Sri Balaji Agencies | E19: =+'Jan-26'!K18 -> 219486.1 | F19: 135912 | G19: 15.12.2025 | H19: 10 | I19: 30.12.2025
B20: 18 | C20: Chellakere(KUWSDB) | D20: Shivaganga Service Station | E20: =+'Jan-26'!K19 -> 161104.96 | F20: 58955.35 | G20: 15.12.2025 | H20: 15 | I20: 03.01.2025
B21: 19 | C21: Chellakere(KUWSDB)-09 | E21: =+'Jan-26'!K20 -> 0 | I21: C&C
B22: 20 | C22: Molakalmuru | D22: Priyanka Petroleum | E22: =+'Jan-26'!K21 -> 27990.595 | F22: New | I22: 05.01.2026
B23: 21 | C23: Chennagiri | E23: =+'Jan-26'!K22 -> 0
B24: 22 | C24: Khanapur(PKG-3) | D24: V.V.Varde | E24: =+'Jan-26'!K23 -> 103942.75 | F24: 50000 | G24: 13.12.2025 | H24: 15 | I24: 03.01.2025
B25: 23 | C25: Munavalli(PKG-3)-2 | D25: Shri Daneshwari | E25: =+'Jan-26'!K24 -> 0.0019999997 | F25: 107000 | G25: 15.12.2025 | H25: 10 | I25: 30.12.2025
B26: 24 | C26: Borgaon(PKG-3) | D26: Aadisagar Petrolium | E26: =+'Jan-26'!K26 -> 115310.98 | F26: 287043.3 | G26: 16.12.2025 | H26: 30 | I26: 15.01.2026
B27: 25 | C27: Ugar,Kudichi(PKG-3) | D27: Shiri Bhrhmanath Petrolium | E27: =+'Jan-26'!K27 -> 151510.55 | F27: 313314 | G27: 15.12.2025 | H27: 30 | I27: 15.01.2026
B28: 26 | C28: Kabbur(PKG-3) | D28: Shri Jai Hanuman Petrolium | E28: =+'Jan-26'!K28 -> 0
B29: 27 | C29: Kumta (PKG-1) | D29: Krishma fuel station | E29: =+'Jan-26'!K29 -> 0
B30: 28 | C30: Jalgaon | D30: Sri Sai Petrol Pump | E30: =+'Jan-26'!K30 -> 1368586.5 | F30: 1700000 | G30: 15.12.2025 | H30: 30 | I30: 15.01.2026
B31: 29 | C31: MKBD | D31: Shree Sai Samarth Petroleum | E31: =+'Jan-26'!K31 -> 366041.65 | F31: 461912.77 | G31: 15.12.2025 | H31: 30 | I31: 15.01.2026
B32: 30 | C32: Haveri | D32: Shivalingeshwar Petroleum | E32: =+'Jan-26'!K32 -> -0.0031000001 | F32: 224862 | G32: 12.12.2025 | H32: 10
B33: 31 | C33: Haveri | D33: M/s Magavi City Fuels | E33: =+'Jan-26'!K33 -> 150830.73 | F33: 14064 | G33: 16.12.2025 | H33: 13 | I33: 03.01.2025
B34: 32 | C34: Guttal | D34: Taware filling station | E34: =+'Jan-26'!K34 -> 0.00039999996 | F34: 50000 | G34: 24.12.2025 | H34: 7 | I34: 30.12.2025
B35: 33 | C35: Rattihali | D35: Shree Siri Gowari petroliam | E35: =+'Jan-26'!K36 -> 6442.724 | F35: 272393 | G35: 15.12.2025 | H35: 15 | I35: 30.12.2025
B36: 34 | C36: Rattihali-2 | D36: Shiva Oil Traders | E36: =+'Jan-26'!K37 -> 162379.88 | F36: New | H36: 15 | I36: 05.01.2026
B37: 35 | C37: Gajendragada | D37: Vanasri Petrol Pump | E37: =+'Jan-26'!K38 -> 10249.402 | H37: 30 | I37: 05.01.2026
B38: 36 | C38: Gokak(PKG-3) | D38: AJ Petrolinks | E38: =+'Jan-26'!K39 -> 437987.29 | F38: 1000000 | G38: 13.12.2025 | H38: 15 | I38: 05.01.2026
B39: 37 | C39: Ankaligi | D39: Shiv ganga | E39: =+'Jan-26'!K41 -> 306662.51 | F39: 361718.01 | G39: 15.12.2025 | H39: 15 | I39: 03.01.2025
B40: 38 | C40: ShankeshWAR | D40: SR Patil | E40: =+'Jan-26'!K42 -> 0 | I40: C&C
B41: 39 | C41: Talikote(PKG-1) | D41: Raykar Oil Agencies | E41: =+'Jan-26'!K43 -> 27659.595 | F41: 64000 | G41: 15.12.2025 | H41: 10 | I41: 30.12.2025
...

Sheet HO(DG)
A1: JSASFuel Genie India Pvt.Ltd
A2: S.No | B2: Date | C2: GRN No | D2: Ind No/Bill No | E2: Diesel (Lts) | F2: Price | G2: Amount | H2: Petrol (Lts) | I2: Price | J2: Amount | K2: Total amount | L2: Amount paid | M2: As on date | N2: Remarks
A3: Opening Balance | M3: 16292.058 | O3: 2623243.4
A4: 1 | B4: 46023 | G4: =E4*F4 -> 0 | H4: 0 | I4: 0 | J4: =H4*I4 -> 0 | K4: =G4+J4 -> 0 | L4: 0 | M4: =M3+K4-L4 -> 16292.058
A5: 2 | B5: 46024 | G5: =E5*F5 -> 0 | H5: 0 | I5: 0 | J5: =H5*I5 -> 0 | K5: =G5+J5 -> 0 | L5: 0 | M5: =M4+K5-L5 -> 16292.058
A6: 3 | B6: 46025 | G6: =E6*F6 -> 0 | H6: 0 | I6: 0 | J6: =H6*I6 -> 0 | K6: =G6+J6 -> 0 | L6: 0 | M6: =M5+K6-L6 -> 16292.058
A7: 4 | B7: 46026 | G7: =E7*F7 -> 0 | H7: 0 | I7: 0 | J7: =H7*I7 -> 0 | K7: =G7+J7 -> 0 | L7: 0 | M7: =M6+K7-L7 -> 16292.058 | P7: 5679
A8: 5 | B8: 46027 | G8: =E8*F8 -> 0 | H8: 0 | I8: 0 | J8: =H8*I8 -> 0 | K8: =G8+J8 -> 0 | L8: 0 | M8: =M7+K8-L8 -> 16292.058
A9: 6 | B9: 46028 | G9: =E9*F9 -> 0 | H9: 0 | I9: 0 | J9: =H9*I9 -> 0 | K9: =G9+J9 -> 0 | L9: 0 | M9: =M8+K9-L9 -> 16292.058
A10: 7 | B10: 46029 | G10: =E10*F10 -> 0 | H10: 0 | I10: 0 | J10: =H10*I10 -> 0 | K10: =G10+J10 -> 0 | L10: 0 | M10: =M9+K10-L10 -> 16292.058
A11: 8 | B11: 46030 | D11: 2 | E11: 200 | F11: 95.83 | G11: =E11*F11 -> 19166 | H11: 0 | I11: 0 | J11: =H11*I11 -> 0 | K11: =G11+J11 -> 19166 | L11: 0 | M11: =M10+K11-L11 -> 35458.058
A12: 9 | B12: 46031 | G12: =E12*F12 -> 0 | H12: 0 | I12: 0 | K12: =G12+J12 -> 0 | L12: 0 | M12: =M11+K12-L12 -> 35458.058
A13: 10 | B13: 46032 | G13: =E13*F13 -> 0 | H13: 0 | I13: 0 | K13: =G13+J13 -> 0 | L13: 0 | M13: =M12+K13-L13 -> 35458.058
A14: 11 | B14: 46033 | G14: =E14*F14 -> 0 | H14: 0 | I14: 0 | K14: =G14+J14 -> 0 | L14: 0 | M14: =M13+K14-L14 -> 35458.058 | P14: 1905988 | Q14: =P14-M14 -> 1870529.9
A15: 12 | B15: 46034 | G15: =E15*F15 -> 0 | H15: 0 | I15: 0 | K15: =G15+J15 -> 0 | L15: 0 | M15: =M14+K15-L15 -> 35458.058
A16: 13 | B16: 46035 | G16: =E16*F16 -> 0 | H16: 0 | I16: 0 | J16: =H16*I16 -> 0 | K16: =G16+J16 -> 0 | L16: 0 | M16: =M15+K16-L16 -> 35458.058
A17: 14 | B17: 46036 | G17: =E17*F17 -> 0 | H17: 0 | I17: 0 | J17: =H17*I17 -> 0 | K17: =G17+J17 -> 0 | L17: 0 | M17: =M16+K17-L17 -> 35458.058
A18: 15 | B18: 46037 | E18: 193.68 | F18: 95.83 | G18: =E18*F18 -> 18560.354 | H18: 0 | I18: 0 | J18: =H18*I18 -> 0 | K18: =G18+J18 -> 18560.354 | L18: 0 | M18: =M17+K18-L18 -> 54018.413
A19: 16 | B19: 46038 | G19: =E19*F19 -> 0 | H19: 0 | I19: 0 | J19: =H19*I19 -> 0 | K19: =G19+J19 -> 0 | L19: 0 | M19: =M18+K19-L19 -> 54018.413
A20: 17 | B20: 46039 | G20: =E20*F20 -> 0 | J20: =H20*I20 -> 0 | K20: =G20+J20 -> 0 | L20: 0 | M20: =M19+K20-L20 -> 54018.413
A21: 18 | B21: 46040 | G21: =E21*F21 -> 0 | J21: =H21*I21 -> 0 | K21: =G21+J21 -> 0 | L21: 0 | M21: =M20+K21-L21 -> 54018.413
A22: 19 | B22: 46041 | G22: =E22*F22 -> 0 | J22: =H22*I22 -> 0 | K22: =G22+J22 -> 0 | L22: 54000 | M22: =M21+K22-L22 -> 18.4127
A23: 20 | B23: 46042 | G23: =E23*F23 -> 0 | J23: =H23*I23 -> 0 | K23: =G23+J23 -> 0 | M23: =M22+K23-L23 -> 18.4127
A24: 21 | B24: 46043 | G24: =E24*F24 -> 0 | J24: =H24*I24 -> 0 | K24: =G24+J24 -> 0 | M24: =M23+K24-L24 -> 18.4127
A25: 22 | B25: 46044 | G25: =E25*F25 -> 0 | J25: =H25*I25 -> 0 | K25: =G25+J25 -> 0 | M25: =M24+K25-L25 -> 18.4127
A26: 23 | B26: 46045 | E26: 60 | F26: 95.7 | G26: =E26*F26 -> 5742 | J26: =H26*I26 -> 0 | K26: =G26+J26 -> 5742 | L26: 5742 | M26: =M25+K26-L26 -> 18.4127
A27: 24 | B27: 46046 | E27: 160 | F27: 95.83 | G27: =E27*F27 -> 15332.8 | J27: =H27*I27 -> 0 | K27: =G27+J27 -> 15332.8 | M27: =M26+K27-L27 -> 15351.213
A28: 25 | B28: 46047 | G28: =E28*F28 -> 0 | J28: =H28*I28 -> 0 | K28: =G28+J28 -> 0 | M28: =M27+K28-L28 -> 15351.213
A29: 26 | B29: 46048 | G29: =E29*F29 -> 0 | J29: =H29*I29 -> 0 | K29: =G29+J29 -> 0 | M29: =M28+K29-L29 -> 15351.213
A30: 27 | B30: 46049 | G30: =E30*F30 -> 0 | J30: =H30*I30 -> 0 | K30: =G30+J30 -> 0 | M30: =M29+K30-L30 -> 15351.213
A31: 28 | B31: 46050 | G31: =E31*F31 -> 0 | J31: =H31*I31 -> 0 | K31: =G31+J31 -> 0 | M31: =M30+K31-L31 -> 15351.213
A32: 29 | B32: 46051 | G32: =E32*F32 -> 0 | J32: =H32*I32 -> 0 | K32: =G32+J32 -> 0 | M32: =M31+K32-L32 -> 15351.213
A33: 30 | B33: 46052 | G33: =E33*F33 -> 0 | J33: =H33*I33 -> 0 | K33: =G33+J33 -> 0 | M33: =M32+K33-L33 -> 15351.213
A34: 31 | B34: 46053 | E34: 180 | F34: 95.83 | G34: =E34*F34 -> 17249.4 | J34: =H34*I34 -> 0 | K34: =G34+J34 -> 17249.4 | L34: 0 | M34: =M33+K34-L34 -> 32600.613 | O34: 2669494 | P34: =O34-M34 -> 2636893.4
E35: 0 | F35: 0 | G35: =E35*F35 -> 0 | J35: =H35*I35 -> 0 | K35: =G35+J35 -> 0 | M35: =M34+K35-L35 -> 32600.613
E36: =SUM(E4:E34) -> 793.68 | G36: =SUM(G4:G34) -> 76050.554 | H36: =SUM(H4:H34) -> 0 | J36: =SUM(J4:J34) -> 0 | K36: =SUM(K4:K34) -> 76050.554 | L36: =SUM(L4:L34) -> 59742
M45: 2408309
M46: 5327.86
M47: =M45-M46 -> 2402981.1

Sheet Sheet2
A2: S.No | B2: NAme | C2: Lacation | D2: Card Number | E2: Card Number | F2: Category | G2: 1st Jan | I2: 2nd Jan | J2: 3rd Jan | K2: 4th Jan | L2: 5th Jan | M2: 6th Jan | N2: 7th Jan | O2: 8th Jan | P2: 9th Jan | Q2: 10th Jan | R2: 11th Jan | S2: 12th Jan | T2: 13th Jan | U2: 14th Jan | V2: 15th Jan | W2: 16th Jan | X2: 17th Jan | Y2: 18th Jan | Z2: 19th Jan | AA2: 20th Jan | AB2: 21st Jan | AC2: 22nd Jan | AD2: 23rd Jan | AE2: 24th Jan | AF2: 25th Jan | AG2: 26th Jan | AH2: 27th Jan | AI2: 28th Jan | AJ2: 29th Jan | AK2: 30th Jan | AL2: 31st Jan | AM2: Total
F3: Diesel
A4: 1 | B4: Rambabu | C4: HO(Two Wheeler) | D4: FC3450563999 | E4: Diesel | F4: 0 | G4: 0 | H4: 0 | I4: 0 | J4: 0 | K4: 0 | L4: 0 | M4: 0 | N4: 0 | O4: 0 | P4: 0 | Q4: 0 | R4: 0 | S4: 0 | T4: 0 | U4: 0 | V4: 0 | W4: 0 | X4: 5.22 | Y4: 0 | Z4: 0 | AA4: 0 | AB4: 0 | AC4: 0 | AD4: 60 | AE4: 0 | AF4: 0 | AG4: 0 | AH4: 4.56 | AI4: 0 | AJ4: 0 | AK4: 0 | AL4: 0 | AM4: =SUM(F4:AL4) -> 69.78
E5: Petrol | F5: 0 | G5: 4.69 | H5: 0 | I5: 0 | J5: 0 | K5: 0 | L5: 0 | M5: 0 | N5: 3.91 | O5: 0 | P5: 6.98 | Q5: 0 | R5: 0 | S5: 0 | T5: 0 | U5: 0 | V5: 0 | W5: 0 | X5: 0 | Y5: 0 | Z5: 0 | AB5: 0 | AC5: 0 | AD5: 0 | AE5: 0 | AF5: 0 | AG5: 0 | AH5: 0 | AI5: 0 | AJ5: 0 | AK5: 0 | AL5: 0 | AM5: =SUM(F5:AL5) -> 15.58
A6: 2 | B6: Hanumanth Rao | C6: HO | D6: FC3450676131 | E6: Diesel | F6: 0 | G6: 0 | H6: 0 | I6: 0 | J6: 0 | K6: 0 | L6: 0 | M6: 0 | N6: 0 | O6: 0 | P6: 0 | Q6: 0 | R6: 0 | S6: 0 | T6: 0 | U6: 0 | V6: 0 | W6: 0 | X6: 0 | Y6: 0 | Z6: 0 | AA6: 0 | AB6: 0 | AC6: 0 | AD6: 0 | AE6: 0 | AF6: 0 | AG6: 0 | AH6: 0 | AI6: 0 | AJ6: 0 | AK6: 0 | AL6: 0 | AM6: =SUM(F6:AL6) -> 0
E7: Petrol | F7: 0 | G7: 0 | H7: 0 | I7: 0 | J7: 0 | K7: 0 | L7: 0 | M7: 0 | N7: 0 | O7: 0 | P7: 0 | Q7: 0 | R7: 0 | S7: 0 | T7: 0 | U7: 0 | V7: 0 | W7: 0 | X7: 0 | Y7: 0 | Z7: 0 | AB7: 0 | AC7: 0 | AD7: 0 | AE7: 0 | AF7: 0 | AG7: 0 | AH7: 0 | AI7: 0 | AJ7: 0 | AK7: 0 | AL7: 0 | AM7: =SUM(F7:AL7) -> 0
A8: 3 | B8: Radhakrishna | C8: HO | D8: FC8000207658 | E8: Diesel | F8: 0 | G8: 0 | H8: 0 | I8: 0 | J8: 33.44 | K8: 0 | L8: 0 | M8: 0 | N8: 0 | O8: 0 | P8: 0 | Q8: 0 | R8: 35.53 | S8: 0 | T8: 0 | U8: 0 | V8: 0 | W8: 0 | X8: 0 | Y8: 0 | Z8: 0 | AA8: 0 | AB8: 33.44 | AC8: 0 | AD8: 0 | AE8: 0 | AF8: 0 | AG8: 0 | AH8: 0 | AI8: 0 | AJ8: 0 | AK8: 0 | AL8: 0 | AM8: =SUM(F8:AL8) -> 102.41
E9: Petrol | F9: 0 | G9: 0 | H9: 0 | I9: 0 | J9: 0 | K9: 0 | L9: 0 | M9: 0 | N9: 0 | O9: 0 | P9: 0 | Q9: 0 | R9: 0 | S9: 0 | T9: 0 | U9: 0 | V9: 0 | W9: 0 | X9: 0 | Y9: 0 | Z9: 0 | AB9: 0 | AC9: 0 | AD9: 0 | AE9: 0 | AF9: 0 | AG9: 0 | AH9: 0 | AI9: 0 | AJ9: 0 | AK9: 0 | AL9: 0 | AM9: =SUM(F9:AL9) -> 0
A10: 4 | B10: VIjay | C10: HO | D10: FC3450698859 | E10: Diesel | F10: 0 | G10: 0 | H10: 0 | I10: 0 | J10: 0 | K10: 0 | L10: 0 | M10: 0 | N10: 0 | O10: 0 | P10: 49.22 | Q10: 0 | R10: 0 | S10: 0 | T10: 0 | U10: 54.57 | V10: 0 | W10: 0 | X10: 0 | Y10: 0 | Z10: 0 | AA10: 0 | AB10: 0 | AC10: 0 | AD10: 49.8 | AE10: 0 | AF10: 0 | AG10: 0 | AH10: 0 | AI10: 0 | AJ10: 0 | AK10: 0 | AL10: 0 | AM10: =SUM(F10:AL10) -> 153.59
E11: Petrol | F11: 0 | G11: 0 | H11: 0 | I11: 0 | J11: 0 | K11: 0 | L11: 0 | M11: 0 | N11: 0 | O11: 0 | P11: 0 | Q11: 0 | R11: 0 | S11: 0 | T11: 0 | U11: 0 | V11: 0 | W11: 0 | X11: 0 | Y11: 0 | Z11: 0 | AB11: 0 | AC11: 0 | AD11: 0 | AE11: 0 | AF11: 0 | AG11: 0 | AH11: 0 | AI11: 0 | AJ11: 0 | AK11: 0 | AL11: 0 | AM11: =SUM(F11:AL11) -> 0
A12: 5 | B12: Client | C12: Hiriyur | D12: FC3450698864 | E12: Diesel | F12: 0 | G12: 0 | H12: 0 | I12: 0 | J12: 0 | K12: 0 | L12: 0 | M12: 0 | N12: 86.29 | O12: 0 | P12: 0 | Q12: 0 | R12: 0 | S12: 0 | T12: 0 | U12: 0 | V12: 0 | W12: 0 | X12: 0 | Y12: 0 | Z12: 0 | AA12: 0 | AB12: 0 | AC12: 0 | AD12: 145.61 | AE12: 0 | AF12: 0 | AG12: 0 | AH12: 0 | AI12: 0 | AJ12: 0 | AK12: 0 | AL12: 0 | AM12: =SUM(F12:AL12) -> 231.9
E13: Petrol | F13: 0 | G13: 0 | H13: 0 | I13: 0 | J13: 0 | K13: 0 | L13: 0 | M13: 0 | N13: 0 | O13: 0 | P13: 0 | Q13: 0 | R13: 0 | S13: 0 | T13: 0 | U13: 0 | V13: 0 | W13: 0 | X13: 0 | Y13: 0 | Z13: 0 | AB13: 0 | AC13: 0 | AD13: 0 | AE13: 0 | AF13: 0 | AG13: 0 | AH13: 0 | AI13: 0 | AJ13: 0 | AK13: 0 | AL13: 0 | AM13: =SUM(F13:AL13) -> 0
A14: 6 | B14: Client | C14: Hosadurga | D14: FC3450698865 | E14: Diesel | F14: 0 | G14: 0 | H14: 0 | I14: 0 | J14: 0 | K14: 0 | L14: 40 | M14: 40 | N14: 0 | O14: 36 | P14: 35 | Q14: 0 | R14: 0 | S14: 0 | T14: 0 | U14: 0 | V14: 0 | W14: 45 | X14: 45 | Y14: 43.53 | Z14: 40 | AA14: 43 | AB14: 0 | AC14: 40 | AD14: 0 | AE14: 40 | AF14: 0 | AG14: 0 | AH14: 0 | AI14: 0 | AJ14: 0 | AK14: 0 | AL14: 0 | AM14: =SUM(F14:AL14) -> 447.53
E15: Petrol | F15: 0 | G15: 0 | H15: 0 | I15: 0 | J15: 0 | K15: 0 | L15: 0 | M15: 0 | N15: 0 | O15: 0 | P15: 0 | Q15: 0 | R15: 0 | S15: 0 | T15: 0 | U15: 0 | V15: 0 | W15: 0 | X15: 0 | Y15: 0 | Z15: 0 | AB15: 0 | AC15: 0 | AD15: 0 | AE15: 0 | AF15: 0 | AG15: 0 | AH15: 0 | AI15: 0 | AJ15: 0 | AK15: 0 | AL15: 0 | AM15: =SUM(F15:AL15) -> 0
G18: Diesel Price

Sheet Khammam-1
A1: Divya laxmi ganapathi
A2: S.No | B2: Date | C2: GRN No | D2: Ind No/Bill No | E2: Diesel (Lts) | F2: Price | G2: Amount | H2: Petrol (Lts) | I2: Price | J2: Amount | K2: Total amount | L2: Amount paid | M2: As 0n Date | N2: Remarks
A3: Opening Balance | K3: 3956161.3 | M3: =+K3 -> 3956161.3 | O3: 11178224
A4: 1 | B4: 46023 | G4: =E4*F4 -> 0 | K4: =G4+J4 -> 0 | L4: 0 | M4: =M3+K4-L4 -> 3956161.3
A5: 2 | B5: 46024 | E5: 2000 | F5: 95.68 | G5: =E5*F5 -> 191360 | J5: =H5*I5 -> 0 | K5: =G5+J5 -> 191360 | L5: 0 | M5: =M4+K5-L5 -> 4147521.3
A6: 3 | B6: 46025 | E6: 2000 | F6: 95.68 | G6: =E6*F6 -> 191360 | J6: =H6*I6 -> 0 | K6: =G6+J6 -> 191360 | L6: 0 | M6: =M5+K6-L6 -> 4338881.3
A7: 4 | B7: 46026 | E7: 2000 | F7: 95.68 | G7: =E7*F7 -> 191360 | J7: =H7*I7 -> 0 | K7: =G7+J7 -> 191360 | L7: 0 | M7: =M6+K7-L7 -> 4530241.3
A8: 5 | B8: 46027 | E8: 1891.06 | F8: 95.68 | G8: =E8*F8 -> 180936.62 | J8: =H8*I8 -> 0 | K8: =G8+J8 -> 180936.62 | L8: 0 | M8: =M7+K8-L8 -> 4711178
A9: 6 | B9: 46028 | E9: 4534.98 | F9: 95.68 | G9: =E9*F9 -> 433906.89 | H9: 40 | I9: 107.46 | J9: =H9*I9 -> 4298.4 | K9: =G9+J9 -> 438205.29 | L9: 0 | M9: =M8+K9-L9 -> 5149383.2
A10: 7 | B10: 46029 | E10: 6508.24 | F10: 95.68 | G10: =E10*F10 -> 622708.4 | H10: 40 | I10: 107.46 | J10: =H10*I10 -> 4298.4 | K10: =G10+J10 -> 627006.8 | L10: 0 | M10: =M9+K10-L10 -> 5776390.1
A11: 8 | B11: 46030 | E11: 3700 | F11: 95.68 | G11: =E11*F11 -> 354016 | H11: 40 | I11: 107.46 | J11: =H11*I11 -> 4298.4 | K11: =G11+J11 -> 358314.4 | L11: 0 | M11: =M10+K11-L11 -> 6134704.5
A12: 9 | B12: 46031 | E12: 2000 | F12: 95.68 | G12: =E12*F12 -> 191360 | H12: 20 | I12: 107.46 | J12: =H12*I12 -> 2149.2 | K12: =G12+J12 -> 193509.2 | L12: 0 | M12: =M11+K12-L12 -> 6328213.7
A13: 10 | B13: 46032 | E13: 4500 | F13: 95.68 | G13: =E13*F13 -> 430560 | H13: 40 | I13: 107.46 | J13: =H13*I13 -> 4298.4 | K13: =G13+J13 -> 434858.4 | L13: 0 | M13: =M12+K13-L13 -> 6763072.1
A14: 11 | B14: 46033 | G14: =E14*F14 -> 0 | J14: =H14*I14 -> 0 | K14: =G14+J14 -> 0 | L14: 0 | M14: =M13+K14-L14 -> 6763072.1
A15: 12 | B15: 46034 | G15: =E15*F15 -> 0 | J15: =H15*I15 -> 0 | K15: =G15+J15 -> 0 | L15: 0 | M15: =M14+K15-L15 -> 6763072.1
A16: 13 | B16: 46035 | G16: =E16*F16 -> 0 | J16: =H16*I16 -> 0 | K16: =G16+J16 -> 0 | L16: 0 | M16: =M15+K16-L16 -> 6763072.1
A17: 14 | B17: 46036 | G17: =E17*F17 -> 0 | J17: =H17*I17 -> 0 | K17: =G17+J17 -> 0 | L17: 0 | M17: =M16+K17-L17 -> 6763072.1
A18: 15 | B18: 46037 | G18: =E18*F18 -> 0 | J18: =H18*I18 -> 0 | K18: =G18+J18 -> 0 | L18: 0 | M18: =M17+K18-L18 -> 6763072.1
A19: 16 | B19: 46038 | G19: =E19*F19 -> 0 | J19: =H19*I19 -> 0 | K19: =G19+J19 -> 0 | L19: 0 | M19: =M18+K19-L19 -> 6763072.1
A20: 17 | B20: 46039 | G20: =E20*F20 -> 0 | J20: =H20*I20 -> 0 | K20: =G20+J20 -> 0 | L20: 0 | M20: =M19+K20-L20 -> 6763072.1
A21: 18 | B21: 46040 | G21: =E21*F21 -> 0 | J21: =H21*I21 -> 0 | K21: =G21+J21 -> 0 | L21: 0 | M21: =M20+K21-L21 -> 6763072.1
A22: 19 | B22: 46041 | E22: 5500 | F22: 95.68 | G22: =E22*F22 -> 526240 | H22: 95 | I22: 107.46 | J22: =H22*I22 -> 10208.7 | K22: =G22+J22 -> 536448.7 | L22: 6503593 | M22: =M21+K22-L22 -> 795927.75
A23: 20 | B23: 46042 | G23: =E23*F23 -> 0 | J23: =H23*I23 -> 0 | K23: =G23+J23 -> 0 | L23: 0 | M23: =M22+K23-L23 -> 795927.75
A24: 21 | B24: 46043 | E24: 1500 | F24: 95.68 | G24: =E24*F24 -> 143520 | J24: =H24*I24 -> 0 | K24: =G24+J24 -> 143520 | L24: 0 | M24: =M23+K24-L24 -> 939447.75
A25: 22 | B25: 46044 | E25: 1500 | F25: 95.68 | G25: =E25*F25 -> 143520 | J25: =H25*I25 -> 0 | K25: =G25+J25 -> 143520 | L25: 0 | M25: =M24+K25-L25 -> 1082967.8
A26: 23 | B26: 46045 | E26: 4300 | F26: 95.68 | G26: =E26*F26 -> 411424 | H26: 20 | I26: 107.46 | J26: =H26*I26 -> 2149.2 | K26: =G26+J26 -> 413573.2 | L26: 0 | M26: =M25+K26-L26 -> 1496541
A27: 24 | B27: 46046 | E27: 1500 | F27: 95.68 | G27: =E27*F27 -> 143520 | J27: =H27*I27 -> 0 | K27: =G27+J27 -> 143520 | L27: 0 | M27: =M26+K27-L27 -> 1640061
A28: 25 | B28: 46047 | E28: 1500 | F28: 95.68 | G28: =E28*F28 -> 143520 | J28: =H28*I28 -> 0 | K28: =G28+J28 -> 143520 | L28: 0 | M28: =M27+K28-L28 -> 1783581
A29: 26 | B29: 46048 | E29: 1500 | F29: 95.68 | G29: =E29*F29 -> 143520 | J29: =H29*I29 -> 0 | K29: =G29+J29 -> 143520 | L29: 0 | M29: =M28+K29-L29 -> 1927101
A30: 27 | B30: 46049 | E30: 1500 | F30: 95.68 | G30: =E30*F30 -> 143520 | J30: =H30*I30 -> 0 | K30: =G30+J30 -> 143520 | L30: 0 | M30: =M29+K30-L30 -> 2070621
A31: 28 | B31: 46050 | E31: 1500 | F31: 95.68 | G31: =E31*F31 -> 143520 | J31: =H31*I31 -> 0 | K31: =G31+J31 -> 143520 | L31: 0 | M31: =M30+K31-L31 -> 2214141
A32: 29 | B32: 46051 | E32: 2500 | F32: 95.68 | G32: =E32*F32 -> 239200 | J32: =H32*I32 -> 0 | K32: =G32+J32 -> 239200 | L32: 0 | M32: =M31+K32-L32 -> 2453341
A33: 30 | B33: 46052 | E33: 1500 | F33: 95.68 | G33: =E33*F33 -> 143520 | J33: =H33*I33 -> 0 | K33: =G33+J33 -> 143520 | L33: 0 | M33: =M32+K33-L33 -> 2596861
A34: 31 | B34: 46053 | E34: 2500 | F34: 95.68 | G34: =E34*F34 -> 239200 | K34: =G34+J34 -> 239200 | L34: 0 | M34: =M33+K34-L34 -> 2836061
A35: 32 | G35: =E35*F35 -> 0 | J35: =H35*I35 -> 0 | K35: =G35+J35 -> 0 | L35: 0 | M35: =M34+K35-L35 -> 2836061
A36: 33 | G36: =E36*F36 -> 0 | J36: =H36*I36 -> 0 | K36: =G36+J36 -> 0 | L36: 0
A37: 34 | G37: =E37*F37 -> 0 | J37: =H37*I37 -> 0 | K37: =G37+J37 -> 0
E38: =SUM(E3:E37) -> 55934.28 | G38: =SUM(G3:G37) -> 5351791.9 | H38: =SUM(H3:H37) -> 295 | J38: =SUM(J3:J37) -> 31700.7 | K38: =SUM(K4:K37) -> 5383492.6 | L38: =SUM(L3:L37) -> 6503593
E39: 62644.369
E40: 12000

Sheet Khammam-2
A1: Jayasai union bunk
A2: S.No | B2: Date | C2: GRN No | D2: Ind No/Bill No | E2: Diesel (Lts) | F2: Price | G2: Amount | H2: Petrol (Lts) | I2: Price | J2: Amount | K2: Total amount | L2: Amount paid | M2: As 0n Date | N2: Remarks
A3: Opening Balance | K3: 3669815.6 | M3: 3669815.6
A4: 1 | B4: 46023 | G4: =E4*F4 -> 0 | J4: =H4*I4 -> 0 | K4: =G4+J4 -> 0 | M4: =M3+K4-L4 -> 3669815.6 | O4: =O3+M4-N4 -> 3669815.6
A5: 2 | B5: 46024 | E5: 2700 | F5: 95.7 | G5: =E5*F5 -> 258390 | H5: 75 | I5: 107.48 | J5: =H5*I5 -> 8061 | K5: =G5+J5 -> 266451 | M5: =M4+K5-L5 -> 3936266.6
A6: 3 | B6: 46025 | E6: 5500 | F6: 95.7 | G6: =E6*F6 -> 526350 | H6: 60 | I6: 107.48 | J6: =H6*I6 -> 6448.8 | K6: =G6+J6 -> 532798.8 | M6: =M5+K6-L6 -> 4469065.4
A7: 4 | B7: 46026 | G7: =E7*F7 -> 0 | J7: =H7*I7 -> 0 | K7: =G7+J7 -> 0 | M7: =M6+K7-L7 -> 4469065.4
A8: 5 | B8: 46027 | E8: 2700 | F8: 95.7 | G8: =E8*F8 -> 258390 | H8: 60 | I8: 107.48 | J8: =H8*I8 -> 6448.8 | K8: =G8+J8 -> 264838.8 | M8: =M7+K8-L8 -> 4733904.2 | O8: 12802499
A9: 6 | B9: 46028 | E9: 2800 | F9: 95.7 | G9: =E9*F9 -> 267960 | J9: =H9*I9 -> 0 | K9: =G9+J9 -> 267960 | M9: =M8+K9-L9 -> 5001864.2
A10: 7 | B10: 46029 | G10: =E10*F10 -> 0 | J10: =H10*I10 -> 0 | K10: =G10+J10 -> 0 | M10: =M9+K10-L10 -> 5001864.2
A11: 8 | B11: 46030 | G11: =E11*F11 -> 0 | J11: =H11*I11 -> 0 | K11: =G11+J11 -> 0 | M11: =M10+K11-L11 -> 5001864.2
A12: 9 | B12: 46031 | G12: =E12*F12 -> 0 | J12: =H12*I12 -> 0 | K12: =G12+J12 -> 0 | M12: =M11+K12-L12 -> 5001864.2
A13: 10 | B13: 46032 | G13: =E13*F13 -> 0 | J13: =H13*I13 -> 0 | K13: =G13+J13 -> 0 | M13: =M12+K13-L13 -> 5001864.2
A14: 11 | B14: 46033 | G14: =E14*F14 -> 0 | J14: =H14*I14 -> 0 | K14: =G14+J14 -> 0 | M14: =M13+K14-L14 -> 5001864.2
A15: 12 | B15: 46034 | E15: 3194.369 | F15: 95.7 | G15: =E15*F15 -> 305701.11 | H15: 40 | I15: 107.48 | J15: =H15*I15 -> 4299.2 | K15: =G15+J15 -> 310000.31 | M15: =M14+K15-L15 -> 5311864.5
A16: 13 | B16: 46035 | G16: =E16*F16 -> 0 | J16: =H16*I16 -> 0 | K16: =G16+J16 -> 0 | M16: =M15+K16-L16 -> 5311864.5
A17: 14 | B17: 46036 | G17: =E17*F17 -> 0 | J17: =H17*I17 -> 0 | K17: =G17+J17 -> 0 | M17: =M16+K17-L17 -> 5311864.5
A18: 15 | B18: 46037 | G18: =E18*F18 -> 0 | J18: =H18*I18 -> 0 | K18: =G18+J18 -> 0 | M18: =M17+K18-L18 -> 5311864.5
A19: 16 | B19: 46038 | G19: =E19*F19 -> 0 | H19: 46.52 | I19: 107.48 | J19: =H19*I19 -> 4999.9696 | K19: =G19+J19 -> 4999.9696 | M19: =M18+K19-L19 -> 5316864.5
A20: 17 | B20: 46039 | D20: Round Off | G20: =E20*F20 -> 0 | J20: =H20*I20 -> 0 | K20: =G20+J20 -> 0 | M20: =M19+K20-L20 -> 5316864.5
A21: 18 | B21: 46040 | G21: =E21*F21 -> 0 | J21: =H21*I21 -> 0 | K21: =G21+J21 -> 0 | M21: =M20+K21-L21 -> 5316864.5
A22: 19 | B22: 46041 | G22: =E22*F22 -> 0 | J22: =H22*I22 -> 0 | K22: =G22+J22 -> 0 | L22: 5316861 | M22: =M21+K22-L22 -> 3.4829
B23: 46041 | L23: 3.48 | M23: =M22+K23-L23 -> 0.0029000002
A24: 20 | B24: 46042 | E24: 5000 | F24: 95.7 | G24: =E24*F24 -> 478500 | H24: 40 | I24: 107.48 | J24: =H24*I24 -> 4299.2 | K24: =G24+J24 -> 482799.2 | M24: =M23+K24-L24 -> 482799.2
A25: 21 | B25: 46043 | E25: 2700 | F25: 95.7 | G25: =E25*F25 -> 258390 | H25: 60 | I25: 107.48 | J25: =H25*I25 -> 6448.8 | K25: =G25+J25 -> 264838.8 | M25: =M24+K25-L25 -> 747638
A26: 22 | B26: 46044 | E26: =2800+2700 -> 5500 | F26: 95.7 | G26: =E26*F26 -> 526350 | H26: 60 | I26: 107.48 | J26: =H26*I26 -> 6448.8 | K26: =G26+J26 -> 532798.8 | M26: =M25+K26-L26 -> 1280436.8
A27: 23 | B27: 46045 | E27: 2850 | F27: 95.7 | G27: =E27*F27 -> 272745 | H27: 55 | I27: 107.48 | J27: =H27*I27 -> 5911.4 | K27: =G27+J27 -> 278656.4 | M27: =M26+K27-L27 -> 1559093.2
A28: 24 | B28: 46046 | E28: 5400 | F28: 95.7 | G28: =E28*F28 -> 516780 | H28: 40 | I28: 107.48 | J28: =H28*I28 -> 4299.2 | K28: =G28+J28 -> 521079.2 | M28: =M27+K28-L28 -> 2080172.4
A29: 25 | B29: 46047 | E29: 2800 | F29: 95.7 | G29: =E29*F29 -> 267960 | H29: 60 | I29: 107.48 | J29: =H29*I29 -> 6448.8 | K29: =G29+J29 -> 274408.8 | M29: =M28+K29-L29 -> 2354581.2
A30: 26 | B30: 46048 | F30: 95.7 | G30: =E30*F30 -> 0 | I30: 107.48 | J30: =H30*I30 -> 0 | K30: =G30+J30 -> 0 | M30: =M29+K30-L30 -> 2354581.2
A31: 27 | B31: 46049 | E31: 5300 | F31: 95.7 | G31: =E31*F31 -> 507210 | H31: 40 | I31: 107.48 | J31: =H31*I31 -> 4299.2 | K31: =G31+J31 -> 511509.2 | M31: =M30+K31-L31 -> 2866090.4
A32: 28 | B32: 46050 | E32: 2700 | F32: 95.7 | G32: =E32*F32 -> 258390 | H32: 60 | I32: 107.48 | J32: =H32*I32 -> 6448.8 | K32: =G32+J32 -> 264838.8 | M32: =M31+K32-L32 -> 3130929.2
A33: 29 | B33: 46051 | E33: 5500 | F33: 95.7 | G33: =E33*F33 -> 526350 | H33: 20 | I33: 107.48 | J33: =H33*I33 -> 2149.6 | K33: =G33+J33 -> 528499.6 | M33: =M32+K33-L33 -> 3659428.8
A34: 30 | B34: 46052 | E34: 5500 | F34: 95.7 | G34: =E34*F34 -> 526350 | H34: 40 | I34: 107.48 | J34: =H34*I34 -> 4299.2 | K34: =G34+J34 -> 530649.2 | M34: =M33+K34-L34 -> 4190078
A35: 31 | B35: 46053 | E35: 2500 | F35: 95.7 | G35: =E35*F35 -> 239250 | H35: 60 | I35: 107.48 | J35: =H35*I35 -> 6448.8 | K35: =G35+J35 -> 245698.8 | M35: =M34+K35-L35 -> 4435776.8
E36: =SUM(E4:E35) -> 62644.369 | G36: =SUM(G4:G35) -> 5995066.1 | H36: =SUM(H4:H35) -> 816.52 | J36: =SUM(J4:J35) -> 87759.57 | K36: =SUM(K4:K35) -> 6082825.7 | L36: =SUM(L4:L35) -> 5316864.5
K37: 5383492.6
K38: 1133100
K39: 6082825.7
K40: =SUM(K37:K39) -> 12599418

Sheet Khammam-3
A1: JSASFuel Genie India Pvt.Ltd
A2: S.No | B2: Date | C2: GRN No | D2: Ind No/Bill No | E2: Diesel (Lts) | F2: Price | G2: Amount | H2: Petrol (Lts) | I2: Price | J2: Amount | K2: Total amount | L2: Amount paid | M2: As 0n Date | N2: Remarks
A3: Opening Balance | K3: 0 | M3: 0
A4: 1 | B4: 46023 | G4: =E4*F4 -> 0 | J4: =H4*I4 -> 0 | K4: =G4+J4 -> 0 | M4: =M3+K4-L4 -> 0 | O4: =O3+M4-N4 -> 0
A5: 2 | B5: 46024 | G5: =E5*F5 -> 0 | J5: =H5*I5 -> 0 | K5: =G5+J5 -> 0 | M5: =M4+K5-L5 -> 0
A6: 3 | B6: 46025 | G6: =E6*F6 -> 0 | J6: =H6*I6 -> 0 | K6: =G6+J6 -> 0 | M6: =M5+K6-L6 -> 0
A7: 4 | B7: 46026 | G7: =E7*F7 -> 0 | J7: =H7*I7 -> 0 | K7: =G7+J7 -> 0 | M7: =M6+K7-L7 -> 0
A8: 5 | B8: 46027 | G8: =E8*F8 -> 0 | J8: =H8*I8 -> 0 | K8: =G8+J8 -> 0 | M8: =M7+K8-L8 -> 0
A9: 6 | B9: 46028 | G9: =E9*F9 -> 0 | J9: =H9*I9 -> 0 | K9: =G9+J9 -> 0 | M9: =M8+K9-L9 -> 0
A10: 7 | B10: 46029 | G10: =E10*F10 -> 0 | J10: =H10*I10 -> 0 | K10: =G10+J10 -> 0 | M10: =M9+K10-L10 -> 0
A11: 8 | B11: 46030 | G11: =E11*F11 -> 0 | J11: =H11*I11 -> 0 | K11: =G11+J11 -> 0 | M11: =M10+K11-L11 -> 0
A12: 9 | B12: 46031 | G12: =E12*F12 -> 0 | J12: =H12*I12 -> 0 | K12: =G12+J12 -> 0 | M12: =M11+K12-L12 -> 0
A13: 10 | B13: 46032 | G13: =E13*F13 -> 0 | J13: =H13*I13 -> 0 | K13: =G13+J13 -> 0 | M13: =M12+K13-L13 -> 0
A14: 11 | B14: 46033 | G14: =E14*F14 -> 0 | J14: =H14*I14 -> 0 | K14: =G14+J14 -> 0 | M14: =M13+K14-L14 -> 0
A15: 12 | B15: 46034 | G15: =E15*F15 -> 0 | J15: =H15*I15 -> 0 | K15: =G15+J15 -> 0 | M15: =M14+K15-L15 -> 0
A16: 13 | B16: 46035 | E16: 6000 | F16: 94.7 | G16: =E16*F16 -> 568200 | J16: =H16*I16 -> 0 | K16: =G16+J16 -> 568200 | M16: =M15+K16-L16 -> 568200
A17: 14 | B17: 46036 | E17: 6000 | F17: 94.7 | G17: =E17*F17 -> 568200 | J17: =H17*I17 -> 0 | K17: =G17+J17 -> 568200 | M17: =M16+K17-L17 -> 1136400
A18: 15 | B18: 46037 | G18: =E18*F18 -> 0 | J18: =H18*I18 -> 0 | K18: =G18+J18 -> 0 | M18: =M17+K18-L18 -> 1136400
A19: 16 | B19: 46038 | G19: =E19*F19 -> 0 | J19: =H19*I19 -> 0 | K19: =G19+J19 -> 0 | M19: =M18+K19-L19 -> 1136400
A20: 17 | B20: 46039 | G20: =E20*F20 -> 0 | J20: =H20*I20 -> 0 | K20: =G20+J20 -> 0 | M20: =M19+K20-L20 -> 1136400
A21: 18 | B21: 46040 | G21: =E21*F21 -> 0 | J21: =H21*I21 -> 0 | K21: =G21+J21 -> 0 | M21: =M20+K21-L21 -> 1136400
A22: 19 | B22: 46041 | G22: =E22*F22 -> 0 | J22: =H22*I22 -> 0 | K22: =G22+J22 -> 0 | L22: 1016000 | M22: =M21+K22-L22 -> 120400
A23: 20 | B23: 46042 | G23: =E23*F23 -> 0 | J23: =H23*I23 -> 0 | K23: =G23+J23 -> 0 | M23: =M22+K23-L23 -> 120400
A24: 21 | B24: 46043 | G24: =E24*F24 -> 0 | J24: =H24*I24 -> 0 | K24: =G24+J24 -> 0 | M24: =M23+K24-L24 -> 120400
A25: 22 | B25: 46044 | G25: =E25*F25 -> 0 | J25: =H25*I25 -> 0 | K25: =G25+J25 -> 0 | M25: =M24+K25-L25 -> 120400
A26: 23 | B26: 46045 | G26: =E26*F26 -> 0 | J26: =H26*I26 -> 0 | K26: =G26+J26 -> 0 | M26: =M25+K26-L26 -> 120400
A27: 24 | B27: 46046 | G27: =E27*F27 -> 0 | J27: =H27*I27 -> 0 | K27: =G27+J27 -> 0 | M27: =M26+K27-L27 -> 120400
A28: 25 | B28: 46047 | G28: =E28*F28 -> 0 | J28: =H28*I28 -> 0 | K28: =G28+J28 -> 0 | M28: =M27+K28-L28 -> 120400
A29: 26 | B29: 46048 | G29: =E29*F29 -> 0 | J29: =H29*I29 -> 0 | K29: =G29+J29 -> 0 | M29: =M28+K29-L29 -> 120400
A30: 27 | B30: 46049 | G30: =E30*F30 -> 0 | J30: =H30*I30 -> 0 | K30: =G30+J30 -> 0 | M30: =M29+K30-L30 -> 120400
A31: 28 | B31: 46050 | G31: =E31*F31 -> 0 | J31: =H31*I31 -> 0 | K31: =G31+J31 -> 0 | M31: =M30+K31-L31 -> 120400
A32: 29 | B32: 46051 | G32: =E32*F32 -> 0 | J32: =H32*I32 -> 0 | K32: =G32+J32 -> 0 | M32: =M31+K32-L32 -> 120400
A33: 30 | B33: 46052 | G33: =E33*F33 -> 0 | J33: =H33*I33 -> 0 | K33: =G33+J33 -> 0 | M33: =M32+K33-L33 -> 120400
A34: 31 | B34: 46053 | G34: =E34*F34 -> 0 | J34: =H34*I34 -> 0 | K34: =G34+J34 -> 0 | M34: =M33+K34-L34 -> 120400
E35: =SUM(E4:E34) -> 12000 | G35: =SUM(G4:G34) -> 1136400 | H35: =SUM(H4:H34) -> 0 | J35: =SUM(J4:J34) -> 0 | K35: =SUM(K4:K34) -> 1136400 | L35: =SUM(L4:L34) -> 1016000

Sheet Jadcherla-3
A1: JSASFuel Genie India Pvt.Ltd
A2: S.No | B2: Date | C2: GRN No | D2: Ind no/Bill No | E2: Diesel (Lts) | F2: Price | G2: Amount | H2: Petrol (Lts) | I2: Price | J2: Amount | K2: Total amount | L2: Amount paid | M2: As on Date | N2: Remarks
A3: Opening Balance | M3: 1183331.5
A4: 1 | B4: 46023 | E4: 1500 | F4: 95.43 | G4: =E4*F4 -> 143145 | H4: 0 | I4: 0 | J4: =H4*I4 -> 0 | K4: =G4+J4 -> 143145 | L4: 0 | M4: =+M3+K4-L4 -> 1326476.5
A5: 2 | B5: 46024 | G5: =E5*F5 -> 0 | H5: 0 | I5: 0 | J5: =H5*I5 -> 0 | K5: =G5+J5 -> 0 | L5: 0 | M5: =+M4+K5-L5 -> 1326476.5
A6: 3 | B6: 46025 | E6: 1000 | F6: 95.43 | G6: =E6*F6 -> 95430 | H6: 0 | I6: 0 | J6: =H6*I6 -> 0 | K6: =G6+J6 -> 95430 | M6: =+M5+K6-L6 -> 1421906.5
A7: 4 | B7: 46026 | G7: =E7*F7 -> 0 | H7: 0 | I7: 0 | J7: =H7*I7 -> 0 | K7: =G7+J7 -> 0 | M7: =+M6+K7-L7 -> 1421906.5
A8: 5 | B8: 46027 | G8: =E8*F8 -> 0 | H8: 0 | I8: 0 | J8: =H8*I8 -> 0 | K8: =G8+J8 -> 0 | M8: =+M7+K8-L8 -> 1421906.5
A9: 6 | B9: 46028 | G9: =E9*F9 -> 0 | H9: 0 | I9: 0 | J9: =H9*I9 -> 0 | K9: =G9+J9 -> 0 | M9: =+M8+K9-L9 -> 1421906.5
A10: 7 | B10: 46029 | G10: =E10*F10 -> 0 | H10: 0 | I10: 0 | J10: =H10*I10 -> 0 | K10: =G10+J10 -> 0 | M10: =+M9+K10-L10 -> 1421906.5
A11: 8 | B11: 46030 | E11: 1000 | F11: 95.43 | G11: =E11*F11 -> 95430 | H11: 0 | I11: 0 | J11: =H11*I11 -> 0 | K11: =G11+J11 -> 95430 | M11: =+M10+K11-L11 -> 1517336.5
A12: 9 | B12: 46031 | G12: =E12*F12 -> 0 | H12: 0 | I12: 0 | J12: =H12*I12 -> 0 | K12: =G12+J12 -> 0 | M12: =+M11+K12-L12 -> 1517336.5
A13: 10 | B13: 46032 | G13: =E13*F13 -> 0 | H13: 0 | I13: 0 | J13: =H13*I13 -> 0 | K13: =G13+J13 -> 0 | M13: =+M12+K13-L13 -> 1517336.5
A14: 11 | B14: 46033 | G14: =E14*F14 -> 0 | H14: 0 | I14: 0 | J14: =H14*I14 -> 0 | K14: =G14+J14 -> 0 | M14: =+M13+K14-L14 -> 1517336.5
A15: 12 | B15: 46034 | G15: =E15*F15 -> 0 | H15: 0 | I15: 0 | J15: =H15*I15 -> 0 | K15: =G15+J15 -> 0 | M15: =+M14+K15-L15 -> 1517336.5
A16: 13 | B16: 46035 | G16: =E16*F16 -> 0 | H16: 0 | I16: 0 | J16: =H16*I16 -> 0 | K16: =G16+J16 -> 0 | L16: 1000000 | M16: =+M15+K16-L16 -> 517336.5
A17: 14 | B17: 46036 | E17: 1000 | F17: 95.43 | G17: =E17*F17 -> 95430 | H17: 0 | I17: 0 | J17: =H17*I17 -> 0 | K17: =G17+J17 -> 95430 | M17: =+M16+K17-L17 -> 612766.5
A18: 15 | B18: 46037 | G18: =E18*F18 -> 0 | H18: 0 | I18: 0 | J18: =H18*I18 -> 0 | K18: =G18+J18 -> 0 | M18: =+M17+K18-L18 -> 612766.5
A19: 16 | B19: 46038 | G19: =E19*F19 -> 0 | H19: 0 | I19: 0 | J19: =H19*I19 -> 0 | K19: =G19+J19 -> 0 | M19: =+M18+K19-L19 -> 612766.5
A20: 17 | B20: 46039 | G20: =E20*F20 -> 0 | H20: 0 | I20: 0 | J20: =H20*I20 -> 0 | K20: =G20+J20 -> 0 | M20: =+M19+K20-L20 -> 612766.5
A21: 18 | B21: 46040 | G21: =E21*F21 -> 0 | H21: 0 | I21: 0 | J21: =H21*I21 -> 0 | K21: =G21+J21 -> 0 | M21: =+M20+K21-L21 -> 612766.5
A22: 19 | B22: 46041 | G22: =E22*F22 -> 0 | H22: 0 | I22: 0 | J22: =H22*I22 -> 0 | K22: =G22+J22 -> 0 | L22: 600000 | M22: =+M21+K22-L22 -> 12766.5
A23: 20 | B23: 46042 | G23: =E23*F23 -> 0 | H23: 0 | I23: 0 | J23: =H23*I23 -> 0 | K23: =G23+J23 -> 0 | M23: =+M22+K23-L23 -> 12766.5
A24: 21 | B24: 46043 | G24: =E24*F24 -> 0 | H24: 0 | I24: 0 | J24: =H24*I24 -> 0 | K24: =G24+J24 -> 0 | M24: =+M23+K24-L24 -> 12766.5
A25: 22 | B25: 46044 | G25: =E25*F25 -> 0 | H25: 0 | I25: 0 | J25: =H25*I25 -> 0 | K25: =G25+J25 -> 0 | M25: =+M24+K25-L25 -> 12766.5
A26: 23 | B26: 46045 | G26: =E26*F26 -> 0 | H26: 0 | I26: 0 | J26: =H26*I26 -> 0 | K26: =G26+J26 -> 0 | M26: =+M25+K26-L26 -> 12766.5
A27: 24 | B27: 46046 | E27: 1000 | F27: 95.43 | G27: =E27*F27 -> 95430 | H27: 0 | I27: 0 | J27: =H27*I27 -> 0 | K27: =G27+J27 -> 95430 | M27: =+M26+K27-L27 -> 108196.5
A28: 25 | B28: 46047 | G28: =E28*F28 -> 0 | H28: 0 | I28: 0 | J28: =H28*I28 -> 0 | K28: =G28+J28 -> 0 | M28: =+M27+K28-L28 -> 108196.5
A29: 26 | B29: 46048 | G29: =E29*F29 -> 0 | H29: 0 | I29: 0 | J29: =H29*I29 -> 0 | K29: =G29+J29 -> 0 | M29: =+M28+K29-L29 -> 108196.5
A30: 27 | B30: 46049 | G30: =E30*F30 -> 0 | H30: 0 | I30: 0 | J30: =H30*I30 -> 0 | K30: =G30+J30 -> 0 | M30: =+M29+K30-L30 -> 108196.5
A31: 28 | B31: 46050 | G31: =E31*F31 -> 0 | H31: 0 | I31: 0 | J31: =H31*I31 -> 0 | K31: =G31+J31 -> 0 | M31: =+M30+K31-L31 -> 108196.5
A32: 29 | B32: 46051 | G32: =E32*F32 -> 0 | H32: 0 | I32: 0 | J32: =H32*I32 -> 0 | K32: =G32+J32 -> 0 | M32: =+M31+K32-L32 -> 108196.5
A33: 30 | B33: 46052 | E33: 2000 | F33: 95.43 | G33: =E33*F33 -> 190860 | H33: 0 | I33: 0 | J33: =H33*I33 -> 0 | K33: =G33+J33 -> 190860 | M33: =+M32+K33-L33 -> 299056.5
A34: 31 | B34: 46053 | G34: =E34*F34 -> 0 | H34: 0 | I34: 0 | J34: =H34*I34 -> 0 | K34: =G34+J34 -> 0 | L34: 0 | M34: =+M33+K34-L34 -> 299056.5
E35: =SUM(E4:E34) -> 7500 | G35: =SUM(G4:G34) -> 715725 | H35: =SUM(H4:H34) -> 0 | J35: =SUM(J4:J34) -> 0 | K35: =SUM(K4:K34) -> 715725 | L35: =SUM(L4:L34) -> 1600000
F38: /

Sheet Jadcherla-4
A1: Shree Poornima F/S
A2: S.No | B2: Date | C2: GRN No | D2: Ind No/Bill No | E2: Diesel (Lts) | F2: Price | G2: Amount | H2: Petrol (Lts) | I2: Price | J2: Amount | K2: Total amount | L2: Amount paid | M2: As on date | N2: Remarks
A3: Opening Balance | M3: 5405
A4: 1 | B4: 46023 | G4: =E4*F4 -> 0 | H4: 0 | I4: 0 | J4: =H4*I4 -> 0 | K4: =G4+J4 -> 0 | L4: 0 | M4: =M3+K4-L4 -> 5405
A5: 2 | B5: 46024 | G5: =E5*F5 -> 0 | H5: 50 | I5: 108.1 | J5: =H5*I5 -> 5405 | K5: =G5+J5 -> 5405 | L5: 0 | M5: =M4+K5-L5 -> 10810
A6: 3 | B6: 46025 | G6: =E6*F6 -> 0 | H6: 0 | I6: 0 | J6: =H6*I6 -> 0 | K6: =G6+J6 -> 0 | L6: 0 | M6: =M5+K6-L6 -> 10810
A7: 4 | B7: 46026 | G7: =E7*F7 -> 0 | H7: 0 | I7: 0 | J7: =H7*I7 -> 0 | K7: =G7+J7 -> 0 | L7: 0 | M7: =M6+K7-L7 -> 10810
A8: 5 | B8: 46027 | G8: =E8*F8 -> 0 | H8: 0 | I8: 0 | J8: =H8*I8 -> 0 | K8: =G8+J8 -> 0 | L8: 0 | M8: =M7+K8-L8 -> 10810
A9: 6 | B9: 46028 | G9: =E9*F9 -> 0 | H9: 0 | I9: 0 | J9: =H9*I9 -> 0 | K9: =G9+J9 -> 0 | L9: 0 | M9: =M8+K9-L9 -> 10810
A10: 7 | B10: 46029 | G10: =E10*F10 -> 0 | H10: 0 | I10: 0 | J10: =H10*I10 -> 0 | K10: =G10+J10 -> 0 | L10: 0 | M10: =M9+K10-L10 -> 10810
A11: 8 | B11: 46030 | G11: =E11*F11 -> 0 | H11: 0 | I11: 0 | J11: =H11*I11 -> 0 | K11: =G11+J11 -> 0 | L11: 0 | M11: =M10+K11-L11 -> 10810
A12: 9 | B12: 46031 | G12: =E12*F12 -> 0 | H12: 0 | I12: 0 | K12: =G12+J12 -> 0 | L12: 0 | M12: =M11+K12-L12 -> 10810
A13: 10 | B13: 46032 | G13: =E13*F13 -> 0 | H13: 0 | I13: 0 | K13: =G13+J13 -> 0 | L13: 0 | M13: =M12+K13-L13 -> 10810
A14: 11 | B14: 46033 | G14: =E14*F14 -> 0 | H14: 0 | I14: 0 | K14: =G14+J14 -> 0 | L14: 0 | M14: =M13+K14-L14 -> 10810
A15: 12 | B15: 46034 | G15: =E15*F15 -> 0 | H15: 0 | I15: 0 | K15: =G15+J15 -> 0 | L15: 0 | M15: =M14+K15-L15 -> 10810
A16: 13 | B16: 46035 | G16: =E16*F16 -> 0 | H16: 0 | I16: 0 | J16: =H16*I16 -> 0 | K16: =G16+J16 -> 0 | L16: 0 | M16: =M15+K16-L16 -> 10810
A17: 14 | B17: 46036 | G17: =E17*F17 -> 0 | H17: 0 | I17: 0 | J17: =H17*I17 -> 0 | K17: =G17+J17 -> 0 | L17: 0 | M17: =M16+K17-L17 -> 10810
A18: 15 | B18: 46037 | G18: =E18*F18 -> 0 | H18: 0 | I18: 0 | J18: =H18*I18 -> 0 | K18: =G18+J18 -> 0 | L18: 0 | M18: =M17+K18-L18 -> 10810
A19: 16 | B19: 46038 | G19: =E19*F19 -> 0 | H19: 0 | I19: 0 | J19: =H19*I19 -> 0 | K19: =G19+J19 -> 0 | L19: 0 | M19: =M18+K19-L19 -> 10810
A20: 17 | B20: 46039 | G20: =E20*F20 -> 0 | H20: 50 | I20: 108.1 | J20: =H20*I20 -> 5405 | K20: =G20+J20 -> 5405 | L20: 16215 | M20: =M19+K20-L20 -> 0
A21: 18 | B21: 46040 | G21: =E21*F21 -> 0 | H21: 0 | I21: 0 | J21: =H21*I21 -> 0 | K21: =G21+J21 -> 0 | L21: 0 | M21: =M20+K21-L21 -> 0
A22: 19 | B22: 46041 | G22: =E22*F22 -> 0 | H22: 0 | I22: 0 | J22: =H22*I22 -> 0 | K22: =G22+J22 -> 0 | L22: 0 | M22: =M21+K22-L22 -> 0
A23: 20 | B23: 46042 | G23: =E23*F23 -> 0 | H23: 0 | I23: 0 | J23: =H23*I23 -> 0 | K23: =G23+J23 -> 0 | L23: 0 | M23: =M22+K23-L23 -> 0
A24: 21 | B24: 46043 | G24: =E24*F24 -> 0 | H24: 0 | I24: 0 | J24: =H24*I24 -> 0 | K24: =G24+J24 -> 0 | L24: 0 | M24: =M23+K24-L24 -> 0
A25: 22 | B25: 46044 | G25: =E25*F25 -> 0 | H25: 0 | I25: 0 | J25: =H25*I25 -> 0 | K25: =G25+J25 -> 0 | L25: 0 | M25: =M24+K25-L25 -> 0
A26: 23 | B26: 46045 | E26: 0 | F26: 0 | G26: =E26*F26 -> 0 | H26: 0 | I26: 0 | J26: =H26*I26 -> 0 | K26: =G26+J26 -> 0 | L26: 0 | M26: =M25+K26-L26 -> 0
A27: 24 | B27: 46046 | G27: =E27*F27 -> 0 | H27: 0 | I27: 0 | J27: =H27*I27 -> 0 | K27: =G27+J27 -> 0 | L27: 0 | M27: =M26+K27-L27 -> 0
A28: 25 | B28: 46047 | G28: =E28*F28 -> 0 | H28: 0 | I28: 0 | J28: =H28*I28 -> 0 | K28: =G28+J28 -> 0 | L28: 0 | M28: =M27+K28-L28 -> 0
A29: 26 | B29: 46048 | G29: =E29*F29 -> 0 | H29: 0 | I29: 0 | J29: =H29*I29 -> 0 | K29: =G29+J29 -> 0 | L29: 0 | M29: =M28+K29-L29 -> 0
A30: 27 | B30: 46049 | G30: =E30*F30 -> 0 | H30: 0 | I30: 0 | J30: =H30*I30 -> 0 | K30: =G30+J30 -> 0 | L30: 0 | M30: =M29+K30-L30 -> 0
A31: 28 | B31: 46050 | G31: =E31*F31 -> 0 | H31: 50 | I31: 108.1 | J31: =H31*I31 -> 5405 | K31: =G31+J31 -> 5405 | M31: =M30+K31-L31 -> 5405
A32: 28 | B32: 46051 | G32: =E32*F32 -> 0 | J32: =H32*I32 -> 0 | K32: =G32+J32 -> 0 | M32: =M31+K32-L32 -> 5405
A33: 28 | B33: 46052 | G33: =E33*F33 -> 0 | J33: =H33*I33 -> 0 | K33: =G33+J33 -> 0 | M33: =M32+K33-L33 -> 5405
A34: 28 | B34: 46053 | G34: =E34*F34 -> 0 | J34: =H34*I34 -> 0 | K34: =G34+J34 -> 0 | M34: =M33+K34-L34 -> 5405
E35: =SUM(E4:E34) -> 0 | G35: =SUM(G4:G34) -> 0 | H35: =SUM(H4:H34) -> 150 | J35: =SUM(J4:J34) -> 16215 | K35: =SUM(K4:K34) -> 16215 | L35: =SUM(L4:L34) -> 16215

Sheet Devarakhadra
A1: Kurumurthy Swami F/S
A2: S.No | B2: Date | C2: GRN No | D2: Ind no/Bill No | E2: Diesel (Lts) | F2: Price | G2: Amount | H2: Petrol (Lts) | I2: Price | J2: Amount | K2: Total amount | L2: Amount paid | M2: As on Date | N2: Remarks
A3: Opening Balance | M3: 5026.311 | O3: 121213.37
A4: 1 | B4: 46023 | E4: 35 | F4: 97.1 | G4: =E4*F4 -> 3398.5 | J4: =H4*I4 -> 0 | K4: =G4+J4 -> 3398.5 | M4: =+M3+K4-L4 -> 8424.811
A5: 2 | B5: 46024 | E5: 0 | F5: 0 | G5: =E5*F5 -> 0 | H5: 5 | I5: 108.83 | J5: =H5*I5 -> 544.15 | K5: =G5+J5 -> 544.15 | M5: =+M4+K5-L5 -> 8968.961
A6: 3 | B6: 46025 | E6: 0 | F6: 0 | G6: =E6*F6 -> 0 | J6: =H6*I6 -> 0 | K6: =G6+J6 -> 0 | M6: =+M5+K6-L6 -> 8968.961
A7: 4 | B7: 46026 | E7: 0 | F7: 0 | G7: =E7*F7 -> 0 | H7: 5 | I7: 108.83 | J7: =H7*I7 -> 544.15 | K7: =G7+J7 -> 544.15 | M7: =+M6+K7-L7 -> 9513.111
A8: 5 | B8: 46027 | E8: 0 | F8: 0 | G8: =E8*F8 -> 0 | J8: =H8*I8 -> 0 | K8: =G8+J8 -> 0 | M8: =+M7+K8-L8 -> 9513.111
A9: 6 | B9: 46028 | E9: 0 | F9: 0 | G9: =E9*F9 -> 0 | J9: =H9*I9 -> 0 | K9: =G9+J9 -> 0 | M9: =+M8+K9-L9 -> 9513.111
A10: 7 | B10: 46029 | E10: 0 | F10: 0 | G10: =E10*F10 -> 0 | J10: =H10*I10 -> 0 | K10: =G10+J10 -> 0 | M10: =+M9+K10-L10 -> 9513.111
A11: 8 | B11: 46030 | E11: 20 | F11: 97.1 | G11: =E11*F11 -> 1942 | J11: =H11*I11 -> 0 | K11: =G11+J11 -> 1942 | M11: =+M10+K11-L11 -> 11455.111
A12: 9 | B12: 46031 | E12: 0 | F12: 0 | G12: =E12*F12 -> 0 | H12: 5 | I12: 108.83 | J12: =H12*I12 -> 544.15 | K12: =G12+J12 -> 544.15 | M12: =+M11+K12-L12 -> 11999.261
A13: 10 | B13: 46032 | E13: 0 | F13: 0 | G13: =E13*F13 -> 0 | J13: =H13*I13 -> 0 | K13: =G13+J13 -> 0 | M13: =+M12+K13-L13 -> 11999.261
A14: 11 | B14: 46033 | E14: 0 | F14: 0 | G14: =E14*F14 -> 0 | J14: =H14*I14 -> 0 | K14: =G14+J14 -> 0 | M14: =+M13+K14-L14 -> 11999.261
A15: 12 | B15: 46034 | E15: 0 | F15: 0 | G15: =E15*F15 -> 0 | J15: =H15*I15 -> 0 | K15: =G15+J15 -> 0 | M15: =+M14+K15-L15 -> 11999.261
A16: 13 | B16: 46035 | E16: 0 | F16: 0 | G16: =E16*F16 -> 0 | J16: =H16*I16 -> 0 | K16: =G16+J16 -> 0 | M16: =+M15+K16-L16 -> 11999.261
A17: 14 | B17: 46036 | E17: 0 | F17: 0 | G17: =E17*F17 -> 0 | J17: =H17*I17 -> 0 | K17: =G17+J17 -> 0 | M17: =+M16+K17-L17 -> 11999.261
A18: 15 | B18: 46037 | E18: 0 | F18: 0 | G18: =E18*F18 -> 0 | H18: 5 | I18: 108.83 | J18: =H18*I18 -> 544.15 | K18: =G18+J18 -> 544.15 | M18: =+M17+K18-L18 -> 12543.411
A19: 16 | B19: 46038 | E19: 0 | F19: 0 | G19: =E19*F19 -> 0 | J19: =H19*I19 -> 0 | K19: =G19+J19 -> 0 | M19: =+M18+K19-L19 -> 12543.411 | N19: Fuel bills
A20: 17 | B20: 46039 | E20: 35 | F20: 97.1 | G20: =E20*F20 -> 3398.5 | J20: =H20*I20 -> 0 | K20: =G20+J20 -> 3398.5 | L20: 12543 | M20: =+M19+K20-L20 -> 3398.911
A21: 18 | B21: 46040 | E21: 0 | F21: 0 | G21: =E21*F21 -> 0 | J21: =H21*I21 -> 0 | K21: =G21+J21 -> 0 | M21: =+M20+K21-L21 -> 3398.911
A22: 19 | B22: 46041 | E22: 0 | F22: 0 | G22: =E22*F22 -> 0 | J22: =H22*I22 -> 0 | K22: =G22+J22 -> 0 | M22: =+M21+K22-L22 -> 3398.911
A23: 20 | B23: 46042 | E23: 0 | F23: 0 | G23: =E23*F23 -> 0 | J23: =H23*I23 -> 0 | K23: =G23+J23 -> 0 | M23: =+M22+K23-L23 -> 3398.911
A24: 21 | B24: 46043 | E24: 0 | F24: 0 | G24: =E24*F24 -> 0 | J24: =H24*I24 -> 0 | K24: =G24+J24 -> 0 | M24: =+M23+K24-L24 -> 3398.911
A25: 22 | B25: 46044 | E25: 0 | F25: 0 | G25: =E25*F25 -> 0 | J25: =H25*I25 -> 0 | K25: =G25+J25 -> 0 | M25: =+M24+K25-L25 -> 3398.911
A26: 23 | B26: 46045 | E26: 0 | F26: 0 | G26: =E26*F26 -> 0 | H26: 5 | I26: 108.83 | J26: =H26*I26 -> 544.15 | K26: =G26+J26 -> 544.15 | M26: =+M25+K26-L26 -> 3943.061
A27: 24 | B27: 46046 | E27: 0 | F27: 0 | G27: =E27*F27 -> 0 | J27: =H27*I27 -> 0 | K27: =G27+J27 -> 0 | M27: =+M26+K27-L27 -> 3943.061
A28: 25 | B28: 46047 | E28: 0 | F28: 0 | G28: =E28*F28 -> 0 | J28: =H28*I28 -> 0 | K28: =G28+J28 -> 0 | M28: =+M27+K28-L28 -> 3943.061
A29: 26 | B29: 46048 | E29: 0 | F29: 0 | G29: =E29*F29 -> 0 | J29: =H29*I29 -> 0 | K29: =G29+J29 -> 0 | M29: =+M28+K29-L29 -> 3943.061
A30: 27 | B30: 46049 | E30: 0 | F30: 0 | G30: =E30*F30 -> 0 | J30: =H30*I30 -> 0 | K30: =G30+J30 -> 0 | M30: =+M29+K30-L30 -> 3943.061
A31: 28 | B31: 46050 | E31: 0 | F31: 0 | G31: =E31*F31 -> 0 | J31: =H31*I31 -> 0 | K31: =G31+J31 -> 0 | M31: =+M30+K31-L31 -> 3943.061
A32: 29 | B32: 46051 | E32: 0 | F32: 0 | G32: =E32*F32 -> 0 | H32: 10 | I32: 108.83 | J32: =H32*I32 -> 1088.3 | K32: =G32+J32 -> 1088.3 | M32: =+M31+K32-L32 -> 5031.361
A33: 30 | B33: 46052 | E33: 0 | F33: 0 | G33: =E33*F33 -> 0 | H33: 5 | I33: 108.83 | J33: =H33*I33 -> 544.15 | K33: =G33+J33 -> 544.15 | M33: =+M32+K33-L33 -> 5575.511
A34: 31 | B34: 46053 | G34: =E34*F34 -> 0 | H34: 2.58 | I34: 108.83 | J34: =H34*I34 -> 280.7814 | K34: =G34+J34 -> 280.7814 | M34: =+M33+K34-L34 -> 5856.2924 | O34: 5921.25 | P34: =O34-M34 -> 64.9576
E35: =SUM(E4:E34) -> 90 | G35: =SUM(G4:G34) -> 8739 | H35: =SUM(H4:H34) -> 42.58 | J35: =SUM(J4:J34) -> 4633.9814 | K35: =SUM(K4:K34) -> 13372.981 | L35: =SUM(L4:L34) -> 12543

Sheet Devarakhadra-2
A1: JSASFuel Genie India Pvt.Ltd
A2: S.No | B2: Date | C2: GRN No | D2: Ind no/Bill No | E2: Diesel (Lts) | F2: Price | G2: Amount | H2: Petrol (Lts) | I2: Price | J2: Amount | K2: Total amount | L2: Amount paid | M2: As on Date | N2: Remarks
A3: Opening Balance | M3: 0
A4: 1 | B4: 46023 | G4: =E4*F4 -> 0 | H4: 0 | I4: 0 | J4: =H4*I4 -> 0 | K4: =G4+J4 -> 0 | L4: 0 | M4: =+M3+K4-L4 -> 0
A5: 2 | B5: 46024 | G5: =E5*F5 -> 0 | H5: 0 | I5: 0 | J5: =H5*I5 -> 0 | K5: =G5+J5 -> 0 | L5: 0 | M5: =+M4+K5-L5 -> 0
A6: 3 | B6: 46025 | G6: =E6*F6 -> 0 | H6: 0 | I6: 0 | J6: =H6*I6 -> 0 | K6: =G6+J6 -> 0 | L6: 0 | M6: =+M5+K6-L6 -> 0
A7: 4 | B7: 46026 | G7: =E7*F7 -> 0 | H7: 0 | I7: 0 | J7: =H7*I7 -> 0 | K7: =G7+J7 -> 0 | L7: 0 | M7: =+M6+K7-L7 -> 0
A8: 5 | B8: 46027 | G8: =E8*F8 -> 0 | H8: 0 | I8: 0 | J8: =H8*I8 -> 0 | K8: =G8+J8 -> 0 | L8: 0 | M8: =+M7+K8-L8 -> 0
A9: 6 | B9: 46028 | G9: =E9*F9 -> 0 | H9: 0 | I9: 0 | J9: =H9*I9 -> 0 | K9: =G9+J9 -> 0 | L9: 0 | M9: =+M8+K9-L9 -> 0
A10: 7 | B10: 46029 | G10: =E10*F10 -> 0 | H10: 0 | I10: 0 | J10: =H10*I10 -> 0 | K10: =G10+J10 -> 0 | L10: 0 | M10: =+M9+K10-L10 -> 0
A11: 8 | B11: 46030 | G11: =E11*F11 -> 0 | H11: 0 | I11: 0 | J11: =H11*I11 -> 0 | K11: =G11+J11 -> 0 | L11: 0 | M11: =+M10+K11-L11 -> 0
A12: 9 | B12: 46031 | G12: =E12*F12 -> 0 | H12: 0 | I12: 0 | J12: =H12*I12 -> 0 | K12: =G12+J12 -> 0 | L12: 0 | M12: =+M11+K12-L12 -> 0
A13: 10 | B13: 46032 | G13: =E13*F13 -> 0 | H13: 0 | I13: 0 | J13: =H13*I13 -> 0 | K13: =G13+J13 -> 0 | L13: 0 | M13: =+M12+K13-L13 -> 0
A14: 11 | B14: 46033 | G14: =E14*F14 -> 0 | H14: 0 | I14: 0 | J14: =H14*I14 -> 0 | K14: =G14+J14 -> 0 | L14: 0 | M14: =+M13+K14-L14 -> 0
A15: 12 | B15: 46034 | G15: =E15*F15 -> 0 | H15: 0 | I15: 0 | J15: =H15*I15 -> 0 | K15: =G15+J15 -> 0 | L15: 0 | M15: =+M14+K15-L15 -> 0
A16: 13 | B16: 46035 | G16: =E16*F16 -> 0 | H16: 0 | I16: 0 | J16: =H16*I16 -> 0 | K16: =G16+J16 -> 0 | L16: 0 | M16: =+M15+K16-L16 -> 0
A17: 14 | B17: 46036 | H17: 0 | I17: 0 | J17: =H17*I17 -> 0 | K17: =G17+J17 -> 0 | L17: 0 | M17: =+M16+K17-L17 -> 0
A18: 15 | B18: 46037 | H18: 0 | I18: 0 | J18: =H18*I18 -> 0 | K18: =G18+J18 -> 0 | L18: 0 | M18: =+M17+K18-L18 -> 0
A19: 16 | B19: 46038 | H19: 0 | I19: 0 | J19: =H19*I19 -> 0 | K19: =G19+J19 -> 0 | L19: 0 | M19: =+M18+K19-L19 -> 0
A20: 17 | B20: 46039 | G20: =E20*F20 -> 0 | H20: 0 | I20: 0 | J20: =H20*I20 -> 0 | K20: =G20+J20 -> 0 | L20: 0 | M20: =+M19+K20-L20 -> 0
A21: 18 | B21: 46040 | G21: =E21*F21 -> 0 | H21: 0 | I21: 0 | J21: =H21*I21 -> 0 | K21: =G21+J21 -> 0 | L21: 0 | M21: =+M20+K21-L21 -> 0
A22: 19 | B22: 46041 | G22: =E22*F22 -> 0 | H22: 0 | I22: 0 | J22: =H22*I22 -> 0 | K22: =G22+J22 -> 0 | L22: 0 | M22: =+M21+K22-L22 -> 0
A23: 20 | B23: 46042 | G23: =E23*F23 -> 0 | H23: 0 | I23: 0 | J23: =H23*I23 -> 0 | K23: =G23+J23 -> 0 | L23: 0 | M23: =+M22+K23-L23 -> 0
A24: 21 | B24: 46043 | G24: =E24*F24 -> 0 | H24: 0 | I24: 0 | J24: =H24*I24 -> 0 | K24: =G24+J24 -> 0 | L24: 0 | M24: =+M23+K24-L24 -> 0
A25: 22 | B25: 46044 | G25: =E25*F25 -> 0 | H25: 0 | I25: 0 | J25: =H25*I25 -> 0 | K25: =G25+J25 -> 0 | L25: 0 | M25: =+M24+K25-L25 -> 0
A26: 23 | B26: 46045 | G26: =E26*F26 -> 0 | H26: 0 | I26: 0 | J26: =H26*I26 -> 0 | K26: =G26+J26 -> 0 | L26: 0 | M26: =+M25+K26-L26 -> 0
