Workbook

Sheet  MIs
A2: S.No | B2: NAme | C2: Lacation | D2: Card Number | E2: Card Number | F2: Category | G2: 1st Jan | I2: 2nd Jan | J2: 3rd Jan | K2: 4th Jan | L2: 5th Jan | M2: 6th Jan | N2: 7th Jan | O2: 8th Jan | P2: 9th Jan | Q2: 10th Jan | R2: 11th Jan | S2: 12th Jan | T2: 13th Jan | U2: 14th Jan | V2: 15th Jan | W2: 16th Jan | X2: 17th Jan | Y2: 18th Jan | Z2: 19th Jan | AA2: 20th Jan | AB2: 21st Jan | AC2: 22nd Jan | AD2: 23rd Jan | AE2: 24th Jan | AF2: 25th Jan | AG2: 26th Jan | AH2: 27th Jan | AI2: 28th Jan | AJ2: 29th Jan | AK2: 30th Jan | AL2: 31st Jan | AM2: Total
F3: Diesel
A4: 1 | B4: Rambabu | C4: HO(Two Wheeler) | D4: FC3450563999 | E4: Diesel | F4: 0 | G4: 0 | H4: 0 | I4: 0 | J4: 0 | K4: 0 | L4: 0 | M4: 0 | N4: 0 | O4: 0 | P4: 0 | Q4: 0 | R4: 0 | S4: 0 | T4: 0 | U4: 0 | V4: 0 | W4: 0 | X4: 5.22 | Y4: 0 | Z4: 0 | AA4: 0 | AB4: 0 | AC4: 0 | AD4: 60 | AE4: 0 | AF4: 0 | AG4: 0 | AH4: 4.56 | AI4: 0 | AJ4: 0 | AK4: 0 | AL4: 0 | AM4: =SUM(F4:AL4) -> 69.78
E5: Petrol | F5: 0 | G5: 4.69 | H5: 0 | I5: 0 | J5: 0 | K5: 0 | L5: 0 | M5: 0 | N5: 3.91 | O5: 0 | P5: 6.98 | Q5: 0 | R5: 0 | S5: 0 | T5: 0 | U5: 0 | V5: 0 | W5: 0 | X5: 0 | Y5: 0 | Z5: 0 | AB5: 0 | AC5: 0 | AD5: 0 | AE5: 0 | AF5: 0 | AG5: 0 | AH5: 0 | AI5: 0 | AJ5: 0 | AK5: 0 | AL5: 0 | AM5: =SUM(F5:AL5) -> 15.58
A6: 2 | B6: Hanumanth Rao | C6: HO | D6: FC3450676131 | E6: Diesel | F6: 0 | G6: 0 | H6: 0 | I6: 0 | J6: 0 | K6: 0 | L6: 0 | M6: 0 | N6: 0 | O6: 0 | P6: 0 | Q6: 0 | R6: 0 | S6: 0 | T6: 0 | U6: 0 | V6: 0 | W6: 0 | X6: 0 | Y6: 0 | Z6: 0 | AA6: 0 | AB6: 0 | AC6: 0 | AD6: 0 | AE6: 0 | AF6: 0 | AG6: 0 | AH6: 0 | AI6: 0 | AJ6: 0 | AK6: 0 | AL6: 0 | AM6: =SUM(F6:AL6) -> 0
E7: Petrol | F7: 0 | G7: 0 | H7: 0 | I7: 0 | J7: 0 | K7: 0 | L7: 0 | M7: 0 | N7: 0 | O7: 0 | P7: 0 | Q7: 0 | R7: 0 | S7: 0 | T7: 0 | U7: 0 | V7: 0 | W7: 0 | X7: 0 | Y7: 0 | Z7: 0 | AB7: 0 | AC7: 0 | AD7: 0 | AE7: 0 | AF7: 0 | AG7: 0 | AH7: 0 | AI7: 0 | AJ7: 0 | AK7: 0 | AL7: 0 | AM7: =SUM(F7:AL7) -> 0
A8: 3 | B8: Radhakrishna | C8: HO | D8: FC8000207658 | E8: Diesel | F8: 0 | G8: 0 | H8: 0 | I8: 0 | J8: 33.44 | K8: 0 | L8: 0 | M8: 0 | N8: 0 | O8: 0 | P8: 0 | Q8: 0 | R8: 35.53 | S8: 0 | T8: 0 | U8: 0 | V8: 0 | W8: 0 | X8: 0 | Y8: 0 | Z8: 0 | AA8: 0 | AB8: 33.44 | AC8: 0 | AD8: 0 | AE8: 0 | AF8: 0 | AG8: 0 | AH8: 0 | AI8: 0 | AJ8: 0 | AK8: 0 | AL8: 0 | AM8: =SUM(F8:AL8) -> 102.41
E9: Petrol | F9: 0 | G9: 0 | H9: 0 | I9: 0 | J9: 0 | K9: 0 | L9: 0 | M9: 0 | N9: 0 | O9: 0 | P9: 0 | Q9: 0 | R9: 0 | S9: 0 | T9: 0 | U9: 0 | V9: 0 | W9: 0 | X9: 0 | Y9: 0 | Z9: 0 | AB9: 0 | AC9: 0 | AD9: 0 | AE9: 0 | AF9: 0 | AG9: 0 | AH9: 0 | AI9: 0 | AJ9: 0 | AK9: 0 | AL9: 0 | AM9: =SUM(F9:AL9) -> 0
A10: 4 | B10: VIjay | C10: HO | D10: FC3450698859 | E10: Diesel | F10: 0 | G10: 0 | H10: 0 | I10: 0 | J10: 0 | K10: 0 | L10: 0 | M10: 0 | N10: 0 | O10: 0 | P10: 49.22 | Q10: 0 | R10: 0 | S10: 0 | T10: 0 | U10: 54.57 | V10: 0 | W10: 0 | X10: 0 | Y10: 0 | Z10: 0 | AA10: 0 | AB10: 0 | AC10: 0 | AD10: 49.8 | AE10: 0 | AF10: 0 | AG10: 0 | AH10: 0 | AI10: 0 | AJ10: 0 | AK10: 0 | AL10: 0 | AM10: =SUM(F10:AL10) -> 153.59
E11: Petrol | F11: 0 | G11: 0 | H11: 0 | I11: 0 | J11: 0 | K11: 0 | L11: 0 | M11: 0 | N11: 0 | O11: 0 | P11: 0 | Q11: 0 | R11: 0 | S11: 0 | T11: 0 | U11: 0 | V11: 0 | W11: 0 | X11: 0 | Y11: 0 | Z11: 0 | AB11: 0 | AC11: 0 | AD11: 0 | AE11: 0 | AF11: 0 | AG11: 0 | AH11: 0 | AI11: 0 | AJ11: 0 | AK11: 0 | AL11: 0 | AM11: =SUM(F11:AL11) -> 0
A12: 5 | B12: Client | C12: Hiriyur | D12: FC3450698864 | E12: Diesel | F12: 0 | G12: 0 | H12: 0 | I12: 0 | J12: 0 | K12: 0 | L12: 0 | M12: 0 | N12: 86.29 | O12: 0 | P12: 0 | Q12: 0 | R12: 0 | S12: 0 | T12: 0 | U12: 0 | V12: 0 | W12: 0 | X12: 0 | Y12: 0 | Z12: 0 | AA12: 0 | AB12: 0 | AC12: 0 | AD12: 145.61 | AE12: 0 | AF12: 0 | AG12: 0 | AH12: 0 | AI12: 0 | AJ12: 0 | AK12: 0 | AL12: 0 | AM12: =SUM(F12:AL12) -> 231.9
E13: Petrol | F13: 0 | G13: 0 | H13: 0 | I13: 0 | J13: 0 | K13: 0 | L13: 0 | M13: 0 | N13: 0 | O13: 0 | P13: 0 | Q13: 0 | R13: 0 | S13: 0 | T13: 0 | U13: 0 | V13: 0 | W13: 0 | X13: 0 | Y13: 0 | Z13: 0 | AB13: 0 | AC13: 0 | AD13: 0 | AE13: 0 | AF13: 0 | AG13: 0 | AH13: 0 | AI13: 0 | AJ13: 0 | AK13: 0 | AL13: 0 | AM13: =SUM(F13:AL13) -> 0
A14: 6 | B14: Client | C14: Hosadurga | D14: FC3450698865 | E14: Diesel | F14: 0 | G14: 0 | H14: 0 | I14: 0 | J14: 0 | K14: 0 | L14: 40 | M14: 40 | N14: 0 | O14: 36 | P14: 35 | Q14: 0 | R14: 0 | S14: 0 | T14: 0 | U14: 0 | V14: 0 | W14: 45 | X14: 45 | Y14: 43.53 | Z14: 40 | AA14: 43 | AB14: 0 | AC14: 40 | AD14: 0 | AE14: 40 | AF14: 0 | AG14: 0 | AH14: 0 | AI14: 0 | AJ14: 0 | AK14: 0 | AL14: 0 | AM14: =SUM(F14:AL14) -> 447.53
E15: Petrol | F15: 0 | G15: 0 | H15: 0 | I15: 0 | J15: 0 | K15: 0 | L15: 0 | M15: 0 | N15: 0 | O15: 0 | P15: 0 | Q15: 0 | R15: 0 | S15: 0 | T15: 0 | U15: 0 | V15: 0 | W15: 0 | X15: 0 | Y15: 0 | Z15: 0 | AB15: 0 | AC15: 0 | AD15: 0 | AE15: 0 | AF15: 0 | AG15: 0 | AH15: 0 | AI15: 0 | AJ15: 0 | AK15: 0 | AL15: 0 | AM15: =SUM(F15:AL15) -> 0
G18: Diesel Price

Sheet  Aug-26
A1: S.no | B1: Site Name | C1: Bunk Name | D1: Diesel(Liters) | E1: Diesel Amount | F1: Petrol(Liters) | G1: Petrol Amount | H1: Total Amount | I1: Opening Blance | J1: Amount Paid | K1: Closing Balances
A2: 1 | B2: Khammam-1 | C2: Divya laxmi ganapathi | D2: =+'Khammam-1'!E38 -> 26800 | E2: =+'Khammam-1'!G38 -> 2781840 | F2: =+'Khammam-1'!H38 -> 205 | G2: =+'Khammam-1'!J38 -> 23716.45 | H2: =E2+G2 -> 2805556.5 | I2: =+'Khammam-1'!K3 -> 3834148.7 | J2: =+'Khammam-1'!L38 -> 3834140 | K2: =H2+I2-J2 -> 2805565.2
A3: 2 | B3: Khammam-2 | C3: Jayasai union bunk | D3: =+'Khammam-2'!E38 -> 35123.528 | E3: =+'Khammam-2'!G38 -> 3646524.7 | F3: =+'Khammam-2'!H38 -> 515 | G3: =+'Khammam-2'!J38 -> 59595.8 | H3: =E3+G3 -> 3706120.5 | I3: =+'Khammam-2'!K3 -> 18929637 | J3: =+'Khammam-2'!L38 -> 22635758 | K3: =H3+I3-J3 -> 0
A4: 3 | B4: Khammam-3 | C4: JSASFuel Genie India Pvt.Ltd | D4: =+'Khammam-3'!E35 -> 0 | E4: =+'Khammam-3'!G35 -> 0 | F4: =+'Khammam-3'!H35 -> 0 | G4: =+'Khammam-3'!J35 -> 0 | H4: =E4+G4 -> 0 | I4: =+'Khammam-3'!M3 -> 1510680 | J4: =+'Khammam-3'!L35 -> 1510680 | K4: =H4+I4-J4 -> 0
A5: 4 | B5: Khammam | C5: Sai Madeana Filling Station | D5: =+'Khammam-4'!E35 -> 18900 | E5: =+'Khammam-4'!G35 -> 1958418 | F5: =+'Khammam-4'!H35 -> 70 | G5: =+'Khammam-4'!J35 -> 8084.3 | H5: =E5+G5 -> 1966502.3 | I5: =+'Khammam-4'!M3 -> 0 | J5: =+'Khammam-4'!L35 -> 1123138 | K5: =H5+I5-J5 -> 843364.3
A6: 5 | B6: Khammam | C6: Vajra mahalakshmi filling station | D6: =+' Khammam-5'!E35 -> 16260 | E6: =+' Khammam-5'!G35 -> 1684861.2 | F6: =+' Khammam-5'!H35 -> 240 | G6: =+' Khammam-5'!J35 -> 27717.6 | H6: =E6+G6 -> 1712578.8 | I6: =+' Khammam-5'!M3 -> 0 | J6: =+' Khammam-5'!L35 -> 1134007 | K6: =H6+I6-J6 -> 578571.8
A7: 6 | B7: Khammam-Cash&Carry | C7: NA | D7: =+' Khammam&Cash'!E46 -> 7032.753 | E7: =+' Khammam&Cash'!G46 -> 729999.76 | F7: =+' Khammam&Cash'!H46 -> 0 | G7: =+' Khammam&Cash'!J46 -> 0 | H7: =E7+G7 -> 729999.76 | I7: =+' Khammam&Cash'!M3 -> 0 | J7: =+' Khammam&Cash'!L46 -> 729999.76 | K7: =H7+I7-J7 -> 0
A8: 7 | B8: Jadcherla-2 | C8: Shree Poornima F/S | D8: =+'Jadcherla-4'!E35 -> 0 | E8: =+'Jadcherla-4'!G35 -> 0 | F8: =+'Jadcherla-4'!H35 -> 20 | G8: =+'Jadcherla-4'!J35 -> 2326.6 | H8: =E8+G8 -> 2326.6 | I8: =+'Jadcherla-4'!M3 -> 50273.68 | J8: =+'Jadcherla-4'!L35 -> 50000 | K8: =H8+I8-J8 -> 2600.28
A9: 8 | B9: Sangareddy-2 | C9: Durga Bhavani F/S | D9: =+' Sangareddy-2'!E35 -> 38.25 | E9: =+' Sangareddy-2'!G35 -> 3999.42 | F9: =+' Sangareddy-2'!H35 -> 20 | G9: =+' Sangareddy-2'!J35 -> 2330.8 | H9: =E9+G9 -> 6330.22 | I9: =+' Sangareddy-2'!M3 -> 52609.145 | J9: =+' Sangareddy-2'!L35 -> 58939.365 | K9: =H9+I9-J9 -> 0
A10: 9 | B10: Sangareddy-3 | C10: Shiva Parvathi Filling Station | D10: =+' Sangareddy-3'!E36 -> 9474 | E10: =+' Sangareddy-3'!G36 -> 988611.9 | F10: =+' Sangareddy-3'!H36 -> 84 | G10: =+' Sangareddy-3'!J36 -> 9823.68 | H10: =E10+G10 -> 998435.58 | I10: =+' Sangareddy-3'!M3 -> 754936.41 | J10: =+' Sangareddy-3'!L36 -> 1607217 | K10: =H10+I10-J10 -> 146154.99
A11: 10 | B11: NarayanaKhed | C11: Sai Shiva Filling Station | D11: =Narayankhed!E35 -> 1332.8144 | E11: =+Narayankhed!G35 -> 140000.59 | F11: =+Narayankhed!H35 -> 0 | G11: =+Narayankhed!J35 -> 0 | H11: =E11+G11 -> 140000.59 | I11: =+Narayankhed!M3 -> 0 | J11: =+Narayankhed!L35 -> 140000.59 | K11: =H11+I11-J11 -> 0
A12: 11 | B12: Dindi | C12: Akarapu Balakistamma Fillling | D12: =+Dindi!E35 -> 33.78 | E12: =+Dindi!G35 -> 3545.211 | F12: =+Dindi!H35 -> 0 | G12: =+Dindi!J35 -> 0 | H12: =E12+G12 -> 3545.211 | I12: =+Dindi!M3 -> 0 | J12: =+Dindi!L35 -> 3545.211 | K12: =H12+I12-J12 -> 0
A13: 12 | B13: Madanapalli | C13: NA | D13: =+'Madana palli'!E37 -> 0 | E13: =+'Madana palli'!G37 -> 0 | F13: =+'Madana palli'!H37 -> 3.4 | G13: =+'Madana palli'!J37 -> 399.364 | H13: =E13+G13 -> 399.364 | I13: =+'Madana palli'!M3 -> 0 | J13: =+'Madana palli'!L37 -> 399.364 | K13: =H13+I13-J13 -> 0
A14: 13 | B14: Kovvur | C14: Sri Venkateshwara Services | D14: =+'Sri Venkateshwara Services'!E37 -> 879.64 | E14: =+'Sri Venkateshwara Services'!G37 -> 92080.715 | F14: =+'Sri Venkateshwara Services'!H37 -> 70 | G14: =+'Sri Venkateshwara Services'!J37 -> 8187.2 | H14: =E14+G14 -> 100267.92 | I14: =+'Sri Venkateshwara Services'!M3 -> 0 | J14: =+'Sri Venkateshwara Services'!L37 -> 83230 | K14: =H14+I14-J14 -> 17037.915
A15: 14 | B15: Jangareddygudem | C15: Solasa Krishna Oil Company | D15: =+' Solasa Krishna OIl'!E37 -> 2182.97 | E15: =+' Solasa Krishna OIl'!G37 -> 230085.04 | F15: =+' Solasa Krishna OIl'!H37 -> 25.01 | G15: =+' Solasa Krishna OIl'!J37 -> 2944.6774 | H15: =E15+G15 -> 233029.72 | I15: =+' Solasa Krishna OIl'!M3 -> 0 | J15: =+' Solasa Krishna OIl'!L37 -> 186667 | K15: =H15+I15-J15 -> 46362.715
A16: 15 | B16: Amalapuram | C16: Royal Fill 'N' Fly | D16: =+'Amalapuram(KKD)'!E37 -> 7986.03 | E16: =+'Amalapuram(KKD)'!G37 -> 840536.86 | F16: =+'Amalapuram(KKD)'!H37 -> 141 | G16: =+'Amalapuram(KKD)'!J37 -> 16578.78 | H16: =E16+G16 -> 857115.64 | I16: =+'Amalapuram(KKD)'!M3 -> 0 | J16: =+'Amalapuram(KKD)'!L37 -> 430256 | K16: =H16+I16-J16 -> 426859.64
A17: 16 | B17: Yeleshwaram | C17: Sri sathya Filling Station | D17: =+'Yeleshwaram(KKD)'!E37 -> 954.16 | E17: =+'Yeleshwaram(KKD)'!G37 -> 100625.71 | F17: =+'Yeleshwaram(KKD)'!H37 -> 35 | G17: =+'Yeleshwaram(KKD)'!J37 -> 4124.4 | H17: =E17+G17 -> 104750.11 | I17: =+'Yeleshwaram(KKD)'!M3 -> 19106.6 | J17: =+'Yeleshwaram(KKD)'!L37 -> 115358 | K17: =H17+I17-J17 -> 8498.7136
A18: 17 | B18: Pitapuam | C18: Satya Siva Durga Agencies, Chebrolu | D18: =+' Pitapram(KKD)'!E37 -> 5592.86 | E18: =+' Pitapram(KKD)'!G37 -> 588424.8 | F18: =+' Pitapram(KKD)'!H37 -> 188 | G18: =+' Pitapram(KKD)'!J37 -> 22105.04 | H18: =E18+G18 -> 610529.84 | I18: =+' Pitapram(KKD)'!M3 -> 92349.157 | J18: =+' Pitapram(KKD)'!L37 -> 578525 | K18: =H18+I18-J18 -> 124354
A19: 18 | B19: Kakinada | C19: Multiple bunks | D19: =+'Multiple bunks(KKD)'!E289 -> 1535.73 | E19: =+'Multiple bunks(KKD)'!G289 -> 161495.57 | F19: =+'Multiple bunks(KKD)'!H289 -> 184.58 | G19: =+'Multiple bunks(KKD)'!J289 -> 21686.104 | H19: =E19+G19 -> 183181.67 | I19: =+'Multiple bunks(KKD)'!M3 -> 0 | J19: =+'Multiple bunks(KKD)'!L289 -> 183181.67 | K19: =H19+I19-J19 -> 0
A20: 19 | B20: YG Gudda-2 | C20: Pankaja HP Fuel Center | D20: =+'YG Gudda'!E39 -> 9400 | E20: =+'YG Gudda'!G39 -> 931916 | F20: =+'YG Gudda'!H39 -> 245 | G20: =+'YG Gudda'!J39 -> 27253.8 | H20: =E20+G20 -> 959169.8 | I20: =+'YG Gudda'!M3 -> 296621.36 | J20: =+'YG Gudda'!L39 -> 1128000 | K20: =H20+I20-J20 -> 127791.16
A21: 20 | B21: YG Gudda-2 | C21: One stop | D21: =+' YG Gudda-2'!E39 -> 1500 | E21: =+' YG Gudda-2'!G39 -> 148530 | F21: =+' YG Gudda-2'!H39 -> 70 | G21: =+' YG Gudda-2'!J39 -> 7778.4 | H21: =E21+G21 -> 156308.4 | I21: =+' YG Gudda-2'!M3 -> 299.3192 | J21: =+' YG Gudda-2'!L39 -> 0 | K21: =H21+I21-J21 -> 156607.72
A22: 21 | B22: Hosadurga-2 | C22: Shree Veeraprathap Fuel | D22: =+'Hosadurga -2'!E35 -> 2400 | E22: =+'Hosadurga -2'!G35 -> 238512 | F22: =+'Hosadurga -2'!H35 -> 240 | G22: =+'Hosadurga -2'!J35 -> 26812.8 | H22: =+'Hosadurga -2'!K35 -> 265324.8 | I22: =+'Hosadurga -2'!K3 -> 484.7941 | J22: =+'Hosadurga -2'!L35 -> 147000 | K22: =H22+I22-J22 -> 118809.59
A23: 22 | B23: Malebennuru(KUWSDB) | C23: Sri Ramanjuneya Service Station | D23: =+'Malebenur(KUWSDB)'!E37 -> 4150 | E23: =+'Malebenur(KUWSDB)'!G37 -> 414958.5 | F23: =+'Malebenur(KUWSDB)'!H37 -> 200 | G23: =+'Malebenur(KUWSDB)'!J37 -> 22405.2 | H23: =E23+G23 -> 437363.7 | I23: =+'Malebenur(KUWSDB)'!K3 -> 130766.71 | J23: =+'Malebenur(KUWSDB)'!L37 -> 445902 | K23: =H23+I23-J23 -> 122228.41
A24: 23 | B24: kadur | C24: Vishal Service Station | D24: =+Kadur!E35 -> 0 | E24: =+Kadur!G35 -> 0 | F24: =+Kadur!H35 -> 0 | G24: =+Kadur!J35 -> 0 | H24: =E24+G24 -> 0 | I24: =+Kadur!K3 -> 673026.9 | J24: =+Kadur!L35 -> 673026 | K24: =H24+I24-J24 -> 0.9
A25: 24 | B25: Hiriyur(VJNL) | C25: Sri Balaji Agencies | D25: =+'Hiriyur(VJNL)'!E35 -> 4000 | E25: =+'Hiriyur(VJNL)'!G35 -> 400360 | F25: =+'Hiriyur(VJNL)'!H35 -> 315 | G25: =+'Hiriyur(VJNL)'!J35 -> 35317.8 | H25: =E25+G25 -> 435677.8 | I25: =+'Hiriyur(VJNL)'!K3 -> 208267.9 | J25: =+'Hiriyur(VJNL)'!L35 -> 424000 | K25: =H25+I25-J25 -> 219945.7
A26: 25 | B26: Chellakere(KUWSDB) | C26: Shivaganga Service Station | D26: =+'Chellakere -1'!E38 -> 3000 | E26: =+'Chellakere -1'!G38 -> 300150 | F26: =+'Chellakere -1'!H38 -> 175 | G26: =+'Chellakere -1'!J38 -> 19612.25 | H26: =E26+G26 -> 319762.25 | I26: =+'Chellakere -1'!K3 -> 210978.25 | J26: =+'Chellakere -1'!L38 -> 530740 | K26: =H26+I26-J26 -> 0.5014
A27: 26 | B27: Chellakere(KUWSDB)-09 | C27: Shivaganga Service Station | D27: =+' Chellakere-PKG-9'!E36 -> 735.99 | E27: =+' Chellakere-PKG-9'!G36 -> 73532.47 | F27: =+' Chellakere-PKG-9'!H36 -> 41.02 | G27: =+' Chellakere-PKG-9'!J36 -> 4597.1114 | H27: =E27+G27 -> 78129.582 | I27: =+' Chellakere-PKG-9'!M3 -> 0 | J27: =+' Chellakere-PKG-9'!L36 -> 78129.582 | K27: =H27+I27-J27 -> 0
A28: 27 | B28: Molakalmuru | C28: Sri Lakshmi Venkateshwara Filling Station | D28: =+Molakamuru!E35 -> 900 | E28: =+Molakamuru!G35 -> 90036 | F28: =+Molakamuru!H35 -> 85 | G28: =+Molakamuru!J35 -> 9525.1 | H28: =E28+G28 -> 99561.1 | I28: =+Molakamuru!K3 -> 50699.16 | J28: =+Molakamuru!L35 -> 115000 | K28: =H28+I28-J28 -> 35260.26
A29: 28 | B29: Chennagiri | C29: NA | D29: =+' Chennagiri'!E35 -> 860 | E29: =+' Chennagiri'!G35 -> 85894.2 | F29: =+' Chennagiri'!H35 -> 78 | G29: =+' Chennagiri'!J35 -> 8740.68 | H29: =E29+G29 -> 94634.88 | I29: =+' Chennagiri'!K3 -> 0 | J29: =+' Chennagiri'!L35 -> 94634.88 | K29: =H29+I29-J29 -> 0
A30: 29 | B30: Khanapur(PKG-3) | C30: V.V.Varde | D30: =+Khanapur!E35 -> 865.03 | E30: =+Khanapur!G35 -> 85369.611 | F30: =+Khanapur!H35 -> 90 | G30: =+Khanapur!J35 -> 9966.6 | H30: =E30+G30 -> 95336.211 | I30: =+Khanapur!M3 -> 84731.659 | J30: =+Khanapur!L35 -> 138271 | K30: =H30+I30-J30 -> 41796.87
A31: 30 | B31: Munavalli(PKG-3) | C31: Shre Shiva Petroleum | D31: =+'Munavali-2'!E40 -> 5000 | E31: =+'Munavali-2'!G40 -> 496750 | F31: =+'Munavali-2'!H40 -> 30 | G31: =+'Munavali-2'!J40 -> 3343.5 | H31: =E31+G31 -> 500093.5 | I31: =+'Munavali-2'!M3 -> 146708 | J31: =+'Munavali-2'!L40 -> 300000 | K31: =H31+I31-J31 -> 346801.5
A32: 31 | B32: Munavalli(PKG-3) | C32: Daneshwari Petroleum | D32: =+' Munavali'!E39 -> 200 | E32: =+' Munavali'!G39 -> 19826 | F32: =+' Munavali'!H39 -> 217.31 | G32: =+' Munavali'!J39 -> 24167.045 | H32: =E32+G32 -> 43993.045 | I32: =+' Munavali'!M3 -> 274277.22 | J32: =+' Munavali'!L39 -> 317605 | K32: =H32+I32-J32 -> 665.2699
A33: 32 | B33: Borgaon(PKG-3) | C33: Aadisagar Petrolium | D33: =+Borgaon!E35 -> 0 | E33: =+Borgaon!G35 -> 0 | F33: =+Borgaon!H35 -> 0 | G33: =+Borgaon!J35 -> 0 | H33: =E33+G33 -> 0 | I33: =+Borgaon!K3 -> 208.3907 | J33: =+Borgaon!L35 -> 208.39 | K33: =H33+I33-J33 -> 0.00069999999
A34: 33 | B34: Ugar,Kudichi(PKG-3) | C34: Shiri Bhrhmanath Petrolium | D34: =+'Ugar,Khagwad,Kudichi'!E37 -> 7624 | E34: =+'Ugar,Khagwad,Kudichi'!G37 -> 760417.76 | F34: =+'Ugar,Khagwad,Kudichi'!H37 -> 297 | G34: =+'Ugar,Khagwad,Kudichi'!J37 -> 33361.15 | H34: =E34+G34 -> 793778.91 | I34: =+'Ugar,Khagwad,Kudichi'!M3 -> 342020.48 | J34: =+'Ugar,Khagwad,Kudichi'!L37 -> 551965.02 | K34: =H34+I34-J34 -> 583834.37
A35: 34 | B35: Shedbal | C35: Varad Petroluem | D35: =+shedbal!E38 -> 3478.18 | E35: =+shedbal!G38 -> 346853.66 | F35: =+shedbal!H38 -> 192 | G35: =+shedbal!J38 -> 21475.2 | H35: =E35+G35 -> 368328.86 | I35: =+shedbal!M3 -> 506281.15 | J35: =+shedbal!L38 -> 703968.95 | K35: =H35+I35-J35 -> 170641.05
A36: 35 | B36: Kabbur(PKG-3) | C36: Shri Jai Hanuman Petrolium | D36: =+Kabbur!E35 -> 352 | E36: =+Kabbur!G35 -> 34992.32 | F36: =+Kabbur!H35 -> 23.23 | G36: =+Kabbur!J35 -> 2590.3773 | H36: =E36+G36 -> 37582.697 | I36: 0 | J36: =+Kabbur!L35 -> 37582.697 | K36: =H36+I36-J36 -> 0
A37: 36 | B37: Kumta (PKG-1) | C37: V.M.Mirjankar (Kumta) Bharat | D37: =+kumta!E41 -> 1229 | E37: =+kumta!G41 -> 122629.62 | F37: =+kumta!H41 -> 100 | G37: =+kumta!J41 -> 11198 | H37: =E37+G37 -> 133827.62 | I37: =kumta!M3 -> 60343.607 | J37: =+kumta!L41 -> 170079 | K37: =H37+I37-J37 -> 24092.227
A38: 37 | B38: Jalgaon-2 | C38: Nayara | D38: =+'Jalgoan-2'!E56 -> 3826.03 | E38: ='Jalgoan-2'!G56 -> 380734.65 | F38: =+'Jalgoan-2'!H56 -> 160 | G38: =+'Jalgoan-2'!J56 -> 18108.8 | H38: =E38+G38 -> 398843.45 | I38: =+'Jalgoan-2'!M3 -> 4531108.2 | J38: =+'Jalgoan-2'!L56 -> 4879951.6 | K38: =H38+I38-J38 -> 50000.028
A39: 38 | B39: MKBD | C39: Shree Sai Samarth Petroleum | D39: =+MKBD!E42 -> 3000 | E39: =+MKBD!G42 -> 296820 | F39: =+MKBD!H42 -> 50 | G39: =+MKBD!J42 -> 5613.5 | H39: =E39+G39 -> 302433.5 | I39: =+MKBD!K3 -> 929513.51 | J39: =+MKBD!L42 -> 1141380 | K39: =H39+I39-J39 -> 90567.01
A40: 39 | B40: Haveri | C40: M/s Magavi City Fuels | D40: =' Haveri-2'!E42 -> 2755.91 | E40: =' Haveri-2'!G42 -> 273661.86 | F40: =' Haveri-2'!H42 -> 74.5 | G40: =' Haveri-2'!J42 -> 8299.3 | H40: =E40+G40 -> 281961.16 | I40: =' Haveri-2'!M3 -> 119035.39 | J40: =+' Haveri-2'!L42 -> 359944 | K40: =H40+I40-J40 -> 41052.548
...

Sheet HO(DG)
A1: JSASFuel Genie India Pvt.Ltd
A2: S.No | B2: Date | C2: GRN No | D2: Ind No/Bill No | E2: Diesel (Lts) | F2: Price | G2: Amount | H2: Petrol (Lts) | I2: Price | J2: Amount | K2: Total amount | L2: Amount paid | M2: As on date | N2: Remarks
A3: Opening Balance | K3: 265977.75 | M3: 265977.75
A4: 1 | B4: 46235 | G4: =E4*F4 -> 0 | H4: 0 | I4: 0 | J4: =H4*I4 -> 0 | K4: =G4+J4 -> 0 | L4: 0 | M4: =M3+K4-L4 -> 265977.75
A5: 2 | B5: 46236 | G5: =E5*F5 -> 0 | K5: =G5+J5 -> 0 | M5: =M4+K5-L5 -> 265977.75
A6: 3 | B6: 46237 | E6: 70 | F6: 103.76 | G6: =E6*F6 -> 7263.2 | K6: =G6+J6 -> 7263.2 | L6: =H6+K6 -> 7263.2 | M6: =M5+K6-L6 -> 265977.75
A7: 4 | B7: 46238 | G7: =E7*F7 -> 0 | K7: =G7+J7 -> 0 | M7: =M6+K7-L7 -> 265977.75
A8: 5 | B8: 46239 | E8: 70 | F8: 103.76 | G8: =E8*F8 -> 7263.2 | K8: =G8+J8 -> 7263.2 | L8: =H8+K8 -> 7263.2 | M8: =M7+K8-L8 -> 265977.75
A9: 6 | B9: 46240 | G9: =E9*F9 -> 0 | K9: =G9+J9 -> 0 | M9: =M8+K9-L9 -> 265977.75
A10: 7 | B10: 46241 | E10: 140 | F10: 103.76 | G10: =E10*F10 -> 14526.4 | K10: =G10+J10 -> 14526.4 | L10: =H10+K10 -> 14526.4 | M10: =M9+K10-L10 -> 265977.75
B11: 46242 | G11: =E11*F11 -> 0 | K11: =G11+J11 -> 0 | L11: =H11+K11 -> 0 | M11: =M10+K11-L11 -> 265977.75
A12: 8 | B12: 46243 | G12: =E12*F12 -> 0 | K12: =G12+J12 -> 0 | M12: =M11+K12-L12 -> 265977.75
A13: 9 | B13: 46244 | E13: 70 | F13: 103.76 | G13: =E13*F13 -> 7263.2 | K13: =G13+J13 -> 7263.2 | L13: =H13+K13 -> 7263.2 | M13: =M12+K13-L13 -> 265977.75
A14: 10 | B14: 46245 | E14: 70 | F14: 103.76 | G14: =E14*F14 -> 7263.2 | K14: =G14+J14 -> 7263.2 | L14: =H14+K14 -> 7263.2 | M14: =M13+K14-L14 -> 265977.75
A15: 11 | B15: 46246 | G15: =E15*F15 -> 0 | K15: =G15+J15 -> 0 | M15: =M14+K15-L15 -> 265977.75
A16: 12 | B16: 46247 | E16: 70 | F16: 103.76 | G16: =E16*F16 -> 7263.2 | K16: =G16+J16 -> 7263.2 | L16: =H16+K16 -> 7263.2 | M16: =M15+K16-L16 -> 265977.75 | N16: Credit Card
A17: 13 | B17: 46248 | G17: =E17*F17 -> 0 | K17: =G17+J17 -> 0 | L17: 265910 | M17: =M16+K17-L17 -> 67.75
B18: 46248 | E18: 70 | F18: 103.76 | G18: =E18*F18 -> 7263.2 | K18: =G18+J18 -> 7263.2 | L18: =H18+K18 -> 7263.2 | M18: =M17+K18-L18 -> 67.75
A19: 14 | B19: 46249 | G19: =E19*F19 -> 0 | K19: =G19+J19 -> 0 | L19: 67.75 | M19: =M18+K19-L19 -> 0 | N19: Roundoff
A20: 15 | B20: 46250 | G20: =E20*F20 -> 0 | K20: =G20+J20 -> 0 | M20: =M19+K20-L20 -> 0
A21: 16 | B21: 46251 | G21: =E21*F21 -> 0 | K21: =G21+J21 -> 0 | M21: =M20+K21-L21 -> 0
A22: 17 | B22: 46252 | G22: =E22*F22 -> 0 | K22: =G22+J22 -> 0 | M22: =M21+K22-L22 -> 0
A23: 18 | B23: 46253 | E23: 140 | F23: 103.76 | G23: =E23*F23 -> 14526.4 | K23: =G23+J23 -> 14526.4 | L23: =H23+K23 -> 14526.4 | M23: =M22+K23-L23 -> 0
A24: 19 | B24: 46254 | E24: 70 | F24: 103.76 | G24: =E24*F24 -> 7263.2 | K24: =G24+J24 -> 7263.2 | L24: =H24+K24 -> 7263.2 | M24: =M23+K24-L24 -> 0
A25: 20 | B25: 46255 | G25: =E25*F25 -> 0 | K25: =G25+J25 -> 0 | M25: =M24+K25-L25 -> 0
A26: 21 | B26: 46256 | E26: 70 | F26: 103.76 | G26: =E26*F26 -> 7263.2 | K26: =G26+J26 -> 7263.2 | L26: =H26+K26 -> 7263.2 | M26: =M25+K26-L26 -> 0
A27: 22 | B27: 46257 | G27: =E27*F27 -> 0 | K27: =G27+J27 -> 0 | M27: =M26+K27-L27 -> 0
A28: 23 | B28: 46258 | E28: 50 | F28: 103.76 | G28: =E28*F28 -> 5188 | K28: =G28+J28 -> 5188 | L28: =H28+K28 -> 5188 | M28: =M27+K28-L28 -> 0
A29: 24 | B29: 46259 | G29: =E29*F29 -> 0 | K29: =G29+J29 -> 0 | M29: =M28+K29-L29 -> 0
A30: 25 | B30: 46260 | E30: 100 | F30: 103.76 | G30: =E30*F30 -> 10376 | K30: =G30+J30 -> 10376 | L30: =H30+K30 -> 10376 | M30: =M29+K30-L30 -> 0
A31: 26 | B31: 46261 | G31: =E31*F31 -> 0 | K31: =G31+J31 -> 0 | M31: =M30+K31-L31 -> 0
A32: 27 | B32: 46262 | E32: 100 | F32: 103.76 | G32: =E32*F32 -> 10376 | K32: =G32+J32 -> 10376 | L32: =H32+K32 -> 10376 | M32: =M31+K32-L32 -> 0
A33: 28 | B33: 46263 | G33: =E33*F33 -> 0 | K33: =G33+J33 -> 0 | M33: =M32+K33-L33 -> 0
B34: 46264 | G34: =E34*F34 -> 0 | M34: =M33+K34-L34 -> 0
A35: 29 | B35: 46265 | E35: 70 | F35: 103.76 | G35: =E35*F35 -> 7263.2 | K35: =G35+J35 -> 7263.2 | L35: =H35+K35 -> 7263.2 | M35: =M34+K35-L35 -> 0
G36: =E36*F36 -> 0 | K36: =G36+J36 -> 0 | M36: =M35+K36-L36 -> 0
A37: 30 | K37: =G37+J37 -> 0 | M37: =M36+K37-L37 -> 0
A38: 31 | M38: =M37+K38-L38 -> 0
A39: 32 | M39: =M38+K39-L39 -> 0
A40: 33
...

Sheet Khammam-1
A1: Divya laxmi ganapathi
A2: S.No | B2: Date | C2: GRN No | D2: Ind No/Bill No | E2: Diesel (Lts) | F2: Price | G2: Amount | H2: Petrol (Lts) | I2: Price | J2: Amount | K2: Total amount | L2: Amount paid | M2: As 0n Date | N2: Remarks
A3: Opening Balance | K3: 3834148.7 | M3: 3834148.7 | O3: =K3-M3 -> 0
A4: 1 | B4: 46235 | G4: =E4*F4 -> 0 | K4: =G4+J4 -> 0 | M4: =M3+K4-L4 -> 3834148.7
A5: 2 | B5: 46236 | G5: =E5*F5 -> 0 | J5: =H5*I5 -> 0 | K5: =G5+J5 -> 0 | M5: =M4+K5-L5 -> 3834148.7
A6: 3 | B6: 46237 | G6: =E6*F6 -> 0 | J6: =H6*I6 -> 0 | K6: =G6+J6 -> 0 | M6: =M5+K6-L6 -> 3834148.7
A7: 4 | B7: 46238 | G7: =E7*F7 -> 0 | J7: =H7*I7 -> 0 | K7: =G7+J7 -> 0 | M7: =M6+K7-L7 -> 3834148.7
A8: 5 | B8: 46239 | G8: =E8*F8 -> 0 | J8: =H8*I8 -> 0 | K8: =G8+J8 -> 0 | M8: =M7+K8-L8 -> 3834148.7
A9: 6 | B9: 46240 | G9: =E9*F9 -> 0 | J9: =H9*I9 -> 0 | K9: =G9+J9 -> 0 | M9: =M8+K9-L9 -> 3834148.7
A10: 7 | B10: 46241 | G10: =E10*F10 -> 0 | J10: =H10*I10 -> 0 | K10: =G10+J10 -> 0 | M10: =M9+K10-L10 -> 3834148.7
A11: 8 | B11: 46242 | G11: =E11*F11 -> 0 | J11: =H11*I11 -> 0 | K11: =G11+J11 -> 0 | M11: =M10+K11-L11 -> 3834148.7
A12: 9 | B12: 46243 | G12: =E12*F12 -> 0 | J12: =H12*I12 -> 0 | K12: =G12+J12 -> 0 | M12: =M11+K12-L12 -> 3834148.7
A13: 10 | B13: 46244 | G13: =E13*F13 -> 0 | J13: =H13*I13 -> 0 | K13: =G13+J13 -> 0 | M13: =M12+K13-L13 -> 3834148.7
A14: 11 | B14: 46245 | G14: =E14*F14 -> 0 | J14: =H14*I14 -> 0 | K14: =G14+J14 -> 0 | M14: =M13+K14-L14 -> 3834148.7
A15: 12 | B15: 46246 | G15: =E15*F15 -> 0 | J15: =H15*I15 -> 0 | K15: =G15+J15 -> 0 | M15: =M14+K15-L15 -> 3834148.7
A16: 13 | B16: 46247 | E16: 2800 | F16: 103.8 | G16: =E16*F16 -> 290640 | J16: =H16*I16 -> 0 | K16: =G16+J16 -> 290640 | L16: 3834140 | M16: =M15+K16-L16 -> 290648.71
A17: 14 | B17: 46248 | G17: =E17*F17 -> 0 | J17: =H17*I17 -> 0 | K17: =G17+J17 -> 0 | M17: =M16+K17-L17 -> 290648.71
A18: 15 | B18: 46249 | E18: 2800 | F18: 103.8 | G18: =E18*F18 -> 290640 | J18: =H18*I18 -> 0 | K18: =G18+J18 -> 290640 | M18: =M17+K18-L18 -> 581288.71
A19: 16 | B19: 46250 | E19: 2700 | F19: 103.8 | G19: =E19*F19 -> 280260 | J19: =H19*I19 -> 0 | K19: =G19+J19 -> 280260 | M19: =M18+K19-L19 -> 861548.71
A20: 17 | B20: 46251 | E20: 4300 | F20: 103.8 | G20: =E20*F20 -> 446340 | H20: 75 | I20: 115.69 | J20: =H20*I20 -> 8676.75 | K20: =G20+J20 -> 455016.75 | M20: =M19+K20-L20 -> 1316565.5
A21: 18 | B21: 46252 | E21: 2800 | F21: 103.8 | G21: =E21*F21 -> 290640 | J21: =H21*I21 -> 0 | K21: =G21+J21 -> 290640 | M21: =M20+K21-L21 -> 1607205.5
A22: 19 | B22: 46253 | E22: 1500 | F22: 103.8 | G22: =E22*F22 -> 155700 | H22: 130 | I22: 115.69 | J22: =H22*I22 -> 15039.7 | K22: =G22+J22 -> 170739.7 | M22: =M21+K22-L22 -> 1777945.2
A23: 20 | B23: 46254 | E23: 1000 | F23: 103.8 | G23: =E23*F23 -> 103800 | J23: =H23*I23 -> 0 | K23: =G23+J23 -> 103800 | M23: =M22+K23-L23 -> 1881745.2
A24: 21 | B24: 46255 | G24: =E24*F24 -> 0 | J24: =H24*I24 -> 0 | K24: =G24+J24 -> 0 | M24: =M23+K24-L24 -> 1881745.2
A25: 22 | B25: 46256 | E25: 1200 | F25: 103.8 | G25: =E25*F25 -> 124560 | J25: =H25*I25 -> 0 | K25: =G25+J25 -> 124560 | M25: =M24+K25-L25 -> 2006305.2
A26: 23 | B26: 46257 | G26: =E26*F26 -> 0 | J26: =H26*I26 -> 0 | K26: =G26+J26 -> 0 | M26: =M25+K26-L26 -> 2006305.2
A27: 24 | B27: 46258 | G27: =E27*F27 -> 0 | J27: =H27*I27 -> 0 | K27: =G27+J27 -> 0 | M27: =M26+K27-L27 -> 2006305.2
A28: 25 | B28: 46259 | E28: 2700 | F28: 103.8 | G28: =E28*F28 -> 280260 | J28: =H28*I28 -> 0 | K28: =G28+J28 -> 280260 | M28: =M27+K28-L28 -> 2286565.2
A29: 26 | B29: 46260 | E29: 1600 | F29: 103.8 | G29: =E29*F29 -> 166080 | J29: =H29*I29 -> 0 | K29: =G29+J29 -> 166080 | M29: =M28+K29-L29 -> 2452645.2
A30: 27 | B30: 46261 | G30: =E30*F30 -> 0 | J30: =H30*I30 -> 0 | K30: =G30+J30 -> 0 | M30: =M29+K30-L30 -> 2452645.2
A31: 28 | B31: 46262 | E31: 800 | F31: 103.8 | G31: =E31*F31 -> 83040 | J31: =H31*I31 -> 0 | K31: =G31+J31 -> 83040 | M31: =M30+K31-L31 -> 2535685.2
A32: 29 | B32: 46263 | E32: 1400 | F32: 103.8 | G32: =E32*F32 -> 145320 | J32: =H32*I32 -> 0 | K32: =G32+J32 -> 145320 | M32: =M31+K32-L32 -> 2681005.2
A33: 30 | B33: 46264 | G33: =E33*F33 -> 0 | J33: =H33*I33 -> 0 | K33: =G33+J33 -> 0 | M33: =M32+K33-L33 -> 2681005.2
A34: 31 | B34: 46265 | E34: 1200 | F34: 103.8 | G34: =E34*F34 -> 124560 | K34: =G34+J34 -> 124560 | M34: =M33+K34-L34 -> 2805565.2
A35: 32 | G35: =E35*F35 -> 0 | J35: =H35*I35 -> 0 | K35: =G35+J35 -> 0 | M35: =M34+K35-L35 -> 2805565.2
A36: 33 | G36: =E36*F36 -> 0 | J36: =H36*I36 -> 0 | K36: =G36+J36 -> 0
A37: 34 | G37: =E37*F37 -> 0 | J37: =H37*I37 -> 0 | K37: =G37+J37 -> 0
E38: =SUM(E3:E37) -> 26800 | G38: =SUM(G3:G37) -> 2781840 | H38: =SUM(H3:H37) -> 205 | J38: =SUM(J3:J37) -> 23716.45 | K38: =SUM(K4:K37) -> 2805556.5 | L38: =SUM(L3:L37) -> 3834140

Sheet Khammam-2
A1: Jayasai union bunk
A2: S.No | B2: Date | C2: GRN No | D2: Ind No/Bill No | E2: Diesel (Lts) | F2: Price | G2: Amount | H2: Petrol (Lts) | I2: Price | J2: Amount | K2: Total amount | L2: Amount paid | M2: As 0n Date | N2: Remarks
A3: Opening Balance | K3: 18929637 | M3: 18929637
A4: 1 | B4: 46235 | E4: 5600 | F4: 103.82 | G4: =E4*F4 -> 581392 | H4: 95 | I4: 115.72 | J4: =H4*I4 -> 10993.4 | K4: =G4+J4 -> 592385.4 | L4: 250000 | M4: =M3+K4-L4 -> 19272022 | N4: 250000-IOCL/40696-DGM Sir | O4: 40696
A5: 2 | B5: 46236 | G5: =E5*F5 -> 0 | J5: =H5*I5 -> 0 | K5: =G5+J5 -> 0 | M5: =M4+K5-L5 -> 19272022
A6: 3 | B6: 46237 | E6: 2215.373 | F6: 103.82 | G6: =E6*F6 -> 230000.02 | J6: =H6*I6 -> 0 | K6: =G6+J6 -> 230000.02 | M6: =M5+K6-L6 -> 19502022 | N6: DGM Sir | O6: 230000
A7: 4 | B7: 46238 | E7: 1300.33 | F7: 103.82 | G7: =E7*F7 -> 135000.26 | J7: =H7*I7 -> 0 | K7: =G7+J7 -> 135000.26 | M7: =M6+K7-L7 -> 19637023 | N7: DGM Sir | O7: 135000.26
A8: 5 | B8: 46239 | G8: =E8*F8 -> 0 | H8: 120 | I8: 115.72 | J8: =H8*I8 -> 13886.4 | K8: =G8+J8 -> 13886.4 | M8: =M7+K8-L8 -> 19650909
A9: 6 | B9: 46240 | E9: 3530 | F9: 103.82 | G9: =E9*F9 -> 366484.6 | J9: =H9*I9 -> 0 | K9: =G9+J9 -> 366484.6 | M9: =M8+K9-L9 -> 20017394 | N9: Devendra | O9: 366485
A10: 7 | B10: 46241 | E10: 2720 | F10: 103.82 | G10: =E10*F10 -> 282390.4 | J10: =H10*I10 -> 0 | K10: =G10+J10 -> 282390.4 | M10: =M9+K10-L10 -> 20299784 | N10: Devendra | O10: 282390.4
A11: 8 | B11: 46242 | E11: 3178.58 | F11: 103.82 | G11: =E11*F11 -> 330000.18 | H11: 95 | I11: 115.72 | J11: =H11*I11 -> 10993.4 | K11: =G11+J11 -> 340993.58 | L11: 70000 | M11: =M10+K11-L11 -> 20570778 | N11: 260000/DGM-70000 IOCL | O11: 260000
A12: 9 | B12: 46243 | G12: =E12*F12 -> 0 | J12: =H12*I12 -> 0 | K12: =G12+J12 -> 0 | M12: =M11+K12-L12 -> 20570778
A13: 10 | B13: 46244 | E13: 722.405 | F13: 103.82 | G13: =E13*F13 -> 75000.087 | J13: =H13*I13 -> 0 | K13: =G13+J13 -> 75000.087 | M13: =M12+K13-L13 -> 20645778 | N13: DGM Sir | O13: 75000 | W13: 250000
A14: 11 | B14: 46245 | E14: 4382.59 | F14: 103.82 | G14: =E14*F14 -> 455000.49 | H14: 130 | I14: 115.72 | J14: =H14*I14 -> 15043.6 | K14: =G14+J14 -> 470044.09 | L14: 300000 | M14: =M13+K14-L14 -> 20815822 | N14: 300000-IOCL/DGM-155000 | O14: 155000 | W14: 70000
A15: 12 | B15: 46246 | E15: 674.25 | F15: 103.82 | G15: =E15*F15 -> 70000.635 | J15: =H15*I15 -> 0 | K15: =G15+J15 -> 70000.635 | M15: =M14+K15-L15 -> 20885823 | N15: DGM Sir | O15: 70000 | S15: 5000000 | W15: 46366
A16: 13 | B16: 46247 | E16: 5400 | F16: 103.82 | G16: =E16*F16 -> 560628 | J16: =H16*I16 -> 0 | K16: =G16+J16 -> 560628 | L16: 15885823 | M16: =M15+K16-L16 -> 5560628 | O16: =SUM(O4:O15) -> 1614571.7 | Q16: 6086287 | S16: 6086287
A17: 14 | B17: 46248 | E17: 5400 | F17: 103.82 | G17: =E17*F17 -> 560628 | H17: 75 | I17: 115.72 | J17: =H17*I17 -> 8679 | K17: =G17+J17 -> 569307 | M17: =M16+K17-L17 -> 6129935 | O17: 1410932 | S17: =SUM(S15:S16) -> 11086287
A18: 15 | B18: 46249 | G18: =E18*F18 -> 0 | J18: =H18*I18 -> 0 | K18: =G18+J18 -> 0 | M18: =M17+K18-L18 -> 6129935 | O18: 600000 | S18: 1162961.4
A19: 16 | B19: 46250 | G19: =E19*F19 -> 0 | J19: =H19*I19 -> 0 | K19: =G19+J19 -> 0 | M19: =M18+K19-L19 -> 6129935 | O19: =SUM(O16:O18) -> 3625503.7 | S19: =S17-S18 -> 9923325.6
A20: 17 | B20: 46251 | G20: =E20*F20 -> 0 | J20: =H20*I20 -> 0 | K20: =G20+J20 -> 0 | M20: =M19+K20-L20 -> 6129935 | S20: 32869.06
A21: 18 | B21: 46252 | G21: =E21*F21 -> 0 | J21: =H21*I21 -> 0 | K21: =G21+J21 -> 0 | M21: =M20+K21-L21 -> 6129935 | S21: =S19+S20 -> 9956194.6
A22: 19 | B22: 46253 | G22: =E22*F22 -> 0 | J22: =H22*I22 -> 0 | K22: =G22+J22 -> 0 | M22: =M21+K22-L22 -> 6129935
A23: 20 | B23: 46254 | G23: =E23*F23 -> 0 | J23: =H23*I23 -> 0 | K23: =G23+J23 -> 0 | M23: =M22+K23-L23 -> 6129935
A24: 21 | B24: 46255 | G24: =E24*F24 -> 0 | J24: =H24*I24 -> 0 | K24: =G24+J24 -> 0 | M24: =M23+K24-L24 -> 6129935
A25: 22 | B25: 46256 | G25: =E25*F25 -> 0 | J25: =H25*I25 -> 0 | K25: =G25+J25 -> 0 | M25: =M24+K25-L25 -> 6129935
A26: 23 | B26: 46257 | G26: =E26*F26 -> 0 | J26: =H26*I26 -> 0 | K26: =G26+J26 -> 0 | M26: =M25+K26-L26 -> 6129935
A27: 24 | B27: 46258 | G27: =E27*F27 -> 0 | J27: =H27*I27 -> 0 | K27: =G27+J27 -> 0 | M27: =M26+K27-L27 -> 6129935
A28: 25 | B28: 46259 | G28: =E28*F28 -> 0 | J28: =H28*I28 -> 0 | K28: =G28+J28 -> 0 | M28: =M27+K28-L28 -> 6129935
A29: 26 | B29: 46260 | G29: =E29*F29 -> 0 | J29: =H29*I29 -> 0 | K29: =G29+J29 -> 0 | M29: =M28+K29-L29 -> 6129935
A30: 27 | B30: 46261 | G30: =E30*F30 -> 0 | J30: =H30*I30 -> 0 | K30: =G30+J30 -> 0 | M30: =M29+K30-L30 -> 6129935
A31: 28 | B31: 46262 | G31: =E31*F31 -> 0 | J31: =H31*I31 -> 0 | K31: =G31+J31 -> 0 | L31: 6129935 | M31: =M30+K31-L31 -> 0
A32: 29 | B32: 46263 | G32: =E32*F32 -> 0 | J32: =H32*I32 -> 0 | K32: =G32+J32 -> 0 | M32: =M31+K32-L32 -> 0
A33: 30 | B33: 46264 | G33: =E33*F33 -> 0 | J33: =H33*I33 -> 0 | K33: =G33+J33 -> 0 | M33: =M32+K33-L33 -> 0
A34: 31 | B34: 46265 | G34: =E34*F34 -> 0 | J34: =H34*I34 -> 0 | K34: =G34+J34 -> 0 | M34: =M33+K34-L34 -> 0
A35: 32 | G35: =E35*F35 -> 0 | J35: =H35*I35 -> 0 | K35: =G35+J35 -> 0 | M35: =M34+K35-L35 -> 0
A36: 33 | G36: =E36*F36 -> 0 | J36: =H36*I36 -> 0 | K36: =G36+J36 -> 0 | M36: =M35+K36-L36 -> 0
E38: =SUM(E4:E36) -> 35123.528 | G38: =SUM(G4:G36) -> 3646524.7 | H38: =SUM(H4:H36) -> 515 | J38: =SUM(J4:J36) -> 59595.8 | K38: =SUM(K4:K36) -> 3706120.5 | L38: =SUM(L4:L36) -> 22635758

Sheet Khammam-3
A1: JSASFuel Genie India Pvt.Ltd
A2: S.No | B2: Date | C2: GRN No | D2: Ind No/Bill No | E2: Diesel (Lts) | F2: Price | G2: Amount | H2: Petrol (Lts) | I2: Price | J2: Amount | K2: Total amount | L2: Amount paid | M2: As 0n Date | N2: Remarks
A3: Opening Balance | K3: 1510680 | M3: 1510680
A4: 1 | B4: 46235 | G4: =E4*F4 -> 0 | J4: =H4*I4 -> 0 | K4: =G4+J4 -> 0 | M4: =M3+K4-L4 -> 1510680
A5: 2 | B5: 46236 | G5: =E5*F5 -> 0 | J5: =H5*I5 -> 0 | K5: =G5+J5 -> 0 | M5: =M4+K5-L5 -> 1510680
A6: 3 | B6: 46237 | G6: =E6*F6 -> 0 | J6: =H6*I6 -> 0 | K6: =G6+J6 -> 0 | M6: =M5+K6-L6 -> 1510680
A7: 4 | B7: 46238 | G7: =E7*F7 -> 0 | J7: =H7*I7 -> 0 | K7: =G7+J7 -> 0 | M7: =M6+K7-L7 -> 1510680
A8: 5 | B8: 46239 | G8: =E8*F8 -> 0 | J8: =H8*I8 -> 0 | K8: =G8+J8 -> 0 | L8: 1200000 | M8: =M7+K8-L8 -> 310680
A9: 6 | B9: 46240 | G9: =E9*F9 -> 0 | J9: =H9*I9 -> 0 | K9: =G9+J9 -> 0 | L9: 310680 | M9: =M8+K9-L9 -> 0
A10: 7 | B10: 46241 | G10: =E10*F10 -> 0 | J10: =H10*I10 -> 0 | K10: =G10+J10 -> 0 | M10: =M9+K10-L10 -> 0
A11: 8 | B11: 46242 | G11: =E11*F11 -> 0 | J11: =H11*I11 -> 0 | K11: =G11+J11 -> 0 | M11: =M10+K11-L11 -> 0
A12: 9 | B12: 46243 | G12: =E12*F12 -> 0 | J12: =H12*I12 -> 0 | K12: =G12+J12 -> 0 | M12: =M11+K12-L12 -> 0
A13: 10 | B13: 46244 | G13: =E13*F13 -> 0 | J13: =H13*I13 -> 0 | K13: =G13+J13 -> 0 | M13: =M12+K13-L13 -> 0
A14: 11 | B14: 46245 | G14: =E14*F14 -> 0 | J14: =H14*I14 -> 0 | K14: =G14+J14 -> 0 | M14: =M13+K14-L14 -> 0
A15: 12 | B15: 46246 | G15: =E15*F15 -> 0 | J15: =H15*I15 -> 0 | K15: =G15+J15 -> 0 | M15: =M14+K15-L15 -> 0
A16: 13 | B16: 46247 | G16: =E16*F16 -> 0 | J16: =H16*I16 -> 0 | K16: =G16+J16 -> 0 | M16: =M15+K16-L16 -> 0
A17: 14 | B17: 46248 | G17: =E17*F17 -> 0 | J17: =H17*I17 -> 0 | K17: =G17+J17 -> 0 | M17: =M16+K17-L17 -> 0
A18: 15 | B18: 46249 | G18: =E18*F18 -> 0 | J18: =H18*I18 -> 0 | K18: =G18+J18 -> 0 | M18: =M17+K18-L18 -> 0
A19: 16 | B19: 46250 | G19: =E19*F19 -> 0 | J19: =H19*I19 -> 0 | K19: =G19+J19 -> 0 | M19: =M18+K19-L19 -> 0
A20: 17 | B20: 46251 | G20: =E20*F20 -> 0 | J20: =H20*I20 -> 0 | K20: =G20+J20 -> 0 | M20: =M19+K20-L20 -> 0
A21: 18 | B21: 46252 | G21: =E21*F21 -> 0 | J21: =H21*I21 -> 0 | K21: =G21+J21 -> 0 | M21: =M20+K21-L21 -> 0
... A33: 30 | B33: 46264 | G33: =E33*F33 -> 0 | J33: =H33*I33 -> 0 | K33: =G33+J33 -> 0 | M33: =M32+K33-L33 -> 0
A34: 31 | G34: =E34*F34 -> 0 | J34: =H34*I34 -> 0 | K34: =G34+J34 -> 0 | M34: =M33+K34-L34 -> 0
E35: =SUM(E4:E34) -> 0 | G35: =SUM(G4:G34) -> 0 | H35: =SUM(H4:H34) -> 0 | J35: =SUM(J4:J34) -> 0 | K35: =SUM(K4:K34) -> 0 | L35: =SUM(L4:L34) -> 1510680

Sheet Khammam-4
A1: Sai Madeana Filling Station
A2: S.No | B2: Date | C2: GRN No | D2: Ind No/Bill No | E2: Diesel (Lts) | F2: Price | G2: Amount | H2: Petrol (Lts) | I2: Price | J2: Amount | K2: Total amount | L2: Amount paid | M2: As 0n Date | N2: Remarks
A3: Opening Balance | K3: 0 | M3: 0
A4: 1 | B4: 46235 | G4: =E4*F4 -> 0 | J4: =H4*I4 -> 0 | K4: =G4+J4 -> 0 | M4: =M3+K4-L4 -> 0
A5: 2 | B5: 46236 | G5: =E5*F5 -> 0 | J5: =H5*I5 -> 0 | K5: =G5+J5 -> 0 | M5: =M4+K5-L5 -> 0
A6: 3 | B6: 46237 | G6: =E6*F6 -> 0 | J6: =H6*I6 -> 0 | K6: =G6+J6 -> 0 | M6: =M5+K6-L6 -> 0
A7: 4 | B7: 46238 | G7: =E7*F7 -> 0 | J7: =H7*I7 -> 0 | K7: =G7+J7 -> 0 | M7: =M6+K7-L7 -> 0
A8: 5 | B8: 46239 | G8: =E8*F8 -> 0 | J8: =H8*I8 -> 0 | K8: =G8+J8 -> 0 | M8: =M7+K8-L8 -> 0
A9: 6 | B9: 46240 | G9: =E9*F9 -> 0 | J9: =H9*I9 -> 0 | K9: =G9+J9 -> 0 | M9: =M8+K9-L9 -> 0
A10: 7 | B10: 46241 | G10: =E10*F10 -> 0 | J10: =H10*I10 -> 0 | K10: =G10+J10 -> 0 | M10: =M9+K10-L10 -> 0
A11: 8 | B11: 46242 | G11: =E11*F11 -> 0 | J11: =H11*I11 -> 0 | K11: =G11+J11 -> 0 | M11: =M10+K11-L11 -> 0
A12: 9 | B12: 46243 | G12: =E12*F12 -> 0 | J12: =H12*I12 -> 0 | K12: =G12+J12 -> 0 | M12: =M11+K12-L12 -> 0
A13: 10 | B13: 46244 | G13: =E13*F13 -> 0 | J13: =H13*I13 -> 0 | K13: =G13+J13 -> 0 | M13: =M12+K13-L13 -> 0
A14: 11 | B14: 46245 | G14: =E14*F14 -> 0 | J14: =H14*I14 -> 0 | K14: =G14+J14 -> 0 | M14: =M13+K14-L14 -> 0
A15: 12 | B15: 46246 | G15: =E15*F15 -> 0 | J15: =H15*I15 -> 0 | K15: =G15+J15 -> 0 | M15: =M14+K15-L15 -> 0
... A21: 18 | B21: 46252 | G21: =E21*F21 -> 0 | J21: =H21*I21 -> 0 | K21: =G21+J21 -> 0 | M21: =M20+K21-L21 -> 0
A22: 19 | B22: 46253 | E22: 2700 | F22: 103.62 | G22: =E22*F22 -> 279774 | J22: =H22*I22 -> 0 | K22: =G22+J22 -> 279774 | M22: =M21+K22-L22 -> 279774
A23: 20 | B23: 46254 | G23: =E23*F23 -> 0 | J23: =H23*I23 -> 0 | K23: =G23+J23 -> 0 | M23: =M22+K23-L23 -> 279774
A24: 21 | B24: 46255 | E24: 2700 | F24: 103.62 | G24: =E24*F24 -> 279774 | J24: =H24*I24 -> 0 | K24: =G24+J24 -> 279774 | M24: =M23+K24-L24 -> 559548
A25: 22 | B25: 46256 | E25: 2700 | F25: 103.62 | G25: =E25*F25 -> 279774 | H25: 35 | I25: 115.49 | J25: =H25*I25 -> 4042.15 | K25: =G25+J25 -> 283816.15 | M25: =M24+K25-L25 -> 843364.15
A26: 23 | B26: 46257 | G26: =E26*F26 -> 0 | J26: =H26*I26 -> 0 | K26: =G26+J26 -> 0 | M26: =M25+K26-L26 -> 843364.15
A27: 24 | B27: 46258 | G27: =E27*F27 -> 0 | J27: =H27*I27 -> 0 | K27: =G27+J27 -> 0 | M27: =M26+K27-L27 -> 843364.15
A28: 25 | B28: 46259 | E28: 2700 | F28: 103.62 | G28: =E28*F28 -> 279774 | J28: =H28*I28 -> 0 | K28: =G28+J28 -> 279774 | M28: =M27+K28-L28 -> 1123138.1
A29: 26 | B29: 46260 | G29: =E29*F29 -> 0 | J29: =H29*I29 -> 0 | K29: =G29+J29 -> 0 | M29: =M28+K29-L29 -> 1123138.1
A30: 27 | B30: 46261 | G30: =E30*F30 -> 0 | J30: =H30*I30 -> 0 | K30: =G30+J30 -> 0 | M30: =M29+K30-L30 -> 1123138.1
A31: 28 | B31: 46262 | E31: 2700 | F31: 103.62 | G31: =E31*F31 -> 279774 | H31: 35 | I31: 115.49 | J31: =H31*I31 -> 4042.15 | K31: =G31+J31 -> 283816.15 | L31: 1123138 | M31: =M30+K31-L31 -> 283816.3
A32: 29 | B32: 46263 | E32: 2700 | F32: 103.62 | G32: =E32*F32 -> 279774 | J32: =H32*I32 -> 0 | K32: =G32+J32 -> 279774 | M32: =M31+K32-L32 -> 563590.3
A33: 30 | B33: 46264 | G33: =E33*F33 -> 0 | J33: =H33*I33 -> 0 | K33: =G33+J33 -> 0 | M33: =M32+K33-L33 -> 563590.3
A34: 31 | B34: 46265 | E34: 2700 | F34: 103.62 | G34: =E34*F34 -> 279774 | J34: =H34*I34 -> 0 | K34: =G34+J34 -> 279774 | M34: =M33+K34-L34 -> 843364.3
E35: =SUM(E4:E34) -> 18900 | G35: =SUM(G4:G34) -> 1958418 | H35: =SUM(H4:H34) -> 70 | J35: =SUM(J4:J34) -> 8084.3 | K35: =SUM(K4:K34) -> 1966502.3 | L35: =SUM(L4:L34) -> 1123138

Sheet  Khammam-5
A1: Vajra mahalakshmi filling station
A2: S.No | B2: Date | C2: GRN No | D2: Ind No/Bill No | E2: Diesel (Lts) | F2: Price | G2: Amount | H2: Petrol (Lts) | I2: Price | J2: Amount | K2: Total amount | L2: Amount paid | M2: As 0n Date | N2: Remarks
A3: Opening Balance | K3: 0 | M3: 0
A4: 1 | B4: 46235 | G4: =E4*F4 -> 0 | J4: =H4*I4 -> 0 | K4: =G4+J4 -> 0 | M4: =M3+K4-L4 -> 0
A5: 2 | B5: 46236 | G5: =E5*F5 -> 0 | J5: =H5*I5 -> 0 | K5: =G5+J5 -> 0 | M5: =M4+K5-L5 -> 0
A6: 3 | B6: 46237 | G6: =E6*F6 -> 0 | J6: =H6*I6 -> 0 | K6: =G6+J6 -> 0 | M6: =M5+K6-L6 -> 0
A7: 4 | B7: 46238 | G7: =E7*F7 -> 0 | J7: =H7*I7 -> 0 | K7: =G7+J7 -> 0 | M7: =M6+K7-L7 -> 0
A8: 5 | B8: 46239 | G8: =E8*F8 -> 0 | J8: =H8*I8 -> 0 | K8: =G8+J8 -> 0 | M8: =M7+K8-L8 -> 0
A9: 6 | B9: 46240 | G9: =E9*F9 -> 0 | J9: =H9*I9 -> 0 | K9: =G9+J9 -> 0 | M9: =M8+K9-L9 -> 0
A10: 7 | B10: 46241 | G10: =E10*F10 -> 0 | J10: =H10*I10 -> 0 | K10: =G10+J10 -> 0 | M10: =M9+K10-L10 -> 0
A11: 8 | B11: 46242 | G11: =E11*F11 -> 0 | J11: =H11*I11 -> 0 | K11: =G11+J11 -> 0 | M11: =M10+K11-L11 -> 0
A12: 9 | B12: 46243 | G12: =E12*F12 -> 0 | J12: =H12*I12 -> 0 | K12: =G12+J12 -> 0 | M12: =M11+K12-L12 -> 0
A13: 10 | B13: 46244 | G13: =E13*F13 -> 0 | J13: =H13*I13 -> 0 | K13: =G13+J13 -> 0 | M13: =M12+K13-L13 -> 0
A14: 11 | B14: 46245 | G14: =E14*F14 -> 0 | J14: =H14*I14 -> 0 | K14: =G14+J14 -> 0 | M14: =M13+K14-L14 -> 0
A15: 12 | B15: 46246 | G15: =E15*F15 -> 0 | J15: =H15*I15 -> 0 | K15: =G15+J15 -> 0 | M15: =M14+K15-L15 -> 0
... A22: 19 | B22: 46253 | G22: =E22*F22 -> 0 | J22: =H22*I22 -> 0 | K22: =G22+J22 -> 0 | M22: =M21+K22-L22 -> 0
A23: 20 | B23: 46254 | E23: 5260 | F23: 103.62 | G23: =E23*F23 -> 545041.2 | J23: =H23*I23 -> 0 | K23: =G23+J23 -> 545041.2 | M23: =M22+K23-L23 -> 545041.2
A24: 21 | B24: 46255 | G24: =E24*F24 -> 0 | J24: =H24*I24 -> 0 | K24: =G24+J24 -> 0 | M24: =M23+K24-L24 -> 545041.2
A25: 22 | B25: 46256 | E25: 2800 | F25: 103.62 | G25: =E25*F25 -> 290136 | H25: 75 | I25: 115.49 | J25: =H25*I25 -> 8661.75 | K25: =G25+J25 -> 298797.75 | M25: =M24+K25-L25 -> 843838.95
A26: 23 | B26: 46257 | G26: =E26*F26 -> 0 | J26: =H26*I26 -> 0 | K26: =G26+J26 -> 0 | M26: =M25+K26-L26 -> 843838.95
A27: 24 | B27: 46258 | G27: =E27*F27 -> 0 | J27: =H27*I27 -> 0 | K27: =G27+J27 -> 0 | M27: =M26+K27-L27 -> 843838.95
A28: 25 | B28: 46259 | G28: =E28*F28 -> 0 | J28: =H28*I28 -> 0 | K28: =G28+J28 -> 0 | M28: =M27+K28-L28 -> 843838.95
A29: 26 | B29: 46260 | E29: 2700 | F29: 103.62 | G29: =E29*F29 -> 279774 | H29: 90 | I29: 115.49 | J29: =H29*I29 -> 10394.1 | K29: =G29+J29 -> 290168.1 | M29: =M28+K29-L29 -> 1134007.1
A30: 27 | B30: 46261 | G30: =E30*F30 -> 0 | J30: =H30*I30 -> 0 | K30: =G30+J30 -> 0 | M30: =M29+K30-L30 -> 1134007.1
A31: 28 | B31: 46262 | G31: =E31*F31 -> 0 | J31: =H31*I31 -> 0 | K31: =G31+J31 -> 0 | L31: 1134007 | M31: =M30+K31-L31 -> 0.05
A32: 29 | B32: 46263 | E32: 2800 | F32: 103.62 | G32: =E32*F32 -> 290136 | H32: 40 | I32: 115.49 | J32: =H32*I32 -> 4619.6 | K32: =G32+J32 -> 294755.6 | M32: =M31+K32-L32 -> 294755.65
A33: 30 | B33: 46264 | E33: 2700 | F33: 103.62 | G33: =E33*F33 -> 279774 | H33: 35 | I33: 115.49 | J33: =H33*I33 -> 4042.15 | K33: =G33+J33 -> 283816.15 | M33: =M32+K33-L33 -> 578571.8
A34: 31 | G34: =E34*F34 -> 0 | J34: =H34*I34 -> 0 | K34: =G34+J34 -> 0 | M34: =M33+K34-L34 -> 578571.8
E35: =SUM(E4:E34) -> 16260 | G35: =SUM(G4:G34) -> 1684861.2 | H35: =SUM(H4:H34) -> 240 | J35: =SUM(J4:J34) -> 27717.6 | K35: =SUM(K4:K34) -> 1712578.8 | L35: =SUM(L4:L34) -> 1134007

Sheet  Khammam&Cash
A1: Cash &Carry
A2: S.No | B2: Date | D2: Ind No/Bill No | E2: Diesel (Lts) | F2: Price | G2: Amount | H2: Petrol (Lts) | I2: Price | J2: Amount | K2: Total amount | L2: Amount paid | M2: As 0n Date | N2: Remarks
A3: Opening Balance | K3: 0 | M3: 0
A4: 1 | B4: 46236 | C4: Stambhadri Fuel Park HPCL | E4: 1734.104 | F4: 103.8 | G4: =E4*F4 -> 180000 | K4: =G4+J4 -> 180000 | L4: =H4+K4 -> 180000 | M4: =M3+K4-L4 -> 0
A5: 2 | B5: 46238 | C5: Stambhadri Fuel Park HPCL | E5: 3853.56 | F5: 103.8 | G5: =E5*F5 -> 399999.53 | J5: =H5*I5 -> 0 | K5: =G5+J5 -> 399999.53 | L5: =H5+K5 -> 399999.53 | M5: =M4+K5-L5 -> 0
A6: 3 | B6: 46242 | C6: Stambhadri Fuel Park HPCL | E6: 1445.089 | F6: 103.8 | G6: =E6*F6 -> 150000.24 | J6: =H6*I6 -> 0 | K6: =G6+J6 -> 150000.24 | L6: =H6+K6 -> 150000.24 | M6: =M5+K6-L6 -> 0
A7: 4 | G7: =E7*F7 -> 0 | J7: =H7*I7 -> 0 | K7: =G7+J7 -> 0 | L7: =H7+K7 -> 0 | M7: =M6+K7-L7 -> 0
A8: 5 | G8: =E8*F8 -> 0 | J8: =H8*I8 -> 0 | K8: =G8+J8 -> 0 | L8: =H8+K8 -> 0 | M8: =M7+K8-L8 -> 0
A9: 6 | G9: =E9*F9 -> 0 | J9: =H9*I9 -> 0 | K9: =G9+J9 -> 0 | L9: =H9+K9 -> 0 | M9: =M8+K9-L9 -> 0
A10: 7 | G10: =E10*F10 -> 0 | J10: =H10*I10 -> 0 | K10: =G10+J10 -> 0 | L10: =H10+K10 -> 0 | M10: =M9+K10-L10 -> 0
A11: 8 | G11: =E11*F11 -> 0 | J11: =H11*I11 -> 0 | K11: =G11+J11 -> 0 | L11: =H11+K11 -> 0 | M11: =M10+K11-L11 -> 0
A12: 9 | G12: =E12*F12 -> 0 | J12: =H12*I12 -> 0 | K12: =G12+J12 -> 0 | L12: =H12+K12 -> 0 | M12: =M11+K12-L12 -> 0
A13: 10 | G13: =E13*F13 -> 0 | J13: =H13*I13 -> 0 | K13: =G13+J13 -> 0 | L13: =H13+K13 -> 0 | M13: =M12+K13-L13 -> 0
A14: 11 | G14: =E14*F14 -> 0 | J14: =H14*I14 -> 0 | K14: =G14+J14 -> 0 | L14: =H14+K14 -> 0 | M14: =M13+K14-L14 -> 0
A15: 12 | G15: =E15*F15 -> 0 | J15: =H15*I15 -> 0 | K15: =G15+J15 -> 0 | L15: =H15+K15 -> 0 | M15: =M14+K15-L15 -> 0
A16: 13 | G16: =E16*F16 -> 0 | J16: =H16*I16 -> 0 | K16: =G16+J16 -> 0 | L16: =H16+K16 -> 0 | M16: =M15+K16-L16 -> 0
A17: 14 | G17: =E17*F17 -> 0 | J17: =H17*I17 -> 0 | K17: =G17+J17 -> 0 | L17: =H17+K17 -> 0 | M17: =M16+K17-L17 -> 0
A18: 15 | G18: =E18*F18 -> 0 | J18: =H18*I18 -> 0 | K18: =G18+J18 -> 0 | L18: =H18+K18 -> 0 | M18: =M17+K18-L18 -> 0
... A22: 19 | G22: =E22*F22 -> 0 | J22: =H22*I22 -> 0 | K22: =G22+J22 -> 0 | L22: =H22+K22 -> 0 | M22: =M21+K22-L22 -> 0
A23: 20 | G23: =E23*F23 -> 0 | J23: =H23*I23 -> 0 | K23: =G23+J23 -> 0 | L23: 0 | M23: =M22+K23-L23 -> 0
A24: 21 | G24: =E24*F24 -> 0 | J24: =H24*I24 -> 0 | K24: =G24+J24 -> 0 | L24: =H24+K24 -> 0 | M24: =M23+K24-L24 -> 0
A25: 22 | G25: =E25*F25 -> 0 | J25: =H25*I25 -> 0 | K25: =G25+J25 -> 0 | L25: =H25+K25 -> 0 | M25: =M24+K25-L25 -> 0
A26: 23 | G26: =E26*F26 -> 0 | J26: =H26*I26 -> 0 | K26: =G26+J26 -> 0 | L26: =H26+K26 -> 0 | M26: =M25+K26-L26 -> 0
A27: 24 | G27: =E27*F27 -> 0 | K27: =G27+J27 -> 0 | L27: =H27+K27 -> 0 | M27: =M26+K27-L27 -> 0
A28: 25 | G28: =E28*F28 -> 0 | J28: =H28*I28 -> 0 | K28: =G28+J28 -> 0 | L28: =H28+K28 -> 0 | M28: =M26+K28-L28 -> 0
A29: 26 | G29: =E29*F29 -> 0 | J29: =H29*I29 -> 0 | K29: =G29+J29 -> 0 | L29: =H29+K29 -> 0 | M29: =M28+K29-L29 -> 0
A30: 27 | G30: =E30*F30 -> 0 | J30: =H30*I30 -> 0 | K30: =G30+J30 -> 0 | L30: =H30+K30 -> 0 | M30: =M29+K30-L30 -> 0
A31: 28 | G31: =E31*F31 -> 0 | J31: =H31*I31 -> 0 | K31: =G31+J31 -> 0 | L31: =H31+K31 -> 0 | M31: =M30+K31-L31 -> 0
A32: 29 | G32: =E32*F32 -> 0 | J32: =H32*I32 -> 0 | K32: =G32+J32 -> 0 | L32: =H32+K32 -> 0 | M32: =M31+K32-L32 -> 0
A33: 30 | G33: =E33*F33 -> 0 | J33: =H33*I33 -> 0 | K33: =G33+J33 -> 0 | L33: =H33+K33 -> 0 | M33: =M32+K33-L33 -> 0
A34: 31 | G34: =E34*F34 -> 0 | J34: =H34*I34 -> 0 | K34: =G34+J34 -> 0 | L34: =H34+K34 -> 0 | M34: =M33+K34-L34 -> 0
A35: 32 | G35: =E35*F35 -> 0 | K35: =G35+J35 -> 0 | L35: =H35+K35 -> 0 | M35: =M34+K35-L35 -> 0
A36: 33 | G36: =E36*F36 -> 0 | J36: =H36*I36 -> 0 | K36: =G36+J36 -> 0 | L36: =H36+K36 -> 0 | M36: =M35+K36-L36 -> 0
A37: 34 | G37: =E37*F37 -> 0 | J37: =H37*I37 -> 0 | K37: =G37+J37 -> 0 | L37: =H37+K37 -> 0 | M37: =M36+K37-L37 -> 0
G38: =E38*F38 -> 0 | K38: =G38+J38 -> 0 | L38: =H38+K38 -> 0 | M38: =M37+K38-L38 -> 0
G39: =E39*F39 -> 0 | K39: =G39+J39 -> 0 | L39: =H39+K39 -> 0 | M39: =M38+K39-L39 -> 0
G40: =E40*F40 -> 0 | K40: =G40+J40 -> 0 | L40: =H40+K40 -> 0 | M40: =M39+K40-L40 -> 0
M41: =M40+K41-L41 -> 0
A45: 35 | G45: =E45*F45 -> 0 | J45: =H45*I45 -> 0 | K45: =G45+J45 -> 0
E46: =SUM(E3:E45) -> 7032.753 | G46: =SUM(G3:G45) -> 729999.76 | H46: =SUM(H3:H45) -> 0 | J46: =SUM(J3:J45) -> 0 | K46: =SUM(K4:K45) -> 729999.76 | L46: =SUM(L3:L45) -> 729999.76

Sheet Jadcherla-4
A1: Shree Poornima F/S
A2: S.No | B2: Date | C2: GRN No | D2: Ind No/Bill No | E2: Diesel (Lts) | F2: Price | G2: Amount | H2: Petrol (Lts) | I2: Price | J2: Amount | K2: Total amount | L2: Amount paid | M2: As on date | N2: Remarks
A3: Opening Balance | M3: 50273.68
A4: 1 | B4: 46235 | G4: =E4*F4 -> 0 | J4: =H4*I4 -> 0 | K4: =G4+J4 -> 0 | L4: 0 | M4: =M3+K4-L4 -> 50273.68
A5: 2 | B5: 46236 | G5: =E5*F5 -> 0 | J5: =H5*I5 -> 0 | K5: =G5+J5 -> 0 | L5: 0 | M5: =M4+K5-L5 -> 50273.68
A6: 3 | B6: 46237 | G6: =E6*F6 -> 0 | J6: =H6*I6 -> 0 | K6: =G6+J6 -> 0 | L6: 0 | M6: =M5+K6-L6 -> 50273.68
A7: 4 | B7: 46238 | G7: =E7*F7 -> 0 | J7: =H7*I7 -> 0 | K7: =G7+J7 -> 0 | L7: 0 | M7: =M6+K7-L7 -> 50273.68
A8: 5 | B8: 46239 | G8: =E8*F8 -> 0 | J8: =H8*I8 -> 0 | K8: =G8+J8 -> 0 | L8: 0 | M8: =M7+K8-L8 -> 50273.68
A9: 6 | B9: 46240 | G9: =E9*F9 -> 0 | J9: =H9*I9 -> 0 | K9: =G9+J9 -> 0 | L9: 0 | M9: =M8+K9-L9 -> 50273.68
A10: 7 | B10: 46241 | G10: =E10*F10 -> 0 | J10: =H10*I10 -> 0 | K10: =G10+J10 -> 0 | L10: 0 | M10: =M9+K10-L10 -> 50273.68
A11: 8 | B11: 46242 | G11: =E11*F11 -> 0 | J11: =H11*I11 -> 0 | K11: =G11+J11 -> 0 | L11: 0 | M11: =M10+K11-L11 -> 50273.68
A12: 9 | B12: 46243 | G12: =E12*F12 -> 0 | J12: =H12*I12 -> 0 | K12: =G12+J12 -> 0 | L12: 0 | M12: =M11+K12-L12 -> 50273.68
A13: 10 | B13: 46244 | G13: =E13*F13 -> 0 | J13: =H13*I13 -> 0 | K13: =G13+J13 -> 0 | L13: 0 | M13: =M12+K13-L13 -> 50273.68
A14: 11 | B14: 46245 | G14: =E14*F14 -> 0 | J14: =H14*I14 -> 0 | K14: =G14+J14 -> 0 | L14: 0 | M14: =M13+K14-L14 -> 50273.68
A15: 12 | B15: 46246 | G15: =E15*F15 -> 0 | J15: =H15*I15 -> 0 | K15: =G15+J15 -> 0 | L15: 0 | M15: =M14+K15-L15 -> 50273.68
A16: 13 | B16: 46247 | G16: =E16*F16 -> 0 | J16: =H16*I16 -> 0 | K16: =G16+J16 -> 0 | L16: 0 | M16: =M15+K16-L16 -> 50273.68
A17: 14 | B17: 46248 | G17: =E17*F17 -> 0 | H17: 20 | I17: 116.33 | J17: =H17*I17 -> 2326.6 | K17: =G17+J17 -> 2326.6 | L17: 50000 | M17: =M16+K17-L17 -> 2600.28
A18: 15 | B18: 46249 | G18: =E18*F18 -> 0 | J18: =H18*I18 -> 0 | K18: =G18+J18 -> 0 | L18: 0 | M18: =M17+K18-L18 -> 2600.28
A19: 16 | B19: 46250 | G19: 0 | J19: 0 | K19: 0 | L19: 0 | M19: =M18+K19-L19 -> 2600.28
A20: 17 | B20: 46251 | G20: =E20*F20 -> 0 | J20: =H20*I20 -> 0 | K20: =G20+J20 -> 0 | L20: 0 | M20: =M19+K20-L20 -> 2600.28
A21: 18 | B21: 46252 | G21: =E21*F21 -> 0 | J21: =H21*I21 -> 0 | K21: =G21+J21 -> 0 | L21: 0 | M21: =M20+K21-L21 -> 2600.28
A22: 19 | B22: 46253 | G22: =E22*F22 -> 0 | J22: =H22*I22 -> 0 | K22: =G22+J22 -> 0 | L22: 0 | M22: =M21+K22-L22 -> 2600.28
A23: 20 | B23: 46254 | G23: =E23*F23 -> 0 | J23: =H23*I23 -> 0 | K23: =G23+J23 -> 0 | L23: 0 | M23: =M22+K23-L23 -> 2600.28
A24: 21 | B24: 46255 | G24: =E24*F24 -> 0 | J24: =H24*I24 -> 0 | K24: =G24+J24 -> 0 | L24: 0 | M24: =M23+K24-L24 -> 2600.28
A25: 22 | B25: 46256 | G25: =E25*F25 -> 0 | J25: =H25*I25 -> 0 | K25: =G25+J25 -> 0 | L25: 0 | M25: =M24+K25-L25 -> 2600.28
A26: 23 | B26: 46257 | G26: =E26*F26 -> 0 | J26: =H26*I26 -> 0 | K26: =G26+J26 -> 0 | L26: 0 | M26: =M25+K26-L26 -> 2600.28
A27: 24 | B27: 46258 | G27: =E27*F27 -> 0 | J27: =H27*I27 -> 0 | K27: =G27+J27 -> 0 | L27: 0 | M27: =M26+K27-L27 -> 2600.28
A28: 25 | B28: 46259 | G28: =E28*F28 -> 0 | J28: =H28*I28 -> 0 | K28: =G28+J28 -> 0 | L28: 0 | M28: =M27+K28-L28 -> 2600.28
A29: 26 | B29: 46260 | G29: =E29*F29 -> 0 | J29: =H29*I29 -> 0 | K29: =G29+J29 -> 0 | L29: 0 | M29: =M28+K29-L29 -> 2600.28
A30: 27 | B30: 46261 | G30: =E30*F30 -> 0 | J30: =H30*I30 -> 0 | K30: =G30+J30 -> 0 | L30: 0 | M30: =M29+K30-L30 -> 2600.28
A31: 28 | B31: 46262 | G31: =E31*F31 -> 0 | J31: =H31*I31 -> 0 | K31: =G31+J31 -> 0 | L31: 0 | M31: =M30+K31-L31 -> 2600.28
... A33: 30 | B33: 46264 | G33: =E33*F33 -> 0 | J33: =H33*I33 -> 0 | K33: =G33+J33 -> 0 | L33: 0 | M33: =M32+K33-L33 -> 2600.28
A34: 31 | G34: =E34*F34 -> 0 | J34: =H34*I34 -> 0 | K34: =G34+J34 -> 0 | M34: =M33+K34-L34 -> 2600.28
E35: =SUM(E4:E34) -> 0 | G35: =SUM(G4:G34) -> 0 | H35: =SUM(H4:H34) -> 20 | J35: =SUM(J4:J34) -> 2326.6 | K35: =SUM(K4:K34) -> 2326.6 | L35: =SUM(L4:L34) -> 50000

Sheet  Sangareddy-2
A1: Durga Bhavani F/S
A2: S.No | B2: Date | C2: GRN No | D2: Ind no/Bill No | E2: Diesel (Lts) | F2: Price | G2: Amount | H2: Petrol (Lts) | I2: Price | J2: Amount | K2: Total amount | L2: Amount paid | M2: As on Date | N2: Remarks
A3: Opening Balance | M3: 52609.145
A4: 1 | B4: 45870 | G4: =E4*F4 -> 0 | H4: 10 | I4: 116.54 | J4: =H4*I4 -> 1165.4 | K4: =G4+J4 -> 1165.4 | M4: =M3+K4-L4 -> 53774.545
A5: 2 | B5: 45871 | E5: 38.25 | F5: 104.56 | G5: =E5*F5 -> 3999.42 | H5: 5 | I5: 116.54 | J5: =H5*I5 -> 582.7 | K5: =G5+J5 -> 4582.12 | M5: =M4+K5-L5 -> 58356.665
A6: 3 | B6: 45872 | G6: =E6*F6 -> 0 | H6: 5 | I6: 116.54 | J6: =H6*I6 -> 582.7 | K6: =G6+J6 -> 582.7 | M6: =M5+K6-L6 -> 58939.365
A7: 4 | B7: 45873 | G7: =E7*F7 -> 0 | J7: =H7*I7 -> 0 | K7: =G7+J7 -> 0 | M7: =M6+K7-L7 -> 58939.365
A8: 5 | B8: 45874 | G8: =E8*F8 -> 0 | J8: =H8*I8 -> 0 | K8: =G8+J8 -> 0 | M8: =M7+K8-L8 -> 58939.365
A9: 6 | B9: 45875 | G9: =E9*F9 -> 0 | J9: =H9*I9 -> 0 | K9: =G9+J9 -> 0 | M9: =M8+K9-L9 -> 58939.365
A10: 7 | B10: 45876 | G10: =E10*F10 -> 0 | J10: =H10*I10 -> 0 | K10: =G10+J10 -> 0 | M10: =M9+K10-L10 -> 58939.365
A11: 8 | B11: 45877 | G11: =E11*F11 -> 0 | J11: =H11*I11 -> 0 | K11: =G11+J11 -> 0 | M11: =M10+K11-L11 -> 58939.365
A12: 9 | B12: 45878 | G12: =E12*F12 -> 0 | J12: =H12*I12 -> 0 | K12: =G12+J12 -> 0 | M12: =M11+K12-L12 -> 58939.365
A13: 10 | B13: 45879 | G13: =E13*F13 -> 0 | J13: =H13*I13 -> 0 | K13: =G13+J13 -> 0 | M13: =M12+K13-L13 -> 58939.365
A14: 11 | B14: 45880 | G14: =E14*F14 -> 0 | J14: =H14*I14 -> 0 | K14: =G14+J14 -> 0 | M14: =M13+K14-L14 -> 58939.365
A15: 12 | B15: 45881 | G15: =E15*F15 -> 0 | J15: =H15*I15 -> 0 | K15: =G15+J15 -> 0 | M15: =M14+K15-L15 -> 58939.365
A16: 13 | B16: 45882 | G16: =E16*F16 -> 0 | J16: =H16*I16 -> 0 | K16: =G16+J16 -> 0 | M16: =M15+K16-L16 -> 58939.365
A17: 14 | B17: 45883 | G17: =E17*F17 -> 0 | J17: =H17*I17 -> 0 | K17: =G17+J17 -> 0 | M17: =M16+K17-L17 -> 58939.365
A18: 15 | B18: 45884 | G18: =E18*F18 -> 0 | J18: =H18*I18 -> 0 | K18: =G18+J18 -> 0 | M18: =M17+K18-L18 -> 58939.365
... A22: 19 | B22: 45888 | G22: =E22*F22 -> 0 | J22: =H22*I22 -> 0 | K22: =G22+J22 -> 0 | M22: =M21+K22-L22 -> 58939.365
A23: 20 | B23: 45889 | G23: =E23*F23 -> 0 | J23: =H23*I23 -> 0 | K23: =G23+J23 -> 0 | L23: 58939.365 | M23: =M22+K23-L23 -> 0 | Q23: 96.44
A24: 21 | B24: 45890 | G24: =E24*F24 -> 0 | J24: =H24*I24 -> 0 | K24: =G24+J24 -> 0 | M24: =M23+K24-L24 -> 0
A25: 22 | B25: 45891 | G25: =E25*F25 -> 0 | J25: =H25*I25 -> 0 | K25: =G25+J25 -> 0 | M25: =M24+K25-L25 -> 0
A26: 23 | B26: 45892 | G26: =E26*F26 -> 0 | J26: =H26*I26 -> 0 | K26: =G26+J26 -> 0 | M26: =M25+K26-L26 -> 0
A27: 24 | B27: 45893 | G27: =E27*F27 -> 0 | J27: =H27*I27 -> 0 | K27: =G27+J27 -> 0 | M27: =M26+K27-L27 -> 0
A28: 25 | B28: 45894 | G28: =E28*F28 -> 0 | J28: =H28*I28 -> 0 | K28: =G28+J28 -> 0 | M28: =M27+K28-L28 -> 0
A29: 26 | B29: 45895 | G29: =E29*F29 -> 0 | J29: =H29*I29 -> 0 | K29: =G29+J29 -> 0 | M29: =M28+K29-L29 -> 0
A30: 27 | B30: 45896 | G30: =E30*F30 -> 0 | J30: =H30*I30 -> 0 | K30: =G30+J30 -> 0 | M30: =M29+K30-L30 -> 0
A31: 28 | B31: 45897 | G31: =E31*F31 -> 0 | J31: =H31*I31 -> 0 | K31: =G31+J31 -> 0 | M31: =M30+K31-L31 -> 0
A32: 29 | B32: 45898 | G32: =E32*F32 -> 0 | J32: =H32*I32 -> 0 | K32: =G32+J32 -> 0 | M32: =M31+K32-L32 -> 0
A33: 30 | B33: 45899 | G33: =E33*F33 -> 0 | J33: =H33*I33 -> 0 | K33: =G33+J33 -> 0 | L33: 0 | M33: =M32+K33-L33 -> 0
A34: 31 | G34: =E34*F34 -> 0 | J34: =H34*I34 -> 0 | K34: =G34+J34 -> 0 | L34: 0 | M34: =M33+K34-L34 -> 0
E35: =SUM(E4:E34) -> 38.25 | G35: =SUM(G4:G34) -> 3999.42 | H35: =SUM(H4:H34) -> 20 | J35: =SUM(J4:J34) -> 2330.8 | K35: =SUM(K4:K34) -> 6330.22 | L35: =SUM(L4:L34) -> 58939.365

Sheet  Sangareddy-3
A1: SHIVA PARVATHI FILLING STATION SADASHIVPET
A2: S.No | B2: Date | C2: GRN No | D2: Ind no/Bill No | E2: Diesel (Lts) | F2: Price | G2: Amount | H2: Petrol (Lts) | I2: Price | J2: Amount | K2: Total amount | L2: Amount paid | M2: As on Date | N2: Remarks
A3: Opening Balance | M3: 754936.41
A4: 1 | B4: 45870 | E4: 600 | F4: 104.35 | G4: =E4*F4 -> 62610 | J4: =H4*I4 -> 0 | K4: =G4+J4 -> 62610 | M4: =M3+K4-L4 -> 817546.41
A5: 2 | B5: 45871 | E5: 690 | F5: 104.35 | G5: =E5*F5 -> 72001.5 | J5: =H5*I5 -> 0 | K5: =G5+J5 -> 72001.5 | M5: =M4+K5-L5 -> 889547.91
A6: 3 | B6: 45872 | G6: =E6*F6 -> 0 | J6: =H6*I6 -> 0 | K6: =G6+J6 -> 0 | M6: =M5+K6-L6 -> 889547.91
A7: 4 | B7: 45873 | G7: =E7*F7 -> 0 | J7: =H7*I7 -> 0 | K7: =G7+J7 -> 0 | M7: =M6+K7-L7 -> 889547.91
A8: 5 | B8: 45874 | G8: =E8*F8 -> 0 | J8: =H8*I8 -> 0 | K8: =G8+J8 -> 0 | M8: =M7+K8-L8 -> 889547.91
A9: 6 | B9: 45875 | E9: 600 | F9: 104.35 | G9: =E9*F9 -> 62610 | J9: =H9*I9 -> 0 | K9: =G9+J9 -> 62610 | M9: =M8+K9-L9 -> 952157.91
A10: 7 | B10: 45876 | E10: 690 | F10: 104.35 | G10: =E10*F10 -> 72001.5 | H10: 6 | I10: 116.25 | J10: =H10*I10 -> 697.5 | K10: =G10+J10 -> 72699 | M10: =M9+K10-L10 -> 1024856.9
A11: 8 | B11: 45877 | G11: =E11*F11 -> 0 | J11: =H11*I11 -> 0 | K11: =G11+J11 -> 0 | M11: =M10+K11-L11 -> 1024856.9
A12: 9 | B12: 45878 | G12: =E12*F12 -> 0 | J12: =H12*I12 -> 0 | K12: =G12+J12 -> 0 | M12: =M11+K12-L12 -> 1024856.9
A13: 10 | B13: 45879 | E13: 690 | F13: 104.35 | G13: =E13*F13 -> 72001.5 | H13: 12 | I13: 116.25 | J13: =H13*I13 -> 1395 | K13: =G13+J13 -> 73396.5 | M13: =M12+K13-L13 -> 1098253.4
A14: 11 | B14: 45880 | E14: 690 | F14: 104.35 | G14: =E14*F14 -> 72001.5 | H14: 6 | I14: 116.25 | J14: =H14*I14 -> 697.5 | K14: =G14+J14 -> 72699 | M14: =M13+K14-L14 -> 1170952.4
A15: 12 | B15: 45881 | G15: =E15*F15 -> 0 | K15: =G15+J15 -> 0 | M15: =M14+K15-L15 -> 1170952.4
A16: 13 | B16: 45882 | E16: 734 | F16: 104.35 | G16: =E16*F16 -> 76592.9 | J16: =H16*I16 -> 0 | K16: =G16+J16 -> 76592.9 | M16: =M15+K16-L16 -> 1247545.3
A17: 14 | B17: 45883 | E17: 690 | F17: 104.35 | G17: =E17*F17 -> 72001.5 | H17: 6 | I17: 116.25 | J17: =H17*I17 -> 697.5 | K17: =G17+J17 -> 72699 | M17: =M16+K17-L17 -> 1320244.3
A18: 15 | B18: 45884 | G18: =E18*F18 -> 0 | J18: =H18*I18 -> 0 | K18: =G18+J18 -> 0 | M18: =M17+K18-L18 -> 1320244.3
A19: 16 | B19: 45885 | G19: =E19*F19 -> 0 | H19: 18 | I19: 116.25 | J19: =H19*I19 -> 2092.5 | K19: =G19+J19 -> 2092.5 | M19: =M18+K19-L19 -> 1322336.8
A20: 17 | B20: 45886 | E20: 690 | F20: 104.35 | G20: =E20*F20 -> 72001.5 | J20: =H20*I20 -> 0 | K20: =G20+J20 -> 72001.5 | M20: =M19+K20-L20 -> 1394338.3
A21: 18 | B21: 45887 | G21: =E21*F21 -> 0 | H21: 6 | I21: 116.25 | J21: =H21*I21 -> 697.5 | K21: =G21+J21 -> 697.5 | M21: =M20+K21-L21 -> 1395035.8
A22: 19 | B22: 45888 | E22: 690 | F22: 104.35 | G22: =E22*F22 -> 72001.5 | J22: =H22*I22 -> 0 | K22: =G22+J22 -> 72001.5 | M22: =M21+K22-L22 -> 1467037.3
A23: 20 | B23: 45889 | G23: =E23*F23 -> 0 | J23: =H23*I23 -> 0 | K23: =G23+J23 -> 0 | L23: 800000 | M23: =M22+K23-L23 -> 667037.31
A24: 21 | B24: 45890 | E24: 730 | F24: 104.35 | G24: =E24*F24 -> 76175.5 | J24: =H24*I24 -> 0 | K24: =G24+J24 -> 76175.5 | M24: =M23+K24-L24 -> 743212.81
A25: 22 | B25: 45891 | E25: 600 | F25: 104.35 | G25: =E25*F25 -> 62610 | J25: =H25*I25 -> 0 | K25: =G25+J25 -> 62610 | M25: =M24+K25-L25 -> 805822.81
A26: 23 | B26: 45892 | G26: =E26*F26 -> 0 | J26: =H26*I26 -> 0 | K26: =G26+J26 -> 0 | M26: =M25+K26-L26 -> 805822.81
A27: 24 | B27: 45893 | G27: =E27*F27 -> 0 | J27: =H27*I27 -> 0 | K27: =G27+J27 -> 0 | M27: =M26+K27-L27 -> 805822.81
A28: 25 | B28: 45894 | G28: =E28*F28 -> 0 | H28: 12 | I28: 116.25 | J28: =H28*I28 -> 1395 | K28: =G28+J28 -> 1395 | M28: =M27+K28-L28 -> 807217.81
A29: 26 | B29: 45895 | G29: =E29*F29 -> 0 | J29: =H29*I29 -> 0 | K29: =G29+J29 -> 0 | M29: =M28+K29-L29 -> 807217.81
A30: 27 | B30: 45896 | G30: =E30*F30 -> 0 | J30: =H30*I30 -> 0 | K30: =G30+J30 -> 0 | M30: =M29+K30-L30 -> 807217.81
A31: 28 | B31: 45897 | G31: =E31*F31 -> 0 | H31: 6 | I31: 126.03 | J31: =H31*I31 -> 756.18 | K31: =G31+J31 -> 756.18 | L31: 807217 | M31: =M30+K31-L31 -> 756.9929
A32: 29 | B32: 45898 | E32: 690 | F32: 104.35 | G32: =E32*F32 -> 72001.5 | H32: 6 | I32: 116.25 | J32: =H32*I32 -> 697.5 | K32: =G32+J32 -> 72699 | M32: =M31+K32-L32 -> 73455.993
A33: 30 | B33: 45899 | G33: =E33*F33 -> 0 | J33: =H33*I33 -> 0 | K33: =G33+J33 -> 0 | M33: =M32+K33-L33 -> 73455.993
A34: 31 | B34: 45900 | E34: 690 | F34: 104.35 | G34: =E34*F34 -> 72001.5 | H34: 6 | I34: 116.25 | J34: =H34*I34 -> 697.5 | K34: =G34+J34 -> 72699 | M34: =M33+K34-L34 -> 146154.99
A35: 32 | G35: =E35*F35 -> 0 | J35: =H35*I35 -> 0 | K35: =G35+J35 -> 0 | M35: =M34+K35-L35 -> 146154.99
E36: =SUM(E4:E35) -> 9474 | G36: =SUM(G4:G35) -> 988611.9 | H36: =SUM(H4:H35) -> 84 | J36: =SUM(J4:J35) -> 9823.68 | K36: =SUM(K4:K35) -> 998435.58 | L36: =SUM(L4:L35) -> 1607217

Sheet Narayankhed
A2: S.No | B2: Date | C2: GRN No | D2: Ind no/Bill No | E2: Diesel (Lts) | F2: Price | G2: Amount | H2: Petrol (Lts) | I2: Price | J2: Amount | K2: Total amount | L2: Amount paid | M2: As on Date | N2: Remarks
A3: Opening Balance | M3: 0
A4: 1 | B4: 45870 | G4: =E4*F4 -> 0 | J4: =H4*I4 -> 0 | K4: =G4+J4 -> 0 | L4: =H4+K4 -> 0 | M4: =M3+K4-L4 -> 0
A5: 2 | B5: 45871 | G5: =E5*F5 -> 0 | J5: =H5*I5 -> 0 | K5: =G5+J5 -> 0 | L5: =H5+K5 -> 0 | M5: =M4+K5-L5 -> 0 | S5: 185.65
A6: 3 | B6: 45872 | G6: =E6*F6 -> 0 | J6: =H6*I6 -> 0 | K6: =G6+J6 -> 0 | L6: =H6+K6 -> 0 | M6: =M5+K6-L6 -> 0 | S6: 5
