Workbook

Sheet  MIs
A2: S.No | B2: NAme | C2: Lacation | D2: Card Number | E2: Card Number | F2: Category | G2: 1st Jan | I2: 2nd Jan | J2: 3rd Jan | K2: 4th Jan | L2: 5th Jan | M2: 6th Jan | N2: 7th Jan | O2: 8th Jan | P2: 9th Jan | Q2: 10th Jan | R2: 11th Jan | S2: 12th Jan | T2: 13th Jan | U2: 14th Jan | V2: 15th Jan | W2: 16th Jan | X2: 17th Jan | Y2: 18th Jan | Z2: 19th Jan | AA2: 20th Jan | AB2: 21st Jan | AC2: 22nd Jan | AD2: 23rd Jan | AE2: 24th Jan | AF2: 25th Jan | AG2: 26th Jan | AH2: 27th Jan | AI2: 28th Jan | AJ2: 29th Jan | AK2: 30th Jan | AL2: 31st Jan | AM2: Total
F3: Diesel
A4: 1 | B4: Rambabu | C4: HO(Two Wheeler) | D4: FC3450563999 | E4: Diesel | F4: 0 | G4: 0 | H4: 0 | I4: 0 | J4: 0 | K4: 0 | L4: 0 | M4: 0 | N4: 0 | O4: 0 | P4: 0 | Q4: 0 | R4: 0 | S4: 0 | T4: 0 | U4: 0 | V4: 0 | W4: 0 | X4: 5.22 | Y4: 0 | Z4: 0 | AA4: 0 | AB4: 0 | AC4: 0 | AD4: 60 | AE4: 0 | AF4: 0 | AG4: 0 | AH4: 4.56 | AI4: 0 | AJ4: 0 | AK4: 0 | AL4: 0 | AM4: =SUM(F4:AL4) -> 69.78
E5: Petrol | F5: 0 | G5: 4.69 | H5: 0 | I5: 0 | J5: 0 | K5: 0 | L5: 0 | M5: 0 | N5: 3.91 | O5: 0 | P5: 6.98 | Q5: 0 | R5: 0 | S5: 0 | T5: 0 | U5: 0 | V5: 0 | W5: 0 | X5: 0 | Y5: 0 | Z5: 0 | AB5: 0 | AC5: 0 | AD5: 0 | AE5: 0 | AF5: 0 | AG5: 0 | AH5: 0 | AI5: 0 | AJ5: 0 | AK5: 0 | AL5: 0 | AM5: =SUM(F5:AL5) -> 15.58
A6: 2 | B6: Hanumanth Rao | C6: HO | D6: FC3450676131 | E6: Diesel | F6: 0 | G6: 0 | H6: 0 | I6: 0 | J6: 0 | K6: 0 | L6: 0 | M6: 0 | N6: 0 | O6: 0 | P6: 0 | Q6: 0 | R6: 0 | S6: 0 | T6: 0 | U6: 0 | V6: 0 | W6: 0 | X6: 0 | Y6: 0 | Z6: 0 | AA6: 0 | AB6: 0 | AC6: 0 | AD6: 0 | AE6: 0 | AF6: 0 | AG6: 0 | AH6: 0 | AI6: 0 | AJ6: 0 | AK6: 0 | AL6: 0 | AM6: =SUM(F6:AL6) -> 0
E7: Petrol | F7: 0 | G7: 0 | H7: 0 | I7: 0 | J7: 0 | K7: 0 | L7: 0 | M7: 0 | N7: 0 | O7: 0 | P7: 0 | Q7: 0 | R7: 0 | S7: 0 | T7: 0 | U7: 0 | V7: 0 | W7: 0 | X7: 0 | Y7: 0 | Z7: 0 | AB7: 0 | AC7: 0 | AD7: 0 | AE7: 0 | AF7: 0 | AG7: 0 | AH7: 0 | AI7: 0 | AJ7: 0 | AK7: 0 | AL7: 0 | AM7: =SUM(F7:AL7) -> 0
A8: 3 | B8: Radhakrishna | C8: HO | D8: FC8000207658 | E8: Diesel | F8: 0 | G8: 0 | H8: 0 | I8: 0 | J8: 33.44 | K8: 0 | L8: 0 | M8: 0 | N8: 0 | O8: 0 | P8: 0 | Q8: 0 | R8: 35.53 | S8: 0 | T8: 0 | U8: 0 | V8: 0 | W8: 0 | X8: 0 | Y8: 0 | Z8: 0 | AA8: 0 | AB8: 33.44 | AC8: 0 | AD8: 0 | AE8: 0 | AF8: 0 | AG8: 0 | AH8: 0 | AI8: 0 | AJ8: 0 | AK8: 0 | AL8: 0 | AM8: =SUM(F8:AL8) -> 102.41
E9: Petrol | F9: 0 | G9: 0 | H9: 0 | I9: 0 | J9: 0 | K9: 0 | L9: 0 | M9: 0 | N9: 0 | O9: 0 | P9: 0 | Q9: 0 | R9: 0 | S9: 0 | T9: 0 | U9: 0 | V9: 0 | W9: 0 | X9: 0 | Y9: 0 | Z9: 0 | AB9: 0 | AC9: 0 | AD9: 0 | AE9: 0 | AF9: 0 | AG9: 0 | AH9: 0 | AI9: 0 | AJ9: 0 | AK9: 0 | AL9: 0 | AM9: =SUM(F9:AL9) -> 0
A10: 4 | B10: VIjay | C10: HO | D10: FC3450698859 | E10: Diesel | F10: 0 | G10: 0 | H10: 0 | I10: 0 | J10: 0 | K10: 0 | L10: 0 | M10: 0 | N10: 0 | O10: 0 | P10: 49.22 | Q10: 0 | R10: 0 | S10: 0 | T10: 0 | U10: 54.57 | V10: 0 | W10: 0 | X10: 0 | Y10: 0 | Z10: 0 | AA10: 0 | AB10: 0 | AC10: 0 | AD10: 49.8 | AE10: 0 | AF10: 0 | AG10: 0 | AH10: 0 | AI10: 0 | AJ10: 0 | AK10: 0 | AL10: 0 | AM10: =SUM(F10:AL10) -> 153.59
E11: Petrol | F11: 0 | G11: 0 | H11: 0 | I11: 0 | J11: 0 | K11: 0 | L11: 0 | M11: 0 | N11: 0 | O11: 0 | P11: 0 | Q11: 0 | R11: 0 | S11: 0 | T11: 0 | U11: 0 | V11: 0 | W11: 0 | X11: 0 | Y11: 0 | Z11: 0 | AB11: 0 | AC11: 0 | AD11: 0 | AE11: 0 | AF11: 0 | AG11: 0 | AH11: 0 | AI11: 0 | AJ11: 0 | AK11: 0 | AL11: 0 | AM11: =SUM(F11:AL11) -> 0
A12: 5 | B12: Client | C12: Hiriyur | D12: FC3450698864 | E12: Diesel | F12: 0 | G12: 0 | H12: 0 | I12: 0 | J12: 0 | K12: 0 | L12: 0 | M12: 0 | N12: 86.29 | O12: 0 | P12: 0 | Q12: 0 | R12: 0 | S12: 0 | T12: 0 | U12: 0 | V12: 0 | W12: 0 | X12: 0 | Y12: 0 | Z12: 0 | AA12: 0 | AB12: 0 | AC12: 0 | AD12: 145.61 | AE12: 0 | AF12: 0 | AG12: 0 | AH12: 0 | AI12: 0 | AJ12: 0 | AK12: 0 | AL12: 0 | AM12: =SUM(F12:AL12) -> 231.9
E13: Petrol | F13: 0 | G13: 0 | H13: 0 | I13: 0 | J13: 0 | K13: 0 | L13: 0 | M13: 0 | N13: 0 | O13: 0 | P13: 0 | Q13: 0 | R13: 0 | S13: 0 | T13: 0 | U13: 0 | V13: 0 | W13: 0 | X13: 0 | Y13: 0 | Z13: 0 | AB13: 0 | AC13: 0 | AD13: 0 | AE13: 0 | AF13: 0 | AG13: 0 | AH13: 0 | AI13: 0 | AJ13: 0 | AK13: 0 | AL13: 0 | AM13: =SUM(F13:AL13) -> 0
A14: 6 | B14: Client | C14: Hosadurga | D14: FC3450698865 | E14: Diesel | F14: 0 | G14: 0 | H14: 0 | I14: 0 | J14: 0 | K14: 0 | L14: 40 | M14: 40 | N14: 0 | O14: 36 | P14: 35 | Q14: 0 | R14: 0 | S14: 0 | T14: 0 | U14: 0 | V14: 0 | W14: 45 | X14: 45 | Y14: 43.53 | Z14: 40 | AA14: 43 | AB14: 0 | AC14: 40 | AD14: 0 | AE14: 40 | AF14: 0 | AG14: 0 | AH14: 0 | AI14: 0 | AJ14: 0 | AK14: 0 | AL14: 0 | AM14: =SUM(F14:AL14) -> 447.53
E15: Petrol | F15: 0 | G15: 0 | H15: 0 | I15: 0 | J15: 0 | K15: 0 | L15: 0 | M15: 0 | N15: 0 | O15: 0 | P15: 0 | Q15: 0 | R15: 0 | S15: 0 | T15: 0 | U15: 0 | V15: 0 | W15: 0 | X15: 0 | Y15: 0 | Z15: 0 | AB15: 0 | AC15: 0 | AD15: 0 | AE15: 0 | AF15: 0 | AG15: 0 | AH15: 0 | AI15: 0 | AJ15: 0 | AK15: 0 | AL15: 0 | AM15: =SUM(F15:AL15) -> 0
G18: Diesel Price

Sheet OCT-26
A1: S.no | B1: Site Name | C1: Bunk Name | D1: Diesel(Liters) | E1: Diesel Amount | F1: Petrol(Liters) | G1: Petrol Amount | H1: Total Amount | I1: Opening Blance | J1: Amount Paid | K1: Closing Balances
A2: 1 | B2: Khammam-1 | C2: Divya laxmi ganapathi | D2: =+'Khammam-1'!E38 -> 5000 | E2: =+'Khammam-1'!G38 -> 519000 | F2: =+'Khammam-1'!H38 -> 350 | G2: =+'Khammam-1'!J38 -> 40491.5 | H2: =E2+G2 -> 559491.5 | I2: =+'Khammam-1'!K3 -> 4131883.8 | J2: =+'Khammam-1'!L38 -> 400000 | K2: =H2+I2-J2 -> 4291375.3
A3: 2 | B3: Khammam-2 | C3: Jayasai union bunk | D3: =+'Khammam-2'!E39 -> 29600 | E3: =+'Khammam-2'!G39 -> 3073072 | F3: =+'Khammam-2'!H39 -> 130 | G3: =+'Khammam-2'!J39 -> 15043.6 | H3: =E3+G3 -> 3088115.6 | I3: =+'Khammam-2'!K3 -> 4248603.6 | J3: =+'Khammam-2'!L39 -> 2000000 | K3: =H3+I3-J3 -> 5336719.2
A4: 4 | B4: Khammam | C4: Sai Madeana Filling Station | D4: =+'Khammam-4'!E35 -> 2700 | E4: =+'Khammam-4'!G35 -> 279774 | F4: =+'Khammam-4'!H35 -> 75 | G4: =+'Khammam-4'!J35 -> 8661.75 | H4: =E4+G4 -> 288435.75 | I4: =+'Khammam-4'!M3 -> 3141611.1 | J4: =+'Khammam-4'!L35 -> 288435.75 | K4: =H4+I4-J4 -> 3141611.1
A5: 5 | B5: Khammam | C5: Vajra mahalakshmi filling station | D5: =+' Khammam-5'!E35 -> 0 | E5: =+' Khammam-5'!G35 -> 0 | F5: =+' Khammam-5'!H35 -> 0 | G5: =+' Khammam-5'!J35 -> 0 | H5: =E5+G5 -> 0 | I5: =+' Khammam-5'!M3 -> 1445001.9 | J5: =+' Khammam-5'!L35 -> 0 | K5: =H5+I5-J5 -> 1445001.9
A6: 6 | B6: Khammam-Cash&Carry | C6: NA | D6: =+' Khammam&Cash'!E46 -> 0 | E6: =+' Khammam&Cash'!G46 -> 0 | F6: =+' Khammam&Cash'!H46 -> 0 | G6: =+' Khammam&Cash'!J46 -> 0 | H6: =E6+G6 -> 0 | I6: =+' Khammam&Cash'!M3 -> 0 | J6: =+' Khammam&Cash'!L46 -> 0 | K6: =H6+I6-J6 -> 0
A7: 7 | B7: Jadcherla-2 | C7: Shree Poornima F/S | D7: =+'Jadcherla-4'!E35 -> 100 | E7: =+'Jadcherla-4'!G35 -> 10442 | F7: =+'Jadcherla-4'!H35 -> 0 | G7: =+'Jadcherla-4'!J35 -> 0 | H7: =E7+G7 -> 10442 | I7: =+'Jadcherla-4'!M3 -> 47858.18 | J7: =+'Jadcherla-4'!L35 -> 50000 | K7: =H7+I7-J7 -> 8300.18
A8: 8 | B8: Sangareddy-2 | C8: Durga Bhavani F/S | D8: =+' Sangareddy-2'!E35 -> 0 | E8: =+' Sangareddy-2'!G35 -> 0 | F8: =+' Sangareddy-2'!H35 -> 0 | G8: =+' Sangareddy-2'!J35 -> 0 | H8: =E8+G8 -> 0 | I8: =+' Sangareddy-2'!M3 -> 0 | J8: =+' Sangareddy-2'!L35 -> 0 | K8: =H8+I8-J8 -> 0
A9: 9 | B9: Sangareddy-3 | C9: Shiva Parvathi Filling Station | D9: =+' Sangareddy-3'!E36 -> 5520 | E9: =+' Sangareddy-3'!G36 -> 576012 | F9: =+' Sangareddy-3'!H36 -> 60 | G9: =+' Sangareddy-3'!J36 -> 6975 | H9: =E9+G9 -> 582987 | I9: =+' Sangareddy-3'!M3 -> 366809.49 | J9: =+' Sangareddy-3'!L36 -> 0 | K9: =H9+I9-J9 -> 949796.49
A10: 10 | B10: NarayanaKhed | C10: Sai Shiva Filling Station | D10: =Narayankhed!E36 -> 1522.561 | E10: =+Narayankhed!G36 -> 160000.2 | F10: =+Narayankhed!H36 -> 0 | G10: =+Narayankhed!J36 -> 0 | H10: =E10+G10 -> 160000.2 | I10: =+Narayankhed!M3 -> 0 | J10: =+Narayankhed!L36 -> 160000.2 | K10: =H10+I10-J10 -> 0
A11: 11 | B11: Dindi | C11: Akarapu Balakistamma Fillling | D11: =+Dindi!E35 -> 67.52 | E11: =+Dindi!G35 -> 7086.224 | F11: =+Dindi!H35 -> 0 | G11: =+Dindi!J35 -> 0 | H11: =E11+G11 -> 7086.224 | I11: =+Dindi!M3 -> 0 | J11: =+Dindi!L35 -> 7086.224 | K11: =H11+I11-J11 -> 0
A12: 12 | B12: Madanapalli | C12: NA | D12: =+'Madana palli'!E37 -> 0 | E12: =+'Madana palli'!G37 -> 0 | F12: =+'Madana palli'!H37 -> 0 | G12: =+'Madana palli'!J37 -> 0 | H12: =E12+G12 -> 0 | I12: =+'Madana palli'!M3 -> 0 | J12: =+'Madana palli'!L37 -> 0 | K12: =H12+I12-J12 -> 0
A13: 13 | B13: Kovvur | C13: Sri Venkateshwara Services | D13: =+'Sri Venkateshwara Services'!E37 -> 2274.37 | E13: =+'Sri Venkateshwara Services'!G37 -> 238081.05 | F13: =+'Sri Venkateshwara Services'!H37 -> 426 | G13: =+'Sri Venkateshwara Services'!J37 -> 49824.96 | H13: =E13+G13 -> 287906.01 | I13: =+'Sri Venkateshwara Services'!M3 -> 115419.84 | J13: =+'Sri Venkateshwara Services'!L37 -> 338000 | K13: =H13+I13-J13 -> 65325.85
A14: 14 | B14: Jangareddygudem | C14: Solasa Krishna Oil Company | D14: =+' Solasa Krishna OIl'!E37 -> 2252.17 | E14: =+' Solasa Krishna OIl'!G37 -> 237378.72 | F14: =+' Solasa Krishna OIl'!H37 -> 40.2 | G14: =+' Solasa Krishna OIl'!J37 -> 4733.148 | H14: =E14+G14 -> 242111.87 | I14: =+' Solasa Krishna OIl'!M3 -> 238901.54 | J14: =+' Solasa Krishna OIl'!L37 -> 200000 | K14: =H14+I14-J14 -> 281013.4
A15: 15 | B15: Amalapuram | C15: Royal Fill 'N' Fly | D15: =+'Amalapuram(KKD)'!E37 -> 5710 | E15: =+'Amalapuram(KKD)'!G37 -> 600977.5 | F15: =+'Amalapuram(KKD)'!H37 -> 113.55 | G15: =+'Amalapuram(KKD)'!J37 -> 13351.209 | H15: =E15+G15 -> 614328.71 | I15: =+'Amalapuram(KKD)'!M3 -> 519637.76 | J15: =+'Amalapuram(KKD)'!L37 -> 1000000 | K15: =H15+I15-J15 -> 133966.47
A16: 16 | B16: Yeleshwaram | C16: Sri sathya Filling Station | D16: =+'Yeleshwaram(KKD)'!E37 -> 1087 | E16: =+'Yeleshwaram(KKD)'!G37 -> 114635.02 | F16: =+'Yeleshwaram(KKD)'!H37 -> 110 | G16: =+'Yeleshwaram(KKD)'!J37 -> 12962.4 | H16: =E16+G16 -> 127597.42 | I16: =+'Yeleshwaram(KKD)'!M3 -> 17080.343 | J16: =+'Yeleshwaram(KKD)'!L37 -> 80000 | K16: =H16+I16-J16 -> 64677.763
A17: 17 | B17: Pitapuam | C17: Satya Siva Durga Agencies, Chebrolu | D17: =+' Pitapram(KKD)'!E37 -> 1222.54 | E17: =+' Pitapram(KKD)'!G37 -> 128623.43 | F17: =+' Pitapram(KKD)'!H37 -> 55 | G17: =+' Pitapram(KKD)'!J37 -> 6466.9 | H17: =E17+G17 -> 135090.33 | I17: =+' Pitapram(KKD)'!M3 -> 291832.98 | J17: =+' Pitapram(KKD)'!L37 -> 423000 | K17: =H17+I17-J17 -> 3923.3177
A18: 18 | B18: Kakinada | C18: Multiple bunks | D18: =+' Pitapram(KKD)'!E38 -> 0 | E18: =+' Pitapram(KKD)'!G38 -> 0 | F18: =+' Pitapram(KKD)'!H38 -> 0 | G18: =+' Pitapram(KKD)'!J38 -> 0 | H18: =E18+G18 -> 0 | I18: =+'Multiple bunks(KKD)'!M3 -> 0 | J18: =+' Pitapram(KKD)'!L38 -> 0 | K18: =H18+I18-J18 -> 0
A19: 19 | B19: YG Gudda-2 | C19: Pankaja HP Fuel Center | D19: =+'YG Gudda'!E39 -> 4600 | E19: =+'YG Gudda'!G39 -> 456044 | F19: =+'YG Gudda'!H39 -> 210 | G19: =+'YG Gudda'!J39 -> 23360.4 | H19: =E19+G19 -> 479404.4 | I19: =+'YG Gudda'!M3 -> 305951.76 | J19: =+'YG Gudda'!L39 -> 600000 | K19: =H19+I19-J19 -> 185356.16
A20: 20 | B20: YG Gudda-2 | C20: One stop | D20: =+' YG Gudda-2'!E39 -> 800 | E20: =+' YG Gudda-2'!G39 -> 79216 | F20: =+' YG Gudda-2'!H39 -> 35 | G20: =+' YG Gudda-2'!J39 -> 3889.2 | H20: =E20+G20 -> 83105.2 | I20: =+' YG Gudda-2'!M3 -> 255923.32 | J20: =+' YG Gudda-2'!L39 -> 200000 | K20: =H20+I20-J20 -> 139028.52
A21: 21 | B21: Hosadurga-2 | C21: Shree Veeraprathap Fuel | D21: =+'Hosadurga -2'!E35 -> 1000 | E21: =+'Hosadurga -2'!G35 -> 99360 | F21: =+'Hosadurga -2'!H35 -> 100 | G21: =+'Hosadurga -2'!J35 -> 11168 | H21: =+'Hosadurga -2'!K35 -> 110528 | I21: =+'Hosadurga -2'!M3 -> 126009.99 | J21: =+'Hosadurga -2'!L35 -> 226000 | K21: =H21+I21-J21 -> 10537.994
A22: 22 | B22: Malebennuru(KUWSDB) | C22: Sri Ramanjuneya Service Station | D22: =+'Malebenur(KUWSDB)'!E39 -> 3866.63 | E22: =+'Malebenur(KUWSDB)'!G39 -> 386591.66 | F22: =+'Malebenur(KUWSDB)'!H39 -> 109.99 | G22: =+'Malebenur(KUWSDB)'!J39 -> 12319.979 | H22: =E22+G22 -> 398911.64 | I22: =+'Malebenur(KUWSDB)'!M3 -> 290892.11 | J22: =+'Malebenur(KUWSDB)'!L39 -> 300029.24 | K22: =H22+I22-J22 -> 389774.51
A23: 23 | B23: kadur | C23: Vishal Service Station | D23: =+Kadur!E35 -> 0 | E23: =+Kadur!G35 -> 0 | F23: =+Kadur!H35 -> 0 | G23: =+Kadur!J35 -> 0 | H23: =E23+G23 -> 0 | I23: =+Kadur!K3 -> 175658 | J23: =+Kadur!L35 -> 100000 | K23: =H23+I23-J23 -> 75658
A24: 24 | B24: Hiriyur(VJNL) | C24: Sri Balaji Agencies | D24: =+'Hiriyur(VJNL)'!E35 -> 2600 | E24: =+'Hiriyur(VJNL)'!G35 -> 260182 | F24: =+'Hiriyur(VJNL)'!H35 -> 120 | G24: =+'Hiriyur(VJNL)'!J35 -> 13450.8 | H24: =E24+G24 -> 273632.8 | I24: =+'Hiriyur(VJNL)'!K3 -> 212444.1 | J24: =+'Hiriyur(VJNL)'!L35 -> 278000 | K24: =H24+I24-J24 -> 208076.9
A25: 25 | B25: Chellakere(KUWSDB) | C25: Shivaganga Service Station | D25: =+'Chellakere -1'!E38 -> 1800 | E25: =+'Chellakere -1'!G38 -> 180054 | F25: =+'Chellakere -1'!H38 -> 105 | G25: =+'Chellakere -1'!J38 -> 11764.2 | H25: =E25+G25 -> 191818.2 | I25: =+'Chellakere -1'!K3 -> 0 | J25: =+'Chellakere -1'!L38 -> 200000 | K25: =H25+I25-J25 -> -8181.8
A26: 26 | B26: Chellakere(KUWSDB)-09 | C26: Shivaganga Service Station | D26: =+' Chellakere-PKG-9'!E38 -> 283.42 | E26: =+' Chellakere-PKG-9'!G38 -> 28349.969 | F26: =+' Chellakere-PKG-9'!H38 -> 30 | G26: =+' Chellakere-PKG-9'!J38 -> 3361.2 | H26: =E26+G26 -> 31711.169 | I26: =+' Chellakere-PKG-9'!M3 -> 0 | J26: =+' Chellakere-PKG-9'!L38 -> 21028.499 | K26: =H26+I26-J26 -> 10682.67
A27: 27 | B27: Molakalmuru | C27: Sri Lakshmi Venkateshwara Filling Station | D27: =+Molakamuru!E35 -> 500 | E27: =+Molakamuru!G35 -> 50015 | F27: =+Molakamuru!H35 -> 40 | G27: =+Molakamuru!J35 -> 4481.2 | H27: =E27+G27 -> 54496.2 | I27: =+Molakamuru!K3 -> 44770.66 | J27: =+Molakamuru!L35 -> 0 | K27: =H27+I27-J27 -> 99266.86
A28: 28 | B28: Chennagiri | C28: NA | D28: =+' Chennagiri'!E35 -> 615 | E28: =+' Chennagiri'!G35 -> 61411.7 | F28: =+' Chennagiri'!H35 -> 35 | G28: =+' Chennagiri'!J35 -> 3921.05 | H28: =E28+G28 -> 65332.75 | I28: =+' Chennagiri'!K3 -> 0 | J28: =+' Chennagiri'!L35 -> 65332.75 | K28: =H28+I28-J28 -> 0
A29: 29 | B29: Khanapur(PKG-3) | C29: V.V.Varde | D29: =+Khanapur!E35 -> 245.6 | E29: =+Khanapur!G35 -> 24266.906 | F29: =+Khanapur!H35 -> 60 | G29: =+Khanapur!J35 -> 6644.4 | H29: =E29+G29 -> 30911.306 | I29: =+Khanapur!M3 -> 120785.13 | J29: =+Khanapur!L35 -> 100000 | K29: =H29+I29-J29 -> 51696.435
A30: 30 | B30: Munavalli(PKG-3) | C30: Shre Shiva Petroleum | D30: =+'Munavali-2'!E40 -> 2000 | E30: =+'Munavali-2'!G40 -> 198700 | F30: =+'Munavali-2'!H40 -> 0 | G30: =+'Munavali-2'!J40 -> 0 | H30: =E30+G30 -> 198700 | I30: =+'Munavali-2'!M3 -> 263421.5 | J30: =+'Munavali-2'!L40 -> 363000 | K30: =H30+I30-J30 -> 99121.5
A31: 31 | B31: Munavalli(PKG-3) | C31: Daneshwari Petroleum | D31: =+' Munavali'!E39 -> 0 | E31: =+' Munavali'!G39 -> 0 | F31: =+' Munavali'!H39 -> 150 | G31: =+' Munavali'!J39 -> 16681.5 | H31: =E31+G31 -> 16681.5 | I31: =+' Munavali'!M3 -> 30045.067 | J31: =+' Munavali'!L39 -> 0 | K31: =H31+I31-J31 -> 46726.567
A32: 33 | B32: Ugar,Kudichi(PKG-3) | C32: Shiri Bhrhmanath Petrolium | D32: =+'Ugar,Khagwad,Kudichi'!E38 -> 2722.45 | E32: =+'Ugar,Khagwad,Kudichi'!G38 -> 271502.24 | F32: =+'Ugar,Khagwad,Kudichi'!H38 -> 215 | G32: =+'Ugar,Khagwad,Kudichi'!J38 -> 24048.8 | H32: =E32+G32 -> 295551.04 | I32: =+'Ugar,Khagwad,Kudichi'!M3 -> 300655.8 | J32: =+'Ugar,Khagwad,Kudichi'!L38 -> 161435.49 | K32: =H32+I32-J32 -> 434771.35
A33: 34 | B33: Shedbal | C33: Varad Petroluem | D33: =+shedbal!E38 -> 1136 | E33: =+shedbal!G38 -> 113293.28 | F33: =+shedbal!H38 -> 77 | G33: =+shedbal!J38 -> 8612.45 | H33: =E33+G33 -> 121905.73 | I33: =+shedbal!M3 -> 158612.05 | J33: =+shedbal!L38 -> 150000 | K33: =H33+I33-J33 -> 130517.78
A34: 35 | B34: Kabbur(PKG-3) | C34: Shri Jai Hanuman Petrolium | D34: =+Kabbur!E35 -> 30 | E34: =+Kabbur!G35 -> 2982.3 | F34: =+Kabbur!H35 -> 0 | G34: =+Kabbur!J35 -> 0 | H34: =E34+G34 -> 2982.3 | I34: 0 | J34: =+Kabbur!L35 -> 2982.3 | K34: =H34+I34-J34 -> 0
A35: 36 | B35: Kumta (PKG-1) | C35: V.M.Mirjankar (Kumta) Bharat | D35: =+kumta!E41 -> 894.82 | E35: =+kumta!G41 -> 89285.14 | F35: =+kumta!H41 -> 39 | G35: =+kumta!J41 -> 4367.22 | H35: =E35+G35 -> 93652.36 | I35: =kumta!M3 -> 84520.658 | J35: =+kumta!L41 -> 100000 | K35: =H35+I35-J35 -> 78173.018
A36: 37 | B36: Jalgaon-2 | C36: Nayara | D36: =+'Jalgoan-2'!E56 -> 0 | E36: ='Jalgoan-2'!G56 -> 0 | F36: =+'Jalgoan-2'!H56 -> 60 | G36: =+'Jalgoan-2'!J56 -> 7090.8 | H36: =E36+G36 -> 7090.8 | I36: =+'Jalgoan-2'!M3 -> 605152.24 | J36: =+'Jalgoan-2'!L56 -> 0 | K36: =H36+I36-J36 -> 612243.04
A37: 38 | B37: MKBD | C37: Shree Sai Samarth Petroleum | D37: =+MKBD!E42 -> 3800 | E37: =+MKBD!G42 -> 375972 | F37: =+MKBD!H42 -> 40 | G37: =+MKBD!J42 -> 4490.8 | H37: =E37+G37 -> 380462.8 | I37: =+MKBD!K3 -> 0 | J37: =+MKBD!L42 -> 0 | K37: =H37+I37-J37 -> 380462.8
A38: 39 | B38: Haveri | C38: M/s Magavi City Fuels | D38: =' Haveri-2'!E42 -> 3207.57 | E38: =' Haveri-2'!G42 -> 318511.7 | F38: =' Haveri-2'!H42 -> 48 | G38: =' Haveri-2'!J42 -> 5347.2 | H38: =E38+G38 -> 323858.9 | I38: =' Haveri-2'!M3 -> 82823.565 | J38: =+' Haveri-2'!L42 -> 350000 | K38: =H38+I38-J38 -> 56682.466
A39: 40 | B39: Guttal-2 | C39: Himagiri Petroleum | D39: =+' Guttal-2'!E35 -> 1664 | E39: =+' Guttal-2'!G35 -> 165734.4 | F39: =+' Guttal-2'!H35 -> 107.61 | G39: =+' Guttal-2'!J35 -> 12021.113 | H39: =E39+G39 -> 177755.51 | I39: =+' Guttal-2'!M3 -> 459610.06 | J39: =+' Guttal-2'!L35 -> 550000 | K39: =H39+I39-J39 -> 87365.57
A40: 41 | B40: Rattihali-2 | C40: Shiva Oil Traders | D40: =+'Rattihali-2'!E37 -> 1647.32 | E40: =+'Rattihali-2'!G37 -> 164237.8 | F40: =+'Rattihali-2'!H37 -> 95 | G40: =+'Rattihali-2'!J37 -> 10622.9 | H40: =E40+G40 -> 174860.7 | I40: =+'Rattihali-2'!M3 -> 161393.37 | J40: =+'Rattihali-2'!L37 -> 200000 | K40: =H40+I40-J40 -> 136254.08
...

Sheet HO(DG)
A2: S.No | B2: Date | C2: GRN No | D2: Ind No/Bill No | E2: Diesel (Lts) | F2: Price | G2: Amount | H2: Petrol (Lts) | I2: Price | J2: Amount | K2: Total amount | L2: Amount paid | M2: As on date | N2: Remarks
A3: Opening Balance | K3: - | M3: 0
A4: 1 | B4: 46296 | G4: - | H4: - | I4: - | J4: - | K4: - | L4: - | M4: -
A5: 2 | B5: 46297 | G5: - | H5: - | I5: - | J5: - | K5: - | M5: -
A6: 3 | B6: 46298 | E6: 50 | F6: 103.76 | G6: =E6*F6 -> 5188 | H6: 0 | I6: 0 | J6: =H6*I6 -> 0 | K6: =G6+J6 -> 5188 | L6: 5188 | M6: -
A7: 4 | B7: 46299 | E7: 0 | F7: 0 | G7: =E7*F7 -> 0 | H7: 0 | I7: 0 | J7: =H7*I7 -> 0 | K7: =G7+J7 -> 0 | M7: -
A8: 5 | B8: 46300 | E8: 100 | F8: 103.76 | G8: =E8*F8 -> 10376 | H8: 0 | I8: 0 | J8: =H8*I8 -> 0 | K8: =G8+J8 -> 10376 | L8: 10376 | M8: -
A9: 6 | B9: 46301 | E9: 40 | F9: 103.76 | G9: =E9*F9 -> 4150.4 | H9: 0 | I9: 0 | J9: =H9*I9 -> 0 | K9: =G9+J9 -> 4150.4 | L9: 4150.4 | M9: -
A10: 7 | B10: 46302 | E10: 0 | F10: 0 | G10: =E10*F10 -> 0 | H10: 0 | I10: 0 | J10: =H10*I10 -> 0 | K10: =G10+J10 -> 0 | M10: -
A11: 8 | B11: 46303 | E11: 0 | F11: 0 | G11: =E11*F11 -> 0 | H11: 0 | I11: 0 | J11: =H11*I11 -> 0 | K11: =G11+J11 -> 0 | M11: -
A12: 9 | B12: 46304 | E12: 0 | F12: 0 | G12: =E12*F12 -> 0 | H12: 0 | I12: 0 | J12: =H12*I12 -> 0 | K12: =G12+J12 -> 0 | M12: -
A13: 10 | B13: 46305 | E13: 0 | F13: 0 | G13: =E13*F13 -> 0 | H13: 0 | I13: 0 | J13: =H13*I13 -> 0 | K13: =G13+J13 -> 0 | M13: -
A14: 11 | B14: 46306 | E14: 0 | F14: 0 | G14: =E14*F14 -> 0 | H14: 0 | I14: 0 | J14: =H14*I14 -> 0 | K14: =G14+J14 -> 0 | M14: -
A15: 12 | B15: 46307 | E15: 0 | F15: 0 | G15: =E15*F15 -> 0 | H15: 0 | I15: 0 | J15: =H15*I15 -> 0 | K15: =G15+J15 -> 0 | M15: -
A16: 13 | B16: 46308 | E16: 0 | F16: 0 | G16: =E16*F16 -> 0 | H16: 0 | I16: 0 | J16: =H16*I16 -> 0 | K16: =G16+J16 -> 0 | M16: -
A17: 14 | B17: 46309 | E17: 50 | F17: 103.76 | G17: =E17*F17 -> 5188 | H17: 0 | I17: 0 | J17: =H17*I17 -> 0 | K17: =G17+J17 -> 5188 | M17: -
A18: 15 | B18: 46310 | E18: 0 | F18: 0 | G18: =E18*F18 -> 0 | H18: 0 | I18: 0 | J18: =H18*I18 -> 0 | K18: =G18+J18 -> 0 | M18: -
A19: 16 | B19: 46311 | E19: 0 | F19: 0 | G19: =E19*F19 -> 0 | H19: 0 | I19: 0 | J19: =H19*I19 -> 0 | K19: =G19+J19 -> 0 | M19: -
A20: 17 | B20: 46312 | E20: 0 | F20: 0 | G20: =E20*F20 -> 0 | H20: 0 | I20: 0 | J20: =H20*I20 -> 0 | K20: =G20+J20 -> 0 | M20: -
A21: 18 | B21: 46313 | M21: -
A22: 19 | B22: 46314 | K22: - | M22: -
A23: 20 | B23: 46315 | K23: - | M23: -
A24: 21 | B24: 46316 | G24: - | K24: - | M24: -
A25: 22 | B25: 46317 | G25: - | K25: - | M25: -
A26: 23 | B26: 46318 | G26: - | K26: - | M26: -
A27: 24 | B27: 46319 | G27: - | K27: - | M27: -
A28: 25 | B28: 46320 | G28: - | K28: - | M28: -
A29: 26 | B29: 46321 | G29: - | K29: - | M29: -
A30: 27 | B30: 46322 | G30: - | K30: - | M30: -
A31: 28 | B31: 46323 | G31: - | K31: - | M31: -
A32: 29 | B32: 46324 | G32: - | K32: -
A33: 30 | B33: 46325 | G33: - | K33: - | M33: -
A34: 31 | B34: 46326 | G34: - | K34: - | M34: -
A35: 32 | B35: 46327 | G35: - | K35: - | M35: -
A36: 33 | B36: 46328 | G36: - | K36: - | M36: -
A37: 34 | G37: - | K37: - | M37: -
A38: 35 | K38: - | M38: -
A39: 36 | M39: -
A40: 37 | M40: -
A41: 38
...

Sheet Khammam-1
A1: Divya laxmi ganapathi
A2: S.No | B2: Date | C2: GRN No | D2: Ind No/Bill No | E2: Diesel (Lts) | F2: Price | G2: Amount | H2: Petrol (Lts) | I2: Price | J2: Amount | K2: Total amount | L2: Amount paid | M2: As 0n Date | N2: Remarks
A3: Opening Balance | K3: 4131883.8 | M3: 4131883.8 | O3: =K3-M3 -> 0
A4: 1 | B4: 46296 | G4: =E4*F4 -> 0 | K4: =G4+J4 -> 0 | M4: =M3+K4-L4 -> 4131883.8
A5: 2 | B5: 46297 | G5: =E5*F5 -> 0 | K5: =G5+J5 -> 0 | M5: =M4+K5-L5 -> 4131883.8
A6: 3 | B6: 46298 | G6: =E6*F6 -> 0 | K6: =G6+J6 -> 0 | M6: =M5+K6-L6 -> 4131883.8
A7: 4 | B7: 46299 | G7: =E7*F7 -> 0 | K7: =G7+J7 -> 0 | M7: =M6+K7-L7 -> 4131883.8
A8: 5 | B8: 46300 | G8: =E8*F8 -> 0 | K8: =G8+J8 -> 0 | M8: =M7+K8-L8 -> 4131883.8
A9: 6 | B9: 46301 | G9: =E9*F9 -> 0 | K9: =G9+J9 -> 0 | M9: =M8+K9-L9 -> 4131883.8
A10: 7 | B10: 46302 | G10: =E10*F10 -> 0 | K10: =G10+J10 -> 0 | M10: =M9+K10-L10 -> 4131883.8
A11: 8 | B11: 46303 | G11: =E11*F11 -> 0 | K11: =G11+J11 -> 0 | M11: =M10+K11-L11 -> 4131883.8
A12: 9 | B12: 46304 | E12: 2300 | F12: 103.8 | G12: =E12*F12 -> 238740 | H12: 110 | I12: 115.69 | J12: =H12*I12 -> 12725.9 | K12: =G12+J12 -> 251465.9 | M12: =M11+K12-L12 -> 4383349.7
A13: 10 | B13: 46305 | G13: =E13*F13 -> 0 | J13: =H13*I13 -> 0 | K13: =G13+J13 -> 0 | M13: =M12+K13-L13 -> 4383349.7
A14: 11 | B14: 46306 | G14: =E14*F14 -> 0 | J14: =H14*I14 -> 0 | K14: =G14+J14 -> 0 | M14: =M13+K14-L14 -> 4383349.7
A15: 12 | B15: 46307 | G15: =E15*F15 -> 0 | H15: 110 | I15: 115.69 | J15: =H15*I15 -> 12725.9 | K15: =G15+J15 -> 12725.9 | M15: =M14+K15-L15 -> 4396075.6
A16: 13 | B16: 46308 | G16: =E16*F16 -> 0 | J16: =H16*I16 -> 0 | K16: =G16+J16 -> 0 | M16: =M15+K16-L16 -> 4396075.6
A17: 14 | B17: 46309 | G17: =E17*F17 -> 0 | J17: =H17*I17 -> 0 | K17: =G17+J17 -> 0 | M17: =M16+K17-L17 -> 4396075.6
A18: 15 | B18: 46310 | E18: 2700 | F18: 103.8 | G18: =E18*F18 -> 280260 | H18: 130 | I18: 115.69 | J18: =H18*I18 -> 15039.7 | K18: =G18+J18 -> 295299.7 | L18: 400000 | M18: =M17+K18-L18 -> 4291375.3 | N18: HPCL Card
A19: 16 | B19: 46311 | G19: =E19*F19 -> 0 | K19: =G19+J19 -> 0 | M19: =M18+K19-L19 -> 4291375.3
A20: 17 | B20: 46312 | G20: =E20*F20 -> 0 | K20: =G20+J20 -> 0 | M20: =M19+K20-L20 -> 4291375.3
A21: 18 | B21: 46313 | G21: =E21*F21 -> 0 | K21: =G21+J21 -> 0 | M21: =M20+K21-L21 -> 4291375.3
A22: 19 | B22: 46314 | G22: =E22*F22 -> 0 | K22: =G22+J22 -> 0 | M22: =M21+K22-L22 -> 4291375.3
A23: 20 | B23: 46315 | G23: =E23*F23 -> 0 | K23: =G23+J23 -> 0 | M23: =M22+K23-L23 -> 4291375.3
A24: 21 | B24: 46316 | G24: =E24*F24 -> 0 | K24: =G24+J24 -> 0 | M24: =M23+K24-L24 -> 4291375.3
A25: 22 | B25: 46317 | G25: =E25*F25 -> 0 | K25: =G25+J25 -> 0 | M25: =M24+K25-L25 -> 4291375.3
A26: 23 | B26: 46318 | G26: =E26*F26 -> 0 | K26: =G26+J26 -> 0 | M26: =M25+K26-L26 -> 4291375.3
A27: 24 | B27: 46319 | G27: =E27*F27 -> 0 | K27: =G27+J27 -> 0 | M27: =M26+K27-L27 -> 4291375.3
A28: 25 | B28: 46320 | G28: =E28*F28 -> 0 | K28: =G28+J28 -> 0 | M28: =M27+K28-L28 -> 4291375.3
A29: 26 | B29: 46321 | G29: =E29*F29 -> 0 | K29: =G29+J29 -> 0 | M29: =M28+K29-L29 -> 4291375.3
A30: 27 | B30: 46322 | G30: =E30*F30 -> 0 | K30: =G30+J30 -> 0 | M30: =M29+K30-L30 -> 4291375.3
... A34: 31 | B34: 46326 | G34: =E34*F34 -> 0 | K34: =G34+J34 -> 0 | M34: =M33+K34-L34 -> 4291375.3
A35: 32 | G35: =E35*F35 -> 0 | K35: =G35+J35 -> 0 | M35: =M34+K35-L35 -> 4291375.3
A36: 33 | G36: =E36*F36 -> 0 | J36: =H36*I36 -> 0 | K36: =G36+J36 -> 0
A37: 34 | G37: =E37*F37 -> 0 | J37: =H37*I37 -> 0 | K37: =G37+J37 -> 0
E38: =SUM(E3:E37) -> 5000 | G38: =SUM(G3:G37) -> 519000 | H38: =SUM(H3:H37) -> 350 | J38: =SUM(J3:J37) -> 40491.5 | K38: =SUM(K4:K37) -> 559491.5 | L38: =SUM(L3:L37) -> 400000

Sheet Khammam-2
A1: Jayasai union bunk
A2: S.No | B2: Date | C2: GRN No | D2: Ind No/Bill No | E2: Diesel (Lts) | F2: Price | G2: Amount | H2: Petrol (Lts) | I2: Price | J2: Amount | K2: Total amount | L2: Amount paid | M2: As 0n Date | N2: Remarks
A3: Opening Balance | K3: 4248603.6 | M3: 4248603.6
A4: 1 | B4: 46296 | E4: 1000 | F4: 103.82 | G4: =E4*F4 -> 103820 | J4: =H4*I4 -> 0 | K4: =G4+J4 -> 103820 | M4: =M3+K4-L4 -> 4352423.6
A5: 2 | B5: 46297 | E5: =1000+700 -> 1700 | F5: 103.82 | G5: =E5*F5 -> 176494 | J5: =H5*I5 -> 0 | K5: =G5+J5 -> 176494 | M5: =M4+K5-L5 -> 4528917.6
A6: 3 | B6: 46298 | E6: =2700+2500 -> 5200 | F6: 103.82 | G6: =E6*F6 -> 539864 | J6: =H6*I6 -> 0 | K6: =G6+J6 -> 539864 | M6: =M5+K6-L6 -> 5068781.6
A7: 4 | B7: 46299 | E7: 2700 | F7: 103.82 | G7: =E7*F7 -> 280314 | J7: =H7*I7 -> 0 | K7: =G7+J7 -> 280314 | M7: =M6+K7-L7 -> 5349095.6
A8: 5 | B8: 46300 | G8: =E8*F8 -> 0 | J8: =H8*I8 -> 0 | K8: =G8+J8 -> 0 | M8: =M7+K8-L8 -> 5349095.6
A9: 6 | B9: 46301 | E9: 2700 | F9: 103.82 | G9: =E9*F9 -> 280314 | H9: 90 | I9: 115.72 | J9: =H9*I9 -> 10414.8 | K9: =G9+J9 -> 290728.8 | M9: =M8+K9-L9 -> 5639824.4
A10: 7 | B10: 46302 | E10: 2700 | F10: 103.82 | G10: =E10*F10 -> 280314 | H10: 40 | I10: 115.72 | J10: =H10*I10 -> 4628.8 | K10: =G10+J10 -> 284942.8 | M10: =M9+K10-L10 -> 5924767.2
A11: 8 | B11: 46303 | G11: =E11*F11 -> 0 | J11: =H11*I11 -> 0 | K11: =G11+J11 -> 0 | M11: =M10+K11-L11 -> 5924767.2
A12: 9 | B12: 46304 | G12: =E12*F12 -> 0 | J12: =H12*I12 -> 0 | K12: =G12+J12 -> 0 | M12: =M11+K12-L12 -> 5924767.2
A13: 10 | B13: 46305 | E13: 5300 | F13: 103.82 | G13: =E13*F13 -> 550246 | J13: =H13*I13 -> 0 | K13: =G13+J13 -> 550246 | M13: =M12+K13-L13 -> 6475013.2 | V13: 250000
A14: 11 | B14: 46306 | G14: =E14*F14 -> 0 | J14: =H14*I14 -> 0 | K14: =G14+J14 -> 0 | M14: =M13+K14-L14 -> 6475013.2 | V14: 70000
A15: 12 | B15: 46307 | G15: =E15*F15 -> 0 | J15: =H15*I15 -> 0 | K15: =G15+J15 -> 0 | M15: =M14+K15-L15 -> 6475013.2 | V15: 46366
A16: 13 | B16: 46308 | E16: 2800 | F16: 103.82 | G16: =E16*F16 -> 290696 | J16: =H16*I16 -> 0 | K16: =G16+J16 -> 290696 | M16: =M15+K16-L16 -> 6765709.2
A17: 14 | B17: 46309 | E17: 2600 | F17: 103.82 | G17: =E17*F17 -> 269932 | J17: =H17*I17 -> 0 | K17: =G17+J17 -> 269932 | M17: =M16+K17-L17 -> 7035641.2
A18: 15 | B18: 46310 | E18: 2900 | F18: 103.82 | G18: =E18*F18 -> 301078 | J18: =H18*I18 -> 0 | K18: =G18+J18 -> 301078 | L18: 2000000 | M18: =M17+K18-L18 -> 5336719.2
A19: 16 | B19: 46311 | G19: =E19*F19 -> 0 | J19: =H19*I19 -> 0 | K19: =G19+J19 -> 0 | M19: =M18+K19-L19 -> 5336719.2
A20: 17 | B20: 46312 | G20: =E20*F20 -> 0 | J20: =H20*I20 -> 0 | K20: =G20+J20 -> 0 | M20: =M19+K20-L20 -> 5336719.2
A21: 18 | B21: 46313 | G21: =E21*F21 -> 0 | J21: =H21*I21 -> 0 | K21: =G21+J21 -> 0 | M21: =M20+K21-L21 -> 5336719.2
A22: 19 | B22: 46314 | G22: =E22*F22 -> 0 | J22: =H22*I22 -> 0 | K22: =G22+J22 -> 0 | M22: =M21+K22-L22 -> 5336719.2
A23: 20 | B23: 46315 | G23: =E23*F23 -> 0 | J23: =H23*I23 -> 0 | K23: =G23+J23 -> 0 | M23: =M22+K23-L23 -> 5336719.2
A24: 21 | B24: 46316 | G24: =E24*F24 -> 0 | J24: =H24*I24 -> 0 | K24: =G24+J24 -> 0 | M24: =M23+K24-L24 -> 5336719.2
B25: 46317 | G25: =E25*F25 -> 0 | K25: =G25+J25 -> 0 | M25: =M24+K25-L25 -> 5336719.2
A26: 22 | B26: 46318 | G26: =E26*F26 -> 0 | J26: =H26*I26 -> 0 | K26: =G26+J26 -> 0 | M26: =M25+K26-L26 -> 5336719.2
A27: 23 | B27: 46319 | G27: =E27*F27 -> 0 | J27: =H27*I27 -> 0 | K27: =G27+J27 -> 0 | M27: =M26+K27-L27 -> 5336719.2
A28: 24 | B28: 46320 | G28: =E28*F28 -> 0 | J28: =H28*I28 -> 0 | K28: =G28+J28 -> 0 | M28: =M27+K28-L28 -> 5336719.2
A29: 25 | B29: 46321 | G29: =E29*F29 -> 0 | J29: =H29*I29 -> 0 | K29: =G29+J29 -> 0 | M29: =M28+K29-L29 -> 5336719.2
A30: 26 | B30: 46322 | G30: =E30*F30 -> 0 | J30: =H30*I30 -> 0 | K30: =G30+J30 -> 0 | M30: =M29+K30-L30 -> 5336719.2
A31: 27 | B31: 46323 | G31: =E31*F31 -> 0 | J31: =H31*I31 -> 0 | K31: =G31+J31 -> 0 | M31: =M30+K31-L31 -> 5336719.2
A32: 28 | B32: 46324 | G32: =E32*F32 -> 0 | J32: =H32*I32 -> 0 | K32: =G32+J32 -> 0 | M32: =M31+K32-L32 -> 5336719.2
A33: 29 | B33: 46325 | G33: =E33*F33 -> 0 | J33: =H33*I33 -> 0 | K33: =G33+J33 -> 0 | M33: =M32+K33-L33 -> 5336719.2
A34: 30 | B34: 46326 | G34: =E34*F34 -> 0 | J34: =H34*I34 -> 0 | K34: =G34+J34 -> 0 | M34: =M33+K34-L34 -> 5336719.2
A35: 31 | B35: 46327 | G35: =E35*F35 -> 0 | J35: =H35*I35 -> 0 | K35: =G35+J35 -> 0 | M35: =M34+K35-L35 -> 5336719.2
A36: 32 | G36: =E36*F36 -> 0 | J36: =H36*I36 -> 0 | K36: =G36+J36 -> 0 | M36: =M35+K36-L36 -> 5336719.2
A37: 33 | G37: =E37*F37 -> 0 | J37: =H37*I37 -> 0 | K37: =G37+J37 -> 0 | M37: =M36+K37-L37 -> 5336719.2
E39: =SUM(E4:E37) -> 29600 | G39: =SUM(G4:G37) -> 3073072 | H39: =SUM(H4:H37) -> 130 | J39: =SUM(J4:J37) -> 15043.6 | K39: =SUM(K4:K37) -> 3088115.6 | L39: =SUM(L4:L37) -> 2000000

Sheet Khammam-4
A1: Sai Madeana Filling Station
A2: S.No | B2: Date | C2: GRN No | D2: Ind No/Bill No | E2: Diesel (Lts) | F2: Price | G2: Amount | H2: Petrol (Lts) | I2: Price | J2: Amount | K2: Total amount | L2: Amount paid | M2: As 0n Date | N2: Remarks
A3: Opening Balance | K3: 3141611.1 | M3: 3141611.1
A4: 1 | B4: 46296 | G4: =E4*F4 -> 0 | J4: =H4*I4 -> 0 | K4: =G4+J4 -> 0 | M4: =M3+K4-L4 -> 3141611.1
A5: 2 | B5: 46297 | E5: 2700 | F5: 103.62 | G5: =E5*F5 -> 279774 | H5: 75 | I5: 115.49 | J5: =H5*I5 -> 8661.75 | K5: =G5+J5 -> 288435.75 | L5: 288435.75 | M5: =M4+K5-L5 -> 3141611.1
A6: 3 | B6: 46298 | G6: =E6*F6 -> 0 | J6: =H6*I6 -> 0 | K6: =G6+J6 -> 0 | M6: =M5+K6-L6 -> 3141611.1
A7: 4 | B7: 46299 | G7: =E7*F7 -> 0 | J7: =H7*I7 -> 0 | K7: =G7+J7 -> 0 | M7: =M6+K7-L7 -> 3141611.1
A8: 5 | B8: 46300 | G8: =E8*F8 -> 0 | J8: =H8*I8 -> 0 | K8: =G8+J8 -> 0 | M8: =M7+K8-L8 -> 3141611.1
A9: 6 | B9: 46301 | G9: =E9*F9 -> 0 | J9: =H9*I9 -> 0 | K9: =G9+J9 -> 0 | M9: =M8+K9-L9 -> 3141611.1
A10: 7 | B10: 46302 | G10: =E10*F10 -> 0 | J10: =H10*I10 -> 0 | K10: =G10+J10 -> 0 | M10: =M9+K10-L10 -> 3141611.1
A11: 8 | B11: 46303 | G11: =E11*F11 -> 0 | J11: =H11*I11 -> 0 | K11: =G11+J11 -> 0 | M11: =M10+K11-L11 -> 3141611.1
A12: 9 | B12: 46304 | G12: =E12*F12 -> 0 | J12: =H12*I12 -> 0 | K12: =G12+J12 -> 0 | M12: =M11+K12-L12 -> 3141611.1
A13: 10 | B13: 46305 | G13: =E13*F13 -> 0 | J13: =H13*I13 -> 0 | K13: =G13+J13 -> 0 | M13: =M12+K13-L13 -> 3141611.1
A14: 11 | B14: 46306 | G14: =E14*F14 -> 0 | J14: =H14*I14 -> 0 | K14: =G14+J14 -> 0 | M14: =M13+K14-L14 -> 3141611.1
A15: 12 | B15: 46307 | G15: =E15*F15 -> 0 | J15: =H15*I15 -> 0 | K15: =G15+J15 -> 0 | M15: =M14+K15-L15 -> 3141611.1
A16: 13 | B16: 46308 | G16: =E16*F16 -> 0 | J16: =H16*I16 -> 0 | K16: =G16+J16 -> 0 | M16: =M15+K16-L16 -> 3141611.1
A17: 14 | B17: 46309 | G17: =E17*F17 -> 0 | J17: =H17*I17 -> 0 | K17: =G17+J17 -> 0 | M17: =M16+K17-L17 -> 3141611.1
... A34: 31 | B34: 46326 | G34: =E34*F34 -> 0 | J34: =H34*I34 -> 0 | K34: =G34+J34 -> 0 | M34: =M33+K34-L34 -> 3141611.1
E35: =SUM(E4:E34) -> 2700 | G35: =SUM(G4:G34) -> 279774 | H35: =SUM(H4:H34) -> 75 | J35: =SUM(J4:J34) -> 8661.75 | K35: =SUM(K4:K34) -> 288435.75 | L35: =SUM(L4:L34) -> 288435.75

Sheet  Khammam-5
A1: Vajra mahalakshmi filling station
A2: S.No | B2: Date | C2: GRN No | D2: Ind No/Bill No | E2: Diesel (Lts) | F2: Price | G2: Amount | H2: Petrol (Lts) | I2: Price | J2: Amount | K2: Total amount | L2: Amount paid | M2: As 0n Date | N2: Remarks
A3: Opening Balance | K3: 1445001.9 | M3: 1445001.9
A4: 1 | B4: 46296 | G4: =E4*F4 -> 0 | J4: =H4*I4 -> 0 | K4: =G4+J4 -> 0 | M4: =M3+K4-L4 -> 1445001.9
A5: 2 | B5: 46297 | G5: =E5*F5 -> 0 | J5: =H5*I5 -> 0 | K5: =G5+J5 -> 0 | M5: =M4+K5-L5 -> 1445001.9
A6: 3 | B6: 46298 | G6: =E6*F6 -> 0 | J6: =H6*I6 -> 0 | K6: =G6+J6 -> 0 | M6: =M5+K6-L6 -> 1445001.9
A7: 4 | B7: 46299 | G7: =E7*F7 -> 0 | J7: =H7*I7 -> 0 | K7: =G7+J7 -> 0 | M7: =M6+K7-L7 -> 1445001.9
A8: 5 | B8: 46300 | G8: =E8*F8 -> 0 | J8: =H8*I8 -> 0 | K8: =G8+J8 -> 0 | M8: =M7+K8-L8 -> 1445001.9
A9: 6 | B9: 46301 | G9: =E9*F9 -> 0 | J9: =H9*I9 -> 0 | K9: =G9+J9 -> 0 | M9: =M8+K9-L9 -> 1445001.9
A10: 7 | B10: 46302 | G10: =E10*F10 -> 0 | J10: =H10*I10 -> 0 | K10: =G10+J10 -> 0 | M10: =M9+K10-L10 -> 1445001.9
A11: 8 | B11: 46303 | G11: =E11*F11 -> 0 | J11: =H11*I11 -> 0 | K11: =G11+J11 -> 0 | M11: =M10+K11-L11 -> 1445001.9
A12: 9 | B12: 46304 | G12: =E12*F12 -> 0 | J12: =H12*I12 -> 0 | K12: =G12+J12 -> 0 | M12: =M11+K12-L12 -> 1445001.9
A13: 10 | B13: 46305 | G13: =E13*F13 -> 0 | J13: =H13*I13 -> 0 | K13: =G13+J13 -> 0 | M13: =M12+K13-L13 -> 1445001.9
A14: 11 | B14: 46306 | G14: =E14*F14 -> 0 | J14: =H14*I14 -> 0 | K14: =G14+J14 -> 0 | M14: =M13+K14-L14 -> 1445001.9
A15: 12 | B15: 46307 | G15: =E15*F15 -> 0 | J15: =H15*I15 -> 0 | K15: =G15+J15 -> 0 | M15: =M14+K15-L15 -> 1445001.9
... A34: 31 | B34: 46326 | G34: =E34*F34 -> 0 | J34: =H34*I34 -> 0 | K34: =G34+J34 -> 0 | M34: =M33+K34-L34 -> 1445001.9
E35: =SUM(E4:E34) -> 0 | G35: =SUM(G4:G34) -> 0 | H35: =SUM(H4:H34) -> 0 | J35: =SUM(J4:J34) -> 0 | K35: =SUM(K4:K34) -> 0 | L35: =SUM(L4:L34) -> 0

Sheet  Khammam-6
A1: Jai Sreeram
A2: S.No | B2: Date | C2: GRN No | D2: Ind No/Bill No | E2: Diesel (Lts) | F2: Price | G2: Amount | H2: Petrol (Lts) | I2: Price | J2: Amount | K2: Total amount | L2: Amount paid | M2: As 0n Date | N2: Remarks
A3: Opening Balance | K3: 0 | M3: 0
A4: 1 | B4: 46296 | G4: =E4*F4 -> 0 | J4: =H4*I4 -> 0 | K4: =G4+J4 -> 0 | M4: =M3+K4-L4 -> 0
A5: 2 | B5: 46297 | G5: =E5*F5 -> 0 | J5: =H5*I5 -> 0 | K5: =G5+J5 -> 0 | M5: =M4+K5-L5 -> 0
A6: 3 | B6: 46298 | E6: 5400 | F6: 103.84 | G6: =E6*F6 -> 560736 | J6: =H6*I6 -> 0 | K6: =G6+J6 -> 560736 | M6: =M5+K6-L6 -> 560736
A7: 4 | B7: 46299 | G7: =E7*F7 -> 0 | J7: =H7*I7 -> 0 | K7: =G7+J7 -> 0 | M7: =M6+K7-L7 -> 560736
A8: 5 | B8: 46300 | E8: 2700 | F8: 103.84 | G8: =E8*F8 -> 280368 | J8: =H8*I8 -> 0 | K8: =G8+J8 -> 280368 | M8: =M7+K8-L8 -> 841104
A9: 6 | B9: 46301 | E9: 2700 | F9: 103.84 | G9: =E9*F9 -> 280368 | J9: =H9*I9 -> 0 | K9: =G9+J9 -> 280368 | M9: =M8+K9-L9 -> 1121472
A10: 7 | B10: 46302 | E10: 2700 | F10: 103.84 | G10: =E10*F10 -> 280368 | J10: =H10*I10 -> 0 | K10: =G10+J10 -> 280368 | M10: =M9+K10-L10 -> 1401840
A11: 8 | B11: 46303 | E11: 2700 | F11: 103.84 | G11: =E11*F11 -> 280368 | J11: =H11*I11 -> 0 | K11: =G11+J11 -> 280368 | M11: =M10+K11-L11 -> 1682208
A12: 9 | B12: 46304 | E12: 5400 | F12: 103.84 | G12: =E12*F12 -> 560736 | J12: =H12*I12 -> 0 | K12: =G12+J12 -> 560736 | M12: =M11+K12-L12 -> 2242944
A13: 10 | B13: 46305 | E13: 5400 | F13: 103.84 | G13: =E13*F13 -> 560736 | J13: =H13*I13 -> 0 | K13: =G13+J13 -> 560736 | M13: =M12+K13-L13 -> 2803680
A14: 11 | B14: 46306 | E14: 2700 | F14: 103.84 | G14: =E14*F14 -> 280368 | J14: =H14*I14 -> 0 | K14: =G14+J14 -> 280368 | M14: =M13+K14-L14 -> 3084048
A15: 12 | B15: 46307 | E15: 2700 | F15: 103.84 | G15: =E15*F15 -> 280368 | J15: =H15*I15 -> 0 | K15: =G15+J15 -> 280368 | M15: =M14+K15-L15 -> 3364416
A16: 13 | B16: 46308 | E16: 2700 | F16: 103.84 | G16: =E16*F16 -> 280368 | J16: =H16*I16 -> 0 | K16: =G16+J16 -> 280368 | M16: =M15+K16-L16 -> 3644784
A17: 14 | B17: 46309 | E17: 2700 | F17: 103.84 | G17: =E17*F17 -> 280368 | J17: =H17*I17 -> 0 | K17: =G17+J17 -> 280368 | M17: =M16+K17-L17 -> 3925152
A18: 15 | B18: 46310 | E18: 2700 | F18: 103.84 | G18: =E18*F18 -> 280368 | J18: =H18*I18 -> 0 | K18: =G18+J18 -> 280368 | M18: =M17+K18-L18 -> 4205520
A19: 16 | B19: 46311 | G19: =E19*F19 -> 0 | J19: =H19*I19 -> 0 | K19: =G19+J19 -> 0 | M19: =M18+K19-L19 -> 4205520
A20: 17 | B20: 46312 | G20: =E20*F20 -> 0 | J20: =H20*I20 -> 0 | K20: =G20+J20 -> 0 | M20: =M19+K20-L20 -> 4205520
A21: 18 | B21: 46313 | G21: =E21*F21 -> 0 | J21: =H21*I21 -> 0 | K21: =G21+J21 -> 0 | M21: =M20+K21-L21 -> 4205520
A22: 19 | B22: 46314 | G22: =E22*F22 -> 0 | J22: =H22*I22 -> 0 | K22: =G22+J22 -> 0 | M22: =M21+K22-L22 -> 4205520
A23: 20 | B23: 46315 | G23: =E23*F23 -> 0 | J23: =H23*I23 -> 0 | K23: =G23+J23 -> 0 | M23: =M22+K23-L23 -> 4205520
A24: 21 | B24: 46316 | G24: =E24*F24 -> 0 | J24: =H24*I24 -> 0 | K24: =G24+J24 -> 0 | M24: =M23+K24-L24 -> 4205520
A25: 22 | B25: 46317 | G25: =E25*F25 -> 0 | J25: =H25*I25 -> 0 | K25: =G25+J25 -> 0 | M25: =M24+K25-L25 -> 4205520
A26: 23 | B26: 46318 | G26: =E26*F26 -> 0 | J26: =H26*I26 -> 0 | K26: =G26+J26 -> 0 | M26: =M25+K26-L26 -> 4205520
A27: 24 | B27: 46319 | G27: =E27*F27 -> 0 | J27: =H27*I27 -> 0 | K27: =G27+J27 -> 0 | M27: =M26+K27-L27 -> 4205520
A28: 25 | B28: 46320 | G28: =E28*F28 -> 0 | J28: =H28*I28 -> 0 | K28: =G28+J28 -> 0 | M28: =M27+K28-L28 -> 4205520
A29: 26 | B29: 46321 | G29: =E29*F29 -> 0 | J29: =H29*I29 -> 0 | K29: =G29+J29 -> 0 | M29: =M28+K29-L29 -> 4205520
A30: 27 | B30: 46322 | G30: =E30*F30 -> 0 | J30: =H30*I30 -> 0 | K30: =G30+J30 -> 0 | M30: =M29+K30-L30 -> 4205520
... A34: 31 | B34: 46326 | G34: =E34*F34 -> 0 | J34: =H34*I34 -> 0 | K34: =G34+J34 -> 0 | M34: =M33+K34-L34 -> 4205520
E35: =SUM(E4:E34) -> 40500 | G35: =SUM(G4:G34) -> 4205520 | H35: =SUM(H4:H34) -> 0 | J35: =SUM(J4:J34) -> 0 | K35: =SUM(K4:K34) -> 4205520 | L35: =SUM(L4:L34) -> 0

Sheet  Khammam&Cash
A1: Cash &Carry
A2: S.No | B2: Date | D2: Ind No/Bill No | E2: Diesel (Lts) | F2: Price | G2: Amount | H2: Petrol (Lts) | I2: Price | J2: Amount | K2: Total amount | L2: Amount paid | M2: As 0n Date | N2: Remarks
A3: Opening Balance | K3: 0 | M3: 0
A4: 1 | G4: =E4*F4 -> 0 | K4: =G4+J4 -> 0 | L4: =H4+K4 -> 0 | M4: =M3+K4-L4 -> 0
A5: 2 | G5: =E5*F5 -> 0 | J5: =H5*I5 -> 0 | K5: =G5+J5 -> 0 | L5: =H5+K5 -> 0 | M5: =M4+K5-L5 -> 0
A6: 3 | G6: =E6*F6 -> 0 | J6: =H6*I6 -> 0 | K6: =G6+J6 -> 0 | L6: =H6+K6 -> 0 | M6: =M5+K6-L6 -> 0
A7: 4 | G7: =E7*F7 -> 0 | J7: =H7*I7 -> 0 | K7: =G7+J7 -> 0 | L7: =H7+K7 -> 0 | M7: =M6+K7-L7 -> 0
A8: 5 | G8: =E8*F8 -> 0 | J8: =H8*I8 -> 0 | K8: =G8+J8 -> 0 | L8: =H8+K8 -> 0 | M8: =M7+K8-L8 -> 0
A9: 6 | G9: =E9*F9 -> 0 | J9: =H9*I9 -> 0 | K9: =G9+J9 -> 0 | L9: =H9+K9 -> 0 | M9: =M8+K9-L9 -> 0
A10: 7 | G10: =E10*F10 -> 0 | J10: =H10*I10 -> 0 | K10: =G10+J10 -> 0 | L10: =H10+K10 -> 0 | M10: =M9+K10-L10 -> 0
A11: 8 | G11: =E11*F11 -> 0 | J11: =H11*I11 -> 0 | K11: =G11+J11 -> 0 | L11: =H11+K11 -> 0 | M11: =M10+K11-L11 -> 0
A12: 9 | G12: =E12*F12 -> 0 | J12: =H12*I12 -> 0 | K12: =G12+J12 -> 0 | L12: =H12+K12 -> 0 | M12: =M11+K12-L12 -> 0
A13: 10 | G13: =E13*F13 -> 0 | J13: =H13*I13 -> 0 | K13: =G13+J13 -> 0 | L13: =H13+K13 -> 0 | M13: =M12+K13-L13 -> 0
A14: 11 | G14: =E14*F14 -> 0 | J14: =H14*I14 -> 0 | K14: =G14+J14 -> 0 | L14: =H14+K14 -> 0 | M14: =M13+K14-L14 -> 0
A15: 12 | G15: =E15*F15 -> 0 | J15: =H15*I15 -> 0 | K15: =G15+J15 -> 0 | L15: =H15+K15 -> 0 | M15: =M14+K15-L15 -> 0
A16: 13 | G16: =E16*F16 -> 0 | J16: =H16*I16 -> 0 | K16: =G16+J16 -> 0 | L16: =H16+K16 -> 0 | M16: =M15+K16-L16 -> 0
... A22: 19 | G22: =E22*F22 -> 0 | J22: =H22*I22 -> 0 | K22: =G22+J22 -> 0 | L22: =H22+K22 -> 0 | M22: =M21+K22-L22 -> 0
A23: 20 | G23: =E23*F23 -> 0 | J23: =H23*I23 -> 0 | K23: =G23+J23 -> 0 | L23: 0 | M23: =M22+K23-L23 -> 0
A24: 21 | G24: =E24*F24 -> 0 | J24: =H24*I24 -> 0 | K24: =G24+J24 -> 0 | L24: =H24+K24 -> 0 | M24: =M23+K24-L24 -> 0
A25: 22 | G25: =E25*F25 -> 0 | J25: =H25*I25 -> 0 | K25: =G25+J25 -> 0 | L25: =H25+K25 -> 0 | M25: =M24+K25-L25 -> 0
A26: 23 | G26: =E26*F26 -> 0 | J26: =H26*I26 -> 0 | K26: =G26+J26 -> 0 | L26: =H26+K26 -> 0 | M26: =M25+K26-L26 -> 0
A27: 24 | G27: =E27*F27 -> 0 | K27: =G27+J27 -> 0 | L27: =H27+K27 -> 0 | M27: =M26+K27-L27 -> 0
A28: 25 | G28: =E28*F28 -> 0 | J28: =H28*I28 -> 0 | K28: =G28+J28 -> 0 | L28: =H28+K28 -> 0 | M28: =M26+K28-L28 -> 0
A29: 26 | G29: =E29*F29 -> 0 | J29: =H29*I29 -> 0 | K29: =G29+J29 -> 0 | L29: =H29+K29 -> 0 | M29: =M28+K29-L29 -> 0
A30: 27 | G30: =E30*F30 -> 0 | J30: =H30*I30 -> 0 | K30: =G30+J30 -> 0 | L30: =H30+K30 -> 0 | M30: =M29+K30-L30 -> 0
A31: 28 | G31: =E31*F31 -> 0 | J31: =H31*I31 -> 0 | K31: =G31+J31 -> 0 | L31: =H31+K31 -> 0 | M31: =M30+K31-L31 -> 0
A32: 29 | G32: =E32*F32 -> 0 | J32: =H32*I32 -> 0 | K32: =G32+J32 -> 0 | L32: =H32+K32 -> 0 | M32: =M31+K32-L32 -> 0
A33: 30 | G33: =E33*F33 -> 0 | J33: =H33*I33 -> 0 | K33: =G33+J33 -> 0 | L33: =H33+K33 -> 0 | M33: =M32+K33-L33 -> 0
A34: 31 | G34: =E34*F34 -> 0 | J34: =H34*I34 -> 0 | K34: =G34+J34 -> 0 | L34: =H34+K34 -> 0 | M34: =M33+K34-L34 -> 0
A35: 32 | G35: =E35*F35 -> 0 | K35: =G35+J35 -> 0 | L35: =H35+K35 -> 0 | M35: =M34+K35-L35 -> 0
A36: 33 | G36: =E36*F36 -> 0 | J36: =H36*I36 -> 0 | K36: =G36+J36 -> 0 | L36: =H36+K36 -> 0 | M36: =M35+K36-L36 -> 0
A37: 34 | G37: =E37*F37 -> 0 | J37: =H37*I37 -> 0 | K37: =G37+J37 -> 0 | L37: =H37+K37 -> 0 | M37: =M36+K37-L37 -> 0
G38: =E38*F38 -> 0 | K38: =G38+J38 -> 0 | L38: =H38+K38 -> 0 | M38: =M37+K38-L38 -> 0
G39: =E39*F39 -> 0 | K39: =G39+J39 -> 0 | L39: =H39+K39 -> 0 | M39: =M38+K39-L39 -> 0
G40: =E40*F40 -> 0 | K40: =G40+J40 -> 0 | L40: =H40+K40 -> 0 | M40: =M39+K40-L40 -> 0
M41: =M40+K41-L41 -> 0
A45: 35 | G45: =E45*F45 -> 0 | J45: =H45*I45 -> 0 | K45: =G45+J45 -> 0
E46: =SUM(E3:E45) -> 0 | G46: =SUM(G3:G45) -> 0 | H46: =SUM(H3:H45) -> 0 | J46: =SUM(J3:J45) -> 0 | K46: =SUM(K4:K45) -> 0 | L46: =SUM(L3:L45) -> 0

Sheet Jadcherla-4
A1: Shree Poornima F/S
A2: S.No | B2: Date | C2: GRN No | D2: Ind No/Bill No | E2: Diesel (Lts) | F2: Price | G2: Amount | H2: Petrol (Lts) | I2: Price | J2: Amount | K2: Total amount | L2: Amount paid | M2: As on date | N2: Remarks
A3: Opening Balance | K3: 47858.18 | M3: 47858.18
A4: 1 | B4: 46296 | G4: =E4*F4 -> 0 | J4: =H4*I4 -> 0 | K4: =G4+J4 -> 0 | L4: 0 | M4: =M3+K4-L4 -> 47858.18
A5: 2 | B5: 46297 | G5: =E5*F5 -> 0 | J5: =H5*I5 -> 0 | K5: =G5+J5 -> 0 | L5: 0 | M5: =M4+K5-L5 -> 47858.18
A6: 3 | B6: 46298 | G6: =E6*F6 -> 0 | J6: =H6*I6 -> 0 | K6: =G6+J6 -> 0 | L6: 0 | M6: =M5+K6-L6 -> 47858.18
A7: 4 | B7: 46299 | G7: =E7*F7 -> 0 | J7: =H7*I7 -> 0 | K7: =G7+J7 -> 0 | L7: 0 | M7: =M6+K7-L7 -> 47858.18
A8: 5 | B8: 46300 | G8: =E8*F8 -> 0 | J8: =H8*I8 -> 0 | K8: =G8+J8 -> 0 | L8: 0 | M8: =M7+K8-L8 -> 47858.18
A9: 6 | B9: 46301 | G9: =E9*F9 -> 0 | J9: =H9*I9 -> 0 | K9: =G9+J9 -> 0 | L9: 0 | M9: =M8+K9-L9 -> 47858.18
A10: 7 | B10: 46302 | G10: =E10*F10 -> 0 | J10: =H10*I10 -> 0 | K10: =G10+J10 -> 0 | L10: 0 | M10: =M9+K10-L10 -> 47858.18
A11: 8 | B11: 46303 | G11: =E11*F11 -> 0 | J11: =H11*I11 -> 0 | K11: =G11+J11 -> 0 | L11: 0 | M11: =M10+K11-L11 -> 47858.18
A12: 9 | B12: 46304 | E12: 100 | F12: 104.42 | G12: =E12*F12 -> 10442 | J12: =H12*I12 -> 0 | K12: =G12+J12 -> 10442 | L12: 0 | M12: =M11+K12-L12 -> 58300.18
A13: 10 | B13: 46305 | G13: =E13*F13 -> 0 | J13: =H13*I13 -> 0 | K13: =G13+J13 -> 0 | L13: 0 | M13: =M12+K13-L13 -> 58300.18
A14: 11 | B14: 46306 | G14: =E14*F14 -> 0 | J14: =H14*I14 -> 0 | K14: =G14+J14 -> 0 | L14: 0 | M14: =M13+K14-L14 -> 58300.18
A15: 12 | B15: 46307 | G15: =E15*F15 -> 0 | J15: =H15*I15 -> 0 | K15: =G15+J15 -> 0 | L15: 0 | M15: =M14+K15-L15 -> 58300.18
A16: 13 | B16: 46308 | G16: =E16*F16 -> 0 | J16: =H16*I16 -> 0 | K16: =G16+J16 -> 0 | L16: 0 | M16: =M15+K16-L16 -> 58300.18
A17: 14 | B17: 46309 | G17: =E17*F17 -> 0 | J17: =H17*I17 -> 0 | K17: =G17+J17 -> 0 | L17: 0 | M17: =M16+K17-L17 -> 58300.18
A18: 15 | B18: 46310 | G18: =E18*F18 -> 0 | J18: =H18*I18 -> 0 | K18: =G18+J18 -> 0 | L18: 50000 | M18: =M17+K18-L18 -> 8300.18
A19: 16 | B19: 46311 | G19: 0 | J19: 0 | K19: 0 | L19: 0 | M19: =M18+K19-L19 -> 8300.18
A20: 17 | B20: 46312 | G20: =E20*F20 -> 0 | J20: =H20*I20 -> 0 | K20: =G20+J20 -> 0 | L20: 0 | M20: =M19+K20-L20 -> 8300.18
A21: 18 | B21: 46313 | G21: =E21*F21 -> 0 | J21: =H21*I21 -> 0 | K21: =G21+J21 -> 0 | L21: 0 | M21: =M20+K21-L21 -> 8300.18
A22: 19 | B22: 46314 | G22: =E22*F22 -> 0 | J22: =H22*I22 -> 0 | K22: =G22+J22 -> 0 | L22: 0 | M22: =M21+K22-L22 -> 8300.18
A23: 20 | B23: 46315 | G23: =E23*F23 -> 0 | J23: =H23*I23 -> 0 | K23: =G23+J23 -> 0 | L23: 0 | M23: =M22+K23-L23 -> 8300.18
A24: 21 | B24: 46316 | G24: =E24*F24 -> 0 | J24: =H24*I24 -> 0 | K24: =G24+J24 -> 0 | L24: 0 | M24: =M23+K24-L24 -> 8300.18
A25: 22 | B25: 46317 | G25: =E25*F25 -> 0 | J25: =H25*I25 -> 0 | K25: =G25+J25 -> 0 | L25: 0 | M25: =M24+K25-L25 -> 8300.18
A26: 23 | B26: 46318 | G26: =E26*F26 -> 0 | J26: =H26*I26 -> 0 | K26: =G26+J26 -> 0 | L26: 0 | M26: =M25+K26-L26 -> 8300.18
A27: 24 | B27: 46319 | G27: =E27*F27 -> 0 | J27: =H27*I27 -> 0 | K27: =G27+J27 -> 0 | L27: 0 | M27: =M26+K27-L27 -> 8300.18
A28: 25 | B28: 46320 | G28: =E28*F28 -> 0 | J28: =H28*I28 -> 0 | K28: =G28+J28 -> 0 | L28: 0 | M28: =M27+K28-L28 -> 8300.18
A29: 26 | B29: 46321 | G29: =E29*F29 -> 0 | J29: =H29*I29 -> 0 | K29: =G29+J29 -> 0 | L29: 0 | M29: =M28+K29-L29 -> 8300.18
A30: 27 | B30: 46322 | G30: =E30*F30 -> 0 | J30: =H30*I30 -> 0 | K30: =G30+J30 -> 0 | L30: 0 | M30: =M29+K30-L30 -> 8300.18
A31: 28 | B31: 46323 | G31: =E31*F31 -> 0 | J31: =H31*I31 -> 0 | K31: =G31+J31 -> 0 | L31: 0 | M31: =M30+K31-L31 -> 8300.18
... A33: 30 | B33: 46325 | G33: =E33*F33 -> 0 | J33: =H33*I33 -> 0 | K33: =G33+J33 -> 0 | L33: 0 | M33: =M32+K33-L33 -> 8300.18
A34: 31 | B34: 46326 | G34: =E34*F34 -> 0 | J34: =H34*I34 -> 0 | K34: =G34+J34 -> 0 | M34: =M33+K34-L34 -> 8300.18
E35: =SUM(E4:E34) -> 100 | G35: =SUM(G4:G34) -> 10442 | H35: =SUM(H4:H34) -> 0 | J35: =SUM(J4:J34) -> 0 | K35: =SUM(K4:K34) -> 10442 | L35: =SUM(L4:L34) -> 50000

Sheet  Sangareddy-2
A1: Durga Bhavani F/S
A2: S.No | B2: Date | C2: GRN No | D2: Ind no/Bill No | E2: Diesel (Lts) | F2: Price | G2: Amount | H2: Petrol (Lts) | I2: Price | J2: Amount | K2: Total amount | L2: Amount paid | M2: As on Date | N2: Remarks
A3: Opening Balance | M3: 0
A4: 1 | B4: 46266 | G4: =E4*F4 -> 0 | J4: =H4*I4 -> 0 | K4: =G4+J4 -> 0 | M4: =M3+K4-L4 -> 0
A5: 2 | B5: 46267 | G5: =E5*F5 -> 0 | J5: =H5*I5 -> 0 | K5: =G5+J5 -> 0 | M5: =M4+K5-L5 -> 0
A6: 3 | B6: 46268 | G6: =E6*F6 -> 0 | J6: =H6*I6 -> 0 | K6: =G6+J6 -> 0 | M6: =M5+K6-L6 -> 0
A7: 4 | B7: 46269 | G7: =E7*F7 -> 0 | J7: =H7*I7 -> 0 | K7: =G7+J7 -> 0 | M7: =M6+K7-L7 -> 0
A8: 5 | B8: 46270 | G8: =E8*F8 -> 0 | J8: =H8*I8 -> 0 | K8: =G8+J8 -> 0 | M8: =M7+K8-L8 -> 0
A9: 6 | B9: 46271 | G9: =E9*F9 -> 0 | J9: =H9*I9 -> 0 | K9: =G9+J9 -> 0 | M9: =M8+K9-L9 -> 0
A10: 7 | B10: 46272 | G10: =E10*F10 -> 0 | J10: =H10*I10 -> 0 | K10: =G10+J10 -> 0 | M10: =M9+K10-L10 -> 0
A11: 8 | B11: 46273 | G11: =E11*F11 -> 0 | J11: =H11*I11 -> 0 | K11: =G11+J11 -> 0 | M11: =M10+K11-L11 -> 0
A12: 9 | B12: 46274 | G12: =E12*F12 -> 0 | J12: =H12*I12 -> 0 | K12: =G12+J12 -> 0 | M12: =M11+K12-L12 -> 0
A13: 10 | B13: 46275 | G13: =E13*F13 -> 0 | J13: =H13*I13 -> 0 | K13: =G13+J13 -> 0 | M13: =M12+K13-L13 -> 0
A14: 11 | B14: 46276 | G14: =E14*F14 -> 0 | J14: =H14*I14 -> 0 | K14: =G14+J14 -> 0 | M14: =M13+K14-L14 -> 0
A15: 12 | B15: 46277 | G15: =E15*F15 -> 0 | J15: =H15*I15 -> 0 | K15: =G15+J15 -> 0 | M15: =M14+K15-L15 -> 0
... A32: 29 | B32: 46294 | G32: =E32*F32 -> 0 | J32: =H32*I32 -> 0 | K32: =G32+J32 -> 0 | M32: =M31+K32-L32 -> 0
A33: 30 | B33: 46295 | G33: =E33*F33 -> 0 | J33: =H33*I33 -> 0 | K33: =G33+J33 -> 0 | L33: 0 | M33: =M32+K33-L33 -> 0
A34: 31 | G34: =E34*F34 -> 0 | J34: =H34*I34 -> 0 | K34: =G34+J34 -> 0 | L34: 0 | M34: =M33+K34-L34 -> 0
E35: =SUM(E4:E34) -> 0 | G35: =SUM(G4:G34) -> 0 | H35: =SUM(H4:H34) -> 0 | J35: =SUM(J4:J34) -> 0 | K35: =SUM(K4:K34) -> 0 | L35: =SUM(L4:L34) -> 0

Sheet  Sangareddy-3
A1: SHIVA PARVATHI FILLING STATION SADASHIVPET
A2: S.No | B2: Date | C2: GRN No | D2: Ind no/Bill No | E2: Diesel (Lts) | F2: Price | G2: Amount | H2: Petrol (Lts) | I2: Price | J2: Amount | K2: Total amount | L2: Amount paid | M2: As on Date | N2: Remarks
A3: Opening Balance | M3: 366809.49
A4: 1 | B4: 46296 | E4: 690 | F4: 104.35 | G4: =E4*F4 -> 72001.5 | J4: =H4*I4 -> 0 | K4: =G4+J4 -> 72001.5 | M4: =M3+K4-L4 -> 438810.99
A5: 2 | B5: 46297 | G5: =E5*F5 -> 0 | J5: =H5*I5 -> 0 | K5: =G5+J5 -> 0 | M5: =M4+K5-L5 -> 438810.99
A6: 3 | B6: 46298 | E6: 690 | F6: 104.35 | G6: =E6*F6 -> 72001.5 | J6: =H6*I6 -> 0 | K6: =G6+J6 -> 72001.5 | M6: =M5+K6-L6 -> 510812.49
A7: 4 | B7: 46299 | G7: =E7*F7 -> 0 | J7: =H7*I7 -> 0 | K7: =G7+J7 -> 0 | M7: =M6+K7-L7 -> 510812.49
A8: 5 | B8: 46300 | E8: 690 | F8: 104.35 | G8: =E8*F8 -> 72001.5 | H8: 20 | I8: 116.25 | J8: =H8*I8 -> 2325 | K8: =G8+J8 -> 74326.5 | M8: =M7+K8-L8 -> 585138.99
A9: 6 | B9: 46301 | G9: =E9*F9 -> 0 | J9: =H9*I9 -> 0 | K9: =G9+J9 -> 0 | M9: =M8+K9-L9 -> 585138.99
A10: 7 | B10: 46302 | E10: 690 | F10: 104.35 | G10: =E10*F10 -> 72001.5 | J10: =H10*I10 -> 0 | K10: =G10+J10 -> 72001.5 | M10: =M9+K10-L10 -> 657140.49
A11: 8 | B11: 46303 | G11: =E11*F11 -> 0 | J11: =H11*I11 -> 0 | K11: =G11+J11 -> 0 | M11: =M10+K11-L11 -> 657140.49
A12: 9 | B12: 46304 | E12: 690 | F12: 104.35 | G12: =E12*F12 -> 72001.5 | J12: =H12*I12 -> 0 | K12: =G12+J12 -> 72001.5 | M12: =M11+K12-L12 -> 729141.99
A13: 10 | B13: 46305 | E13: 690 | F13: 104.35 | G13: =E13*F13 -> 72001.5 | J13: =H13*I13 -> 0 | K13: =G13+J13 -> 72001.5 | M13: =M12+K13-L13 -> 801143.49
A14: 11 | B14: 46306 | G14: =E14*F14 -> 0 | J14: =H14*I14 -> 0 | K14: =G14+J14 -> 0 | M14: =M13+K14-L14 -> 801143.49
A15: 12 | B15: 46307 | G15: =E15*F15 -> 0 | K15: =G15+J15 -> 0 | M15: =M14+K15-L15 -> 801143.49
A16: 13 | B16: 46308 | E16: 690 | F16: 104.35 | G16: =E16*F16 -> 72001.5 | H16: 20 | I16: 116.25 | J16: =H16*I16 -> 2325 | K16: =G16+J16 -> 74326.5 | M16: =M15+K16-L16 -> 875469.99
A17: 14 | B17: 46309 | G17: =E17*F17 -> 0 | J17: =H17*I17 -> 0 | K17: =G17+J17 -> 0 | M17: =M16+K17-L17 -> 875469.99
A18: 15 | B18: 46310 | E18: 690 | F18: 104.35 | G18: =E18*F18 -> 72001.5 | H18: 20 | I18: 116.25 | J18: =H18*I18 -> 2325 | K18: =G18+J18 -> 74326.5 | M18: =M17+K18-L18 -> 949796.49
A19: 16 | B19: 46311 | G19: =E19*F19 -> 0 | J19: =H19*I19 -> 0 | K19: =G19+J19 -> 0 | M19: =M18+K19-L19 -> 949796.49
A20: 17 | B20: 46312 | G20: =E20*F20 -> 0 | J20: =H20*I20 -> 0 | K20: =G20+J20 -> 0 | M20: =M19+K20-L20 -> 949796.49
A21: 18 | B21: 46313 | G21: =E21*F21 -> 0 | J21: =H21*I21 -> 0 | K21: =G21+J21 -> 0 | M21: =M20+K21-L21 -> 949796.49
A22: 19 | B22: 46314 | G22: =E22*F22 -> 0 | J22: =H22*I22 -> 0 | K22: =G22+J22 -> 0 | M22: =M21+K22-L22 -> 949796.49
A23: 20 | B23: 46315 | G23: =E23*F23 -> 0 | J23: =H23*I23 -> 0 | K23: =G23+J23 -> 0 | M23: =M22+K23-L23 -> 949796.49
A24: 21 | B24: 46316 | G24: =E24*F24 -> 0 | J24: =H24*I24 -> 0 | K24: =G24+J24 -> 0 | M24: =M23+K24-L24 -> 949796.49
A25: 22 | B25: 46317 | G25: =E25*F25 -> 0 | J25: =H25*I25 -> 0 | K25: =G25+J25 -> 0 | M25: =M24+K25-L25 -> 949796.49
A26: 23 | B26: 46318 | G26: =E26*F26 -> 0 | J26: =H26*I26 -> 0 | K26: =G26+J26 -> 0 | M26: =M25+K26-L26 -> 949796.49
A27: 24 | B27: 46319 | G27: =E27*F27 -> 0 | J27: =H27*I27 -> 0 | K27: =G27+J27 -> 0 | M27: =M26+K27-L27 -> 949796.49
A28: 25 | B28: 46320 | G28: =E28*F28 -> 0 | J28: =H28*I28 -> 0 | K28: =G28+J28 -> 0 | M28: =M27+K28-L28 -> 949796.49
A29: 26 | B29: 46321 | G29: =E29*F29 -> 0 | J29: =H29*I29 -> 0 | K29: =G29+J29 -> 0 | M29: =M28+K29-L29 -> 949796.49
A30: 27 | B30: 46322 | G30: =E30*F30 -> 0 | J30: =H30*I30 -> 0 | K30: =G30+J30 -> 0 | M30: =M29+K30-L30 -> 949796.49
... A34: 31 | B34: 46326 | G34: =E34*F34 -> 0 | J34: =H34*I34 -> 0 | K34: =G34+J34 -> 0 | M34: =M33+K34-L34 -> 949796.49
A35: 32 | G35: =E35*F35 -> 0 | J35: =H35*I35 -> 0 | K35: =G35+J35 -> 0 | M35: =M34+K35-L35 -> 949796.49
E36: =SUM(E4:E35) -> 5520 | G36: =SUM(G4:G35) -> 576012 | H36: =SUM(H4:H35) -> 60 | J36: =SUM(J4:J35) -> 6975 | K36: =SUM(K4:K35) -> 582987 | L36: =SUM(L4:L35) -> 0

Sheet Narayankhed
A2: S.No | B2: Date | C2: GRN No | D2: Ind no/Bill No | E2: Diesel (Lts) | F2: Price | G2: Amount | H2: Petrol (Lts) | I2: Price | J2: Amount | K2: Total amount | L2: Amount paid | M2: As on Date | N2: Remarks
A3: Opening Balance
A4: 1 | B4: 46296 | E4: 285.39 | F4: 105.12 | G4: =E4*F4 -> 30000.197 | J4: =H4*I4 -> 0 | K4: =G4+J4 -> 30000.197 | L4: 30000.197 | M4: =M3+K4-L4 -> 0 | N4: BPCL
A5: 2 | B5: 46297 | G5: =E5*F5 -> 0 | J5: =H5*I5 -> 0 | K5: =G5+J5 -> 0 | M5: =M4+K5-L5 -> 0
A6: 3 | B6: 46298 | G6: =E6*F6 -> 0 | J6: =H6*I6 -> 0 | K6: =G6+J6 -> 0 | M6: =M5+K6-L6 -> 0
A7: 4 | B7: 46299 | G7: =E7*F7 -> 0 | J7: =H7*I7 -> 0 | K7: =G7+J7 -> 0 | M7: =M6+K7-L7 -> 0
A8: 5 | B8: 46300 | E8: 285.39 | F8: 105.12 | G8: =E8*F8 -> 30000.197 | J8: =H8*I8 -> 0 | K8: =G8+J8 -> 30000.197 | L8: 30000.197 | M8: =M7+K8-L8 -> 0 | N8: BPCL
A9: 6 | B9: 46301 | E9: 285.63 | F9: 105.03 | G9: =E9*F9 -> 29999.719 | J9: =H9*I9 -> 0 | K9: =G9+J9 -> 29999.719 | L9: =H9+K9 -> 29999.719 | M9: =M8+K9-L9 -> 0 | N9: BPCL
A10: 7 | B10: 46302 | E10: 95.13 | F10: 105.12 | G10: =E10*F10 -> 10000.066 | J10: =H10*I10 -> 0 | K10: =G10+J10 -> 10000.066 | L10: 10000.066 | M10: =M9+K10-L10 -> 0 | N10: BPCL
B11: 46302 | E11: 95.211 | F11: 105.03 | G11: =E11*F11 -> 10000.011 | K11: =G11+J11 -> 10000.011 | L11: 10000.011 | M11: =M10+K11-L11 -> 0 | N11: HPCL
A12: 8 | B12: 46303 | G12: =E12*F12 -> 0 | J12: =H12*I12 -> 0 | K12: =G12+J12 -> 0 | M12: =M10+K12-L12 -> 0
A13: 9 | B13: 46304 | E13: 285.39 | F13: 105.12 | G13: =E13*F13 -> 30000.197 | J13: =H13*I13 -> 0 | K13: =G13+J13 -> 30000.197 | L13: 30000.197 | M13: =M12+K13-L13 -> 0 | N13: BPCL
A14: 10 | B14: 46305 | G14: =E14*F14 -> 0 | J14: =H14*I14 -> 0 | K14: =G14+J14 -> 0 | M14: =M13+K14-L14 -> 0
A15: 11 | B15: 46306 | G15: =E15*F15 -> 0 | J15: =H15*I15 -> 0 | K15: =G15+J15 -> 0 | M15: =M14+K15-L15 -> 0
A16: 12 | B16: 46307 | G16: =E16*F16 -> 0 | J16: =H16*I16 -> 0 | K16: =G16+J16 -> 0 | M16: =M15+K16-L16 -> 0
A17: 13 | B17: 46308 | G17: =E17*F17 -> 0 | J17: =H17*I17 -> 0 | K17: =G17+J17 -> 0 | M17: =M16+K17-L17 -> 0
A18: 14 | B18: 46309 | E18: 190.42 | F18: 105.03 | G18: =E18*F18 -> 19999.813 | J18: =H18*I18 -> 0 | K18: =G18+J18 -> 19999.813 | L18: 19999.813 | M18: =M17+K18-L18 -> 0
A19: 15 | B19: 46310 | G19: =E19*F19 -> 0 | J19: =H19*I19 -> 0 | K19: =G19+J19 -> 0 | M19: =M18+K19-L19 -> 0
A20: 16 | B20: 46311 | G20: =E20*F20 -> 0 | J20: =H20*I20 -> 0 | K20: =G20+J20 -> 0 | M20: =M19+K20-L20 -> 0
A21: 17 | B21: 46312 | G21: =E21*F21 -> 0 | J21: =H21*I21 -> 0 | K21: =G21+J21 -> 0 | M21: =M20+K21-L21 -> 0
A22: 18 | B22: 46313 | G22: =E22*F22 -> 0 | J22: =H22*I22 -> 0 | K22: =G22+J22 -> 0 | M22: =M21+K22-L22 -> 0
A23: 19 | B23: 46314 | G23: =E23*F23 -> 0 | J23: =H23*I23 -> 0 | K23: =G23+J23 -> 0 | M23: =M22+K23-L23 -> 0
A24: 20 | B24: 46315 | G24: =E24*F24 -> 0 | J24: =H24*I24 -> 0 | K24: =G24+J24 -> 0 | M24: =M23+K24-L24 -> 0
A25: 21 | B25: 46316 | G25: =E25*F25 -> 0 | J25: =H25*I25 -> 0 | K25: =G25+J25 -> 0 | M25: =M24+K25-L25 -> 0
A26: 22 | B26: 46317 | G26: =E26*F26 -> 0 | J26: =H26*I26 -> 0 | K26: =G26+J26 -> 0 | M26: =M25+K26-L26 -> 0
A27: 23 | B27: 46318 | G27: =E27*F27 -> 0 | J27: =H27*I27 -> 0 | K27: =G27+J27 -> 0 | M27: =M26+K27-L27 -> 0
A28: 24 | B28: 46319 | G28: =E28*F28 -> 0 | J28: =H28*I28 -> 0 | K28: =G28+J28 -> 0 | M28: =M27+K28-L28 -> 0
A29: 25 | B29: 46320 | G29: =E29*F29 -> 0 | J29: =H29*I29 -> 0 | K29: =G29+J29 -> 0 | M29: =M28+K29-L29 -> 0
A30: 26 | B30: 46321 | G30: =E30*F30 -> 0 | J30: =H30*I30 -> 0 | K30: =G30+J30 -> 0 | M30: =M29+K30-L30 -> 0
... A34: 30 | B34: 46325 | G34: =E34*F34 -> 0 | J34: =H34*I34 -> 0 | K34: =G34+J34 -> 0 | M34: =M33+K34-L34 -> 0
A35: 31 | B35: 46326 | G35: =E35*F35 -> 0 | J35: =H35*I35 -> 0 | K35: =G35+J35 -> 0 | M35: 0
E36: =SUM(E4:E35) -> 1522.561 | G36: =SUM(G4:G35) -> 160000.2 | H36: =SUM(H4:H35) -> 0 | J36: =SUM(J4:J35) -> 0 | K36: =SUM(K4:K35) -> 160000.2 | L36: =SUM(L4:L35) -> 160000.2

Sheet Dindi
A1: Akarapu Balakistamma Fillling
A2: S.No | B2: Date | C2: GRN No | D2: Ind no/Bill No | E2: Diesel (Lts) | F2: Price | G2: Amount | H2: Petrol (Lts) | I2: Price | J2: Amount | K2: Total amount | L2: Amount paid | M2: As on Date | N2: Remarks
A3: Opening Balance | M3: 0
A4: 1 | B4: 45931 | G4: =E4*F4 -> 0 | J4: =H4*I4 -> 0 | K4: =G4+J4 -> 0 | L4: =+K4 -> 0 | M4: 0
A5: 2 | B5: 45932 | G5: =E5*F5 -> 0 | J5: =H5*I5 -> 0 | K5: =G5+J5 -> 0 | L5: =+K5 -> 0 | M5: 0
A6: 3 | B6: 45933 | E6: 28.59 | F6: 104.95 | G6: =E6*F6 -> 3000.5205 | J6: =H6*I6 -> 0 | K6: =G6+J6 -> 3000.5205 | L6: =+K6 -> 3000.5205 | M6: 0
A7: 4 | B7: 45934 | G7: =E7*F7 -> 0 | J7: =H7*I7 -> 0 | K7: =G7+J7 -> 0 | L7: =+K7 -> 0 | M7: 0
A8: 5 | B8: 45935 | G8: =E8*F8 -> 0 | J8: =H8*I8 -> 0 | K8: =G8+J8 -> 0 | L8: =+K8 -> 0 | M8: 0
A9: 6 | B9: 45936 | G9: =E9*F9 -> 0 | J9: =H9*I9 -> 0 | K9: =G9+J9 -> 0 | L9: =+K9 -> 0 | M9: 0
A10: 7 | B10: 45937 | G10: =E10*F10 -> 0 | J10: =H10*I10 -> 0 | K10: =G10+J10 -> 0 | L10: =+K10 -> 0 | M10: 0
A11: 8 | B11: 45938 | G11: =E11*F11 -> 0 | J11: =H11*I11 -> 0 | K11: =G11+J11 -> 0 | L11: =+K11 -> 0 | M11: 0
A12: 9 | B12: 45939 | G12: =E12*F12 -> 0 | J12: =H12*I12 -> 0 | K12: =G12+J12 -> 0 | L12: =+K12 -> 0 | M12: 0
A13: 10 | B13: 45940 | G13: =E13*F13 -> 0 | J13: =H13*I13 -> 0 | K13: =G13+J13 -> 0 | L13: =+K13 -> 0 | M13: 0
A14: 11 | B14: 45941 | G14: =E14*F14 -> 0 | J14: =H14*I14 -> 0 | K14: =G14+J14 -> 0 | L14: =+K14 -> 0 | M14: 0
A15: 12 | B15: 45942 | G15: =E15*F15 -> 0 | J15: =H15*I15 -> 0 | K15: =G15+J15 -> 0 | L15: =+K15 -> 0 | M15: 0
A16: 13 | B16: 45943 | G16: =E16*F16 -> 0 | J16: =H16*I16 -> 0 | K16: =G16+J16 -> 0 | L16: =+K16 -> 0 | M16: 0
A17: 14 | B17: 45944 | G17: =E17*F17 -> 0 | J17: =H17*I17 -> 0 | K17: =G17+J17 -> 0 | L17: =+K17 -> 0 | M17: 0
A18: 15 | B18: 45945 | E18: 38.93 | F18: 104.95 | G18: =E18*F18 -> 4085.7035 | J18: =H18*I18 -> 0 | K18: =G18+J18 -> 4085.7035 | L18: =+K18 -> 4085.7035 | M18: 0
A19: 16 | B19: 45946 | G19: =E19*F19 -> 0 | J19: =H19*I19 -> 0 | K19: =G19+J19 -> 0 | L19: =+K19 -> 0 | M19: 0
A20: 17 | B20: 45947 | G20: =E20*F20 -> 0 | J20: =H20*I20 -> 0 | K20: =G20+J20 -> 0 | L20: =+K20 -> 0 | M20: 0
A21: 18 | B21: 45948 | G21: =E21*F21 -> 0 | J21: =H21*I21 -> 0 | K21: =G21+J21 -> 0 | L21: =+K21 -> 0 | M21: 0
A22: 19 | B22: 45949 | G22: =E22*F22 -> 0 | J22: =H22*I22 -> 0 | K22: =G22+J22 -> 0 | L22: =+K22 -> 0 | M22: 0
A23: 20 | B23: 45950 | G23: =E23*F23 -> 0 | J23: =H23*I23 -> 0 | K23: =G23+J23 -> 0 | L23: =+K23 -> 0 | M23: 0
A24: 21 | B24: 45951 | G24: =E24*F24 -> 0 | J24: =H24*I24 -> 0 | K24: =G24+J24 -> 0 | L24: =+K24 -> 0 | M24: 0
A25: 22 | B25: 45952 | G25: =E25*F25 -> 0 | J25: =H25*I25 -> 0 | K25: =G25+J25 -> 0 | L25: =+K25 -> 0 | M25: 0
A26: 23 | B26: 45953 | G26: =E26*F26 -> 0 | J26: =H26*I26 -> 0 | K26: =G26+J26 -> 0 | L26: =+K26 -> 0 | M26: 0
A27: 24 | B27: 45954 | G27: =E27*F27 -> 0 | J27: =H27*I27 -> 0 | K27: =G27+J27 -> 0 | L27: =+K27 -> 0 | M27: 0
A28: 25 | B28: 45955 | G28: =E28*F28 -> 0 | J28: =H28*I28 -> 0 | K28: =G28+J28 -> 0 | L28: =+K28 -> 0 | M28: 0
A29: 26 | B29: 45956 | G29: =E29*F29 -> 0 | J29: =H29*I29 -> 0 | K29: =G29+J29 -> 0 | L29: =+K29 -> 0 | M29: 0
A30: 27 | B30: 45957 | G30: =E30*F30 -> 0 | J30: =H30*I30 -> 0 | K30: =G30+J30 -> 0 | L30: =+K30 -> 0 | M30: 0
... A34: 31 | B34: 45961 | G34: =E34*F34 -> 0 | J34: =H34*I34 -> 0 | K34: =G34+J34 -> 0 | L34: =+K34 -> 0 | M34: 0
E35: =SUM(E4:E34) -> 67.52 | G35: =SUM(G4:G34) -> 7086.224 | H35: =SUM(H4:H34) -> 0 | J35: =SUM(J4:J34) -> 0 | K35: =SUM(K4:K34) -> 7086.224 | L35: =SUM(L4:L34) -> 7086.224

Sheet Multiple bunks(KKD)
A2: S.No | B2: Date | C2: GRN No | D2: Ind no/Bill No | E2: Diesel (Lts) | F2: Price | G2: Amount | H2: Petrol (Lts) | I2: Price | J2: Amount | K2: Total amount | L2: Amount paid | M2: As on Date | N2: Remarks
A3: Opening Balance
A4: 1 | G4: =E4*F4 -> 0 | J4: =H4*I4 -> 0 | K4: =G4+J4 -> 0 | L4: =+K4 -> 0
A5: 2 | G5: =E5*F5 -> 0 | J5: =H5*I5 -> 0 | K5: =G5+J5 -> 0 | L5: =+K5 -> 0
A6: 3 | G6: =E6*F6 -> 0 | J6: =H6*I6 -> 0 | K6: =G6+J6 -> 0 | L6: =+K6 -> 0
A7: 4 | G7: =E7*F7 -> 0 | J7: =H7*I7 -> 0 | K7: =G7+J7 -> 0 | L7: =+K7 -> 0
A8: 5 | G8: =E8*F8 -> 0 | J8: =H8*I8 -> 0 | K8: =G8+J8 -> 0 | L8: =+K8 -> 0
A9: 6 | G9: =E9*F9 -> 0 | J9: =H9*I9 -> 0 | K9: =G9+J9 -> 0 | L9: =+K9 -> 0
