Workbook

Sheet Dec-25 
A1: S.no | B1: Site Name | C1: Bunk Name | D1: Diesel(Liters) | E1: Diesel Amount | F1: Petrol(Liters) | G1: Petrol Amount | H1: Total Amount | I1: Opening Blance | J1: Amount Paid | K1: Closing Balances
A2: 1 | B2: Khammam-1 | C2: Divya laxmi ganapathi | D2: =+'Khammam-1'!E38 -> 83600 | E2: =+'Khammam-1'!G38 -> 7998848 | F2: =+'Khammam-1'!H38 -> 335 | G2: =+'Khammam-1'!J38 -> 35999.1 | H2: =E2+G2 -> 8034847.1 | I2: =+'Khammam-1'!K3 -> 4574619.2 | J2: =+'Khammam-1'!L38 -> 8653305 | K2: =H2+I2-J2 -> 3956161.3
A3: 2 | B3: Khammam-2 | C3: Jayasai union bunk | D3: =+'Khammam-2'!E35 -> 38100 | E3: =+'Khammam-2'!G35 -> 3646170 | F3: =+'Khammam-2'!H35 -> 220 | G3: =+'Khammam-2'!J35 -> 23645.6 | H3: =E3+G3 -> 3669815.6 | I3: =+'Khammam-2'!K3 -> 9561944.8 | J3: =+'Khammam-2'!L35 -> 9561944.8 | K3: =H3+I3-J3 -> 3669815.6
A4: 3 | B4: Jadcherla-1 | C4: Sai Baba Fuel Station | D4: =+'Jadcherla -1'!E36 -> 0 | E4: =+'Jadcherla -1'!G36 -> 0 | F4: =+'Jadcherla -1'!H36 -> 142.19791 | G4: =+'Jadcherla -1'!J36 -> 15390.08 | H4: =E4+G4 -> 15390.08 | I4: =+'Jadcherla -1'!M3 -> 801890.2 | J4: =+'Jadcherla -1'!L36 -> 817280.28 | K4: =H4+I4-J4 -> -0.0044004744
A5: 4 | B5: Jadcherla-2 | C5: ADHOC FILLING STATION STATION | D5: =+'Jadcharla-2'!E35 -> 0 | E5: =+'Jadcharla-2'!G35 -> 0 | F5: =+'Jadcharla-2'!H35 -> 0 | G5: =+'Jadcharla-2'!J35 -> 0 | H5: =E5+G5 -> 0 | I5: =+'Jadcharla-2'!K3 -> 1123622.9 | J5: =+'Jadcharla-2'!L35 -> 1123622.9 | K5: =H5+I5-J5 -> 0
A6: 5 | B6: Jadcherla-3 | C6: JSASFuel Genie India Pvt.Ltd | D6: =+'Jadcherla-3'!E35 -> 22000 | E6: =+'Jadcherla-3'!G35 -> 2099460 | F6: =+'Jadcherla-3'!H35 -> 0 | G6: =+'Jadcherla-3'!J35 -> 0 | H6: =E6+G6 -> 2099460 | I6: =+'Jadcherla-3'!M3 -> 1839042.5 | J6: =+'Jadcherla-3'!L35 -> 2755171 | K6: =H6+I6-J6 -> 1183331.5
A7: 6 | B7: Jadcherla-4 | C7: Shree Poornima F/S | D7: =+'Jadcherla-4'!E35 -> 0 | E7: =+'Jadcherla-4'!G35 -> 0 | F7: =+'Jadcherla-4'!H35 -> 50 | G7: =+'Jadcherla-4'!J35 -> 5405 | H7: =E7+G7 -> 5405 | I7: =+'Jadcherla-4'!M3 -> 0 | J7: =+'Jadcherla-4'!L35 -> 0 | K7: =H7+I7-J7 -> 5405
A8: 7 | B8: Dindi | C8: Akarapu Balakistamma Fillling | D8: =+Dindi!E35 -> 115.95 | E8: =+Dindi!G35 -> 11188.886 | F8: =+Dindi!H35 -> 0 | G8: =+Dindi!J35 -> 0 | H8: =E8+G8 -> 11188.886 | I8: =+Dindi!M3 -> 0 | J8: =+Dindi!L35 -> 11188.886 | K8: =H8+I8-J8 -> 0
A9: 8 | B9: Devarkhadra-1 | C9: Kurumurthy Swami F/S | D9: =+Devarakhadra!E35 -> 239.68 | E9: =+Devarakhadra!G35 -> 23272.928 | F9: =+Devarakhadra!H35 -> 25 | G9: =+Devarakhadra!J35 -> 2715.95 | H9: =E9+G9 -> 25988.878 | I9: =+Devarakhadra!M3 -> 34600.433 | J9: =+Devarakhadra!L35 -> 55563 | K9: =H9+I9-J9 -> 5026.311
A10: 9 | B10: Devarkhadra-3 | C10: JSASFuel Genie India Pvt.Ltd | D10: =+'Devarakhadra-2'!E35 -> 0 | E10: =+'Devarakhadra-2'!G35 -> 0 | F10: =+'Devarakhadra-2'!H35 -> 0 | G10: =+'Devarakhadra-2'!I35 -> 0 | H10: =E10+G10 -> 0 | I10: =+'Devarakhadra-2'!M3 -> 66053.768 | J10: =+'Devarakhadra-2'!L35 -> 66053.77 | K10: =+'Devarakhadra-2'!M34 -> -0.0015
A11: 10 | B11: Madanapalli | D11: =+'Madana palli'!E35 -> 600 | E11: =+'Madana palli'!G35 -> 58656 | F11: =+'Madana palli'!H35 -> 10.03 | G11: =+'Madana palli'!J35 -> 1099.3883 | H11: =E11+G11 -> 59755.388 | I11: =+'Madana palli'!M3 -> 0 | J11: =+'Madana palli'!L35 -> 59755.388 | K11: =+'Devarakhadra-2'!M35 -> 0
A12: 11 | B12: Amalapuram | C12: Sathya Filling Station | D12: =+Amalapuram!E37 -> 258.89 | E12: =+Amalapuram!G37 -> 23815.919 | F12: =+Amalapuram!H37 -> 35 | G12: =+Amalapuram!J37 -> 3813.9654 | H12: =E12+G12 -> 27629.884 | I12: =+Amalapuram!M3 -> 0 | J12: =+Amalapuram!L37 -> 27629.87 | K12: =H12+I12-J12 -> 0.014
A13: 12 | B13: YG Gudda-1 | C13: Pallavi Petrolium | D13: =+'YG Gudda '!E36 -> 0 | E13: =+'YG Gudda '!G36 -> 0 | F13: =+'YG Gudda '!H36 -> 0 | G13: =+'YG Gudda '!J36 -> 0 | H13: =E13+G13 -> 0 | I13: ='YG Gudda '!K3 -> 25021.542 | J13: =+'YG Gudda '!L36 -> 25021.54 | K13: =H13+I13-J13 -> 0.0015138002
A14: 13 | B14: YG Gudda-2 | C14: Pankaja HP Fuel Center | D14: =+'YG Gudda-2'!E36 -> 10328.479 | E14: =+'YG Gudda-2'!G36 -> 943300 | F14: =+'YG Gudda-2'!H36 -> 490 | G14: =+'YG Gudda-2'!J36 -> 50602.3 | H14: =E14+G14 -> 993902.3 | I14: =+'YG Gudda-2'!M3 -> 340400.91 | J14: =+'YG Gudda-2'!L36 -> 620413 | K14: =H14+I14-J14 -> 713890.2
A15: 14 | B15: Hosadurga-1 | C15: Merchant Petroliums | D15: =+Hosadurga!E35 -> 0 | E15: =+Hosadurga!G35 -> 0 | F15: =+Hosadurga!H35 -> 0 | G15: =+Hosadurga!J35 -> 0 | H15: =E15+G15 -> 0 | I15: =+Hosadurga!K3 -> 2258.6 | J15: =+Hosadurga!L35 -> 0 | K15: =H15+I15-J15 -> 2258.6
A16: 15 | B16: Hosadurga-2 | C16: Shree Veeraprathap Fuel | D16: =+'Hosadurga -2'!E35 -> 4000 | E16: =+'Hosadurga -2'!G35 -> 366080 | F16: =+'Hosadurga -2'!H35 -> 280 | G16: =+'Hosadurga -2'!J35 -> 29027.6 | H16: =+'Hosadurga -2'!K35 -> 395107.6 | I16: =+'Hosadurga -2'!K3 -> 354228.04 | J16: =+'Hosadurga -2'!L35 -> 551781.84 | K16: =H16+I16-J16 -> 197553.8
A17: 16 | B17: Malebennuru(KUWSDB) | C17: Sri Ramanjuneya Service Station | D17: =+'Malebenur(KUWSDB)'!E36 -> 6900 | E17: =+'Malebenur(KUWSDB)'!G36 -> 635766 | F17: =+'Malebenur(KUWSDB)'!H36 -> 255 | G17: =+'Malebenur(KUWSDB)'!J36 -> 26512.35 | H17: =E17+G17 -> 662278.35 | I17: =+'Malebenur(KUWSDB)'!K3 -> 151062.96 | J17: =+'Malebenur(KUWSDB)'!L36 -> 610983.95 | K17: =H17+I17-J17 -> 202357.35
A18: 17 | B18: kadur | C18: Vishal Service Station | D18: =+Kadur!E35 -> 2200 | E18: =+Kadur!G35 -> 202730 | F18: =+Kadur!H35 -> 180 | G18: =+Kadur!J35 -> 18768.6 | H18: =E18+G18 -> 221498.6 | I18: =+Kadur!K3 -> 164331.63 | J18: =+Kadur!L35 -> 175801 | K18: =H18+I18-J18 -> 210029.23
A19: 18 | B19: Hiriyur(VJNL) | C19: Sri Balaji Agencies | D19: =+'Hiriyur(VJNL)'!E35 -> 4600 | E19: =+'Hiriyur(VJNL)'!G35 -> 424258 | F19: =+'Hiriyur(VJNL)'!H35 -> 140 | G19: =+'Hiriyur(VJNL)'!J35 -> 14571.2 | H19: =E19+G19 -> 438829.2 | I19: =+'Hiriyur(VJNL)'!K3 -> 385911.6 | J19: =+'Hiriyur(VJNL)'!L35 -> 385912 | K19: =H19+I19-J19 -> 438828.8
A20: 19 | B20: Chellakere(KUWSDB) | C20: Shivaganga Service Station | D20: =+'Chellakere -1'!E35 -> 3270 | E20: =+'Chellakere -1'!G35 -> 301461.3 | F20: =+'Chellakere -1'!H35 -> 235 | G20: =+'Chellakere -1'!J35 -> 24449.4 | H20: =E20+G20 -> 325910.7 | I20: =+'Chellakere -1'!K3 -> 128004.75 | J20: =+'Chellakere -1'!L35 -> 308512.35 | K20: =H20+I20-J20 -> 145403.1
A21: 20 | B21: Chellakere(KUWSDB)-09 | D21: =+' Chellakere-PKG-9'!E35 -> 939.66 | E21: =+' Chellakere-PKG-9'!G35 -> 86629.505 | F21: =+' Chellakere-PKG-9'!H35 -> 80.58 | G21: =+' Chellakere-PKG-9'!J35 -> 8382.7374 | H21: =E21+G21 -> 95012.243 | I21: =+' Chellakere-PKG-9'!M3 -> 0 | J21: =+' Chellakere-PKG-9'!L35 -> 95012.243 | K21: =H21+I21-J21 -> 0
A22: 21 | B22: Molakalmuru | C22: Sri Lakshmi Venkateshwara Filling Station | D22: =+Molakamuru!E35 -> 1414.99 | E22: =+Molakamuru!G35 -> 130431.03 | F22: =+Molakamuru!H35 -> 50.012 | G22: =+Molakamuru!J35 -> 5202.2482 | H22: =E22+G22 -> 135633.28 | I22: =+Molakamuru!K3 -> 0 | J22: =+Molakamuru!L35 -> 82044.777 | K22: =H22+I22-J22 -> 53588.5
A23: 22 | B23: Chennagiri | D23: =+' Chennagiri'!E35 -> 685 | E23: =+' Chennagiri'!G35 -> 63034.95 | F23: =+' Chennagiri'!H35 -> 49 | G23: =+' Chennagiri'!J35 -> 5099.92 | H23: =E23+G23 -> 68134.87 | I23: =+' Chennagiri'!K3 -> 0 | J23: =+' Chennagiri'!L35 -> 68134.87 | K23: =H23+I23-J23 -> 0
A24: 23 | B24: Khanapur(PKG-3) | C24: V.V.Varde | D24: =+Khanapur!E35 -> 1226.17 | E24: =+Khanapur!G35 -> 111434.33 | F24: =+Khanapur!H35 -> 83 | G24: =+Khanapur!J35 -> 8529.91 | H24: =E24+G24 -> 119964.24 | I24: =+Khanapur!M3 -> 29018.261 | J24: =+Khanapur!L35 -> 50000 | K24: =H24+I24-J24 -> 98982.5
A25: 24 | B25: Munavalli(PKG-3)-2 | C25: Shri Daneshwari | D25: =+'Munavali-2'!E37 -> 8154.25 | E25: =+'Munavali-2'!G37 -> 744736.99 | F25: =+'Munavali-2'!H37 -> 189.71 | G25: =+'Munavali-2'!J37 -> 19605.804 | H25: =E25+G25 -> 764342.8 | I25: =+'Munavali-2'!M3 -> 554212.7 | J25: =+'Munavali-2'!L37 -> 658024.7 | K25: =H25+I25-J25 -> 660530.8
A26: 25 | B26: Borgaon(PKG-3) | C26: Aadisagar Petrolium | D26: =+Borgaon!E35 -> 6077.86 | E26: =+Borgaon!G35 -> 557765.21 | F26: =+Borgaon!H35 -> 70 | G26: =+Borgaon!J35 -> 7259 | H26: =E26+G26 -> 565024.21 | I26: =+Borgaon!K3 -> 67414.901 | J26: =+Borgaon!L35 -> 512043.3 | K26: =H26+I26-J26 -> 120395.81
A27: 26 | B27: Ugar,Kudichi(PKG-3) | C27: Shiri Bhrhmanath Petrolium | D27: =+'Ugar,Khagwad,Kudichi'!E35 -> 5246.45 | E27: =+'Ugar,Khagwad,Kudichi'!G35 -> 482306.15 | F27: =+'Ugar,Khagwad,Kudichi'!H35 -> 279.98 | G27: =+'Ugar,Khagwad,Kudichi'!J35 -> 29123.972 | H27: =E27+G27 -> 511430.12 | I27: =+'Ugar,Khagwad,Kudichi'!M3 -> 394249.74 | J27: =+'Ugar,Khagwad,Kudichi'!L35 -> 613314 | K27: =H27+I27-J27 -> 292365.86
A28: 27 | B28: Kabbur(PKG-3) | C28: Shri Jai Hanuman Petrolium | D28: =+Kabbur!E35 -> 240 | E28: =+Kabbur!G35 -> 21981.6 | F28: =+Kabbur!H35 -> 25.58 | G28: =+Kabbur!J35 -> 2648.2974 | H28: =E28+G28 -> 24629.897 | I28: 0 | J28: =+Kabbur!L35 -> 24629.897 | K28: =H28+I28-J28 -> 0
A29: 28 | B29: Kumta (PKG-1) | C29: Krishma fuel station | D29: =+kumta!E35 -> 2073.27 | E29: =+kumta!G35 -> 190574.98 | F29: =+kumta!H35 -> 121.24 | G29: =+kumta!J35 -> 12604.11 | H29: =E29+G29 -> 203179.09 | I29: 0 | J29: =+kumta!L35 -> 203179.09 | K29: =H29+I29-J29 -> 0
A30: 29 | B30: Jalgaon | C30: Sri Sai Petrol Pump | D30: =+Jalgaon!E54 -> 13809.45 | E30: =+Jalgaon!G54 -> 1266325.5 | F30: =+Jalgaon!H54 -> 242 | G30: =+Jalgaon!J54 -> 25455.98 | H30: =E30+G30 -> 1291781.5 | I30: =+Jalgaon!K3 -> 1148460.8 | J30: =+Jalgaon!L54 -> 1709938.5 | K30: =H30+I30-J30 -> 730303.78
A31: 30 | B31: MKBD | C31: Shree Sai Samarth Petroleum | D31: =+MKBD!E38 -> 4100 | E31: =+MKBD!G38 -> 373674 | F31: =+MKBD!H38 -> 101 | G31: =+MKBD!J38 -> 12871.9 | H31: =E31+G31 -> 386545.9 | I31: =+MKBD!K3 -> 437930.65 | J31: =+MKBD!L38 -> 461912.77 | K31: =H31+I31-J31 -> 362563.78
A32: 31 | B32: Haveri | C32: Shivalingeshwar Petroleum | D32: =+Haveri!E37 -> 100 | E32: =+Haveri!G37 -> 9147 | F32: =+Haveri!H37 -> 0 | G32: =+Haveri!J37 -> 0 | H32: =E32+G32 -> 9147 | I32: =+Haveri!M3 -> 225176.08 | J32: =+Haveri!L37 -> 224862 | K32: =H32+I32-J32 -> 9461.0769
A33: 32 | B33: Haveri | C33: M/s Magavi City Fuels | D33: =' Haveri-2'!E37 -> 3340.47 | E33: =' Haveri-2'!G37 -> 305619.6 | F33: =' Haveri-2'!H37 -> 140.56 | G33: =' Haveri-2'!J37 -> 14538.121 | H33: =E33+G33 -> 320157.72 | I33: =' Haveri-2'!M3 -> 0 | J33: =+' Haveri-2'!L37 -> 155714 | K33: =H33+I33-J33 -> 164443.72
A34: 33 | B34: Guttal | C34: Taware filling station | D34: =+Guttal!E35 -> 4725.6 | E34: =+Guttal!G35 -> 433810.08 | F34: =+Guttal!H35 -> 153 | G34: =+Guttal!J35 -> 15875.28 | H34: =E34+G34 -> 449685.36 | I34: =+Guttal!M3 -> 58502.01 | J34: =+Guttal!L35 -> 171500 | K34: =H34+I34-J34 -> 336687.37
A35: 34 | B35: Rattihali | C35: Shree Siri Gowari petroliam | D35: =+Rattihali!E35 -> 1507.83 | E35: =+Rattihali!G35 -> 138780.67 | F35: =+Rattihali!H35 -> 39 | G35: =+Rattihali!J35 -> 4056.78 | H35: =E35+G35 -> 142837.45 | I35: =+Rattihali!M3 -> 135998.27 | J35: =+Rattihali!L35 -> 272393 | K35: =H35+I35-J35 -> 6442.724
A36: 35 | B36: Rattihali-2 | C36: Shiva Oil Traders | D36: =+'Rattihali-2'!E37 -> 3253.25 | E36: =+'Rattihali-2'!G37 -> 298941.14 | F36: =+'Rattihali-2'!H37 -> 111 | G36: =+'Rattihali-2'!J37 -> 11939.16 | H36: =E36+G36 -> 310880.3 | I36: =+'Rattihali-2'!M3 -> 0 | J36: =+'Rattihali-2'!L37 -> 0 | K36: =H36+I36-J36 -> 310880.3
A37: 36 | B37: Gajendragada | C37: Vanasri Petrol Pump | D37: =+Gajendragada!E35 -> 18 | E37: =+Gajendragada!G35 -> 1652.94 | F37: =+Gajendragada!H35 -> 15 | G37: =+Gajendragada!J35 -> 1557 | H37: =E37+G37 -> 3209.94 | I37: =+Gajendragada!K3 -> 1290.2615 | J37: =+Gajendragada!L35 -> 0 | K37: =H37+I37-J37 -> 4500.2015
A38: 37 | B38: Gokak(PKG-3) | C38: AJ Petrolinks | D38: =+'Gokak Dharwad PKG 3'!E40 -> 10248.64 | E38: =+'Gokak Dharwad PKG 3'!G40 -> 937545.59 | F38: =+'Gokak Dharwad PKG 3'!H40 -> 277 | G38: =+'Gokak Dharwad PKG 3'!J40 -> 28644.57 | H38: =E38+G38 -> 966190.16 | I38: =+'Gokak Dharwad PKG 3'!K3 -> 619206.33 | J38: =+'Gokak Dharwad PKG 3'!L40 -> 1038037 | K38: =H38+I38-J38 -> 547359.48
A39: 38 | B39: Ankaligi | C39: Shiv ganga | D39: =+Ankalgi!E35 -> 4561.13 | E39: =+Ankalgi!G35 -> 416476.78 | F39: =+Ankalgi!H35 -> 150 | G39: =+Ankalgi!J35 -> 15484.5 | H39: =E39+G39 -> 431961.28 | I39: =+Ankalgi!M3 -> 109864.35 | J39: =+Ankalgi!L35 -> 361718.01 | K39: =H39+I39-J39 -> 180107.62
A40: 39 | B40: ShankeshWAR | C40: SR Patil | D40: =+' Shankeshwar'!E35 -> 730 | E40: =+' Shankeshwar'!G35 -> 66652.6 | F40: =+' Shankeshwar'!H35 -> 62 | G40: =+' Shankeshwar'!J35 -> 6399.64 | H40: =E40+G40 -> 73052.24 | J40: =+' Shankeshwar'!L35 -> 73052.24 | K40: =H40+I40-J40 -> 0
...

Sheet Sheet1
B2: S.no | C2: Site Name | D2: Bunk Name | E2: Outstannding | F2: Last Payment | G2: L.P Date | H2: Credit period in Days | I2: Next Payment Date
B3: 1 | C3: Khammam-1 | D3: Divya laxmi ganapathi | E3: =+'Dec-25 '!K2 -> 3956161.3 | F3: 7753305 | G3: 15.12.2025 | H3: 45 | I3: 30.01.2025
B4: 2 | C4: Khammam-2 | D4: Jayasai union bunk | E4: =+'Dec-25 '!K3 -> 3669815.6 | F4: 9561886 | G4: 15.12.2025 | H4: 45 | I4: 30.01.2025
B5: 3 | C5: Jadcherla-1 | D5: Sai Baba Fuel Station | E5: =+'Dec-25 '!K4 -> -0.0044004744 | F5: 307000 | G5: 15.12.2025 | H5: Close | I5: Close
B6: 4 | C6: Jadcherla-2 | D6: ADHOC FILLING STATION STATION | E6: =+'Dec-25 '!K5 -> 0 | F6: 1123622.9 | G6: 13.12.2025 | H6: Close | I6: Close
B7: 5 | C7: Jadcherla-3 | D7: JSASFuel Genie India Pvt.Ltd | E7: =+'Dec-25 '!K6 -> 1183331.5 | F7: 2755171 | G7: 16.12.2025 | H7: 15 | I7: 05.01.2026
B8: 6 | C8: Dindi | D8: Akarapu Balakistamma Fillling | E8: =+'Dec-25 '!K8 -> 0 | I8: C&C
B9: 7 | C9: Devarkhadra-1 | D9: Kurumurthy Swami F/S | E9: =+'Dec-25 '!K9 -> 5026.311 | F9: 55563 | G9: 16.12.2025 | H9: 10 | I9: 05.01.2026
B10: 8 | C10: Devarkhadra-3 | D10: JSASFuel Genie India Pvt.Ltd | E10: =+'Dec-25 '!K10 -> -0.0015 | F10: 66053.77 | G10: 16.12.2025 | H10: 15 | I10: 05.01.2026
B11: 9 | C11: Madanapalli | E11: =+'Dec-25 '!K11 -> 0 | I11: C&C
B12: 10 | C12: Amalapuram | D12: Sathya Filling Station | E12: =+'Dec-25 '!K12 -> 0.014 | I12: C&C
B13: 11 | C13: YG Gudda-1 | D13: Pallavi Petrolium | E13: =+'Dec-25 '!K13 -> 0.0015138002 | F13: 25000 | G13: 16.12.2025 | H13: 10 | I13: 0
B14: 12 | C14: YG Gudda-2 | D14: Pankaja HP Fuel Center | E14: =+'Dec-25 '!K14 -> 713890.2 | F14: 205413 | G14: 15.12.2025 | H14: 15 | I14: 05.01.2026
B15: 13 | C15: Hosadurga-1 | D15: Merchant Petroliums | E15: =+'Dec-25 '!K15 -> 2258.6 | I15: 0
B16: 14 | C16: Hosadurga-2 | D16: Shree Veeraprathap Fuel | E16: =+'Dec-25 '!K16 -> 197553.8 | F16: 551781.84 | G16: 15.12.2025 | H16: 15 | I16: 05.01.2026
B17: 15 | C17: Malebennuru(KUWSDB) | D17: Sri Ramanjuneya Service Station | E17: =+'Dec-25 '!K17 -> 202357.35 | F17: 40495 | G17: 15.12.2025 | H17: 10 | I17: 27.12.2025
B18: 16 | C18: kadur | D18: Vishal Service Station | E18: =+'Dec-25 '!K18 -> 210029.23 | F18: 175801 | G18: 15.12.2025 | H18: 30 | I18: 15.01.2026
B19: 17 | C19: Hiriyur(VJNL) | D19: Sri Balaji Agencies | E19: =+'Dec-25 '!K19 -> 438828.8 | F19: 135912 | G19: 15.12.2025 | H19: 10 | I19: 30.12.2025
B20: 18 | C20: Chellakere(KUWSDB) | D20: Shivaganga Service Station | E20: =+'Dec-25 '!K20 -> 145403.1 | F20: 58955.35 | G20: 15.12.2025 | H20: 15 | I20: 03.01.2025
B21: 19 | C21: Chellakere(KUWSDB)-09 | E21: =+'Dec-25 '!K21 -> 0 | I21: C&C
B22: 20 | C22: Molakalmuru | D22: Priyanka Petroleum | E22: =+'Dec-25 '!K22 -> 53588.5 | F22: New | I22: 05.01.2026
B23: 21 | C23: Chennagiri | E23: =+'Dec-25 '!K23 -> 0
B24: 22 | C24: Khanapur(PKG-3) | D24: V.V.Varde | E24: =+'Dec-25 '!K24 -> 98982.5 | F24: 50000 | G24: 13.12.2025 | H24: 15 | I24: 03.01.2025
B25: 23 | C25: Munavalli(PKG-3)-2 | D25: Shri Daneshwari | E25: =+'Dec-25 '!K25 -> 660530.8 | F25: 107000 | G25: 15.12.2025 | H25: 10 | I25: 30.12.2025
B26: 24 | C26: Borgaon(PKG-3) | D26: Aadisagar Petrolium | E26: =+'Dec-25 '!K26 -> 120395.81 | F26: 287043.3 | G26: 16.12.2025 | H26: 30 | I26: 15.01.2026
B27: 25 | C27: Ugar,Kudichi(PKG-3) | D27: Shiri Bhrhmanath Petrolium | E27: =+'Dec-25 '!K27 -> 292365.86 | F27: 313314 | G27: 15.12.2025 | H27: 30 | I27: 15.01.2026
B28: 26 | C28: Kabbur(PKG-3) | D28: Shri Jai Hanuman Petrolium | E28: =+'Dec-25 '!K28 -> 0
B29: 27 | C29: Kumta (PKG-1) | D29: Krishma fuel station | E29: =+'Dec-25 '!K29 -> 0
B30: 28 | C30: Jalgaon | D30: Sri Sai Petrol Pump | E30: =+'Dec-25 '!K30 -> 730303.78 | F30: 1700000 | G30: 15.12.2025 | H30: 30 | I30: 15.01.2026
B31: 29 | C31: MKBD | D31: Shree Sai Samarth Petroleum | E31: =+'Dec-25 '!K31 -> 362563.78 | F31: 461912.77 | G31: 15.12.2025 | H31: 30 | I31: 15.01.2026
B32: 30 | C32: Haveri | D32: Shivalingeshwar Petroleum | E32: =+'Dec-25 '!K32 -> 9461.0769 | F32: 224862 | G32: 12.12.2025 | H32: 10
B33: 31 | C33: Haveri | D33: M/s Magavi City Fuels | E33: =+'Dec-25 '!K33 -> 164443.72 | F33: 14064 | G33: 16.12.2025 | H33: 13 | I33: 03.01.2025
B34: 32 | C34: Guttal | D34: Taware filling station | E34: =+'Dec-25 '!K34 -> 336687.37 | F34: 50000 | G34: 24.12.2025 | H34: 7 | I34: 30.12.2025
B35: 33 | C35: Rattihali | D35: Shree Siri Gowari petroliam | E35: =+'Dec-25 '!K35 -> 6442.724 | F35: 272393 | G35: 15.12.2025 | H35: 15 | I35: 30.12.2025
B36: 34 | C36: Rattihali-2 | D36: Shiva Oil Traders | E36: =+'Dec-25 '!K36 -> 310880.3 | F36: New | H36: 15 | I36: 05.01.2026
B37: 35 | C37: Gajendragada | D37: Vanasri Petrol Pump | E37: =+'Dec-25 '!K37 -> 4500.2015 | H37: 30 | I37: 05.01.2026
B38: 36 | C38: Gokak(PKG-3) | D38: AJ Petrolinks | E38: =+'Dec-25 '!K38 -> 547359.48 | F38: 1000000 | G38: 13.12.2025 | H38: 15 | I38: 05.01.2026
B39: 37 | C39: Ankaligi | D39: Shiv ganga | E39: =+'Dec-25 '!K39 -> 180107.62 | F39: 361718.01 | G39: 15.12.2025 | H39: 15 | I39: 03.01.2025
B40: 38 | C40: ShankeshWAR | D40: SR Patil | E40: =+'Dec-25 '!K40 -> 0 | I40: C&C
B41: 39 | C41: Talikote(PKG-1) | D41: Raykar Oil Agencies | E41: =+'Dec-25 '!K41 -> 21107.796 | F41: 64000 | G41: 15.12.2025 | H41: 10 | I41: 30.12.2025
...

Sheet  Ho(DG)
A1: JSASFuel Genie India Pvt.Ltd
A2: S.No | B2: Date | C2: GRN No | D2: Ind No/Bill No | E2: Diesel (Lts) | F2: Price | G2: Amount | H2: Petrol (Lts) | I2: Price | J2: Amount | K2: Total amount | L2: Amount paid | M2: As on date | N2: Remarks
A3: Opening Balance | M3: 0 | O3: 2623243.4
A4: 1 | B4: 45992 | G4: =E4*F4 -> 0 | H4: 0 | I4: 0 | J4: =H4*I4 -> 0 | K4: =G4+J4 -> 0 | L4: 0 | M4: =M3+K4-L4 -> 0
A5: 2 | B5: 45993 | G5: =E5*F5 -> 0 | H5: 0 | I5: 0 | J5: =H5*I5 -> 0 | K5: =G5+J5 -> 0 | L5: 0 | M5: =M4+K5-L5 -> 0
A6: 3 | B6: 45994 | G6: =E6*F6 -> 0 | H6: 0 | I6: 0 | J6: =H6*I6 -> 0 | K6: =G6+J6 -> 0 | L6: 0 | M6: =M5+K6-L6 -> 0
A7: 4 | B7: 45995 | G7: =E7*F7 -> 0 | H7: 0 | I7: 0 | J7: =H7*I7 -> 0 | K7: =G7+J7 -> 0 | L7: 0 | M7: =M6+K7-L7 -> 0 | P7: 5679
A8: 5 | B8: 45996 | G8: =E8*F8 -> 0 | H8: 0 | I8: 0 | J8: =H8*I8 -> 0 | K8: =G8+J8 -> 0 | L8: 0 | M8: =M7+K8-L8 -> 0
A9: 6 | B9: 45997 | G9: =E9*F9 -> 0 | H9: 0 | I9: 0 | J9: =H9*I9 -> 0 | K9: =G9+J9 -> 0 | L9: 0 | M9: =M8+K9-L9 -> 0
A10: 7 | B10: 45998 | G10: =E10*F10 -> 0 | H10: 0 | I10: 0 | J10: =H10*I10 -> 0 | K10: =G10+J10 -> 0 | L10: 0 | M10: =M9+K10-L10 -> 0
A11: 8 | B11: 45999 | G11: =E11*F11 -> 0 | H11: 0 | I11: 0 | J11: =H11*I11 -> 0 | K11: =G11+J11 -> 0 | L11: 0 | M11: =M10+K11-L11 -> 0
A12: 9 | B12: 46000 | G12: =E12*F12 -> 0 | H12: 0 | I12: 0 | K12: =G12+J12 -> 0 | L12: 0 | M12: =M11+K12-L12 -> 0
A13: 10 | B13: 46001 | G13: =E13*F13 -> 0 | H13: 0 | I13: 0 | K13: =G13+J13 -> 0 | L13: 0 | M13: =M12+K13-L13 -> 0
A14: 11 | B14: 46002 | G14: =E14*F14 -> 0 | H14: 0 | I14: 0 | K14: =G14+J14 -> 0 | L14: 0 | M14: =M13+K14-L14 -> 0 | P14: 1905988 | Q14: =P14-M14 -> 1905988
A15: 12 | B15: 46003 | G15: =E15*F15 -> 0 | H15: 0 | I15: 0 | K15: =G15+J15 -> 0 | L15: 0 | M15: =M14+K15-L15 -> 0
A16: 13 | B16: 46004 | G16: =E16*F16 -> 0 | H16: 0 | I16: 0 | J16: =H16*I16 -> 0 | K16: =G16+J16 -> 0 | L16: 0 | M16: =M15+K16-L16 -> 0
A17: 14 | B17: 46005 | G17: =E17*F17 -> 0 | H17: 0 | I17: 0 | J17: =H17*I17 -> 0 | K17: =G17+J17 -> 0 | L17: 0 | M17: =M16+K17-L17 -> 0
A18: 15 | B18: 46006 | G18: =E18*F18 -> 0 | H18: 0 | I18: 0 | J18: =H18*I18 -> 0 | K18: =G18+J18 -> 0 | L18: 0 | M18: =M17+K18-L18 -> 0
A19: 16 | B19: 46007 | G19: =E19*F19 -> 0 | H19: 0 | I19: 0 | J19: =H19*I19 -> 0 | K19: =G19+J19 -> 0 | L19: 0 | M19: =M18+K19-L19 -> 0
A20: 17 | B20: 46008 | G20: =E20*F20 -> 0 | J20: =H20*I20 -> 0 | K20: =G20+J20 -> 0 | L20: 0 | M20: =M19+K20-L20 -> 0
A21: 18 | B21: 46009 | G21: =E21*F21 -> 0 | J21: =H21*I21 -> 0 | K21: =G21+J21 -> 0 | L21: 0 | M21: =M20+K21-L21 -> 0
A22: 19 | B22: 46010 | G22: =E22*F22 -> 0 | J22: =H22*I22 -> 0 | K22: =G22+J22 -> 0 | M22: =M21+K22-L22 -> 0
A23: 20 | B23: 46011 | G23: =E23*F23 -> 0 | J23: =H23*I23 -> 0 | K23: =G23+J23 -> 0 | M23: =M22+K23-L23 -> 0
A24: 21 | B24: 46012 | G24: =E24*F24 -> 0 | J24: =H24*I24 -> 0 | K24: =G24+J24 -> 0 | M24: =M23+K24-L24 -> 0
A25: 22 | B25: 46013 | G25: =E25*F25 -> 0 | J25: =H25*I25 -> 0 | K25: =G25+J25 -> 0 | M25: =M24+K25-L25 -> 0
A26: 23 | B26: 46014 | G26: =E26*F26 -> 0 | J26: =H26*I26 -> 0 | K26: =G26+J26 -> 0 | M26: =M25+K26-L26 -> 0
A27: 24 | B27: 46015 | G27: =E27*F27 -> 0 | J27: =H27*I27 -> 0 | K27: =G27+J27 -> 0 | M27: =M26+K27-L27 -> 0
A28: 25 | B28: 46016 | G28: =E28*F28 -> 0 | J28: =H28*I28 -> 0 | K28: =G28+J28 -> 0 | M28: =M27+K28-L28 -> 0
A29: 26 | B29: 46017 | G29: =E29*F29 -> 0 | J29: =H29*I29 -> 0 | K29: =G29+J29 -> 0 | M29: =M28+K29-L29 -> 0
A30: 27 | B30: 46018 | G30: =E30*F30 -> 0 | J30: =H30*I30 -> 0 | K30: =G30+J30 -> 0 | M30: =M29+K30-L30 -> 0
A31: 28 | B31: 46019 | G31: =E31*F31 -> 0 | J31: =H31*I31 -> 0 | K31: =G31+J31 -> 0 | M31: =M30+K31-L31 -> 0
A32: 29 | B32: 46020 | G32: =E32*F32 -> 0 | J32: =H32*I32 -> 0 | K32: =G32+J32 -> 0 | M32: =M31+K32-L32 -> 0
A33: 30 | B33: 46021 | G33: =E33*F33 -> 0 | J33: =H33*I33 -> 0 | K33: =G33+J33 -> 0 | M33: =M32+K33-L33 -> 0
A34: 31 | B34: 46022 | E34: 170.01 | F34: 95.83 | G34: =E34*F34 -> 16292.058 | J34: =H34*I34 -> 0 | K34: =G34+J34 -> 16292.058 | L34: 0 | M34: =M33+K34-L34 -> 16292.058 | O34: 2669494 | P34: =O34-M34 -> 2653201.9
E35: 0 | F35: 0 | G35: =E35*F35 -> 0 | J35: =H35*I35 -> 0 | K35: =G35+J35 -> 0 | M35: =M34+K35-L35 -> 16292.058
E36: =SUM(E4:E34) -> 170.01 | G36: =SUM(G4:G34) -> 16292.058 | H36: =SUM(H4:H34) -> 0 | J36: =SUM(J4:J34) -> 0 | K36: =SUM(K4:K34) -> 16292.058 | L36: =SUM(L4:L34) -> 0
M45: 2408309
M46: 5327.86
M47: =M45-M46 -> 2402981.1

Sheet Khammam-1
A1: Divya laxmi ganapathi
A2: S.No | B2: Date | C2: GRN No | D2: Ind No/Bill No | E2: Diesel (Lts) | F2: Price | G2: Amount | H2: Petrol (Lts) | I2: Price | J2: Amount | K2: Total amount | L2: Amount paid | M2: As 0n Date | N2: Remarks
A3: Opening Balance | K3: 4574619.2 | M3: =+K3 -> 4574619.2 | O3: 11178224
A4: 1 | B4: 45992 | G4: =E4*F4 -> 0 | K4: =G4+J4 -> 0 | L4: 0 | M4: =M3+K4-L4 -> 4574619.2
A5: 2 | B5: 45993 | E5: 2700 | F5: 95.68 | G5: =E5*F5 -> 258336 | H5: 20 | I5: 107.46 | J5: =H5*I5 -> 2149.2 | K5: =G5+J5 -> 260485.2 | L5: 900000 | M5: =M4+K5-L5 -> 3935104.4
A6: 3 | B6: 45994 | E6: 5500 | F6: 95.68 | G6: =E6*F6 -> 526240 | H6: 40 | I6: 107.46 | J6: =H6*I6 -> 4298.4 | K6: =G6+J6 -> 530538.4 | M6: =M5+K6-L6 -> 4465642.8
A7: 4 | B7: 45995 | E7: 2700 | F7: 95.68 | G7: =E7*F7 -> 258336 | J7: =H7*I7 -> 0 | K7: =G7+J7 -> 258336 | M7: =M6+K7-L7 -> 4723978.8
A8: 5 | B8: 45996 | E8: 5500 | F8: 95.68 | G8: =E8*F8 -> 526240 | H8: 20 | I8: 107.46 | J8: =H8*I8 -> 2149.2 | K8: =G8+J8 -> 528389.2 | M8: =M7+K8-L8 -> 5252368
A9: 6 | B9: 45997 | E9: 5400 | F9: 95.68 | G9: =E9*F9 -> 516672 | H9: 20 | I9: 107.46 | J9: =H9*I9 -> 2149.2 | K9: =G9+J9 -> 518821.2 | M9: =M8+K9-L9 -> 5771189.2
A10: 7 | B10: 45998 | E10: 4400 | F10: 95.68 | G10: =E10*F10 -> 420992 | J10: =H10*I10 -> 0 | K10: =G10+J10 -> 420992 | M10: =M9+K10-L10 -> 6192181.2
A11: 8 | B11: 45999 | E11: 2700 | F11: 95.68 | G11: =E11*F11 -> 258336 | H11: 20 | I11: 107.46 | J11: =H11*I11 -> 2149.2 | K11: =G11+J11 -> 260485.2 | M11: =M10+K11-L11 -> 6452666.4
A12: 9 | B12: 46000 | E12: 5400 | F12: 95.68 | G12: =E12*F12 -> 516672 | H12: 20 | I12: 107.46 | J12: =H12*I12 -> 2149.2 | K12: =G12+J12 -> 518821.2 | M12: =M11+K12-L12 -> 6971487.6
A13: 10 | B13: 46001 | G13: =E13*F13 -> 0 | J13: =H13*I13 -> 0 | K13: =G13+J13 -> 0 | M13: =M12+K13-L13 -> 6971487.6
A14: 11 | B14: 46002 | G14: =E14*F14 -> 0 | J14: =H14*I14 -> 0 | K14: =G14+J14 -> 0 | M14: =M13+K14-L14 -> 6971487.6
A15: 12 | B15: 46003 | G15: =E15*F15 -> 0 | J15: =H15*I15 -> 0 | K15: =G15+J15 -> 0 | M15: =M14+K15-L15 -> 6971487.6
A16: 13 | B16: 46004 | E16: 5400 | F16: 95.68 | G16: =E16*F16 -> 516672 | H16: 40 | I16: 107.46 | J16: =H16*I16 -> 4298.4 | K16: =G16+J16 -> 520970.4 | M16: =M15+K16-L16 -> 7492458
A17: 14 | B17: 46005 | E17: 5500 | F17: 95.68 | G17: =E17*F17 -> 526240 | H17: 20 | I17: 107.46 | J17: =H17*I17 -> 2149.2 | K17: =G17+J17 -> 528389.2 | M17: =M16+K17-L17 -> 8020847.2
A18: 15 | B18: 46006 | G18: =E18*F18 -> 0 | J18: =H18*I18 -> 0 | K18: =G18+J18 -> 0 | L18: 7753305 | M18: =M17+K18-L18 -> 267542.24
A19: 16 | B19: 46007 | E19: 5500 | F19: 95.68 | G19: =E19*F19 -> 526240 | J19: =H19*I19 -> 0 | K19: =G19+J19 -> 526240 | M19: =M18+K19-L19 -> 793782.24
A20: 17 | B20: 46008 | E20: 5500 | F20: 95.68 | G20: =E20*F20 -> 526240 | J20: =H20*I20 -> 0 | K20: =G20+J20 -> 526240 | M20: =M19+K20-L20 -> 1320022.2
A21: 18 | B21: 46009 | E21: 0 | F21: 0 | G21: =E21*F21 -> 0 | J21: =H21*I21 -> 0 | K21: =G21+J21 -> 0 | M21: =M20+K21-L21 -> 1320022.2
A22: 19 | B22: 46010 | E22: 2800 | F22: 95.68 | G22: =E22*F22 -> 267904 | J22: =H22*I22 -> 0 | K22: =G22+J22 -> 267904 | M22: =M21+K22-L22 -> 1587926.2
A23: 20 | B23: 46011 | E23: 2800 | F23: 95.68 | G23: =E23*F23 -> 267904 | H23: 40 | I23: 107.46 | J23: =H23*I23 -> 4298.4 | K23: =G23+J23 -> 272202.4 | M23: =M22+K23-L23 -> 1860128.6
A24: 21 | B24: 46012 | E24: 2000 | F24: 95.68 | G24: =E24*F24 -> 191360 | J24: =H24*I24 -> 0 | K24: =G24+J24 -> 191360 | M24: =M23+K24-L24 -> 2051488.6
A25: 22 | B25: 46013 | E25: 1000 | F25: 95.68 | G25: =E25*F25 -> 95680 | J25: =H25*I25 -> 0 | K25: =G25+J25 -> 95680 | M25: =M24+K25-L25 -> 2147168.6
A26: 23 | B26: 46014 | E26: 4300 | F26: 95.68 | G26: =E26*F26 -> 411424 | H26: 55 | I26: 107.46 | J26: =H26*I26 -> 5910.3 | K26: =G26+J26 -> 417334.3 | M26: =M25+K26-L26 -> 2564502.9
A27: 24 | B27: 46015 | E27: 4300 | F27: 95.68 | G27: =E27*F27 -> 411424 | J27: =H27*I27 -> 0 | K27: =G27+J27 -> 411424 | M27: =M26+K27-L27 -> 2975926.9
A28: 25 | B28: 46016 | E28: 1500 | F28: 95.68 | G28: =E28*F28 -> 143520 | J28: =H28*I28 -> 0 | K28: =G28+J28 -> 143520 | M28: =M27+K28-L28 -> 3119446.9
A29: 26 | B29: 46017 | E29: 1500 | F29: 95.68 | G29: =E29*F29 -> 143520 | J29: =H29*I29 -> 0 | K29: =G29+J29 -> 143520 | M29: =M28+K29-L29 -> 3262966.9
A30: 27 | B30: 46018 | E30: 1500 | F30: 95.68 | G30: =E30*F30 -> 143520 | J30: =H30*I30 -> 0 | K30: =G30+J30 -> 143520 | M30: =M29+K30-L30 -> 3406486.9
A31: 28 | B31: 46019 | E31: 1500 | F31: 95.68 | G31: =E31*F31 -> 143520 | J31: =H31*I31 -> 0 | K31: =G31+J31 -> 143520 | M31: =M30+K31-L31 -> 3550006.9
A32: 29 | B32: 46020 | E32: 1500 | F32: 95.68 | G32: =E32*F32 -> 143520 | J32: =H32*I32 -> 0 | K32: =G32+J32 -> 143520 | M32: =M31+K32-L32 -> 3693526.9
A33: 30 | B33: 46021 | E33: 2700 | F33: 95.68 | G33: =E33*F33 -> 258336 | H33: 40 | I33: 107.46 | J33: =H33*I33 -> 4298.4 | K33: =G33+J33 -> 262634.4 | M33: =M32+K33-L33 -> 3956161.3
A34: 31 | B34: 46022 | G34: =E34*F34 -> 0 | K34: =G34+J34 -> 0 | M34: =M33+K34-L34 -> 3956161.3
A35: 32 | G35: =E35*F35 -> 0 | J35: =H35*I35 -> 0 | K35: =G35+J35 -> 0 | M35: =M34+K35-L35 -> 3956161.3
A36: 33 | G36: =E36*F36 -> 0 | J36: =H36*I36 -> 0 | K36: =G36+J36 -> 0
A37: 34 | G37: =E37*F37 -> 0 | H37: 0 | I37: 0 | J37: =H37*I37 -> 0 | K37: =G37+J37 -> 0
E38: =SUM(E3:E37) -> 83600 | G38: =SUM(G3:G37) -> 7998848 | H38: =SUM(H3:H37) -> 335 | J38: =SUM(J3:J37) -> 35999.1 | K38: =SUM(K4:K37) -> 8034847.1 | L38: =SUM(L3:L37) -> 8653305

Sheet Khammam-2
A1: Jayasai union bunk
A2: S.No | B2: Date | C2: GRN No | D2: Ind No/Bill No | E2: Diesel (Lts) | F2: Price | G2: Amount | H2: Petrol (Lts) | I2: Price | J2: Amount | K2: Total amount | L2: Amount paid | M2: As 0n Date | N2: Remarks
A3: Opening Balance | K3: 9561944.8 | M3: 9561944.8
A4: 1 | B4: 45992 | G4: =E4*F4 -> 0 | J4: =H4*I4 -> 0 | K4: =G4+J4 -> 0 | M4: =M3+K4-L4 -> 9561944.8 | O4: =O3+M4-N4 -> 9561944.8
A5: 2 | B5: 45993 | G5: =E5*F5 -> 0 | J5: =H5*I5 -> 0 | K5: =G5+J5 -> 0 | M5: =M4+K5-L5 -> 9561944.8
A6: 3 | B6: 45994 | G6: =E6*F6 -> 0 | J6: =H6*I6 -> 0 | K6: =G6+J6 -> 0 | M6: =M5+K6-L6 -> 9561944.8
A7: 4 | B7: 45995 | G7: =E7*F7 -> 0 | J7: =H7*I7 -> 0 | K7: =G7+J7 -> 0 | M7: =M6+K7-L7 -> 9561944.8
A8: 5 | B8: 45996 | G8: =E8*F8 -> 0 | J8: =H8*I8 -> 0 | K8: =G8+J8 -> 0 | M8: =M7+K8-L8 -> 9561944.8 | O8: 12802499
A9: 6 | B9: 45997 | G9: =E9*F9 -> 0 | J9: =H9*I9 -> 0 | K9: =G9+J9 -> 0 | M9: =M8+K9-L9 -> 9561944.8
A10: 7 | B10: 45998 | G10: =E10*F10 -> 0 | J10: =H10*I10 -> 0 | K10: =G10+J10 -> 0 | M10: =M9+K10-L10 -> 9561944.8
A11: 8 | B11: 45999 | G11: =E11*F11 -> 0 | J11: =H11*I11 -> 0 | K11: =G11+J11 -> 0 | M11: =M10+K11-L11 -> 9561944.8
A12: 9 | B12: 46000 | G12: =E12*F12 -> 0 | J12: =H12*I12 -> 0 | K12: =G12+J12 -> 0 | M12: =M11+K12-L12 -> 9561944.8
A13: 10 | B13: 46001 | G13: =E13*F13 -> 0 | J13: =H13*I13 -> 0 | K13: =G13+J13 -> 0 | M13: =M12+K13-L13 -> 9561944.8
A14: 11 | B14: 46002 | G14: =E14*F14 -> 0 | J14: =H14*I14 -> 0 | K14: =G14+J14 -> 0 | M14: =M13+K14-L14 -> 9561944.8
A15: 12 | B15: 46003 | G15: =E15*F15 -> 0 | J15: =H15*I15 -> 0 | K15: =G15+J15 -> 0 | M15: =M14+K15-L15 -> 9561944.8
A16: 13 | B16: 46004 | G16: =E16*F16 -> 0 | J16: =H16*I16 -> 0 | K16: =G16+J16 -> 0 | M16: =M15+K16-L16 -> 9561944.8
A17: 14 | B17: 46005 | G17: =E17*F17 -> 0 | J17: =H17*I17 -> 0 | K17: =G17+J17 -> 0 | M17: =M16+K17-L17 -> 9561944.8
A18: 15 | B18: 46006 | G18: =E18*F18 -> 0 | J18: =H18*I18 -> 0 | K18: =G18+J18 -> 0 | L18: 9561886 | M18: =M17+K18-L18 -> 58.78
A19: 16 | B19: 46007 | G19: =E19*F19 -> 0 | J19: =H19*I19 -> 0 | K19: =G19+J19 -> 0 | M19: =M18+K19-L19 -> 58.78
A20: 17 | B20: 46008 | D20: Round Off | G20: =E20*F20 -> 0 | J20: =H20*I20 -> 0 | K20: =G20+J20 -> 0 | L20: 58.78 | M20: =M19+K20-L20 -> -6.7055339e-10
A21: 18 | B21: 46009 | E21: 2700 | F21: 95.7 | G21: =E21*F21 -> 258390 | J21: =H21*I21 -> 0 | K21: =G21+J21 -> 258390 | M21: =M20+K21-L21 -> 258390
A22: 19 | B22: 46010 | E22: 2700 | F22: 95.7 | G22: =E22*F22 -> 258390 | J22: =H22*I22 -> 0 | K22: =G22+J22 -> 258390 | M22: =M21+K22-L22 -> 516780
A23: 20 | B23: 46011 | E23: 2700 | F23: 95.7 | G23: =E23*F23 -> 258390 | J23: =H23*I23 -> 0 | K23: =G23+J23 -> 258390 | M23: =M22+K23-L23 -> 775170
A24: 21 | B24: 46012 | E24: 2800 | F24: 95.7 | G24: =E24*F24 -> 267960 | J24: =H24*I24 -> 0 | K24: =G24+J24 -> 267960 | M24: =M23+K24-L24 -> 1043130
A25: 22 | B25: 46013 | E25: 2700 | F25: 95.7 | G25: =E25*F25 -> 258390 | J25: =H25*I25 -> 0 | K25: =G25+J25 -> 258390 | M25: =M24+K25-L25 -> 1301520
A26: 23 | B26: 46014 | E26: 2700 | F26: 95.7 | G26: =E26*F26 -> 258390 | H26: 40 | I26: 107.48 | J26: =H26*I26 -> 4299.2 | K26: =G26+J26 -> 262689.2 | M26: =M25+K26-L26 -> 1564209.2
A27: 24 | B27: 46015 | E27: 2700 | F27: 95.7 | G27: =E27*F27 -> 258390 | J27: =H27*I27 -> 0 | K27: =G27+J27 -> 258390 | M27: =M26+K27-L27 -> 1822599.2
A28: 25 | B28: 46016 | E28: 2700 | F28: 95.7 | G28: =E28*F28 -> 258390 | H28: 40 | I28: 107.48 | J28: =H28*I28 -> 4299.2 | K28: =G28+J28 -> 262689.2 | M28: =M27+K28-L28 -> 2085288.4
A29: 26 | B29: 46017 | E29: 2700 | F29: 95.7 | G29: =E29*F29 -> 258390 | H29: 40 | I29: 107.48 | J29: =H29*I29 -> 4299.2 | K29: =G29+J29 -> 262689.2 | M29: =M28+K29-L29 -> 2347977.6
A30: 27 | B30: 46018 | E30: 2700 | F30: 95.7 | G30: =E30*F30 -> 258390 | H30: 40 | I30: 107.48 | J30: =H30*I30 -> 4299.2 | K30: =G30+J30 -> 262689.2 | M30: =M29+K30-L30 -> 2610666.8
A31: 28 | B31: 46019 | E31: 2700 | F31: 95.7 | G31: =E31*F31 -> 258390 | H31: 40 | I31: 107.48 | J31: =H31*I31 -> 4299.2 | K31: =G31+J31 -> 262689.2 | M31: =M30+K31-L31 -> 2873356
A32: 29 | B32: 46020 | E32: 2700 | F32: 95.7 | G32: =E32*F32 -> 258390 | H32: 20 | I32: 107.48 | J32: =H32*I32 -> 2149.6 | K32: =G32+J32 -> 260539.6 | M32: =M31+K32-L32 -> 3133895.6
A33: 30 | B33: 46021 | E33: 2800 | F33: 95.7 | G33: =E33*F33 -> 267960 | J33: =H33*I33 -> 0 | K33: =G33+J33 -> 267960 | M33: =M32+K33-L33 -> 3401855.6
A34: 31 | B34: 46022 | E34: 2800 | F34: 95.7 | G34: =E34*F34 -> 267960 | J34: =H34*I34 -> 0 | K34: =G34+J34 -> 267960 | M34: =M33+K34-L34 -> 3669815.6
E35: =SUM(E4:E34) -> 38100 | G35: =SUM(G4:G34) -> 3646170 | H35: =SUM(H4:H34) -> 220 | J35: =SUM(J4:J34) -> 23645.6 | K35: =SUM(K4:K34) -> 3669815.6 | L35: =SUM(L4:L34) -> 9561944.8
E38: 83600
E40: =SUM(E35:E39) -> 121700

Sheet Jadcherla -1
A1: Sai Baba Fuel Station
A2: S.No | B2: Date | C2: GRN No | D2: Ind No/Bill No | E2: Diesel (Lts) | F2: Price | G2: Amount | H2: Petrol (Lts) | I2: Price | J2: Amount | K2: Total amount | L2: Amount paid | M2: As on date | N2: Remarks
A3: Opening Balance | M3: 801890.2 | O3: 2623243.4
A4: 1 | B4: 45992 | G4: =E4*F4 -> 0 | H4: 50 | I4: 108.23 | J4: =H4*I4 -> 5411.5 | K4: =G4+J4 -> 5411.5 | L4: 5411.5 | M4: =M3+K4-L4 -> 801890.2
A5: 2 | B5: 45993 | G5: =E5*F5 -> 0 | J5: =H5*I5 -> 0 | K5: =G5+J5 -> 0 | M5: =M4+K5-L5 -> 801890.2
A6: 3 | B6: 45994 | G6: =E6*F6 -> 0 | J6: =H6*I6 -> 0 | K6: =G6+J6 -> 0 | M6: =M5+K6-L6 -> 801890.2
A7: 4 | B7: 45995 | G7: =E7*F7 -> 0 | J7: =H7*I7 -> 0 | K7: =G7+J7 -> 0 | M7: =M6+K7-L7 -> 801890.2 | P7: 5679
A8: 5 | B8: 45996 | G8: =E8*F8 -> 0 | J8: =H8*I8 -> 0 | K8: =G8+J8 -> 0 | M8: =M7+K8-L8 -> 801890.2
A9: 6 | B9: 45997 | G9: =E9*F9 -> 0 | J9: =H9*I9 -> 0 | K9: =G9+J9 -> 0 | M9: =M8+K9-L9 -> 801890.2
A10: 7 | B10: 45998 | G10: =E10*F10 -> 0 | J10: =H10*I10 -> 0 | K10: =G10+J10 -> 0 | M10: =M9+K10-L10 -> 801890.2
A11: 8 | B11: 45999 | G11: =E11*F11 -> 0 | H11: 46 | I11: 108.23 | J11: =H11*I11 -> 4978.58 | K11: =G11+J11 -> 4978.58 | L11: 4978.58 | M11: =M10+K11-L11 -> 801890.2
A12: 9 | B12: 46000 | G12: =E12*F12 -> 0 | K12: =G12+J12 -> 0 | M12: =M11+K12-L12 -> 801890.2
A13: 10 | B13: 46001 | G13: =E13*F13 -> 0 | K13: =G13+J13 -> 0 | M13: =M12+K13-L13 -> 801890.2
A14: 11 | B14: 46002 | G14: =E14*F14 -> 0 | K14: =G14+J14 -> 0 | M14: =M13+K14-L14 -> 801890.2 | P14: 1905988 | Q14: =P14-M14 -> 1104097.8
A15: 12 | B15: 46003 | G15: =E15*F15 -> 0 | K15: =G15+J15 -> 0 | L15: 500000 | M15: =M14+K15-L15 -> 301890.2
A16: 13 | B16: 46004 | G16: =E16*F16 -> 0 | J16: =H16*I16 -> 0 | K16: =G16+J16 -> 0 | M16: =M15+K16-L16 -> 301890.2
A17: 14 | B17: 46005 | G17: =E17*F17 -> 0 | J17: =H17*I17 -> 0 | K17: =G17+J17 -> 0 | M17: =M16+K17-L17 -> 301890.2
A18: 15 | B18: 46006 | G18: =E18*F18 -> 0 | H18: 46.197912 | I18: 108.23 | J18: =H18*I18 -> 5000 | K18: =G18+J18 -> 5000 | L18: 307000 | M18: =M17+K18-L18 -> -109.8044
A19: 16 | B19: 46007 | G19: =E19*F19 -> 0 | J19: =H19*I19 -> 0 | K19: =G19+J19 -> 0 | L19: -109.8 | M19: =M18+K19-L19 -> -0.0044004743
A20: 17 | B20: 46008 | G20: =E20*F20 -> 0 | J20: =H20*I20 -> 0 | K20: =G20+J20 -> 0 | M20: =M19+K20-L20 -> -0.0044004743
A21: 18 | B21: 46009 | G21: =E21*F21 -> 0 | J21: =H21*I21 -> 0 | K21: =G21+J21 -> 0 | M21: =M20+K21-L21 -> -0.0044004743
A22: 19 | B22: 46010 | G22: =E22*F22 -> 0 | J22: =H22*I22 -> 0 | K22: =G22+J22 -> 0 | M22: =M21+K22-L22 -> -0.0044004743
A23: 20 | B23: 46011 | G23: =E23*F23 -> 0 | J23: =H23*I23 -> 0 | K23: =G23+J23 -> 0 | M23: =M22+K23-L23 -> -0.0044004743
A24: 21 | B24: 46012 | G24: =E24*F24 -> 0 | J24: =H24*I24 -> 0 | K24: =G24+J24 -> 0 | M24: =M23+K24-L24 -> -0.0044004743
A25: 22 | B25: 46013 | G25: =E25*F25 -> 0 | J25: =H25*I25 -> 0 | K25: =G25+J25 -> 0 | M25: =M24+K25-L25 -> -0.0044004743
A26: 23 | B26: 46014 | G26: =E26*F26 -> 0 | J26: =H26*I26 -> 0 | K26: =G26+J26 -> 0 | M26: =M25+K26-L26 -> -0.0044004743
A27: 24 | B27: 46015 | G27: =E27*F27 -> 0 | J27: =H27*I27 -> 0 | K27: =G27+J27 -> 0 | M27: =M26+K27-L27 -> -0.0044004743
A28: 25 | B28: 46016 | G28: =E28*F28 -> 0 | J28: =H28*I28 -> 0 | K28: =G28+J28 -> 0 | M28: =M27+K28-L28 -> -0.0044004743
A29: 26 | B29: 46017 | G29: =E29*F29 -> 0 | J29: =H29*I29 -> 0 | K29: =G29+J29 -> 0 | M29: =M28+K29-L29 -> -0.0044004743
A30: 27 | B30: 46018 | G30: =E30*F30 -> 0 | J30: =H30*I30 -> 0 | K30: =G30+J30 -> 0 | M30: =M29+K30-L30 -> -0.0044004743
A31: 28 | B31: 46019 | G31: =E31*F31 -> 0 | J31: =H31*I31 -> 0 | K31: =G31+J31 -> 0 | M31: =M30+K31-L31 -> -0.0044004743
... A33: 30 | B33: 46021 | G33: =E33*F33 -> 0 | J33: =H33*I33 -> 0 | K33: =G33+J33 -> 0 | M33: =M32+K33-L33 -> -0.0044004743
A34: 31 | B34: 46022 | G34: =E34*F34 -> 0 | J34: =H34*I34 -> 0 | K34: =G34+J34 -> 0 | L34: 0 | M34: =M33+K34-L34 -> -0.0044004743 | O34: 2669494 | P34: =O34-M34 -> 2669494
E35: 0 | F35: 0 | G35: =E35*F35 -> 0 | J35: =H35*I35 -> 0 | K35: =G35+J35 -> 0 | M35: =M34+K35-L35 -> -0.0044004743
E36: =SUM(E4:E34) -> 0 | G36: =SUM(G4:G34) -> 0 | H36: =SUM(H4:H34) -> 142.19791 | J36: =SUM(J4:J34) -> 15390.08 | K36: =SUM(K4:K34) -> 15390.08 | L36: =SUM(L4:L34) -> 817280.28
M45: 2408309
M46: 5327.86
M47: =M45-M46 -> 2402981.1

Sheet Jadcharla-2
A1: Jadcherla FILLING STATION STATION
A2: S.No | B2: Date | C2: GRN No | D2: Ind No/Bill No | E2: Diesel (Lts) | F2: Price | G2: Amount | H2: Petrol (Lts) | I2: Price | J2: Amount | K2: Total amount | L2: Amount paid | M2: As on Date | N2: Remarks
A3: Opening Balance | K3: 1123622.9 | M3: =+K3 -> 1123622.9
A4: 1 | B4: 45992 | G4: =E4*F4 -> 0 | J4: =H4*I4 -> 0 | K4: =G4+J4 -> 0 | M4: =M3+K4-L4 -> 1123622.9
A5: 2 | B5: 45993 | G5: =E5*F5 -> 0 | J5: =H5*I5 -> 0 | K5: =G5+J5 -> 0 | M5: =M4+K5-L5 -> 1123622.9
A6: 3 | B6: 45994 | G6: =E6*F6 -> 0 | J6: =H6*I6 -> 0 | K6: =G6+J6 -> 0 | M6: =M5+K6-L6 -> 1123622.9 | R6: 541.08
A7: 4 | B7: 45995 | G7: =E7*F7 -> 0 | J7: =H7*I7 -> 0 | K7: =G7+J7 -> 0 | M7: =M6+K7-L7 -> 1123622.9
A8: 5 | B8: 45996 | G8: =E8*F8 -> 0 | J8: =H8*I8 -> 0 | K8: =G8+J8 -> 0 | M8: =M7+K8-L8 -> 1123622.9
A9: 6 | B9: 45997 | G9: =E9*F9 -> 0 | J9: =H9*I9 -> 0 | K9: =G9+J9 -> 0 | M9: =M8+K9-L9 -> 1123622.9
A10: 7 | B10: 45998 | G10: =E10*F10 -> 0 | J10: =H10*I10 -> 0 | K10: =G10+J10 -> 0 | M10: =M9+K10-L10 -> 1123622.9
A11: 8 | B11: 45999 | G11: =E11*F11 -> 0 | J11: =H11*I11 -> 0 | K11: =G11+J11 -> 0 | M11: =M10+K11-L11 -> 1123622.9
A12: 9 | B12: 46000 | G12: =E12*F12 -> 0 | J12: =H12*I12 -> 0 | K12: =G12+J12 -> 0 | M12: =M11+K12-L12 -> 1123622.9
A13: 10 | B13: 46001 | G13: =E13*F13 -> 0 | J13: =H13*I13 -> 0 | K13: =G13+J13 -> 0 | M13: =M12+K13-L13 -> 1123622.9
A14: 11 | B14: 46002 | G14: =E14*F14 -> 0 | J14: =H14*I14 -> 0 | K14: =G14+J14 -> 0 | M14: =M13+K14-L14 -> 1123622.9
A15: 12 | B15: 46003 | G15: =E15*F15 -> 0 | J15: =H15*I15 -> 0 | K15: =G15+J15 -> 0 | M15: =M14+K15-L15 -> 1123622.9
A16: 13 | B16: 46004 | G16: =E16*F16 -> 0 | J16: =H16*I16 -> 0 | K16: =G16+J16 -> 0 | L16: 1123622.9 | M16: =M15+K16-L16 -> 0
A17: 14 | B17: 46005 | G17: =E17*F17 -> 0 | J17: =H17*I17 -> 0 | K17: =G17+J17 -> 0 | M17: =M16+K17-L17 -> 0
A18: 15 | B18: 46006 | G18: =E18*F18 -> 0 | J18: =H18*I18 -> 0 | K18: =G18+J18 -> 0 | M18: =M17+K18-L18 -> 0
A19: 16 | B19: 46007 | G19: =E19*F19 -> 0 | J19: =H19*I19 -> 0 | K19: =G19+J19 -> 0 | M19: =M18+K19-L19 -> 0
A20: 17 | B20: 46008 | G20: =E20*F20 -> 0 | J20: =H20*I20 -> 0 | K20: =G20+J20 -> 0 | M20: =M19+K20-L20 -> 0
A21: 18 | B21: 46009 | G21: =E21*F21 -> 0 | J21: =H21*I21 -> 0 | K21: =G21+J21 -> 0 | M21: =M20+K21-L21 -> 0
A22: 19 | B22: 46010 | G22: =E22*F22 -> 0 | J22: =H22*I22 -> 0 | K22: =G22+J22 -> 0 | M22: =M21+K22-L22 -> 0
A23: 20 | B23: 46011 | G23: =E23*F23 -> 0 | J23: =H23*I23 -> 0 | K23: =G23+J23 -> 0 | M23: =M22+K23-L23 -> 0
A24: 21 | B24: 46012 | G24: =E24*F24 -> 0 | J24: =H24*I24 -> 0 | K24: =G24+J24 -> 0 | M24: =M23+K24-L24 -> 0
A25: 22 | B25: 46013 | G25: =E25*F25 -> 0 | J25: =H25*I25 -> 0 | K25: =G25+J25 -> 0 | M25: =M24+K25-L25 -> 0
A26: 23 | B26: 46014 | G26: =E26*F26 -> 0 | J26: =H26*I26 -> 0 | K26: =G26+J26 -> 0 | M26: =M25+K26-L26 -> 0
A27: 24 | B27: 46015 | G27: =E27*F27 -> 0 | J27: =H27*I27 -> 0 | K27: =G27+J27 -> 0 | M27: =M26+K27-L27 -> 0
A28: 25 | B28: 46016 | G28: =E28*F28 -> 0 | J28: =H28*I28 -> 0 | K28: =G28+J28 -> 0 | M28: =M27+K28-L28 -> 0
... A33: 30 | B33: 46021 | G33: =E33*F33 -> 0 | J33: =H33*I33 -> 0 | K33: =G33+J33 -> 0 | M33: =M32+K33-L33 -> 0
A34: 31 | B34: 46022 | E34: 0 | F34: 0 | G34: =E34*F34 -> 0 | J34: =H34*I34 -> 0 | K34: =G34+J34 -> 0 | M34: =M33+K34-L34 -> 0 | O34: 1688453.6 | P34: 1900671 | Q34: =P34-O34 -> 212217.42
E35: =SUM(E4:E34) -> 0 | G35: =SUM(G4:G34) -> 0 | H35: =SUM(H4:H34) -> 0 | J35: =SUM(J4:J34) -> 0 | K35: =SUM(K4:K34) -> 0 | L35: =SUM(L4:L34) -> 1123622.9

Sheet Jadcherla-3
A1: JSASFuel Genie India Pvt.Ltd
A2: S.No | B2: Date | C2: GRN No | D2: Ind no/Bill No | E2: Diesel (Lts) | F2: Price | G2: Amount | H2: Petrol (Lts) | I2: Price | J2: Amount | K2: Total amount | L2: Amount paid | M2: As on Date | N2: Remarks
A3: Opening Balance | M3: 1839042.5
A4: 1 | B4: 45992 | G4: =E4*F4 -> 0 | H4: 0 | I4: 0 | J4: =H4*I4 -> 0 | K4: =G4+J4 -> 0 | L4: 0 | M4: =+M3+K4-L4 -> 1839042.5
A5: 2 | B5: 45993 | G5: =E5*F5 -> 0 | H5: 0 | I5: 0 | J5: =H5*I5 -> 0 | K5: =G5+J5 -> 0 | L5: 0 | M5: =+M4+K5-L5 -> 1839042.5
A6: 3 | B6: 45994 | E6: 2000 | F6: 95.43 | G6: =E6*F6 -> 190860 | H6: 0 | I6: 0 | J6: =H6*I6 -> 0 | K6: =G6+J6 -> 190860 | M6: =+M5+K6-L6 -> 2029902.5
A7: 4 | B7: 45995 | G7: =E7*F7 -> 0 | H7: 0 | I7: 0 | J7: =H7*I7 -> 0 | K7: =G7+J7 -> 0 | M7: =+M6+K7-L7 -> 2029902.5
A8: 5 | B8: 45996 | G8: =E8*F8 -> 0 | H8: 0 | I8: 0 | J8: =H8*I8 -> 0 | K8: =G8+J8 -> 0 | M8: =+M7+K8-L8 -> 2029902.5
A9: 6 | B9: 45997 | E9: 1500 | F9: 95.43 | G9: =E9*F9 -> 143145 | H9: 0 | I9: 0 | J9: =H9*I9 -> 0 | K9: =G9+J9 -> 143145 | M9: =+M8+K9-L9 -> 2173047.5
A10: 7 | B10: 45998 | E10: 2000 | F10: 95.43 | G10: =E10*F10 -> 190860 | H10: 0 | I10: 0 | J10: =H10*I10 -> 0 | K10: =G10+J10 -> 190860 | M10: =+M9+K10-L10 -> 2363907.5
A11: 8 | B11: 45999 | G11: =E11*F11 -> 0 | H11: 0 | I11: 0 | J11: =H11*I11 -> 0 | K11: =G11+J11 -> 0 | M11: =+M10+K11-L11 -> 2363907.5
A12: 9 | B12: 46000 | G12: =E12*F12 -> 0 | H12: 0 | I12: 0 | J12: =H12*I12 -> 0 | K12: =G12+J12 -> 0 | M12: =+M11+K12-L12 -> 2363907.5
A13: 10 | B13: 46001 | E13: 1700 | F13: 95.43 | G13: =E13*F13 -> 162231 | H13: 0 | I13: 0 | J13: =H13*I13 -> 0 | K13: =G13+J13 -> 162231 | M13: =+M12+K13-L13 -> 2526138.5
A14: 11 | B14: 46002 | E14: 2400 | F14: 95.43 | G14: =E14*F14 -> 229032 | H14: 0 | I14: 0 | J14: =H14*I14 -> 0 | K14: =G14+J14 -> 229032 | M14: =+M13+K14-L14 -> 2755170.5
A15: 12 | B15: 46003 | G15: =E15*F15 -> 0 | H15: 0 | I15: 0 | J15: =H15*I15 -> 0 | K15: =G15+J15 -> 0 | M15: =+M14+K15-L15 -> 2755170.5
A16: 13 | B16: 46004 | G16: =E16*F16 -> 0 | H16: 0 | I16: 0 | J16: =H16*I16 -> 0 | K16: =G16+J16 -> 0 | M16: =+M15+K16-L16 -> 2755170.5
A17: 14 | B17: 46005 | G17: =E17*F17 -> 0 | H17: 0 | I17: 0 | J17: =H17*I17 -> 0 | K17: =G17+J17 -> 0 | M17: =+M16+K17-L17 -> 2755170.5
A18: 15 | B18: 46006 | E18: 1500 | F18: 95.43 | G18: =E18*F18 -> 143145 | H18: 0 | I18: 0 | J18: =H18*I18 -> 0 | K18: =G18+J18 -> 143145 | M18: =+M17+K18-L18 -> 2898315.5
A19: 16 | B19: 46007 | G19: =E19*F19 -> 0 | H19: 0 | I19: 0 | J19: =H19*I19 -> 0 | K19: =G19+J19 -> 0 | L19: 2755171 | M19: =+M18+K19-L19 -> 143144.5
A20: 17 | B20: 46008 | E20: 2400 | F20: 95.43 | G20: =E20*F20 -> 229032 | H20: 0 | I20: 0 | J20: =H20*I20 -> 0 | K20: =G20+J20 -> 229032 | M20: =+M19+K20-L20 -> 372176.5
A21: 18 | B21: 46009 | G21: =E21*F21 -> 0 | H21: 0 | I21: 0 | J21: =H21*I21 -> 0 | K21: =G21+J21 -> 0 | M21: =+M20+K21-L21 -> 372176.5
A22: 19 | B22: 46010 | E22: 2000 | F22: 95.43 | G22: =E22*F22 -> 190860 | H22: 0 | I22: 0 | J22: =H22*I22 -> 0 | K22: =G22+J22 -> 190860 | M22: =+M21+K22-L22 -> 563036.5
A23: 20 | B23: 46011 | G23: =E23*F23 -> 0 | H23: 0 | I23: 0 | J23: =H23*I23 -> 0 | K23: =G23+J23 -> 0 | M23: =+M22+K23-L23 -> 563036.5
A24: 21 | B24: 46012 | E24: 1500 | F24: 95.43 | G24: =E24*F24 -> 143145 | H24: 0 | I24: 0 | J24: =H24*I24 -> 0 | K24: =G24+J24 -> 143145 | M24: =+M23+K24-L24 -> 706181.5
A25: 22 | B25: 46013 | G25: =E25*F25 -> 0 | H25: 0 | I25: 0 | J25: =H25*I25 -> 0 | K25: =G25+J25 -> 0 | M25: =+M24+K25-L25 -> 706181.5
A26: 23 | B26: 46014 | E26: 1000 | F26: 95.43 | G26: =E26*F26 -> 95430 | H26: 0 | I26: 0 | J26: =H26*I26 -> 0 | K26: =G26+J26 -> 95430 | M26: =+M25+K26-L26 -> 801611.5
A27: 24 | B27: 46015 | G27: =E27*F27 -> 0 | H27: 0 | I27: 0 | J27: =H27*I27 -> 0 | K27: =G27+J27 -> 0 | M27: =+M26+K27-L27 -> 801611.5
A28: 25 | B28: 46016 | G28: =E28*F28 -> 0 | H28: 0 | I28: 0 | J28: =H28*I28 -> 0 | K28: =G28+J28 -> 0 | M28: =+M27+K28-L28 -> 801611.5
A29: 26 | B29: 46017 | E29: 1700 | F29: 95.43 | G29: =E29*F29 -> 162231 | H29: 0 | I29: 0 | J29: =H29*I29 -> 0 | K29: =G29+J29 -> 162231 | M29: =+M28+K29-L29 -> 963842.5
A30: 27 | B30: 46018 | E30: 0 | G30: =E30*F30 -> 0 | H30: 0 | I30: 0 | J30: =H30*I30 -> 0 | K30: =G30+J30 -> 0 | M30: =+M29+K30-L30 -> 963842.5
A31: 28 | B31: 46019 | E31: 1000 | F31: 95.43 | G31: =E31*F31 -> 95430 | H31: 0 | I31: 0 | J31: =H31*I31 -> 0 | K31: =G31+J31 -> 95430 | M31: =+M30+K31-L31 -> 1059272.5
A32: 29 | B32: 46020 | G32: =E32*F32 -> 0 | H32: 0 | I32: 0 | J32: =H32*I32 -> 0 | K32: =G32+J32 -> 0 | M32: =+M31+K32-L32 -> 1059272.5
A33: 30 | B33: 46021 | E33: 1300 | F33: 95.43 | G33: =E33*F33 -> 124059 | H33: 0 | I33: 0 | J33: =H33*I33 -> 0 | K33: =G33+J33 -> 124059 | M33: =+M32+K33-L33 -> 1183331.5
A34: 31 | B34: 46022 | G34: =E34*F34 -> 0 | H34: 0 | I34: 0 | J34: =H34*I34 -> 0 | K34: =G34+J34 -> 0 | L34: 0 | M34: =+M33+K34-L34 -> 1183331.5
E35: =SUM(E4:E34) -> 22000 | G35: =SUM(G4:G34) -> 2099460 | H35: =SUM(H4:H34) -> 0 | J35: =SUM(J4:J34) -> 0 | K35: =SUM(K4:K34) -> 2099460 | L35: =SUM(L4:L34) -> 2755171
F38: /

Sheet Jadcherla-4
A1: Shree Poornima F/S
A2: S.No | B2: Date | C2: GRN No | D2: Ind No/Bill No | E2: Diesel (Lts) | F2: Price | G2: Amount | H2: Petrol (Lts) | I2: Price | J2: Amount | K2: Total amount | L2: Amount paid | M2: As on date | N2: Remarks
A3: Opening Balance | M3: 0
A4: 1 | B4: 45992 | G4: =E4*F4 -> 0 | H4: 0 | I4: 0 | J4: =H4*I4 -> 0 | K4: =G4+J4 -> 0 | L4: 0 | M4: =M3+K4-L4 -> 0
A5: 2 | B5: 45993 | G5: =E5*F5 -> 0 | H5: 0 | I5: 0 | J5: =H5*I5 -> 0 | K5: =G5+J5 -> 0 | L5: 0 | M5: =M4+K5-L5 -> 0
A6: 3 | B6: 45994 | G6: =E6*F6 -> 0 | H6: 0 | I6: 0 | J6: =H6*I6 -> 0 | K6: =G6+J6 -> 0 | L6: 0 | M6: =M5+K6-L6 -> 0
A7: 4 | B7: 45995 | G7: =E7*F7 -> 0 | H7: 0 | I7: 0 | J7: =H7*I7 -> 0 | K7: =G7+J7 -> 0 | L7: 0 | M7: =M6+K7-L7 -> 0
A8: 5 | B8: 45996 | G8: =E8*F8 -> 0 | H8: 0 | I8: 0 | J8: =H8*I8 -> 0 | K8: =G8+J8 -> 0 | L8: 0 | M8: =M7+K8-L8 -> 0
A9: 6 | B9: 45997 | G9: =E9*F9 -> 0 | H9: 0 | I9: 0 | J9: =H9*I9 -> 0 | K9: =G9+J9 -> 0 | L9: 0 | M9: =M8+K9-L9 -> 0
A10: 7 | B10: 45998 | G10: =E10*F10 -> 0 | H10: 0 | I10: 0 | J10: =H10*I10 -> 0 | K10: =G10+J10 -> 0 | L10: 0 | M10: =M9+K10-L10 -> 0
A11: 8 | B11: 45999 | G11: =E11*F11 -> 0 | H11: 0 | I11: 0 | J11: =H11*I11 -> 0 | K11: =G11+J11 -> 0 | L11: 0 | M11: =M10+K11-L11 -> 0
A12: 9 | B12: 46000 | G12: =E12*F12 -> 0 | H12: 0 | I12: 0 | K12: =G12+J12 -> 0 | L12: 0 | M12: =M11+K12-L12 -> 0
A13: 10 | B13: 46001 | G13: =E13*F13 -> 0 | H13: 0 | I13: 0 | K13: =G13+J13 -> 0 | L13: 0 | M13: =M12+K13-L13 -> 0
A14: 11 | B14: 46002 | G14: =E14*F14 -> 0 | H14: 0 | I14: 0 | K14: =G14+J14 -> 0 | L14: 0 | M14: =M13+K14-L14 -> 0
A15: 12 | B15: 46003 | G15: =E15*F15 -> 0 | H15: 0 | I15: 0 | K15: =G15+J15 -> 0 | L15: 0 | M15: =M14+K15-L15 -> 0
A16: 13 | B16: 46004 | G16: =E16*F16 -> 0 | H16: 0 | I16: 0 | J16: =H16*I16 -> 0 | K16: =G16+J16 -> 0 | L16: 0 | M16: =M15+K16-L16 -> 0
A17: 14 | B17: 46005 | G17: =E17*F17 -> 0 | H17: 0 | I17: 0 | J17: =H17*I17 -> 0 | K17: =G17+J17 -> 0 | L17: 0 | M17: =M16+K17-L17 -> 0
A18: 15 | B18: 46006 | G18: =E18*F18 -> 0 | H18: 0 | I18: 0 | J18: =H18*I18 -> 0 | K18: =G18+J18 -> 0 | L18: 0 | M18: =M17+K18-L18 -> 0
A19: 16 | B19: 46007 | G19: =E19*F19 -> 0 | H19: 0 | I19: 0 | J19: =H19*I19 -> 0 | K19: =G19+J19 -> 0 | L19: 0 | M19: =M18+K19-L19 -> 0
A20: 17 | B20: 46008 | G20: =E20*F20 -> 0 | H20: 0 | I20: 0 | J20: =H20*I20 -> 0 | K20: =G20+J20 -> 0 | L20: 0 | M20: =M19+K20-L20 -> 0
A21: 18 | B21: 46009 | G21: =E21*F21 -> 0 | H21: 0 | I21: 0 | J21: =H21*I21 -> 0 | K21: =G21+J21 -> 0 | L21: 0 | M21: =M20+K21-L21 -> 0
A22: 19 | B22: 46010 | G22: =E22*F22 -> 0 | H22: 0 | I22: 0 | J22: =H22*I22 -> 0 | K22: =G22+J22 -> 0 | L22: 0 | M22: =M21+K22-L22 -> 0
A23: 20 | B23: 46011 | G23: =E23*F23 -> 0 | H23: 0 | I23: 0 | J23: =H23*I23 -> 0 | K23: =G23+J23 -> 0 | L23: 0 | M23: =M22+K23-L23 -> 0
A24: 21 | B24: 46012 | G24: =E24*F24 -> 0 | H24: 0 | I24: 0 | J24: =H24*I24 -> 0 | K24: =G24+J24 -> 0 | L24: 0 | M24: =M23+K24-L24 -> 0
A25: 22 | B25: 46013 | G25: =E25*F25 -> 0 | H25: 0 | I25: 0 | J25: =H25*I25 -> 0 | K25: =G25+J25 -> 0 | L25: 0 | M25: =M24+K25-L25 -> 0
A26: 23 | B26: 46014 | E26: 0 | F26: 0 | G26: =E26*F26 -> 0 | H26: 50 | I26: 108.1 | J26: =H26*I26 -> 5405 | K26: =G26+J26 -> 5405 | L26: 0 | M26: =M25+K26-L26 -> 5405
A27: 24 | B27: 46015 | G27: =E27*F27 -> 0 | H27: 0 | I27: 0 | J27: =H27*I27 -> 0 | K27: =G27+J27 -> 0 | L27: 0 | M27: =M26+K27-L27 -> 5405
A28: 25 | B28: 46016 | G28: =E28*F28 -> 0 | H28: 0 | I28: 0 | J28: =H28*I28 -> 0 | K28: =G28+J28 -> 0 | L28: 0 | M28: =M27+K28-L28 -> 5405
A29: 26 | B29: 46017 | G29: =E29*F29 -> 0 | H29: 0 | I29: 0 | J29: =H29*I29 -> 0 | K29: =G29+J29 -> 0 | L29: 0 | M29: =M28+K29-L29 -> 5405
A30: 27 | B30: 46018 | G30: =E30*F30 -> 0 | H30: 0 | I30: 0 | J30: =H30*I30 -> 0 | K30: =G30+J30 -> 0 | L30: 0 | M30: =M29+K30-L30 -> 5405
A31: 28 | B31: 46019 | G31: =E31*F31 -> 0 | J31: =H31*I31 -> 0 | K31: =G31+J31 -> 0 | M31: =M30+K31-L31 -> 5405
A32: 28 | B32: 46020 | G32: =E32*F32 -> 0 | J32: =H32*I32 -> 0 | K32: =G32+J32 -> 0 | M32: =M31+K32-L32 -> 5405
A33: 28 | B33: 46021 | G33: =E33*F33 -> 0 | J33: =H33*I33 -> 0 | K33: =G33+J33 -> 0 | M33: =M32+K33-L33 -> 5405
A34: 28 | B34: 46022 | G34: =E34*F34 -> 0 | J34: =H34*I34 -> 0 | K34: =G34+J34 -> 0 | M34: =M33+K34-L34 -> 5405
E35: =SUM(E4:E34) -> 0 | G35: =SUM(G4:G34) -> 0 | H35: =SUM(H4:H34) -> 50 | J35: =SUM(J4:J34) -> 5405 | K35: =SUM(K4:K34) -> 5405 | L35: =SUM(L4:L34) -> 0

Sheet Devarakhadra
A1: Kurumurthy Swami F/S
A2: S.No | B2: Date | C2: GRN No | D2: Ind no/Bill No | E2: Diesel (Lts) | F2: Price | G2: Amount | H2: Petrol (Lts) | I2: Price | J2: Amount | K2: Total amount | L2: Amount paid | M2: As on Date | N2: Remarks
A3: Opening Balance | M3: 34600.433 | O3: 121213.37
A4: 1 | B4: 45992 | E4: 93.4 | F4: 97.1 | G4: =E4*F4 -> 9069.14 | J4: =H4*I4 -> 0 | K4: =G4+J4 -> 9069.14 | M4: =+M3+K4-L4 -> 43669.573
A5: 2 | B5: 45993 | G5: =E5*F5 -> 0 | J5: =H5*I5 -> 0 | K5: =G5+J5 -> 0 | M5: =+M4+K5-L5 -> 43669.573
A6: 3 | B6: 45994 | G6: =E6*F6 -> 0 | J6: =H6*I6 -> 0 | K6: =G6+J6 -> 0 | M6: =+M5+K6-L6 -> 43669.573
A7: 4 | B7: 45995 | E7: 35 | F7: 97.1 | G7: =E7*F7 -> 3398.5 | J7: =H7*I7 -> 0 | K7: =G7+J7 -> 3398.5 | M7: =+M6+K7-L7 -> 47068.073
A8: 5 | B8: 45996 | G8: =E8*F8 -> 0 | J8: =H8*I8 -> 0 | K8: =G8+J8 -> 0 | M8: =+M7+K8-L8 -> 47068.073
A9: 6 | B9: 45997 | E9: 39 | F9: 97.1 | G9: =E9*F9 -> 3786.9 | J9: =H9*I9 -> 0 | K9: =G9+J9 -> 3786.9 | M9: =+M8+K9-L9 -> 50854.973
A10: 7 | B10: 45998 | G10: =E10*F10 -> 0 | J10: =H10*I10 -> 0 | K10: =G10+J10 -> 0 | M10: =+M9+K10-L10 -> 50854.973
A11: 8 | B11: 45999 | G11: =E11*F11 -> 0 | H11: 5 | I11: 108.93 | J11: =H11*I11 -> 544.65 | K11: =G11+J11 -> 544.65 | M11: =+M10+K11-L11 -> 51399.623
A12: 9 | B12: 46000 | G12: =E12*F12 -> 0 | J12: =H12*I12 -> 0 | K12: =G12+J12 -> 0 | M12: =+M11+K12-L12 -> 51399.623
A13: 10 | B13: 46001 | G13: =E13*F13 -> 0 | J13: =H13*I13 -> 0 | K13: =G13+J13 -> 0 | M13: =+M12+K13-L13 -> 51399.623
A14: 11 | B14: 46002 | E14: 37.28 | F14: 97.1 | G14: =E14*F14 -> 3619.888 | H14: 5 | I14: 108.83 | J14: =H14*I14 -> 544.15 | K14: =G14+J14 -> 4164.038 | M14: =+M13+K14-L14 -> 55563.661
A15: 12 | B15: 46003 | G15: =E15*F15 -> 0 | J15: =H15*I15 -> 0 | K15: =G15+J15 -> 0 | M15: =+M14+K15-L15 -> 55563.661
A16: 13 | B16: 46004 | G16: =E16*F16 -> 0 | H16: 5 | I16: 108.83 | J16: =H16*I16 -> 544.15 | K16: =G16+J16 -> 544.15 | M16: =+M15+K16-L16 -> 56107.811
A17: 14 | B17: 46005 | G17: =E17*F17 -> 0 | J17: =H17*I17 -> 0 | K17: =G17+J17 -> 0 | M17: =+M16+K17-L17 -> 56107.811
A18: 15 | B18: 46006 | G18: =E18*F18 -> 0 | J18: =H18*I18 -> 0 | K18: =G18+J18 -> 0 | M18: =+M17+K18-L18 -> 56107.811
A19: 16 | B19: 46007 | G19: =E19*F19 -> 0 | J19: =H19*I19 -> 0 | K19: =G19+J19 -> 0 | L19: 55563 | M19: =+M18+K19-L19 -> 544.811 | N19: Fuel bills
A20: 17 | B20: 46008 | G20: =E20*F20 -> 0 | J20: =H20*I20 -> 0 | K20: =G20+J20 -> 0 | M20: =+M19+K20-L20 -> 544.811
A21: 18 | B21: 46009 | G21: =E21*F21 -> 0 | J21: =H21*I21 -> 0 | K21: =G21+J21 -> 0 | M21: =+M20+K21-L21 -> 544.811
A22: 19 | B22: 46010 | G22: =E22*F22 -> 0 | J22: =H22*I22 -> 0 | K22: =G22+J22 -> 0 | M22: =+M21+K22-L22 -> 544.811
A23: 20 | B23: 46011 | G23: =E23*F23 -> 0 | J23: =H23*I23 -> 0 | K23: =G23+J23 -> 0 | M23: =+M22+K23-L23 -> 544.811
A24: 21 | B24: 46012 | G24: =E24*F24 -> 0 | J24: =H24*I24 -> 0 | K24: =G24+J24 -> 0 | M24: =+M23+K24-L24 -> 544.811
A25: 22 | B25: 46013 | E25: 35 | F25: 97.1 | G25: =E25*F25 -> 3398.5 | J25: =H25*I25 -> 0 | K25: =G25+J25 -> 3398.5 | M25: =+M24+K25-L25 -> 3943.311
A26: 23 | B26: 46014 | G26: =E26*F26 -> 0 | J26: =H26*I26 -> 0 | K26: =G26+J26 -> 0 | M26: =+M25+K26-L26 -> 3943.311
A27: 24 | B27: 46015 | G27: =E27*F27 -> 0 | J27: =H27*I27 -> 0 | K27: =G27+J27 -> 0 | M27: =+M26+K27-L27 -> 3943.311
A28: 25 | B28: 46016 | G28: =E28*F28 -> 0 | H28: 5 | I28: 108.3 | J28: =H28*I28 -> 541.5 | K28: =G28+J28 -> 541.5 | M28: =+M27+K28-L28 -> 4484.811
A29: 26 | B29: 46017 | G29: =E29*F29 -> 0 | J29: =H29*I29 -> 0 | K29: =G29+J29 -> 0 | M29: =+M28+K29-L29 -> 4484.811
A30: 27 | B30: 46018 | G30: =E30*F30 -> 0 | J30: =H30*I30 -> 0 | K30: =G30+J30 -> 0 | M30: =+M29+K30-L30 -> 4484.811
A31: 28 | B31: 46019 | G31: =E31*F31 -> 0 | H31: 5 | I31: 108.3 | J31: =H31*I31 -> 541.5 | K31: =G31+J31 -> 541.5 | M31: =+M30+K31-L31 -> 5026.311
A32: 29 | B32: 46020 | G32: =E32*F32 -> 0 | J32: =H32*I32 -> 0 | K32: =G32+J32 -> 0 | M32: =+M31+K32-L32 -> 5026.311
A33: 30 | B33: 46021 | G33: =E33*F33 -> 0 | J33: =H33*I33 -> 0 | K33: =G33+J33 -> 0 | M33: =+M32+K33-L33 -> 5026.311
A34: 31 | B34: 46022 | G34: =E34*F34 -> 0 | J34: =H34*I34 -> 0 | K34: =G34+J34 -> 0 | M34: =+M33+K34-L34 -> 5026.311
E35: =SUM(E4:E34) -> 239.68 | G35: =SUM(G4:G34) -> 23272.928 | H35: =SUM(H4:H34) -> 25 | J35: =SUM(J4:J34) -> 2715.95 | K35: =SUM(K4:K34) -> 25988.878 | L35: =SUM(L4:L34) -> 55563

Sheet Devarakhadra-2
A1: JSASFuel Genie India Pvt.Ltd
A2: S.No | B2: Date | C2: GRN No | D2: Ind no/Bill No | E2: Diesel (Lts) | F2: Price | G2: Amount | H2: Petrol (Lts) | I2: Price | J2: Amount | K2: Total amount | L2: Amount paid | M2: As on Date | N2: Remarks
A3: Opening Balance | M3: 66053.768
A4: 1 | B4: 45992 | G4: =E4*F4 -> 0 | H4: 0 | I4: 0 | J4: =H4*I4 -> 0 | K4: =G4+J4 -> 0 | L4: 0 | M4: =+M3+K4-L4 -> 66053.768
A5: 2 | B5: 45993 | G5: =E5*F5 -> 0 | H5: 0 | I5: 0 | J5: =H5*I5 -> 0 | K5: =G5+J5 -> 0 | L5: 0 | M5: =+M4+K5-L5 -> 66053.768
A6: 3 | B6: 45994 | G6: =E6*F6 -> 0 | H6: 0 | I6: 0 | J6: =H6*I6 -> 0 | K6: =G6+J6 -> 0 | L6: 0 | M6: =+M5+K6-L6 -> 66053.768
A7: 4 | B7: 45995 | G7: =E7*F7 -> 0 | H7: 0 | I7: 0 | J7: =H7*I7 -> 0 | K7: =G7+J7 -> 0 | L7: 0 | M7: =+M6+K7-L7 -> 66053.768
A8: 5 | B8: 45996 | G8: =E8*F8 -> 0 | H8: 0 | I8: 0 | J8: =H8*I8 -> 0 | K8: =G8+J8 -> 0 | L8: 0 | M8: =+M7+K8-L8 -> 66053.768
A9: 6 | B9: 45997 | G9: =E9*F9 -> 0 | H9: 0 | I9: 0 | J9: =H9*I9 -> 0 | K9: =G9+J9 -> 0 | L9: 0 | M9: =+M8+K9-L9 -> 66053.768
A10: 7 | B10: 45998 | G10: =E10*F10 -> 0 | H10: 0 | I10: 0 | J10: =H10*I10 -> 0 | K10: =G10+J10 -> 0 | L10: 0 | M10: =+M9+K10-L10 -> 66053.768
A11: 8 | B11: 45999 | G11: =E11*F11 -> 0 | H11: 0 | I11: 0 | J11: =H11*I11 -> 0 | K11: =G11+J11 -> 0 | L11: 0 | M11: =+M10+K11-L11 -> 66053.768
A12: 9 | B12: 46000 | G12: =E12*F12 -> 0 | H12: 0 | I12: 0 | J12: =H12*I12 -> 0 | K12: =G12+J12 -> 0 | L12: 0 | M12: =+M11+K12-L12 -> 66053.768
A13: 10 | B13: 46001 | G13: =E13*F13 -> 0 | H13: 0 | I13: 0 | J13: =H13*I13 -> 0 | K13: =G13+J13 -> 0 | L13: 0 | M13: =+M12+K13-L13 -> 66053.768
A14: 11 | B14: 46002 | G14: =E14*F14 -> 0 | H14: 0 | I14: 0 | J14: =H14*I14 -> 0 | K14: =G14+J14 -> 0 | L14: 0 | M14: =+M13+K14-L14 -> 66053.768
A15: 12 | B15: 46003 | G15: =E15*F15 -> 0 | H15: 0 | I15: 0 | J15: =H15*I15 -> 0 | K15: =G15+J15 -> 0 | L15: 0 | M15: =+M14+K15-L15 -> 66053.768
A16: 13 | B16: 46004 | G16: =E16*F16 -> 0 | H16: 0 | I16: 0 | J16: =H16*I16 -> 0 | K16: =G16+J16 -> 0 | L16: 0 | M16: =+M15+K16-L16 -> 66053.768
A17: 14 | B17: 46005 | H17: 0 | I17: 0 | J17: =H17*I17 -> 0 | K17: =G17+J17 -> 0 | L17: 0 | M17: =+M16+K17-L17 -> 66053.768
A18: 15 | B18: 46006 | H18: 0 | I18: 0 | J18: =H18*I18 -> 0 | K18: =G18+J18 -> 0 | L18: 66053.77 | M18: =+M17+K18-L18 -> -0.0015
A19: 16 | B19: 46007 | H19: 0 | I19: 0 | J19: =H19*I19 -> 0 | K19: =G19+J19 -> 0 | L19: 0 | M19: =+M18+K19-L19 -> -0.0015
A20: 17 | B20: 46008 | G20: =E20*F20 -> 0 | H20: 0 | I20: 0 | J20: =H20*I20 -> 0 | K20: =G20+J20 -> 0 | L20: 0 | M20: =+M19+K20-L20 -> -0.0015
A21: 18 | B21: 46009 | G21: =E21*F21 -> 0 | H21: 0 | I21: 0 | J21: =H21*I21 -> 0 | K21: =G21+J21 -> 0 | L21: 0 | M21: =+M20+K21-L21 -> -0.0015
A22: 19 | B22: 46010 | G22: =E22*F22 -> 0 | H22: 0 | I22: 0 | J22: =H22*I22 -> 0 | K22: =G22+J22 -> 0 | L22: 0 | M22: =+M21+K22-L22 -> -0.0015
A23: 20 | B23: 46011 | G23: =E23*F23 -> 0 | H23: 0 | I23: 0 | J23: =H23*I23 -> 0 | K23: =G23+J23 -> 0 | L23: 0 | M23: =+M22+K23-L23 -> -0.0015
A24: 21 | B24: 46012 | G24: =E24*F24 -> 0 | H24: 0 | I24: 0 | J24: =H24*I24 -> 0 | K24: =G24+J24 -> 0 | L24: 0 | M24: =+M23+K24-L24 -> -0.0015
A25: 22 | B25: 46013 | G25: =E25*F25 -> 0 | H25: 0 | I25: 0 | J25: =H25*I25 -> 0 | K25: =G25+J25 -> 0 | L25: 0 | M25: =+M24+K25-L25 -> -0.0015
A26: 23 | B26: 46014 | G26: =E26*F26 -> 0 | H26: 0 | I26: 0 | J26: =H26*I26 -> 0 | K26: =G26+J26 -> 0 | L26: 0 | M26: =+M25+K26-L26 -> -0.0015
A27: 24 | B27: 46015 | G27: =E27*F27 -> 0 | H27: 0 | I27: 0 | J27: =H27*I27 -> 0 | K27: =G27+J27 -> 0 | L27: 0 | M27: =+M26+K27-L27 -> -0.0015
A28: 25 | B28: 46016 | G28: =E28*F28 -> 0 | H28: 0 | I28: 0 | J28: =H28*I28 -> 0 | K28: =G28+J28 -> 0 | L28: 0 | M28: =+M27+K28-L28 -> -0.0015
A29: 26 | B29: 46017 | G29: =E29*F29 -> 0 | H29: 0 | I29: 0 | J29: =H29*I29 -> 0 | K29: =G29+J29 -> 0 | L29: 0 | M29: =+M28+K29-L29 -> -0.0015
A30: 27 | B30: 46018 | G30: =E30*F30 -> 0 | H30: 0 | I30: 0 | J30: =H30*I30 -> 0 | K30: =G30+J30 -> 0 | L30: 0 | M30: =+M29+K30-L30 -> -0.0015
A31: 28 | B31: 46019 | G31: =E31*F31 -> 0 | H31: 0 | I31: 0 | J31: =H31*I31 -> 0 | K31: =G31+J31 -> 0 | L31: 0 | M31: =+M30+K31-L31 -> -0.0015
... A34: 31 | B34: 46022 | G34: =E34*F34 -> 0 | H34: 0 | I34: 0 | J34: =H34*I34 -> 0 | K34: =G34+J34 -> 0 | L34: 0 | M34: =+M33+K34-L34 -> -0.0015
E35: =SUM(E4:E34) -> 0 | G35: =SUM(G4:G34) -> 0 | H35: =SUM(H4:H34) -> 0 | J35: =SUM(J4:J34) -> 0 | K35: =SUM(K4:K34) -> 0 | L35: =SUM(L4:L34) -> 66053.77
F38: /

Sheet Dindi
A1: Akarapu Balakistamma Fillling
A2: S.No | B2: Date | C2: GRN No | D2: Ind no/Bill No | E2: Diesel (Lts) | F2: Price | G2: Amount | H2: Petrol (Lts) | I2: Price | J2: Amount | K2: Total amount | L2: Amount paid | M2: As on Date | N2: Remarks
A3: Opening Balance | M3: 0
A4: 1 | B4: 45992 | G4: =E4*F4 -> 0 | H4: 0 | I4: 0 | J4: =H4*I4 -> 0 | K4: =G4+J4 -> 0 | L4: =+K4 -> 0 | M4: 0
A5: 2 | B5: 45993 | G5: =E5*F5 -> 0 | H5: 0 | I5: 0 | J5: =H5*I5 -> 0 | K5: =G5+J5 -> 0 | L5: =+K5 -> 0 | M5: 0
A6: 3 | B6: 45994 | G6: =E6*F6 -> 0 | H6: 0 | I6: 0 | J6: =H6*I6 -> 0 | K6: =G6+J6 -> 0 | L6: =+K6 -> 0 | M6: 0
A7: 4 | B7: 45995 | G7: =E7*F7 -> 0 | H7: 0 | I7: 0 | J7: =H7*I7 -> 0 | K7: =G7+J7 -> 0 | L7: =+K7 -> 0 | M7: 0
A8: 5 | B8: 45996 | G8: =E8*F8 -> 0 | H8: 0 | I8: 0 | J8: =H8*I8 -> 0 | K8: =G8+J8 -> 0 | L8: =+K8 -> 0 | M8: 0
A9: 6 | B9: 45997 | G9: =E9*F9 -> 0 | H9: 0 | I9: 0 | J9: =H9*I9 -> 0 | K9: =G9+J9 -> 0 | L9: =+K9 -> 0 | M9: 0
A10: 7 | B10: 45998 | G10: =E10*F10 -> 0 | H10: 0 | I10: 0 | J10: =H10*I10 -> 0 | K10: =G10+J10 -> 0 | L10: =+K10 -> 0 | M10: 0
