Workbook

Sheet  Aug-25 
A1: S.no | B1: Site Name | C1: Bunk Name | D1: Diesel(Liters) | E1: Diesel Amount | F1: Petrol(Liters) | G1: Petrol Amount | H1: Total Amount | I1: Opening Blance | J1: Amount Paid | K1: Closing Balances
A2: 1 | B2: Khammam-1 | C2: Divya laxmi ganapathi | D2: =+'Khammam-1'!E38 -> 66910.82 | E2: =+'Khammam-1'!G38 -> 6401975.3 | F2: =+'Khammam-1'!H38 -> 480 | G2: =+'Khammam-1'!J38 -> 51580.8 | H2: =E2+G2 -> 6453556.1 | I2: =+'Khammam-1'!K3 -> 14609947 | J2: =+'Khammam-1'!L38 -> 10000000 | K2: =H2+I2-J2 -> 11063503
A3: 2 | B3: Khammam-2 | C3: Jayasai union bunk | D3: =+'Khammam-2'!E35 -> 94406.49 | E3: =+'Khammam-2'!G35 -> 9034701.1 | F3: =+'Khammam-2'!H35 -> 470 | G3: =+'Khammam-2'!J35 -> 50515.6 | H3: =E3+G3 -> 9085216.7 | I3: =+'Khammam-2'!K3 -> 12663588 | J3: =+'Khammam-2'!L35 -> 10000000 | K3: =H3+I3-J3 -> 11748805
A4: 3 | B4: Jadcherla-1 | C4: Sai Baba Fuel Station | D4: =+'Jedcherla -1'!E36 -> 38219.44 | E4: =+'Jedcherla -1'!G36 -> 3685118.4 | F4: =+'Jedcherla -1'!H36 -> 472.1 | G4: =+'Jedcherla -1'!J36 -> 51095.383 | H4: =E4+G4 -> 3736213.8 | I4: =+'Jedcherla -1'!M3 -> 1388015.3 | J4: =+'Jedcherla -1'!L36 -> 1288000 | K4: =H4+I4-J4 -> 3836229.1
A5: 4 | B5: Jadcherla-2 | C5: ADHOC FILLING STATION STATION | D5: =+'Jedcharla-2'!E35 -> 0 | E5: =+'Jedcharla-2'!G35 -> 0 | F5: 0 | G5: 0 | H5: =E5+G5 -> 0 | I5: =+'Jedcharla-2'!K3 -> 1400599.6 | J5: =+'Jedcharla-2'!L35 -> 1400600 | K5: =H5+I5-J5 -> -0.4242
A6: 5 | B6: Sangareddy-1 | C6: Sree Shiva Parvathi Filling Station | D6: =+Sangareddy!E40 -> 0 | E6: =+Sangareddy!G40 -> 0 | F6: =+Sangareddy!H40 -> 0 | G6: =+Sangareddy!J40 -> 0 | H6: =E6+G6 -> 0 | I6: =+Sangareddy!K3 -> 0 | J6: =+Sangareddy!L40 -> 0 | K6: =H6+I6-J6 -> 0
A7: 6 | B7: Dindi | C7: Akarapu Balakistamma Fillling | D7: =+Dindi!E35 -> 176.65 | E7: =+Dindi!G35 -> 17065.626 | F7: =+Dindi!H35 -> 25 | G7: =+Dindi!J35 -> 2729 | H7: =E7+G7 -> 19794.626 | J7: =+Dindi!L35 -> 19794.626 | K7: =H7+I7-J7 -> 0
A8: 7 | B8: Devarkhadra-1 | C8: Kurumurthy Swami F/S | D8: =+Devarakhadra!E35 -> 12052.63 | E8: =+Devarakhadra!G35 -> 1170310.4 | F8: =+Devarakhadra!H35 -> 108 | G8: =+Devarakhadra!J35 -> 11753.64 | H8: =E8+G8 -> 1182064 | I8: =+Devarakhadra!M3 -> 580925.58 | J8: =+Devarakhadra!L35 -> 1200000 | K8: =H8+I8-J8 -> 562989.59
A9: 8 | B9: Devarkhadra-2 | C9: M/S. Sri Rama Filling Station | D9: =+'Devarakhadra-2'!E35 -> 1380.16 | E9: =+'Devarakhadra-2'!G35 -> 134013.54 | F9: =+'Devarakhadra-2'!H35 -> 0 | G9: =+'Devarakhadra-2'!I35 -> 0 | H9: =E9+G9 -> 134013.54 | I9: =+'Devarakhadra-2'!M3 -> 0 | J9: =+'Devarakhadra-2'!L35 -> 0 | K9: =H9+I9-J9 -> 134013.54
A10: 9 | B10: Amalapuram | C10: Sathya Filling Station | D10: =+Amalapuram!E35 -> 224.73 | E10: =+Amalapuram!G35 -> 21892.275 | F10: =+Amalapuram!H35 -> 74.19 | G10: =+Amalapuram!J35 -> 8122.7237 | H10: =E10+G10 -> 30014.999 | I10: =+Amalapuram!M3 -> 0 | J10: =+Amalapuram!L35 -> 30014.994 | K10: =H10+I10-J10 -> 0.0045
A11: 10 | B11: YG Gudda-1 | C11: Pallavi Petrolium | D11: =+'YG Gudda '!E36 -> 4400 | E11: =+'YG Gudda '!G36 -> 401720 | F11: =+'YG Gudda '!H36 -> 315 | G11: =+'YG Gudda '!J36 -> 32520.6 | H11: =E11+G11 -> 434240.6 | I11: ='YG Gudda '!K3 -> 99992.615 | J11: =+'YG Gudda '!L36 -> 250000 | K11: =H11+I11-J11 -> 284233.21
A12: 11 | B12: YG Gudda-2 | C12: Pankaja HP Fuel Center | D12: =+'YG Gudda-2'!E36 -> 4800 | E12: =+'YG Gudda-2'!G36 -> 438384 | F12: =+'YG Gudda-2'!H36 -> 210 | G12: =+'YG Gudda-2'!J36 -> 21686.7 | H12: =E12+G12 -> 460070.7 | I12: =+'YG Gudda-2'!M3 -> 0 | J12: =+'YG Gudda-2'!L36 -> 230000 | K12: =H12+I12-J12 -> 230070.7
A13: 12 | B13: Hosadurga-1 | C13: Merchant Petroliums | D13: =+Hosadurga!E35 -> 0 | E13: =+Hosadurga!G35 -> 0 | F13: =+Hosadurga!H35 -> 70 | G13: =+Hosadurga!J35 -> 7279.3 | H13: =E13+G13 -> 7279.3 | I13: =+Hosadurga!K3 -> 0 | J13: =+Hosadurga!L35 -> 0 | K13: =H13+I13-J13 -> 7279.3
A14: 13 | B14: Hosadurga-2 | C14: Shree Veeraprathap Fuel | D14: =+'Hosadurga -2'!E35 -> 6000 | E14: =+'Hosadurga -2'!G35 -> 549300 | F14: =+'Hosadurga -2'!H35 -> 210 | G14: =+'Hosadurga -2'!J35 -> 21783.3 | H14: =+'Hosadurga -2'!K35 -> 571083.3 | I14: =+'Hosadurga -2'!K3 -> 618231.25 | J14: =+'Hosadurga -2'!L35 -> 750000 | K14: =H14+I14-J14 -> 439314.55
A15: 14 | B15: Malebennuru(KUWSDB) | C15: Sri Ramanjuneya Service Station | D15: =+'Malebenur(KUWSDB)'!E36 -> 5316.78 | E15: =+'Malebenur(KUWSDB)'!G36 -> 490526.12 | F15: =+'Malebenur(KUWSDB)'!H36 -> 210 | G15: =+'Malebenur(KUWSDB)'!J36 -> 21867.3 | H15: =E15+G15 -> 512393.42 | I15: =+'Malebenur(KUWSDB)'!K3 -> 46138.764 | J15: =+'Malebenur(KUWSDB)'!L36 -> 366722.67 | K15: =H15+I15-J15 -> 191809.52
A16: 15 | B16: kadur | C16: Vishal Service Station | D16: =+Kadur!E35 -> 0 | E16: =+Kadur!G35 -> 0 | F16: =+Kadur!H35 -> 110 | G16: =+Kadur!J35 -> 11469.7 | H16: =E16+G16 -> 11469.7 | I16: =+Kadur!K3 -> 405569.43 | J16: =+Kadur!L35 -> 0 | K16: =H16+I16-J16 -> 417039.13
A17: 16 | B17: Hiriyur(VJNL) | C17: Sri Balaji Agencies | D17: =+'Hiriyur(VJNL)'!E35 -> 4300 | E17: =+'Hiriyur(VJNL)'!G35 -> 396718 | F17: =+'Hiriyur(VJNL)'!H35 -> 175 | G17: =+'Hiriyur(VJNL)'!J35 -> 18224.5 | H17: =E17+G17 -> 414942.5 | I17: =+'Hiriyur(VJNL)'!K3 -> 26749.8 | J17: =+'Hiriyur(VJNL)'!L35 -> 249700 | K17: =H17+I17-J17 -> 191992.3
A18: 17 | B18: Chellakere(KUWSDB) | C18: Sri Vishnu Baba Petroleum | D18: =+'Chellakere (KUWSDB)'!E35 -> 2909.69 | E18: =+'Chellakere (KUWSDB)'!G35 -> 268383.71 | F18: =+'Chellakere (KUWSDB)'!H35 -> 130 | G18: =+'Chellakere (KUWSDB)'!J35 -> 13536.9 | H18: =E18+G18 -> 281920.61 | I18: 0 | J18: =+'Chellakere (KUWSDB)'!L35 -> 281920.61 | K18: =H18+I18-J18 -> 0
A19: 18 | B19: Molakalmuru | C19: Sri Lakshmi Venkateshwara Filling Station | D19: =+Molakamuru!E35 -> 1212.59 | E19: =+Molakamuru!G35 -> 111839.05 | F19: =+Molakamuru!H35 -> 44.96 | G19: =+Molakamuru!J35 -> 4680.2043 | H19: =E19+G19 -> 116519.25 | I19: =+Molakamuru!K3 -> 0 | J19: =+Molakamuru!L35 -> 116519.25 | K19: =H19+I19-J19 -> 0
A20: 19 | B20: Khanapur(PKG-3) | C20: J K Makavi | D20: =+Khanapur!E35 -> 60 | E20: =+Khanapur!G35 -> 5452.8 | F20: =+Khanapur!H35 -> 23.91 | G20: =+Khanapur!J35 -> 2457.2307 | H20: =E20+G20 -> 7910.0307 | I20: 0 | J20: =+Khanapur!M35 -> 7910.0307 | K20: =H20+I20-J20 -> 0
A21: 20 | B21: Munavalli(PKG-3)-2 | C21: Shri Daneshwari | D21: =+'Munavali-2'!E37 -> 7155.15 | E21: =+'Munavali-2'!G37 -> 653398.44 | F21: =+'Munavali-2'!H37 -> 145 | G21: =+'Munavali-2'!J37 -> 14969.8 | H21: =E21+G21 -> 668368.24 | I21: =+'Munavali-2'!M3 -> 26506.4 | J21: =+'Munavali-2'!L37 -> 215000.41 | K21: =H21+I21-J21 -> 479874.23
A22: 21 | B22: Borgaon(PKG-3) | C22: Aadisagar Petrolium | D22: =+Borgaon!E35 -> 839.25 | E22: =+Borgaon!G35 -> 77017.973 | F22: =+Borgaon!H35 -> 53 | G22: =+Borgaon!J35 -> 5532.8 | H22: =E22+G22 -> 82550.773 | I22: =+Borgaon!K3 -> 29694.836 | J22: =+Borgaon!L35 -> 73270 | K22: =H22+I22-J22 -> 38975.608
A23: 22 | B23: Ugar,Kudichi(PKG-3) | C23: Shiri Bhrhmanath Petrolium | D23: =+'Ugar,Khagwad,Kudichi'!E35 -> 4077.58 | E23: =+'Ugar,Khagwad,Kudichi'!G35 -> 374851.93 | F23: =+'Ugar,Khagwad,Kudichi'!H35 -> 297 | G23: =+'Ugar,Khagwad,Kudichi'!J35 -> 30855.33 | H23: =E23+G23 -> 405707.26 | I23: =+'Ugar,Khagwad,Kudichi'!M3 -> 21188.98 | J23: =+'Ugar,Khagwad,Kudichi'!L35 -> 150000 | K23: =H23+I23-J23 -> 276896.24
A24: 23 | B24: Kabbur(PKG-3) | C24: Shri Jai Hanuman Petrolium | D24: =+Kabbur!E35 -> 462 | E24: =+Kabbur!G35 -> 42314.58 | F24: =+Kabbur!H35 -> 29.66 | G24: =+Kabbur!J35 -> 3070.6998 | H24: =E24+G24 -> 45385.28 | I24: 0 | J24: =+Kabbur!L35 -> 45385.28 | K24: =H24+I24-J24 -> 0
A25: 24 | B25: Kumta (PKG-1) | C25: Krishma fuel station | D25: =+kumta!E35 -> 541.82 | E25: =+kumta!G35 -> 49804.094 | F25: =+kumta!H35 -> 58.99 | G25: =+kumta!J35 -> 6132.6004 | H25: =E25+G25 -> 55936.695 | I25: 0 | J25: =+kumta!L35 -> 55936.695 | K25: =H25+I25-J25 -> 0
A26: 25 | B26: Jalgaon | C26: Sri Sai Petrol Pump | D26: =+Jalgaon!E44 -> 2780.66 | E26: =+Jalgaon!G44 -> 255051.58 | F26: =+Jalgaon!H44 -> 27.1 | G26: =+Jalgaon!J44 -> 2850.649 | H26: =E26+G26 -> 257902.22 | I26: =+Jalgaon!K3 -> 50163.215 | J26: =+Jalgaon!L44 -> 92300.319 | K26: =H26+I26-J26 -> 215765.12
A27: 26 | B27: MKBD | C27: Shree Sai Samarth Petroleum | D27: =+MKBD!E36 -> 1520 | E27: =+MKBD!G36 -> 138802 | F27: =+MKBD!H36 -> 40 | G27: =+MKBD!J36 -> 4184 | H27: =E27+G27 -> 142986 | I27: =+MKBD!K3 -> 1198639.6 | J27: =+MKBD!L36 -> 0 | K27: =H27+I27-J27 -> 1341625.6
A28: 27 | B28: Haveri | C28: Shivalingeshwar Petroleum | D28: =+Haveri!E35 -> 2742.88 | E28: =+Haveri!G35 -> 250808.57 | F28: =+Haveri!H35 -> 98.16 | G28: =+Haveri!J35 -> 10149.744 | H28: =E28+G28 -> 260958.32 | I28: =+Haveri!M3 -> 35526.318 | J28: =+Haveri!L35 -> 129940.78 | K28: =H28+I28-J28 -> 166543.86
A29: 28 | B29: Guttal | C29: Taware filling station | D29: =+Guttal!E35 -> 1059 | E29: =+Guttal!G35 -> 97216.2 | F29: =+Guttal!H35 -> 73 | G29: =+Guttal!J35 -> 7575.56 | H29: =E29+G29 -> 104791.76 | I29: 0 | J29: =+Guttal!L35 -> 104791.76 | K29: =H29+I29-J29 -> 0
A30: 29 | B30: Rattihali | C30: Shree Siri Gowari petroliam | D30: =+Rattihali!E35 -> 3159.83 | E30: =+Rattihali!G35 -> 290830.75 | F30: =+Rattihali!H35 -> 54.78 | G30: =+Rattihali!J35 -> 5698.2156 | H30: =E30+G30 -> 296528.97 | I30: =+Rattihali!M3 -> 53365.686 | J30: =+Rattihali!L35 -> 80000 | K30: =H30+I30-J30 -> 269894.65 | L30: 266689
A31: 30 | B31: Gajendragada | C31: Vanasri Petrol Pump | D31: =+Gajendragada!E35 -> 570 | E31: =+Gajendragada!G35 -> 52343.1 | F31: =+Gajendragada!H35 -> 70 | G31: =+Gajendragada!J35 -> 7266 | H31: =E31+G31 -> 59609.1 | I31: =+Gajendragada!K3 -> 21726.412 | J31: =+Gajendragada!L35 -> 21207 | K31: =H31+I31-J31 -> 60128.512 | L31: =K30-L30 -> 3205.6546
A32: 31 | B32: Ghattaprabha(PKG-3) | C32: Vivek Petrol Pump | D32: =+Ghattaprabha!E35 -> 0 | E32: =+Ghattaprabha!G35 -> 0 | F32: =+Ghattaprabha!H35 -> 0 | G32: =+Ghattaprabha!J35 -> 0 | H32: =E32+G32 -> 0 | I32: =+Ghattaprabha!M3 -> 0 | J32: =+Ghattaprabha!L35 -> 0 | K32: =H32+I32-J32 -> 0
A33: 32 | B33: Gokak(PKG-3) | C33: AJ Petrolinks | D33: =+'Gokak Dharwad PKG 3'!E40 -> 9723.02 | E33: =+'Gokak Dharwad PKG 3'!G40 -> 889461.87 | F33: =+'Gokak Dharwad PKG 3'!H40 -> 452.74 | G33: =+'Gokak Dharwad PKG 3'!J40 -> 46817.843 | H33: =E33+G33 -> 936279.71 | I33: =+'Gokak Dharwad PKG 3'!K3 -> 506954.43 | J33: =+'Gokak Dharwad PKG 3'!L40 -> 700000 | K33: =H33+I33-J33 -> 743234.15
A34: 33 | B34: Ankaligi | C34: Shiv ganga | D34: =+Ankalgi!E35 -> 2640.08 | E34: =+Ankalgi!G35 -> 241065.7 | F34: =+Ankalgi!H35 -> 139 | G34: =+Ankalgi!J35 -> 14348.97 | H34: =E34+G34 -> 255414.67 | I34: =+Ankalgi!M3 -> 122991.1 | J34: =+Ankalgi!L35 -> 150000 | K34: =H34+I34-J34 -> 228405.77
A35: 34 | B35: ShankeshWAR | C35: SR Patil | D35: =+' Shankeshwar'!E35 -> 0 | E35: =+' Shankeshwar'!G35 -> 0 | F35: =+' Shankeshwar'!H35 -> 40 | G35: =+' Shankeshwar'!J35 -> 4128.8 | H35: =E35+G35 -> 4128.8 | J35: =+' Shankeshwar'!L35 -> 4128.8 | K35: =H35+I35-J35 -> 0
A36: 35 | B36: Talikote(PKG-1) | C36: Raykar Oil Agencies | D36: =+' Talikote'!E46 -> 867.11 | E36: =+' Talikote'!G46 -> 79300.041 | F36: =+' Talikote'!H46 -> 90.55 | G36: =+' Talikote'!J46 -> 9366.492 | H36: =E36+G36 -> 88666.533 | I36: =+' Talikote'!N3 -> 3504.4807 | J36: =+' Talikote'!L46 -> 51355.13 | K36: =H36+I36-J36 -> 40815.884
A37: 36 | B37: Chadchan(PKG-1) | C37: Khavekar Petrolium | D37: =+Chadchan!E35 -> 1932.57 | E37: =+Chadchan!G35 -> 176308.36 | F37: =+Chadchan!H35 -> 68.72 | G37: =+Chadchan!J35 -> 7089.1552 | H37: =E37+G37 -> 183397.52 | I37: =+Chadchan!K3 -> 105566 | J37: =+Chadchan!L35 -> 100000 | K37: =H37+I37-J37 -> 188963.52
A38: 37 | B38: Sindagi | C38: G.P.PORWAL | D38: =+Sindagi!E44 -> 936.21 | E38: =+Sindagi!G44 -> 85410.438 | F38: =+Sindagi!H44 -> 30.7 | G38: =+Sindagi!J44 -> 3391.429 | H38: =E38+G38 -> 88801.867 | I38: =+Sindagi!M3 -> 908.2041 | J38: =+Sindagi!L44 -> 57833.21 | K38: =H38+I38-J38 -> 31876.861
A39: 38 | B39: Muddebihal(PKG-1) | C39: Bhosle Service Station | D39: =+Muddebihal!E47 -> 1810.92 | E39: =+Muddebihal!G47 -> 165608.63 | F39: =+Muddebihal!H47 -> 53.13 | G39: =+Muddebihal!J47 -> 5493.1107 | H39: =E39+G39 -> 171101.74 | I39: =+Muddebihal!M3 -> 9020.7913 | J39: =+Muddebihal!L47 -> 134608.34 | K39: =H39+I39-J39 -> 45514.196
A40: 39 | B40: Almela(PKG-1) | C40: Shiddeshwar Petroleums | D40: =+Alemela!E43 -> 1021.68 | E40: =+Alemela!G43 -> 93310.034 | F40: =+Alemela!H43 -> 124.93 | G40: =+Alemela!J43 -> 12900.272 | H40: =E40+G40 -> 106210.31 | I40: =+Alemela!M3 -> 20963.168 | J40: =+Alemela!L43 -> 90000 | K40: =H40+I40-J40 -> 37173.474
...

Sheet Khammam-1
A1: Divya laxmi ganapathi
A2: S.No | B2: Date | C2: GRN No | D2: Ind No/Bill No | E2: Diesel (Lts) | F2: Price | G2: Amount | H2: Petrol (Lts) | I2: Price | J2: Amount | K2: Total amount | L2: Amount paid | M2: As 0n Date | N2: Remarks
A3: Opening Balance | K3: 14609947 | M3: =+K3 -> 14609947 | O3: 14609972
A4: 1 | B4: 45870 | E4: 6729.01 | F4: 95.68 | G4: =E4*F4 -> 643831.68 | H4: 60 | I4: 107.46 | J4: =H4*I4 -> 6447.6 | K4: =G4+J4 -> 650279.28 | L4: 10000000 | M4: =M3+K4-L4 -> 5260226.5
A5: 2 | B5: 45871 | E5: 5675.71 | F5: 95.68 | G5: =E5*F5 -> 543051.93 | H5: 20 | I5: 107.46 | J5: =H5*I5 -> 2149.2 | K5: =G5+J5 -> 545201.13 | M5: =M4+K5-L5 -> 5805427.6
A6: 3 | B6: 45872 | E6: 0 | F6: 0 | G6: =E6*F6 -> 0 | H6: 0 | I6: 0 | J6: =H6*I6 -> 0 | K6: =G6+J6 -> 0 | M6: =M5+K6-L6 -> 5805427.6
A7: 4 | B7: 45873 | E7: 0 | F7: 0 | G7: =E7*F7 -> 0 | H7: 0 | I7: 0 | J7: =H7*I7 -> 0 | K7: =G7+J7 -> 0 | M7: =M6+K7-L7 -> 5805427.6
A8: 5 | B8: 45874 | E8: 5500 | F8: 95.68 | G8: =E8*F8 -> 526240 | H8: 40 | I8: 107.46 | J8: =H8*I8 -> 4298.4 | K8: =G8+J8 -> 530538.4 | M8: =M7+K8-L8 -> 6335966
A9: 6 | B9: 45875 | E9: 2500 | F9: 95.68 | G9: =E9*F9 -> 239200 | H9: 60 | I9: 107.46 | J9: =H9*I9 -> 6447.6 | K9: =G9+J9 -> 245647.6 | M9: =M8+K9-L9 -> 6581613.6
A10: 7 | B10: 45876 | E10: 2700 | F10: 95.68 | G10: =E10*F10 -> 258336 | H10: 20 | I10: 107.46 | J10: =H10*I10 -> 2149.2 | K10: =G10+J10 -> 260485.2 | M10: =M9+K10-L10 -> 6842098.8
A11: 8 | B11: 45877 | E11: 0 | F11: 0 | G11: =E11*F11 -> 0 | H11: 0 | I11: 0 | J11: =H11*I11 -> 0 | K11: =G11+J11 -> 0 | M11: =M10+K11-L11 -> 6842098.8
A12: 9 | B12: 45878 | E12: 2500 | F12: 95.67 | G12: =E12*F12 -> 239175 | H12: 0 | I12: 0 | J12: =H12*I12 -> 0 | K12: =G12+J12 -> 239175 | M12: =M11+K12-L12 -> 7081273.8
A13: 10 | B13: 45879 | E13: 0 | F13: 0 | G13: =E13*F13 -> 0 | H13: 0 | I13: 0 | J13: =H13*I13 -> 0 | K13: =G13+J13 -> 0 | M13: =M12+K13-L13 -> 7081273.8
A14: 11 | B14: 45880 | E14: 2700 | F14: 95.68 | G14: =E14*F14 -> 258336 | H14: 40 | I14: 107.46 | J14: =H14*I14 -> 4298.4 | K14: =G14+J14 -> 262634.4 | M14: =M13+K14-L14 -> 7343908.2
A15: 12 | B15: 45881 | E15: 0 | F15: 0 | G15: =E15*F15 -> 0 | H15: 0 | I15: 0 | J15: =H15*I15 -> 0 | K15: =G15+J15 -> 0 | M15: =M14+K15-L15 -> 7343908.2
A16: 13 | B16: 45882 | E16: 2700 | F16: 95.68 | G16: =E16*F16 -> 258336 | H16: 20 | I16: 107.46 | J16: =H16*I16 -> 2149.2 | K16: =G16+J16 -> 260485.2 | M16: =M15+K16-L16 -> 7604393.4
... A32: 29 | B32: 45898 | E32: 2132.55 | F32: 95.68 | G32: =E32*F32 -> 204042.38 | H32: 0 | I32: 0 | J32: =H32*I32 -> 0 | K32: =G32+J32 -> 204042.38 | M32: =M31+K32-L32 -> 10800896
A33: 30 | B33: 45899 | E33: 2700 | F33: 95.67 | G33: =E33*F33 -> 258309 | H33: 40 | I33: 107.46 | J33: =H33*I33 -> 4298.4 | K33: =G33+J33 -> 262607.4 | M33: =M32+K33-L33 -> 11063503 | O33: 11063398 | P33: =M33-O33 -> 105.202
A34: 31 | B34: 45900 | E34: 0 | F34: 0 | G34: =E34*F34 -> 0 | H34: 0 | I34: 0 | J34: =H34*I34 -> 0 | K34: =G34+J34 -> 0 | M34: =M33+K34-L34 -> 11063503
A35: 32 | E35: 0 | F35: 0 | G35: =E35*F35 -> 0 | H35: 0 | I35: 0 | J35: =H35*I35 -> 0 | K35: =G35+J35 -> 0 | M35: =M34+K35-L35 -> 11063503
A36: 33 | E36: 0 | F36: 0 | G36: =E36*F36 -> 0 | H36: 0 | I36: 0 | J36: =H36*I36 -> 0 | K36: =G36+J36 -> 0
A37: 34
E38: =SUM(E3:E37) -> 66910.82 | G38: =SUM(G3:G37) -> 6401975.3 | H38: =SUM(H3:H37) -> 480 | J38: =SUM(J3:J37) -> 51580.8 | K38: =SUM(K4:K37) -> 6453556.1 | L38: =SUM(L3:L37) -> 10000000

Sheet Khammam-2
A1: Jayasai union bunk
A2: S.No | B2: Date | C2: GRN No | D2: Ind No/Bill No | E2: Diesel (Lts) | F2: Price | G2: Amount | H2: Petrol (Lts) | I2: Price | J2: Amount | K2: Total amount | L2: Amount paid | M2: As 0n Date | N2: Remarks
A3: Opening Balance | K3: 12663588 | M3: =+K3 -> 12663588 | O3: 12663588
A4: 1 | B4: 45870 | E4: 0 | F4: 0 | G4: =E4*F4 -> 0 | H4: 0 | I4: 0 | J4: =H4*I4 -> 0 | K4: =G4+J4 -> 0 | L4: 10000000 | M4: =M3+K4-L4 -> 2663588.3
A5: 2 | B5: 45871 | E5: 2700 | F5: 95.7 | G5: =E5*F5 -> 258390 | H5: 0 | I5: 0 | J5: =H5*I5 -> 0 | K5: =G5+J5 -> 258390 | M5: =M4+K5-L5 -> 2921978.3
A6: 3 | B6: 45872 | E6: 2700 | F6: 95.7 | G6: =E6*F6 -> 258390 | H6: 40 | I6: 107.48 | J6: =H6*I6 -> 4299.2 | K6: =G6+J6 -> 262689.2 | M6: =M5+K6-L6 -> 3184667.5
A7: 4 | B7: 45873 | E7: 6281.12 | F7: 95.7 | G7: =E7*F7 -> 601103.18 | H7: 20 | I7: 107.48 | J7: =H7*I7 -> 2149.6 | K7: =G7+J7 -> 603252.78 | M7: =M6+K7-L7 -> 3787920.3
A8: 5 | B8: 45874 | E8: 0 | F8: 0 | G8: =E8*F8 -> 0 | H8: 0 | I8: 0 | J8: =H8*I8 -> 0 | K8: =G8+J8 -> 0 | M8: =M7+K8-L8 -> 3787920.3
A9: 6 | B9: 45875 | E9: 2106.39 | F9: 95.7 | G9: =E9*F9 -> 201581.52 | H9: 0 | I9: 0 | J9: =H9*I9 -> 0 | K9: =G9+J9 -> 201581.52 | M9: =M8+K9-L9 -> 3989501.8
A10: 7 | B10: 45876 | E10: 2800 | F10: 95.7 | G10: =E10*F10 -> 267960 | H10: 0 | I10: 0 | J10: =H10*I10 -> 0 | K10: =G10+J10 -> 267960 | M10: =M9+K10-L10 -> 4257461.8
A11: 8 | B11: 45877 | E11: 6978.81 | F11: 95.7 | G11: =E11*F11 -> 667872.12 | H11: 35 | I11: 107.48 | J11: =H11*I11 -> 3761.8 | K11: =G11+J11 -> 671633.92 | M11: =M10+K11-L11 -> 4929095.7
A12: 9 | B12: 45878 | E12: 3800 | F12: 95.7 | G12: =E12*F12 -> 363660 | H12: 40 | I12: 107.48 | J12: =H12*I12 -> 4299.2 | K12: =G12+J12 -> 367959.2 | M12: =M11+K12-L12 -> 5297054.9
A13: 10 | B13: 45879 | E13: 5063.53 | F13: 95.7 | G13: =E13*F13 -> 484579.82 | H13: 0 | I13: 0 | J13: =H13*I13 -> 0 | K13: =G13+J13 -> 484579.82 | M13: =M12+K13-L13 -> 5781634.7
A14: 11 | B14: 45880 | E14: 0 | F14: 0 | G14: =E14*F14 -> 0 | H14: 0 | I14: 0 | J14: =H14*I14 -> 0 | K14: =G14+J14 -> 0 | M14: =M13+K14-L14 -> 5781634.7
A15: 12 | B15: 45881 | E15: 5879.49 | F15: 95.7 | G15: =E15*F15 -> 562667.19 | H15: 40 | I15: 107.48 | J15: =H15*I15 -> 4299.2 | K15: =G15+J15 -> 566966.39 | M15: =M14+K15-L15 -> 6348601.1
A16: 13 | B16: 45882 | E16: 0 | F16: 95.7 | G16: =E16*F16 -> 0 | H16: 0 | I16: 107.48 | J16: =H16*I16 -> 0 | K16: =G16+J16 -> 0 | M16: =M15+K16-L16 -> 6348601.1
... A19: 16 | B19: 45885 | E19: 2100.91 | F19: 95.7 | G19: =E19*F19 -> 201057.09 | H19: 0 | I19: 0 | J19: =H19*I19 -> 0 | K19: =G19+J19 -> 201057.09 | M19: =M18+K19-L19 -> 7110794.4
A20: 17 | B20: 45886 | E20: =2700+2700 -> 5400 | F20: 95.7 | G20: =E20*F20 -> 516780 | H20: 60 | I20: 107.48 | J20: =H20*I20 -> 6448.8 | K20: =G20+J20 -> 523228.8 | M20: =M19+K20-L20 -> 7634023.2
A21: 18 | B21: 45887 | E21: 2700 | F21: 95.7 | G21: =E21*F21 -> 258390 | H21: 0 | I21: 0 | J21: =H21*I21 -> 0 | K21: =G21+J21 -> 258390 | M21: =M20+K21-L21 -> 7892413.2
A22: 19 | B22: 45888 | E22: =2800+614.79 -> 3414.79 | F22: 95.7 | G22: =E22*F22 -> 326795.4 | H22: 0 | I22: 0 | J22: =H22*I22 -> 0 | K22: =G22+J22 -> 326795.4 | M22: =M21+K22-L22 -> 8219208.6
A23: 20 | B23: 45889 | E23: 3716.62 | F23: 95.7 | G23: =E23*F23 -> 355680.53 | H23: 40 | I23: 107.48 | J23: =H23*I23 -> 4299.2 | K23: =G23+J23 -> 359979.73 | M23: =M22+K23-L23 -> 8579188.3
A24: 21 | B24: 45890 | E24: 4437.48 | F24: 95.7 | G24: =E24*F24 -> 424666.84 | H24: 20 | I24: 107.48 | J24: =H24*I24 -> 2149.6 | K24: =G24+J24 -> 426816.44 | M24: =M23+K24-L24 -> 9006004.8
A25: 22 | B25: 45891 | E25: 5400 | F25: 95.7 | G25: =E25*F25 -> 516780 | H25: 40 | I25: 107.48 | J25: =H25*I25 -> 4299.2 | K25: =G25+J25 -> 521079.2 | M25: =M24+K25-L25 -> 9527084
A26: 23 | B26: 45892 | E26: 5500 | F26: 95.7 | G26: =E26*F26 -> 526350 | H26: 40 | I26: 107.48 | J26: =H26*I26 -> 4299.2 | K26: =G26+J26 -> 530649.2 | M26: =M25+K26-L26 -> 10057733
A27: 24 | B27: 45893 | E27: 0 | F27: 0 | G27: =E27*F27 -> 0 | H27: 0 | I27: 0 | J27: =H27*I27 -> 0 | K27: =G27+J27 -> 0 | M27: =M26+K27-L27 -> 10057733
A28: 25 | B28: 45894 | E28: 4800 | F28: 95.7 | G28: =E28*F28 -> 459360 | H28: 20 | I28: 107.48 | J28: =H28*I28 -> 2149.6 | K28: =G28+J28 -> 461509.6 | M28: =M27+K28-L28 -> 10519243
A29: 26 | B29: 45895 | E29: 2700 | F29: 95.7 | G29: =E29*F29 -> 258390 | H29: 0 | I29: 0 | J29: =H29*I29 -> 0 | K29: =G29+J29 -> 258390 | M29: =M28+K29-L29 -> 10777633
A30: 27 | B30: 45896 | E30: 2552.66 | F30: 95.7 | G30: =E30*F30 -> 244289.56 | H30: 0 | I30: 0 | J30: =H30*I30 -> 0 | K30: =G30+J30 -> 244289.56 | M30: =M29+K30-L30 -> 11021922
A31: 28 | B31: 45897 | E31: 0 | F31: 0 | G31: =E31*F31 -> 0 | H31: 0 | I31: 0 | J31: =H31*I31 -> 0 | K31: =G31+J31 -> 0 | M31: =M30+K31-L31 -> 11021922
A32: 29 | B32: 45898 | E32: 5500 | F32: 95.7 | G32: =E32*F32 -> 526350 | H32: 55 | I32: 107.48 | J32: =H32*I32 -> 5911.4 | K32: =G32+J32 -> 532261.4 | M32: =M31+K32-L32 -> 11554184
A33: 30 | B33: 45899 | E33: 2033.66 | F33: 95.7 | G33: =E33*F33 -> 194621.26 | H33: 0 | I33: 0 | J33: =H33*I33 -> 0 | K33: =G33+J33 -> 194621.26 | M33: =M32+K33-L33 -> 11748805
A34: 31 | B34: 45900 | G34: =E34*F34 -> 0 | H34: 0 | I34: 0 | J34: =H34*I34 -> 0 | K34: =G34+J34 -> 0 | M34: =M33+K34-L34 -> 11748805
E35: =SUM(E4:E34) -> 94406.49 | G35: =SUM(G4:G34) -> 9034701.1 | H35: =SUM(H4:H34) -> 470 | J35: =SUM(J4:J34) -> 50515.6 | K35: =SUM(K4:K34) -> 9085216.7 | L35: =SUM(L4:L34) -> 10000000

Sheet Jedcherla -1
A1: Sai Baba Fuel Station
A2: S.No | B2: Date | C2: GRN No | D2: Ind No/Bill No | E2: Diesel (Lts) | F2: Price | G2: Amount | H2: Petrol (Lts) | I2: Price | J2: Amount | K2: Total amount | L2: Amount paid | M2: As on date | N2: Remarks
A3: Opening Balance | M3: 1388015.3 | O3: 1388015.3
A4: 1 | B4: 45870 | E4: 1500 | F4: 96.42 | G4: =E4*F4 -> 144630 | H4: 10 | I4: 108.23 | J4: =H4*I4 -> 1082.3 | K4: =G4+J4 -> 145712.3 | L4: 0 | M4: =M3+K4-L4 -> 1533727.6 | O4: 1526163 | P4: =M4-O4 -> 7564.5685
A5: 2 | B5: 45871 | E5: 3000 | F5: 96.42 | G5: =E5*F5 -> 289260 | H5: 15 | I5: 108.23 | J5: =H5*I5 -> 1623.45 | K5: =G5+J5 -> 290883.45 | L5: 1288000 | M5: =M4+K5-L5 -> 536611.02
A6: 3 | B6: 45872 | E6: 0 | F6: 0 | G6: =E6*F6 -> 0 | H6: 25 | I6: 108.23 | J6: =H6*I6 -> 2705.75 | K6: =G6+J6 -> 2705.75 | L6: 0 | M6: =M5+K6-L6 -> 539316.77
A7: 4 | B7: 45873 | E7: 4100 | F7: 96.42 | G7: =E7*F7 -> 395322 | H7: 20 | I7: 108.23 | J7: =H7*I7 -> 2164.6 | K7: =G7+J7 -> 397486.6 | L7: 0 | M7: =M6+K7-L7 -> 936803.37
A8: 5 | B8: 45874 | E8: 0 | F8: 0 | G8: =E8*F8 -> 0 | H8: 10 | I8: 108.23 | J8: =H8*I8 -> 1082.3 | K8: =G8+J8 -> 1082.3 | L8: 0 | M8: =M7+K8-L8 -> 937885.67
A9: 6 | B9: 45875 | E9: 4261.78 | F9: 96.42 | G9: =E9*F9 -> 410920.83 | H9: 20 | I9: 108.23 | J9: =H9*I9 -> 2164.6 | K9: =G9+J9 -> 413085.43 | L9: 0 | M9: =M8+K9-L9 -> 1350971.1 | O9: 10
A10: 7 | B10: 45876 | E10: 1400 | F10: 96.42 | G10: =E10*F10 -> 134988 | H10: 10 | I10: 108.23 | J10: =H10*I10 -> 1082.3 | K10: =G10+J10 -> 136070.3 | L10: 0 | M10: =M9+K10-L10 -> 1487041.4
A11: 8 | B11: 45877 | E11: 1850 | F11: 96.42 | G11: =E11*F11 -> 178377 | H11: 20 | I11: 108.23 | J11: =H11*I11 -> 2164.6 | K11: =G11+J11 -> 180541.6 | L11: 0 | M11: =M10+K11-L11 -> 1667583
A12: 9 | B12: 45878 | E12: 2500 | F12: 96.42 | G12: =E12*F12 -> 241050 | H12: 10 | I12: 108.23 | J12: =H12*I12 -> 1082.3 | K12: =G12+J12 -> 242132.3 | L12: 0 | M12: =M11+K12-L12 -> 1909715.3
A13: 10 | B13: 45879 | E13: 0 | F13: 0 | G13: =E13*F13 -> 0 | H13: 10 | I13: 108.23 | J13: =H13*I13 -> 1082.3 | K13: =G13+J13 -> 1082.3 | L13: 0 | M13: =M12+K13-L13 -> 1910797.6
A14: 11 | B14: 45880 | E14: 0 | F14: 0 | G14: =E14*F14 -> 0 | H14: 10 | I14: 108.23 | J14: =H14*I14 -> 1082.3 | K14: =G14+J14 -> 1082.3 | L14: 0 | M14: =M13+K14-L14 -> 1911879.9
A15: 12 | B15: 45881 | E15: 1300 | F15: 96.42 | G15: =E15*F15 -> 125346 | H15: 15 | I15: 108.23 | J15: =H15*I15 -> 1623.45 | K15: =G15+J15 -> 126969.45 | L15: 0 | M15: =M14+K15-L15 -> 2038849.3
A16: 13 | B16: 45882 | E16: 2429.66 | F16: 96.42 | G16: =E16*F16 -> 234267.82 | H16: 20 | I16: 108.23 | J16: =H16*I16 -> 2164.6 | K16: =G16+J16 -> 236432.42 | L16: 0 | M16: =M15+K16-L16 -> 2275281.8
A17: 14 | B17: 45883 | E17: 35 | F17: 96.42 | G17: =E17*F17 -> 3374.7 | H17: 20 | I17: 108.23 | J17: =H17*I17 -> 2164.6 | K17: =G17+J17 -> 5539.3 | L17: 0 | M17: =M16+K17-L17 -> 2280821.1 | P17: 6.08.2025
A18: 15 | B18: 45884 | E18: 0 | F18: 0 | G18: =E18*F18 -> 0 | H18: 5 | I18: 108.23 | J18: =H18*I18 -> 541.15 | K18: =G18+J18 -> 541.15 | L18: 0 | M18: =M17+K18-L18 -> 2281362.2 | P18: 5340
A19: 16 | B19: 45885 | E19: 0 | F19: 0 | G19: =E19*F19 -> 0 | H19: 5 | I19: 108.23 | J19: =H19*I19 -> 541.15 | K19: =G19+J19 -> 541.15 | L19: 0 | M19: =M18+K19-L19 -> 2281903.4 | P19: BPCL
A20: 17 | B20: 45886 | E20: 0 | F20: 0 | G20: =E20*F20 -> 0 | H20: 15 | I20: 108.23 | J20: =H20*I20 -> 1623.45 | K20: =G20+J20 -> 1623.45 | L20: 0 | M20: =M19+K20-L20 -> 2283526.8
A21: 18 | B21: 45887 | E21: 1000 | F21: 96.42 | G21: =E21*F21 -> 96420 | H21: 10 | I21: 108.23 | J21: =H21*I21 -> 1082.3 | K21: =G21+J21 -> 97502.3 | L21: 0 | M21: =M20+K21-L21 -> 2381029.1
A22: 19 | B22: 45888 | E22: 0 | F22: 0 | G22: =E22*F22 -> 0 | H22: 5 | I22: 108.23 | J22: =H22*I22 -> 541.15 | K22: =G22+J22 -> 541.15 | L22: 0 | M22: =M21+K22-L22 -> 2381570.3
A23: 20 | B23: 45889 | E23: 1500 | F23: 96.42 | G23: =E23*F23 -> 144630 | H23: 10 | I23: 108.23 | J23: =H23*I23 -> 1082.3 | K23: =G23+J23 -> 145712.3 | L23: 0 | M23: =M22+K23-L23 -> 2527282.6
A24: 21 | B24: 45890 | E24: 0 | F24: 0 | G24: =E24*F24 -> 0 | H24: 20 | I24: 108.23 | J24: =H24*I24 -> 2164.6 | K24: =G24+J24 -> 2164.6 | L24: 0 | M24: =M23+K24-L24 -> 2529447.2
A25: 22 | B25: 45891 | E25: 3943 | F25: 96.42 | G25: =E25*F25 -> 380184.06 | H25: 37.6 | I25: 108.23 | J25: =H25*I25 -> 4069.448 | K25: =G25+J25 -> 384253.51 | L25: 0 | M25: =M24+K25-L25 -> 2913700.7
A26: 23 | B26: 45892 | E26: 2400 | F26: 96.42 | G26: =E26*F26 -> 231408 | H26: 20 | I26: 108.23 | J26: =H26*I26 -> 2164.6 | K26: =G26+J26 -> 233572.6 | L26: 0 | M26: =M25+K26-L26 -> 3147273.3
A27: 24 | B27: 45893 | E27: 1500 | F27: 96.42 | G27: =E27*F27 -> 144630 | H27: 0 | I27: 108.23 | J27: =H27*I27 -> 0 | K27: =G27+J27 -> 144630 | L27: 0 | M27: =M26+K27-L27 -> 3291903.3
A28: 25 | B28: 45894 | E28: 3500 | F28: 96.42 | G28: =E28*F28 -> 337470 | H28: 29.5 | I28: 108.23 | J28: =H28*I28 -> 3192.785 | K28: =G28+J28 -> 340662.78 | L28: 0 | M28: =M27+K28-L28 -> 3632566.1
A29: 26 | B29: 45895 | E29: 0 | F29: 0 | G29: =E29*F29 -> 0 | H29: 15 | I29: 108.23 | J29: =H29*I29 -> 1623.45 | K29: =G29+J29 -> 1623.45 | L29: 0 | M29: =M28+K29-L29 -> 3634189.5
A30: 27 | B30: 45896 | E30: 0 | F30: 0 | G30: =E30*F30 -> 0 | H30: 10 | I30: 108.23 | J30: =H30*I30 -> 1082.3 | K30: =G30+J30 -> 1082.3 | L30: 0 | M30: =M29+K30-L30 -> 3635271.8
A31: 28 | B31: 45897 | E31: 1000 | F31: 96.42 | G31: =E31*F31 -> 96420 | H31: 30 | I31: 108.23 | J31: =H31*I31 -> 3246.9 | K31: =G31+J31 -> 99666.9 | L31: 0 | M31: =M30+K31-L31 -> 3734938.7
A32: 29 | B32: 45898 | E32: 0 | F32: 0 | G32: 0 | H32: 20 | I32: 108.23 | J32: =H32*I32 -> 2164.6 | K32: =G32+J32 -> 2164.6 | L32: 0 | M32: =M31+K32-L32 -> 3737103.3
A33: 30 | B33: 45899 | E33: 1000 | F33: 96.42 | G33: =E33*F33 -> 96420 | H33: 15 | I33: 108.23 | J33: =H33*I33 -> 1623.45 | K33: =G33+J33 -> 98043.45 | L33: 0 | M33: =M32+K33-L33 -> 3835146.8
A34: 31 | B34: 45900 | E34: 0 | F34: 0 | G34: 0 | H34: 10 | I34: 108.23 | J34: =H34*I34 -> 1082.3 | K34: =G34+J34 -> 1082.3 | L34: 0 | M34: =M33+K34-L34 -> 3836229.1
E35: 0 | F35: 0 | G35: =E35*F35 -> 0 | H35: 0 | I35: 0 | J35: =H35*I35 -> 0 | K35: =G35+J35 -> 0 | M35: =M34+K35-L35 -> 3836229.1
E36: =SUM(E4:E34) -> 38219.44 | G36: =SUM(G4:G34) -> 3685118.4 | H36: =SUM(H4:H34) -> 472.1 | J36: =SUM(J4:J34) -> 51095.383 | K36: =SUM(K4:K34) -> 3736213.8 | L36: =SUM(L4:L34) -> 1288000
E38: 38209.44

Sheet Jedcharla-2
A1: ADHOC FILLING STATION STATION
A2: S.No | B2: Date | C2: GRN No | D2: Ind No/Bill No | E2: Diesel (Lts) | F2: Price | G2: Amount | H2: Petrol (Lts) | I2: Price | J2: Amount | K2: Total amount | L2: Amount paid | M2: As on Date | N2: Remarks
A3: Opening Balance | K3: 1400599.6 | M3: =+K3 -> 1400599.6 | O3: 1400599.6
A4: 1 | B4: 45870 | E4: 0 | F4: 0 | G4: =E4*F4 -> 0 | J4: =H4*I4 -> 0 | K4: =G4+J4 -> 0 | M4: =M3+K4-L4 -> 1400599.6
A5: 2 | B5: 45871 | E5: 0 | F5: 0 | G5: =E5*F5 -> 0 | J5: =H5*I5 -> 0 | K5: =G5+J5 -> 0 | L5: 1400600 | M5: =M4+K5-L5 -> -0.4242
A6: 3 | B6: 45872 | E6: 0 | F6: 0 | G6: =E6*F6 -> 0 | J6: =H6*I6 -> 0 | K6: =G6+J6 -> 0 | M6: =M5+K6-L6 -> -0.4242 | R6: 541.08
A7: 4 | B7: 45873 | E7: 0 | F7: 0 | G7: =E7*F7 -> 0 | J7: =H7*I7 -> 0 | K7: =G7+J7 -> 0 | M7: =M6+K7-L7 -> -0.4242
A8: 5 | B8: 45874 | E8: 0 | F8: 0 | G8: =E8*F8 -> 0 | J8: =H8*I8 -> 0 | K8: =G8+J8 -> 0 | M8: =M7+K8-L8 -> -0.4242
A9: 6 | B9: 45875 | E9: 0 | F9: 0 | G9: =E9*F9 -> 0 | J9: =H9*I9 -> 0 | K9: =G9+J9 -> 0 | M9: =M8+K9-L9 -> -0.4242
A10: 7 | B10: 45876 | E10: 0 | F10: 0 | G10: =E10*F10 -> 0 | J10: =H10*I10 -> 0 | K10: =G10+J10 -> 0 | M10: =M9+K10-L10 -> -0.4242
A11: 8 | B11: 45877 | E11: 0 | F11: 0 | G11: =E11*F11 -> 0 | J11: =H11*I11 -> 0 | K11: =G11+J11 -> 0 | M11: =M10+K11-L11 -> -0.4242
A12: 9 | B12: 45878 | E12: 0 | F12: 0 | G12: =E12*F12 -> 0 | J12: =H12*I12 -> 0 | K12: =G12+J12 -> 0 | M12: =M11+K12-L12 -> -0.4242
A13: 10 | B13: 45879 | E13: 0 | F13: 0 | G13: =E13*F13 -> 0 | J13: =H13*I13 -> 0 | K13: =G13+J13 -> 0 | M13: =M12+K13-L13 -> -0.4242
A14: 11 | B14: 45880 | E14: 0 | F14: 0 | G14: =E14*F14 -> 0 | J14: =H14*I14 -> 0 | K14: =G14+J14 -> 0 | M14: =M13+K14-L14 -> -0.4242
A15: 12 | B15: 45881 | E15: 0 | F15: 0 | G15: =E15*F15 -> 0 | J15: =H15*I15 -> 0 | K15: =G15+J15 -> 0 | M15: =M14+K15-L15 -> -0.4242
A16: 13 | B16: 45882 | E16: 0 | F16: 0 | G16: =E16*F16 -> 0 | J16: =H16*I16 -> 0 | K16: =G16+J16 -> 0 | M16: =M15+K16-L16 -> -0.4242
A17: 14 | B17: 45883 | E17: 0 | F17: 0 | G17: =E17*F17 -> 0 | J17: =H17*I17 -> 0 | K17: =G17+J17 -> 0 | M17: =M16+K17-L17 -> -0.4242
A18: 15 | B18: 45884 | E18: 0 | F18: 0 | G18: =E18*F18 -> 0 | J18: =H18*I18 -> 0 | K18: =G18+J18 -> 0 | M18: =M17+K18-L18 -> -0.4242
... A33: 30 | B33: 45899 | E33: 0 | F33: 0 | G33: =E33*F33 -> 0 | J33: =H33*I33 -> 0 | K33: =G33+J33 -> 0 | M33: =M32+K33-L33 -> -0.4242
A34: 31 | B34: 45900 | E34: 0 | F34: 0 | G34: =E34*F34 -> 0 | J34: =H34*I34 -> 0 | K34: =G34+J34 -> 0 | M34: =M33+K34-L34 -> -0.4242 | O34: 1688453.6 | P34: 1900671 | Q34: =P34-O34 -> 212217.42
E35: =SUM(E4:E34) -> 0 | G35: =SUM(G4:G34) -> 0 | H35: =SUM(H4:H34) -> 0 | J35: =SUM(J4:J34) -> 0 | K35: =SUM(K4:K34) -> 0 | L35: =SUM(L4:L34) -> 1400600

Sheet Dindi
A1: Akarapu Balakistamma Fillling
A2: S.No | B2: Date | C2: GRN No | D2: Ind no/Bill No | E2: Diesel (Lts) | F2: Price | G2: Amount | H2: Petrol (Lts) | I2: Price | J2: Amount | K2: Total amount | L2: Amount paid | M2: As on Date | N2: Remarks
A3: Opening Balance | M3: 0
A4: 1 | B4: 45870 | E4: 0 | F4: 0 | G4: =E4*F4 -> 0 | H4: 0 | I4: 0 | J4: =H4*I4 -> 0 | K4: =G4+J4 -> 0 | L4: =+K4 -> 0 | M4: 0
A5: 2 | B5: 45871 | E5: 0 | F5: 0 | G5: =E5*F5 -> 0 | H5: 0 | I5: 0 | J5: =H5*I5 -> 0 | K5: =G5+J5 -> 0 | L5: =+K5 -> 0 | M5: 0
A6: 3 | B6: 45872 | E6: 0 | F6: 0 | G6: =E6*F6 -> 0 | H6: 0 | I6: 0 | J6: =H6*I6 -> 0 | K6: =G6+J6 -> 0 | L6: =+K6 -> 0 | M6: 0
A7: 4 | B7: 45873 | E7: 43.78 | F7: 96.83 | G7: =E7*F7 -> 4239.2174 | H7: 0 | I7: 0 | J7: =H7*I7 -> 0 | K7: =G7+J7 -> 4239.2174 | L7: =+K7 -> 4239.2174 | M7: 0
A8: 5 | B8: 45874 | E8: 0 | F8: 0 | G8: =E8*F8 -> 0 | H8: 0 | I8: 0 | J8: =H8*I8 -> 0 | K8: =G8+J8 -> 0 | L8: =+K8 -> 0 | M8: 0
A9: 6 | B9: 45875 | E9: 0 | F9: 0 | G9: =E9*F9 -> 0 | H9: 0 | I9: 0 | J9: =H9*I9 -> 0 | K9: =G9+J9 -> 0 | L9: =+K9 -> 0 | M9: 0
A10: 7 | B10: 45876 | E10: 0 | F10: 0 | G10: =E10*F10 -> 0 | H10: 0 | I10: 0 | J10: =H10*I10 -> 0 | K10: =G10+J10 -> 0 | L10: =+K10 -> 0 | M10: 0
A11: 8 | B11: 45877 | E11: 0 | F11: 0 | G11: =E11*F11 -> 0 | H11: 0 | I11: 0 | J11: =H11*I11 -> 0 | K11: =G11+J11 -> 0 | L11: =+K11 -> 0 | M11: 0
A12: 9 | B12: 45878 | E12: 0 | F12: 0 | G12: =E12*F12 -> 0 | H12: 0 | I12: 0 | J12: =H12*I12 -> 0 | K12: =G12+J12 -> 0 | L12: =+K12 -> 0 | M12: 0
A13: 10 | B13: 45879 | E13: 0 | F13: 0 | G13: =E13*F13 -> 0 | H13: 0 | I13: 0 | J13: =H13*I13 -> 0 | K13: =G13+J13 -> 0 | L13: =+K13 -> 0 | M13: 0
A14: 11 | B14: 45880 | E14: 0 | F14: 0 | G14: =E14*F14 -> 0 | H14: 0 | I14: 0 | J14: =H14*I14 -> 0 | K14: =G14+J14 -> 0 | L14: =+K14 -> 0 | M14: 0
A15: 12 | B15: 45881 | E15: 0 | F15: 0 | G15: =E15*F15 -> 0 | H15: 0 | I15: 0 | J15: =H15*I15 -> 0 | K15: =G15+J15 -> 0 | L15: =+K15 -> 0 | M15: 0
... A33: 30 | B33: 45899 | E33: 0 | F33: 0 | G33: =E33*F33 -> 0 | H33: 0 | I33: 0 | J33: =H33*I33 -> 0 | K33: =G33+J33 -> 0 | L33: =+K33 -> 0 | M33: 0
A34: 31 | E34: 0 | F34: 0 | G34: =E34*F34 -> 0 | H34: 0 | I34: 0 | J34: =H34*I34 -> 0 | K34: =G34+J34 -> 0 | L34: =+K34 -> 0 | M34: 0
E35: =SUM(E4:E34) -> 176.65 | G35: =SUM(G4:G34) -> 17065.626 | H35: =SUM(H4:H34) -> 25 | J35: =SUM(J4:J34) -> 2729 | K35: =SUM(K4:K34) -> 19794.626 | L35: =SUM(L4:L34) -> 19794.626

Sheet Sangareddy
A1: Sree Shiva Parvathi Filling Station
A2: S.No | B2: Date | C2: GRN No | D2: Ind No/Bill No | E2: Diesel (Lts) | F2: Price | G2: Amount | H2: Petrol (Lts) | I2: Price | J2: Amount | K2: Total amount | L2: Amount paid | M2: As on Date | N2: Remarks
A3: Opening Balance | K3: 0 | M3: =+K3 -> 0
A4: 1 | B4: 45870 | E4: 0 | F4: 0 | G4: =E4*F4 -> 0 | H4: 0 | I4: 0 | J4: =H4*I4 -> 0 | K4: =G4+J4 -> 0 | M4: =M3+K4-L4 -> 0
A5: 2 | B5: 45871 | E5: 0 | F5: 0 | G5: =E5*F5 -> 0 | H5: 0 | I5: 0 | J5: =H5*I5 -> 0 | K5: =G5+J5 -> 0 | M5: =M4+K5-L5 -> 0
A6: 3 | B6: 45872 | E6: 0 | F6: 0 | G6: =E6*F6 -> 0 | H6: 0 | I6: 0 | J6: =H6*I6 -> 0 | K6: =G6+J6 -> 0 | M6: =M5+K6-L6 -> 0
B7: 45873 | E7: 0 | F7: 0 | G7: =E7*F7 -> 0 | H7: 0 | I7: 0 | J7: =H7*I7 -> 0 | K7: =G7+J7 -> 0 | M7: =M6+K7-L7 -> 0
A8: 4 | B8: 45874 | E8: 0 | F8: 0 | G8: =E8*F8 -> 0 | H8: 0 | I8: 0 | J8: =H8*I8 -> 0 | K8: =G8+J8 -> 0 | M8: =M7+K8-L8 -> 0
A9: 5 | B9: 45875 | E9: 0 | F9: 0 | G9: =E9*F9 -> 0 | H9: 0 | I9: 0 | J9: =H9*I9 -> 0 | K9: =G9+J9 -> 0 | M9: =M8+K9-L9 -> 0
A10: 6 | B10: 45876 | E10: 0 | F10: 0 | G10: =E10*F10 -> 0 | H10: 0 | I10: 0 | J10: =H10*I10 -> 0 | K10: =G10+J10 -> 0 | M10: =M9+K10-L10 -> 0
A11: 7 | B11: 45877 | E11: 0 | F11: 0 | G11: =E11*F11 -> 0 | H11: 0 | I11: 0 | J11: =H11*I11 -> 0 | K11: =G11+J11 -> 0 | M11: =M10+K11-L11 -> 0
A12: 8 | B12: 45878 | E12: 0 | F12: 0 | G12: =E12*F12 -> 0 | H12: 0 | I12: 0 | J12: =H12*I12 -> 0 | K12: =G12+J12 -> 0 | M12: =M11+K12-L12 -> 0
A13: 9 | B13: 45879 | E13: 0 | F13: 0 | G13: =E13*F13 -> 0 | H13: 0 | I13: 0 | J13: =H13*I13 -> 0 | K13: =G13+J13 -> 0 | M13: =M12+K13-L13 -> 0
A14: 10 | B14: 45880 | E14: 0 | F14: 0 | G14: =E14*F14 -> 0 | H14: 0 | I14: 0 | J14: =H14*I14 -> 0 | K14: =G14+J14 -> 0 | M14: =M13+K14-L14 -> 0
A15: 11 | B15: 45881 | E15: 0 | F15: 0 | G15: =E15*F15 -> 0 | H15: 0 | I15: 0 | J15: =H15*I15 -> 0 | K15: =G15+J15 -> 0 | M15: =M14+K15-L15 -> 0
A16: 12 | B16: 45882 | E16: 0 | F16: 0 | G16: =E16*F16 -> 0 | H16: 0 | I16: 0 | J16: =H16*I16 -> 0 | K16: =G16+J16 -> 0 | M16: =M15+K16-L16 -> 0
A17: 13 | B17: 45883 | E17: 0 | F17: 0 | G17: =E17*F17 -> 0 | H17: 0 | I17: 0 | J17: =H17*I17 -> 0 | K17: =G17+J17 -> 0 | M17: =M16+K17-L17 -> 0
A18: 14 | B18: 45884 | E18: 0 | F18: 0 | G18: =E18*F18 -> 0 | H18: 0 | I18: 0 | J18: =H18*I18 -> 0 | K18: =G18+J18 -> 0 | M18: =M17+K18-L18 -> 0
A19: 15 | B19: 45885 | E19: 0 | F19: 0 | G19: =E19*F19 -> 0 | H19: 0 | I19: 0 | J19: =H19*I19 -> 0 | K19: =G19+J19 -> 0 | M19: =M18+K19-L19 -> 0
... A34: 30 | B34: 45900 | E34: 0 | F34: 0 | G34: =E34*F34 -> 0 | H34: 0 | I34: 0 | J34: =H34*I34 -> 0 | K34: =G34+J34 -> 0 | M34: =M33+K34-L34 -> 0
A35: 31 | E35: 0 | F35: 0 | G35: =E35*F35 -> 0 | H35: 0 | I35: 0 | J35: =H35*I35 -> 0 | K35: =G35+J35 -> 0 | M35: =M34+K35-L35 -> 0
A36: 32 | E36: 0 | F36: 0 | G36: =E36*F36 -> 0 | H36: 0 | I36: 0 | J36: =H36*I36 -> 0 | K36: =G36+J36 -> 0 | M36: =M35+K36-L36 -> 0
A37: 33 | E37: 0 | F37: 0 | G37: =E37*F37 -> 0 | H37: 0 | I37: 0 | J37: =H37*I37 -> 0 | K37: =G37+J37 -> 0 | M37: =M36+K37-L37 -> 0
A38: 34 | E38: 0 | F38: 0 | G38: =E38*F38 -> 0 | H38: 0 | I38: 0 | J38: =H38*I38 -> 0 | K38: =G38+J38 -> 0 | M38: =M37+K38-L38 -> 0
A39: 35 | E39: 0 | F39: 0 | G39: =E39*F39 -> 0 | H39: 0 | I39: 0 | J39: =H39*I39 -> 0 | K39: =G39+J39 -> 0 | M39: =M38+K39-L39 -> 0
E40: =SUM(E4:E39) -> 0 | G40: =SUM(G4:G39) -> 0 | H40: =SUM(H4:H39) -> 0 | J40: =SUM(J4:J39) -> 0 | K40: =SUM(K4:K39) -> 0 | L40: =SUM(L4:L39) -> 0

Sheet Devarakhadra
A1: Kurumurthy Swami F/S
A2: S.No | B2: Date | C2: GRN No | D2: Ind no/Bill No | E2: Diesel (Lts) | F2: Price | G2: Amount | H2: Petrol (Lts) | I2: Price | J2: Amount | K2: Total amount | L2: Amount paid | M2: As on Date | N2: Remarks
A3: Opening Balance | M3: 580925.58 | O3: 580925.58
A4: 1 | B4: 45870 | E4: 765 | F4: 97.1 | G4: =E4*F4 -> 74281.5 | H4: 0 | I4: 0 | J4: =H4*I4 -> 0 | K4: =G4+J4 -> 74281.5 | L4: 0 | M4: =+M3+K4-L4 -> 655207.08
A5: 2 | B5: 45871 | E5: 564 | F5: 97.1 | G5: =E5*F5 -> 54764.4 | H5: 5 | I5: 108.83 | J5: =H5*I5 -> 544.15 | K5: =G5+J5 -> 55308.55 | L5: 600000 | M5: =+M4+K5-L5 -> 110515.63
A6: 3 | B6: 45872 | E6: 303.5 | F6: 97.1 | G6: =E6*F6 -> 29469.85 | H6: 5 | I6: 108.83 | J6: =H6*I6 -> 544.15 | K6: =G6+J6 -> 30014 | L6: 0 | M6: =+M5+K6-L6 -> 140529.63
A7: 4 | B7: 45873 | E7: 817.91 | F7: 97.1 | G7: =E7*F7 -> 79419.061 | H7: 0 | I7: 0 | J7: =H7*I7 -> 0 | K7: =G7+J7 -> 79419.061 | L7: 0 | M7: =+M6+K7-L7 -> 219948.69
A8: 5 | B8: 45874 | E8: 267 | F8: 97.1 | G8: =E8*F8 -> 25925.7 | H8: 5 | I8: 108.83 | J8: =H8*I8 -> 544.15 | K8: =G8+J8 -> 26469.85 | L8: 0 | M8: =+M7+K8-L8 -> 246418.54
A9: 6 | B9: 45875 | E9: 830 | F9: 97.1 | G9: =E9*F9 -> 80593 | H9: 0 | I9: 0 | J9: =H9*I9 -> 0 | K9: =G9+J9 -> 80593 | L9: 0 | M9: =+M8+K9-L9 -> 327011.54
A10: 7 | B10: 45876 | E10: 87.5 | F10: 97.1 | G10: =E10*F10 -> 8496.25 | H10: 0 | I10: 0 | J10: =H10*I10 -> 0 | K10: =G10+J10 -> 8496.25 | L10: 0 | M10: =+M9+K10-L10 -> 335507.79
A11: 8 | B11: 45877 | E11: 615 | F11: 97.1 | G11: =E11*F11 -> 59716.5 | H11: 15 | I11: 108.83 | J11: =H11*I11 -> 1632.45 | K11: =G11+J11 -> 61348.95 | L11: 0 | M11: =+M10+K11-L11 -> 396856.74
A12: 9 | B12: 45878 | E12: 615 | F12: 97.1 | G12: =E12*F12 -> 59716.5 | H12: 7 | I12: 108.83 | J12: =H12*I12 -> 761.81 | K12: =G12+J12 -> 60478.31 | L12: 0 | M12: =+M11+K12-L12 -> 457335.05
A13: 10 | B13: 45879 | E13: 549.2 | F13: 97.1 | G13: =E13*F13 -> 53327.32 | H13: 5 | I13: 108.83 | J13: =H13*I13 -> 544.15 | K13: =G13+J13 -> 53871.47 | L13: 0 | M13: =+M12+K13-L13 -> 511206.52
A14: 11 | B14: 45880 | E14: 0 | F14: 0 | G14: =E14*F14 -> 0 | H14: 0 | I14: 0 | J14: =H14*I14 -> 0 | K14: =G14+J14 -> 0 | L14: 0 | M14: =+M13+K14-L14 -> 511206.52
A15: 12 | B15: 45881 | E15: 390.2 | F15: 97.1 | G15: =E15*F15 -> 37888.42 | H15: 0 | I15: 0 | J15: =H15*I15 -> 0 | K15: =G15+J15 -> 37888.42 | L15: 0 | M15: =+M14+K15-L15 -> 549094.94
... A18: 15 | B18: 45884 | E18: 0 | F18: 0 | G18: =E18*F18 -> 0 | H18: 0 | I18: 0 | J18: =H18*I18 -> 0 | K18: =G18+J18 -> 0 | L18: 0 | M18: =+M17+K18-L18 -> 282479.09
A19: 16 | B19: 45885 | E19: 72 | F19: 97.1 | G19: =E19*F19 -> 6991.2 | H19: 10 | I19: 108.83 | J19: =H19*I19 -> 1088.3 | K19: =G19+J19 -> 8079.5 | L19: 0 | M19: =+M18+K19-L19 -> 290558.59 | N19: Fuel bills
A20: 17 | B20: 45886 | E20: 15 | F20: 97.1 | G20: =E20*F20 -> 1456.5 | H20: 0 | I20: 0 | J20: =H20*I20 -> 0 | K20: =G20+J20 -> 1456.5 | L20: 0 | M20: =+M19+K20-L20 -> 292015.09
A21: 18 | B21: 45887 | E21: 0 | F21: 0 | G21: =E21*F21 -> 0 | H21: 5 | I21: 108.83 | J21: =H21*I21 -> 544.15 | K21: =G21+J21 -> 544.15 | L21: 0 | M21: =+M20+K21-L21 -> 292559.24
A22: 19 | B22: 45888 | E22: 40 | F22: 97.1 | G22: =E22*F22 -> 3884 | H22: 0 | I22: 0 | J22: =H22*I22 -> 0 | K22: =G22+J22 -> 3884 | L22: 0 | M22: =+M21+K22-L22 -> 296443.24
A23: 20 | B23: 45889 | E23: 49.27 | F23: 97.1 | G23: =E23*F23 -> 4784.117 | H23: 0 | I23: 0 | J23: =H23*I23 -> 0 | K23: =G23+J23 -> 4784.117 | L23: 0 | M23: =+M22+K23-L23 -> 301227.36
A24: 21 | B24: 45890 | E24: 660 | F24: 97.1 | G24: =E24*F24 -> 64086 | H24: 5 | I24: 108.83 | J24: =H24*I24 -> 544.15 | K24: =G24+J24 -> 64630.15 | L24: 300000 | M24: =+M23+K24-L24 -> 65857.506
A25: 22 | B25: 45891 | E25: 785 | F25: 97.1 | G25: =E25*F25 -> 76223.5 | H25: 0 | I25: 0 | J25: =H25*I25 -> 0 | K25: =G25+J25 -> 76223.5 | L25: 0 | M25: =+M24+K25-L25 -> 142081.01
A26: 23 | B26: 45892 | E26: =200+400+30 -> 630 | F26: 97.1 | G26: =E26*F26 -> 61173 | H26: 0 | I26: 0 | J26: =H26*I26 -> 0 | K26: =G26+J26 -> 61173 | L26: 0 | M26: =+M25+K26-L26 -> 203254.01
A27: 24 | B27: 45893 | E27: =43+15+149+55 -> 262 | F27: 97.1 | G27: =E27*F27 -> 25440.2 | H27: 5 | I27: 108.83 | J27: =H27*I27 -> 544.15 | K27: =G27+J27 -> 25984.35 | L27: 0 | M27: =+M26+K27-L27 -> 229238.36
A28: 25 | B28: 45894 | E28: 1021.5 | F28: 97.1 | G28: =E28*F28 -> 99187.65 | H28: 5 | I28: 108.83 | J28: =H28*I28 -> 544.15 | K28: =G28+J28 -> 99731.8 | L28: 0 | M28: =+M27+K28-L28 -> 328970.16
A29: 26 | B29: 45895 | E29: =15+63.33+350 -> 428.33 | F29: 97.1 | G29: =E29*F29 -> 41590.843 | H29: 5 | I29: 108.83 | J29: =H29*I29 -> 544.15 | K29: =G29+J29 -> 42134.993 | L29: 0 | M29: =+M28+K29-L29 -> 371105.15
A30: 27 | B30: 45896 | E30: 46.48 | F30: 97.1 | G30: =E30*F30 -> 4513.208 | H30: 0 | I30: 0 | J30: =H30*I30 -> 0 | K30: =G30+J30 -> 4513.208 | L30: 0 | M30: =+M29+K30-L30 -> 375618.36
A31: 28 | B31: 45897 | E31: 650 | F31: 97.1 | G31: =E31*F31 -> 63115 | H31: 5 | I31: 108.83 | J31: =H31*I31 -> 544.15 | K31: =G31+J31 -> 63659.15 | L31: 0 | M31: =+M30+K31-L31 -> 439277.51
A32: 29 | B32: 45898 | E32: =60+15+33.51+400 -> 508.51 | F32: 97.1 | G32: =E32*F32 -> 49376.321 | H32: 6 | I32: 108.83 | J32: =H32*I32 -> 652.98 | K32: =G32+J32 -> 50029.301 | L32: 0 | M32: =+M31+K32-L32 -> 489306.81
A33: 30 | B33: 45899 | E33: 624.73 | F33: 97.1 | G33: =E33*F33 -> 60661.283 | H33: 0 | I33: 0 | J33: =H33*I33 -> 0 | K33: =G33+J33 -> 60661.283 | L33: 0 | M33: =+M32+K33-L33 -> 549968.09
A34: 31 | B34: 45900 | E34: 128.5 | F34: 97.1 | G34: =E34*F34 -> 12477.35 | H34: 5 | I34: 108.83 | J34: =H34*I34 -> 544.15 | K34: =G34+J34 -> 13021.5 | L34: 0 | M34: =+M33+K34-L34 -> 562989.59
E35: =SUM(E4:E34) -> 12052.63 | G35: =SUM(G4:G34) -> 1170310.4 | H35: =SUM(H4:H34) -> 108 | J35: =SUM(J4:J34) -> 11753.64 | K35: =SUM(K4:K34) -> 1182064 | L35: =SUM(L4:L34) -> 1200000

Sheet Devarakhadra-2
A1: Sri rama F/S
A2: S.No | B2: Date | C2: GRN No | D2: Ind no/Bill No | E2: Diesel (Lts) | F2: Price | G2: Amount | H2: Petrol (Lts) | I2: Price | J2: Amount | K2: Total amount | L2: Amount paid | M2: As on Date | N2: Remarks
A3: Opening Balance | M3: 0
A4: 1 | B4: 45870 | E4: 0 | F4: 0 | G4: =E4*F4 -> 0 | H4: 0 | I4: 0 | J4: =H4*I4 -> 0 | K4: =G4+J4 -> 0 | L4: 0 | M4: =+M3+K4-L4 -> 0
A5: 2 | B5: 45871 | E5: 0 | F5: 0 | G5: =E5*F5 -> 0 | H5: 0 | I5: 0 | J5: =H5*I5 -> 0 | K5: =G5+J5 -> 0 | L5: 0 | M5: =+M4+K5-L5 -> 0
A6: 3 | B6: 45872 | E6: 0 | F6: 0 | G6: =E6*F6 -> 0 | H6: 0 | I6: 0 | J6: =H6*I6 -> 0 | K6: =G6+J6 -> 0 | L6: 0 | M6: =+M5+K6-L6 -> 0
A7: 4 | B7: 45873 | E7: 0 | F7: 0 | G7: =E7*F7 -> 0 | H7: 0 | I7: 0 | J7: =H7*I7 -> 0 | K7: =G7+J7 -> 0 | L7: 0 | M7: =+M6+K7-L7 -> 0
A8: 5 | B8: 45874 | E8: 0 | F8: 0 | G8: =E8*F8 -> 0 | H8: 0 | I8: 0 | J8: =H8*I8 -> 0 | K8: =G8+J8 -> 0 | L8: 0 | M8: =+M7+K8-L8 -> 0
A9: 6 | B9: 45875 | E9: 0 | F9: 0 | G9: =E9*F9 -> 0 | H9: 0 | I9: 0 | J9: =H9*I9 -> 0 | K9: =G9+J9 -> 0 | L9: 0 | M9: =+M8+K9-L9 -> 0
A10: 7 | B10: 45876 | E10: 0 | F10: 0 | G10: =E10*F10 -> 0 | H10: 0 | I10: 0 | J10: =H10*I10 -> 0 | K10: =G10+J10 -> 0 | L10: 0 | M10: =+M9+K10-L10 -> 0
A11: 8 | B11: 45877 | E11: 0 | F11: 0 | G11: =E11*F11 -> 0 | H11: 0 | I11: 0 | J11: =H11*I11 -> 0 | K11: =G11+J11 -> 0 | L11: 0 | M11: =+M10+K11-L11 -> 0
A12: 9 | B12: 45878 | E12: 0 | F12: 0 | G12: =E12*F12 -> 0 | H12: 0 | I12: 0 | J12: =H12*I12 -> 0 | K12: =G12+J12 -> 0 | L12: 0 | M12: =+M11+K12-L12 -> 0
A13: 10 | B13: 45879 | E13: 0 | F13: 0 | G13: =E13*F13 -> 0 | H13: 0 | I13: 0 | J13: =H13*I13 -> 0 | K13: =G13+J13 -> 0 | L13: 0 | M13: =+M12+K13-L13 -> 0
A14: 11 | B14: 45880 | E14: 644.71 | F14: 97.1 | G14: =E14*F14 -> 62601.341 | H14: 0 | I14: 0 | J14: =H14*I14 -> 0 | K14: =G14+J14 -> 62601.341 | L14: 0 | M14: =+M13+K14-L14 -> 62601.341
A15: 12 | B15: 45881 | E15: 0 | F15: 0 | G15: =E15*F15 -> 0 | H15: 0 | I15: 0 | J15: =H15*I15 -> 0 | K15: =G15+J15 -> 0 | L15: 0 | M15: =+M14+K15-L15 -> 62601.341
... A34: 31 | B34: 45900 | E34: 0 | F34: 0 | G34: =E34*F34 -> 0 | H34: 0 | I34: 0 | J34: =H34*I34 -> 0 | K34: =G34+J34 -> 0 | L34: 0 | M34: =+M33+K34-L34 -> 134013.54
E35: =SUM(E4:E34) -> 1380.16 | G35: =SUM(G4:G34) -> 134013.54 | H35: =SUM(H4:H34) -> 0 | J35: =SUM(J4:J34) -> 0 | K35: =SUM(K4:K34) -> 134013.54 | L35: =SUM(L4:L34) -> 0

Sheet Amalapuram
A1: Sathya Filling Station
A2: S.No | B2: Date | C2: GRN No | D2: Ind no/Bill No | E2: Diesel (Lts) | F2: Price | G2: Amount | H2: Petrol (Lts) | I2: Price | J2: Amount | K2: Total amount | L2: Amount paid | M2: As on Date | N2: Remarks
A3: Opening Balance | M3: 0
A4: 1 | B4: 45870 | E4: 0 | F4: 0 | G4: =E4*F4 -> 0 | H4: 0 | I4: 0 | J4: =H4*I4 -> 0 | K4: =G4+J4 -> 0 | L4: 0 | M4: =+M3+K4-L4 -> 0
A5: 2 | B5: 45871 | E5: 0 | F5: 0 | G5: =E5*F5 -> 0 | H5: 0 | I5: 0 | J5: =H5*I5 -> 0 | K5: =G5+J5 -> 0 | L5: 0 | M5: =+M4+K5-L5 -> 0
A6: 3 | B6: 45872 | E6: 46.14 | F6: 97.38 | G6: =E6*F6 -> 4493.1132 | H6: 0 | I6: 0 | J6: =H6*I6 -> 0 | K6: =G6+J6 -> 4493.1132 | L6: 4493.1132 | M6: =+M5+K6-L6 -> 0
A7: 4 | B7: 45873 | E7: 0 | F7: 0 | G7: =E7*F7 -> 0 | H7: 0 | I7: 0 | J7: =H7*I7 -> 0 | K7: =G7+J7 -> 0 | L7: 0 | M7: =+M6+K7-L7 -> 0
A8: 5 | B8: 45874 | E8: 46.04 | F8: 97.38 | G8: =E8*F8 -> 4483.3752 | H8: 0 | I8: 0 | J8: =H8*I8 -> 0 | K8: =G8+J8 -> 4483.3752 | L8: 4483.3752 | M8: =+M7+K8-L8 -> 0
A9: 6 | B9: 45875 | E9: 0 | F9: 0 | G9: =E9*F9 -> 0 | H9: 20 | I9: 109.55 | J9: =H9*I9 -> 2191 | K9: =G9+J9 -> 2191 | L9: 2191 | M9: =+M8+K9-L9 -> 0
A10: 7 | B10: 45876 | E10: 0 | F10: 0 | G10: =E10*F10 -> 0 | H10: 0 | I10: 0 | J10: =H10*I10 -> 0 | K10: =G10+J10 -> 0 | L10: 0 | M10: =+M9+K10-L10 -> 0
A11: 8 | B11: 45877 | E11: 0 | F11: 0 | G11: =E11*F11 -> 0 | H11: 0 | I11: 0 | J11: =H11*I11 -> 0 | K11: =G11+J11 -> 0 | L11: 0 | M11: =+M10+K11-L11 -> 0
A12: 9 | B12: 45878 | E12: 0 | F12: 0 | G12: =E12*F12 -> 0 | H12: 0 | I12: 0 | J12: =H12*I12 -> 0 | K12: =G12+J12 -> 0 | L12: 0 | M12: =+M11+K12-L12 -> 0
A13: 10 | B13: 45879 | E13: 0 | F13: 0 | G13: =E13*F13 -> 0 | H13: 15 | I13: 109.55 | J13: =H13*I13 -> 1643.25 | K13: =G13+J13 -> 1643.25 | L13: 1643.25 | M13: =+M12+K13-L13 -> 0
A14: 11 | B14: 45880 | E14: 42.91 | F14: 97.38 | G14: =E14*F14 -> 4178.5758 | H14: 0 | I14: 0 | J14: =H14*I14 -> 0 | K14: =G14+J14 -> 4178.5758 | L14: 4178.5758 | M14: =+M13+K14-L14 -> 0
A15: 12 | B15: 45881 | E15: 0 | F15: 0 | G15: =E15*F15 -> 0 | H15: 0 | I15: 0 | J15: =H15*I15 -> 0 | K15: =G15+J15 -> 0 | L15: 0 | M15: =+M14+K15-L15 -> 0
... A34: 31 | B34: 45900 | E34: 0 | F34: 0 | G34: =E34*F34 -> 0 | H34: 0 | I34: 0 | J34: =H34*I34 -> 0 | K34: =G34+J34 -> 0 | L34: 0 | M34: =+M33+K34-L34 -> 0.0045
E35: =SUM(E4:E34) -> 224.73 | G35: =SUM(G4:G34) -> 21892.275 | H35: =SUM(H4:H34) -> 74.19 | J35: =SUM(J4:J34) -> 8122.7237 | K35: =SUM(K4:K34) -> 30014.999 | L35: =SUM(L4:L34) -> 30014.994

Sheet Kadur
A1: Vishal Service Station
A2: S.No | B2: Date | C2: GRN No | D2: Ind No/Bill No | E2: Diesel (Lts) | F2: Price | G2: Amount | H2: Petrol (Lts) | I2: Price | J2: Amount | K2: Total amount | L2: Amount paid | M2: As on Date | N2: Remarks
A3: Opening Balance | K3: 405569.43 | M3: 405569.43 | O3: 207239.43
A4: 1 | B4: 45870 | F4: 0 | G4: =E4*F4 -> 0 | H4: 0 | I4: 0 | J4: =H4*I4 -> 0 | K4: =G4+J4 -> 0 | M4: =M3+K4-L4 -> 405569.43
A5: 2 | B5: 45871 | F5: 0 | G5: =E5*F5 -> 0 | H5: 0 | I5: 0 | J5: =H5*I5 -> 0 | K5: =G5+J5 -> 0 | M5: =M4+K5-L5 -> 405569.43
A6: 3 | B6: 45872 | F6: 0 | G6: =E6*F6 -> 0 | H6: 0 | I6: 0 | J6: =H6*I6 -> 0 | K6: =G6+J6 -> 0 | M6: =M5+K6-L6 -> 405569.43
A7: 4 | B7: 45873 | F7: 0 | G7: =E7*F7 -> 0 | H7: 0 | I7: 0 | J7: =H7*I7 -> 0 | K7: =G7+J7 -> 0 | M7: =M6+K7-L7 -> 405569.43
A8: 5 | B8: 45874 | F8: 0 | G8: =E8*F8 -> 0 | H8: 0 | I8: 0 | J8: =H8*I8 -> 0 | K8: =G8+J8 -> 0 | M8: =M7+K8-L8 -> 405569.43
A9: 6 | B9: 45875 | F9: 0 | G9: =E9*F9 -> 0 | H9: 0 | I9: 0 | J9: =H9*I9 -> 0 | K9: =G9+J9 -> 0 | M9: =M8+K9-L9 -> 405569.43
A10: 7 | B10: 45876 | F10: 0 | G10: =E10*F10 -> 0 | H10: 0 | I10: 0 | J10: =H10*I10 -> 0 | K10: =G10+J10 -> 0 | M10: =M9+K10-L10 -> 405569.43
A11: 8 | B11: 45877 | F11: 0 | G11: =E11*F11 -> 0 | H11: 0 | I11: 0 | J11: =H11*I11 -> 0 | K11: =G11+J11 -> 0 | M11: =M10+K11-L11 -> 405569.43
A12: 9 | B12: 45878 | F12: 0 | G12: =E12*F12 -> 0 | H12: 0 | I12: 0 | J12: =H12*I12 -> 0 | K12: =G12+J12 -> 0 | M12: =M11+K12-L12 -> 405569.43
A13: 10 | B13: 45879 | F13: 0 | G13: =E13*F13 -> 0 | H13: 0 | I13: 0 | J13: =H13*I13 -> 0 | K13: =G13+J13 -> 0 | M13: =M12+K13-L13 -> 405569.43
A14: 11 | B14: 45880 | F14: 0 | G14: =E14*F14 -> 0 | H14: 0 | I14: 0 | J14: =H14*I14 -> 0 | K14: =G14+J14 -> 0 | M14: =M13+K14-L14 -> 405569.43
A15: 12 | B15: 45881 | F15: 0 | G15: =E15*F15 -> 0 | H15: 0 | I15: 0 | J15: =H15*I15 -> 0 | K15: =G15+J15 -> 0 | M15: =M14+K15-L15 -> 405569.43
... A33: 30 | B33: 45899 | F33: 0 | G33: =E33*F33 -> 0 | H33: 0 | I33: 0 | J33: =H33*I33 -> 0 | K33: =G33+J33 -> 0 | M33: =M32+K33-L33 -> 417039.13
A34: 31 | F34: 0 | G34: =E34*F34 -> 0 | J34: =H34*I34 -> 0 | K34: =G34+J34 -> 0
E35: =SUM(E4:E34) -> 0 | G35: =SUM(G4:G34) -> 0 | H35: =SUM(H4:H34) -> 110 | J35: =SUM(J4:J34) -> 11469.7 | K35: =SUM(K4:K34) -> 11469.7 | L35: =SUM(L4:L31) -> 0

Sheet YG Gudda 
A1: Pallavi Petrolium
A2: S.No | B2: Date | C2: GRN No | D2: Ind No/Bill No | E2: Diesel (Lts) | F2: Price | G2: Amount | H2: Petrol (Lts) | I2: Price | J2: Amount | K2: Total amount | L2: Amount paid | M2: As on Date | N2: Remarks
A3: Opening Balance | K3: 99992.615 | M3: =+K3 -> 99992.615 | O3: 99992.615
A4: 1 | B4: 45870 | E4: 0 | F4: 0 | G4: =E4*F4 -> 0 | H4: 0 | I4: 0 | J4: =H4*I4 -> 0 | K4: =G4+J4 -> 0 | M4: =M3+K4-L4 -> 99992.615
A5: 2 | B5: 45871 | E5: 0 | F5: 0 | G5: =E5*F5 -> 0 | H5: 0 | I5: 0 | J5: =H5*I5 -> 0 | K5: =G5+J5 -> 0 | L5: 100000 | M5: =M4+K5-L5 -> -7.3854862
A6: 3 | B6: 45872 | E6: 0 | F6: 0 | G6: =E6*F6 -> 0 | H6: 0 | I6: 0 | J6: =H6*I6 -> 0 | K6: =G6+J6 -> 0 | M6: =M5+K6-L6 -> -7.3854862
A7: 4 | B7: 45873 | E7: 0 | F7: 0 | G7: =E7*F7 -> 0 | H7: 0 | I7: 0 | J7: =H7*I7 -> 0 | K7: =G7+J7 -> 0 | M7: =M6+K7-L7 -> -7.3854862
A8: 5 | B8: 45874 | E8: 0 | F8: 0 | G8: =E8*F8 -> 0 | H8: 0 | I8: 0 | J8: =H8*I8 -> 0 | K8: =G8+J8 -> 0 | M8: =M7+K8-L8 -> -7.3854862
A9: 6 | B9: 45875 | E9: 0 | F9: 0 | G9: =E9*F9 -> 0 | H9: 0 | I9: 0 | J9: =H9*I9 -> 0 | K9: =G9+J9 -> 0 | M9: =M8+K9-L9 -> -7.3854862
A10: 7 | B10: 45876 | E10: 2000 | F10: 91.3 | G10: =E10*F10 -> 182600 | H10: 105 | I10: 103.24 | J10: =H10*I10 -> 10840.2 | K10: =G10+J10 -> 193440.2 | M10: =M9+K10-L10 -> 193432.81
A11: 8 | B11: 45877 | E11: 0 | F11: 0 | G11: =E11*F11 -> 0 | H11: 0 | I11: 0 | J11: =H11*I11 -> 0 | K11: =G11+J11 -> 0 | M11: =M10+K11-L11 -> 193432.81
A12: 9 | B12: 45878 | E12: 0 | F12: 0 | G12: =E12*F12 -> 0 | H12: 0 | I12: 0 | J12: =H12*I12 -> 0 | K12: =G12+J12 -> 0 | M12: =M11+K12-L12 -> 193432.81
A13: 10 | B13: 45879 | E13: 0 | F13: 0 | G13: =E13*F13 -> 0 | H13: 0 | I13: 0 | J13: =H13*I13 -> 0 | K13: =G13+J13 -> 0 | M13: =M12+K13-L13 -> 193432.81
A14: 11 | B14: 45880 | E14: 0 | F14: 0 | G14: =E14*F14 -> 0 | H14: 0 | I14: 0 | J14: =H14*I14 -> 0 | K14: =G14+J14 -> 0 | M14: =M13+K14-L14 -> 193432.81
A15: 12 | B15: 45881 | E15: 0 | F15: 0 | G15: =E15*F15 -> 0 | H15: 0 | I15: 0 | J15: =H15*I15 -> 0 | K15: =G15+J15 -> 0 | M15: =M14+K15-L15 -> 193432.81
A16: 13 | B16: 45882 | E16: 0 | F16: 0 | G16: =E16*F16 -> 0 | H16: 0 | I16: 0 | J16: =H16*I16 -> 0 | K16: =G16+J16 -> 0 | L16: 150000 | M16: =M15+K16-L16 -> 43432.815
A17: 14 | B17: 45883 | E17: 0 | F17: 0 | G17: =E17*F17 -> 0 | H17: 0 | I17: 0 | J17: =H17*I17 -> 0 | K17: =G17+J17 -> 0 | M17: =M16+K17-L17 -> 43432.815
A18: 15 | B18: 45884 | E18: 0 | F18: 0 | G18: =E18*F18 -> 0 | H18: 0 | I18: 0 | J18: =H18*I18 -> 0 | K18: =G18+J18 -> 0 | M18: =M17+K18-L18 -> 43432.815
A19: 16 | B19: 45885 | E19: 0 | F19: 0 | G19: =E19*F19 -> 0 | H19: 0 | I19: 0 | J19: =H19*I19 -> 0 | K19: =G19+J19 -> 0 | M19: =M18+K19-L19 -> 43432.815
A20: 17 | B20: 45886 | E20: 0 | F20: 0 | G20: =E20*F20 -> 0 | H20: 0 | I20: 0 | J20: =H20*I20 -> 0 | K20: =G20+J20 -> 0 | M20: =M19+K20-L20 -> 43432.815
A21: 18 | B21: 45887 | E21: 0 | F21: 0 | G21: =E21*F21 -> 0 | H21: 0 | I21: 0 | J21: =H21*I21 -> 0 | K21: =G21+J21 -> 0 | M21: =M20+K21-L21 -> 43432.815
A22: 19 | B22: 45888 | E22: 0 | F22: 0 | G22: =E22*F22 -> 0 | H22: 105 | I22: 103.24 | J22: =H22*I22 -> 10840.2 | K22: =G22+J22 -> 10840.2 | M22: =M21+K22-L22 -> 54273.015
A23: 20 | B23: 45889 | E23: 0 | F23: 0 | G23: =E23*F23 -> 0 | H23: 0 | I23: 0 | J23: =H23*I23 -> 0 | K23: =G23+J23 -> 0 | M23: =M22+K23-L23 -> 54273.015
A24: 21 | B24: 45890 | E24: 1000 | F24: 91.3 | G24: =E24*F24 -> 91300 | H24: 0 | I24: 0 | J24: =H24*I24 -> 0 | K24: =G24+J24 -> 91300 | M24: =M23+K24-L24 -> 145573.01
A25: 22 | B25: 45891 | E25: 0 | F25: 0 | G25: =E25*F25 -> 0 | H25: 0 | I25: 0 | J25: =H25*I25 -> 0 | K25: =G25+J25 -> 0 | M25: =M24+K25-L25 -> 145573.01
A26: 23 | B26: 45892 | E26: 0 | F26: 0 | G26: =E26*F26 -> 0 | H26: 0 | I26: 0 | J26: =H26*I26 -> 0 | K26: =G26+J26 -> 0 | M26: =M25+K26-L26 -> 145573.01
A27: 24 | B27: 45893 | E27: 0 | F27: 0 | G27: =E27*F27 -> 0 | H27: 0 | I27: 0 | J27: =H27*I27 -> 0 | K27: =G27+J27 -> 0 | M27: =M26+K27-L27 -> 145573.01
A28: 25 | B28: 45894 | E28: 1400 | F28: 91.3 | G28: =E28*F28 -> 127820 | H28: 105 | I28: 103.24 | J28: =H28*I28 -> 10840.2 | K28: =G28+J28 -> 138660.2 | M28: =M27+K28-L28 -> 284233.21
... A34: 31 | B34: 45900 | E34: 0 | F34: 0 | G34: =E34*F34 -> 0 | H34: 0 | I34: 0 | J34: =H34*I34 -> 0 | K34: =G34+J34 -> 0 | M34: =M33+K34-L34 -> 284233.21
A35: 32 | E35: 0 | G35: =E35*F35 -> 0 | H35: 0 | J35: =H35*I35 -> 0 | K35: =G35+J35 -> 0 | M35: =M34+K35-L35 -> 284233.21
E36: =SUM(E4:E35) -> 4400 | G36: =SUM(G4:G35) -> 401720 | H36: =SUM(H4:H35) -> 315 | J36: =SUM(J4:J35) -> 32520.6 | K36: =SUM(K4:K35) -> 434240.6 | L36: =SUM(L4:L35) -> 250000

Sheet YG Gudda-2
A1: Pankaja HP Fuel Center
A2: S.No | B2: Date | C2: GRN No | D2: Ind No/Bill No | E2: Diesel (Lts) | F2: Price | G2: Amount | H2: Petrol (Lts) | I2: Price | J2: Amount | K2: Total amount | L2: Amount paid | M2: As on Date | N2: Remarks
A3: Opening Balance | K3: 0 | M3: =+K3 -> 0 | O3: 99992.615
A4: 1 | B4: 45870 | E4: 2400 | F4: 91.33 | G4: =E4*F4 -> 219192 | H4: 105 | I4: 103.27 | J4: =H4*I4 -> 10843.35 | K4: =G4+J4 -> 230035.35 | M4: =M3+K4-L4 -> 230035.35
A5: 2 | B5: 45871 | E5: 0 | F5: 0 | G5: =E5*F5 -> 0 | H5: 0 | I5: 0 | J5: =H5*I5 -> 0 | K5: =G5+J5 -> 0 | L5: 0 | M5: =M4+K5-L5 -> 230035.35
A6: 3 | B6: 45872 | E6: 0 | F6: 0 | G6: =E6*F6 -> 0 | H6: 0 | I6: 0 | J6: =H6*I6 -> 0 | K6: =G6+J6 -> 0 | M6: =M5+K6-L6 -> 230035.35
A7: 4 | B7: 45873 | E7: 0 | F7: 0 | G7: =E7*F7 -> 0 | H7: 0 | I7: 0 | J7: =H7*I7 -> 0 | K7: =G7+J7 -> 0 | M7: =M6+K7-L7 -> 230035.35
A8: 5 | B8: 45874 | E8: 0 | F8: 0 | G8: =E8*F8 -> 0 | H8: 0 | I8: 0 | J8: =H8*I8 -> 0 | K8: =G8+J8 -> 0 | M8: =M7+K8-L8 -> 230035.35
A9: 6 | B9: 45875 | E9: 0 | F9: 0 | G9: =E9*F9 -> 0 | H9: 0 | I9: 0 | J9: =H9*I9 -> 0 | K9: =G9+J9 -> 0 | M9: =M8+K9-L9 -> 230035.35
A10: 7 | B10: 45876 | E10: 0 | F10: 0 | G10: =E10*F10 -> 0 | H10: 0 | I10: 0 | J10: =H10*I10 -> 0 | K10: =G10+J10 -> 0 | M10: =M9+K10-L10 -> 230035.35
A11: 8 | B11: 45877 | E11: 0 | F11: 0 | G11: =E11*F11 -> 0 | H11: 0 | I11: 0 | J11: =H11*I11 -> 0 | K11: =G11+J11 -> 0 | M11: =M10+K11-L11 -> 230035.35
A12: 9 | B12: 45878 | E12: 0 | F12: 0 | G12: =E12*F12 -> 0 | H12: 0 | I12: 0 | J12: =H12*I12 -> 0 | K12: =G12+J12 -> 0 | M12: =M11+K12-L12 -> 230035.35
A13: 10 | B13: 45879 | E13: 0 | F13: 0 | G13: =E13*F13 -> 0 | H13: 0 | I13: 0 | J13: =H13*I13 -> 0 | K13: =G13+J13 -> 0 | M13: =M12+K13-L13 -> 230035.35
A14: 11 | B14: 45880 | E14: 0 | F14: 0 | G14: =E14*F14 -> 0 | H14: 0 | I14: 0 | J14: =H14*I14 -> 0 | K14: =G14+J14 -> 0 | M14: =M13+K14-L14 -> 230035.35
A15: 12 | B15: 45881 | E15: 0 | F15: 0 | G15: =E15*F15 -> 0 | H15: 0 | I15: 0 | J15: =H15*I15 -> 0 | K15: =G15+J15 -> 0 | L15: 230000 | M15: =M14+K15-L15 -> 35.35
A16: 13 | B16: 45882 | E16: 2400 | F16: 91.33 | G16: =E16*F16 -> 219192 | H16: 105 | I16: 103.27 | J16: =H16*I16 -> 10843.35 | K16: =G16+J16 -> 230035.35 | M16: =M15+K16-L16 -> 230070.7
A17: 14 | B17: 45883 | E17: 0 | F17: 0 | G17: =E17*F17 -> 0 | H17: 0 | I17: 0 | J17: =H17*I17 -> 0 | K17: =G17+J17 -> 0 | M17: =M16+K17-L17 -> 230070.7
A18: 15 | B18: 45884 | E18: 0 | F18: 0 | G18: =E18*F18 -> 0 | H18: 0 | I18: 0 | J18: =H18*I18 -> 0 | K18: =G18+J18 -> 0 | M18: =M17+K18-L18 -> 230070.7
A19: 16 | B19: 45885 | E19: 0 | F19: 0 | G19: =E19*F19 -> 0 | H19: 0 | I19: 0 | J19: =H19*I19 -> 0 | K19: =G19+J19 -> 0 | M19: =M18+K19-L19 -> 230070.7
A20: 17 | B20: 45886 | E20: 0 | F20: 0 | G20: =E20*F20 -> 0 | H20: 0 | I20: 0 | J20: =H20*I20 -> 0 | K20: =G20+J20 -> 0 | M20: =M19+K20-L20 -> 230070.7
A21: 18 | B21: 45887 | E21: 0 | F21: 0 | G21: =E21*F21 -> 0 | H21: 0 | I21: 0 | J21: =H21*I21 -> 0 | K21: =G21+J21 -> 0 | M21: =M20+K21-L21 -> 230070.7
A22: 19 | B22: 45888 | E22: 0 | F22: 0 | G22: =E22*F22 -> 0 | H22: 0 | I22: 0 | J22: =H22*I22 -> 0 | K22: =G22+J22 -> 0 | M22: =M21+K22-L22 -> 230070.7
A23: 20 | B23: 45889 | E23: 0 | F23: 0 | G23: =E23*F23 -> 0 | H23: 0 | I23: 0 | J23: =H23*I23 -> 0 | K23: =G23+J23 -> 0 | M23: =M22+K23-L23 -> 230070.7
A24: 21 | B24: 45890 | E24: 0 | F24: 0 | G24: =E24*F24 -> 0 | H24: 0 | I24: 0 | J24: =H24*I24 -> 0 | K24: =G24+J24 -> 0 | M24: =M23+K24-L24 -> 230070.7
A25: 22 | B25: 45891 | E25: 0 | F25: 0 | G25: =E25*F25 -> 0 | H25: 0 | I25: 0 | J25: =H25*I25 -> 0 | K25: =G25+J25 -> 0 | M25: =M24+K25-L25 -> 230070.7
A26: 23 | B26: 45892 | E26: 0 | F26: 0 | G26: =E26*F26 -> 0 | H26: 0 | I26: 0 | J26: =H26*I26 -> 0 | K26: =G26+J26 -> 0 | M26: =M25+K26-L26 -> 230070.7
A27: 24 | B27: 45893 | E27: 0 | F27: 0 | G27: =E27*F27 -> 0 | H27: 0 | I27: 0 | J27: =H27*I27 -> 0 | K27: =G27+J27 -> 0 | M27: =M26+K27-L27 -> 230070.7
... A34: 31 | B34: 45900 | E34: 0 | F34: 0 | G34: =E34*F34 -> 0 | H34: 0 | I34: 0 | J34: =H34*I34 -> 0 | K34: =G34+J34 -> 0 | M34: =M33+K34-L34 -> 230070.7
A35: 32 | E35: 0 | G35: =E35*F35 -> 0 | H35: 0 | J35: =H35*I35 -> 0 | K35: =G35+J35 -> 0 | M35: =M34+K35-L35 -> 230070.7
E36: =SUM(E4:E35) -> 4800 | G36: =SUM(G4:G35) -> 438384 | H36: =SUM(H4:H35) -> 210 | J36: =SUM(J4:J35) -> 21686.7 | K36: =SUM(K4:K35) -> 460070.7 | L36: =SUM(L4:L35) -> 230000

Sheet Hosadurga
A1: Merchant Petroliums
A2: S.No | B2: Date | C2: GRN No | D2: Ind No/Bill No | E2: Diesel (Lts) | F2: Price | G2: Amount | H2: Petrol (Lts) | I2: Price | J2: Amount | K2: Total amount | L2: Amount paid | M2: As on Date | N2: Remarks
A3: Opening Balance | K3: 0 | M3: =+K3 -> 0
A4: 1 | B4: 45870 | G4: =E4*F4 -> 0 | H4: 0 | J4: =H4*I4 -> 0 | K4: =G4+J4 -> 0 | L4: 0 | M4: =M3+K4-L4 -> 0
A5: 2 | B5: 45871 | G5: =E5*F5 -> 0 | H5: 0 | I5: 0 | J5: =H5*I5 -> 0 | K5: =G5+J5 -> 0 | L5: 0 | M5: =M4+K5-L5 -> 0
A6: 3 | B6: 45872 | G6: =E6*F6 -> 0 | H6: 0 | I6: 0 | J6: =H6*I6 -> 0 | K6: =G6+J6 -> 0 | L6: 0 | M6: =M5+K6-L6 -> 0
A7: 4 | B7: 45873 | G7: =E7*F7 -> 0 | H7: 0 | I7: 0 | J7: =H7*I7 -> 0 | K7: =G7+J7 -> 0 | L7: 0 | M7: =M6+K7-L7 -> 0
A8: 5 | B8: 45874 | G8: =E8*F8 -> 0 | H8: 0 | I8: 0 | J8: =H8*I8 -> 0 | K8: =G8+J8 -> 0 | L8: 0 | M8: =M7+K8-L8 -> 0
A9: 6 | B9: 45875 | G9: =E9*F9 -> 0 | H9: 0 | I9: 0 | J9: =H9*I9 -> 0 | K9: =G9+J9 -> 0 | L9: 0 | M9: =M8+K9-L9 -> 0
A10: 7 | B10: 45876 | G10: =E10*F10 -> 0 | H10: 0 | I10: 0 | J10: =H10*I10 -> 0 | K10: =G10+J10 -> 0 | L10: 0 | M10: =M9+K10-L10 -> 0
A11: 8 | B11: 45877 | G11: =E11*F11 -> 0 | H11: 0 | I11: 0 | J11: =H11*I11 -> 0 | K11: =G11+J11 -> 0 | L11: 0 | M11: =M10+K11-L11 -> 0
A12: 9 | B12: 45878 | G12: =E12*F12 -> 0 | H12: 0 | I12: 0 | J12: =H12*I12 -> 0 | K12: =G12+J12 -> 0 | L12: 0 | M12: =M11+K12-L12 -> 0
A13: 10 | B13: 45879 | G13: =E13*F13 -> 0 | H13: 0 | I13: 0 | J13: =H13*I13 -> 0 | K13: =G13+J13 -> 0 | L13: 0 | M13: =M12+K13-L13 -> 0
