Workbook

Sheet Oct-25 
A1: S.no | B1: Site Name | C1: Bunk Name | D1: Diesel(Liters) | E1: Diesel Amount | F1: Petrol(Liters) | G1: Petrol Amount | H1: Total Amount | I1: Opening Blance | J1: Amount Paid | K1: Closing Balances
A2: 1 | B2: Khammam-1 | C2: Divya laxmi ganapathi | D2: =+'Khammam-1'!E38 -> 56900 | E2: =+'Khammam-1'!G38 -> 5444192 | F2: =+'Khammam-1'!H38 -> 235 | G2: =+'Khammam-1'!J38 -> 25253.1 | H2: =E2+G2 -> 5469445.1 | I2: =+'Khammam-1'!K3 -> 11177697 | J2: =+'Khammam-1'!L38 -> 7500000 | K2: =H2+I2-J2 -> 9147141.7
A3: 2 | B3: Khammam-2 | C3: Jayasai union bunk | D3: =+'Khammam-2'!E38 -> 111000 | E3: =+'Khammam-2'!G38 -> 10622700 | F3: =+'Khammam-2'!H38 -> 900 | G3: =+'Khammam-2'!J38 -> 96732 | H3: =E3+G3 -> 10719432 | I3: =+'Khammam-2'!K3 -> 13443331 | J3: =+'Khammam-2'!L38 -> 0 | K3: =H3+I3-J3 -> 24162763
A4: 3 | B4: Jadcherla-1 | C4: Sai Baba Fuel Station | D4: =+'Jedcherla -1'!E36 -> 12153.6 | E4: =+'Jedcherla -1'!G36 -> 1171850.1 | F4: =+'Jedcherla -1'!H36 -> 693.13 | G4: =+'Jedcherla -1'!J36 -> 75018.46 | H4: =E4+G4 -> 1246868.6 | I4: =+'Jedcherla -1'!M3 -> 2639914.6 | J4: =+'Jedcherla -1'!L36 -> 2175000 | K4: =H4+I4-J4 -> 1711783.1
A5: 4 | B5: Jadcherla-2 | C5: ADHOC FILLING STATION STATION | D5: =+'Jedcharla-2'!E35 -> 51700 | E5: =+'Jedcharla-2'!G35 -> 4985431 | F5: 0 | G5: 0 | H5: =E5+G5 -> 4985431 | I5: =+'Jedcharla-2'!K3 -> 238933 | J5: =+'Jedcharla-2'!L35 -> 2900000 | K5: =H5+I5-J5 -> 2324364
A6: 5 | B6: Dindi | C6: Akarapu Balakistamma Fillling | D6: =+Dindi!E35 -> 85.88 | E6: =+Dindi!G35 -> 8315.7604 | F6: =+Dindi!H35 -> 0 | G6: =+Dindi!J35 -> 0 | H6: =E6+G6 -> 8315.7604 | J6: =+Dindi!L35 -> 8315.7604 | K6: =H6+I6-J6 -> 0
A7: 6 | B7: Devarkhadra-1 | C7: Kurumurthy Swami F/S | D7: =+Devarakhadra!E35 -> 7811.71 | E7: =+Devarakhadra!G35 -> 758517.04 | F7: =+Devarakhadra!H35 -> 129 | G7: =+Devarakhadra!J35 -> 14039.07 | H7: =E7+G7 -> 772556.11 | I7: =+Devarakhadra!M3 -> 121213.37 | J7: =+Devarakhadra!L35 -> 700000 | K7: =H7+I7-J7 -> 193769.48
A8: 7 | B8: Devarkhadra-2 | C8: M/S. Sri Rama Filling Station | D8: =+'Devarakhadra-2'!E35 -> 0 | E8: =+'Devarakhadra-2'!G35 -> 0 | F8: =+'Devarakhadra-2'!H35 -> 0 | G8: =+'Devarakhadra-2'!I35 -> 0 | H8: =E8+G8 -> 0 | I8: =+'Devarakhadra-2'!M3 -> 132273.54 | J8: =+'Devarakhadra-2'!L35 -> 132200 | K8: =H8+I8-J8 -> 73.536
A9: 8 | B9: Devarkhadra-3 | C9: JSASFuel Genie India Pvt.Ltd | D9: =+'Devarakhadra-3'!E35 -> 1743.87 | E9: =+'Devarakhadra-3'!G35 -> 167115.06 | F9: =+'Devarakhadra-3'!H35 -> 0 | G9: =+'Devarakhadra-3'!I35 -> 0 | H9: =E9+G9 -> 167115.06 | I9: =+'Devarakhadra-3'!M3 -> 0 | J9: =+'Devarakhadra-3'!L35 -> 0 | K9: =+'Devarakhadra-3'!M34 -> 167115.06
A10: 9 | B10: MAdanapalli | C10: Sri Mallikarjuna Traders | D10: =+'Madana palli'!E35 -> 1126.73 | E10: =+'Madana palli'!G35 -> 109975.3 | F10: =+'Madana palli'!H35 -> 15.93 | G10: =+'Madana palli'!J35 -> 1748.1757 | H10: =E10+G10 -> 111723.48 | I10: =+'Madana palli'!M3 -> 0 | J10: =+'Madana palli'!L35 -> 111723.48 | K10: =+'Devarakhadra-3'!M35 -> 0
A11: 10 | B11: Amalapuram | C11: Sathya Filling Station | D11: =+Amalapuram!E37 -> 340.68 | E11: =+Amalapuram!G37 -> 32321.64 | F11: =+Amalapuram!H37 -> 175 | G11: =+Amalapuram!J37 -> 19169.45 | H11: =E11+G11 -> 51491.09 | I11: =+Amalapuram!M3 -> 0 | J11: =+Amalapuram!L37 -> 51491.095 | K11: =H11+I11-J11 -> -0.0045
A12: 11 | B12: YG Gudda-1 | C12: Pallavi Petrolium | D12: =+'YG Gudda '!E36 -> 1000 | E12: =+'YG Gudda '!G36 -> 91300 | F12: =+'YG Gudda '!H36 -> 210 | G12: =+'YG Gudda '!J36 -> 21680.4 | H12: =E12+G12 -> 112980.4 | I12: ='YG Gudda '!K3 -> 109814.66 | J12: =+'YG Gudda '!L36 -> 120000 | K12: =H12+I12-J12 -> 102795.06
A13: 12 | B13: YG Gudda-2 | C13: Pankaja HP Fuel Center | D13: =+'YG Gudda-2'!E36 -> 8100 | E13: =+'YG Gudda-2'!G36 -> 739773 | F13: =+'YG Gudda-2'!H36 -> 280 | G13: =+'YG Gudda-2'!J36 -> 28915.6 | H13: =E13+G13 -> 768688.6 | I13: =+'YG Gudda-2'!M3 -> 306111 | J13: =+'YG Gudda-2'!L36 -> 750000 | K13: =H13+I13-J13 -> 324799.6
A14: 13 | B14: Hosadurga-1 | C14: Merchant Petroliums | D14: =+Hosadurga!E35 -> 0 | E14: =+Hosadurga!G35 -> 0 | F14: =+Hosadurga!H35 -> 0 | G14: =+Hosadurga!J35 -> 0 | H14: =E14+G14 -> 0 | I14: =+Hosadurga!K3 -> 2258.6 | J14: =+Hosadurga!L35 -> 0 | K14: =H14+I14-J14 -> 2258.6
A15: 14 | B15: Hosadurga-2 | C15: Shree Veeraprathap Fuel | D15: =+'Hosadurga -2'!E35 -> 7100 | E15: =+'Hosadurga -2'!G35 -> 649792 | F15: =+'Hosadurga -2'!H35 -> 310 | G15: =+'Hosadurga -2'!J35 -> 32137.7 | H15: =+'Hosadurga -2'!K35 -> 681929.7 | I15: =+'Hosadurga -2'!K3 -> 277709.09 | J15: =+'Hosadurga -2'!L35 -> 500000 | K15: =H15+I15-J15 -> 459638.79
A16: 15 | B16: Malebennuru(KUWSDB) | C16: Sri Ramanjuneya Service Station | D16: =+'Malebenur(KUWSDB)'!E36 -> 3928.62 | E16: =+'Malebenur(KUWSDB)'!G36 -> 362013.42 | F16: =+'Malebenur(KUWSDB)'!H36 -> 164.86 | G16: =+'Malebenur(KUWSDB)'!J36 -> 17140.494 | H16: =E16+G16 -> 379153.91 | I16: =+'Malebenur(KUWSDB)'!K3 -> 2634.8284 | J16: =+'Malebenur(KUWSDB)'!L36 -> 342853.33 | K16: =H16+I16-J16 -> 38935.405
A17: 16 | B17: kadur | C17: Vishal Service Station | D17: =+Kadur!E35 -> 1500 | E17: =+Kadur!G35 -> 138225 | F17: =+Kadur!H35 -> 140 | G17: =+Kadur!J35 -> 14597.8 | H17: =E17+G17 -> 152822.8 | I17: =+Kadur!K3 -> 11508.831 | J17: =+Kadur!L35 -> 0 | K17: =H17+I17-J17 -> 164331.63
A18: 17 | B18: Hiriyur(VJNL) | C18: Sri Balaji Agencies | D18: =+'Hiriyur(VJNL)'!E35 -> 6800 | E18: =+'Hiriyur(VJNL)'!G35 -> 627164 | F18: =+'Hiriyur(VJNL)'!H35 -> 280 | G18: =+'Hiriyur(VJNL)'!J35 -> 29142.4 | H18: =E18+G18 -> 656306.4 | I18: =+'Hiriyur(VJNL)'!K3 -> 74841.4 | J18: =+'Hiriyur(VJNL)'!L35 -> 409797 | K18: =H18+I18-J18 -> 321350.8
A19: 18 | B19: Chellakere(KUWSDB) | C19: Sri Vishnu Baba Petroleum | D19: =+'Chellakere (KUWSDB)'!E35 -> 3055 | E19: =+'Chellakere (KUWSDB)'!G35 -> 281665.35 | F19: =+'Chellakere (KUWSDB)'!H35 -> 145 | G19: =+'Chellakere (KUWSDB)'!J35 -> 15084.35 | H19: =E19+G19 -> 296749.7 | I19: 0 | J19: =+'Chellakere (KUWSDB)'!L35 -> 296749.75 | K19: =H19+I19-J19 -> -0.05
A20: 19 | B20: Molakalmuru | C20: Sri Lakshmi Venkateshwara Filling Station | D20: =+Molakamuru!E36 -> 1199.996 | E20: =+Molakamuru!G36 -> 110652.63 | F20: =+Molakamuru!H36 -> 45 | G20: =+Molakamuru!J36 -> 4682.4 | H20: =E20+G20 -> 115335.03 | I20: =+Molakamuru!K3 -> 0 | J20: =+Molakamuru!L36 -> 115335.03 | K20: =H20+I20-J20 -> 0
A21: 20 | B21: Khanapur(PKG-3) | C21: V.V.Varde | D21: =+Khanapur!E35 -> 1063.75 | E21: =+Khanapur!G35 -> 96666 | F21: =+Khanapur!H35 -> 81 | G21: =+Khanapur!J35 -> 8324.37 | H21: =E21+G21 -> 104990.37 | I21: =+Khanapur!M3 -> 10170.75 | J21: =+Khanapur!L35 -> 65000 | K21: =H21+I21-J21 -> 50161.12
A22: 21 | B22: Munavalli(PKG-3)-2 | C22: Shri Daneshwari | D22: =+'Munavali-2'!E37 -> 9723.27 | E22: =+'Munavali-2'!G37 -> 887929.02 | F22: =+'Munavali-2'!H37 -> 159 | G22: =+'Munavali-2'!J37 -> 16415.16 | H22: =E22+G22 -> 904344.18 | I22: =+'Munavali-2'!M3 -> 204851.03 | J22: =+'Munavali-2'!L37 -> 450000 | K22: =H22+I22-J22 -> 659195.2
A23: 22 | B23: Borgaon(PKG-3) | C23: Aadisagar Petrolium | D23: =+Borgaon!E37 -> 1049.33 | E23: =+Borgaon!G37 -> 96297.014 | F23: =+Borgaon!H37 -> 61 | G23: =+Borgaon!J37 -> 6364.08 | H23: =E23+G23 -> 102661.09 | I23: =+Borgaon!K3 -> 41597.607 | J23: =+Borgaon!L37 -> 82597 | K23: =H23+I23-J23 -> 61661.701
A24: 23 | B24: Ugar,Kudichi(PKG-3) | C24: Shiri Bhrhmanath Petrolium | D24: =+'Ugar,Khagwad,Kudichi'!E35 -> 2204.24 | E24: =+'Ugar,Khagwad,Kudichi'!G35 -> 202635.78 | F24: =+'Ugar,Khagwad,Kudichi'!H35 -> 301 | G24: =+'Ugar,Khagwad,Kudichi'!J35 -> 32501.74 | H24: =E24+G24 -> 235137.52 | I24: =+'Ugar,Khagwad,Kudichi'!M3 -> 230919.24 | J24: =+'Ugar,Khagwad,Kudichi'!L35 -> 231041 | K24: =H24+I24-J24 -> 235015.76
A25: 24 | B25: Kabbur(PKG-3) | C25: Shri Jai Hanuman Petrolium | D25: =+Kabbur!E35 -> 550.65 | E25: =+Kabbur!G35 -> 50434.034 | F25: =+Kabbur!H35 -> 41.33 | G25: =+Kabbur!J35 -> 4278.8949 | H25: =E25+G25 -> 54712.928 | I25: 0 | J25: =+Kabbur!L35 -> 54712.928 | K25: =H25+I25-J25 -> 0
A26: 25 | B26: Kumta (PKG-1) | C26: Krishma fuel station | D26: =+kumta!E35 -> 1364.5 | E26: =+kumta!G35 -> 125424.84 | F26: =+kumta!H35 -> 49.68 | G26: =+kumta!J35 -> 5162.9346 | H26: =E26+G26 -> 130587.77 | I26: 0 | J26: =+kumta!L35 -> 130587.77 | K26: =H26+I26-J26 -> 0
A27: 26 | B27: Jalgaon | C27: Sri Sai Petrol Pump | D27: =+Jalgaon!E48 -> 9772.69 | E27: =+Jalgaon!G48 -> 896212.92 | F27: =+Jalgaon!H48 -> 97 | G27: =+Jalgaon!J48 -> 10203.43 | H27: =E27+G27 -> 906416.35 | I27: =+Jalgaon!K3 -> 509588.32 | J27: =+Jalgaon!L48 -> 710403.36 | K27: =H27+I27-J27 -> 705601.31
A28: 27 | B28: MKBD | C28: Shree Sai Samarth Petroleum | D28: =+MKBD!E36 -> 1800 | E28: =+MKBD!G36 -> 164052 | F28: =+MKBD!H36 -> 40 | G28: =+MKBD!J36 -> 4184 | H28: =E28+G28 -> 168236 | I28: =+MKBD!K3 -> 108480.65 | J28: =+MKBD!L36 -> 0 | K28: =H28+I28-J28 -> 276716.65
A29: 28 | B29: Haveri | C29: Shivalingeshwar Petroleum | D29: =+Haveri!E36 -> 4650 | E29: =+Haveri!G36 -> 425345.26 | F29: =+Haveri!H36 -> 115.98 | G29: =+Haveri!J36 -> 11992.332 | H29: =E29+G29 -> 437337.59 | I29: =+Haveri!M3 -> 100388.61 | J29: =+Haveri!L36 -> 410000 | K29: =H29+I29-J29 -> 127726.19
A30: 29 | B30: Guttal | C30: Taware filling station | D30: =+Guttal!E35 -> 1039.61 | E30: =+Guttal!G35 -> 95436.198 | F30: =+Guttal!H35 -> 83 | G30: =+Guttal!J35 -> 8613.74 | H30: =E30+G30 -> 104049.94 | I30: 0 | J30: =+Guttal!L35 -> 67093.874 | K30: =H30+I30-J30 -> 36956.064
A31: 30 | B31: Rattihali | C31: Shree Siri Gowari petroliam | D31: =+Rattihali!E35 -> 1736.13 | E31: =+Rattihali!G35 -> 159793.41 | F31: =+Rattihali!H35 -> 63.75 | G31: =+Rattihali!J35 -> 6631.275 | H31: =E31+G31 -> 166424.68 | I31: =+Rattihali!M3 -> 173876.23 | J31: =+Rattihali!L35 -> 150000 | K31: =H31+I31-J31 -> 190300.91
A32: 31 | B32: Gajendragada | C32: Vanasri Petrol Pump | D32: =+Gajendragada!E35 -> 675 | E32: =+Gajendragada!G35 -> 61985.25 | F32: =+Gajendragada!H35 -> 25 | G32: =+Gajendragada!J35 -> 2595 | H32: =E32+G32 -> 64580.25 | I32: =+Gajendragada!K3 -> 133672.01 | J32: =+Gajendragada!L35 -> 100000 | K32: =H32+I32-J32 -> 98252.262
A33: 32 | B33: Gokak(PKG-3) | C33: AJ Petrolinks | D33: =+'Gokak Dharwad PKG 3'!E40 -> 13672.48 | E33: =+'Gokak Dharwad PKG 3'!G40 -> 1250758.5 | F33: =+'Gokak Dharwad PKG 3'!H40 -> 280.67 | G33: =+'Gokak Dharwad PKG 3'!J40 -> 29062.885 | H33: =E33+G33 -> 1279821.4 | I33: =+'Gokak Dharwad PKG 3'!K3 -> 1036892.1 | J33: =+'Gokak Dharwad PKG 3'!L40 -> 1000000 | K33: =H33+I33-J33 -> 1316713.4
A34: 33 | B34: Ankaligi | C34: Shiv ganga | D34: =+Ankalgi!E35 -> 2105.29 | E34: =+Ankalgi!G35 -> 192234.03 | F34: =+Ankalgi!H35 -> 128 | G34: =+Ankalgi!J35 -> 13213.44 | H34: =E34+G34 -> 205447.47 | I34: =+Ankalgi!M3 -> 105996.1 | J34: =+Ankalgi!L35 -> 270000 | K34: =H34+I34-J34 -> 41443.572
A35: 34 | B35: ShankeshWAR | C35: SR Patil | D35: =+' Shankeshwar'!E35 -> 485.68 | E35: =+' Shankeshwar'!G35 -> 44342.584 | F35: =+' Shankeshwar'!H35 -> 51.01 | G35: =+' Shankeshwar'!J35 -> 4644.9 | H35: =E35+G35 -> 48987.484 | J35: =+' Shankeshwar'!L35 -> 48987.484 | K35: =H35+I35-J35 -> 0
A36: 35 | B36: Talikote(PKG-1) | C36: Raykar Oil Agencies | D36: =+' Talikote'!E46 -> 1173.55 | E36: =+' Talikote'!G46 -> 107372.12 | F36: =+' Talikote'!H46 -> 127.01 | G36: =+' Talikote'!J46 -> 13137.914 | H36: =E36+G36 -> 120510.03 | I36: =+' Talikote'!N3 -> 20613.942 | J36: =+' Talikote'!L46 -> 97999.71 | K36: =H36+I36-J36 -> 43124.265
A37: 36 | B37: Chadchan(PKG-1) | C37: Khavekar Petrolium | D37: =+Chadchan!E35 -> 1424.68 | E37: =+Chadchan!G35 -> 129973.56 | F37: =+Chadchan!H35 -> 102.18 | G37: =+Chadchan!J35 -> 10540.889 | H37: =E37+G37 -> 140514.45 | I37: =+Chadchan!K3 -> 92882.428 | J37: =+Chadchan!L35 -> 90000 | K37: =H37+I37-J37 -> 143396.87
A38: 37 | B38: Sindagi | C38: G.P.PORWAL | D38: =+Sindagi!E44 -> 0 | E38: =+Sindagi!G44 -> 0 | F38: =+Sindagi!H44 -> 0 | G38: =+Sindagi!J44 -> 0 | H38: =E38+G38 -> 0 | I38: =+Sindagi!M3 -> 0 | J38: =+Sindagi!L44 -> 0 | K38: =H38+I38-J38 -> 0
A39: 38 | B39: Muddebihal(PKG-1) | C39: Bhosle Service Station | D39: =+Muddebihal!E47 -> 652.34 | E39: =+Muddebihal!G47 -> 59656.493 | F39: =+Muddebihal!H47 -> 14.84 | G39: =+Muddebihal!J47 -> 1534.3076 | H39: =E39+G39 -> 61190.801 | I39: =+Muddebihal!M3 -> 30403.024 | J39: =+Muddebihal!L47 -> 88000 | K39: =H39+I39-J39 -> 3593.8248
A40: 39 | B40: Muddebihal(PKG-1)2 | C40: PS NAGATHAN PETROLIUM | D40: =+'Muddebhihal-2'!E47 -> 481 | E40: =+'Muddebhihal-2'!G47 -> 43973.02 | F40: =+'Muddebhihal-2'!H47 -> 25 | G40: =+'Muddebhihal-2'!J47 -> 2583.75 | H40: =+'Muddebhihal-2'!K47 -> 46556.77 | I40: =+'Muddebhihal-2'!M3 -> 0 | J40: =+'Muddebhihal-2'!L47 -> 0 | K40: =+'Muddebhihal-2'!M46 -> 46556.77
...

Sheet Sheet2

Sheet Khammam-1
A1: Divya laxmi ganapathi
A2: S.No | B2: Date | C2: GRN No | D2: Ind No/Bill No | E2: Diesel (Lts) | F2: Price | G2: Amount | H2: Petrol (Lts) | I2: Price | J2: Amount | K2: Total amount | L2: Amount paid | M2: As 0n Date | N2: Remarks
A3: Opening Balance | K3: 11177697 | M3: =+K3 -> 11177697 | O3: 11178224
A4: 1 | B4: 45931 | G4: =E4*F4 -> 0 | J4: =H4*I4 -> 0 | K4: =G4+J4 -> 0 | L4: 0 | M4: =M3+K4-L4 -> 11177697
A5: 2 | B5: 45932 | G5: =E5*F5 -> 0 | J5: =H5*I5 -> 0 | K5: =G5+J5 -> 0 | M5: =M4+K5-L5 -> 11177697
A6: 3 | B6: 45933 | G6: =E6*F6 -> 0 | J6: =H6*I6 -> 0 | K6: =G6+J6 -> 0 | M6: =M5+K6-L6 -> 11177697
A7: 4 | B7: 45934 | G7: =E7*F7 -> 0 | J7: =H7*I7 -> 0 | K7: =G7+J7 -> 0 | M7: =M6+K7-L7 -> 11177697
A8: 5 | B8: 45935 | G8: =E8*F8 -> 0 | J8: =H8*I8 -> 0 | K8: =G8+J8 -> 0 | M8: =M7+K8-L8 -> 11177697
A9: 6 | B9: 45936 | G9: =E9*F9 -> 0 | J9: =H9*I9 -> 0 | K9: =G9+J9 -> 0 | M9: =M8+K9-L9 -> 11177697
A10: 7 | B10: 45937 | D10: 1 | E10: 2800 | F10: 95.68 | G10: =E10*F10 -> 267904 | H10: 20 | I10: 107.46 | J10: =H10*I10 -> 2149.2 | K10: =G10+J10 -> 270053.2 | M10: =M9+K10-L10 -> 11447750
A11: 8 | B11: 45938 | G11: =E11*F11 -> 0 | J11: =H11*I11 -> 0 | K11: =G11+J11 -> 0 | M11: =M10+K11-L11 -> 11447750
A12: 9 | B12: 45939 | D12: 2 | E12: 4000 | F12: 95.68 | G12: =E12*F12 -> 382720 | J12: =H12*I12 -> 0 | K12: =G12+J12 -> 382720 | M12: =M11+K12-L12 -> 11830470
A13: 10 | B13: 45940 | G13: =E13*F13 -> 0 | J13: =H13*I13 -> 0 | K13: =G13+J13 -> 0 | M13: =M12+K13-L13 -> 11830470
A14: 11 | B14: 45941 | D14: 3 | E14: 6500 | F14: 95.68 | G14: =E14*F14 -> 621920 | H14: 20 | I14: 107.46 | J14: =H14*I14 -> 2149.2 | K14: =G14+J14 -> 624069.2 | M14: =M13+K14-L14 -> 12454539
A15: 12 | B15: 45942 | G15: =E15*F15 -> 0 | J15: =H15*I15 -> 0 | K15: =G15+J15 -> 0 | M15: =M14+K15-L15 -> 12454539
A16: 13 | B16: 45943 | G16: =E16*F16 -> 0 | J16: =H16*I16 -> 0 | K16: =G16+J16 -> 0 | M16: =M15+K16-L16 -> 12454539
A17: 14 | B17: 45944 | G17: =E17*F17 -> 0 | J17: =H17*I17 -> 0 | K17: =G17+J17 -> 0 | L17: 5000000 | M17: =M16+K17-L17 -> 7454539
A18: 15 | B18: 45945 | G18: =E18*F18 -> 0 | J18: =H18*I18 -> 0 | K18: =G18+J18 -> 0 | M18: =M17+K18-L18 -> 7454539
A19: 16 | B19: 45946 | D19: 4 | E19: 4200 | F19: 95.68 | G19: =E19*F19 -> 401856 | H19: 20 | I19: 107.46 | J19: =H19*I19 -> 2149.2 | K19: =G19+J19 -> 404005.2 | M19: =M18+K19-L19 -> 7858544.2
A20: 17 | B20: 45947 | D20: 5 | E20: 4300 | F20: 95.68 | G20: =E20*F20 -> 411424 | H20: 20 | I20: 107.46 | J20: =H20*I20 -> 2149.2 | K20: =G20+J20 -> 413573.2 | M20: =M19+K20-L20 -> 8272117.4
A21: 18 | B21: 45948 | D21: 6 | E21: 5300 | F21: 95.68 | G21: =E21*F21 -> 507104 | H21: 20 | I21: 107.46 | J21: =H21*I21 -> 2149.2 | K21: =G21+J21 -> 509253.2 | M21: =M20+K21-L21 -> 8781370.6
A22: 19 | B22: 45949 | D22: 7 | E22: 1500 | F22: 95.68 | G22: =E22*F22 -> 143520 | J22: =H22*I22 -> 0 | K22: =G22+J22 -> 143520 | M22: =M21+K22-L22 -> 8924890.6
A23: 20 | B23: 45950 | G23: =E23*F23 -> 0 | J23: =H23*I23 -> 0 | K23: =G23+J23 -> 0 | M23: =M22+K23-L23 -> 8924890.6
A24: 21 | B24: 45951 | D24: 8 | E24: 4700 | F24: 95.68 | G24: =E24*F24 -> 449696 | H24: 60 | I24: 107.46 | J24: =H24*I24 -> 6447.6 | K24: =G24+J24 -> 456143.6 | M24: =M23+K24-L24 -> 9381034.2
A25: 22 | B25: 45952 | D25: 9 | E25: 3000 | F25: 95.68 | G25: =E25*F25 -> 287040 | J25: =H25*I25 -> 0 | K25: =G25+J25 -> 287040 | L25: 2500000 | M25: =M24+K25-L25 -> 7168074.2
A26: 23 | B26: 45953 | D26: 10 | E26: 1000 | F26: 95.68 | G26: =E26*F26 -> 95680 | J26: =H26*I26 -> 0 | K26: =G26+J26 -> 95680 | M26: =M25+K26-L26 -> 7263754.2
A27: 24 | B27: 45954 | D27: 11 | E27: 2700 | F27: 95.68 | G27: =E27*F27 -> 258336 | J27: =H27*I27 -> 0 | K27: =G27+J27 -> 258336 | M27: =M26+K27-L27 -> 7522090.2
A28: 25 | B28: 45955 | D28: 12 | E28: 2700 | F28: 95.68 | G28: =E28*F28 -> 258336 | H28: 20 | I28: 107.46 | J28: =H28*I28 -> 2149.2 | K28: =G28+J28 -> 260485.2 | M28: =M27+K28-L28 -> 7782575.4
A29: 26 | B29: 45956 | G29: =E29*F29 -> 0 | J29: =H29*I29 -> 0 | K29: =G29+J29 -> 0 | M29: =M28+K29-L29 -> 7782575.4
A30: 27 | B30: 45957 | D30: 13 | E30: 3700 | F30: 95.68 | G30: =E30*F30 -> 354016 | J30: =H30*I30 -> 0 | K30: =G30+J30 -> 354016 | M30: =M29+K30-L30 -> 8136591.4
A31: 28 | B31: 45958 | D31: 14 | E31: 2700 | F31: 95.68 | G31: =E31*F31 -> 258336 | H31: 20 | I31: 107.46 | J31: =H31*I31 -> 2149.2 | K31: =G31+J31 -> 260485.2 | M31: =M30+K31-L31 -> 8397076.6
A32: 29 | B32: 45959 | D32: 15 | E32: 2800 | F32: 95.68 | G32: =E32*F32 -> 267904 | J32: =H32*I32 -> 0 | K32: =G32+J32 -> 267904 | M32: =M31+K32-L32 -> 8664980.6 | O32: 11177692 | P32: =M32-O32 -> -2512710.9
A33: 30 | B33: 45960 | D33: 16 | E33: 2300 | F33: 95.68 | G33: =E33*F33 -> 220064 | H33: 35 | I33: 107.46 | J33: =H33*I33 -> 3761.1 | K33: =G33+J33 -> 223825.1 | M33: =M32+K33-L33 -> 8888805.7
A34: 31 | B34: 45961 | D34: 17 | E34: 2700 | F34: 95.68 | G34: =E34*F34 -> 258336 | J34: =H34*I34 -> 0 | K34: =G34+J34 -> 258336 | M34: =M33+K34-L34 -> 9147141.7
A35: 32 | G35: =E35*F35 -> 0 | J35: =H35*I35 -> 0 | K35: =G35+J35 -> 0 | M35: =M34+K35-L35 -> 9147141.7
A36: 33 | E36: 0 | G36: =E36*F36 -> 0 | J36: =H36*I36 -> 0 | K36: =G36+J36 -> 0
A37: 34 | E37: 0 | F37: 0 | G37: =E37*F37 -> 0 | H37: 0 | I37: 0 | J37: =H37*I37 -> 0 | K37: =G37+J37 -> 0
E38: =SUM(E3:E37) -> 56900 | G38: =SUM(G3:G37) -> 5444192 | H38: =SUM(H3:H37) -> 235 | J38: =SUM(J3:J37) -> 25253.1 | K38: =SUM(K4:K37) -> 5469445.1 | L38: =SUM(L3:L37) -> 7500000

Sheet Khammam-2
A1: Jayasai union bunk
A2: S.No | B2: Date | C2: GRN No | D2: Ind No/Bill No | E2: Diesel (Lts) | F2: Price | G2: Amount | H2: Petrol (Lts) | I2: Price | J2: Amount | K2: Total amount | L2: Amount paid | M2: As 0n Date | N2: Remarks
A3: Opening Balance | K3: 13443331 | M3: 13443331
A4: 1 | B4: 45931 | D4: 1 | E4: 5500 | F4: 95.7 | G4: =E4*F4 -> 526350 | H4: 40 | I4: 107.48 | J4: =H4*I4 -> 4299.2 | K4: =G4+J4 -> 530649.2 | M4: =M3+K4-L4 -> 13973980 | O4: =O3+M4-N4 -> 13973980
A5: 2 | B5: 45932 | G5: =E5*F5 -> 0 | J5: =H5*I5 -> 0 | K5: =G5+J5 -> 0 | M5: =M4+K5-L5 -> 13973980
A6: 3 | B6: 45933 | D6: 2 | E6: 5500 | F6: 95.7 | G6: =E6*F6 -> 526350 | H6: 75 | I6: 107.48 | J6: =H6*I6 -> 8061 | K6: =G6+J6 -> 534411 | M6: =M5+K6-L6 -> 14508391
A7: 4 | B7: 45934 | D7: 3 | E7: 6600 | F7: 95.7 | G7: =E7*F7 -> 631620 | H7: 40 | I7: 107.48 | J7: =H7*I7 -> 4299.2 | K7: =G7+J7 -> 635919.2 | M7: =M6+K7-L7 -> 15144310
A8: 5 | B8: 45935 | D8: 4 | E8: 3800 | F8: 95.7 | G8: =E8*F8 -> 363660 | J8: =H8*I8 -> 0 | K8: =G8+J8 -> 363660 | M8: =M7+K8-L8 -> 15507970 | O8: 12802499
A9: 6 | B9: 45936 | D9: 5 | E9: 2200 | F9: 95.7 | G9: =E9*F9 -> 210540 | J9: =H9*I9 -> 0 | K9: =G9+J9 -> 210540 | M9: =M8+K9-L9 -> 15718510
A10: 7 | B10: 45937 | D10: 6 | E10: 5200 | F10: 95.7 | G10: =E10*F10 -> 497640 | H10: 60 | I10: 107.48 | J10: =H10*I10 -> 6448.8 | K10: =G10+J10 -> 504088.8 | M10: =M9+K10-L10 -> 16222599
A11: 8 | B11: 45938 | D11: 7 | E11: 8500 | F11: 95.7 | G11: =E11*F11 -> 813450 | H11: 35 | I11: 107.48 | J11: =H11*I11 -> 3761.8 | K11: =G11+J11 -> 817211.8 | M11: =M10+K11-L11 -> 17039811
A12: 9 | B12: 45939 | D12: 8 | E12: 5400 | F12: 95.7 | G12: =E12*F12 -> 516780 | H12: 60 | I12: 107.48 | J12: =H12*I12 -> 6448.8 | K12: =G12+J12 -> 523228.8 | M12: =M11+K12-L12 -> 17563040
A13: 10 | B13: 45940 | D13: 9 | E13: 6500 | F13: 95.7 | G13: =E13*F13 -> 622050 | H13: 60 | I13: 107.48 | J13: =H13*I13 -> 6448.8 | K13: =G13+J13 -> 628498.8 | M13: =M12+K13-L13 -> 18191538
A14: 11 | B14: 45941 | D14: 10 | E14: 2700 | F14: 95.7 | G14: =E14*F14 -> 258390 | H14: 20 | I14: 107.48 | J14: =H14*I14 -> 2149.6 | K14: =G14+J14 -> 260539.6 | M14: =M13+K14-L14 -> 18452078 | P14: 24162284
A15: 12 | B15: 45942 | D15: 11 | E15: 2700 | F15: 95.7 | G15: =E15*F15 -> 258390 | H15: 20 | I15: 107.48 | J15: =H15*I15 -> 2149.6 | K15: =G15+J15 -> 260539.6 | M15: =M14+K15-L15 -> 18712618
A16: 13 | B16: 45943 | D16: 12 | E16: 4800 | F16: 95.7 | G16: =E16*F16 -> 459360 | H16: 40 | I16: 107.48 | J16: =H16*I16 -> 4299.2 | K16: =G16+J16 -> 463659.2 | M16: =M15+K16-L16 -> 19176277
A17: 14 | B17: 45944 | D17: 13 | E17: 5500 | F17: 95.7 | G17: =E17*F17 -> 526350 | H17: 55 | I17: 107.48 | J17: =H17*I17 -> 5911.4 | K17: =G17+J17 -> 532261.4 | M17: =M16+K17-L17 -> 19708538
A18: 15 | B18: 45945 | D18: 14 | E18: 5400 | F18: 95.7 | G18: =E18*F18 -> 516780 | H18: 60 | I18: 107.48 | J18: =H18*I18 -> 6448.8 | K18: =G18+J18 -> 523228.8 | M18: =M17+K18-L18 -> 20231767
A19: 16 | B19: 45946 | D19: 15 | E19: 2700 | F19: 95.7 | G19: =E19*F19 -> 258390 | H19: 20 | I19: 107.48 | J19: =H19*I19 -> 2149.6 | K19: =G19+J19 -> 260539.6 | M19: =M18+K19-L19 -> 20492307
A20: 17 | B20: 45947 | D20: 16 | E20: 2700 | F20: 95.7 | G20: =E20*F20 -> 258390 | H20: 20 | I20: 107.48 | J20: =H20*I20 -> 2149.6 | K20: =G20+J20 -> 260539.6 | M20: =M19+K20-L20 -> 20752846
A21: 18 | B21: 45948 | D21: 17 | E21: 5400 | F21: 95.7 | G21: =E21*F21 -> 516780 | H21: 40 | I21: 107.48 | J21: =H21*I21 -> 4299.2 | K21: =G21+J21 -> 521079.2 | M21: =M20+K21-L21 -> 21273925
A22: 19 | B22: 45949 | G22: =E22*F22 -> 0 | J22: =H22*I22 -> 0 | K22: =G22+J22 -> 0 | M22: =M21+K22-L22 -> 21273925
A23: 20 | B23: 45950 | G23: =E23*F23 -> 0 | J23: =H23*I23 -> 0 | K23: =G23+J23 -> 0 | M23: =M22+K23-L23 -> 21273925
A24: 21 | B24: 45951 | D24: 18 | E24: 2700 | F24: 95.7 | G24: =E24*F24 -> 258390 | H24: 20 | I24: 107.48 | J24: =H24*I24 -> 2149.6 | K24: =G24+J24 -> 260539.6 | M24: =M23+K24-L24 -> 21534465
A25: 22 | B25: 45952 | D25: 19 | E25: 7000 | F25: 95.7 | G25: =E25*F25 -> 669900 | H25: 40 | I25: 107.48 | J25: =H25*I25 -> 4299.2 | K25: =G25+J25 -> 674199.2 | M25: =M24+K25-L25 -> 22208664
A26: 23 | B26: 45953 | D26: 20 | E26: 2700 | F26: 95.7 | G26: =E26*F26 -> 258390 | H26: 20 | I26: 107.48 | J26: =H26*I26 -> 2149.6 | K26: =G26+J26 -> 260539.6 | M26: =M25+K26-L26 -> 22469204
A27: 24 | B27: 45954 | D27: 21 | E27: 2800 | F27: 95.7 | G27: =E27*F27 -> 267960 | H27: 40 | I27: 107.48 | J27: =H27*I27 -> 4299.2 | K27: =G27+J27 -> 272259.2 | M27: =M26+K27-L27 -> 22741463
A28: 25 | B28: 45955 | D28: 22 | E28: 2700 | F28: 95.7 | G28: =E28*F28 -> 258390 | H28: 40 | I28: 107.48 | J28: =H28*I28 -> 4299.2 | K28: =G28+J28 -> 262689.2 | M28: =M27+K28-L28 -> 23004152
A29: 26 | B29: 45956 | D29: 23 | E29: 6500 | F29: 95.7 | G29: =E29*F29 -> 622050 | H29: 20 | I29: 107.48 | J29: =H29*I29 -> 2149.6 | K29: =G29+J29 -> 624199.6 | M29: =M28+K29-L29 -> 23628352
A30: 27 | B30: 45957 | D30: 24 | E30: 2700 | F30: 95.7 | G30: =E30*F30 -> 258390 | H30: 40 | I30: 107.48 | J30: =H30*I30 -> 4299.2 | K30: =G30+J30 -> 262689.2 | M30: =M29+K30-L30 -> 23891041
A31: 28 | B31: 45958 | D31: 25 | E31: 2800 | F31: 95.7 | G31: =E31*F31 -> 267960 | H31: 35 | I31: 107.48 | J31: =H31*I31 -> 3761.8 | K31: =G31+J31 -> 271721.8 | M31: =M30+K31-L31 -> 24162763
A32: 29 | B32: 45959 | G32: =E32*F32 -> 0 | J32: =H32*I32 -> 0 | K32: =G32+J32 -> 0 | M32: =M31+K32-L32 -> 24162763
A33: 30 | B33: 45960 | G33: =E33*F33 -> 0 | J33: =H33*I33 -> 0 | K33: =G33+J33 -> 0 | M33: =M32+K33-L33 -> 24162763
A34: 31 | B34: 45961 | G34: =E34*F34 -> 0 | J34: =H34*I34 -> 0 | K34: =G34+J34 -> 0 | M34: =M33+K34-L34 -> 24162763
E38: =SUM(E4:E34) -> 111000 | G38: =SUM(G4:G34) -> 10622700 | H38: =SUM(H4:H34) -> 900 | J38: =SUM(J4:J34) -> 96732 | K38: =SUM(K4:K34) -> 10719432 | L38: =SUM(L4:L34) -> 0

Sheet Jedcherla -1
A1: Sai Baba Fuel Station
A2: S.No | B2: Date | C2: GRN No | D2: Ind No/Bill No | E2: Diesel (Lts) | F2: Price | G2: Amount | H2: Petrol (Lts) | I2: Price | J2: Amount | K2: Total amount | L2: Amount paid | M2: As on date | N2: Remarks
A3: Opening Balance | M3: 2639914.6 | O3: 2623243.4
A4: 1 | B4: 45931 | F4: 0 | G4: 0 | H4: 15 | I4: 108.23 | J4: =H4*I4 -> 1623.45 | K4: =G4+J4 -> 1623.45 | M4: =M3+K4-L4 -> 2641538
A5: 2 | B5: 45932 | G5: =E5*F5 -> 0 | J5: =H5*I5 -> 0 | K5: =G5+J5 -> 0 | M5: =M4+K5-L5 -> 2641538
A6: 3 | B6: 45933 | E6: 2400 | F6: 96.42 | G6: =E6*F6 -> 231408 | H6: 15 | I6: 108.28 | J6: =H6*I6 -> 1624.2 | K6: =G6+J6 -> 233032.2 | M6: =M5+K6-L6 -> 2874570.2
A7: 4 | B7: 45934 | G7: =E7*F7 -> 0 | H7: 5 | I7: 108.28 | J7: =H7*I7 -> 541.4 | K7: =G7+J7 -> 541.4 | M7: =M6+K7-L7 -> 2875111.6 | P7: 5679
A8: 5 | B8: 45935 | E8: 500 | F8: 96.42 | G8: =E8*F8 -> 48210 | H8: 5 | I8: 108.23 | J8: =H8*I8 -> 541.15 | K8: =G8+J8 -> 48751.15 | M8: =M7+K8-L8 -> 2923862.8
A9: 6 | B9: 45936 | E9: 1500 | F9: 96.42 | G9: =E9*F9 -> 144630 | H9: 35 | I9: 108.23 | J9: =H9*I9 -> 3788.05 | K9: =G9+J9 -> 148418.05 | M9: =M8+K9-L9 -> 3072280.8
A10: 7 | B10: 45937 | D10: 34.94 | E10: 1634.94 | F10: 96.42 | G10: =E10*F10 -> 157640.91 | H10: 10 | I10: 108.23 | J10: =H10*I10 -> 1082.3 | K10: =G10+J10 -> 158723.21 | L10: 975000 | M10: =M9+K10-L10 -> 2256004
A11: 8 | B11: 45938 | E11: 2000 | F11: 96.42 | G11: =E11*F11 -> 192840 | H11: 55 | I11: 108.23 | J11: =H11*I11 -> 5952.65 | K11: =G11+J11 -> 198792.65 | M11: =M10+K11-L11 -> 2454796.7
A12: 9 | B12: 45939 | E12: 2400 | F12: 96.42 | G12: =E12*F12 -> 231408 | H12: 5 | I12: 108.23 | J12: =H12*I12 -> 541.15 | K12: =G12+J12 -> 231949.15 | M12: =M11+K12-L12 -> 2686745.8
A13: 10 | B13: 45940 | G13: =E13*F13 -> 0 | H13: 35 | I13: 108.23 | J13: =H13*I13 -> 3788.05 | K13: =G13+J13 -> 3788.05 | M13: =M12+K13-L13 -> 2690533.9
A14: 11 | B14: 45941 | E14: 1500 | F14: 96.42 | G14: =E14*F14 -> 144630 | H14: 20 | I14: 108.23 | J14: =H14*I14 -> 2164.6 | K14: =G14+J14 -> 146794.6 | M14: =M13+K14-L14 -> 2837328.5
A15: 12 | B15: 45942 | E15: 37.96 | F15: 96.42 | G15: =E15*F15 -> 3660.1032 | H15: 15 | I15: 108.23 | J15: =H15*I15 -> 1623.45 | K15: =G15+J15 -> 5283.5532 | M15: =M14+K15-L15 -> 2842612
A16: 13 | B16: 45943 | G16: =E16*F16 -> 0 | H16: 15 | I16: 108.23 | J16: =H16*I16 -> 1623.45 | K16: =G16+J16 -> 1623.45 | M16: =M15+K16-L16 -> 2844235.5
A17: 14 | B17: 45944 | G17: =E17*F17 -> 0 | H17: 15 | I17: 108.23 | J17: =H17*I17 -> 1623.45 | K17: =G17+J17 -> 1623.45 | M17: =M16+K17-L17 -> 2845858.9
A18: 15 | B18: 45945 | G18: =E18*F18 -> 0 | H18: 20 | I18: 108.23 | J18: =H18*I18 -> 2164.6 | K18: =G18+J18 -> 2164.6 | L18: 500000 | M18: =M17+K18-L18 -> 2348023.5
A19: 16 | B19: 45946 | E19: 33.7 | F19: 96.42 | G19: =E19*F19 -> 3249.354 | H19: 25 | I19: 108.23 | J19: =H19*I19 -> 2705.75 | K19: =G19+J19 -> 5955.104 | M19: =M18+K19-L19 -> 2353978.6
A20: 17 | B20: 45947 | E20: 0 | G20: =E20*F20 -> 0 | H20: 20 | I20: 108.23 | J20: =H20*I20 -> 2164.6 | K20: =G20+J20 -> 2164.6 | M20: =M19+K20-L20 -> 2356143.2
A21: 18 | B21: 45948 | E21: 60 | F21: 96.42 | G21: =E21*F21 -> 5785.2 | H21: 25 | I21: 108.23 | J21: =H21*I21 -> 2705.75 | K21: =G21+J21 -> 8490.95 | M21: =M20+K21-L21 -> 2364634.2
A22: 19 | B22: 45949 | G22: =E22*F22 -> 0 | H22: 10 | I22: 108.23 | J22: =H22*I22 -> 1082.3 | K22: =G22+J22 -> 1082.3 | M22: =M21+K22-L22 -> 2365716.5
A23: 20 | B23: 45950 | G23: =E23*F23 -> 0 | H23: 5 | I23: 108.23 | J23: =H23*I23 -> 541.15 | K23: =G23+J23 -> 541.15 | M23: =M22+K23-L23 -> 2366257.6
A24: 21 | B24: 45951 | G24: =E24*F24 -> 0 | H24: 73.42 | I24: 108.23 | J24: =H24*I24 -> 7946.2466 | K24: =G24+J24 -> 7946.2466 | M24: =M23+K24-L24 -> 2374203.9
A25: 22 | B25: 45952 | G25: =E25*F25 -> 0 | H25: 22 | I25: 108.23 | J25: =H25*I25 -> 2381.06 | K25: =G25+J25 -> 2381.06 | M25: =M24+K25-L25 -> 2376584.9
A26: 23 | B26: 45953 | G26: =E26*F26 -> 0 | H26: 97.71 | I26: 108.23 | J26: =H26*I26 -> 10575.153 | K26: =G26+J26 -> 10575.153 | M26: =M25+K26-L26 -> 2387160.1
A27: 24 | B27: 45954 | G27: =E27*F27 -> 0 | J27: =H27*I27 -> 0 | K27: =G27+J27 -> 0 | M27: =M26+K27-L27 -> 2387160.1
A28: 25 | B28: 45955 | G28: =E28*F28 -> 0 | J28: =H28*I28 -> 0 | K28: =G28+J28 -> 0 | M28: =M27+K28-L28 -> 2387160.1
A29: 26 | B29: 45956 | G29: =E29*F29 -> 0 | H29: 100 | I29: 108.23 | J29: =H29*I29 -> 10823 | K29: =G29+J29 -> 10823 | M29: =M28+K29-L29 -> 2397983.1
A30: 27 | B30: 45957 | G30: =E30*F30 -> 0 | J30: =H30*I30 -> 0 | K30: =G30+J30 -> 0 | M30: =M29+K30-L30 -> 2397983.1
A31: 28 | B31: 45958 | G31: =E31*F31 -> 0 | J31: =H31*I31 -> 0 | K31: =G31+J31 -> 0 | M31: =M30+K31-L31 -> 2397983.1
A32: 29 | B32: 45959 | E32: 35 | F32: 96.42 | G32: =E32*F32 -> 3374.7 | H32: 50 | I32: 108.23 | J32: =H32*I32 -> 5411.5 | K32: =G32+J32 -> 8786.2 | M32: =M31+K32-L32 -> 2406769.3
A33: 30 | B33: 45960 | G33: =E33*F33 -> 0 | J33: =H33*I33 -> 0 | K33: =G33+J33 -> 0 | L33: 700000 | M33: =M32+K33-L33 -> 1706769.3
A34: 31 | B34: 45961 | E34: 52 | F34: 96.42 | G34: =E34*F34 -> 5013.84 | J34: =H34*I34 -> 0 | K34: =G34+J34 -> 5013.84 | L34: 0 | M34: =M33+K34-L34 -> 1711783.1 | O34: 2669494 | P34: =O34-M34 -> 957710.87
E35: 0 | F35: 0 | G35: =E35*F35 -> 0 | J35: =H35*I35 -> 0 | K35: =G35+J35 -> 0 | M35: =M34+K35-L35 -> 1711783.1
E36: =SUM(E4:E34) -> 12153.6 | G36: =SUM(G4:G34) -> 1171850.1 | H36: =SUM(H4:H34) -> 693.13 | J36: =SUM(J4:J34) -> 75018.46 | K36: =SUM(K4:K34) -> 1246868.6 | L36: =SUM(L4:L34) -> 2175000
M45: 2408309
M46: 5327.86
M47: =M45-M46 -> 2402981.1

Sheet Jedcharla-2
A1: ADHOC FILLING STATION STATION
A2: S.No | B2: Date | C2: GRN No | D2: Ind No/Bill No | E2: Diesel (Lts) | F2: Price | G2: Amount | H2: Petrol (Lts) | I2: Price | J2: Amount | K2: Total amount | L2: Amount paid | M2: As on Date | N2: Remarks
A3: Opening Balance | K3: 238933 | M3: =+K3 -> 238933 | O3: 238933
A4: 1 | B4: 45931 | G4: =E4*F4 -> 0 | J4: =H4*I4 -> 0 | K4: =G4+J4 -> 0 | M4: =M3+K4-L4 -> 238933
A5: 2 | B5: 45932 | G5: =E5*F5 -> 0 | J5: =H5*I5 -> 0 | K5: =G5+J5 -> 0 | M5: =M4+K5-L5 -> 238933
A6: 3 | B6: 45933 | G6: =E6*F6 -> 0 | J6: =H6*I6 -> 0 | K6: =G6+J6 -> 0 | M6: =M5+K6-L6 -> 238933 | R6: 541.08
A7: 4 | B7: 45934 | G7: =E7*F7 -> 0 | J7: =H7*I7 -> 0 | K7: =G7+J7 -> 0 | M7: =M6+K7-L7 -> 238933
A8: 5 | B8: 45935 | G8: =E8*F8 -> 0 | J8: =H8*I8 -> 0 | K8: =G8+J8 -> 0 | M8: =M7+K8-L8 -> 238933
A9: 6 | B9: 45936 | G9: =E9*F9 -> 0 | J9: =H9*I9 -> 0 | K9: =G9+J9 -> 0 | M9: =M8+K9-L9 -> 238933
A10: 7 | B10: 45937 | D10: 1 | E10: 2500 | F10: 96.43 | G10: =E10*F10 -> 241075 | J10: =H10*I10 -> 0 | K10: =G10+J10 -> 241075 | M10: =M9+K10-L10 -> 480008
A11: 8 | B11: 45938 | G11: =E11*F11 -> 0 | J11: =H11*I11 -> 0 | K11: =G11+J11 -> 0 | M11: =M10+K11-L11 -> 480008
A12: 9 | B12: 45939 | G12: =E12*F12 -> 0 | J12: =H12*I12 -> 0 | K12: =G12+J12 -> 0 | M12: =M11+K12-L12 -> 480008
A13: 10 | B13: 45940 | G13: =E13*F13 -> 0 | J13: =H13*I13 -> 0 | K13: =G13+J13 -> 0 | L13: 200000 | M13: =M12+K13-L13 -> 280008
A14: 11 | B14: 45941 | D14: 2 | E14: 2400 | F14: 96.43 | G14: =E14*F14 -> 231432 | J14: =H14*I14 -> 0 | K14: =G14+J14 -> 231432 | M14: =M13+K14-L14 -> 511440
A15: 12 | B15: 45942 | D15: 3 | E15: 2000 | F15: 96.43 | G15: =E15*F15 -> 192860 | H15: 0 | I15: 0 | J15: =H15*I15 -> 0 | K15: =G15+J15 -> 192860 | M15: =M14+K15-L15 -> 704300
A16: 13 | B16: 45943 | D16: 4 | E16: 2000 | F16: 96.43 | G16: =E16*F16 -> 192860 | J16: =H16*I16 -> 0 | K16: =G16+J16 -> 192860 | M16: =M15+K16-L16 -> 897160
A17: 14 | B17: 45944 | D17: 5 | E17: 4800 | F17: 96.43 | G17: =E17*F17 -> 462864 | J17: =H17*I17 -> 0 | K17: =G17+J17 -> 462864 | M17: =M16+K17-L17 -> 1360024
A18: 15 | B18: 45945 | D18: 6 | E18: 4400 | F18: 96.43 | G18: =E18*F18 -> 424292 | J18: =H18*I18 -> 0 | K18: =G18+J18 -> 424292 | L18: 800000 | M18: =M17+K18-L18 -> 984316
A19: 16 | B19: 45946 | D19: 7 | E19: 2400 | F19: 96.43 | G19: =E19*F19 -> 231432 | J19: =H19*I19 -> 0 | K19: =G19+J19 -> 231432 | M19: =M18+K19-L19 -> 1215748
A20: 17 | B20: 45947 | D20: 8 | E20: 2400 | F20: 96.43 | G20: =E20*F20 -> 231432 | J20: =H20*I20 -> 0 | K20: =G20+J20 -> 231432 | M20: =M19+K20-L20 -> 1447180
A21: 18 | B21: 45948 | D21: 9 | E21: 4300 | F21: 96.43 | G21: =E21*F21 -> 414649 | J21: =H21*I21 -> 0 | K21: =G21+J21 -> 414649 | M21: =M20+K21-L21 -> 1861829
A22: 19 | B22: 45949 | D22: 10 | E22: 4400 | F22: 96.43 | G22: =E22*F22 -> 424292 | J22: =H22*I22 -> 0 | K22: =G22+J22 -> 424292 | M22: =M21+K22-L22 -> 2286121
A23: 20 | B23: 45950 | G23: =E23*F23 -> 0 | J23: =H23*I23 -> 0 | K23: =G23+J23 -> 0 | M23: =M22+K23-L23 -> 2286121
A24: 21 | B24: 45951 | D24: 11 | E24: 1500 | F24: 96.43 | G24: =E24*F24 -> 144645 | J24: =H24*I24 -> 0 | K24: =G24+J24 -> 144645 | M24: =M23+K24-L24 -> 2430766
A25: 22 | B25: 45952 | D25: 12 | E25: 2400 | F25: 96.43 | G25: =E25*F25 -> 231432 | J25: =H25*I25 -> 0 | K25: =G25+J25 -> 231432 | M25: =M24+K25-L25 -> 2662198
A26: 23 | B26: 45953 | D26: 13 | E26: 1400 | F26: 96.43 | G26: =E26*F26 -> 135002 | J26: =H26*I26 -> 0 | K26: =G26+J26 -> 135002 | M26: =M25+K26-L26 -> 2797200
A27: 24 | B27: 45954 | D27: 14 | E27: 2400 | F27: 96.43 | G27: =E27*F27 -> 231432 | J27: =H27*I27 -> 0 | K27: =G27+J27 -> 231432 | M27: =M26+K27-L27 -> 3028632
A28: 25 | B28: 45955 | D28: 15 | E28: 1600 | F28: 96.43 | G28: =E28*F28 -> 154288 | J28: =H28*I28 -> 0 | K28: =G28+J28 -> 154288 | M28: =M27+K28-L28 -> 3182920
A29: 26 | B29: 45956 | D29: 16 | E29: 2400 | F29: 96.43 | G29: =E29*F29 -> 231432 | J29: =H29*I29 -> 0 | K29: =G29+J29 -> 231432 | M29: =M28+K29-L29 -> 3414352
A30: 27 | B30: 45957 | D30: 17 | E30: 2400 | F30: 96.43 | G30: =E30*F30 -> 231432 | J30: =H30*I30 -> 0 | K30: =G30+J30 -> 231432 | M30: =M29+K30-L30 -> 3645784
A31: 28 | B31: 45958 | D31: 18 | E31: 1800 | F31: 96.43 | G31: =E31*F31 -> 173574 | J31: =H31*I31 -> 0 | K31: =G31+J31 -> 173574 | M31: =M30+K31-L31 -> 3819358
A32: 29 | B32: 45959 | D32: 19 | E32: 1000 | F32: 96.43 | G32: =E32*F32 -> 96430 | J32: =H32*I32 -> 0 | K32: =G32+J32 -> 96430 | M32: =M31+K32-L32 -> 3915788
A33: 30 | B33: 45960 | D33: 20 | E33: 1200 | F33: 96.43 | G33: =E33*F33 -> 115716 | J33: =H33*I33 -> 0 | K33: =G33+J33 -> 115716 | L33: 1900000 | M33: =M32+K33-L33 -> 2131504
A34: 31 | B34: 45961 | D34: 21 | E34: 2000 | F34: 96.43 | G34: =E34*F34 -> 192860 | J34: =H34*I34 -> 0 | K34: =G34+J34 -> 192860 | M34: =M33+K34-L34 -> 2324364 | O34: 1688453.6 | P34: 1900671 | Q34: =P34-O34 -> 212217.42
E35: =SUM(E4:E34) -> 51700 | G35: =SUM(G4:G34) -> 4985431 | H35: =SUM(H4:H34) -> 0 | J35: =SUM(J4:J34) -> 0 | K35: =SUM(K4:K34) -> 4985431 | L35: =SUM(L4:L34) -> 2900000

Sheet Devarakhadra
A1: Kurumurthy Swami F/S
A2: S.No | B2: Date | C2: GRN No | D2: Ind no/Bill No | E2: Diesel (Lts) | F2: Price | G2: Amount | H2: Petrol (Lts) | I2: Price | J2: Amount | K2: Total amount | L2: Amount paid | M2: As on Date | N2: Remarks
A3: Opening Balance | M3: 121213.37 | O3: 121213.37
A4: 1 | B4: 45931 | D4: 1 | E4: 441 | F4: 97.1 | G4: =E4*F4 -> 42821.1 | H4: 5 | I4: 108.83 | J4: =H4*I4 -> 544.15 | K4: =G4+J4 -> 43365.25 | M4: =+M3+K4-L4 -> 164578.62
A5: 2 | B5: 45932 | D5: 2 | E5: 33.8 | F5: 97.1 | G5: =E5*F5 -> 3281.98 | H5: 5 | I5: 108.83 | J5: =H5*I5 -> 544.15 | K5: =G5+J5 -> 3826.13 | M5: =+M4+K5-L5 -> 168404.75
A6: 3 | B6: 45933 | D6: 3 | E6: 270.6 | F6: 97.1 | G6: =E6*F6 -> 26275.26 | H6: 10 | I6: 108.83 | J6: =H6*I6 -> 1088.3 | K6: =G6+J6 -> 27363.56 | M6: =+M5+K6-L6 -> 195768.31
A7: 4 | B7: 45934 | D7: 4 | E7: 683.4 | F7: 97.1 | G7: =E7*F7 -> 66358.14 | H7: 7 | I7: 108.83 | J7: =H7*I7 -> 761.81 | K7: =G7+J7 -> 67119.95 | M7: =+M6+K7-L7 -> 262888.26
A8: 5 | B8: 45935 | D8: 5 | E8: 160 | F8: 97.1 | G8: =E8*F8 -> 15536 | J8: =H8*I8 -> 0 | K8: =G8+J8 -> 15536 | M8: =+M7+K8-L8 -> 278424.26
A9: 6 | B9: 45936 | D9: 6 | E9: 809.25 | F9: 97.1 | G9: =E9*F9 -> 78578.175 | J9: =H9*I9 -> 0 | K9: =G9+J9 -> 78578.175 | M9: =+M8+K9-L9 -> 357002.43
A10: 7 | B10: 45937 | D10: 7 | E10: 647.67 | F10: 97.1 | G10: =E10*F10 -> 62888.757 | H10: 6 | I10: 108.83 | J10: =H10*I10 -> 652.98 | K10: =G10+J10 -> 63541.737 | M10: =+M9+K10-L10 -> 420544.17
A11: 8 | B11: 45938 | D11: 8 | E11: 466.71 | F11: 97.1 | G11: =E11*F11 -> 45317.541 | H11: 5 | I11: 108.83 | J11: =H11*I11 -> 544.15 | K11: =G11+J11 -> 45861.691 | M11: =+M10+K11-L11 -> 466405.86
A12: 9 | B12: 45939 | D12: 9 | E12: 712.49 | F12: 97.1 | G12: =E12*F12 -> 69182.779 | J12: =H12*I12 -> 0 | K12: =G12+J12 -> 69182.779 | M12: =+M11+K12-L12 -> 535588.64
A13: 10 | B13: 45940 | D13: 10 | E13: 284 | F13: 97.1 | G13: =E13*F13 -> 27576.4 | J13: =H13*I13 -> 0 | K13: =G13+J13 -> 27576.4 | L13: 150000 | M13: =+M12+K13-L13 -> 413165.04
A14: 11 | B14: 45941 | D14: 11 | E14: 511.11 | F14: 97.1 | G14: =E14*F14 -> 49628.781 | H14: 0 | I14: 108.83 | J14: =H14*I14 -> 0 | K14: =G14+J14 -> 49628.781 | M14: =+M13+K14-L14 -> 462793.82
A15: 12 | B15: 45942 | D15: 12 | G15: =E15*F15 -> 0 | H15: 28 | I15: 108.83 | J15: =H15*I15 -> 3047.24 | K15: =G15+J15 -> 3047.24 | M15: =+M14+K15-L15 -> 465841.06
A16: 13 | B16: 45943 | D16: 13 | E16: 575.43 | F16: 97.1 | G16: =E16*F16 -> 55874.253 | H16: 5 | I16: 108.83 | J16: =H16*I16 -> 544.15 | K16: =G16+J16 -> 56418.403 | M16: =+M15+K16-L16 -> 522259.46
A17: 14 | B17: 45944 | D17: 14 | E17: 118 | F17: 97.1 | G17: =E17*F17 -> 11457.8 | H17: 3 | I17: 108.83 | J17: =H17*I17 -> 326.49 | K17: =G17+J17 -> 11784.29 | M17: =+M16+K17-L17 -> 534043.75
A18: 15 | B18: 45945 | D18: 15 | E18: 18 | F18: 97.1 | G18: =E18*F18 -> 1747.8 | J18: =H18*I18 -> 0 | K18: =G18+J18 -> 1747.8 | L18: 200000 | M18: =+M17+K18-L18 -> 335791.55
A19: 16 | B19: 45946 | D19: 16 | E19: 12 | F19: 97.1 | G19: =E19*F19 -> 1165.2 | H19: 5 | I19: 108.83 | J19: =H19*I19 -> 544.15 | K19: =G19+J19 -> 1709.35 | M19: =+M18+K19-L19 -> 337500.9 | N19: Fuel bills
A20: 17 | B20: 45947 | D20: 17 | E20: 50 | F20: 97.1 | G20: =E20*F20 -> 4855 | J20: =H20*I20 -> 0 | K20: =G20+J20 -> 4855 | M20: =+M19+K20-L20 -> 342355.9
A21: 18 | B21: 45948 | D21: 18 | E21: 111 | F21: 97.1 | G21: =E21*F21 -> 10778.1 | H21: 5 | I21: 108.83 | J21: =H21*I21 -> 544.15 | K21: =G21+J21 -> 11322.25 | M21: =+M20+K21-L21 -> 353678.15
A22: 19 | B22: 45949 | D22: 19 | E22: =35+20 -> 55 | F22: 97.1 | G22: =E22*F22 -> 5340.5 | J22: =H22*I22 -> 0 | K22: =G22+J22 -> 5340.5 | M22: =+M21+K22-L22 -> 359018.65
A23: 20 | B23: 45950 | D23: 20 | E23: 0 | F23: 97.1 | G23: =E23*F23 -> 0 | H23: 5 | I23: 108.83 | J23: =H23*I23 -> 544.15 | K23: =G23+J23 -> 544.15 | M23: =+M22+K23-L23 -> 359562.8
A24: 21 | B24: 45951 | D24: 21 | G24: =E24*F24 -> 0 | H24: 10 | I24: 108.83 | J24: =H24*I24 -> 1088.3 | K24: =G24+J24 -> 1088.3 | M24: =+M23+K24-L24 -> 360651.1
A25: 22 | B25: 45952 | D25: 22 | E25: 373 | F25: 97.1 | G25: =E25*F25 -> 36218.3 | H25: 5 | I25: 108.83 | J25: =H25*I25 -> 544.15 | K25: =G25+J25 -> 36762.45 | M25: =+M24+K25-L25 -> 397413.55
A26: 23 | B26: 45953 | D26: 23 | E26: 238 | F26: 97.1 | G26: =E26*F26 -> 23109.8 | H26: 5 | I26: 108.83 | J26: =H26*I26 -> 544.15 | K26: =G26+J26 -> 23653.95 | M26: =+M25+K26-L26 -> 421067.5
A27: 24 | B27: 45954 | D27: 24 | E27: 710.25 | F27: 97.1 | G27: =E27*F27 -> 68965.275 | J27: =H27*I27 -> 0 | K27: =G27+J27 -> 68965.275 | M27: =+M26+K27-L27 -> 490032.78
A28: 25 | B28: 45955 | F28: 97.1 | G28: =E28*F28 -> 0 | J28: =H28*I28 -> 0 | K28: =G28+J28 -> 0 | M28: =+M27+K28-L28 -> 490032.78
A29: 26 | B29: 45956 | D29: 25 | E29: 20 | F29: 97.1 | G29: =E29*F29 -> 1942 | H29: 5 | I29: 108.83 | J29: =H29*I29 -> 544.15 | K29: =G29+J29 -> 2486.15 | M29: =+M28+K29-L29 -> 492518.93
A30: 27 | B30: 45957 | D30: 26 | E30: 135 | F30: 97.1 | G30: =E30*F30 -> 13108.5 | J30: =H30*I30 -> 0 | K30: =G30+J30 -> 13108.5 | M30: =+M29+K30-L30 -> 505627.43
A31: 28 | B31: 45958 | D31: 27 | E31: 176 | F31: 97.1 | G31: =E31*F31 -> 17089.6 | H31: 5 | I31: 108.83 | J31: =H31*I31 -> 544.15 | K31: =G31+J31 -> 17633.75 | M31: =+M30+K31-L31 -> 523261.18
A32: 29 | B32: 45959 | D32: 28 | E32: 200 | F32: 97.1 | G32: =E32*F32 -> 19420 | H32: 10 | I32: 108.83 | J32: =H32*I32 -> 1088.3 | K32: =G32+J32 -> 20508.3 | M32: =+M31+K32-L32 -> 543769.48
A33: 30 | B33: 45960 | G33: =E33*F33 -> 0 | J33: =H33*I33 -> 0 | K33: =G33+J33 -> 0 | L33: 350000 | M33: =+M32+K33-L33 -> 193769.48
A34: 31 | B34: 45961 | G34: =E34*F34 -> 0 | J34: =H34*I34 -> 0 | K34: =G34+J34 -> 0 | M34: =+M33+K34-L34 -> 193769.48
E35: =SUM(E4:E34) -> 7811.71 | G35: =SUM(G4:G34) -> 758517.04 | H35: =SUM(H4:H34) -> 129 | J35: =SUM(J4:J34) -> 14039.07 | K35: =SUM(K4:K34) -> 772556.11 | L35: =SUM(L4:L34) -> 700000

Sheet Devarakhadra-2
A1: Sri rama F/S
A2: S.No | B2: Date | C2: GRN No | D2: Ind no/Bill No | E2: Diesel (Lts) | F2: Price | G2: Amount | H2: Petrol (Lts) | I2: Price | J2: Amount | K2: Total amount | L2: Amount paid | M2: As on Date | N2: Remarks
A3: Opening Balance | M3: 132273.54
A4: 1 | B4: 45931 | G4: =E4*F4 -> 0 | H4: 0 | I4: 0 | J4: =H4*I4 -> 0 | K4: =G4+J4 -> 0 | L4: 0 | M4: =+M3+K4-L4 -> 132273.54
A5: 2 | B5: 45932 | G5: =E5*F5 -> 0 | H5: 0 | I5: 0 | J5: =H5*I5 -> 0 | K5: =G5+J5 -> 0 | L5: 0 | M5: =+M4+K5-L5 -> 132273.54
A6: 3 | B6: 45933 | G6: =E6*F6 -> 0 | H6: 0 | I6: 0 | J6: =H6*I6 -> 0 | K6: =G6+J6 -> 0 | L6: 0 | M6: =+M5+K6-L6 -> 132273.54
A7: 4 | B7: 45934 | G7: =E7*F7 -> 0 | H7: 0 | I7: 0 | J7: =H7*I7 -> 0 | K7: =G7+J7 -> 0 | L7: 0 | M7: =+M6+K7-L7 -> 132273.54
A8: 5 | B8: 45935 | G8: =E8*F8 -> 0 | H8: 0 | I8: 0 | J8: =H8*I8 -> 0 | K8: =G8+J8 -> 0 | L8: 0 | M8: =+M7+K8-L8 -> 132273.54
A9: 6 | B9: 45936 | G9: =E9*F9 -> 0 | H9: 0 | I9: 0 | J9: =H9*I9 -> 0 | K9: =G9+J9 -> 0 | L9: 0 | M9: =+M8+K9-L9 -> 132273.54
A10: 7 | B10: 45937 | G10: =E10*F10 -> 0 | H10: 0 | I10: 0 | J10: =H10*I10 -> 0 | K10: =G10+J10 -> 0 | L10: 132200 | M10: =+M9+K10-L10 -> 73.536
A11: 8 | B11: 45938 | G11: =E11*F11 -> 0 | H11: 0 | I11: 0 | J11: =H11*I11 -> 0 | K11: =G11+J11 -> 0 | L11: 0 | M11: =+M10+K11-L11 -> 73.536
A12: 9 | B12: 45939 | G12: =E12*F12 -> 0 | H12: 0 | I12: 0 | J12: =H12*I12 -> 0 | K12: =G12+J12 -> 0 | L12: 0 | M12: =+M11+K12-L12 -> 73.536
A13: 10 | B13: 45940 | G13: =E13*F13 -> 0 | H13: 0 | I13: 0 | J13: =H13*I13 -> 0 | K13: =G13+J13 -> 0 | L13: 0 | M13: =+M12+K13-L13 -> 73.536
A14: 11 | B14: 45941 | G14: =E14*F14 -> 0 | H14: 0 | I14: 0 | J14: =H14*I14 -> 0 | K14: =G14+J14 -> 0 | L14: 0 | M14: =+M13+K14-L14 -> 73.536
A15: 12 | B15: 45942 | G15: =E15*F15 -> 0 | H15: 0 | I15: 0 | J15: =H15*I15 -> 0 | K15: =G15+J15 -> 0 | L15: 0 | M15: =+M14+K15-L15 -> 73.536
... A33: 30 | B33: 45960 | G33: =E33*F33 -> 0 | H33: 0 | I33: 0 | J33: =H33*I33 -> 0 | K33: =G33+J33 -> 0 | L33: 0 | M33: =+M32+K33-L33 -> 73.536
A34: 31 | G34: =E34*F34 -> 0 | H34: 0 | I34: 0 | J34: =H34*I34 -> 0 | K34: =G34+J34 -> 0 | L34: 0 | M34: =+M33+K34-L34 -> 73.536
E35: =SUM(E4:E34) -> 0 | G35: =SUM(G4:G34) -> 0 | H35: =SUM(H4:H34) -> 0 | J35: =SUM(J4:J34) -> 0 | K35: =SUM(K4:K34) -> 0 | L35: =SUM(L4:L34) -> 132200
F38: /

Sheet Devarakhadra-3
A1: JSASFuel Genie India Pvt.Ltd
A2: S.No | B2: Date | C2: GRN No | D2: Ind no/Bill No | E2: Diesel (Lts) | F2: Price | G2: Amount | H2: Petrol (Lts) | I2: Price | J2: Amount | K2: Total amount | L2: Amount paid | M2: As on Date | N2: Remarks
A3: Opening Balance | M3: 0
A4: 1 | B4: 45931 | G4: =E4*F4 -> 0 | H4: 0 | I4: 0 | J4: =H4*I4 -> 0 | K4: =G4+J4 -> 0 | L4: 0 | M4: =+M3+K4-L4 -> 0
A5: 2 | B5: 45932 | G5: =E5*F5 -> 0 | H5: 0 | I5: 0 | J5: =H5*I5 -> 0 | K5: =G5+J5 -> 0 | L5: 0 | M5: =+M4+K5-L5 -> 0
A6: 3 | B6: 45933 | G6: =E6*F6 -> 0 | H6: 0 | I6: 0 | J6: =H6*I6 -> 0 | K6: =G6+J6 -> 0 | L6: 0 | M6: =+M5+K6-L6 -> 0
A7: 4 | B7: 45934 | G7: =E7*F7 -> 0 | H7: 0 | I7: 0 | J7: =H7*I7 -> 0 | K7: =G7+J7 -> 0 | L7: 0 | M7: =+M6+K7-L7 -> 0
A8: 5 | B8: 45935 | G8: =E8*F8 -> 0 | H8: 0 | I8: 0 | J8: =H8*I8 -> 0 | K8: =G8+J8 -> 0 | L8: 0 | M8: =+M7+K8-L8 -> 0
A9: 6 | B9: 45936 | G9: =E9*F9 -> 0 | H9: 0 | I9: 0 | J9: =H9*I9 -> 0 | K9: =G9+J9 -> 0 | L9: 0 | M9: =+M8+K9-L9 -> 0
A10: 7 | B10: 45937 | G10: =E10*F10 -> 0 | H10: 0 | I10: 0 | J10: =H10*I10 -> 0 | K10: =G10+J10 -> 0 | L10: 0 | M10: =+M9+K10-L10 -> 0
A11: 8 | B11: 45938 | G11: =E11*F11 -> 0 | H11: 0 | I11: 0 | J11: =H11*I11 -> 0 | K11: =G11+J11 -> 0 | L11: 0 | M11: =+M10+K11-L11 -> 0
A12: 9 | B12: 45939 | G12: =E12*F12 -> 0 | H12: 0 | I12: 0 | J12: =H12*I12 -> 0 | K12: =G12+J12 -> 0 | L12: 0 | M12: =+M11+K12-L12 -> 0
A13: 10 | B13: 45940 | G13: =E13*F13 -> 0 | H13: 0 | I13: 0 | J13: =H13*I13 -> 0 | K13: =G13+J13 -> 0 | L13: 0 | M13: =+M12+K13-L13 -> 0
A14: 11 | B14: 45941 | G14: =E14*F14 -> 0 | H14: 0 | I14: 0 | J14: =H14*I14 -> 0 | K14: =G14+J14 -> 0 | L14: 0 | M14: =+M13+K14-L14 -> 0
A15: 12 | B15: 45942 | G15: =E15*F15 -> 0 | H15: 0 | I15: 0 | J15: =H15*I15 -> 0 | K15: =G15+J15 -> 0 | L15: 0 | M15: =+M14+K15-L15 -> 0
A16: 13 | B16: 45943 | G16: =E16*F16 -> 0 | H16: 0 | I16: 0 | J16: =H16*I16 -> 0 | K16: =G16+J16 -> 0 | L16: 0 | M16: =+M15+K16-L16 -> 0
A17: 14 | B17: 45944 | E17: 1743.87 | F17: 95.83 | G17: =E17*F17 -> 167115.06 | H17: 0 | I17: 0 | J17: =H17*I17 -> 0 | K17: =G17+J17 -> 167115.06 | L17: 0 | M17: =+M16+K17-L17 -> 167115.06
A18: 15 | B18: 45945 | G18: =E18*F18 -> 0 | H18: 0 | I18: 0 | J18: =H18*I18 -> 0 | K18: =G18+J18 -> 0 | L18: 0 | M18: =+M17+K18-L18 -> 167115.06
A19: 16 | B19: 45946 | G19: =E19*F19 -> 0 | H19: 0 | I19: 0 | J19: =H19*I19 -> 0 | K19: =G19+J19 -> 0 | L19: 0 | M19: =+M18+K19-L19 -> 167115.06
A20: 17 | B20: 45947 | G20: =E20*F20 -> 0 | H20: 0 | I20: 0 | J20: =H20*I20 -> 0 | K20: =G20+J20 -> 0 | L20: 0 | M20: =+M19+K20-L20 -> 167115.06
A21: 18 | B21: 45948 | G21: =E21*F21 -> 0 | H21: 0 | I21: 0 | J21: =H21*I21 -> 0 | K21: =G21+J21 -> 0 | L21: 0 | M21: =+M20+K21-L21 -> 167115.06
A22: 19 | B22: 45949 | G22: =E22*F22 -> 0 | H22: 0 | I22: 0 | J22: =H22*I22 -> 0 | K22: =G22+J22 -> 0 | L22: 0 | M22: =+M21+K22-L22 -> 167115.06
A23: 20 | B23: 45950 | G23: =E23*F23 -> 0 | H23: 0 | I23: 0 | J23: =H23*I23 -> 0 | K23: =G23+J23 -> 0 | L23: 0 | M23: =+M22+K23-L23 -> 167115.06
A24: 21 | B24: 45951 | G24: =E24*F24 -> 0 | H24: 0 | I24: 0 | J24: =H24*I24 -> 0 | K24: =G24+J24 -> 0 | L24: 0 | M24: =+M23+K24-L24 -> 167115.06
A25: 22 | B25: 45952 | G25: =E25*F25 -> 0 | H25: 0 | I25: 0 | J25: =H25*I25 -> 0 | K25: =G25+J25 -> 0 | L25: 0 | M25: =+M24+K25-L25 -> 167115.06
A26: 23 | B26: 45953 | G26: =E26*F26 -> 0 | H26: 0 | I26: 0 | J26: =H26*I26 -> 0 | K26: =G26+J26 -> 0 | L26: 0 | M26: =+M25+K26-L26 -> 167115.06
A27: 24 | B27: 45954 | G27: =E27*F27 -> 0 | H27: 0 | I27: 0 | J27: =H27*I27 -> 0 | K27: =G27+J27 -> 0 | L27: 0 | M27: =+M26+K27-L27 -> 167115.06
A28: 25 | B28: 45955 | G28: =E28*F28 -> 0 | H28: 0 | I28: 0 | J28: =H28*I28 -> 0 | K28: =G28+J28 -> 0 | L28: 0 | M28: =+M27+K28-L28 -> 167115.06
A29: 26 | B29: 45956 | G29: =E29*F29 -> 0 | H29: 0 | I29: 0 | J29: =H29*I29 -> 0 | K29: =G29+J29 -> 0 | L29: 0 | M29: =+M28+K29-L29 -> 167115.06
... A33: 30 | B33: 45960 | G33: =E33*F33 -> 0 | H33: 0 | I33: 0 | J33: =H33*I33 -> 0 | K33: =G33+J33 -> 0 | L33: 0 | M33: =+M32+K33-L33 -> 167115.06
A34: 31 | G34: =E34*F34 -> 0 | H34: 0 | I34: 0 | J34: =H34*I34 -> 0 | K34: =G34+J34 -> 0 | L34: 0 | M34: =+M33+K34-L34 -> 167115.06
E35: =SUM(E4:E34) -> 1743.87 | G35: =SUM(G4:G34) -> 167115.06 | H35: =SUM(H4:H34) -> 0 | J35: =SUM(J4:J34) -> 0 | K35: =SUM(K4:K34) -> 167115.06 | L35: =SUM(L4:L34) -> 0

Sheet Dindi
A1: Akarapu Balakistamma Fillling
A2: S.No | B2: Date | C2: GRN No | D2: Ind no/Bill No | E2: Diesel (Lts) | F2: Price | G2: Amount | H2: Petrol (Lts) | I2: Price | J2: Amount | K2: Total amount | L2: Amount paid | M2: As on Date | N2: Remarks
A3: Opening Balance | M3: 0
A4: 1 | B4: 45931 | G4: =E4*F4 -> 0 | H4: 0 | I4: 0 | J4: =H4*I4 -> 0 | K4: =G4+J4 -> 0 | L4: =+K4 -> 0 | M4: 0
A5: 2 | B5: 45932 | G5: =E5*F5 -> 0 | H5: 0 | I5: 0 | J5: =H5*I5 -> 0 | K5: =G5+J5 -> 0 | L5: =+K5 -> 0 | M5: 0
A6: 3 | B6: 45933 | G6: =E6*F6 -> 0 | H6: 0 | I6: 0 | J6: =H6*I6 -> 0 | K6: =G6+J6 -> 0 | L6: =+K6 -> 0 | M6: 0
A7: 4 | B7: 45934 | G7: =E7*F7 -> 0 | H7: 0 | I7: 0 | J7: =H7*I7 -> 0 | K7: =G7+J7 -> 0 | L7: =+K7 -> 0 | M7: 0
A8: 5 | B8: 45935 | G8: =E8*F8 -> 0 | H8: 0 | I8: 0 | J8: =H8*I8 -> 0 | K8: =G8+J8 -> 0 | L8: =+K8 -> 0 | M8: 0
A9: 6 | B9: 45936 | G9: =E9*F9 -> 0 | H9: 0 | I9: 0 | J9: =H9*I9 -> 0 | K9: =G9+J9 -> 0 | L9: =+K9 -> 0 | M9: 0
A10: 7 | B10: 45937 | E10: 43.61 | F10: 96.83 | G10: =E10*F10 -> 4222.7563 | H10: 0 | I10: 0 | J10: =H10*I10 -> 0 | K10: =G10+J10 -> 4222.7563 | L10: =+K10 -> 4222.7563 | M10: 0
A11: 8 | B11: 45938 | G11: =E11*F11 -> 0 | H11: 0 | I11: 0 | J11: =H11*I11 -> 0 | K11: =G11+J11 -> 0 | L11: =+K11 -> 0 | M11: 0
A12: 9 | B12: 45939 | G12: =E12*F12 -> 0 | H12: 0 | I12: 0 | J12: =H12*I12 -> 0 | K12: =G12+J12 -> 0 | L12: =+K12 -> 0 | M12: 0
A13: 10 | B13: 45940 | G13: =E13*F13 -> 0 | H13: 0 | I13: 0 | J13: =H13*I13 -> 0 | K13: =G13+J13 -> 0 | L13: =+K13 -> 0 | M13: 0
A14: 11 | B14: 45941 | G14: =E14*F14 -> 0 | H14: 0 | I14: 0 | J14: =H14*I14 -> 0 | K14: =G14+J14 -> 0 | L14: =+K14 -> 0 | M14: 0
A15: 12 | B15: 45942 | G15: =E15*F15 -> 0 | H15: 0 | I15: 0 | J15: =H15*I15 -> 0 | K15: =G15+J15 -> 0 | L15: =+K15 -> 0 | M15: 0
A16: 13 | B16: 45943 | G16: =E16*F16 -> 0 | H16: 0 | I16: 0 | J16: =H16*I16 -> 0 | K16: =G16+J16 -> 0 | L16: =+K16 -> 0 | M16: 0
A17: 14 | B17: 45944 | G17: =E17*F17 -> 0 | H17: 0 | I17: 0 | J17: =H17*I17 -> 0 | K17: =G17+J17 -> 0 | L17: =+K17 -> 0 | M17: 0
A18: 15 | B18: 45945 | G18: =E18*F18 -> 0 | H18: 0 | I18: 0 | J18: =H18*I18 -> 0 | K18: =G18+J18 -> 0 | L18: =+K18 -> 0 | M18: 0
A19: 16 | B19: 45946 | G19: =E19*F19 -> 0 | H19: 0 | I19: 0 | J19: =H19*I19 -> 0 | K19: =G19+J19 -> 0 | L19: =+K19 -> 0 | M19: 0
A20: 17 | B20: 45947 | G20: =E20*F20 -> 0 | H20: 0 | I20: 0 | J20: =H20*I20 -> 0 | K20: =G20+J20 -> 0 | L20: =+K20 -> 0 | M20: 0
A21: 18 | B21: 45948 | G21: =E21*F21 -> 0 | H21: 0 | I21: 0 | J21: =H21*I21 -> 0 | K21: =G21+J21 -> 0 | L21: =+K21 -> 0 | M21: 0
A22: 19 | B22: 45949 | G22: =E22*F22 -> 0 | H22: 0 | I22: 0 | J22: =H22*I22 -> 0 | K22: =G22+J22 -> 0 | L22: =+K22 -> 0 | M22: 0
... A25: 22 | B25: 45952 | G25: =E25*F25 -> 0 | H25: 0 | I25: 0 | J25: =H25*I25 -> 0 | K25: =G25+J25 -> 0 | L25: =+K25 -> 0 | M25: 0
A26: 23 | B26: 45953 | E26: 0 | F26: 0 | G26: =E26*F26 -> 0 | H26: 0 | I26: 0 | J26: =H26*I26 -> 0 | K26: =G26+J26 -> 0 | L26: =+K26 -> 0 | M26: 0
A27: 24 | B27: 45954 | E27: 42.27 | F27: 96.83 | G27: =E27*F27 -> 4093.0041 | H27: 0 | I27: 0 | J27: =H27*I27 -> 0 | K27: =G27+J27 -> 4093.0041 | L27: =+K27 -> 4093.0041 | M27: 0
A28: 25 | B28: 45955 | G28: =E28*F28 -> 0 | H28: 0 | I28: 0 | J28: =H28*I28 -> 0 | K28: =G28+J28 -> 0 | L28: =+K28 -> 0 | M28: 0
A29: 26 | B29: 45956 | G29: =E29*F29 -> 0 | H29: 0 | I29: 0 | J29: =H29*I29 -> 0 | K29: =G29+J29 -> 0 | L29: =+K29 -> 0 | M29: 0
A30: 27 | B30: 45957 | G30: =E30*F30 -> 0 | H30: 0 | I30: 0 | J30: =H30*I30 -> 0 | K30: =G30+J30 -> 0 | L30: =+K30 -> 0 | M30: 0
A31: 28 | B31: 45958 | G31: =E31*F31 -> 0 | H31: 0 | I31: 0 | J31: =H31*I31 -> 0 | K31: =G31+J31 -> 0 | L31: =+K31 -> 0 | M31: 0
A32: 29 | B32: 45959 | G32: =E32*F32 -> 0 | H32: 0 | I32: 0 | J32: =H32*I32 -> 0 | K32: =G32+J32 -> 0 | L32: =+K32 -> 0 | M32: 0
A33: 30 | B33: 45960 | G33: =E33*F33 -> 0 | H33: 0 | I33: 0 | J33: =H33*I33 -> 0 | K33: =G33+J33 -> 0 | L33: =+K33 -> 0 | M33: 0
A34: 31 | G34: =E34*F34 -> 0 | H34: 0 | I34: 0 | J34: =H34*I34 -> 0 | K34: =G34+J34 -> 0 | L34: =+K34 -> 0 | M34: 0
E35: =SUM(E4:E34) -> 85.88 | G35: =SUM(G4:G34) -> 8315.7604 | H35: =SUM(H4:H34) -> 0 | J35: =SUM(J4:J34) -> 0 | K35: =SUM(K4:K34) -> 8315.7604 | L35: =SUM(L4:L34) -> 8315.7604

Sheet Amalapuram
A1: Sathya Filling Station
A2: S.No | B2: Date | C2: GRN No | D2: Ind no/Bill No | E2: Diesel (Lts) | F2: Price | G2: Amount | H2: Petrol (Lts) | I2: Price | J2: Amount | K2: Total amount | L2: Amount paid | M2: As on Date | N2: Remarks
A3: Opening Balance | M3: 0
A4: 1 | B4: 45931 | G4: =E4*F4 -> 0 | J4: =H4*I4 -> 0 | K4: =G4+J4 -> 0 | M4: =+M3+K4-L4 -> 0
A5: 2 | B5: 45932 | G5: =E5*F5 -> 0 | J5: =H5*I5 -> 0 | K5: =G5+J5 -> 0 | M5: =+M4+K5-L5 -> 0
A6: 3 | B6: 45933 | G6: =E6*F6 -> 0 | J6: =H6*I6 -> 0 | K6: =G6+J6 -> 0 | M6: =+M5+K6-L6 -> 0
A7: 4 | B7: 45934 | G7: =E7*F7 -> 0 | J7: =H7*I7 -> 0 | K7: =G7+J7 -> 0 | M7: =+M6+K7-L7 -> 0
A8: 5 | B8: 45935 | C8: Bhaskara Agencies Morampudi | D8: Rajahmundry | G8: =E8*F8 -> 0 | H8: 25 | I8: 108.83 | J8: =H8*I8 -> 2720.75 | K8: =G8+J8 -> 2720.75 | L8: 2720.75 | M8: =+M7+K8-L8 -> 0
A9: 6 | B9: 45936 | C9: Padma Filling Station | D9: Rajahmundry | E9: 20.68 | F9: 96.71 | G9: =E9*F9 -> 1999.9628 | J9: =H9*I9 -> 0 | K9: =G9+J9 -> 1999.9628 | L9: 1999.96 | M9: =+M8+K9-L9 -> 0.0028
A10: 7 | B10: 45937 | C10: Bhaskara Agencies Morampudi | D10: Rajahmundry | E10: 44.45 | F10: 96.71 | G10: =E10*F10 -> 4298.7595 | J10: =H10*I10 -> 0 | K10: =G10+J10 -> 4298.7595 | L10: 4298.76 | M10: =+M9+K10-L10 -> 0.0023
A11: 8 | B11: 45938 | G11: =E11*F11 -> 0 | J11: =H11*I11 -> 0 | K11: =G11+J11 -> 0 | M11: =+M10+K11-L11 -> 0.0023
A12: 9 | B12: 45939 | C12: Sri Venkata Ganesh Enterprises-Venkatapuram | D12: Eluru | E12: 48.53 | F12: 97.66 | G12: =E12*F12 -> 4739.4398 | J12: =H12*I12 -> 0 | K12: =G12+J12 -> 4739.4398 | L12: 4739.4398 | M12: =+M11+K12-L12 -> 0.0023
A13: 10 | B13: 45940 | C13: Sri Venkata Ganesh Enterprises-Venkatapuram | D13: Eluru | G13: =E13*F13 -> 0 | H13: 20 | I13: 109.86 | J13: =H13*I13 -> 2197.2 | K13: =G13+J13 -> 2197.2 | L13: 2197.2 | M13: =+M12+K13-L13 -> 0.0023
A14: 11 | B14: 45941 | G14: =E14*F14 -> 0 | J14: =H14*I14 -> 0 | K14: =G14+J14 -> 0 | M14: =+M13+K14-L14 -> 0.0023
A15: 12 | B15: 45942 | G15: =E15*F15 -> 0 | J15: =H15*I15 -> 0 | K15: =G15+J15 -> 0 | M15: =+M14+K15-L15 -> 0.0023
A16: 13 | B16: 45943 | C16: Sri Venkateswara Enterprises Bharat Petroleum | D16: Yanam | E16: 38.9 | F16: 86.75 | G16: =E16*F16 -> 3374.575 | J16: =H16*I16 -> 0 | K16: =G16+J16 -> 3374.575 | L16: =H16+K16 -> 3374.575 | M16: =+M15+K16-L16 -> 0.0023
B17: 45943 | C17: Sri Lakshmi Filling Station-Nadipalli | D17: Chinthalapudi | H17: 25 | I17: 109.97 | J17: =H17*I17 -> 2749.25 | K17: =G17+J17 -> 2749.25 | L17: 2749.25
A18: 14 | B18: 45944 | G18: =E18*F18 -> 0 | J18: =H18*I18 -> 0 | K18: =G18+J18 -> 0 | M18: =+M16+K18-L18 -> 0.0023
A19: 15 | B19: 45945 | C19: Padma Highway Filling Station | D19: Yanam | E19: 38.04 | F19: 86.75 | G19: =E19*F19 -> 3299.97 | J19: =H19*I19 -> 0 | K19: =G19+J19 -> 3299.97 | L19: 3299.97 | M19: =+M18+K19-L19 -> 0.0023
A20: 16 | B20: 45946 | G20: =E20*F20 -> 0 | J20: =H20*I20 -> 0 | K20: =G20+J20 -> 0 | M20: =+M19+K20-L20 -> 0.0023
A21: 17 | B21: 45947 | C21: Buchibabu Filling Center Bharat Petroleum | D21: Ethakota | E21: 45.44 | F21: 97.06 | G21: =E21*F21 -> 4410.4064 | J21: =H21*I21 -> 0 | K21: =G21+J21 -> 4410.4064 | L21: 4410.41 | M21: =+M20+K21-L21 -> -0.0013
A22: 18 | B22: 45948 | C22: GR Filling Station Bharath Petrolium | D22: Tanuku | G22: =E22*F22 -> 0 | H22: 25 | I22: 109.51 | J22: =H22*I22 -> 2737.75 | K22: =G22+J22 -> 2737.75 | L22: 2737.75 | M22: =+M21+K22-L22 -> -0.0013
A23: 19 | B23: 45949 | C23: GR Filling Station Bharath Petrolium | D23: Tanuku | G23: =E23*F23 -> 0 | H23: 20 | I23: 109.51 | J23: =H23*I23 -> 2190.2 | K23: =G23+J23 -> 2190.2 | L23: 2190.2 | M23: =+M22+K23-L23 -> -0.0013
A24: 20 | B24: 45950 | G24: =E24*F24 -> 0 | J24: =H24*I24 -> 0 | K24: =G24+J24 -> 0 | M24: =+M23+K24-L24 -> -0.0013
A25: 21 | B25: 45951 | G25: =E25*F25 -> 0 | J25: =H25*I25 -> 0 | K25: =G25+J25 -> 0 | M25: =+M24+K25-L25 -> -0.0013
A26: 22 | B26: 45952 | G26: =E26*F26 -> 0 | J26: =H26*I26 -> 0 | K26: =G26+J26 -> 0 | M26: =+M25+K26-L26 -> -0.0013
A27: 23 | B27: 45953 | C27: BHARAT FILLING STATION | D27: Nuziveedu | E27: 30.89 | F27: 97.12 | G27: =E27*F27 -> 3000.0368 | J27: =H27*I27 -> 0 | K27: =G27+J27 -> 3000.0368 | L27: 3000.04 | M27: =+M26+K27-L27 -> -0.0045
A28: 24 | B28: 45954 | C28: Pulla Fuels Bharat Petrolium | D28: Pulla(Bhimadolu) | E28: 30.75 | F28: 97.56 | G28: =E28*F28 -> 2999.97 | J28: =H28*I28 -> 0 | K28: =G28+J28 -> 2999.97 | L28: 2999.97 | M28: =+M27+K28-L28 -> -0.0045
A29: 25 | B29: 45955 | C29: R Ammiraju&Brothers Bharat Petrolium | D29: Nidadavolu | G29: =E29*F29 -> 0 | H29: 25 | I29: 109.21 | J29: =H29*I29 -> 2730.25 | K29: =G29+J29 -> 2730.25 | L29: 2730.25 | M29: =+M28+K29-L29 -> -0.0045
A30: 26 | B30: 45956 | G30: =E30*F30 -> 0 | J30: =H30*I30 -> 0 | K30: =G30+J30 -> 0 | M30: =+M29+K30-L30 -> -0.0045
A31: 27 | B31: 45957 | G31: =E31*F31 -> 0 | J31: =H31*I31 -> 0 | K31: =G31+J31 -> 0 | M31: =+M30+K31-L31 -> -0.0045
A32: 28 | B32: 45958 | G32: =E32*F32 -> 0 | J32: =H32*I32 -> 0 | K32: =G32+J32 -> 0 | M32: =+M31+K32-L32 -> -0.0045
A33: 29 | B33: 45959 | G33: =E33*F33 -> 0 | J33: =H33*I33 -> 0 | K33: =G33+J33 -> 0 | M33: =+M32+K33-L33 -> -0.0045
B34: 45960 | C34: Sri Venkata Sitarama Filling Station | D34: Bhimavaram | G34: =E34*F34 -> 0 | H34: 15 | I34: 109.83 | J34: =H34*I34 -> 1647.45 | K34: =G34+J34 -> 1647.45 | L34: 1647.45 | M34: 0
A35: 30 | B35: 45961 | C35: Sri Venkata Sitarama Filling Station | D35: Bhimavaram | E35: 43 | F35: 97.64 | G35: =E35*F35 -> 4198.52 | H35: 20 | I35: 109.83 | J35: =H35*I35 -> 2196.6 | K35: =G35+J35 -> 6395.12 | L35: 6395.12 | M35: =+M33+K35-L35 -> -0.0045
A36: 31 | E36: 0 | F36: 0 | G36: =E36*F36 -> 0 | J36: =H36*I36 -> 0 | K36: =G36+J36 -> 0 | L36: 0 | M36: =+M35+K36-L36 -> -0.0045
E37: =SUM(E4:E36) -> 340.68 | G37: =SUM(G4:G36) -> 32321.64 | H37: =SUM(H4:H36) -> 175 | J37: =SUM(J4:J36) -> 19169.45 | K37: =SUM(K4:K36) -> 51491.09 | L37: =SUM(L4:L36) -> 51491.095

Sheet Madana palli
A2: S.No | B2: Date | C2: GRN No | D2: Ind no/Bill No | E2: Diesel (Lts) | F2: Price | G2: Amount | H2: Petrol (Lts) | I2: Price | J2: Amount | K2: Total amount | L2: Amount paid | M2: As on Date | N2: Remarks
A3: Opening Balance | M3: 0
A4: 1 | B4: 45931 | G4: =E4*F4 -> 0 | H4: 0 | I4: 0 | J4: =H4*I4 -> 0 | K4: =G4+J4 -> 0 | L4: =+K4 -> 0 | M4: 0
A5: 2 | B5: 45932 | G5: =E5*F5 -> 0 | H5: 0 | I5: 0 | J5: =H5*I5 -> 0 | K5: =G5+J5 -> 0 | L5: =+K5 -> 0 | M5: 0
A6: 3 | B6: 45933 | G6: =E6*F6 -> 0 | H6: 0 | I6: 0 | J6: =H6*I6 -> 0 | K6: =G6+J6 -> 0 | L6: =+K6 -> 0 | M6: 0
A7: 4 | B7: 45934 | G7: =E7*F7 -> 0 | H7: 0 | I7: 0 | J7: =H7*I7 -> 0 | K7: =G7+J7 -> 0 | L7: =+K7 -> 0 | M7: 0
A8: 5 | B8: 45935 | G8: =E8*F8 -> 0 | H8: 0 | I8: 0 | J8: =H8*I8 -> 0 | K8: =G8+J8 -> 0 | L8: =+K8 -> 0 | M8: 0
A9: 6 | B9: 45936 | G9: =E9*F9 -> 0 | H9: 0 | I9: 0 | J9: =H9*I9 -> 0 | K9: =G9+J9 -> 0 | L9: =+K9 -> 0 | M9: 0
A10: 7 | B10: 45937 | G10: =E10*F10 -> 0 | H10: 0 | I10: 0 | J10: =H10*I10 -> 0 | K10: =G10+J10 -> 0 | L10: =+K10 -> 0 | M10: 0
A11: 8 | B11: 45938 | G11: =E11*F11 -> 0 | H11: 0 | I11: 0 | J11: =H11*I11 -> 0 | K11: =G11+J11 -> 0 | L11: =+K11 -> 0 | M11: 0
A12: 9 | B12: 45939 | G12: =E12*F12 -> 0 | H12: 0 | I12: 0 | J12: =H12*I12 -> 0 | K12: =G12+J12 -> 0 | L12: =+K12 -> 0 | M12: 0
A13: 10 | B13: 45940 | G13: =E13*F13 -> 0 | H13: 0 | I13: 0 | J13: =H13*I13 -> 0 | K13: =G13+J13 -> 0 | L13: =+K13 -> 0 | M13: 0
A14: 11 | B14: 45941 | G14: =E14*F14 -> 0 | H14: 0 | I14: 0 | J14: =H14*I14 -> 0 | K14: =G14+J14 -> 0 | L14: =+K14 -> 0 | M14: 0
A15: 12 | B15: 45942 | G15: =E15*F15 -> 0 | H15: 0 | I15: 0 | J15: =H15*I15 -> 0 | K15: =G15+J15 -> 0 | L15: =+K15 -> 0 | M15: 0
... A20: 17 | B20: 45947 | G20: =E20*F20 -> 0 | H20: 0 | I20: 0 | J20: =H20*I20 -> 0 | K20: =G20+J20 -> 0 | L20: =+K20 -> 0 | M20: 0
A21: 18 | B21: 45948 | E21: 335.74 | F21: 97.43 | G21: =E21*F21 -> 32711.148 | H21: 5.56 | I21: 109.61 | J21: =H21*I21 -> 609.4316 | K21: =G21+J21 -> 33320.58 | L21: =+K21 -> 33320.58 | M21: 0 | N21: IOCL
A22: 19 | B22: 45949 | G22: =E22*F22 -> 0 | H22: 0 | I22: 0 | J22: =H22*I22 -> 0 | K22: =G22+J22 -> 0 | L22: =+K22 -> 0 | M22: 0
A23: 20 | B23: 45950 | E23: 61.58 | F23: 97.43 | G23: =E23*F23 -> 5999.7394 | H23: 0 | I23: 0 | J23: =H23*I23 -> 0 | K23: =G23+J23 -> 5999.7394 | L23: =+K23 -> 5999.7394 | M23: 0 | N23: IOCL
A24: 21 | B24: 45951 | G24: =E24*F24 -> 0 | H24: 0 | I24: 0 | J24: =H24*I24 -> 0 | K24: =G24+J24 -> 0 | L24: =+K24 -> 0 | M24: 0
A25: 22 | B25: 45952 | G25: =E25*F25 -> 0 | H25: 0 | I25: 0 | J25: =H25*I25 -> 0 | K25: =G25+J25 -> 0 | L25: =+K25 -> 0 | M25: 0
A26: 23 | B26: 45953 | E26: 200 | F26: 97.76 | G26: =E26*F26 -> 19552 | H26: 0 | I26: 0 | J26: =H26*I26 -> 0 | K26: =G26+J26 -> 19552 | L26: =+K26 -> 19552 | M26: 0 | N26: HPCL
