Workbook

Sheet Sheet1
A1: S.no | B1: Site Name | C1: Bunk Name | D1: Diesel(Liters) | E1: Diesel Amount | F1: Petrol(Liters) | G1: Petrol Amount | H1: Total Amount | I1: Opening Blance | J1: Amount Paid | K1: Closing Balances
A2: 1 | B2: Khammam-1 | C2: Sri Ramakotaiah Fuel Point | D2: 11984.26 | E2: 1146654 | F2: 130 | G2: 13969.8 | H2: =E2+G2 -> 1160623.8 | I2: 5140597 | J2: 2500000 | K2: =I2+H2-J2 -> 3801220.8
A3: 2 | B3: Khammam-2 | C3: Divya laxmi ganapathi | D3: 118512.26 | E3: 11339228 | F3: 535 | G3: 57491.1 | H3: =E3+G3 -> 11396719 | I3: 3730421 | J3: 1500000 | K3: =I3+H3-J3 -> 13627140
A4: 3 | B4: Khammam-3 | C4: Jayasai union bunk | D4: 33155.09 | E4: 3172942.1 | F4: 70 | G4: 7523.6 | H4: =E4+G4 -> 3180465.7 | I4: 8891075.4 | J4: 2000000 | K4: =I4+H4-J4 -> 10071541
A5: 4 | B5: Jadcherla-1 | C5: Sai Baba Fuel Station | D5: 6550.84 | E5: 631631.99 | F5: 305.75 | G5: 33091.323 | H5: =E5+G5 -> 664723.32 | I5: 1966837 | J5: 0 | K5: =I5+H5-J5 -> 2631560.3
A6: 5 | B6: Jadcherla-2 | C6: Uttara Enterprises | D6: 0 | E6: 0 | F6: 0 | G6: 0 | H6: =E6+G6 -> 0 | I6: 1832240.6 | J6: 0 | K6: =I6+H6-J6 -> 1832240.6
A7: 6 | B7: Jadcherla-3 | C7: Bhavani KSK Fuel Station-Nawabpet | D7: 4040 | E7: 389092.4 | F7: 0 | G7: 0 | H7: =E7+G7 -> 389092.4 | I7: 0 | J7: 0 | K7: =I7+H7-J7 -> 389092.4
A8: 7 | B8: Jadcherla-4 | C8: ADHOC FILLING STATION STATION | D8: 11600 | E8: 1118588 | F8: 0 | G8: 0 | H8: =E8+G8 -> 1118588 | I8: 0 | J8: 0 | K8: =I8+H8-J8 -> 1118588
A9: 8 | B9: Sangareddy-1 | C9: Shree lakshmi ganapathi F/S | D9: 4185.96 | E9: 403359.11 | F9: 62 | G9: 6706.54 | H9: =E9+G9 -> 410065.65 | I9: 1004532 | J9: 1414699.8 | K9: 0
A10: 9 | B10: Sangareddy-2 | C10: Sri Durgabhavani Filling Station | D10: 165 | E10: 15912 | F10: 16 | G10: 1732.96 | H10: =E10+G10 -> 17644.96 | I10: 0 | J10: 17644.96 | K10: =I10+H10-J10 -> 0
A11: 10 | B11: Sangareddy-3 | C11: Laxmi Narasimha Enterprises F/S | D11: 40 | E11: 3849 | F11: 0 | G11: 0 | H11: =E11+G11 -> 3849 | I11: 0 | J11: 3849 | K11: =I11+H11-J11 -> 0
A12: 11 | B12: Sangareddy-4 | C12: Sree Shiva Parvathi Filling Station | D12: 1459.79 | E12: 140476 | F12: 16 | G12: 1732.96 | H12: =E12+G12 -> 142208.96 | I12: 0 | J12: 142208.96 | K12: =I12+H12-J12 -> 0
A13: 12 | B13: YG Gudda | C13: Pallavi Petrolium | D13: 3800 | E13: 346940 | F13: 385 | G13: 39747.4 | H13: =E13+G13 -> 386687.4 | I13: 244365 | J13: 299920 | K13: =I13+H13-J13 -> 331132.4
A14: 13 | B14: Hosadurga-1 | C14: Merchant Petroliums | D14: 4500 | E14: 412380 | F14: 140 | G14: 14777 | H14: =E14+G14 -> 427157 | I14: 0 | J14: 150000 | K14: =I14+H14-J14 -> 277157
A15: 14 | B15: Hosadurga-2 | C15: Shree Veeraprathap Fuel | D15: 2000 | E15: 182780 | F15: 135 | G15: 13967.1 | H15: =E15+G15 -> 196747.1 | I15: 151569.4 | J15: 150000 | K15: =I15+H15-J15 -> 198316.5
A16: 15 | B16: Malebennuru(KUWSDB) | C16: Sri Ramanjuneya Service Station | D16: 3277.82 | E16: 301888 | F16: 138 | G16: 14332 | H16: =E16+G16 -> 316220 | I16: 96655 | J16: 385490 | K16: =I16+H16-J16 -> 27385
A17: 16 | B17: kadur | C17: Vishal Service Station | D17: 2000 | E17: 182300 | F17: 145 | G17: 15119.15 | H17: =E17+G17 -> 197419.15 | I17: 578097.65 | J17: 0 | K17: =I17+H17-J17 -> 775516.8
A18: 17 | B18: Hiriyur(VJNL) | C18: Sri Balaji Agencies | D18: 2400 | E18: 221040 | F18: 210 | G18: 21810.6 | H18: =E18+G18 -> 242850.6 | I18: 237520 | J18: 250000 | K18: =I18+H18-J18 -> 230370.6
A19: 18 | B19: Chellakere(KUWSDB) | C19: Sri Vishnu Baba Petroleum | D19: 2045 | E19: 188324.05 | F19: 125 | G19: 12982.5 | H19: =E19+G19 -> 201306.55 | I19: 0 | J19: 201306.55 | K19: =I19+H19-J19 -> 0
A20: 19 | B20: Khanapur(PKG-3) | C20: J K Makavi | D20: 169 | E20: 15411.11 | F20: 16.25 | G20: 1669.23 | H20: =E20+G20 -> 17080.34 | I20: 0 | J20: 17080.34 | K20: =I20+H20-J20 -> 0
A21: 20 | B21: Munavalli(PKG-3) | C21: Shahapur Petroleum | D21: 14283.35 | E21: 1303412.1 | F21: 127 | G21: 13103.86 | H21: =E21+G21 -> 1316516 | I21: 58857 | J21: 1134279.9 | K21: =I21+H21-J21 -> 241093.08
... A24: 23 | B24: Kabbur(PKG-3) | C24: Shri Jai Hanuman Petrolium | D24: 509.02 | E24: 46621.142 | F24: 11.56 | G24: 1196.8068 | H24: =E24+G24 -> 47817.949 | I24: 0 | J24: 47817.949 | K24: =I24+H24-J24 -> 0
A25: 24 | B25: Kumta (PKG-1) | C25: Krishma fuel station | D25: 760.33 | E25: 69889.534 | F25: 47.46 | G25: 4933.9416 | H25: =E25+G25 -> 74823.475 | J25: 74823.475 | K25: =I25+H25-J25 -> 0
A26: 25 | B26: Jalgaon | C26: Sri Sai Petrol Pump | D26: 597.14 | E26: 54712.182 | F26: 13.52 | G26: 1419.4272 | H26: =E26+G26 -> 56131.609 | I26: 4528.49 | J26: 49930.511 | K26: =I26+H26-J26 -> 10729.588
A27: 26 | B27: MKBD | C27: Shree Sai Samarth Petroleum | D27: 25450 | E27: 2319513 | F27: 75 | G27: 7845 | H27: =E27+G27 -> 2327358 | I27: 1668531 | J27: 2000000 | K27: =I27+H27-J27 -> 1995889
A28: 27 | B28: Haveri | C28: Shivalingeshwar Petroleum | D28: 944.46 | E28: 86389.756 | F28: 63.01 | G28: 6517.1243 | H28: =E28+G28 -> 92906.88 | I28: 90058 | J28: 115444 | K28: =I28+H28-J28 -> 67520.88
A29: 28 | B29: Guttal | C29: Taware filling station | D29: 935.89 | E29: 85914.702 | F29: 40 | G29: 4150.4 | H29: =E29+G29 -> 90065.102 | J29: 90065.102 | K29: =I29+H29-J29 -> 0
A30: 29 | B30: Rattihali | C30: Shree Siri Gowari petroliam | D30: 1032.57 | E30: 95037.743 | F30: 45 | G30: 4680.9 | H30: =E30+G30 -> 99718.643 | J30: 99718.643 | K30: =I30+H30-J30 -> 0
A31: 30 | B31: Gajendragada | C31: Vanasri Petrol Pump | D31: 60 | E31: 5509.8 | F31: 18 | G31: 1868.4 | H31: =E31+G31 -> 7378.2 | I31: 30323 | J31: 7378.2 | K31: =I31+H31-J31 -> 30323
A32: 31 | B32: Ghattaprabha(PKG-3) | C32: Vivek Petrol Pump | D32: 0 | E32: 0 | F32: 0 | G32: 0 | H32: =E32+G32 -> 0 | I32: 1036347.3 | J32: 400000 | K32: =I32+H32-J32 -> 636347.32
A33: 32 | B33: Gokak(PKG-3) | C33: AJ Petrolinks | D33: 11163.57 | E33: 1021243.4 | F33: 271 | G33: 28024.11 | H33: =E33+G33 -> 1049267.5 | I33: 473791 | J33: 300000 | K33: =I33+H33-J33 -> 1223058.5
A34: 33 | B34: Ghattaprabha-2(PKG-3) | C34: Manikeri Petroleums | D34: 0 | E34: 0 | F34: 4.82 | G34: 499.98 | H34: =E34+G34 -> 499.98 | I34: 0 | J34: 499.98 | K34: =I34+H34-J34 -> 0
A35: 34 | B35: Ankalgi(PKG-3) | C35: Nirwani Petroleums | D35: 152.92 | E35: 13949.929 | F35: 37.28 | G35: 3857.5144 | H35: =E35+G35 -> 17807.443 | I35: 0 | J35: 17807.443 | K35: =I35+H35-J35 -> 0
A36: 35 | B36: Talikote(PKG-1) | C36: Raykar Oil Agencies | D36: 637.8 | E36: 58358.7 | F36: 61.99 | G36: 5912.6304 | H36: =E36+G36 -> 64271.33 | I36: 0 | J36: 64271.33 | K36: =I36+H36-J36 -> 0
A37: 36 | B37: Chadchan(PKG-1) | C37: Khavekar Petrolium | D37: 577.29 | E37: 52088.877 | F37: 43.88 | G37: 4482.7808 | H37: =E37+G37 -> 56571.658 | I37: 192780 | J37: 192780 | K37: =I37+H37-J37 -> 56571.658
A38: 37 | B38: Sindagi | C38: G.P.PORWAL | D38: 138 | E38: 12589.74 | F38: 0 | G38: 0 | H38: =E38+G38 -> 12589.74 | I38: 0 | J38: 12589.74 | K38: =I38+H38-J38 -> 0
A39: 38 | B39: Muddebihal(PKG-1) | C39: Bhosle Service Station | D39: 98.41 | E39: 8999.5945 | F39: 33.81 | G39: 3495.6159 | H39: =E39+G39 -> 12495.21 | I39: 0 | J39: 12495.21 | K39: =I39+H39-J39 -> 0
A40: 39 | B40: Almela(PKG-1) | C40: Shiddeshwar Petroleums | D40: 35.03 | E40: 3199.2899 | F40: 30.92 | G40: 3192.7992 | H40: =E40+G40 -> 6392.0891 | I40: 0 | J40: 6392.0891 | K40: =I40+H40-J40 -> 0
A41: 40 | B41: Srirangapatna | C41: Sri Chakra Fuel Station | D41: 71.77 | E41: 6500.2089 | F41: 35.13 | G41: 3599.4198 | H41: =E41+G41 -> 10099.629 | I41: 0 | J41: 10099.629 | K41: =I41+H41-J41 -> 0
A42: 41 | B42: Nalatwad(PKG-1) | C42: Shri Pawad Basaweshwar Petroleums | D42: 436.89 | E42: 40027.862 | F42: 21.25 | G42: 2200.8625 | H42: =E42+G42 -> 42228.724 | I42: 48315 | J42: 90535.84 | K42: =I42+H42-J42 -> 7.8843
...

Sheet July-25
A1: S.no | B1: Site Name | C1: Bunk Name | D1: Diesel(Liters) | E1: Diesel Amount | F1: Petrol(Liters) | G1: Petrol Amount | H1: Total Amount | I1: Opening Blance | J1: Amount Paid | K1: Closing Balances
A2: 1 | B2: Khammam-2 | C2: Divya laxmi ganapathi | D2: =+'Khammam-2'!E39 -> 72956.65 | E2: =+'Khammam-2'!G39 -> 6980416.3 | F2: =+'Khammam-2'!H39 -> 596.7 | G2: =+'Khammam-2'!J39 -> 64121.382 | H2: =E2+G2 -> 7044537.7 | I2: =+'Khammam-2'!K3 -> 13565410 | J2: =+'Khammam-2'!L39 -> 6000000 | K2: =H2+I2-J2 -> 14609947
A3: 2 | B3: Khammam-3 | C3: Jayasai union bunk | D3: =+'Khammam-3'!E35 -> 66079.65 | E3: =+'Khammam-3'!G35 -> 6323822.5 | F3: =+'Khammam-3'!H35 -> 445 | G3: =+'Khammam-3'!J35 -> 47828.6 | H3: =E3+G3 -> 6371651.1 | I3: =+'Khammam-3'!K3 -> 10291937 | J3: =+'Khammam-3'!L35 -> 4000000 | K3: =H3+I3-J3 -> 12663588
A4: 3 | B4: Jadcherla-1 | C4: Sai Baba Fuel Station | D4: =+'Jedcherla -1'!E36 -> 17003.65 | E4: =+'Jedcherla -1'!G36 -> 1639491.9 | F4: =+'Jedcherla -1'!H36 -> 548.62 | G4: =+'Jedcherla -1'!J36 -> 59377.143 | H4: =E4+G4 -> 1698869.1 | I4: =+'Jedcherla -1'!M3 -> 2139146.2 | J4: =+'Jedcherla -1'!L36 -> 2450000 | K4: =H4+I4-J4 -> 1388015.3
A5: 4 | B5: Jadcherla-4 | C5: ADHOC FILLING STATION STATION | D5: =+'Jedcharla-3'!E35 -> 51757.47 | E5: =+'Jedcharla-3'!G35 -> 4990972.8 | F5: 0 | G5: 0 | H5: =E5+G5 -> 4990972.8 | I5: =+'Jedcharla-3'!K3 -> 1209626.7 | J5: =+'Jedcharla-3'!L35 -> 4800000 | K5: =H5+I5-J5 -> 1400599.6
A6: 5 | B6: Sangareddy-1 | C6: Sree Shiva Parvathi Filling Station | D6: =+Sangareddy!E40 -> 0 | E6: =+Sangareddy!G40 -> 0 | F6: =+Sangareddy!H40 -> 120 | G6: =+Sangareddy!J40 -> 0 | H6: =E6+G6 -> 0 | I6: =+Sangareddy!K3 -> 362536.8 | J6: =+Sangareddy!L40 -> 362536.8 | K6: =H6+I6-J6 -> 0
A7: 6 | B7: Dindi | C7: Akarapu Balakistamma Fillling | D7: =+Dindi!E35 -> 117.57 | E7: =+Dindi!G35 -> 11384.303 | F7: =+Dindi!H35 -> 5.52 | G7: =+Dindi!J35 -> 599.8032 | H7: =E7+G7 -> 11984.106 | J7: =+Dindi!L35 -> 11984.106 | K7: =H7+I7-J7 -> 0
A8: 7 | B8: Devarkhadra | C8: Kurumurthy Swami F/S | D8: =+Devarakhadra!E35 -> 16462.22 | E8: =+Devarakhadra!G35 -> 1598481.6 | F8: =+Devarakhadra!H35 -> 60 | G8: =+Devarakhadra!J35 -> 6529.8 | H8: =E8+G8 -> 1605011.4 | I8: =+Devarakhadra!M3 -> 169047.22 | J8: =+Devarakhadra!L35 -> 1193133 | K8: =H8+I8-J8 -> 580925.58
A9: 8 | B9: YG Gudda | C9: Pallavi Petrolium | D9: =+'YG Gudda '!E36 -> 12447.47 | E9: =+'YG Gudda '!G36 -> 1136470.4 | F9: =+'YG Gudda '!H36 -> 630 | G9: =+'YG Gudda '!J36 -> 65041.2 | H9: =E9+G9 -> 1201511.6 | I9: ='YG Gudda '!K3 -> 48480.979 | J9: =+'YG Gudda '!L36 -> 1150000 | K9: =H9+I9-J9 -> 99992.615
A10: 9 | B10: Hosadurga-1 | C10: Merchant Petroliums | D10: =+Hosadurga!E35 -> 2500 | E10: =+Hosadurga!G35 -> 229500 | F10: =+Hosadurga!H35 -> 105 | G10: =+Hosadurga!J35 -> 11175.15 | H10: =E10+G10 -> 240675.15 | I10: =+Hosadurga!K3 -> 0 | J10: =+Hosadurga!L35 -> 240675.3 | K10: =H10+I10-J10 -> -0.15
A11: 10 | B11: Hosadurga-2 | C11: Shree Veeraprathap Fuel | D11: =+'Hosadurga -2'!E35 -> 8000 | E11: =+'Hosadurga -2'!G35 -> 732400 | F11: =+'Hosadurga -2'!H35 -> 345 | G11: =+'Hosadurga -2'!J35 -> 35786.85 | H11: =+'Hosadurga -2'!K35 -> 768186.85 | I11: =+'Hosadurga -2'!K3 -> 380044.4 | J11: =+'Hosadurga -2'!L35 -> 530000 | K11: =H11+I11-J11 -> 618231.25
A12: 11 | B12: Malebennuru(KUWSDB) | C12: Sri Ramanjuneya Service Station | D12: =+'Malebenur(KUWSDB)'!E38 -> 4216 | E12: =+'Malebenur(KUWSDB)'!G38 -> 388968.16 | F12: =+'Malebenur(KUWSDB)'!H38 -> 210 | G12: =+'Malebenur(KUWSDB)'!J38 -> 21867.3 | H12: =E12+G12 -> 410835.46 | I12: =+'Malebenur(KUWSDB)'!K3 -> 98761.304 | J12: =+'Malebenur(KUWSDB)'!L36 -> 463458 | K12: =H12+I12-J12 -> 46138.764
A13: 12 | B13: kadur | C13: Vishal Service Station | D13: =+Kadur!E35 -> 2000 | E13: =+Kadur!G35 -> 184300 | F13: =+Kadur!H35 -> 110 | G13: =+Kadur!J35 -> 11469.7 | H13: =E13+G13 -> 195769.7 | I13: =+Kadur!K3 -> 209799.73 | J13: =+Kadur!L35 -> 0 | K13: =H13+I13-J13 -> 405569.43
A14: 13 | B14: Hiriyur(VJNL) | C14: Sri Balaji Agencies | D14: =+'Hiriyur(VJNL)'!E35 -> 4500 | E14: =+'Hiriyur(VJNL)'!G35 -> 415170 | F14: =+'Hiriyur(VJNL)'!H35 -> 280 | G14: =+'Hiriyur(VJNL)'!J35 -> 29159.2 | H14: =E14+G14 -> 444329.2 | I14: =+'Hiriyur(VJNL)'!K3 -> 382940.4 | J14: =+'Hiriyur(VJNL)'!L35 -> 800519.8 | K14: =H14+I14-J14 -> 26749.8
A15: 14 | B15: Chellakere(KUWSDB) | C15: Sri Vishnu Baba Petroleum | D15: =+'Chellakere (KUWSDB)'!E35 -> 4890 | E15: =+'Chellakere (KUWSDB)'!G35 -> 451102.5 | F15: =+'Chellakere (KUWSDB)'!H35 -> 215 | G15: =+'Chellakere (KUWSDB)'!J35 -> 22387.2 | H15: =E15+G15 -> 473489.7 | I15: 0 | J15: =+'Chellakere (KUWSDB)'!L35 -> 473489.7 | K15: =H15+I15-J15 -> 0
A16: 15 | B16: Khanapur(PKG-3) | C16: J K Makavi | D16: =+Khanapur!E35 -> 20 | E16: =+Khanapur!G35 -> 1817.6 | F16: =+Khanapur!H35 -> 27.03 | G16: =+Khanapur!J35 -> 2777.8731 | H16: =E16+G16 -> 4595.4731 | I16: 0 | J16: =+Khanapur!M35 -> 4595.4731 | K16: =H16+I16-J16 -> 0
A17: 16 | B17: Munavalli(PKG-3) | C17: Shahapur Petroleum | D17: =+'Munavalli(KUWSDB)'!E36 -> 219.15 | E17: =+'Munavalli(KUWSDB)'!G36 -> 19999.629 | F17: =+'Munavalli(KUWSDB)'!H36 -> 0 | G17: =+'Munavalli(KUWSDB)'!J36 -> 0 | H17: =E17+G17 -> 19999.629 | I17: =+'Munavalli(KUWSDB)'!M3 -> 587810.79 | J17: =+'Munavalli(KUWSDB)'!L36 -> 607810.42 | K17: =H17+I17-J17 -> 0
A18: 17 | B18: Munavalli(PKG-3)-2 | C18: Shri Daneshwari | D18: =+'Munavali-2'!E36 -> 1839 | E18: =+'Munavali-2'!G36 -> 167937.48 | F18: =+'Munavali-2'!H36 -> 83 | G18: =+'Munavali-2'!J36 -> 8568.92 | H18: =E18+G18 -> 176506.4 | I18: =+'Munavali-2'!M3 -> 0 | J18: =+'Munavali-2'!L36 -> 150000 | K18: =H18+I18-J18 -> 26506.4
A19: 18 | B19: Borgaon(PKG-3) | C19: Aadisagar Petrolium | D19: =+Borgaon!E35 -> 922.62 | E19: =+Borgaon!G35 -> 84668.837 | F19: =+Borgaon!H35 -> 40 | G19: =+Borgaon!J35 -> 4149.2 | H19: =E19+G19 -> 88818.037 | I19: =+Borgaon!K3 -> 59999.798 | J19: =+Borgaon!L35 -> 119123 | K19: =H19+I19-J19 -> 29694.836
A20: 19 | B20: Ugar,Kudichi(PKG-3) | C20: Shiri Bhrhmanath Petrolium | D20: =+'Ugar,Khagwad,Kudichi'!E35 -> 5405.66 | E20: =+'Ugar,Khagwad,Kudichi'!G35 -> 496942.32 | F20: =+'Ugar,Khagwad,Kudichi'!H35 -> 241 | G20: =+'Ugar,Khagwad,Kudichi'!J35 -> 25037.49 | H20: =E20+G20 -> 521979.81 | I20: =+'Ugar,Khagwad,Kudichi'!M4 -> 236571.24 | J20: =+'Ugar,Khagwad,Kudichi'!L35 -> 737362.07 | K20: =H20+I20-J20 -> 21188.98
A21: 20 | B21: Kabbur(PKG-3) | C21: Shri Jai Hanuman Petrolium | D21: =+Kabbur!E35 -> 195 | E21: =+Kabbur!G35 -> 17860.05 | F21: =+Kabbur!H35 -> 28.08 | G21: =+Kabbur!J35 -> 2907.1224 | H21: =E21+G21 -> 20767.172 | I21: 0 | J21: =+Kabbur!L35 -> 20767.172 | K21: =H21+I21-J21 -> 0
A22: 21 | B22: Kumta (PKG-1) | C22: Krishma fuel station | D22: =+kumta!E35 -> 1055.96 | E22: =+kumta!G35 -> 97063.843 | F22: =+kumta!H35 -> 142.22 | G22: =+kumta!J35 -> 14785.191 | H22: =E22+G22 -> 111849.03 | I22: 0 | J22: =+kumta!L35 -> 111849.03 | K22: =H22+I22-J22 -> 0
A23: 22 | B23: Jalgaon | C23: Sri Sai Petrol Pump | D23: =+Jalgaon!E42 -> 1209.65 | E23: =+Jalgaon!G42 -> 110814.88 | F23: =+Jalgaon!H42 -> 8.08 | G23: =+Jalgaon!J42 -> 849.9352 | H23: =E23+G23 -> 111664.82 | I23: =+Jalgaon!K3 -> 17065.88 | J23: =+Jalgaon!L42 -> 78567.482 | K23: =H23+I23-J23 -> 50163.215
A24: 23 | B24: MKBD | C24: Shree Sai Samarth Petroleum | D24: =+MKBD!E36 -> 2000 | E24: =+MKBD!G36 -> 182280 | F24: =+MKBD!H36 -> 40 | G24: =+MKBD!J36 -> 4184 | H24: =E24+G24 -> 186464 | I24: =+MKBD!K3 -> 1012175.6 | J24: =+MKBD!L36 -> 0 | K24: =H24+I24-J24 -> 1198639.6
A25: 24 | B25: Haveri | C25: Shivalingeshwar Petroleum | D25: =+Haveri!E35 -> 1389.88 | E25: =+Haveri!G35 -> 127132.32 | F25: =+Haveri!H35 -> 78.88 | G25: =+Haveri!J35 -> 8156.192 | H25: =E25+G25 -> 135288.52 | I25: =+Haveri!M3 -> 167921.8 | J25: =+Haveri!L35 -> 267684 | K25: =H25+I25-J25 -> 35526.318
A26: 25 | B26: Guttal | C26: Taware filling station | D26: =+Guttal!E35 -> 378.85 | E26: =+Guttal!G35 -> 34778.43 | F26: =+Guttal!H35 -> 56 | G26: =+Guttal!J35 -> 5810.56 | H26: =E26+G26 -> 40588.99 | I26: 0 | J26: =+Guttal!L35 -> 40588.99 | K26: =H26+I26-J26 -> 0
A27: 26 | B27: Rattihali | C27: Shree Siri Gowari petroliam | D27: =+Rattihali!E35 -> 4661.78 | E27: =+Rattihali!G35 -> 429070.23 | F27: =+Rattihali!H35 -> 149.77 | G27: =+Rattihali!J35 -> 15579.075 | H27: =E27+G27 -> 444649.31 | I27: =+Rattihali!M3 -> 155322.81 | J27: =+Rattihali!L35 -> 546606.43 | K27: =H27+I27-J27 -> 53365.686
A28: 27 | B28: Gajendragada | C28: Vanasri Petrol Pump | D28: =+Gajendragada!E35 -> 376.16 | E28: =+Gajendragada!G35 -> 34542.773 | F28: =+Gajendragada!H35 -> 82 | G28: =+Gajendragada!J35 -> 8511.6 | H28: =E28+G28 -> 43054.373 | I28: =+Gajendragada!K3 -> 74049.039 | J28: =+Gajendragada!L35 -> 95377 | K28: =H28+I28-J28 -> 21726.412
A29: 28 | B29: Ghattaprabha(PKG-3) | C29: Vivek Petrol Pump | D29: =+Ghattaprabha!E35 -> 0 | E29: =+Ghattaprabha!G35 -> 0 | F29: =+Ghattaprabha!H35 -> 0 | G29: =+Ghattaprabha!J35 -> 0 | H29: =E29+G29 -> 0 | I29: =+Ghattaprabha!M3 -> 308876.47 | J29: =+Ghattaprabha!L35 -> 308876 | K29: =H29+I29-J29 -> 0.465
A30: 29 | B30: Gokak(PKG-3) | C30: AJ Petrolinks | D30: =+'Gokak Dharwad PKG 3'!E40 -> 19448.83 | E30: =+'Gokak Dharwad PKG 3'!G40 -> 1779179 | F30: =+'Gokak Dharwad PKG 3'!H40 -> 444.65 | G30: =+'Gokak Dharwad PKG 3'!J40 -> 46066.616 | H30: =E30+G30 -> 1825245.6 | I30: =+'Gokak Dharwad PKG 3'!K3 -> 906887.85 | J30: =+'Gokak Dharwad PKG 3'!L40 -> 2225179 | K30: =H30+I30-J30 -> 506954.43
A31: 30 | B31: Ankaligi | C31: Shiv ganga | D31: =+Ankalgi!E35 -> 1939.68 | E31: =+Ankalgi!G35 -> 177112.18 | F31: =+Ankalgi!H35 -> 187.9 | G31: =+Ankalgi!J35 -> 19396.917 | H31: =E31+G31 -> 196509.1 | I31: =+Ankalgi!M3 -> 0 | J31: =+Ankalgi!L35 -> 73518 | K31: =H31+I31-J31 -> 122991.1
A32: 31 | B32: ShankeshWAR | C32: SR Patil | D32: =+' Shankeshwar'!E35 -> 119.76 | E32: =+' Shankeshwar'!G35 -> 10934.088 | F32: =+' Shankeshwar'!H35 -> 29 | G32: =+' Shankeshwar'!J35 -> 2993.38 | H32: =E32+G32 -> 13927.468 | J32: =+' Shankeshwar'!L35 -> 13927.468 | K32: =H32+I32-J32 -> 0
A33: 32 | B33: Talikote(PKG-1) | C33: Raykar Oil Agencies | D33: =+' Talikote'!E45 -> 1274.83 | E33: =+' Talikote'!G45 -> 116609.65 | F33: =+' Talikote'!H45 -> 110.48 | G33: =+' Talikote'!J45 -> 11458.378 | H33: =E33+G33 -> 128068.03 | I33: =+' Talikote'!N3 -> 28582.189 | J33: =+' Talikote'!L45 -> 153145.74 | K33: =H33+I33-J33 -> 3504.4807
A34: 33 | B34: Chadchan(PKG-1) | C34: Khavekar Petrolium | D34: =+Chadchan!E35 -> 1455.5 | E34: =+Chadchan!G35 -> 132785.27 | F34: =+Chadchan!H35 -> 66.91 | G34: =+Chadchan!J35 -> 6902.4356 | H34: =E34+G34 -> 139687.7 | I34: =+Chadchan!K3 -> 92995.303 | J34: =+Chadchan!L35 -> 127117 | K34: =H34+I34-J34 -> 105566
A35: 34 | B35: Sindagi | C35: G.P.PORWAL | D35: =+Sindagi!E44 -> 1574.89 | E35: =+Sindagi!G44 -> 143677.21 | F35: =+Sindagi!H44 -> 15.5 | G35: =+Sindagi!J44 -> 1712.405 | H35: =E35+G35 -> 145389.62 | I35: =+Sindagi!M3 -> 9854.749 | J35: =+Sindagi!L44 -> 154336.16 | K35: =H35+I35-J35 -> 908.2041
A36: 35 | B36: Muddebihal(PKG-1) | C36: Bhosle Service Station | D36: =+Muddebihal!E47 -> 2851 | E36: =+Muddebihal!G47 -> 260723.95 | F36: =+Muddebihal!H47 -> 48.31 | G36: =+Muddebihal!J47 -> 4994.7709 | H36: =E36+G36 -> 265718.72 | I36: =+Muddebihal!M3 -> 27514.01 | J36: =+Muddebihal!L47 -> 284211.94 | K36: =H36+I36-J36 -> 9020.7913
A37: 36 | B37: Almela(PKG-1) | C37: Shiddeshwar Petroleums | D37: =+Alemela!E43 -> 2968.21 | E37: =+Alemela!G43 -> 271086.62 | F37: =+Alemela!H43 -> 42.84 | G37: =+Alemela!J43 -> 4423.6584 | H37: =E37+G37 -> 275510.28 | I37: =+Alemela!M3 -> 74760 | J37: =+Alemela!L43 -> 329307.11 | K37: =H37+I37-J37 -> 20963.168
A38: 37 | B38: Nalatwad(PKG-1) | C38: Shri Pawad Basaweshwar Petroleums | D38: =+Nalatwad!E43 -> 1273.28 | E38: =+Nalatwad!G43 -> 116657.91 | F38: =+Nalatwad!H43 -> 118.02 | G38: =+Nalatwad!J43 -> 12223.331 | H38: =E38+G38 -> 128881.24 | I38: =+Nalatwad!M3 -> 36628.608 | J38: =+Nalatwad!L43 -> 116000 | K38: =H38+I38-J38 -> 49509.853
A39: 38 | B39: Srirangapatna | C39: Sri Chakra Fuel Station | D39: =+Srirangapatna!E35 -> 454.61 | E39: =+Srirangapatna!G35 -> 41174.028 | F39: =+Srirangapatna!H35 -> 51.88 | G39: =+Srirangapatna!J35 -> 5315.6248 | H39: =E39+G39 -> 46489.652 | I39: 0 | J39: =+Srirangapatna!L35 -> 46489.652 | K39: =H39+I39-J39 -> 0
A40: Total | D40: =SUM(D2:D39) -> 315964.98 | E40: =SUM(E2:E39) -> 29937329 | F40: =SUM(F2:F39) -> 5762.39 | G40: =SUM(G2:G39) -> 592148 | H40: =SUM(H2:H39) -> 30529477 | I40: =SUM(I2:I39) -> 32654747 | J40: =SUM(J2:J39) -> 29088236 | K40: =H40+I40-J40 -> 34095988

Sheet Khammam-1
A1: Sri Ramakotaiah Fuel Point
A2: S.No | B2: Date | C2: GRN No | D2: Ind No/Bill No | E2: Diesel (Lts) | F2: Price | G2: Amount | H2: Petrol (Lts) | I2: Price | J2: Amount | K2: Total amount | L2: Amount paid | M2: As 0n Date | N2: Remarks
A3: Opening Balance | M3: =+K3 -> 0 | P3: 220299.06
A4: 1 | B4: 45809 | E4: 0 | F4: 0 | G4: =E4*F4 -> 0 | H4: 0 | I4: 0 | J4: =H4*I4 -> 0 | K4: =G4+J4 -> 0 | L4: 0 | M4: =M3+K4-L4 -> 0
A5: 2 | B5: 45810 | E5: 0 | F5: 0 | G5: =E5*F5 -> 0 | H5: 0 | I5: 0 | J5: =H5*I5 -> 0 | K5: =G5+J5 -> 0 | L5: 0 | M5: =M4+K5-L5 -> 0
A6: 3 | B6: 45811 | E6: 0 | F6: 0 | G6: =E6*F6 -> 0 | H6: 0 | I6: 0 | J6: =H6*I6 -> 0 | K6: =G6+J6 -> 0 | L6: 0 | M6: =M5+K6-L6 -> 0
A7: 4 | B7: 45812 | E7: 0 | F7: 0 | G7: =E7*F7 -> 0 | H7: 0 | I7: 0 | J7: =H7*I7 -> 0 | K7: =G7+J7 -> 0 | M7: =M6+K7-L7 -> 0
A8: 5 | B8: 45813 | E8: 0 | F8: 0 | G8: =E8*F8 -> 0 | H8: 0 | I8: 0 | J8: =H8*I8 -> 0 | K8: =G8+J8 -> 0 | M8: =M7+K8-L8 -> 0
A9: 6 | B9: 45814 | E9: 0 | F9: 0 | G9: =E9*F9 -> 0 | H9: 0 | I9: 0 | J9: =H9*I9 -> 0 | K9: =G9+J9 -> 0 | L9: 0 | M9: =M8+K9-L9 -> 0
A10: 7 | B10: 45815 | E10: 0 | F10: 0 | G10: =E10*F10 -> 0 | H10: 0 | I10: 0 | J10: =H10*I10 -> 0 | K10: =G10+J10 -> 0 | L10: 0 | M10: =M9+K10-L10 -> 0
A11: 8 | B11: 45816 | E11: 0 | F11: 0 | G11: =E11*F11 -> 0 | H11: 0 | I11: 0 | J11: =H11*I11 -> 0 | K11: =G11+J11 -> 0 | L11: 0 | M11: =M10+K11-L11 -> 0
A12: 9 | B12: 45817 | E12: 0 | F12: 0 | G12: =E12*F12 -> 0 | H12: 0 | I12: 0 | J12: =H12*I12 -> 0 | K12: =G12+J12 -> 0 | L12: 0 | M12: =M11+K12-L12 -> 0
A13: 10 | B13: 45818 | E13: 0 | F13: 0 | G13: =E13*F13 -> 0 | H13: 0 | I13: 0 | J13: =H13*I13 -> 0 | K13: =G13+J13 -> 0 | L13: 0 | M13: =M12+K13-L13 -> 0
A14: 11 | B14: 45819 | E14: 0 | F14: 0 | G14: =E14*F14 -> 0 | H14: 0 | I14: 0 | J14: =H14*I14 -> 0 | K14: =G14+J14 -> 0 | L14: 0 | M14: =M13+K14-L14 -> 0
A15: 12 | B15: 45820 | E15: 0 | F15: 0 | G15: =E15*F15 -> 0 | H15: 0 | I15: 0 | J15: =H15*I15 -> 0 | K15: =G15+J15 -> 0 | L15: 0 | M15: =M14+K15-L15 -> 0
A16: 13 | B16: 45821 | E16: 0 | F16: 0 | G16: =E16*F16 -> 0 | H16: 0 | I16: 0 | J16: =H16*I16 -> 0 | K16: =G16+J16 -> 0 | L16: 0 | M16: =M15+K16-L16 -> 0
A17: 14 | B17: 45822 | E17: 0 | F17: 0 | G17: =E17*F17 -> 0 | H17: 0 | I17: 0 | J17: =H17*I17 -> 0 | K17: =G17+J17 -> 0 | L17: 0 | M17: =M16+K17-L17 -> 0
A18: 15 | B18: 45823 | E18: 0 | F18: 0 | G18: =E18*F18 -> 0 | H18: 0 | I18: 0 | J18: =H18*I18 -> 0 | K18: =G18+J18 -> 0 | L18: 0 | M18: =M17+K18-L18 -> 0
A19: 16 | B19: 45824 | E19: 0 | F19: 0 | G19: =E19*F19 -> 0 | H19: 0 | I19: 0 | J19: =H19*I19 -> 0 | K19: =G19+J19 -> 0 | L19: 0 | M19: =M18+K19-L19 -> 0 | O19: .
A20: 17 | B20: 45825 | E20: 0 | F20: 0 | G20: =E20*F20 -> 0 | H20: 0 | I20: 0 | J20: =H20*I20 -> 0 | K20: =G20+J20 -> 0 | L20: 0 | M20: =M19+K20-L20 -> 0
A21: 18 | B21: 45826 | E21: 0 | F21: 0 | G21: =E21*F21 -> 0 | H21: 0 | I21: 0 | J21: =H21*I21 -> 0 | K21: =G21+J21 -> 0 | L21: 0 | M21: =M20+K21-L21 -> 0
A22: 19 | B22: 45827 | E22: 0 | F22: 0 | G22: =E22*F22 -> 0 | H22: 0 | I22: 0 | J22: =H22*I22 -> 0 | K22: =G22+J22 -> 0 | L22: 0 | M22: =M21+K22-L22 -> 0
A23: 20 | B23: 45828 | E23: 0 | F23: 0 | G23: =E23*F23 -> 0 | H23: 0 | I23: 0 | J23: =H23*I23 -> 0 | K23: =G23+J23 -> 0 | L23: 0 | M23: =M22+K23-L23 -> 0
A24: 21 | B24: 45829 | E24: 0 | F24: 0 | G24: =E24*F24 -> 0 | H24: 0 | I24: 0 | J24: =H24*I24 -> 0 | K24: =G24+J24 -> 0 | L24: 0 | M24: =M23+K24-L24 -> 0
A25: 22 | B25: 45830 | E25: 0 | F25: 0 | G25: =E25*F25 -> 0 | H25: 0 | I25: 0 | J25: =H25*I25 -> 0 | K25: =G25+J25 -> 0 | L25: 0 | M25: =M24+K25-L25 -> 0
A26: 23 | B26: 45831 | E26: 0 | F26: 0 | G26: =E26*F26 -> 0 | H26: 0 | I26: 0 | J26: =H26*I26 -> 0 | K26: =G26+J26 -> 0 | L26: 0 | M26: =M25+K26-L26 -> 0
A27: 24 | B27: 45832 | E27: 0 | F27: 0 | G27: =E27*F27 -> 0 | H27: 0 | I27: 0 | J27: =H27*I27 -> 0 | K27: =G27+J27 -> 0 | L27: 0 | M27: =M26+K27-L27 -> 0
A28: 25 | B28: 45833 | E28: 0 | F28: 0 | G28: =E28*F28 -> 0 | H28: 0 | I28: 0 | J28: =H28*I28 -> 0 | K28: =G28+J28 -> 0 | L28: 0 | M28: =M27+K28-L28 -> 0
A29: 26 | B29: 45834 | E29: 0 | F29: 0 | G29: =E29*F29 -> 0 | H29: 0 | I29: 0 | J29: =H29*I29 -> 0 | K29: =G29+J29 -> 0 | L29: 0 | M29: =M28+K29-L29 -> 0
A30: 27 | B30: 45835 | E30: 0 | F30: 0 | G30: =E30*F30 -> 0 | H30: 0 | I30: 0 | J30: =H30*I30 -> 0 | K30: =G30+J30 -> 0 | L30: 0 | M30: =M29+K30-L30 -> 0
A31: 28 | B31: 45836 | E31: 0 | F31: 0 | G31: =E31*F31 -> 0 | H31: 0 | I31: 0 | J31: =H31*I31 -> 0 | K31: =G31+J31 -> 0 | L31: 0 | M31: =M30+K31-L31 -> 0
A32: 29 | B32: 45837 | E32: 0 | F32: 0 | G32: =E32*F32 -> 0 | H32: 0 | I32: 0 | J32: =H32*I32 -> 0 | K32: =G32+J32 -> 0 | L32: 0 | M32: =M31+K32-L32 -> 0
A33: 30 | B33: 45838 | E33: 0 | F33: 0 | G33: =E33*F33 -> 0 | H33: 0 | I33: 0 | J33: =H33*I33 -> 0 | K33: =G33+J33 -> 0 | L33: 0 | M33: =M32+K33-L33 -> 0 | R33: 2584221.7
A34: 31 | E34: 0 | F34: 0 | G34: =E34*F34 -> 0 | H34: 0 | I34: 0 | J34: =H34*I34 -> 0 | K34: =G34+J34 -> 0 | L34: 0 | M34: =M33+K34-L34 -> 0
E35: 0 | F35: 0 | G35: =E35*F35 -> 0 | H35: 0 | I35: 0 | J35: =H35*I35 -> 0 | K35: =G35+J35 -> 0
E36: =SUM(E4:E35) -> 0 | G36: =SUM(G4:G35) -> 0 | H36: =SUM(H4:H35) -> 0 | J36: =SUM(J3:J35) -> 0 | K36: =SUM(K4:K35) -> 0 | L36: =SUM(L4:L35) -> 0
E41: =E36+H36 -> 0

Sheet Khammam-2
A1: Divya laxmi ganapathi
A2: S.No | B2: Date | C2: GRN No | D2: Ind No/Bill No | E2: Diesel (Lts) | F2: Price | G2: Amount | H2: Petrol (Lts) | I2: Price | J2: Amount | K2: Total amount | L2: Amount paid | M2: As 0n Date | N2: Remarks
A3: Opening Balance | K3: 13565410 | M3: =+K3 -> 13565410
A4: 1 | B4: 45839 | E4: 0 | F4: 0 | G4: =E4*F4 -> 0 | H4: 0 | I4: 0 | J4: =H4*I4 -> 0 | K4: =G4+J4 -> 0 | M4: =M3+K4-L4 -> 13565410
A5: 2 | B5: 45840 | E5: 0 | F5: 0 | G5: =E5*F5 -> 0 | H5: 0 | I5: 0 | J5: =H5*I5 -> 0 | K5: =G5+J5 -> 0 | M5: =M4+K5-L5 -> 13565410
A6: 3 | B6: 45841 | E6: 0 | F6: 0 | G6: =E6*F6 -> 0 | H6: 0 | I6: 0 | J6: =H6*I6 -> 0 | K6: =G6+J6 -> 0 | M6: =M5+K6-L6 -> 13565410
A7: 4 | B7: 45842 | E7: 5300.79 | F7: 95.68 | G7: =E7*F7 -> 507179.59 | H7: 20 | I7: 107.46 | J7: =H7*I7 -> 2149.2 | K7: =G7+J7 -> 509328.79 | M7: =M6+K7-L7 -> 14074738
A8: 5 | B8: 45843 | E8: =2500+3290.99+2800 -> 8590.99 | F8: 95.68 | G8: =E8*F8 -> 821985.92 | H8: =40+26.7 -> 66.7 | I8: 107.46 | J8: =H8*I8 -> 7167.582 | K8: =G8+J8 -> 829153.51 | M8: =M7+K8-L8 -> 14903892
A9: 6 | B9: 45844 | E9: 0 | F9: 0 | G9: =E9*F9 -> 0 | H9: 0 | I9: 0 | J9: =H9*I9 -> 0 | K9: =G9+J9 -> 0 | M9: =M8+K9-L9 -> 14903892
A10: 7 | B10: 45845 | E10: 2500 | F10: 95.67 | G10: =E10*F10 -> 239175 | H10: 20 | I10: 107.46 | J10: =H10*I10 -> 2149.2 | K10: =G10+J10 -> 241324.2 | M10: =M9+K10-L10 -> 15145216
A11: 8 | B11: 45846 | E11: 7022.75 | F11: 95.68 | G11: =E11*F11 -> 671936.72 | H11: 55 | I11: 107.46 | J11: =H11*I11 -> 5910.3 | K11: =G11+J11 -> 677847.02 | M11: =M10+K11-L11 -> 15823063
A12: 9 | B12: 45847 | E12: =2500+1541.27+200 -> 4241.27 | F12: 95.68 | G12: =E12*F12 -> 405804.71 | H12: 40 | I12: 107.46 | J12: =H12*I12 -> 4298.4 | K12: =G12+J12 -> 410103.11 | M12: =M11+K12-L12 -> 16233166
A13: 10 | B13: 45847 | E13: 2600 | F13: 95.67 | G13: =E13*F13 -> 248742 | K13: =G13+J13 -> 248742 | M13: =M12+K13-L13 -> 16481908
A14: 11 | B14: 45848 | E14: 0 | F14: 0 | G14: =E14*F14 -> 0 | H14: 0 | I14: 0 | J14: =H14*I14 -> 0 | K14: =G14+J14 -> 0 | M14: =M13+K14-L14 -> 16481908
A15: 12 | B15: 45849 | E15: 0 | F15: 0 | G15: =E15*F15 -> 0 | H15: 0 | I15: 0 | J15: =H15*I15 -> 0 | K15: =G15+J15 -> 0 | M15: =M14+K15-L15 -> 16481908
A16: 13 | B16: 45850 | E16: 2700 | F16: 95.68 | G16: =E16*F16 -> 258336 | H16: 20 | I16: 107.46 | J16: =H16*I16 -> 2149.2 | K16: =G16+J16 -> 260485.2 | M16: =M15+K16-L16 -> 16742393
A17: 14 | B17: 45851 | E17: 2500.26 | F17: 95.68 | G17: =E17*F17 -> 239224.88 | H17: 20 | I17: 107.46 | J17: =H17*I17 -> 2149.2 | K17: =G17+J17 -> 241374.08 | M17: =M16+K17-L17 -> 16983767
A18: 15 | B18: 45852 | E18: 2800 | F18: 95.68 | G18: =E18*F18 -> 267904 | H18: 40 | I18: 107.46 | J18: =H18*I18 -> 4298.4 | K18: =G18+J18 -> 272202.4 | M18: =M17+K18-L18 -> 17255970
A19: 16 | B19: 45853 | E19: 2800 | F19: 95.68 | G19: =E19*F19 -> 267904 | H19: 60 | I19: 107.46 | J19: =H19*I19 -> 6447.6 | K19: =G19+J19 -> 274351.6 | L19: 6000000 | M19: =M18+K19-L19 -> 11530321
A20: 17 | B20: 45854 | E20: 2500 | F20: 95.67 | G20: =E20*F20 -> 239175 | H20: 55 | I20: 107.46 | J20: =H20*I20 -> 5910.3 | K20: =G20+J20 -> 245085.3 | M20: =M19+K20-L20 -> 11775407
A21: 18 | B21: 45854 | E21: =2800+847.32 -> 3647.32 | F21: 95.68 | G21: =E21*F21 -> 348975.58 | K21: =G21+J21 -> 348975.58 | M21: =M20+K21-L21 -> 12124382
A22: 19 | B22: 45855 | E22: 2599.93 | F22: 95.68 | G22: =E22*F22 -> 248761.3 | H22: 20 | I22: 107.46 | J22: =H22*I22 -> 2149.2 | K22: =G22+J22 -> 250910.5 | M22: =M21+K22-L22 -> 12375293
A23: 20 | B23: 45856 | E23: 1006.24 | F23: 95.68 | G23: =E23*F23 -> 96277.043 | H23: 0 | I23: 107.46 | J23: =H23*I23 -> 0 | K23: =G23+J23 -> 96277.043 | M23: =M22+K23-L23 -> 12471570
A24: 21 | B24: 45857 | E24: 2800 | F24: 95.68 | G24: =E24*F24 -> 267904 | H24: 60 | I24: 107.46 | J24: =H24*I24 -> 6447.6 | K24: =G24+J24 -> 274351.6 | M24: =M23+K24-L24 -> 12745921
A25: 22 | B25: 45858 | E25: 2600 | F25: 95.68 | G25: =E25*F25 -> 248768 | H25: 0 | I25: 107.46 | J25: =H25*I25 -> 0 | K25: =G25+J25 -> 248768 | M25: =M24+K25-L25 -> 12994689
A26: 23 | B26: 45859 | E26: 747 | F26: 95.68 | G26: =E26*F26 -> 71472.96 | H26: 0 | I26: 0 | J26: =H26*I26 -> 0 | K26: =G26+J26 -> 71472.96 | M26: =M25+K26-L26 -> 13066162
A27: 24 | B27: 45860 | E27: 0 | F27: 0 | G27: =E27*F27 -> 0 | H27: 0 | I27: 0 | J27: =H27*I27 -> 0 | K27: =G27+J27 -> 0 | M27: =M26+K27-L27 -> 13066162
A28: 25 | B28: 45861 | E28: 0 | F28: 0 | G28: =E28*F28 -> 0 | H28: 0 | I28: 0 | J28: =H28*I28 -> 0 | K28: =G28+J28 -> 0 | M28: =M27+K28-L28 -> 13066162
A29: 26 | B29: 45862 | E29: 0 | F29: 0 | G29: =E29*F29 -> 0 | H29: 0 | I29: 0 | J29: =H29*I29 -> 0 | K29: =G29+J29 -> 0 | M29: =M28+K29-L29 -> 13066162
A30: 27 | B30: 45863 | E30: 0 | F30: 0 | G30: =E30*F30 -> 0 | H30: 0 | I30: 0 | J30: =H30*I30 -> 0 | K30: =G30+J30 -> 0 | M30: =M29+K30-L30 -> 13066162
A31: 28 | B31: 45864 | E31: 0 | F31: 0 | G31: =E31*F31 -> 0 | H31: 0 | I31: 0 | J31: =H31*I31 -> 0 | K31: =G31+J31 -> 0 | M31: =M30+K31-L31 -> 13066162
A32: 29 | B32: 45865 | E32: 0 | F32: 0 | G32: =E32*F32 -> 0 | H32: 0 | I32: 0 | J32: =H32*I32 -> 0 | K32: =G32+J32 -> 0 | M32: =M31+K32-L32 -> 13066162
A33: 30 | B33: 45866 | E33: 0 | F33: 0 | G33: =E33*F33 -> 0 | H33: 0 | I33: 0 | J33: =H33*I33 -> 0 | K33: =G33+J33 -> 0 | M33: =M32+K33-L33 -> 13066162
... A36: 33 | B36: 45869 | E36: 2700 | F36: 95.68 | G36: =E36*F36 -> 258336 | H36: 20 | I36: 107.46 | J36: =H36*I36 -> 2149.2 | K36: =G36+J36 -> 260485.2 | M36: =M35+K36-L36 -> 14609947
A37: 34 | E37: 0 | F37: 0 | G37: =E37*F37 -> 0 | H37: 0 | I37: 0 | J37: =H37*I37 -> 0 | K37: =G37+J37 -> 0
A38: 35
E39: =SUM(E3:E38) -> 72956.65 | G39: =SUM(G3:G38) -> 6980416.3 | H39: =SUM(H3:H38) -> 596.7 | J39: =SUM(J3:J38) -> 64121.382 | K39: =SUM(K4:K38) -> 7044537.7 | L39: =SUM(L3:L38) -> 6000000

Sheet Khammam-3
A1: Jayasai union bunk
A2: S.No | B2: Date | C2: GRN No | D2: Ind No/Bill No | E2: Diesel (Lts) | F2: Price | G2: Amount | H2: Petrol (Lts) | I2: Price | J2: Amount | K2: Total amount | L2: Amount paid | M2: As 0n Date | N2: Remarks
A3: Opening Balance | K3: 10291937 | M3: =+K3 -> 10291937
A4: 1 | B4: 45839 | E4: 4931.2 | F4: 95.7 | G4: =E4*F4 -> 471915.84 | H4: 55 | I4: 107.48 | J4: =H4*I4 -> 5911.4 | K4: =G4+J4 -> 477827.24 | M4: =M3+K4-L4 -> 10769764
A5: 2 | B5: 45840 | E5: 1000 | F5: 95.7 | G5: =E5*F5 -> 95700 | H5: 0 | I5: 0 | J5: =H5*I5 -> 0 | K5: =G5+J5 -> 95700 | M5: =M4+K5-L5 -> 10865464
A6: 3 | B6: 45841 | E6: 3500 | F6: 95.7 | G6: =E6*F6 -> 334950 | H6: 20 | I6: 107.48 | J6: =H6*I6 -> 2149.6 | K6: =G6+J6 -> 337099.6 | M6: =M5+K6-L6 -> 11202564
A7: 4 | B7: 45842 | E7: 1000 | F7: 95.7 | G7: =E7*F7 -> 95700 | H7: 0 | I7: 0 | J7: =H7*I7 -> 0 | K7: =G7+J7 -> 95700 | M7: =M6+K7-L7 -> 11298264
A8: 5 | B8: 45843 | E8: =2500+1000 -> 3500 | F8: 95.7 | G8: =E8*F8 -> 334950 | H8: 20 | I8: 107.48 | J8: =H8*I8 -> 2149.6 | K8: =G8+J8 -> 337099.6 | M8: =M7+K8-L8 -> 11635364
A9: 6 | B9: 45844 | E9: 1500 | F9: 95.7 | G9: =E9*F9 -> 143550 | H9: 0 | I9: 0 | J9: =H9*I9 -> 0 | K9: =G9+J9 -> 143550 | M9: =M8+K9-L9 -> 11778914
A10: 7 | B10: 45845 | E10: 3961.8 | F10: 95.7 | G10: =E10*F10 -> 379144.26 | H10: 40 | I10: 107.48 | J10: =H10*I10 -> 4299.2 | K10: =G10+J10 -> 383443.46 | M10: =M9+K10-L10 -> 12162357
A11: 8 | B11: 45846 | E11: 1500 | F11: 95.7 | G11: =E11*F11 -> 143550 | H11: 0 | I11: 0 | J11: =H11*I11 -> 0 | K11: =G11+J11 -> 143550 | M11: =M10+K11-L11 -> 12305907
A12: 9 | B12: 45847 | G12: =E12*F12 -> 0 | H12: 0 | I12: 0 | J12: =H12*I12 -> 0 | K12: =G12+J12 -> 0 | M12: =M11+K12-L12 -> 12305907
A13: 10 | B13: 45848 | E13: 2800 | F13: 95.7 | G13: =E13*F13 -> 267960 | H13: 55 | I13: 107.48 | J13: =H13*I13 -> 5911.4 | K13: =G13+J13 -> 273871.4 | M13: =M12+K13-L13 -> 12579778
A14: 11 | B14: 45849 | E14: 2700 | F14: 95.7 | G14: =E14*F14 -> 258390 | H14: 20 | I14: 107.48 | J14: =H14*I14 -> 2149.6 | K14: =G14+J14 -> 260539.6 | M14: =M13+K14-L14 -> 12840318
A15: 12 | B15: 45850 | E15: 2800 | F15: 95.7 | G15: =E15*F15 -> 267960 | H15: 20 | I15: 107.48 | J15: =H15*I15 -> 2149.6 | K15: =G15+J15 -> 270109.6 | M15: =M14+K15-L15 -> 13110428
A16: 13 | B16: 45851 | G16: =E16*F16 -> 0 | H16: 0 | I16: 0 | J16: =H16*I16 -> 0 | K16: =G16+J16 -> 0 | M16: =M15+K16-L16 -> 13110428
A17: 14 | B17: 45852 | G17: =E17*F17 -> 0 | H17: 0 | I17: 0 | J17: =H17*I17 -> 0 | K17: =G17+J17 -> 0 | M17: =M16+K17-L17 -> 13110428
A18: 15 | B18: 45853 | G18: =E18*F18 -> 0 | H18: 0 | I18: 0 | J18: =H18*I18 -> 0 | K18: =G18+J18 -> 0 | L18: 2000000 | M18: =M17+K18-L18 -> 11110428
A19: 16 | B19: 45854 | E19: 5200 | F19: 95.7 | G19: =E19*F19 -> 497640 | H19: 0 | I19: 0 | J19: =H19*I19 -> 0 | K19: =G19+J19 -> 497640 | L19: 2000000 | M19: =M18+K19-L19 -> 9608067.7
A20: 17 | B20: 45855 | G20: =E20*F20 -> 0 | H20: 0 | I20: 0 | J20: =H20*I20 -> 0 | K20: =G20+J20 -> 0 | M20: =M19+K20-L20 -> 9608067.7
A21: 18 | B21: 45856 | E21: 2700 | F21: 95.7 | G21: =E21*F21 -> 258390 | H21: 20 | I21: 107.48 | J21: =H21*I21 -> 2149.6 | K21: =G21+J21 -> 260539.6 | M21: =M20+K21-L21 -> 9868607.3
A22: 19 | B22: 45857 | E22: 2700 | F22: 95.7 | G22: =E22*F22 -> 258390 | H22: 0 | I22: 107.48 | J22: =H22*I22 -> 0 | K22: =G22+J22 -> 258390 | M22: =M21+K22-L22 -> 10126997
A23: 20 | B23: 45858 | E23: 2700 | F23: 95.7 | G23: =E23*F23 -> 258390 | H23: 35 | I23: 107.48 | J23: =H23*I23 -> 3761.8 | K23: =G23+J23 -> 262151.8 | M23: =M22+K23-L23 -> 10389149
A24: 21 | B24: 45859 | E24: 2700 | F24: 95.7 | G24: =E24*F24 -> 258390 | H24: 20 | I24: 107.48 | J24: =H24*I24 -> 2149.6 | K24: =G24+J24 -> 260539.6 | M24: =M23+K24-L24 -> 10649689
A25: 22 | B25: 45860 | E25: 2700 | F25: 95.7 | G25: =E25*F25 -> 258390 | H25: 20 | I25: 107.48 | J25: =H25*I25 -> 2149.6 | K25: =G25+J25 -> 260539.6 | M25: =M24+K25-L25 -> 10910228
A26: 23 | B26: 45861 | E26: 2000 | F26: 95.7 | G26: =E26*F26 -> 191400 | H26: 0 | I26: 0 | J26: =H26*I26 -> 0 | K26: =G26+J26 -> 191400 | M26: =M25+K26-L26 -> 11101628
A27: 24 | B27: 45862 | E27: 2000 | F27: 95.7 | G27: =E27*F27 -> 191400 | H27: 40 | I27: 107.48 | J27: =H27*I27 -> 4299.2 | K27: =G27+J27 -> 195699.2 | M27: =M26+K27-L27 -> 11297327
A28: 25 | B28: 45863 | E28: 3857.15 | F28: 95.7 | G28: =E28*F28 -> 369129.26 | H28: 20 | I28: 107.48 | J28: =H28*I28 -> 2149.6 | K28: =G28+J28 -> 371278.85 | M28: =M27+K28-L28 -> 11668606
A29: 26 | B29: 45864 | E29: =2700+1048.23 -> 3748.23 | F29: 95.7 | G29: =E29*F29 -> 358705.61 | H29: 20 | I29: 107.48 | J29: =H29*I29 -> 2149.6 | K29: =G29+J29 -> 360855.21 | M29: =M28+K29-L29 -> 12029462
A30: 27 | B30: 45865 | E30: =1500+1033.82 -> 2533.82 | F30: 95.7 | G30: =E30*F30 -> 242486.57 | H30: 20 | I30: 107.48 | J30: =H30*I30 -> 2149.6 | K30: =G30+J30 -> 244636.17 | M30: =M29+K30-L30 -> 12274098
A31: 28 | B31: 45866 | E31: 2700 | F31: 95.7 | G31: =E31*F31 -> 258390 | H31: 20 | I31: 107.48 | J31: =H31*I31 -> 2149.6 | K31: =G31+J31 -> 260539.6 | M31: =M30+K31-L31 -> 12534637
A32: 29 | B32: 45867 | E32: 1347.45 | F32: 95.7 | G32: =E32*F32 -> 128950.97 | H32: 0 | I32: 0 | J32: =H32*I32 -> 0 | K32: =G32+J32 -> 128950.97 | M32: =M31+K32-L32 -> 12663588
A33: 30 | B33: 45868 | G33: =E33*F33 -> 0 | H33: 0 | I33: 0 | J33: =H33*I33 -> 0 | K33: =G33+J33 -> 0 | M33: =M32+K33-L33 -> 12663588
A34: 31 | G34: =E34*F34 -> 0 | H34: 0 | I34: 0 | J34: =H34*I34 -> 0 | K34: =G34+J34 -> 0 | M34: =M33+K34-L34 -> 12663588
E35: =SUM(E4:E34) -> 66079.65 | G35: =SUM(G4:G34) -> 6323822.5 | H35: =SUM(H4:H34) -> 445 | J35: =SUM(J4:J34) -> 47828.6 | K35: =SUM(K4:K34) -> 6371651.1 | L35: =SUM(L4:L34) -> 4000000

Sheet Jedcherla -1
A1: Sai Baba Fuel Station
A2: S.No | B2: Date | C2: GRN No | D2: Ind No/Bill No | E2: Diesel (Lts) | F2: Price | G2: Amount | H2: Petrol (Lts) | I2: Price | J2: Amount | K2: Total amount | L2: Amount paid | M2: As on date | N2: Remarks
A3: Opening Balance | M3: 2139146.2
A4: 1 | B4: 45839 | E4: 0 | F4: 0 | G4: 0 | H4: 15 | I4: 108.23 | J4: =H4*I4 -> 1623.45 | K4: =G4+J4 -> 1623.45 | L4: 0 | M4: =M3+K4-L4 -> 2140769.6 | P4: 2259050
A5: 2 | B5: 45840 | E5: 4025 | F5: 96.42 | G5: =E5*F5 -> 388090.5 | H5: 29.62 | I5: 108.23 | J5: =H5*I5 -> 3205.7726 | K5: =G5+J5 -> 391296.27 | L5: 0 | M5: =M4+K5-L5 -> 2532065.9
A6: 3 | B6: 45841 | E6: 0 | F6: 0 | G6: =E6*F6 -> 0 | H6: 20 | I6: 108.23 | J6: =H6*I6 -> 2164.6 | K6: =G6+J6 -> 2164.6 | L6: 0 | M6: =M5+K6-L6 -> 2534230.5
A7: 4 | B7: 45842 | E7: 0 | F7: 0 | G7: =E7*F7 -> 0 | H7: 10 | I7: 108.23 | J7: =H7*I7 -> 1082.3 | K7: =G7+J7 -> 1082.3 | L7: 0 | M7: =M6+K7-L7 -> 2535312.8
A8: 5 | B8: 45843 | E8: 0 | F8: 0 | G8: =E8*F8 -> 0 | H8: 18 | I8: 108.23 | J8: =H8*I8 -> 1948.14 | K8: =G8+J8 -> 1948.14 | L8: 0 | M8: =M7+K8-L8 -> 2537261
A9: 6 | B9: 45844 | D9: 30 | E9: 30 | F9: 96.42 | G9: =E9*F9 -> 2892.6 | H9: 27 | I9: 108.23 | J9: =H9*I9 -> 2922.21 | K9: =G9+J9 -> 5814.81 | L9: 0 | M9: =M8+K9-L9 -> 2543075.8
A10: 7 | B10: 45845 | E10: 0 | F10: 0 | G10: =E10*F10 -> 0 | H10: 10 | I10: 108.23 | J10: =H10*I10 -> 1082.3 | K10: =G10+J10 -> 1082.3 | L10: 0 | M10: =M9+K10-L10 -> 2544158.1 | P10: =1619072*96.42 -> 1.5611092e+08
A11: 8 | B11: 45846 | E11: 0 | F11: 0 | G11: =E11*F11 -> 0 | H11: 15 | I11: 108.23 | J11: =H11*I11 -> 1623.45 | K11: =G11+J11 -> 1623.45 | L11: 0 | M11: =M10+K11-L11 -> 2545781.5
A12: 9 | B12: 45847 | E12: 0 | F12: 0 | G12: =E12*F12 -> 0 | H12: 15 | I12: 108.23 | J12: =H12*I12 -> 1623.45 | K12: =G12+J12 -> 1623.45 | L12: 0 | M12: =M11+K12-L12 -> 2547405
A13: 10 | B13: 45848 | E13: 20.74 | F13: 96.42 | G13: =E13*F13 -> 1999.7508 | H13: 30 | I13: 108.23 | J13: =H13*I13 -> 3246.9 | K13: =G13+J13 -> 5246.6508 | L13: 0 | M13: =M12+K13-L13 -> 2552651.6
A14: 11 | B14: 45849 | E14: 124.35 | F14: 96.42 | G14: =E14*F14 -> 11989.827 | H14: 10 | I14: 108.23 | J14: =H14*I14 -> 1082.3 | K14: =G14+J14 -> 13072.127 | L14: 0 | M14: =M13+K14-L14 -> 2565723.7
A15: 12 | B15: 45850 | E15: 0 | F15: 0 | G15: =E15*F15 -> 0 | H15: 14 | I15: 108.23 | J15: =H15*I15 -> 1515.22 | K15: =G15+J15 -> 1515.22 | L15: 0 | M15: =M14+K15-L15 -> 2567239
A16: 13 | B16: 45851 | E16: 0 | F16: 0 | G16: =E16*F16 -> 0 | H16: 15 | I16: 108.23 | J16: =H16*I16 -> 1623.45 | K16: =G16+J16 -> 1623.45 | L16: 0 | M16: =M15+K16-L16 -> 2568862.4
A17: 14 | B17: 45852 | E17: 34.74 | F17: 96.42 | G17: =E17*F17 -> 3349.6308 | H17: 20 | I17: 108.23 | J17: =H17*I17 -> 2164.6 | K17: =G17+J17 -> 5514.2308 | L17: 0 | M17: =M16+K17-L17 -> 2574376.6
A18: 15 | B18: 45853 | E18: 36.09 | F18: 96.42 | G18: =E18*F18 -> 3479.7978 | H18: 20 | I18: 108.23 | J18: =H18*I18 -> 2164.6 | K18: =G18+J18 -> 5644.3978 | L18: 1500000 | M18: =M17+K18-L18 -> 1080021
A19: 16 | B19: 45854 | E19: 0 | F19: 0 | G19: =E19*F19 -> 0 | H19: 20 | I19: 108.23 | J19: =H19*I19 -> 2164.6 | K19: =G19+J19 -> 2164.6 | L19: 0 | M19: =M18+K19-L19 -> 1082185.6
A20: 17 | B20: 45855 | E20: 2000 | F20: 96.42 | G20: =E20*F20 -> 192840 | H20: 5 | I20: 108.23 | J20: =H20*I20 -> 541.15 | K20: =G20+J20 -> 193381.15 | L20: 0 | M20: =M19+K20-L20 -> 1275566.8
A21: 18 | B21: 45856 | E21: 0 | F21: 0 | G21: =E21*F21 -> 0 | H21: 10 | I21: 108.23 | J21: =H21*I21 -> 1082.3 | K21: =G21+J21 -> 1082.3 | L21: 0 | M21: =M20+K21-L21 -> 1276649.1
A22: 19 | B22: 45857 | E22: 2000 | F22: 96.42 | G22: =E22*F22 -> 192840 | H22: 40 | I22: 108.23 | J22: =H22*I22 -> 4329.2 | K22: =G22+J22 -> 197169.2 | L22: 0 | M22: =M21+K22-L22 -> 1473818.3 | P22: 2422641
A23: 20 | B23: 45858 | E23: 0 | F23: 0 | G23: =E23*F23 -> 0 | H23: 5 | I23: 108.23 | J23: =H23*I23 -> 541.15 | K23: =G23+J23 -> 541.15 | L23: 0 | M23: =M22+K23-L23 -> 1474359.4 | P23: 2419549
A24: 21 | B24: 45859 | E24: 0 | F24: 0 | G24: =E24*F24 -> 0 | H24: 5 | I24: 108.23 | J24: =H24*I24 -> 541.15 | K24: =G24+J24 -> 541.15 | L24: 0 | M24: =M23+K24-L24 -> 1474900.6 | P24: =P23-P22 -> -3092
A25: 22 | B25: 45860 | E25: 44 | F25: 96.42 | G25: =E25*F25 -> 4242.48 | H25: 35 | I25: 108.23 | J25: =H25*I25 -> 3788.05 | K25: =G25+J25 -> 8030.53 | L25: 0 | M25: =M24+K25-L25 -> 1482931.1
A26: 23 | B26: 45861 | E26: 31 | F26: 96.42 | G26: =E26*F26 -> 2989.02 | H26: 10 | I26: 108.23 | J26: =H26*I26 -> 1082.3 | K26: =G26+J26 -> 4071.32 | L26: 0 | M26: =M25+K26-L26 -> 1487002.4
A27: 24 | B27: 45862 | E27: 35.19 | F27: 96.42 | G27: =E27*F27 -> 3393.0198 | H27: 25 | I27: 108.23 | J27: =H27*I27 -> 2705.75 | K27: =G27+J27 -> 6098.7698 | L27: 0 | M27: =M26+K27-L27 -> 1493101.2
A28: 25 | B28: 45863 | E28: 0 | F28: 0 | G28: =E28*F28 -> 0 | H28: 15 | I28: 108.23 | J28: =H28*I28 -> 1623.45 | K28: =G28+J28 -> 1623.45 | L28: 0 | M28: =M27+K28-L28 -> 1494724.7
A29: 26 | B29: 45864 | E29: 0 | F29: 0 | G29: =E29*F29 -> 0 | H29: 0 | I29: 0 | J29: =H29*I29 -> 0 | K29: =G29+J29 -> 0 | L29: 0 | M29: =M28+K29-L29 -> 1494724.7
A30: 27 | B30: 45865 | E30: 0 | F30: 0 | G30: =E30*F30 -> 0 | H30: 5 | I30: 108.23 | J30: =H30*I30 -> 541.15 | K30: =G30+J30 -> 541.15 | L30: 0 | M30: =M29+K30-L30 -> 1495265.8
A31: 28 | B31: 45866 | E31: 2500 | F31: 96.42 | G31: =E31*F31 -> 241050 | H31: 25 | I31: 108.23 | J31: =H31*I31 -> 2705.75 | K31: =G31+J31 -> 243755.75 | L31: 0 | M31: =M30+K31-L31 -> 1739021.6
A32: 29 | B32: 45867 | E32: 1622.54 | F32: 96.42 | G32: =E32*F32 -> 156445.31 | H32: 25 | I32: 108.23 | J32: =H32*I32 -> 2705.75 | K32: =G32+J32 -> 159151.06 | L32: 0 | M32: =M31+K32-L32 -> 1898172.6
A33: 30 | B33: 45868 | E33: 2000 | F33: 96.42 | G33: =E33*F33 -> 192840 | H33: 20 | I33: 108.23 | J33: =H33*I33 -> 2164.6 | K33: =G33+J33 -> 195004.6 | L33: 0 | M33: =M32+K33-L33 -> 2093177.2 | O33: 2085613 | P33: =M33-O33 -> 7564.2185
A34: 31 | B34: 45869 | E34: 2500 | F34: 96.42 | G34: =E34*F34 -> 241050 | H34: 35 | I34: 108.23 | J34: =H34*I34 -> 3788.05 | K34: =G34+J34 -> 244838.05 | L34: 950000 | M34: =M33+K34-L34 -> 1388015.3
E35: 0 | F35: 0 | G35: =E35*F35 -> 0 | H35: 0 | I35: 0 | J35: =H35*I35 -> 0 | K35: =G35+J35 -> 0 | M35: =M34+K35-L35 -> 1388015.3
E36: =SUM(E4:E34) -> 17003.65 | G36: =SUM(G4:G34) -> 1639491.9 | H36: =SUM(H4:H34) -> 548.62 | J36: =SUM(J4:J34) -> 59377.143 | K36: =SUM(K4:K34) -> 1698869.1 | L36: =SUM(L4:L34) -> 2450000
E38: 16973.46
E40: =E36-E38 -> 30.19

Sheet Jedcharla-3
A1: ADHOC FILLING STATION STATION
A2: S.No | B2: Date | C2: GRN No | D2: Ind No/Bill No | E2: Diesel (Lts) | F2: Price | G2: Amount | H2: Petrol (Lts) | I2: Price | J2: Amount | K2: Total amount | L2: Amount paid | M2: As on Date | N2: Remarks
A3: Opening Balance | K3: 1209626.7 | M3: =+K3 -> 1209626.7
A4: 1 | B4: 45839 | E4: 1640 | F4: 96.43 | G4: =E4*F4 -> 158145.2 | J4: =H4*I4 -> 0 | K4: =G4+J4 -> 158145.2 | M4: =M3+K4-L4 -> 1367771.9
A5: 2 | B5: 45840 | E5: 0 | F5: 0 | G5: =E5*F5 -> 0 | J5: =H5*I5 -> 0 | K5: =G5+J5 -> 0 | M5: =M4+K5-L5 -> 1367771.9
A6: 3 | B6: 45841 | E6: 2400 | F6: 96.43 | G6: =E6*F6 -> 231432 | J6: =H6*I6 -> 0 | K6: =G6+J6 -> 231432 | M6: =M5+K6-L6 -> 1599203.9 | R6: 541.08
A7: 4 | B7: 45842 | E7: 2000 | F7: 96.43 | G7: =E7*F7 -> 192860 | J7: =H7*I7 -> 0 | K7: =G7+J7 -> 192860 | M7: =M6+K7-L7 -> 1792063.9
A8: 5 | B8: 45843 | E8: 2300 | F8: 96.43 | G8: =E8*F8 -> 221789 | J8: =H8*I8 -> 0 | K8: =G8+J8 -> 221789 | M8: =M7+K8-L8 -> 2013852.9
A9: 6 | B9: 45844 | E9: 2200 | F9: 96.43 | G9: =E9*F9 -> 212146 | J9: =H9*I9 -> 0 | K9: =G9+J9 -> 212146 | M9: =M8+K9-L9 -> 2225998.9
A10: 7 | B10: 45845 | E10: 3400 | F10: 96.43 | G10: =E10*F10 -> 327862 | J10: =H10*I10 -> 0 | K10: =G10+J10 -> 327862 | M10: =M9+K10-L10 -> 2553860.9
A11: 8 | B11: 45846 | E11: 2300 | F11: 96.43 | G11: =E11*F11 -> 221789 | J11: =H11*I11 -> 0 | K11: =G11+J11 -> 221789 | M11: =M10+K11-L11 -> 2775649.9
A12: 9 | B12: 45847 | E12: 3300 | F12: 96.43 | G12: =E12*F12 -> 318219 | J12: =H12*I12 -> 0 | K12: =G12+J12 -> 318219 | M12: =M11+K12-L12 -> 3093868.9
A13: 10 | B13: 45848 | E13: 2500 | F13: 96.43 | G13: =E13*F13 -> 241075 | J13: =H13*I13 -> 0 | K13: =G13+J13 -> 241075 | M13: =M12+K13-L13 -> 3334943.9
A14: 11 | B14: 45849 | E14: 3900 | F14: 96.43 | G14: =E14*F14 -> 376077 | J14: =H14*I14 -> 0 | K14: =G14+J14 -> 376077 | M14: =M13+K14-L14 -> 3711020.9
A15: 12 | B15: 45850 | E15: 4374.39 | F15: 96.43 | G15: =E15*F15 -> 421822.43 | J15: =H15*I15 -> 0 | K15: =G15+J15 -> 421822.43 | M15: =M14+K15-L15 -> 4132843.4
A16: 13 | B16: 45851 | E16: 0 | F16: 0 | G16: =E16*F16 -> 0 | J16: =H16*I16 -> 0 | K16: =G16+J16 -> 0 | M16: =M15+K16-L16 -> 4132843.4
A17: 14 | B17: 45852 | E17: 2000 | F17: 96.43 | G17: =E17*F17 -> 192860 | J17: =H17*I17 -> 0 | K17: =G17+J17 -> 192860 | L17: 400000 | M17: =M16+K17-L17 -> 3925703.4
A18: 15 | B18: 45853 | E18: 2500 | F18: 96.43 | G18: =E18*F18 -> 241075 | J18: =H18*I18 -> 0 | K18: =G18+J18 -> 241075 | L18: 2400000 | M18: =M17+K18-L18 -> 1766778.4
A19: 16 | B19: 45854 | E19: 4600 | F19: 96.43 | G19: =E19*F19 -> 443578 | J19: =H19*I19 -> 0 | K19: =G19+J19 -> 443578 | M19: =M18+K19-L19 -> 2210356.4
A20: 17 | B20: 45855 | E20: 0 | F20: 0 | G20: =E20*F20 -> 0 | J20: =H20*I20 -> 0 | K20: =G20+J20 -> 0 | M20: =M19+K20-L20 -> 2210356.4
A21: 18 | B21: 45856 | E21: 2424 | F21: 96.43 | G21: =E21*F21 -> 233746.32 | J21: =H21*I21 -> 0 | K21: =G21+J21 -> 233746.32 | M21: =M20+K21-L21 -> 2444102.7
A22: 19 | B22: 45857 | E22: 0 | F22: 0 | G22: =E22*F22 -> 0 | J22: =H22*I22 -> 0 | K22: =G22+J22 -> 0 | M22: =M21+K22-L22 -> 2444102.7
A23: 20 | B23: 45858 | E23: 1918.96 | F23: 96.43 | G23: =E23*F23 -> 185045.31 | J23: =H23*I23 -> 0 | K23: =G23+J23 -> 185045.31 | M23: =M22+K23-L23 -> 2629148
A24: 21 | B24: 45859 | E24: 1500.12 | F24: 96.43 | G24: =E24*F24 -> 144656.57 | J24: =H24*I24 -> 0 | K24: =G24+J24 -> 144656.57 | M24: =M23+K24-L24 -> 2773804.6
A25: 22 | B25: 45860 | E25: 2300 | F25: 96.43 | G25: =E25*F25 -> 221789 | J25: =H25*I25 -> 0 | K25: =G25+J25 -> 221789 | M25: =M24+K25-L25 -> 2995593.6
A26: 23 | B26: 45861 | E26: 2000 | F26: 96.43 | G26: =E26*F26 -> 192860 | J26: =H26*I26 -> 0 | K26: =G26+J26 -> 192860 | M26: =M25+K26-L26 -> 3188453.6
A27: 24 | B27: 45862 | E27: 1000 | F27: 96.43 | G27: =E27*F27 -> 96430 | J27: =H27*I27 -> 0 | K27: =G27+J27 -> 96430 | M27: =M26+K27-L27 -> 3284883.6
A28: 25 | B28: 45863 | E28: 1200 | F28: 96.43 | G28: =E28*F28 -> 115716 | J28: =H28*I28 -> 0 | K28: =G28+J28 -> 115716 | M28: =M27+K28-L28 -> 3400599.6
A29: 26 | B29: 45864 | E29: 0 | F29: 0 | G29: =E29*F29 -> 0 | J29: =H29*I29 -> 0 | K29: =G29+J29 -> 0 | L29: 1500000 | M29: =M28+K29-L29 -> 1900599.6
A30: 27 | B30: 45865 | E30: 0 | F30: 0 | G30: =E30*F30 -> 0 | J30: =H30*I30 -> 0 | K30: =G30+J30 -> 0 | M30: =M29+K30-L30 -> 1900599.6
A31: 28 | B31: 45866 | E31: 0 | F31: 0 | G31: =E31*F31 -> 0 | J31: =H31*I31 -> 0 | K31: =G31+J31 -> 0 | M31: =M30+K31-L31 -> 1900599.6
A32: 29 | B32: 45867 | E32: 0 | F32: 0 | G32: =E32*F32 -> 0 | J32: =H32*I32 -> 0 | K32: =G32+J32 -> 0 | M32: =M31+K32-L32 -> 1900599.6
A33: 30 | B33: 45868 | E33: 0 | F33: 0 | G33: =E33*F33 -> 0 | J33: =H33*I33 -> 0 | K33: =G33+J33 -> 0 | M33: =M32+K33-L33 -> 1900599.6
A34: 31 | B34: 45869 | G34: =E34*F34 -> 0 | J34: =H34*I34 -> 0 | K34: =G34+J34 -> 0 | L34: 500000 | M34: =M33+K34-L34 -> 1400599.6 | O34: 1688453.6 | P34: 1900671 | Q34: =P34-O34 -> 212217.42
E35: =SUM(E4:E34) -> 51757.47 | G35: =SUM(G4:G34) -> 4990972.8 | H35: =SUM(H4:H34) -> 0 | J35: =SUM(J4:J34) -> 0 | K35: =SUM(K4:K34) -> 4990972.8 | L35: =SUM(L4:L34) -> 4800000

Sheet Sangareddy
A1: Sree Shiva Parvathi Filling Station
A2: S.No | B2: Date | C2: GRN No | D2: Ind No/Bill No | E2: Diesel (Lts) | F2: Price | G2: Amount | H2: Petrol (Lts) | I2: Price | J2: Amount | K2: Total amount | L2: Amount paid | M2: As on Date | N2: Remarks
A3: Opening Balance | K3: 362536.8 | M3: =+K3 -> 362536.8
A4: 1 | B4: 45839 | E4: 0 | F4: 0 | G4: =E4*F4 -> 0 | H4: 0 | I4: 0 | J4: =H4*I4 -> 0 | K4: =G4+J4 -> 0 | M4: =M3+K4-L4 -> 362536.8
A5: 2 | B5: 45840 | E5: 0 | F5: 0 | G5: =E5*F5 -> 0 | H5: 0 | I5: 0 | J5: =H5*I5 -> 0 | K5: =G5+J5 -> 0 | M5: =M4+K5-L5 -> 362536.8
A6: 3 | B6: 45841 | E6: 0 | F6: 0 | G6: =E6*F6 -> 0 | H6: 0 | I6: 0 | J6: =H6*I6 -> 0 | K6: =G6+J6 -> 0 | M6: =M5+K6-L6 -> 362536.8
B7: 45842 | E7: 0 | F7: 0 | G7: =E7*F7 -> 0 | H7: 0 | I7: 0 | J7: =H7*I7 -> 0 | K7: =G7+J7 -> 0 | M7: =M6+K7-L7 -> 362536.8
A8: 4 | B8: 45843 | E8: 0 | F8: 0 | G8: =E8*F8 -> 0 | H8: 0 | I8: 0 | J8: =H8*I8 -> 0 | K8: =G8+J8 -> 0 | M8: =M7+K8-L8 -> 362536.8
A9: 5 | B9: 45844 | E9: 0 | F9: 0 | G9: =E9*F9 -> 0 | H9: 0 | I9: 0 | J9: =H9*I9 -> 0 | K9: =G9+J9 -> 0 | M9: =M8+K9-L9 -> 362536.8
A10: 6 | B10: 45845 | E10: 0 | F10: 0 | G10: =E10*F10 -> 0 | H10: 0 | I10: 0 | J10: =H10*I10 -> 0 | K10: =G10+J10 -> 0 | M10: =M9+K10-L10 -> 362536.8
A11: 7 | B11: 45846 | E11: 0 | F11: 0 | G11: =E11*F11 -> 0 | H11: 20 | I11: 0 | J11: =H11*I11 -> 0 | K11: =G11+J11 -> 0 | M11: =M10+K11-L11 -> 362536.8
A12: 8 | B12: 45847 | E12: 0 | F12: 0 | G12: =E12*F12 -> 0 | H12: 0 | I12: 0 | J12: =H12*I12 -> 0 | K12: =G12+J12 -> 0 | M12: =M11+K12-L12 -> 362536.8
A13: 9 | B13: 45848 | E13: 0 | F13: 0 | G13: =E13*F13 -> 0 | H13: 0 | I13: 0 | J13: =H13*I13 -> 0 | K13: =G13+J13 -> 0 | M13: =M12+K13-L13 -> 362536.8
A14: 10 | B14: 45849 | E14: 0 | F14: 0 | G14: =E14*F14 -> 0 | H14: 0 | I14: 0 | J14: =H14*I14 -> 0 | K14: =G14+J14 -> 0 | M14: =M13+K14-L14 -> 362536.8
A15: 11 | B15: 45850 | E15: 0 | F15: 0 | G15: =E15*F15 -> 0 | H15: 20 | I15: 0 | J15: =H15*I15 -> 0 | K15: =G15+J15 -> 0 | M15: =M14+K15-L15 -> 362536.8
A16: 12 | B16: 45851 | E16: 0 | F16: 0 | G16: =E16*F16 -> 0 | H16: 0 | I16: 0 | J16: =H16*I16 -> 0 | K16: =G16+J16 -> 0 | M16: =M15+K16-L16 -> 362536.8
A17: 13 | B17: 45852 | E17: 0 | F17: 0 | G17: =E17*F17 -> 0 | H17: 0 | I17: 0 | J17: =H17*I17 -> 0 | K17: =G17+J17 -> 0 | M17: =M16+K17-L17 -> 362536.8
A18: 14 | B18: 45853 | E18: 0 | F18: 0 | G18: =E18*F18 -> 0 | H18: 0 | I18: 0 | J18: =H18*I18 -> 0 | K18: =G18+J18 -> 0 | L18: 362532 | M18: =M17+K18-L18 -> 4.8
A19: 15 | B19: 45854 | E19: 0 | F19: 0 | G19: =E19*F19 -> 0 | H19: 20 | I19: 0 | J19: =H19*I19 -> 0 | K19: =G19+J19 -> 0 | L19: 4.8 | M19: =M18+K19-L19 -> 4.6566306e-11
A20: 16 | B20: 45855 | E20: 0 | F20: 0 | G20: =E20*F20 -> 0 | H20: 0 | I20: 0 | J20: =H20*I20 -> 0 | K20: =G20+J20 -> 0 | M20: =M19+K20-L20 -> 4.6566306e-11
A21: 17 | B21: 45856 | E21: 0 | F21: 0 | G21: =E21*F21 -> 0 | H21: 0 | I21: 0 | J21: =H21*I21 -> 0 | K21: =G21+J21 -> 0 | M21: =M20+K21-L21 -> 4.6566306e-11
A22: 18 | B22: 45857 | E22: 0 | F22: 0 | G22: =E22*F22 -> 0 | H22: 20 | I22: 0 | J22: =H22*I22 -> 0 | K22: =G22+J22 -> 0 | M22: =M21+K22-L22 -> 4.6566306e-11
A23: 19 | B23: 45858 | E23: 0 | F23: 0 | G23: =E23*F23 -> 0 | H23: 0 | I23: 0 | J23: =H23*I23 -> 0 | K23: =G23+J23 -> 0 | M23: =M22+K23-L23 -> 4.6566306e-11
A24: 20 | B24: 45859 | E24: 0 | F24: 0 | G24: =E24*F24 -> 0 | H24: 20 | I24: 0 | J24: =H24*I24 -> 0 | K24: =G24+J24 -> 0 | M24: =M23+K24-L24 -> 4.6566306e-11
A25: 21 | B25: 45860 | E25: 0 | F25: 0 | G25: =E25*F25 -> 0 | H25: 0 | I25: 0 | J25: =H25*I25 -> 0 | K25: =G25+J25 -> 0 | M25: =M24+K25-L25 -> 4.6566306e-11
A26: 22 | B26: 45861 | E26: 0 | F26: 0 | G26: =E26*F26 -> 0 | H26: 0 | I26: 0 | J26: =H26*I26 -> 0 | K26: =G26+J26 -> 0 | M26: =M25+K26-L26 -> 4.6566306e-11
A27: 23 | B27: 45862 | E27: 0 | F27: 0 | G27: =E27*F27 -> 0 | H27: 0 | I27: 0 | J27: =H27*I27 -> 0 | K27: =G27+J27 -> 0 | M27: =M26+K27-L27 -> 4.6566306e-11
A28: 24 | B28: 45863 | E28: 0 | F28: 0 | G28: =E28*F28 -> 0 | H28: 0 | I28: 0 | J28: =H28*I28 -> 0 | K28: =G28+J28 -> 0 | M28: =M27+K28-L28 -> 4.6566306e-11
A29: 25 | B29: 45864 | E29: 0 | F29: 0 | G29: =E29*F29 -> 0 | H29: 0 | I29: 0 | J29: =H29*I29 -> 0 | K29: =G29+J29 -> 0 | M29: =M28+K29-L29 -> 4.6566306e-11
A30: 26 | B30: 45865 | E30: 0 | F30: 0 | G30: =E30*F30 -> 0 | H30: 0 | I30: 0 | J30: =H30*I30 -> 0 | K30: =G30+J30 -> 0 | M30: =M29+K30-L30 -> 4.6566306e-11
A31: 27 | B31: 45866 | E31: 0 | F31: 0 | G31: =E31*F31 -> 0 | H31: 0 | I31: 0 | J31: =H31*I31 -> 0 | K31: =G31+J31 -> 0 | M31: =M30+K31-L31 -> 4.6566306e-11
... A39: 35 | B39: 45874 | E39: 0 | F39: 0 | G39: =E39*F39 -> 0 | H39: 0 | I39: 0 | J39: =H39*I39 -> 0 | K39: =G39+J39 -> 0 | M39: =M38+K39-L39 -> 4.6566306e-11
E40: =SUM(E4:E39) -> 0 | G40: =SUM(G4:G39) -> 0 | H40: =SUM(H4:H39) -> 120 | J40: =SUM(J4:J39) -> 0 | K40: =SUM(K4:K39) -> 0 | L40: =SUM(L4:L39) -> 362536.8

Sheet Dindi
A1: Akarapu Balakistamma Fillling
A2: S.No | B2: Date | C2: GRN No | D2: Ind no/Bill No | E2: Diesel (Lts) | F2: Price | G2: Amount | H2: Petrol (Lts) | I2: Price | J2: Amount | K2: Total amount | L2: Amount paid | M2: As on Date | N2: Remarks
A3: Opening Balance | M3: 0
A4: 1 | B4: 45839 | E4: 0 | F4: 0 | G4: =E4*F4 -> 0 | H4: 0 | I4: 0 | J4: =H4*I4 -> 0 | K4: =G4+J4 -> 0 | L4: =+K4 -> 0 | M4: 0
A5: 2 | B5: 45840 | E5: 42.74 | F5: 96.83 | G5: =E5*F5 -> 4138.5142 | H5: 0 | I5: 0 | J5: =H5*I5 -> 0 | K5: =G5+J5 -> 4138.5142 | L5: =+K5 -> 4138.5142 | M5: 0
A6: 3 | B6: 45841 | E6: 0 | F6: 0 | G6: =E6*F6 -> 0 | H6: 0 | I6: 0 | J6: =H6*I6 -> 0 | K6: =G6+J6 -> 0 | L6: =+K6 -> 0 | M6: 0
A7: 4 | B7: 45842 | E7: 0 | F7: 0 | G7: =E7*F7 -> 0 | H7: 0 | I7: 0 | J7: =H7*I7 -> 0 | K7: =G7+J7 -> 0 | L7: =+K7 -> 0 | M7: 0
A8: 5 | B8: 45843 | E8: 0 | F8: 0 | G8: =E8*F8 -> 0 | H8: 0 | I8: 0 | J8: =H8*I8 -> 0 | K8: =G8+J8 -> 0 | L8: =+K8 -> 0 | M8: 0
A9: 6 | B9: 45844 | E9: 0 | F9: 0 | G9: =E9*F9 -> 0 | H9: 0 | I9: 0 | J9: =H9*I9 -> 0 | K9: =G9+J9 -> 0 | L9: =+K9 -> 0 | M9: 0
A10: 7 | B10: 45845 | E10: 0 | F10: 0 | G10: =E10*F10 -> 0 | H10: 0 | I10: 0 | J10: =H10*I10 -> 0 | K10: =G10+J10 -> 0 | L10: =+K10 -> 0 | M10: 0
A11: 8 | B11: 45846 | E11: 0 | F11: 0 | G11: =E11*F11 -> 0 | H11: 0 | I11: 0 | J11: =H11*I11 -> 0 | K11: =G11+J11 -> 0 | L11: =+K11 -> 0 | M11: 0
A12: 9 | B12: 45847 | E12: 0 | F12: 0 | G12: =E12*F12 -> 0 | H12: 0 | I12: 0 | J12: =H12*I12 -> 0 | K12: =G12+J12 -> 0 | L12: =+K12 -> 0 | M12: 0
A13: 10 | B13: 45848 | E13: 0 | F13: 0 | G13: =E13*F13 -> 0 | H13: 0 | I13: 0 | J13: =H13*I13 -> 0 | K13: =G13+J13 -> 0 | L13: =+K13 -> 0 | M13: 0
A14: 11 | B14: 45849 | E14: 0 | F14: 0 | G14: =E14*F14 -> 0 | H14: 0 | I14: 0 | J14: =H14*I14 -> 0 | K14: =G14+J14 -> 0 | L14: =+K14 -> 0 | M14: 0
A15: 12 | B15: 45850 | E15: 0 | F15: 0 | G15: =E15*F15 -> 0 | H15: 0 | I15: 0 | J15: =H15*I15 -> 0 | K15: =G15+J15 -> 0 | L15: =+K15 -> 0 | M15: 0
... A33: 30 | B33: 45868 | E33: 0 | F33: 0 | G33: =E33*F33 -> 0 | H33: 0 | I33: 0 | J33: =H33*I33 -> 0 | K33: =G33+J33 -> 0 | L33: =+K33 -> 0 | M33: 0
A34: 31 | E34: 0 | F34: 0 | G34: =E34*F34 -> 0 | H34: 0 | I34: 0 | J34: =H34*I34 -> 0 | K34: =G34+J34 -> 0 | L34: =+K34 -> 0 | M34: 0
E35: =SUM(E4:E34) -> 117.57 | G35: =SUM(G4:G34) -> 11384.303 | H35: =SUM(H4:H34) -> 5.52 | J35: =SUM(J4:J34) -> 599.8032 | K35: =SUM(K4:K34) -> 11984.106 | L35: =SUM(L4:L34) -> 11984.106

Sheet Devarakhadra
A1: Kurumurthy Swami F/S
A2: S.No | B2: Date | C2: GRN No | D2: Ind no/Bill No | E2: Diesel (Lts) | F2: Price | G2: Amount | H2: Petrol (Lts) | I2: Price | J2: Amount | K2: Total amount | L2: Amount paid | M2: As on Date | N2: Remarks
A3: Opening Balance | M3: 169047.22
A4: 1 | B4: 45839 | E4: 200 | F4: 97.1 | G4: =E4*F4 -> 19420 | H4: 0 | I4: 0 | J4: =H4*I4 -> 0 | K4: =G4+J4 -> 19420 | L4: 0 | M4: =+M3+K4-L4 -> 188467.22
A5: 2 | B5: 45840 | E5: 0 | F5: 0 | G5: =E5*F5 -> 0 | H5: 0 | I5: 0 | J5: =H5*I5 -> 0 | K5: =G5+J5 -> 0 | L5: 169047 | M5: =+M4+K5-L5 -> 19420.216
A6: 3 | B6: 45841 | E6: 242.14 | F6: 97.1 | G6: =E6*F6 -> 23511.794 | H6: 0 | I6: 0 | J6: =H6*I6 -> 0 | K6: =G6+J6 -> 23511.794 | L6: 0 | M6: =+M5+K6-L6 -> 42932.01
A7: 4 | B7: 45842 | E7: 200 | F7: 97.1 | G7: =E7*F7 -> 19420 | H7: 0 | I7: 0 | J7: =H7*I7 -> 0 | K7: =G7+J7 -> 19420 | L7: 0 | M7: =+M6+K7-L7 -> 62352.01
A8: 5 | B8: 45843 | E8: 197.84 | F8: 97.1 | G8: =E8*F8 -> 19210.264 | H8: 0 | I8: 0 | J8: =H8*I8 -> 0 | K8: =G8+J8 -> 19210.264 | L8: 0 | M8: =+M7+K8-L8 -> 81562.274
A9: 6 | B9: 45844 | E9: 400 | F9: 97.1 | G9: =E9*F9 -> 38840 | H9: 0 | I9: 0 | J9: =H9*I9 -> 0 | K9: =G9+J9 -> 38840 | L9: 0 | M9: =+M8+K9-L9 -> 120402.27
A10: 7 | B10: 45845 | E10: 0 | F10: 0 | G10: =E10*F10 -> 0 | H10: 0 | I10: 0 | J10: =H10*I10 -> 0 | K10: =G10+J10 -> 0 | L10: =+K10 -> 0 | M10: =+M9+K10-L10 -> 120402.27
A11: 8 | B11: 45846 | E11: 100 | F11: 97.1 | G11: =E11*F11 -> 9710 | H11: 5 | I11: 108.83 | J11: =H11*I11 -> 544.15 | K11: =G11+J11 -> 10254.15 | L11: 0 | M11: =+M10+K11-L11 -> 130656.42
A12: 9 | B12: 45847 | E12: 598.19 | F12: 97.1 | G12: =E12*F12 -> 58084.249 | H12: 5 | I12: 108.83 | J12: =H12*I12 -> 544.15 | K12: =G12+J12 -> 58628.399 | L12: 0 | M12: =+M11+K12-L12 -> 189284.82
A13: 10 | B13: 45848 | E13: 580 | F13: 97.1 | G13: =E13*F13 -> 56318 | H13: 0 | I13: 0 | J13: =H13*I13 -> 0 | K13: =G13+J13 -> 56318 | L13: 0 | M13: =+M12+K13-L13 -> 245602.82
A14: 11 | B14: 45849 | E14: 790 | F14: 97.1 | G14: =E14*F14 -> 76709 | H14: 0 | I14: 0 | J14: =H14*I14 -> 0 | K14: =G14+J14 -> 76709 | L14: 0 | M14: =+M13+K14-L14 -> 322311.82
A15: 12 | B15: 45850 | E15: 400 | F15: 97.1 | G15: =E15*F15 -> 38840 | H15: 5 | I15: 108.83 | J15: =H15*I15 -> 544.15 | K15: =G15+J15 -> 39384.15 | L15: 0 | M15: =+M14+K15-L15 -> 361695.97
A16: 13 | B16: 45851 | E16: 642.55 | F16: 97.1 | G16: =E16*F16 -> 62391.605 | H16: 0 | I16: 0 | J16: =H16*I16 -> 0 | K16: =G16+J16 -> 62391.605 | L16: 0 | M16: =+M15+K16-L16 -> 424087.58
A17: 14 | B17: 45852 | E17: =51+58.5 -> 109.5 | F17: 97.1 | G17: =E17*F17 -> 10632.45 | H17: 0 | I17: 0 | J17: =H17*I17 -> 0 | K17: =G17+J17 -> 10632.45 | M17: =+M16+K17-L17 -> 434720.03
A18: 15 | B18: 45853 | E18: =200+39+200 -> 439 | F18: 97.1 | G18: =E18*F18 -> 42626.9 | H18: 5 | I18: 108.83 | J18: =H18*I18 -> 544.15 | K18: =G18+J18 -> 43171.05 | L18: 424086 | M18: =+M17+K18-L18 -> 53805.078
A19: 16 | B19: 45854 | E19: 1492 | F19: 97.1 | G19: =E19*F19 -> 144873.2 | H19: 0 | I19: 0 | J19: =H19*I19 -> 0 | K19: =G19+J19 -> 144873.2 | L19: 0 | M19: =+M18+K19-L19 -> 198678.28 | N19: Fuel bills
A20: 17 | B20: 45855 | E20: 453 | F20: 97.1 | G20: =E20*F20 -> 43986.3 | H20: 10 | I20: 108.83 | J20: =H20*I20 -> 1088.3 | K20: =G20+J20 -> 45074.6 | L20: 0 | M20: =+M19+K20-L20 -> 243752.88
A21: 18 | B21: 45856 | E21: 851.35 | F21: 97.1 | G21: =E21*F21 -> 82666.085 | H21: 0 | I21: 0 | J21: =H21*I21 -> 0 | K21: =G21+J21 -> 82666.085 | L21: 0 | M21: =+M20+K21-L21 -> 326418.96
A22: 19 | B22: 45857 | E22: 1110.81 | F22: 97.1 | G22: =E22*F22 -> 107859.65 | H22: 0 | I22: 0 | J22: =H22*I22 -> 0 | K22: =G22+J22 -> 107859.65 | M22: =+M21+K22-L22 -> 434278.61
A23: 20 | B23: 45858 | E23: 192.5 | F23: 97.1 | G23: =E23*F23 -> 18691.75 | H23: 0 | I23: 0 | J23: =H23*I23 -> 0 | K23: =G23+J23 -> 18691.75 | L23: 0 | M23: =+M22+K23-L23 -> 452970.36
A24: 21 | B24: 45859 | E24: 1107.33 | F24: 97.1 | G24: =E24*F24 -> 107521.74 | H24: 5 | I24: 108.83 | J24: =H24*I24 -> 544.15 | K24: =G24+J24 -> 108065.89 | L24: 0 | M24: =+M23+K24-L24 -> 561036.26
A25: 22 | B25: 45860 | E25: 620 | F25: 97.1 | G25: =E25*F25 -> 60202 | H25: 0 | I25: 0 | J25: =H25*I25 -> 0 | K25: =G25+J25 -> 60202 | L25: 0 | M25: =+M24+K25-L25 -> 621238.26
