Workbook

Sheet Sheet1
A1: S.no | B1: Site Name | C1: Bunk Name | D1: Diesel(Liters) | E1: Diesel Amount | F1: Petrol(Liters) | G1: Petrol Amount | H1: Total Amount | I1: Opening Blance | J1: Amount Paid | K1: Closing Balances
A2: 1 | B2: Khammam-1 | C2: Sri Ramakotaiah Fuel Point | D2: 11984.26 | E2: 1146654 | F2: 130 | G2: 13969.8 | H2: =E2+G2 -> 1160623.8 | I2: 5140597 | J2: 2500000 | K2: =I2+H2-J2 -> 3801220.8
A3: 2 | B3: Khammam-2 | C3: Divya laxmi ganapathi | D3: 118512.26 | E3: 11339228 | F3: 535 | G3: 57491.1 | H3: =E3+G3 -> 11396719 | I3: 3730421 | J3: 1500000 | K3: =I3+H3-J3 -> 13627140
A4: 3 | B4: Khammam-3 | C4: Jayasai union bunk | D4: 33155.09 | E4: 3172942.1 | F4: 70 | G4: 7523.6 | H4: =E4+G4 -> 3180465.7 | I4: 8891075.4 | J4: 2000000 | K4: =I4+H4-J4 -> 10071541
A5: 4 | B5: Jadcherla-1 | C5: Sai Baba Fuel Station | D5: 6550.84 | E5: 631631.99 | F5: 305.75 | G5: 33091.323 | H5: =E5+G5 -> 664723.32 | I5: 1966837 | J5: 0 | K5: =I5+H5-J5 -> 2631560.3
A6: 5 | B6: Jadcherla-2 | C6: Uttara Enterprises | D6: 0 | E6: 0 | F6: 0 | G6: 0 | H6: =E6+G6 -> 0 | I6: 1832240.6 | J6: 0 | K6: =I6+H6-J6 -> 1832240.6
A7: 6 | B7: Jadcherla-3 | C7: Bhavani KSK Fuel Station-Nawabpet | D7: 4040 | E7: 389092.4 | F7: 0 | G7: 0 | H7: =E7+G7 -> 389092.4 | I7: 0 | J7: 0 | K7: =I7+H7-J7 -> 389092.4
A8: 7 | B8: Jadcherla-4 | C8: ADHOC FILLING STATION STATION | D8: 11600 | E8: 1118588 | F8: 0 | G8: 0 | H8: =E8+G8 -> 1118588 | I8: 0 | J8: 0 | K8: =I8+H8-J8 -> 1118588
A9: 8 | B9: Sangareddy-1 | C9: Shree lakshmi ganapathi F/S | D9: 4185.96 | E9: 403359.11 | F9: 62 | G9: 6706.54 | H9: =E9+G9 -> 410065.65 | I9: 1004532 | J9: 1414699.8 | K9: 0
A10: 9 | B10: Sangareddy-2 | C10: Sri Durgabhavani Filling Station | D10: 165 | E10: 15912 | F10: 16 | G10: 1732.96 | H10: =E10+G10 -> 17644.96 | I10: 0 | J10: 17644.96 | K10: =I10+H10-J10 -> 0
A11: 10 | B11: Sangareddy-3 | C11: Laxmi Narasimha Enterprises F/S | D11: 40 | E11: 3849 | F11: 0 | G11: 0 | H11: =E11+G11 -> 3849 | I11: 0 | J11: 3849 | K11: =I11+H11-J11 -> 0
A12: 11 | B12: Sangareddy-4 | C12: Sree Shiva Parvathi Filling Station | D12: 1459.79 | E12: 140476 | F12: 16 | G12: 1732.96 | H12: =E12+G12 -> 142208.96 | I12: 0 | J12: 142208.96 | K12: =I12+H12-J12 -> 0
A13: 12 | B13: YG Gudda | C13: Pallavi Petrolium | D13: 3800 | E13: 346940 | F13: 385 | G13: 39747.4 | H13: =E13+G13 -> 386687.4 | I13: 244365 | J13: 299920 | K13: =I13+H13-J13 -> 331132.4
A14: 13 | B14: Hosadurga-1 | C14: Merchant Petroliums | D14: 4500 | E14: 412380 | F14: 140 | G14: 14777 | H14: =E14+G14 -> 427157 | I14: 0 | J14: 150000 | K14: =I14+H14-J14 -> 277157
A15: 14 | B15: Hosadurga-2 | C15: Shree Veeraprathap Fuel | D15: 2000 | E15: 182780 | F15: 135 | G15: 13967.1 | H15: =E15+G15 -> 196747.1 | I15: 151569.4 | J15: 150000 | K15: =I15+H15-J15 -> 198316.5
A16: 15 | B16: Malebennuru(KUWSDB) | C16: Sri Ramanjuneya Service Station | D16: 3277.82 | E16: 301888 | F16: 138 | G16: 14332 | H16: =E16+G16 -> 316220 | I16: 96655 | J16: 385490 | K16: =I16+H16-J16 -> 27385
A17: 16 | B17: kadur | C17: Vishal Service Station | D17: 2000 | E17: 182300 | F17: 145 | G17: 15119.15 | H17: =E17+G17 -> 197419.15 | I17: 578097.65 | J17: 0 | K17: =I17+H17-J17 -> 775516.8
A18: 17 | B18: Hiriyur(VJNL) | C18: Sri Balaji Agencies | D18: 2400 | E18: 221040 | F18: 210 | G18: 21810.6 | H18: =E18+G18 -> 242850.6 | I18: 237520 | J18: 250000 | K18: =I18+H18-J18 -> 230370.6
A19: 18 | B19: Chellakere(KUWSDB) | C19: Sri Vishnu Baba Petroleum | D19: 2045 | E19: 188324.05 | F19: 125 | G19: 12982.5 | H19: =E19+G19 -> 201306.55 | I19: 0 | J19: 201306.55 | K19: =I19+H19-J19 -> 0
A20: 19 | B20: Khanapur(PKG-3) | C20: J K Makavi | D20: 169 | E20: 15411.11 | F20: 16.25 | G20: 1669.23 | H20: =E20+G20 -> 17080.34 | I20: 0 | J20: 17080.34 | K20: =I20+H20-J20 -> 0
A21: 20 | B21: Munavalli(PKG-3) | C21: Shahapur Petroleum | D21: 14283.35 | E21: 1303412.1 | F21: 127 | G21: 13103.86 | H21: =E21+G21 -> 1316516 | I21: 58857 | J21: 1134279.9 | K21: =I21+H21-J21 -> 241093.08
... A24: 23 | B24: Kabbur(PKG-3) | C24: Shri Jai Hanuman Petrolium | D24: 509.02 | E24: 46621.142 | F24: 11.56 | G24: 1196.8068 | H24: =E24+G24 -> 47817.949 | I24: 0 | J24: 47817.949 | K24: =I24+H24-J24 -> 0
A25: 24 | B25: Kumta (PKG-1) | C25: Krishma fuel station | D25: 760.33 | E25: 69889.534 | F25: 47.46 | G25: 4933.9416 | H25: =E25+G25 -> 74823.475 | J25: 74823.475 | K25: =I25+H25-J25 -> 0
A26: 25 | B26: Jalgaon | C26: Sri Sai Petrol Pump | D26: 597.14 | E26: 54712.182 | F26: 13.52 | G26: 1419.4272 | H26: =E26+G26 -> 56131.609 | I26: 4528.49 | J26: 49930.511 | K26: =I26+H26-J26 -> 10729.588
A27: 26 | B27: MKBD | C27: Shree Sai Samarth Petroleum | D27: 25450 | E27: 2319513 | F27: 75 | G27: 7845 | H27: =E27+G27 -> 2327358 | I27: 1668531 | J27: 2000000 | K27: =I27+H27-J27 -> 1995889
A28: 27 | B28: Haveri | C28: Shivalingeshwar Petroleum | D28: 944.46 | E28: 86389.756 | F28: 63.01 | G28: 6517.1243 | H28: =E28+G28 -> 92906.88 | I28: 90058 | J28: 115444 | K28: =I28+H28-J28 -> 67520.88
A29: 28 | B29: Guttal | C29: Taware filling station | D29: 935.89 | E29: 85914.702 | F29: 40 | G29: 4150.4 | H29: =E29+G29 -> 90065.102 | J29: 90065.102 | K29: =I29+H29-J29 -> 0
A30: 29 | B30: Rattihali | C30: Shree Siri Gowari petroliam | D30: 1032.57 | E30: 95037.743 | F30: 45 | G30: 4680.9 | H30: =E30+G30 -> 99718.643 | J30: 99718.643 | K30: =I30+H30-J30 -> 0
A31: 30 | B31: Gajendragada | C31: Vanasri Petrol Pump | D31: 60 | E31: 5509.8 | F31: 18 | G31: 1868.4 | H31: =E31+G31 -> 7378.2 | I31: 30323 | J31: 7378.2 | K31: =I31+H31-J31 -> 30323
A32: 31 | B32: Ghattaprabha(PKG-3) | C32: Vivek Petrol Pump | D32: 0 | E32: 0 | F32: 0 | G32: 0 | H32: =E32+G32 -> 0 | I32: 1036347.3 | J32: 400000 | K32: =I32+H32-J32 -> 636347.32
A33: 32 | B33: Gokak(PKG-3) | C33: AJ Petrolinks | D33: 11163.57 | E33: 1021243.4 | F33: 271 | G33: 28024.11 | H33: =E33+G33 -> 1049267.5 | I33: 473791 | J33: 300000 | K33: =I33+H33-J33 -> 1223058.5
A34: 33 | B34: Ghattaprabha-2(PKG-3) | C34: Manikeri Petroleums | D34: 0 | E34: 0 | F34: 4.82 | G34: 499.98 | H34: =E34+G34 -> 499.98 | I34: 0 | J34: 499.98 | K34: =I34+H34-J34 -> 0
A35: 34 | B35: Ankalgi(PKG-3) | C35: Nirwani Petroleums | D35: 152.92 | E35: 13949.929 | F35: 37.28 | G35: 3857.5144 | H35: =E35+G35 -> 17807.443 | I35: 0 | J35: 17807.443 | K35: =I35+H35-J35 -> 0
A36: 35 | B36: Talikote(PKG-1) | C36: Raykar Oil Agencies | D36: 637.8 | E36: 58358.7 | F36: 61.99 | G36: 5912.6304 | H36: =E36+G36 -> 64271.33 | I36: 0 | J36: 64271.33 | K36: =I36+H36-J36 -> 0
A37: 36 | B37: Chadchan(PKG-1) | C37: Khavekar Petrolium | D37: 577.29 | E37: 52088.877 | F37: 43.88 | G37: 4482.7808 | H37: =E37+G37 -> 56571.658 | I37: 192780 | J37: 192780 | K37: =I37+H37-J37 -> 56571.658
A38: 37 | B38: Sindagi | C38: G.P.PORWAL | D38: 138 | E38: 12589.74 | F38: 0 | G38: 0 | H38: =E38+G38 -> 12589.74 | I38: 0 | J38: 12589.74 | K38: =I38+H38-J38 -> 0
A39: 38 | B39: Muddebihal(PKG-1) | C39: Bhosle Service Station | D39: 98.41 | E39: 8999.5945 | F39: 33.81 | G39: 3495.6159 | H39: =E39+G39 -> 12495.21 | I39: 0 | J39: 12495.21 | K39: =I39+H39-J39 -> 0
A40: 39 | B40: Almela(PKG-1) | C40: Shiddeshwar Petroleums | D40: 35.03 | E40: 3199.2899 | F40: 30.92 | G40: 3192.7992 | H40: =E40+G40 -> 6392.0891 | I40: 0 | J40: 6392.0891 | K40: =I40+H40-J40 -> 0
A41: 40 | B41: Srirangapatna | C41: Sri Chakra Fuel Station | D41: 71.77 | E41: 6500.2089 | F41: 35.13 | G41: 3599.4198 | H41: =E41+G41 -> 10099.629 | I41: 0 | J41: 10099.629 | K41: =I41+H41-J41 -> 0
A42: 41 | B42: Nalatwad(PKG-1) | C42: Shri Pawad Basaweshwar Petroleums | D42: 436.89 | E42: 40027.862 | F42: 21.25 | G42: 2200.8625 | H42: =E42+G42 -> 42228.724 | I42: 48315 | J42: 90535.84 | K42: =I42+H42-J42 -> 7.8843
...

Sheet June-25
A1: S.no | B1: Site Name | C1: Bunk Name | D1: Diesel(Liters) | E1: Diesel Amount | F1: Petrol(Liters) | G1: Petrol Amount | H1: Total Amount | I1: Opening Blance | J1: Amount Paid | K1: Closing Balances
A2: 1 | B2: Khammam-1 | C2: Sri Ramakotaiah Fuel Point | D2: =+'Khammam-1'!E36 -> 0 | E2: =+'Khammam-1'!G36 -> 0 | F2: =+'Khammam-1'!H36 -> 0 | G2: =+'Khammam-1'!J36 -> 0 | H2: =E2+G2 -> 0 | I2: =+'Khammam-1'!K3 -> 2301220.8 | J2: =+'Khammam-1'!L36 -> 2301220 | K2: =H2+I2-J2 -> 0.7968
A3: 2 | B3: Khammam-2 | C3: Divya laxmi ganapathi | D3: =+'Khammam-2'!E37 -> 148695.59 | E3: =+'Khammam-2'!G37 -> 14227153 | F3: =+'Khammam-2'!H37 -> 630 | G3: =+'Khammam-2'!J37 -> 67699.8 | H3: =E3+G3 -> 14294853 | I3: =+'Khammam-2'!K3 -> 9307338.8 | J3: =+'Khammam-2'!L37 -> 10036782 | K3: =H3+I3-J3 -> 13565410
A4: 3 | B4: Khammam-3 | C4: Jayasai union bunk | D4: =+'Khammam-3'!E35 -> 121466.14 | E4: =+'Khammam-3'!G35 -> 11624310 | F4: =+'Khammam-3'!H35 -> 502.98 | G4: =+'Khammam-3'!J35 -> 54060.29 | H4: =E4+G4 -> 11678370 | I4: =+'Khammam-3'!K3 -> 7457303.4 | J4: =+'Khammam-3'!L35 -> 8843736.1 | K4: =H4+I4-J4 -> 10291937
A5: 4 | B5: Jadcherla-1 | C5: Sai Baba Fuel Station | D5: =+'Jedcherla -1'!E36 -> 26513.87 | E5: =+'Jedcherla -1'!G36 -> 2556467.3 | F5: =+'Jedcherla -1'!H36 -> 479.35 | G5: =+'Jedcherla -1'!J36 -> 51880.05 | H5: =E5+G5 -> 2608347.4 | I5: =+'Jedcherla -1'!K3 -> 1149870.8 | J5: =+'Jedcherla -1'!L36 -> 1619072 | K5: =H5+I5-J5 -> 2139146.2 | M5: 2139146.9
A6: 5 | B6: Jadcherla-2 | C6: Uttara Enterprises | D6: 0 | E6: 0 | F6: 0 | G6: 0 | H6: =E6+G6 -> 0 | I6: =+'Jedcherla-2'!K3 -> 331699.53 | J6: =+'Jedcherla-2'!L35 -> 331700 | K6: =H6+I6-J6 -> -0.4737
A7: 6 | B7: Jadcherla-4 | C7: ADHOC FILLING STATION STATION | D7: =+'Jedcharla-3'!E35 -> 40895.59 | E7: =+'Jedcharla-3'!G35 -> 3943561.7 | F7: 0 | G7: 0 | H7: =E7+G7 -> 3943561.7 | I7: 0 | J7: =+'Jedcharla-3'!L35 -> 2733935 | K7: =H7+I7-J7 -> 1209626.7 | M7: =M5-K5 -> 0.7071
A8: 7 | B8: Sangareddy-1 | C8: Sree Shiva Parvathi Filling Station | D8: =+Sangareddy!E40 -> 8990 | E8: =+Sangareddy!G40 -> 865107.7 | F8: =+Sangareddy!H40 -> 120 | G8: =+Sangareddy!J40 -> 12967.6 | H8: =E8+G8 -> 878075.3 | I8: 0 | J8: =+Sangareddy!L40 -> 515538.5 | K8: =H8+I8-J8 -> 362536.8
A9: 8 | B9: Dindi | C9: Akarapu Balakistamma Fillling | D9: =+Dindi!E35 -> 175.7 | E9: =+Dindi!G35 -> 17013.031 | F9: =+Dindi!H35 -> 7.35 | G9: =+Dindi!J35 -> 798.651 | H9: =E9+G9 -> 17811.682 | J9: =+Dindi!L35 -> 17811.682 | K9: =H9+I9-J9 -> 0
A10: 9 | B10: Devarkhadra | C10: Kurumurthy Swami F/S | D10: =+Devarakhadra!E35 -> 1740.96 | E10: =+Devarakhadra!G35 -> 169047.22 | F10: =+Devarakhadra!H35 -> 0 | G10: =+Devarakhadra!J35 -> 0 | H10: =E10+G10 -> 169047.22 | I10: =+Devarakhadra!M3 -> 0 | J10: =+Devarakhadra!L35 -> 0 | K10: =H10+I10-J10 -> 169047.22
A11: 10 | B11: YG Gudda | C11: Pallavi Petrolium | D11: =+'YG Gudda '!E36 -> 8400 | E11: =+'YG Gudda '!G36 -> 766920 | F11: =+'YG Gudda '!H36 -> 595 | G11: =+'YG Gudda '!J36 -> 61427.8 | H11: =E11+G11 -> 828347.8 | I11: ='YG Gudda '!K3 -> 71933.179 | J11: =+'YG Gudda '!L36 -> 851800 | K11: =H11+I11-J11 -> 48480.979
A12: 11 | B12: Hosadurga-1 | C12: Merchant Petroliums | D12: =+Hosadurga!E35 -> 3100 | E12: =+Hosadurga!G35 -> 284084 | F12: =+Hosadurga!H35 -> 235 | G12: =+Hosadurga!J35 -> 24374.2 | H12: =E12+G12 -> 308458.2 | I12: =+Hosadurga!K3 -> 0 | J12: =+Hosadurga!L35 -> 308458.2 | K12: =H12+I12-J12 -> 0
A13: 12 | B13: Hosadurga-2 | C13: Shree Veeraprathap Fuel | D13: =+'Hosadurga -2'!E35 -> 4000 | E13: =+'Hosadurga -2'!G35 -> 365560 | F13: =+'Hosadurga -2'!H35 -> 140 | G13: =+'Hosadurga -2'!J35 -> 14484.4 | H13: =+'Hosadurga -2'!K35 -> 380044.4 | I13: =+'Hosadurga -2'!K3 -> 388266.5 | J13: =+'Hosadurga -2'!L35 -> 388266.5 | K13: =H13+I13-J13 -> 380044.4
A14: 13 | B14: Malebennuru(KUWSDB) | C14: Sri Ramanjuneya Service Station | D14: =+'Malebenur(KUWSDB)'!E38 -> 3700 | E14: =+'Malebenur(KUWSDB)'!G38 -> 340662 | F14: =+'Malebenur(KUWSDB)'!H38 -> 175 | G14: =+'Malebenur(KUWSDB)'!J38 -> 18175.5 | H14: =E14+G14 -> 358837.5 | I14: =+'Malebenur(KUWSDB)'!K3 -> 36616.014 | J14: =+'Malebenur(KUWSDB)'!L36 -> 296692.21 | K14: =H14+I14-J14 -> 98761.304
A15: 14 | B15: kadur | C15: Vishal Service Station | D15: =+Kadur!E35 -> 0 | E15: =+Kadur!G35 -> 0 | F15: =+Kadur!H35 -> 110 | G15: =+Kadur!J35 -> 11469.7 | H15: =E15+G15 -> 11469.7 | I15: =+Kadur!K3 -> 1167095.1 | J15: =+Kadur!L35 -> 968765.11 | K15: =H15+I15-J15 -> 209799.73
A16: 15 | B16: Hiriyur(VJNL) | C16: Sri Balaji Agencies | D16: =+'Hiriyur(VJNL)'!E35 -> 4000 | E16: =+'Hiriyur(VJNL)'!G35 -> 368400 | F16: =+'Hiriyur(VJNL)'!H35 -> 140 | G16: =+'Hiriyur(VJNL)'!J35 -> 14540.4 | H16: =E16+G16 -> 382940.4 | I16: =+'Hiriyur(VJNL)'!K3 -> 87640.8 | J16: =+'Hiriyur(VJNL)'!L35 -> 87640.8 | K16: =H16+I16-J16 -> 382940.4
A17: 16 | B17: Chellakere(KUWSDB) | C17: Sri Vishnu Baba Petroleum | D17: =+'Chellakere (KUWSDB)'!E35 -> 4564 | E17: =+'Chellakere (KUWSDB)'!G35 -> 416151.18 | F17: =+'Chellakere (KUWSDB)'!H35 -> 242 | G17: =+'Chellakere (KUWSDB)'!J35 -> 25134.12 | H17: =E17+G17 -> 441285.3 | I17: 0 | J17: =+'Chellakere (KUWSDB)'!L35 -> 441285.3 | K17: =H17+I17-J17 -> 0
A18: 17 | B18: Khanapur(PKG-3) | C18: J K Makavi | D18: =+Khanapur!E35 -> 454.02 | E18: =+Khanapur!G35 -> 41261.338 | F18: =+Khanapur!H35 -> 9.73 | G18: =+Khanapur!J35 -> 999.9521 | H18: =E18+G18 -> 42261.29 | I18: 0 | J18: =+Khanapur!M35 -> 42261.29 | K18: =H18+I18-J18 -> 0
A19: 18 | B19: Munavalli(PKG-3) | C19: Shahapur Petroleum | D19: =+'Munavalli(KUWSDB)'!E36 -> 8967.17 | E19: =+'Munavalli(KUWSDB)'!G36 -> 818343.93 | F19: =+'Munavalli(KUWSDB)'!H36 -> 259.38 | G19: =+'Munavalli(KUWSDB)'!J36 -> 26762.828 | H19: =E19+G19 -> 845106.76 | I19: =+'Munavalli(KUWSDB)'!K3 -> 107004.03 | J19: =+'Munavalli(KUWSDB)'!L36 -> 364300 | K19: =H19+I19-J19 -> 587810.79
A20: 19 | B20: Borgaon(PKG-3) | C20: Aadisagar Petrolium | D20: =+Borgaon!E35 -> 364.4 | E20: =+Borgaon!G35 -> 33440.988 | F20: =+Borgaon!H35 -> 36 | G20: =+Borgaon!J35 -> 3732.48 | H20: =E20+G20 -> 37173.468 | I20: =+Borgaon!K3 -> 22826.33 | J20: =+Borgaon!L35 -> 0 | K20: =H20+I20-J20 -> 59999.798
A21: 20 | B21: Ugar,Kudichi(PKG-3) | C21: Shiri Bhrhmanath Petrolium | D21: =+'Ugar,Khagwad,Kudichi'!E35 -> 2862.39 | E21: =+'Ugar,Khagwad,Kudichi'!G35 -> 263139.51 | F21: =+'Ugar,Khagwad,Kudichi'!H35 -> 190 | G21: =+'Ugar,Khagwad,Kudichi'!J35 -> 19739.1 | H21: =E21+G21 -> 282878.61 | I21: =+'Ugar,Khagwad,Kudichi'!K3 -> 241437.63 | J21: =+'Ugar,Khagwad,Kudichi'!L35 -> 287745 | K21: =H21+I21-J21 -> 236571.24
A22: 21 | B22: Kabbur(PKG-3) | C22: Shri Jai Hanuman Petrolium | D22: =+Kabbur!E35 -> 705 | E22: =+Kabbur!G35 -> 64570.95 | F22: =+Kabbur!H35 -> 32.51 | G22: =+Kabbur!J35 -> 3367.2309 | H22: =E22+G22 -> 67938.181 | I22: 0 | J22: =+Kabbur!L35 -> 67938.181 | K22: =H22+I22-J22 -> 0
A23: 22 | B23: Kumta (PKG-1) | C23: Krishna fuel station | D23: =+kumta!E35 -> 1235.75 | E23: =+kumta!G35 -> 113590.14 | F23: =+kumta!H35 -> 91.72 | G23: =+kumta!J35 -> 9532.9908 | H23: =E23+G23 -> 123123.13 | I23: 0 | J23: =+kumta!L35 -> 123123.13 | K23: =H23+I23-J23 -> 0
A24: 23 | B24: Jalgaon | C24: Sri Sai Petrol Pump | D24: =+Jalgaon!E40 -> 823.37 | E24: =+Jalgaon!G40 -> 75472.286 | F24: =+Jalgaon!H40 -> 14.64 | G24: =+Jalgaon!J40 -> 1539.9816 | H24: =E24+G24 -> 77012.267 | I24: =+Jalgaon!K3 -> 13725.912 | J24: =+Jalgaon!L40 -> 73672.3 | K24: =H24+I24-J24 -> 17065.88
A25: 24 | B25: MKBD | C25: Shree Sai Samarth Petroleum | D25: =+MKBD!E36 -> 17089.19 | E25: =+MKBD!G36 -> 1557508.8 | F25: =+MKBD!H36 -> 77 | G25: =+MKBD!J36 -> 8054.2 | H25: 1566762 | I25: =+MKBD!K3 -> 450628.67 | J25: =+MKBD!L36 -> 1005216 | K25: =H25+I25-J25 -> 1012174.7
A26: 25 | B26: Haveri | C26: Shivalingeshwar Petroleum | D26: =+Haveri!E35 -> 3219.58 | E26: =+Haveri!G35 -> 294494.98 | F26: =+Haveri!H35 -> 105.49 | G26: =+Haveri!J35 -> 10907.666 | H26: =E26+G26 -> 305402.65 | I26: =+Haveri!K3 -> 36319.153 | J26: =+Haveri!L35 -> 173800 | K26: =H26+I26-J26 -> 167921.8
A27: 26 | B27: Guttal | C27: Taware filling station | D27: =+Guttal!E35 -> 1316.9 | E27: =+Guttal!G35 -> 120891.42 | F27: =+Guttal!H35 -> 41 | G27: =+Guttal!J35 -> 4254.16 | H27: =E27+G27 -> 125145.58 | I27: 0 | J27: =+Guttal!L35 -> 125145.58 | K27: =H27+I27-J27 -> 0
A28: 27 | B28: Rattihali | C28: Shree Siri Gowari petroliam | D28: =+Rattihali!E35 -> 2658.06 | E28: =+Rattihali!G35 -> 244647.84 | F28: =+Rattihali!H35 -> 151.28 | G28: =+Rattihali!J35 -> 15736.146 | H28: =E28+G28 -> 260383.99 | I28: 0 | J28: =+Rattihali!L35 -> 105061.18 | K28: =H28+I28-J28 -> 155322.81
A29: 28 | B29: Gajendragada | C29: Vanasri Petrol Pump | D29: =+Gajendragada!E35 -> 1032.89 | E29: =+Gajendragada!G35 -> 94850.289 | F29: =+Gajendragada!H35 -> 75 | G29: =+Gajendragada!J35 -> 7785.75 | H29: =E29+G29 -> 102636.04 | I29: =+Gajendragada!K3 -> 59460.8 | J29: =+Gajendragada!L35 -> 88047.8 | K29: =H29+I29-J29 -> 74049.039
A30: 29 | B30: Ghattaprabha(PKG-3) | C30: Vivek Petrol Pump | D30: =+Ghattaprabha!E35 -> 3214.07 | E30: =+Ghattaprabha!G35 -> 294087.4 | F30: =+Ghattaprabha!H35 -> 143 | G30: =+Ghattaprabha!J35 -> 14789.06 | H30: =E30+G30 -> 308876.46 | I30: =+Ghattaprabha!K3 -> 0 | J30: =+Ghattaprabha!L35 -> 0 | K30: =H30+I30-J30 -> 308876.46
A31: 30 | B31: Gokak(PKG-3) | C31: AJ Petrolinks | D31: =+'Gokak Dharwad PKG 3'!E38 -> 10414.8 | E31: =+'Gokak Dharwad PKG 3'!G38 -> 952745.9 | F31: =+'Gokak Dharwad PKG 3'!H38 -> 362 | G31: =+'Gokak Dharwad PKG 3'!J38 -> 37480.98 | H31: =E31+G31 -> 990226.88 | I31: =+'Gokak Dharwad PKG 3'!K3 -> 1537989 | J31: =+'Gokak Dharwad PKG 3'!L38 -> 1621328 | K31: =H31+I31-J31 -> 906887.85
A32: 31 | B32: ShankeshWAR | C32: SR Patil | D32: =+' Shankeshwar'!E35 -> 571.44 | E32: =+' Shankeshwar'!G35 -> 52172.472 | F32: =+' Shankeshwar'!H35 -> 38 | G32: =+' Shankeshwar'!J35 -> 3922.36 | H32: =E32+G32 -> 56094.832 | J32: =+' Shankeshwar'!L35 -> 56094.832 | K32: =H32+I32-J32 -> 0
A33: 32 | B33: Talikote(PKG-1) | C33: Raykar Oil Agencies | D33: =+' Talikote'!E45 -> 1558.26 | E33: =+' Talikote'!G45 -> 142580.79 | F33: =+' Talikote'!H45 -> 72.68 | G33: =+' Talikote'!J45 -> 7518.0192 | H33: =E33+G33 -> 150098.81 | I33: =+' Talikote'!M3 -> 2488 | J33: =+' Talikote'!L45 -> 124004.62 | K33: =H33+I33-J33 -> 28582.189
A34: 33 | B34: Chadchan(PKG-1) | C34: Khavekar Petrolium | D34: =+Chadchan!E35 -> 1216.31 | E34: =+Chadchan!G35 -> 110512.23 | F34: =+Chadchan!H35 -> 71.09 | G34: =+Chadchan!J35 -> 7296.7344 | H34: =E34+G34 -> 117808.97 | I34: =+Chadchan!K3 -> 77981.337 | J34: =+Chadchan!L35 -> 102795 | K34: =H34+I34-J34 -> 92995.303
A35: 34 | B35: Sindagi | C35: G.P.PORWAL | D35: =+Sindagi!E44 -> 2214.03 | E35: =+Sindagi!G44 -> 201985.96 | F35: =+Sindagi!H44 -> 4.52 | G35: =+Sindagi!J44 -> 499.3244 | H35: =E35+G35 -> 202485.28 | I35: 0 | J35: =+Sindagi!L44 -> 192630.53 | K35: =H35+I35-J35 -> 9854.749
A36: 35 | B36: Muddebihal(PKG-1) | C36: Bhosle Service Station | D36: =+Muddebihal!E46 -> 394.94 | E36: =+Muddebihal!G46 -> 36117.263 | F36: =+Muddebihal!H46 -> 28.98 | G36: =+Muddebihal!J46 -> 2996.2422 | H36: =E36+G36 -> 39113.505 | I36: 0 | J36: =+Muddebihal!L46 -> 11599.495 | K36: =H36+I36-J36 -> 27514.01
A37: 36 | B37: Almela(PKG-1) | C37: Shiddeshwar Petroleums | D37: =+Alemela!E43 -> 1216.14 | E37: =+Alemela!G43 -> 111070.07 | F37: =+Alemela!H43 -> 38.84 | G37: =+Alemela!J43 -> 4010.6184 | H37: =E37+G37 -> 115080.68 | I37: 0 | J37: =+Alemela!L43 -> 40321.143 | K37: =H37+I37-J37 -> 74759.542
A38: 37 | B38: Nalatwad(PKG-1) | C38: Shri Pawad Basaweshwar Petroleums | D38: =+Nalatwad!E43 -> 761.83 | E38: =+Nalatwad!G43 -> 69798.865 | F38: =+Nalatwad!H43 -> 53.12 | G38: =+Nalatwad!J43 -> 5501.6384 | H38: =E38+G38 -> 75300.503 | I38: =+Nalatwad!M3 -> 20248.57 | J38: =+Nalatwad!L43 -> 58950.7 | K38: =H38+I38-J38 -> 36598.373
A39: 38 | B39: Srirangapatna | C39: Sri Chakra Fuel Station | D39: =+Srirangapatna!E35 -> 501.25 | E39: =+Srirangapatna!G35 -> 45398.213 | F39: =+Srirangapatna!H35 -> 74.01 | G39: =+Srirangapatna!J35 -> 7583.0646 | H39: =E39+G39 -> 52981.277 | I39: 0 | J39: =+Srirangapatna!L35 -> 52981.277 | K39: =H39+I39-J39 -> 0
A40: Total | D40: =SUM(D2:D39) -> 439033.64 | E40: =SUM(E2:E39) -> 41683118 | F40: =SUM(F2:F39) -> 5346.67 | G40: =SUM(G2:G39) -> 561023.04 | H40: =SUM(H2:H39) -> 42245340 | I40: =SUM(I2:I39) -> 24869094 | J40: =SUM(J2:J39) -> 34459719 | K40: =H40+I40-J40 -> 32654715

Sheet Khammam-1
A1: Sri Ramakotaiah Fuel Point
A2: S.No | B2: Date | C2: GRN No | D2: Ind No/Bill No | E2: Diesel (Lts) | F2: Price | G2: Amount | H2: Petrol (Lts) | I2: Price | J2: Amount | K2: Total amount | L2: Amount paid | M2: As 0n Date | N2: Remarks
A3: Opening Balance | K3: 2301220.8 | M3: =+K3 -> 2301220.8 | P3: 220299.06
A4: 1 | B4: 45809 | E4: 0 | F4: 0 | G4: =E4*F4 -> 0 | H4: 0 | I4: 0 | J4: =H4*I4 -> 0 | K4: =G4+J4 -> 0 | L4: 0 | M4: =M3+K4-L4 -> 2301220.8
A5: 2 | B5: 45810 | E5: 0 | F5: 0 | G5: =E5*F5 -> 0 | H5: 0 | I5: 0 | J5: =H5*I5 -> 0 | K5: =G5+J5 -> 0 | L5: 0 | M5: =M4+K5-L5 -> 2301220.8
A6: 3 | B6: 45811 | E6: 0 | F6: 0 | G6: =E6*F6 -> 0 | H6: 0 | I6: 0 | J6: =H6*I6 -> 0 | K6: =G6+J6 -> 0 | L6: 0 | M6: =M5+K6-L6 -> 2301220.8
A7: 4 | B7: 45812 | E7: 0 | F7: 0 | G7: =E7*F7 -> 0 | H7: 0 | I7: 0 | J7: =H7*I7 -> 0 | K7: =G7+J7 -> 0 | L7: 0 | M7: =M6+K7-L7 -> 2301220.8
A8: 5 | B8: 45813 | E8: 0 | F8: 0 | G8: =E8*F8 -> 0 | H8: 0 | I8: 0 | J8: =H8*I8 -> 0 | K8: =G8+J8 -> 0 | L8: 2301220 | M8: =M7+K8-L8 -> 0.7968
A9: 6 | B9: 45814 | E9: 0 | F9: 0 | G9: =E9*F9 -> 0 | H9: 0 | I9: 0 | J9: =H9*I9 -> 0 | K9: =G9+J9 -> 0 | L9: 0 | M9: =M8+K9-L9 -> 0.7968
A10: 7 | B10: 45815 | E10: 0 | F10: 0 | G10: =E10*F10 -> 0 | H10: 0 | I10: 0 | J10: =H10*I10 -> 0 | K10: =G10+J10 -> 0 | L10: 0 | M10: =M9+K10-L10 -> 0.7968
A11: 8 | B11: 45816 | E11: 0 | F11: 0 | G11: =E11*F11 -> 0 | H11: 0 | I11: 0 | J11: =H11*I11 -> 0 | K11: =G11+J11 -> 0 | L11: 0 | M11: =M10+K11-L11 -> 0.7968
A12: 9 | B12: 45817 | E12: 0 | F12: 0 | G12: =E12*F12 -> 0 | H12: 0 | I12: 0 | J12: =H12*I12 -> 0 | K12: =G12+J12 -> 0 | L12: 0 | M12: =M11+K12-L12 -> 0.7968
A13: 10 | B13: 45818 | E13: 0 | F13: 0 | G13: =E13*F13 -> 0 | H13: 0 | I13: 0 | J13: =H13*I13 -> 0 | K13: =G13+J13 -> 0 | L13: 0 | M13: =M12+K13-L13 -> 0.7968
A14: 11 | B14: 45819 | E14: 0 | F14: 0 | G14: =E14*F14 -> 0 | H14: 0 | I14: 0 | J14: =H14*I14 -> 0 | K14: =G14+J14 -> 0 | L14: 0 | M14: =M13+K14-L14 -> 0.7968
A15: 12 | B15: 45820 | E15: 0 | F15: 0 | G15: =E15*F15 -> 0 | H15: 0 | I15: 0 | J15: =H15*I15 -> 0 | K15: =G15+J15 -> 0 | L15: 0 | M15: =M14+K15-L15 -> 0.7968
... A18: 15 | B18: 45823 | E18: 0 | F18: 0 | G18: =E18*F18 -> 0 | H18: 0 | I18: 0 | J18: =H18*I18 -> 0 | K18: =G18+J18 -> 0 | L18: 0 | M18: =M17+K18-L18 -> 0.7968
A19: 16 | B19: 45824 | E19: 0 | F19: 0 | G19: =E19*F19 -> 0 | H19: 0 | I19: 0 | J19: =H19*I19 -> 0 | K19: =G19+J19 -> 0 | L19: 0 | M19: =M18+K19-L19 -> 0.7968 | O19: .
A20: 17 | B20: 45825 | E20: 0 | F20: 0 | G20: =E20*F20 -> 0 | H20: 0 | I20: 0 | J20: =H20*I20 -> 0 | K20: =G20+J20 -> 0 | L20: 0 | M20: =M19+K20-L20 -> 0.7968
A21: 18 | B21: 45826 | E21: 0 | F21: 0 | G21: =E21*F21 -> 0 | H21: 0 | I21: 0 | J21: =H21*I21 -> 0 | K21: =G21+J21 -> 0 | L21: 0 | M21: =M20+K21-L21 -> 0.7968
A22: 19 | B22: 45827 | E22: 0 | F22: 0 | G22: =E22*F22 -> 0 | H22: 0 | I22: 0 | J22: =H22*I22 -> 0 | K22: =G22+J22 -> 0 | L22: 0 | M22: =M21+K22-L22 -> 0.7968
A23: 20 | B23: 45828 | E23: 0 | F23: 0 | G23: =E23*F23 -> 0 | H23: 0 | I23: 0 | J23: =H23*I23 -> 0 | K23: =G23+J23 -> 0 | L23: 0 | M23: =M22+K23-L23 -> 0.7968
A24: 21 | B24: 45829 | E24: 0 | F24: 0 | G24: =E24*F24 -> 0 | H24: 0 | I24: 0 | J24: =H24*I24 -> 0 | K24: =G24+J24 -> 0 | L24: 0 | M24: =M23+K24-L24 -> 0.7968
A25: 22 | B25: 45830 | E25: 0 | F25: 0 | G25: =E25*F25 -> 0 | H25: 0 | I25: 0 | J25: =H25*I25 -> 0 | K25: =G25+J25 -> 0 | L25: 0 | M25: =M24+K25-L25 -> 0.7968
A26: 23 | B26: 45831 | E26: 0 | F26: 0 | G26: =E26*F26 -> 0 | H26: 0 | I26: 0 | J26: =H26*I26 -> 0 | K26: =G26+J26 -> 0 | L26: 0 | M26: =M25+K26-L26 -> 0.7968
A27: 24 | B27: 45832 | E27: 0 | F27: 0 | G27: =E27*F27 -> 0 | H27: 0 | I27: 0 | J27: =H27*I27 -> 0 | K27: =G27+J27 -> 0 | L27: 0 | M27: =M26+K27-L27 -> 0.7968
A28: 25 | B28: 45833 | E28: 0 | F28: 0 | G28: =E28*F28 -> 0 | H28: 0 | I28: 0 | J28: =H28*I28 -> 0 | K28: =G28+J28 -> 0 | L28: 0 | M28: =M27+K28-L28 -> 0.7968
A29: 26 | B29: 45834 | E29: 0 | F29: 0 | G29: =E29*F29 -> 0 | H29: 0 | I29: 0 | J29: =H29*I29 -> 0 | K29: =G29+J29 -> 0 | L29: 0 | M29: =M28+K29-L29 -> 0.7968
A30: 27 | B30: 45835 | E30: 0 | F30: 0 | G30: =E30*F30 -> 0 | H30: 0 | I30: 0 | J30: =H30*I30 -> 0 | K30: =G30+J30 -> 0 | L30: 0 | M30: =M29+K30-L30 -> 0.7968
A31: 28 | B31: 45836 | E31: 0 | F31: 0 | G31: =E31*F31 -> 0 | H31: 0 | I31: 0 | J31: =H31*I31 -> 0 | K31: =G31+J31 -> 0 | L31: 0 | M31: =M30+K31-L31 -> 0.7968
A32: 29 | B32: 45837 | E32: 0 | F32: 0 | G32: =E32*F32 -> 0 | H32: 0 | I32: 0 | J32: =H32*I32 -> 0 | K32: =G32+J32 -> 0 | L32: 0 | M32: =M31+K32-L32 -> 0.7968
A33: 30 | B33: 45838 | E33: 0 | F33: 0 | G33: =E33*F33 -> 0 | H33: 0 | I33: 0 | J33: =H33*I33 -> 0 | K33: =G33+J33 -> 0 | L33: 0 | M33: =M32+K33-L33 -> 0.7968 | R33: 2584221.7
A34: 31 | E34: 0 | F34: 0 | G34: =E34*F34 -> 0 | H34: 0 | I34: 0 | J34: =H34*I34 -> 0 | K34: =G34+J34 -> 0 | L34: 0 | M34: =M33+K34-L34 -> 0.7968
E35: 0 | F35: 0 | G35: =E35*F35 -> 0 | H35: 0 | I35: 0 | J35: =H35*I35 -> 0 | K35: =G35+J35 -> 0
E36: =SUM(E4:E35) -> 0 | G36: =SUM(G4:G35) -> 0 | H36: =SUM(H4:H35) -> 0 | J36: =SUM(J3:J35) -> 0 | K36: =SUM(K4:K35) -> 0 | L36: =SUM(L4:L35) -> 2301220
E41: =E36+H36 -> 0

Sheet Khammam-2
A1: Divya laxmi ganapathi
A2: S.No | B2: Date | C2: GRN No | D2: Ind No/Bill No | E2: Diesel (Lts) | F2: Price | G2: Amount | H2: Petrol (Lts) | I2: Price | J2: Amount | K2: Total amount | L2: Amount paid | M2: As 0n Date | N2: Remarks
A3: Opening Balance | K3: 9307338.8 | M3: =+K3 -> 9307338.8
A4: 1 | B4: 45809 | E4: 0 | F4: 0 | G4: =E4*F4 -> 0 | H4: 0 | I4: 0 | J4: =H4*I4 -> 0 | K4: =G4+J4 -> 0 | M4: =M3+K4-L4 -> 9307338.8
A5: 2 | B5: 45810 | C5: 2930 | D5: 1055/517 | E5: 2500 | F5: 95.68 | G5: =E5*F5 -> 239200 | H5: 70 | I5: 107.46 | J5: =H5*I5 -> 7522.2 | K5: =G5+J5 -> 246722.2 | M5: =M4+K5-L5 -> 9554061
A6: 3 | B6: 45811 | C6: 2942 | D6: 1091 | E6: 4999.46 | F6: 95.68 | G6: =E6*F6 -> 478348.33 | H6: 20 | I6: 107.46 | J6: =H6*I6 -> 2149.2 | K6: =G6+J6 -> 480497.53 | M6: =M5+K6-L6 -> 10034559
A7: 4 | B7: 45812 | C7: 2951 | D7: 1098 | E7: 2500 | F7: 95.68 | G7: =E7*F7 -> 239200 | H7: 35 | I7: 107.46 | J7: =H7*I7 -> 3761.1 | K7: =G7+J7 -> 242961.1 | M7: =M6+K7-L7 -> 10277520
A8: 5 | B8: 45813 | C8: 2962 | D8: 1119/1125/1129 | E8: 7500.08 | F8: 95.68 | G8: =E8*F8 -> 717607.65 | H8: 55 | I8: 107.46 | J8: =H8*I8 -> 5910.3 | K8: =G8+J8 -> 723517.95 | L8: 10036782 | M8: =M7+K8-L8 -> 964255.63
A9: 6 | B9: 45814 | C9: 2965 | D9: 1134/1139 | E9: 2800.25 | F9: 95.68 | G9: =E9*F9 -> 267927.92 | H9: 55 | I9: 107.46 | J9: =H9*I9 -> 5910.3 | K9: =G9+J9 -> 273838.22 | M9: =M8+K9-L9 -> 1238093.9
A10: 7 | B10: 45815 | C10: 2986 | D10: 1158/1161 | E10: 3716 | F10: 95.68 | G10: =E10*F10 -> 355546.88 | H10: 0 | I10: 107.46 | J10: =H10*I10 -> 0 | K10: =G10+J10 -> 355546.88 | M10: =M9+K10-L10 -> 1593640.7
A11: 8 | B11: 45816 | C11: 2989 | D11: 1172/1166 | E11: 5000.31 | F11: 95.68 | G11: =E11*F11 -> 478429.66 | H11: 20 | I11: 107.46 | J11: =H11*I11 -> 2149.2 | K11: =G11+J11 -> 480578.86 | M11: =M10+K11-L11 -> 2074219.6
A12: 9 | B12: 45817 | E12: 0 | F12: 0 | G12: =E12*F12 -> 0 | H12: 0 | I12: 0 | J12: =H12*I12 -> 0 | K12: =G12+J12 -> 0 | M12: =M11+K12-L12 -> 2074219.6
A13: 10 | B13: 45818 | C13: 3010 | D13: 1196/1192/1199/1197 | E13: 9310.15 | F13: 95.68 | G13: =E13*F13 -> 890795.15 | H13: 0 | I13: 0 | J13: =H13*I13 -> 0 | K13: =G13+J13 -> 890795.15 | M13: =M12+K13-L13 -> 2965014.7
A14: 11 | B14: 45819 | C14: 3017 | D14: 1221/1222/1226/1228 | E14: 9100 | F14: 95.68 | G14: =E14*F14 -> 870688 | H14: 55 | I14: 107.46 | J14: =H14*I14 -> 5910.3 | K14: =G14+J14 -> 876598.3 | M14: =M13+K14-L14 -> 3841613
A15: 12 | B15: 45820 | C15: 3019 | D15: 1216/1236/1244 | E15: 7500.11 | F15: 95.68 | G15: =E15*F15 -> 717610.52 | H15: 40 | I15: 107.46 | J15: =H15*I15 -> 4298.4 | K15: =G15+J15 -> 721908.92 | M15: =M14+K15-L15 -> 4563522
A16: 13 | B16: 45821 | C16: 3030 | D16: 1245/1246/1257/12591264/1263 | E16: 13500 | F16: 95.68 | G16: =E16*F16 -> 1291680 | H16: 40 | I16: 107.46 | J16: =H16*I16 -> 4298.4 | K16: =G16+J16 -> 1295978.4 | M16: =M15+K16-L16 -> 5859500.4
A17: 14 | B17: 45822 | C17: 3031 | D17: 1280/1278/1290/1291/1296 | E17: 10365.24 | F17: 95.68 | G17: =E17*F17 -> 991746.16 | H17: 40 | I17: 107.46 | J17: =H17*I17 -> 4298.4 | K17: =G17+J17 -> 996044.56 | M17: =M16+K17-L17 -> 6855544.9
A18: 15 | B18: 45823 | C18: 3045 | D18: 1300/1306/1320/1309 | E18: 8730.11 | F18: 95.68 | G18: =E18*F18 -> 835296.92 | H18: 20 | I18: 107.46 | J18: =H18*I18 -> 2149.2 | K18: =G18+J18 -> 837446.12 | M18: =M17+K18-L18 -> 7692991.1
A19: 16 | B19: 45824 | C19: 3065 | D19: 1329/1340/1334 | E19: 8600.07 | F19: 95.68 | G19: =E19*F19 -> 822854.7 | H19: 0 | I19: 0 | J19: =H19*I19 -> 0 | K19: =G19+J19 -> 822854.7 | M19: =M18+K19-L19 -> 8515845.8
A20: 17 | B20: 45825 | C20: 3074 | D20: 1333/1357/1346/1344 | E20: 6997.07 | F20: 95.68 | G20: =E20*F20 -> 669479.66 | H20: 60 | I20: 107.46 | J20: =H20*I20 -> 6447.6 | K20: =G20+J20 -> 675927.26 | M20: =M19+K20-L20 -> 9191773
A21: 18 | B21: 45826 | C21: 3085 | D21: 1351/1352/1374/1370 | E21: 9385 | F21: 95.68 | G21: =E21*F21 -> 897956.8 | H21: 40 | I21: 107.46 | J21: =H21*I21 -> 4298.4 | K21: =G21+J21 -> 902255.2 | M21: =M20+K21-L21 -> 10094028
A22: 19 | B22: 45827 | C22: 3104 | D22: 1380 | E22: 2800 | F22: 95.68 | G22: =E22*F22 -> 267904 | H22: 0 | I22: 0 | J22: =H22*I22 -> 0 | K22: =G22+J22 -> 267904 | M22: =M21+K22-L22 -> 10361932
A23: 20 | B23: 45828 | C23: 3120 | D23: 1399 | E23: 2942.85 | F23: 95.68 | G23: =E23*F23 -> 281571.89 | H23: 0 | I23: 0 | J23: =H23*I23 -> 0 | K23: =G23+J23 -> 281571.89 | M23: =M22+K23-L23 -> 10643504
A24: 21 | B24: 45829 | C24: 3122 | D24: 1412/1440 | E24: 7000.46 | F24: 95.68 | G24: =E24*F24 -> 669804.01 | H24: 40 | I24: 107.46 | J24: =H24*I24 -> 4298.4 | K24: =G24+J24 -> 674102.41 | M24: =M23+K24-L24 -> 11317607
A25: 22 | B25: 45830 | C25: 3153 | D25: 1473/1487/1504 | E25: 6452.43 | F25: 95.68 | G25: =E25*F25 -> 617368.5 | H25: 0 | I25: 0 | J25: =H25*I25 -> 0 | K25: =G25+J25 -> 617368.5 | M25: =M24+K25-L25 -> 11934975
A26: 23 | B26: 45831 | C26: 3154 | D26: 1500 | E26: 4112.71 | F26: 95.67 | G26: =E26*F26 -> 393462.97 | H26: 0 | I26: 0 | J26: =H26*I26 -> 0 | K26: =G26+J26 -> 393462.97 | M26: =M25+K26-L26 -> 12328438
A27: 24 | B27: 45832 | C27: 3171 | D27: 1528 | E27: 5676.03 | F27: 95.68 | G27: =E27*F27 -> 543082.55 | H27: 20 | I27: 107.46 | J27: =H27*I27 -> 2149.2 | K27: =G27+J27 -> 545231.75 | M27: =M26+K27-L27 -> 12873670
A28: 25 | B28: 45833 | E28: 0 | F28: 0 | G28: =E28*F28 -> 0 | H28: 0 | I28: 0 | J28: =H28*I28 -> 0 | K28: =G28+J28 -> 0 | M28: =M27+K28-L28 -> 12873670
A29: 26 | B29: 45834 | C29: 3172 | D29: 1567 | E29: 2478.11 | F29: 95.68 | G29: =E29*F29 -> 237105.56 | H29: 0 | I29: 0 | J29: =H29*I29 -> 0 | K29: =G29+J29 -> 237105.56 | M29: =M28+K29-L29 -> 13110775
A30: 27 | B30: 45835 | E30: 0 | F30: 0 | G30: =E30*F30 -> 0 | H30: 0 | I30: 0 | J30: =H30*I30 -> 0 | K30: =G30+J30 -> 0 | M30: =M29+K30-L30 -> 13110775
A31: 28 | B31: 45836 | C31: 3193 | D31: 1630 | E31: 2229.15 | F31: 95.68 | G31: =E31*F31 -> 213285.07 | H31: 0 | I31: 0 | J31: =H31*I31 -> 0 | K31: =G31+J31 -> 213285.07 | M31: =M30+K31-L31 -> 13324060
A32: 29 | B32: 45837 | D32: 1631 | E32: 2500 | F32: 95.68 | G32: =E32*F32 -> 239200 | H32: 20 | I32: 107.46 | J32: =H32*I32 -> 2149.2 | K32: =G32+J32 -> 241349.2 | M32: =M31+K32-L32 -> 13565410
A33: 30 | B33: 45838 | E33: 0 | F33: 0 | G33: =E33*F33 -> 0 | H33: 0 | I33: 0 | J33: =H33*I33 -> 0 | K33: =G33+J33 -> 0 | M33: =M32+K33-L33 -> 13565410
A34: 31 | E34: 0 | F34: 0 | G34: =E34*F34 -> 0 | H34: 0 | I34: 0 | J34: =H34*I34 -> 0 | K34: =G34+J34 -> 0 | M34: =M33+K34-L34 -> 13565410
A35: 32 | E35: 0 | F35: 0 | G35: =E35*F35 -> 0 | H35: 0 | I35: 0 | J35: =H35*I35 -> 0 | K35: =G35+J35 -> 0
A36: 33
E37: =SUM(E3:E36) -> 148695.59 | G37: =SUM(G3:G36) -> 14227153 | H37: =SUM(H3:H36) -> 630 | J37: =SUM(J3:J36) -> 67699.8 | K37: =SUM(K4:K36) -> 14294853 | L37: =SUM(L3:L36) -> 10036782

Sheet Khammam-3
A1: Jayasai union bunk
A2: S.No | B2: Date | C2: GRN No | D2: Ind No/Bill No | E2: Diesel (Lts) | F2: Price | G2: Amount | H2: Petrol (Lts) | I2: Price | J2: Amount | K2: Total amount | L2: Amount paid | M2: As 0n Date | N2: Remarks
A3: Opening Balance | K3: 7457303.4 | M3: =+K3 -> 7457303.4
A4: 1 | B4: 45809 | D4: 2924 | E4: =2500+1800 -> 4300 | F4: 95.7 | G4: =E4*F4 -> 411510 | H4: 0 | I4: 0 | J4: 0 | K4: =G4+J4 -> 411510 | M4: =M3+K4-L4 -> 7868813.4
A5: 2 | B5: 45810 | C5: 2924 | D5: 2932 | E5: 2384.25 | F5: 95.7 | G5: =E5*F5 -> 228172.73 | H5: 0 | I5: 0 | J5: 0 | K5: =G5+J5 -> 228172.73 | M5: =M4+K5-L5 -> 8096986.1
A6: 3 | B6: 45811 | C6: 2941 | D6: 2558/2557 | E6: 5299.96 | F6: 95.7 | G6: =E6*F6 -> 507206.17 | H6: 0 | I6: 0 | J6: 0 | K6: =G6+J6 -> 507206.17 | M6: =M5+K6-L6 -> 8604192.3
A7: 4 | B7: 45812 | C7: 2952 | D7: 2562 | E7: 2503.07 | F7: 95.7 | G7: =E7*F7 -> 239543.8 | H7: 0 | I7: 0 | J7: 0 | K7: =G7+J7 -> 239543.8 | M7: =M6+K7-L7 -> 8843736.1
A8: 5 | B8: 45813 | C8: 2963 | D8: 2579 | E8: 3024.9 | F8: 95.7 | G8: =E8*F8 -> 289482.93 | H8: 0 | I8: 0 | J8: 0 | K8: =G8+J8 -> 289482.93 | L8: 8843736.1 | M8: =M7+K8-L8 -> 289482.93
A9: 6 | B9: 45814 | C9: 2964 | D9: 2591/2590 | E9: 2700 | F9: 95.7 | G9: =E9*F9 -> 258390 | H9: 0 | I9: 0 | J9: 0 | K9: =G9+J9 -> 258390 | M9: =M8+K9-L9 -> 547872.93
A10: 7 | B10: 45815 | C10: 2987 | D10: 2601/2610 | E10: 2160.57 | F10: 95.7 | G10: =E10*F10 -> 206766.55 | H10: 37.98 | I10: 107.48 | J10: =H10*I10 -> 4082.0904 | K10: =G10+J10 -> 210848.64 | M10: =M9+K10-L10 -> 758721.57
A11: 8 | B11: 45816 | C11: 2990 | D11: 2617 | E11: 2321.49 | F11: 95.7 | G11: =E11*F11 -> 222166.59 | H11: 0 | I11: 0 | J11: =H11*I11 -> 0 | K11: =G11+J11 -> 222166.59 | M11: =M10+K11-L11 -> 980888.16
A12: 9 | B12: 45817 | C12: 3001 | D12: 2628/2630/2634/2636/2640 | E12: 10345.15 | F12: 95.7 | G12: =E12*F12 -> 990030.85 | H12: 95 | I12: 107.48 | J12: =H12*I12 -> 10210.6 | K12: =G12+J12 -> 1000241.5 | M12: =M11+K12-L12 -> 1981129.6
A13: 10 | B13: 45818 | E13: 0 | F13: 0 | G13: =E13*F13 -> 0 | H13: 0 | I13: 0 | J13: =H13*I13 -> 0 | K13: =G13+J13 -> 0 | M13: =M12+K13-L13 -> 1981129.6
A14: 11 | B14: 45819 | E14: 0 | F14: 0 | G14: =E14*F14 -> 0 | H14: 0 | I14: 0 | J14: =H14*I14 -> 0 | K14: =G14+J14 -> 0 | M14: =M13+K14-L14 -> 1981129.6
A15: 12 | B15: 45820 | E15: 0 | F15: 0 | G15: =E15*F15 -> 0 | H15: 0 | I15: 0 | J15: =H15*I15 -> 0 | K15: =G15+J15 -> 0 | M15: =M14+K15-L15 -> 1981129.6
A16: 13 | B16: 45821 | E16: 0 | F16: 0 | G16: =E16*F16 -> 0 | H16: 0 | I16: 0 | J16: =H16*I16 -> 0 | K16: =G16+J16 -> 0 | M16: =M15+K16-L16 -> 1981129.6
A17: 14 | B17: 45822 | E17: 0 | F17: 0 | G17: =E17*F17 -> 0 | H17: 0 | I17: 0 | J17: =H17*I17 -> 0 | K17: =G17+J17 -> 0 | M17: =M16+K17-L17 -> 1981129.6
A18: 15 | B18: 45823 | E18: 0 | F18: 0 | G18: =E18*F18 -> 0 | H18: 0 | I18: 0 | J18: =H18*I18 -> 0 | K18: =G18+J18 -> 0 | M18: =M17+K18-L18 -> 1981129.6
A19: 16 | B19: 45824 | E19: 0 | F19: 0 | G19: =E19*F19 -> 0 | H19: 0 | I19: 0 | J19: =H19*I19 -> 0 | K19: =G19+J19 -> 0 | M19: =M18+K19-L19 -> 1981129.6
A20: 17 | B20: 45825 | C20: 3073 | D20: 2657/2663/2664 | E20: 3029.76 | F20: 95.7 | G20: =E20*F20 -> 289948.03 | H20: 20 | I20: 107.48 | J20: =H20*I20 -> 2149.6 | K20: =G20+J20 -> 292097.63 | M20: =M19+K20-L20 -> 2273227.2
A21: 18 | B21: 45826 | C21: 3084 | D21: 2670/2674/2676/2679 | E21: 7800 | F21: 95.7 | G21: =E21*F21 -> 746460 | H21: 20 | I21: 107.48 | J21: =H21*I21 -> 2149.6 | K21: =G21+J21 -> 748609.6 | M21: =M20+K21-L21 -> 3021836.8
A22: 19 | B22: 45827 | C22: 3105 | D22: 2686/2689/2692/2695 | E22: 7500 | F22: 95.7 | G22: =E22*F22 -> 717750 | H22: 60 | I22: 107.48 | J22: =H22*I22 -> 6448.8 | K22: =G22+J22 -> 724198.8 | M22: =M21+K22-L22 -> 3746035.6
A23: 20 | B23: 45828 | C23: 3121 | D23: 2706/2710/2714/2716 | E23: 10300 | F23: 95.7 | G23: =E23*F23 -> 985710 | H23: 40 | I23: 107.48 | J23: =H23*I23 -> 4299.2 | K23: =G23+J23 -> 990009.2 | M23: =M22+K23-L23 -> 4736044.8 | O23: x
A24: 21 | B24: 45829 | E24: 0 | F24: 0 | G24: =E24*F24 -> 0 | H24: 0 | I24: 0 | J24: =H24*I24 -> 0 | K24: =G24+J24 -> 0 | M24: =M23+K24-L24 -> 4736044.8
A25: 22 | B25: 45830 | D25: 2731/2726/2739/2740 | E25: 10000 | F25: 95.7 | G25: =E25*F25 -> 957000 | H25: 20 | I25: 107.48 | J25: =H25*I25 -> 2149.6 | K25: =G25+J25 -> 959149.6 | M25: =M24+K25-L25 -> 5695194.4
A26: 23 | B26: 45831 | C26: 3152 | D26: 2755/2757/2763 | E26: 5300 | F26: 95.7 | G26: =E26*F26 -> 507210 | H26: 20 | I26: 107.48 | J26: =H26*I26 -> 2149.6 | K26: =G26+J26 -> 509359.6 | M26: =M25+K26-L26 -> 6204554
A27: 24 | B27: 45832 | C27: 3155 | D27: 2763/2770/2772/2774 | E27: 7800 | F27: 95.7 | G27: =E27*F27 -> 746460 | H27: 75 | I27: 107.48 | J27: =H27*I27 -> 8061 | K27: =G27+J27 -> 754521 | M27: =M26+K27-L27 -> 6959075
A28: 25 | B28: 45833 | C28: 3170 | D28: 2782/2787 | E28: 6200 | F28: 95.7 | G28: =E28*F28 -> 593340 | H28: 0 | I28: 0 | J28: =H28*I28 -> 0 | K28: =G28+J28 -> 593340 | M28: =M27+K28-L28 -> 7552415
A29: 26 | B29: 45834 | C29: 3173 | D29: 2791/2798/2802/2806 | E29: 9800 | F29: 95.7 | G29: =E29*F29 -> 937860 | H29: 20 | I29: 107.48 | J29: =H29*I29 -> 2149.6 | K29: =G29+J29 -> 940009.6 | M29: =M28+K29-L29 -> 8492424.6
A30: 27 | B30: 45835 | C30: 3190 | D30: 2808/2814/1816/1819 | E30: 8600 | F30: 95.7 | G30: =E30*F30 -> 823020 | H30: 75 | I30: 107.48 | J30: =H30*I30 -> 8061 | K30: =G30+J30 -> 831081 | M30: =M29+K30-L30 -> 9323505.6
A31: 28 | B31: 45836 | C31: 3194 | D31: 2822/2824/2827 | E31: 7300 | F31: 95.7 | G31: =E31*F31 -> 698610 | H31: 20 | I31: 107.48 | J31: =H31*I31 -> 2149.6 | K31: =G31+J31 -> 700759.6 | M31: =M30+K31-L31 -> 10024265
A32: 29 | B32: 45837 | C32: 3207 | D32: 2839 | E32: 696.99 | F32: 95.7 | G32: =E32*F32 -> 66701.943 | H32: 0 | I32: 0 | J32: =H32*I32 -> 0 | K32: =G32+J32 -> 66701.943 | M32: =M31+K32-L32 -> 10090967
A33: 30 | B33: 45838 | C33: 3208 | D33: 2852 | E33: 2100 | F33: 95.7 | G33: =E33*F33 -> 200970 | H33: 0 | I33: 0 | J33: =H33*I33 -> 0 | K33: =G33+J33 -> 200970 | M33: =M32+K33-L33 -> 10291937
A34: 31 | E34: 0 | F34: 0 | G34: =E34*F34 -> 0 | H34: 0 | I34: 0 | J34: =H34*I34 -> 0 | K34: =G34+J34 -> 0 | M34: =M33+K34-L34 -> 10291937
E35: =SUM(E4:E34) -> 121466.14 | G35: =SUM(G4:G34) -> 11624310 | H35: =SUM(H4:H34) -> 502.98 | J35: =SUM(J4:J34) -> 54060.29 | K35: =SUM(K4:K34) -> 11678370 | L35: =SUM(L4:L34) -> 8843736.1

Sheet Jedcherla -1
A1: Sai Baba Fuel Station
A2: S.No | B2: Date | C2: GRN No | D2: Ind No/Bill No | E2: Diesel (Lts) | F2: Price | G2: Amount | H2: Petrol (Lts) | I2: Price | J2: Amount | K2: Total amount | L2: Amount paid | M2: As on date | N2: Remarks
A3: Opening Balance | K3: 1149870.8 | M3: =+K3 -> 1149870.8
A4: 1 | B4: 45809 | E4: 0 | F4: 0 | G4: 0 | H4: 0 | I4: 0 | J4: =H4*I4 -> 0 | K4: =G4+J4 -> 0 | L4: 0 | M4: =M3+K4-L4 -> 1149870.8 | P4: 2259050
A5: 2 | B5: 45810 | E5: 2400 | F5: 96.42 | G5: =E5*F5 -> 231408 | H5: 19 | I5: 108.23 | J5: =H5*I5 -> 2056.37 | K5: =G5+J5 -> 233464.37 | L5: 0 | M5: =M4+K5-L5 -> 1383335.2
A6: 3 | B6: 45811 | E6: 0 | F6: 0 | G6: =E6*F6 -> 0 | H6: 35 | I6: 108.23 | J6: =H6*I6 -> 3788.05 | K6: =G6+J6 -> 3788.05 | L6: 0 | M6: =M5+K6-L6 -> 1387123.2
A7: 4 | B7: 45812 | E7: 2400 | F7: 96.42 | G7: =E7*F7 -> 231408 | H7: 5 | I7: 108.23 | J7: =H7*I7 -> 541.15 | K7: =G7+J7 -> 231949.15 | L7: 0 | M7: =M6+K7-L7 -> 1619072.4
A8: 5 | B8: 45813 | E8: 0 | F8: 0 | G8: =E8*F8 -> 0 | H8: 15 | I8: 108.23 | J8: =H8*I8 -> 1623.45 | K8: =G8+J8 -> 1623.45 | L8: 1619072 | M8: =M7+K8-L8 -> 1623.817 | P8: 23434
A9: 6 | B9: 45814 | E9: 2200 | F9: 96.42 | G9: =E9*F9 -> 212124 | H9: 20 | I9: 108.23 | J9: =H9*I9 -> 2164.6 | K9: =G9+J9 -> 214288.6 | L9: 0 | M9: =M8+K9-L9 -> 215912.42
A10: 7 | B10: 45815 | E10: 34.43 | F10: 96.42 | G10: =E10*F10 -> 3319.7406 | H10: 15 | I10: 108.23 | J10: =H10*I10 -> 1623.45 | K10: =G10+J10 -> 4943.1906 | L10: 0 | M10: =M9+K10-L10 -> 220855.61 | P10: =1619072*96.42 -> 1.5611092e+08
A11: 8 | B11: 45816 | E11: 1500 | F11: 96.42 | G11: =E11*F11 -> 144630 | H11: 29 | I11: 108.23 | J11: =H11*I11 -> 3138.67 | K11: =G11+J11 -> 147768.67 | L11: 0 | M11: =M10+K11-L11 -> 368624.28
A12: 9 | B12: 45817 | E12: 0 | F12: 0 | G12: =E12*F12 -> 0 | H12: 12 | I12: 108.23 | J12: =H12*I12 -> 1298.76 | K12: =G12+J12 -> 1298.76 | L12: 0 | M12: =M11+K12-L12 -> 369923.04
A13: 10 | B13: 45818 | C13: 1539.16 | D13: 0 | E13: 1539.16 | F13: 96.42 | G13: =E13*F13 -> 148405.81 | H13: 5 | I13: 108.23 | J13: =H13*I13 -> 541.15 | K13: =G13+J13 -> 148946.96 | L13: 0 | M13: =M12+K13-L13 -> 518869.99
A14: 11 | B14: 45819 | E14: 0 | F14: 0 | G14: =E14*F14 -> 0 | H14: 25 | I14: 108.23 | J14: =H14*I14 -> 2705.75 | K14: =G14+J14 -> 2705.75 | L14: 0 | M14: =M13+K14-L14 -> 521575.74 | S14: =1539-1490 -> 49
A15: 12 | B15: 45820 | E15: 1730.01 | F15: 96.42 | G15: =E15*F15 -> 166807.56 | H15: 10 | I15: 108.23 | J15: =H15*I15 -> 1082.3 | K15: =G15+J15 -> 167889.86 | L15: 0 | M15: =M14+K15-L15 -> 689465.61 | S15: =1730-1958 -> -228
A16: 13 | B16: 45821 | E16: 228 | F16: 96.42 | G16: =E16*F16 -> 21983.76 | H16: 20 | I16: 108.23 | J16: =H16*I16 -> 2164.6 | K16: =G16+J16 -> 24148.36 | L16: 0 | M16: =M15+K16-L16 -> 713613.97
A17: 14 | B17: 45822 | E17: 2032 | F17: 96.42 | G17: =E17*F17 -> 195925.44 | H17: 10 | I17: 108.23 | J17: =H17*I17 -> 1082.3 | K17: =G17+J17 -> 197007.74 | L17: 0 | M17: =M16+K17-L17 -> 910621.71
A18: 15 | B18: 45823 | D18: 2000 | E18: 0 | F18: 0 | G18: =E18*F18 -> 0 | H18: 15 | I18: 108.23 | J18: =H18*I18 -> 1623.45 | K18: =G18+J18 -> 1623.45 | L18: 0 | M18: =M17+K18-L18 -> 912245.16
A19: 16 | B19: 45824 | D19: 1000 | E19: 3000 | F19: 96.42 | G19: =E19*F19 -> 289260 | H19: 20 | I19: 108.23 | J19: =H19*I19 -> 2164.6 | K19: =G19+J19 -> 291424.6 | L19: 0 | M19: =M18+K19-L19 -> 1203669.8
A20: 17 | B20: 45825 | E20: 2053.97 | F20: 96.42 | G20: =E20*F20 -> 198043.79 | H20: 15 | I20: 108.23 | J20: =H20*I20 -> 1623.45 | K20: =G20+J20 -> 199667.24 | L20: 0 | M20: =M19+K20-L20 -> 1403337
A21: 18 | B21: 45826 | D21: 2200 | E21: 0 | F21: 96.42 | G21: =E21*F21 -> 0 | H21: 20 | I21: 108.23 | J21: =H21*I21 -> 2164.6 | K21: =G21+J21 -> 2164.6 | L21: 0 | M21: =M20+K21-L21 -> 1405501.6
A22: 19 | B22: 45827 | C22: 2500 | D22: 0 | E22: 2500 | F22: 96.42 | G22: =E22*F22 -> 241050 | H22: 20 | I22: 108.23 | J22: =H22*I22 -> 2164.6 | K22: =G22+J22 -> 243214.6 | L22: 0 | M22: =M21+K22-L22 -> 1648716.2 | P22: 2422641
A23: 20 | B23: 45828 | E23: 0 | F23: 0 | G23: =E23*F23 -> 0 | H23: 16.35 | I23: 108.23 | J23: =H23*I23 -> 1769.5605 | K23: =G23+J23 -> 1769.5605 | L23: 0 | M23: =M22+K23-L23 -> 1650485.8 | P23: 2419549
A24: 21 | B24: 45829 | E24: 2830 | F24: 96.42 | G24: =E24*F24 -> 272868.6 | H24: 20 | I24: 108.23 | J24: =H24*I24 -> 2164.6 | K24: =G24+J24 -> 275033.2 | L24: 0 | M24: =M23+K24-L24 -> 1925519 | P24: =P23-P22 -> -3092
A25: 22 | B25: 45830 | E25: 0 | F25: 0 | G25: =E25*F25 -> 0 | H25: 5 | I25: 108.23 | J25: =H25*I25 -> 541.15 | K25: =G25+J25 -> 541.15 | L25: 0 | M25: =M24+K25-L25 -> 1926060.1
A26: 23 | B26: 45831 | E26: 2030.8 | F26: 96.42 | G26: =E26*F26 -> 195809.74 | H26: 15 | I26: 108.23 | J26: =H26*I26 -> 1623.45 | K26: =G26+J26 -> 197433.19 | L26: 0 | M26: =M25+K26-L26 -> 2123493.3
A27: 24 | B27: 45832 | E27: 0 | F27: 0 | G27: =E27*F27 -> 0 | H27: 24 | I27: 108.23 | J27: =H27*I27 -> 2597.52 | K27: =G27+J27 -> 2597.52 | L27: 0 | M27: =M26+K27-L27 -> 2126090.8
A28: 25 | B28: 45833 | E28: 0 | F28: 0 | G28: =E28*F28 -> 0 | H28: 10 | I28: 108.23 | J28: =H28*I28 -> 1082.3 | K28: =G28+J28 -> 1082.3 | L28: 0 | M28: =M27+K28-L28 -> 2127173.1 | U28: =2139146-M35 -> -0.1929
A29: 26 | B29: 45834 | E29: 0 | F29: 0 | G29: =E29*F29 -> 0 | H29: 20 | I29: 108.23 | J29: =H29*I29 -> 2164.6 | K29: =G29+J29 -> 2164.6 | L29: 0 | M29: =M28+K29-L29 -> 2129337.7
A30: 27 | B30: 45835 | E30: 35.5 | F30: 96.42 | G30: =E30*F30 -> 3422.91 | H30: 20 | I30: 108.23 | J30: =H30*I30 -> 2164.6 | K30: =G30+J30 -> 5587.51 | L30: 0 | M30: =M29+K30-L30 -> 2134925.2
A31: 28 | B31: 45836 | E31: 0 | F31: 0 | G31: =E31*F31 -> 0 | H31: 15 | I31: 108.23 | J31: =H31*I31 -> 1623.45 | K31: =G31+J31 -> 1623.45 | L31: 0 | M31: =M30+K31-L31 -> 2136548.7
A32: 29 | B32: 45837 | E32: 0 | F32: 0 | G32: =E32*F32 -> 0 | H32: 15 | I32: 108.23 | J32: =H32*I32 -> 1623.45 | K32: =G32+J32 -> 1623.45 | L32: 0 | M32: =M31+K32-L32 -> 2138172.1
A33: 30 | B33: 45838 | E33: 0 | F33: 0 | G33: =E33*F33 -> 0 | H33: 9 | I33: 108.23 | J33: =H33*I33 -> 974.07 | K33: =G33+J33 -> 974.07 | L33: 0 | M33: =M32+K33-L33 -> 2139146.2
A34: 31 | E34: 0 | F34: 0 | G34: =E34*F34 -> 0 | H34: 0 | I34: 0 | J34: =H34*I34 -> 0 | K34: =G34+J34 -> 0 | L34: 0 | M34: =M33+K34-L34 -> 2139146.2
E35: 0 | F35: 0 | G35: =E35*F35 -> 0 | H35: 0 | I35: 0 | J35: =H35*I35 -> 0 | K35: =G35+J35 -> 0 | M35: =M34+K35-L35 -> 2139146.2
E36: =SUM(E4:E34) -> 26513.87 | G36: =SUM(G4:G34) -> 2556467.3 | H36: =SUM(H4:H34) -> 479.35 | J36: =SUM(J4:J34) -> 51880.05 | K36: =SUM(K4:K34) -> 2608347.4 | L36: =SUM(L4:L34) -> 1619072
E38: 26130
E39: =E36-E38 -> 383.87

Sheet Jedcherla-2
A1: Uttara Enterprises
A2: S.No | B2: Date | C2: GRN No | D2: Ind No/Bill No | E2: Diesel (Lts) | F2: Price | G2: Amount | H2: Petrol (Lts) | I2: Price | J2: Amount | K2: Total amount | L2: Amount paid | M2: As on Date | N2: Remarks
A3: Opening Balance | K3: 331699.53 | M3: =+K3 -> 331699.53
A4: 1 | B4: 45809 | G4: =E4*F4 -> 0 | J4: =H4*I4 -> 0 | K4: =G4+J4 -> 0 | M4: =M3+K4-L4 -> 331699.53
A5: 2 | B5: 45810 | E5: 0 | F5: 0 | G5: =E5*F5 -> 0 | J5: =H5*I5 -> 0 | K5: =G5+J5 -> 0 | M5: =M4+K5-L5 -> 331699.53
A6: 3 | B6: 45811 | E6: 0 | F6: 0 | G6: =E6*F6 -> 0 | J6: =H6*I6 -> 0 | K6: =G6+J6 -> 0 | M6: =M5+K6-L6 -> 331699.53 | R6: 541.08
A7: 4 | B7: 45812 | E7: 0 | F7: 0 | G7: =E7*F7 -> 0 | J7: =H7*I7 -> 0 | K7: =G7+J7 -> 0 | L7: 331700 | M7: =M6+K7-L7 -> -0.4737
A8: 5 | B8: 45813 | E8: 0 | F8: 0 | G8: =E8*F8 -> 0 | J8: =H8*I8 -> 0 | K8: =G8+J8 -> 0 | M8: =M7+K8-L8 -> -0.4737
A9: 6 | B9: 45814 | E9: 0 | F9: 0 | G9: =E9*F9 -> 0 | J9: =H9*I9 -> 0 | K9: =G9+J9 -> 0 | M9: =M8+K9-L9 -> -0.4737
A10: 7 | B10: 45815 | E10: 0 | F10: 0 | G10: =E10*F10 -> 0 | J10: =H10*I10 -> 0 | K10: =G10+J10 -> 0 | M10: =M9+K10-L10 -> -0.4737
A11: 8 | B11: 45816 | E11: 0 | F11: 0 | G11: =E11*F11 -> 0 | J11: =H11*I11 -> 0 | K11: =G11+J11 -> 0 | M11: =M10+K11-L11 -> -0.4737
A12: 9 | B12: 45817 | E12: 0 | F12: 0 | G12: =E12*F12 -> 0 | J12: =H12*I12 -> 0 | K12: =G12+J12 -> 0 | M12: =M11+K12-L12 -> -0.4737
A13: 10 | B13: 45818 | E13: 0 | F13: 0 | G13: =E13*F13 -> 0 | J13: =H13*I13 -> 0 | K13: =G13+J13 -> 0 | M13: =M12+K13-L13 -> -0.4737
A14: 11 | B14: 45819 | E14: 0 | F14: 0 | G14: =E14*F14 -> 0 | J14: =H14*I14 -> 0 | K14: =G14+J14 -> 0 | M14: =M13+K14-L14 -> -0.4737
A15: 12 | B15: 45820 | E15: 0 | F15: 0 | G15: =E15*F15 -> 0 | J15: =H15*I15 -> 0 | K15: =G15+J15 -> 0 | M15: =M14+K15-L15 -> -0.4737
A16: 13 | B16: 45821 | E16: 0 | F16: 0 | G16: =E16*F16 -> 0 | J16: =H16*I16 -> 0 | K16: =G16+J16 -> 0 | M16: =M15+K16-L16 -> -0.4737
A17: 14 | B17: 45822 | E17: 0 | F17: 0 | G17: =E17*F17 -> 0 | J17: =H17*I17 -> 0 | K17: =G17+J17 -> 0 | M17: =M16+K17-L17 -> -0.4737
A18: 15 | B18: 45823 | E18: 0 | F18: 0 | G18: =E18*F18 -> 0 | J18: =H18*I18 -> 0 | K18: =G18+J18 -> 0 | M18: =M17+K18-L18 -> -0.4737
A19: 16 | B19: 45824 | E19: 0 | F19: 0 | G19: =E19*F19 -> 0 | J19: =H19*I19 -> 0 | K19: =G19+J19 -> 0 | M19: =M18+K19-L19 -> -0.4737
... A29: 26 | B29: 45834 | E29: 0 | F29: 0 | G29: =E29*F29 -> 0 | J29: =H29*I29 -> 0 | K29: =G29+J29 -> 0 | M29: =M28+K29-L29 -> -0.4737
A30: 27 | B30: 45835 | E30: 0 | F30: 0 | G30: =E30*F30 -> 0 | J30: =H30*I30 -> 0 | K30: =G30+J30 -> 0 | M30: =M29+K30-L30 -> -0.4737 | P30: =2939612.08-2939070.93 -> 541.15
A31: 28 | B31: 45836 | E31: 0 | F31: 0 | G31: =E31*F31 -> 0 | J31: =H31*I31 -> 0 | K31: =G31+J31 -> 0 | M31: =M30+K31-L31 -> -0.4737
A32: 29 | B32: 45837 | E32: 0 | F32: 0 | G32: =E32*F32 -> 0 | J32: =H32*I32 -> 0 | K32: =G32+J32 -> 0
A33: 30 | B33: 45838 | E33: 0 | F33: 0 | G33: =E33*F33 -> 0 | J33: =H33*I33 -> 0 | K33: =G33+J33 -> 0
A34: 31 | E34: 0 | F34: 0 | G34: =E34*F34 -> 0 | J34: =H34*I34 -> 0 | K34: =G34+J34 -> 0
E35: =SUM(E4:E34) -> 0 | G35: =SUM(G4:G34) -> 0 | H35: =SUM(H4:H34) -> 0 | J35: =SUM(J4:J34) -> 0 | K35: =SUM(K4:K34) -> 0 | L35: =SUM(L4:L34) -> 331700

Sheet Jedcharla-3
A1: ADHOC FILLING STATION STATION
A2: S.No | B2: Date | C2: GRN No | D2: Ind No/Bill No | E2: Diesel (Lts) | F2: Price | G2: Amount | H2: Petrol (Lts) | I2: Price | J2: Amount | K2: Total amount | L2: Amount paid | M2: As on Date | N2: Remarks
A3: Opening Balance | K3: 0 | M3: =+K3 -> 0
A4: 1 | B4: 45809 | E4: 2400 | F4: 96.43 | G4: =E4*F4 -> 231432 | J4: =H4*I4 -> 0 | K4: =G4+J4 -> 231432 | M4: =M3+K4-L4 -> 231432
A5: 2 | B5: 45810 | G5: =E5*F5 -> 0 | J5: =H5*I5 -> 0 | K5: =G5+J5 -> 0 | M5: =M4+K5-L5 -> 231432
A6: 3 | B6: 45811 | E6: 2100 | F6: 96.43 | G6: =E6*F6 -> 202503 | J6: =H6*I6 -> 0 | K6: =G6+J6 -> 202503 | M6: =M5+K6-L6 -> 433935 | R6: 541.08
A7: 4 | B7: 45812 | G7: =E7*F7 -> 0 | J7: =H7*I7 -> 0 | K7: =G7+J7 -> 0 | M7: =M6+K7-L7 -> 433935
A8: 5 | B8: 45813 | E8: 2400 | F8: 96.43 | G8: =E8*F8 -> 231432 | J8: =H8*I8 -> 0 | K8: =G8+J8 -> 231432 | L8: 433935 | M8: =M7+K8-L8 -> 231432
A9: 6 | B9: 45814 | G9: =E9*F9 -> 0 | J9: =H9*I9 -> 0 | K9: =G9+J9 -> 0 | M9: =M8+K9-L9 -> 231432
A10: 7 | B10: 45815 | E10: 2460 | F10: 96.43 | G10: =E10*F10 -> 237217.8 | J10: =H10*I10 -> 0 | K10: =G10+J10 -> 237217.8 | M10: =M9+K10-L10 -> 468649.8
A11: 8 | B11: 45816 | G11: =E11*F11 -> 0 | J11: =H11*I11 -> 0 | K11: =G11+J11 -> 0 | M11: =M10+K11-L11 -> 468649.8
A12: 9 | B12: 45817 | E12: 1428 | F12: 96.43 | G12: =E12*F12 -> 137702.04 | J12: =H12*I12 -> 0 | K12: =G12+J12 -> 137702.04 | M12: =M11+K12-L12 -> 606351.84
A13: 10 | B13: 45818 | E13: 0 | G13: =E13*F13 -> 0 | J13: =H13*I13 -> 0 | K13: =G13+J13 -> 0 | M13: =M12+K13-L13 -> 606351.84
A14: 11 | B14: 45819 | E14: 1400 | F14: 96.43 | G14: =E14*F14 -> 135002 | J14: =H14*I14 -> 0 | K14: =G14+J14 -> 135002 | M14: =M13+K14-L14 -> 741353.84
A15: 12 | B15: 45820 | G15: =E15*F15 -> 0 | J15: =H15*I15 -> 0 | K15: =G15+J15 -> 0 | M15: =M14+K15-L15 -> 741353.84
A16: 13 | B16: 45821 | E16: 2000 | F16: 96.43 | G16: =E16*F16 -> 192860 | J16: =H16*I16 -> 0 | K16: =G16+J16 -> 192860 | M16: =M15+K16-L16 -> 934213.84
A17: 14 | B17: 45822 | G17: =E17*F17 -> 0 | J17: =H17*I17 -> 0 | K17: =G17+J17 -> 0 | M17: =M16+K17-L17 -> 934213.84
A18: 15 | B18: 45823 | E18: 1200 | F18: 96.43 | G18: =E18*F18 -> 115716 | J18: =H18*I18 -> 0 | K18: =G18+J18 -> 115716 | M18: =M17+K18-L18 -> 1049929.8
A19: 16 | B19: 45824 | G19: =E19*F19 -> 0 | J19: =H19*I19 -> 0 | K19: =G19+J19 -> 0 | M19: =M18+K19-L19 -> 1049929.8
A20: 17 | B20: 45825 | G20: =E20*F20 -> 0 | J20: =H20*I20 -> 0 | K20: =G20+J20 -> 0 | M20: =M19+K20-L20 -> 1049929.8
A21: 18 | B21: 45826 | E21: 2200 | F21: 96.43 | G21: =E21*F21 -> 212146 | J21: =H21*I21 -> 0 | K21: =G21+J21 -> 212146 | M21: =M20+K21-L21 -> 1262075.8 | P21: 2200 | Q21: =2200*96.43 -> 212146
A22: 19 | B22: 45827 | E22: 1500 | F22: 96.43 | G22: =E22*F22 -> 144645 | J22: =H22*I22 -> 0 | K22: =G22+J22 -> 144645 | M22: =M21+K22-L22 -> 1406720.8
A23: 20 | B23: 45828 | G23: =E23*F23 -> 0 | J23: =H23*I23 -> 0 | K23: =G23+J23 -> 0 | M23: =M22+K23-L23 -> 1406720.8
A24: 21 | B24: 45829 | G24: =E24*F24 -> 0 | J24: =H24*I24 -> 0 | K24: =G24+J24 -> 0 | M24: =M23+K24-L24 -> 1406720.8
A25: 22 | B25: 45830 | E25: 2000 | F25: 96.43 | G25: =E25*F25 -> 192860 | J25: =H25*I25 -> 0 | K25: =G25+J25 -> 192860 | M25: =M24+K25-L25 -> 1599580.8
A26: 23 | B26: 45831 | G26: =E26*F26 -> 0 | J26: =H26*I26 -> 0 | K26: =G26+J26 -> 0 | M26: =M25+K26-L26 -> 1599580.8
A27: 24 | B27: 45832 | E27: 3984.59 | F27: 96.43 | G27: =E27*F27 -> 384234.01 | J27: =H27*I27 -> 0 | K27: =G27+J27 -> 384234.01 | M27: =M26+K27-L27 -> 1983814.9
A28: 25 | B28: 45833 | E28: 4200 | F28: 96.43 | G28: =E28*F28 -> 405006 | J28: =H28*I28 -> 0 | K28: =G28+J28 -> 405006 | M28: =M27+K28-L28 -> 2388820.9
A29: 26 | B29: 45834 | E29: 1723 | F29: 96.43 | G29: =E29*F29 -> 166148.89 | J29: =H29*I29 -> 0 | K29: =G29+J29 -> 166148.89 | M29: =M28+K29-L29 -> 2554969.7 | P29: 4200
A30: 27 | B30: 45835 | E30: 2000 | F30: 96.43 | G30: =E30*F30 -> 192860 | J30: =H30*I30 -> 0 | K30: =G30+J30 -> 192860 | L30: 2300000 | M30: =M29+K30-L30 -> 447829.74
A31: 28 | B31: 45836 | E31: 2000 | F31: 96.43 | G31: =E31*F31 -> 192860 | J31: =H31*I31 -> 0 | K31: =G31+J31 -> 192860 | M31: =M30+K31-L31 -> 640689.74 | P31: =SUM(P21:P30) -> 6400 | Q31: =62008*6.43 -> 398711.44
A32: 29 | B32: 45837 | E32: 2400 | F32: 96.43 | G32: =E32*F32 -> 231432 | J32: =H32*I32 -> 0 | K32: =G32+J32 -> 231432 | M32: =M31+K32-L32 -> 872121.74
A33: 30 | B33: 45838 | E33: 3500 | F33: 96.43 | G33: =E33*F33 -> 337505 | J33: =H33*I33 -> 0 | K33: =G33+J33 -> 337505 | M33: =M32+K33-L33 -> 1209626.7
A34: 31 | G34: =E34*F34 -> 0 | J34: =H34*I34 -> 0 | K34: =G34+J34 -> 0 | M34: =M33+K34-L34 -> 1209626.7
E35: =SUM(E4:E34) -> 40895.59 | G35: =SUM(G4:G34) -> 3943561.7 | H35: =SUM(H4:H34) -> 0 | J35: =SUM(J4:J34) -> 0 | K35: =SUM(K4:K34) -> 3943561.7 | L35: =SUM(L4:L34) -> 2733935

Sheet Sangareddy
A1: Sree Shiva Parvathi Filling Station
A2: S.No | B2: Date | C2: GRN No | D2: Ind No/Bill No | E2: Diesel (Lts) | F2: Price | G2: Amount | H2: Petrol (Lts) | I2: Price | J2: Amount | K2: Total amount | L2: Amount paid | M2: As on Date | N2: Remarks
A3: Opening Balance | K3: 0 | M3: =+K3 -> 0
A4: 1 | B4: 45809 | E4: 0 | F4: 0 | G4: =E4*F4 -> 0 | H4: 0 | I4: 0 | J4: =H4*I4 -> 0 | K4: =G4+J4 -> 0 | M4: =M3+K4-L4 -> 0
A5: 2 | B5: 45810 | E5: 700 | F5: 96.23 | G5: =E5*F5 -> 67361 | H5: 0 | I5: 0 | J5: =H5*I5 -> 0 | K5: =G5+J5 -> 67361 | L5: =+K5 -> 67361 | M5: =M4+K5-L5 -> 0
A6: 3 | B6: 45811 | E6: 290 | F6: 96.23 | G6: =E6*F6 -> 27906.7 | H6: 0 | I6: 0 | J6: =H6*I6 -> 0 | K6: =G6+J6 -> 27906.7 | L6: =+K6 -> 27906.7 | M6: =M5+K6-L6 -> 0
B7: 45811 | E7: 400 | F7: 96.23 | G7: =E7*F7 -> 38492 | H7: 0 | I7: 0 | J7: =H7*I7 -> 0 | K7: =G7+J7 -> 38492 | M7: =M6+K7-L7 -> 38492
A8: 4 | B8: 45812 | E8: 100 | F8: 96.23 | G8: =E8*F8 -> 9623 | H8: 0 | I8: 0 | J8: =H8*I8 -> 0 | K8: =G8+J8 -> 9623 | L8: 48115 | M8: =M7+K8-L8 -> 0
A9: 5 | B9: 45813 | E9: 600 | F9: 96.23 | G9: =E9*F9 -> 57738 | H9: 0 | I9: 0 | J9: =H9*I9 -> 0 | K9: =G9+J9 -> 57738 | M9: =M8+K9-L9 -> 57738
A10: 6 | B10: 45814 | E10: 600 | F10: 96.23 | G10: =E10*F10 -> 57738 | H10: 0 | I10: 0 | J10: =H10*I10 -> 0 | K10: =G10+J10 -> 57738 | M10: =M9+K10-L10 -> 115476
A11: 7 | B11: 45815 | E11: 600 | F11: 96.23 | G11: =E11*F11 -> 57738 | H11: 20 | I11: 108.03 | J11: =H11*I11 -> 2160.6 | K11: =G11+J11 -> 59898.6 | M11: =M10+K11-L11 -> 175374.6
A12: 8 | B12: 45816 | E12: 0 | F12: 0 | G12: =E12*F12 -> 0 | H12: 0 | I12: 0 | J12: =H12*I12 -> 0 | K12: =G12+J12 -> 0 | M12: =M11+K12-L12 -> 175374.6
A13: 9 | B13: 45817 | E13: 0 | F13: 0 | G13: =E13*F13 -> 0 | H13: 0 | I13: 0 | J13: =H13*I13 -> 0 | K13: =G13+J13 -> 0 | M13: =M12+K13-L13 -> 175374.6
A14: 10 | B14: 45818 | E14: 0 | F14: 0 | G14: =E14*F14 -> 0 | H14: 0 | I14: 0 | J14: =H14*I14 -> 0 | K14: =G14+J14 -> 0 | M14: =M13+K14-L14 -> 175374.6
A15: 11 | B15: 45819 | E15: 600 | F15: 96.23 | G15: =E15*F15 -> 57738 | H15: 20 | I15: 108.03 | J15: =H15*I15 -> 2160.6 | K15: =G15+J15 -> 59898.6 | M15: =M14+K15-L15 -> 235273.2
A16: 12 | B16: 45820 | E16: 0 | F16: 0 | G16: =E16*F16 -> 0 | H16: 0 | I16: 0 | J16: =H16*I16 -> 0 | K16: =G16+J16 -> 0 | M16: =M15+K16-L16 -> 235273.2
A17: 13 | B17: 45821 | E17: 600 | F17: 96.23 | G17: =E17*F17 -> 57738 | H17: 0 | I17: 0 | J17: =H17*I17 -> 0 | K17: =G17+J17 -> 57738 | M17: =M16+K17-L17 -> 293011.2
A18: 14 | B18: 45822 | E18: 0 | F18: 0 | G18: =E18*F18 -> 0 | H18: 0 | I18: 0 | J18: =H18*I18 -> 0 | K18: =G18+J18 -> 0 | M18: =M17+K18-L18 -> 293011.2
A19: 15 | B19: 45823 | E19: 800 | F19: 96.23 | G19: =E19*F19 -> 76984 | H19: 20 | I19: 108.03 | J19: =H19*I19 -> 2160.6 | K19: =G19+J19 -> 79144.6 | M19: =M18+K19-L19 -> 372155.8
A20: 16 | B20: 45824 | E20: 0 | F20: 0 | G20: =E20*F20 -> 0 | H20: 0 | I20: 0 | J20: =H20*I20 -> 0 | K20: =G20+J20 -> 0 | M20: =M19+K20-L20 -> 372155.8
A21: 17 | B21: 45825 | E21: 0 | F21: 0 | G21: =E21*F21 -> 0 | H21: 0 | I21: 0 | J21: =H21*I21 -> 0 | K21: =G21+J21 -> 0 | M21: =M20+K21-L21 -> 372155.8
A22: 18 | B22: 45826 | E22: 800 | F22: 96.23 | G22: =E22*F22 -> 76984 | H22: 20 | I22: 108.03 | J22: =H22*I22 -> 2160.6 | K22: =G22+J22 -> 79144.6 | L22: 372155.8 | M22: =M21+K22-L22 -> 79144.6
A23: 19 | B23: 45827 | E23: 0 | F23: 0 | G23: =E23*F23 -> 0 | H23: 0 | I23: 0 | J23: =H23*I23 -> 0 | K23: =G23+J23 -> 0 | M23: =M22+K23-L23 -> 79144.6
A24: 20 | B24: 45828 | E24: 700 | F24: 96.23 | G24: =E24*F24 -> 67361 | H24: 20 | I24: 108.03 | J24: =H24*I24 -> 2160.6 | K24: =G24+J24 -> 69521.6 | M24: =M23+K24-L24 -> 148666.2
A25: 21 | B25: 45829 | E25: 0 | F25: 0 | G25: =E25*F25 -> 0 | H25: 0 | I25: 0 | J25: =H25*I25 -> 0 | K25: =G25+J25 -> 0 | M25: =M24+K25-L25 -> 148666.2
A26: 22 | B26: 45830 | E26: 600 | F26: 96.23 | G26: =E26*F26 -> 57738 | H26: 0 | I26: 0 | J26: =H26*I26 -> 0 | K26: =G26+J26 -> 57738 | M26: =M25+K26-L26 -> 206404.2
A27: 23 | B27: 45831 | E27: 0 | F27: 0 | G27: =E27*F27 -> 0 | H27: 0 | I27: 0 | J27: =H27*I27 -> 0 | K27: =G27+J27 -> 0 | M27: =M26+K27-L27 -> 206404.2
A28: 24 | B28: 45832 | E28: 800 | F28: 96.23 | G28: =E28*F28 -> 76984 | H28: 0 | I28: 0 | J28: =H28*I28 -> 0 | K28: =G28+J28 -> 76984 | M28: =M27+K28-L28 -> 283388.2
A29: 25 | B29: 45833 | E29: 0 | F29: 0 | G29: =E29*F29 -> 0 | H29: 0 | I29: 0 | J29: =H29*I29 -> 0 | K29: =G29+J29 -> 0 | M29: =M28+K29-L29 -> 283388.2
A30: 26 | B30: 45834 | E30: 0 | F30: 96.23 | G30: =E30*F30 -> 0 | H30: 0 | I30: 0 | J30: =H30*I30 -> 0 | K30: =G30+J30 -> 0 | M30: =M29+K30-L30 -> 283388.2
A31: 27 | B31: 45835 | E31: 0 | F31: 0 | G31: =E31*F31 -> 0 | H31: 0 | I31: 0 | J31: =H31*I31 -> 0 | K31: =G31+J31 -> 0 | M31: =M30+K31-L31 -> 283388.2
A32: 28 | B32: 45836 | E32: 800 | F32: 96.23 | G32: =E32*F32 -> 76984 | H32: 20 | I32: 108.23 | J32: =H32*I32 -> 2164.6 | K32: =G32+J32 -> 79148.6 | M32: =M31+K32-L32 -> 362536.8
A33: 29 | B33: 45837 | E33: 0 | F33: 0 | G33: =E33*F33 -> 0 | H33: 0 | I33: 0 | J33: =H33*I33 -> 0 | K33: =G33+J33 -> 0 | M33: =M32+K33-L33 -> 362536.8
A34: 30 | B34: 45838 | E34: 0 | F34: 0 | G34: =E34*F34 -> 0 | H34: 0 | I34: 0 | J34: =H34*I34 -> 0 | K34: =G34+J34 -> 0 | M34: =M33+K34-L34 -> 362536.8
... A39: 35 | B39: 45843 | E39: 0 | F39: 0 | G39: =E39*F39 -> 0 | H39: 0 | I39: 0 | J39: =H39*I39 -> 0 | K39: =G39+J39 -> 0 | M39: =M38+K39-L39 -> 362536.8
E40: =SUM(E4:E39) -> 8990 | G40: =SUM(G4:G39) -> 865107.7 | H40: =SUM(H4:H39) -> 120 | J40: =SUM(J4:J39) -> 12967.6 | K40: =SUM(K4:K39) -> 878075.3 | L40: =SUM(L4:L39) -> 515538.5

Sheet Dindi
A1: Akarapu Balakistamma Fillling
A2: S.No | B2: Date | C2: GRN No | D2: Ind no/Bill No | E2: Diesel (Lts) | F2: Price | G2: Amount | H2: Petrol (Lts) | I2: Price | J2: Amount | K2: Total amount | L2: Amount paid | M2: As on Date | N2: Remarks
A3: Opening Balance | M3: 0
A4: 1 | B4: 45809 | E4: 0 | F4: 0 | G4: =E4*F4 -> 0 | H4: 0 | I4: 0 | J4: =H4*I4 -> 0 | K4: =G4+J4 -> 0 | L4: =+K4 -> 0 | M4: 0
A5: 2 | B5: 45810 | E5: 0 | F5: 0 | G5: =E5*F5 -> 0 | H5: 0 | I5: 0 | J5: =H5*I5 -> 0 | K5: =G5+J5 -> 0 | L5: =+K5 -> 0 | M5: 0
A6: 3 | B6: 45811 | E6: 0 | F6: 0 | G6: =E6*F6 -> 0 | H6: 0 | I6: 0 | J6: =H6*I6 -> 0 | K6: =G6+J6 -> 0 | L6: =+K6 -> 0 | M6: 0
A7: 4 | B7: 45812 | E7: 51.64 | F7: 96.83 | G7: =E7*F7 -> 5000.3012 | H7: 0 | I7: 0 | J7: =H7*I7 -> 0 | K7: =G7+J7 -> 5000.3012 | L7: =+K7 -> 5000.3012 | M7: 0
A8: 5 | B8: 45813 | E8: 0 | F8: 0 | G8: =E8*F8 -> 0 | H8: 0 | I8: 0 | J8: =H8*I8 -> 0 | K8: =G8+J8 -> 0 | L8: =+K8 -> 0 | M8: 0
A9: 6 | B9: 45814 | E9: 0 | F9: 0 | G9: =E9*F9 -> 0 | H9: 0 | I9: 0 | J9: =H9*I9 -> 0 | K9: =G9+J9 -> 0 | L9: =+K9 -> 0 | M9: 0
A10: 7 | B10: 45815 | E10: 0 | F10: 0 | G10: =E10*F10 -> 0 | H10: 0 | I10: 0 | J10: =H10*I10 -> 0 | K10: =G10+J10 -> 0 | L10: =+K10 -> 0 | M10: 0
A11: 8 | B11: 45816 | E11: 0 | F11: 0 | G11: =E11*F11 -> 0 | H11: 0 | I11: 0 | J11: =H11*I11 -> 0 | K11: =G11+J11 -> 0 | L11: =+K11 -> 0 | M11: 0
A12: 9 | B12: 45817 | E12: 0 | F12: 0 | G12: =E12*F12 -> 0 | H12: 0 | I12: 0 | J12: =H12*I12 -> 0 | K12: =G12+J12 -> 0 | L12: =+K12 -> 0 | M12: 0
