Workbook

Sheet Sep-25 
A1: S.no | B1: Site Name | C1: Bunk Name | D1: Diesel(Liters) | E1: Diesel Amount | F1: Petrol(Liters) | G1: Petrol Amount | H1: Total Amount | I1: Opening Blance | J1: Amount Paid | K1: Closing Balances
A2: 1 | B2: Khammam-1 | C2: Divya laxmi ganapathi | D2: =+'Khammam-1'!E38 -> 79074.87 | E2: =+'Khammam-1'!G38 -> 7565836.6 | F2: =+'Khammam-1'!H38 -> 450 | G2: =+'Khammam-1'!J38 -> 48356.8 | H2: =E2+G2 -> 7614193.4 | I2: =+'Khammam-1'!K3 -> 11063503 | J2: =+'Khammam-1'!L38 -> 7500000 | K2: =H2+I2-J2 -> 11177697
A3: 2 | B3: Khammam-2 | C3: Jayasai union bunk | D3: =+'Khammam-2'!E35 -> 95538.08 | E3: =+'Khammam-2'!G35 -> 9142994.3 | F3: =+'Khammam-2'!H35 -> 475 | G3: =+'Khammam-2'!J35 -> 51053 | H3: =E3+G3 -> 9194047.3 | I3: =+'Khammam-2'!K3 -> 11749284 | J3: =+'Khammam-2'!L35 -> 7500000 | K3: =H3+I3-J3 -> 13443331
A4: 3 | B4: Jadcherla-1 | C4: Sai Baba Fuel Station | D4: =+'Jedcherla -1'!E37 -> 34171.99 | E4: =+'Jedcherla -1'!G37 -> 3294863.3 | F4: =+'Jedcherla -1'!H37 -> 592.72 | G4: =+'Jedcherla -1'!J37 -> 64150.086 | H4: =E4+G4 -> 3359013.4 | I4: =+'Jedcherla -1'!M3 -> 3836229.1 | J4: =+'Jedcherla -1'!L37 -> 4555327.9 | K4: =H4+I4-J4 -> 2639914.6
A5: 4 | B5: Jadcherla-2 | C5: ADHOC FILLING STATION STATION | D5: =+'Jedcharla-2'!E35 -> 23700 | E5: =+'Jedcharla-2'!G35 -> 2285391 | F5: 0 | G5: 0 | H5: =E5+G5 -> 2285391 | I5: =+'Jedcharla-2'!K3 -> 0 | J5: =+'Jedcharla-2'!L35 -> 2046458 | K5: =H5+I5-J5 -> 238933
A6: 6 | B6: Dindi | C6: Akarapu Balakistamma Fillling | D6: =+Dindi!E35 -> 118.69 | E6: =+Dindi!G35 -> 11458.416 | F6: =+Dindi!H35 -> 0 | G6: =+Dindi!J35 -> 0 | H6: =E6+G6 -> 11458.416 | J6: =+Dindi!L35 -> 11458.416 | K6: =H6+I6-J6 -> 0
A7: 7 | B7: Devarkhadra-1 | C7: Kurumurthy Swami F/S | D7: =+Devarakhadra!E35 -> 16286.75 | E7: =+Devarakhadra!G35 -> 1581443.4 | F7: =+Devarakhadra!H35 -> 145 | G7: =+Devarakhadra!J35 -> 15780.35 | H7: =E7+G7 -> 1597223.8 | I7: =+Devarakhadra!M3 -> 562989.59 | J7: =+Devarakhadra!L35 -> 2039000 | K7: =H7+I7-J7 -> 121213.37
A8: 8 | B8: Devarkhadra-2 | C8: M/S. Sri Rama Filling Station | D8: =+'Devarakhadra-2'!E35 -> 1200 | E8: =+'Devarakhadra-2'!G35 -> 116520 | F8: =+'Devarakhadra-2'!H35 -> 0 | G8: =+'Devarakhadra-2'!I35 -> 0 | H8: =E8+G8 -> 116520 | I8: =+'Devarakhadra-2'!M3 -> 134013.54 | J8: =+'Devarakhadra-2'!L35 -> 118260 | K8: =H8+I8-J8 -> 132273.54
A9: 9 | B9: Amalapuram | C9: Sathya Filling Station | D9: =+Amalapuram!E36 -> 148.48 | E9: =+Amalapuram!G36 -> 14017.24 | F9: =+Amalapuram!H36 -> 186.05 | G9: =+Amalapuram!J36 -> 20075.552 | H9: =E9+G9 -> 34092.792 | I9: =+Amalapuram!M3 -> 0 | J9: =+Amalapuram!L36 -> 34092.795 | K9: =H9+I9-J9 -> -0.0026
A10: 10 | B10: YG Gudda-1 | C10: Pallavi Petrolium | D10: =+'YG Gudda '!E36 -> 3000 | E10: =+'YG Gudda '!G36 -> 273900 | F10: =+'YG Gudda '!H36 -> 210 | G10: =+'YG Gudda '!J36 -> 21681.45 | H10: =E10+G10 -> 295581.45 | I10: ='YG Gudda '!K3 -> 284233.21 | J10: =+'YG Gudda '!L36 -> 470000 | K10: =H10+I10-J10 -> 109814.66 | L10: 102795 | M10: =K10-L10 -> 7019.6645
A11: 11 | B11: YG Gudda-2 | C11: Pankaja HP Fuel Center | D11: =+'YG Gudda-2'!E35 -> 8600 | E11: =+'YG Gudda-2'!G35 -> 785438 | F11: =+'YG Gudda-2'!H35 -> 490 | G11: =+'YG Gudda-2'!J35 -> 50602.3 | H11: =E11+G11 -> 836040.3 | I11: =+'YG Gudda-2'!M3 -> 230070.7 | J11: =+'YG Gudda-2'!L35 -> 760000 | K11: =H11+I11-J11 -> 306111
A12: 12 | B12: Hosadurga-1 | C12: Merchant Petroliums | D12: =+Hosadurga!E35 -> 1500 | E12: =+Hosadurga!G35 -> 137700 | F12: =+Hosadurga!H35 -> 70 | G12: =+Hosadurga!J35 -> 7279.3 | H12: =E12+G12 -> 144979.3 | I12: =+Hosadurga!K3 -> 7279.3 | J12: =+Hosadurga!L35 -> 150000 | K12: =H12+I12-J12 -> 2258.6
A13: 13 | B13: Hosadurga-2 | C13: Shree Veeraprathap Fuel | D13: =+'Hosadurga -2'!E35 -> 3776.7 | E13: =+'Hosadurga -2'!G35 -> 345756.89 | F13: =+'Hosadurga -2'!H35 -> 305 | G13: =+'Hosadurga -2'!J35 -> 31637.65 | H13: =+'Hosadurga -2'!K35 -> 377394.54 | I13: =+'Hosadurga -2'!K3 -> 439314.55 | J13: =+'Hosadurga -2'!L35 -> 539000 | K13: =H13+I13-J13 -> 277709.09
A14: 14 | B14: Malebennuru(KUWSDB) | C14: Sri Ramanjuneya Service Station | D14: =+'Malebenur(KUWSDB)'!E36 -> 8303.58 | E14: =+'Malebenur(KUWSDB)'!G36 -> 765757.66 | F14: =+'Malebenur(KUWSDB)'!H36 -> 234.99 | G14: =+'Malebenur(KUWSDB)'!J36 -> 24425.52 | H14: =E14+G14 -> 790183.18 | I14: =+'Malebenur(KUWSDB)'!K3 -> 191809.52 | J14: =+'Malebenur(KUWSDB)'!L36 -> 979357.87 | K14: =H14+I14-J14 -> 2634.8284
A15: 15 | B15: kadur | C15: Vishal Service Station | D15: =+Kadur!E35 -> 0 | E15: =+Kadur!G35 -> 0 | F15: =+Kadur!H35 -> 110 | G15: =+Kadur!J35 -> 11469.7 | H15: =E15+G15 -> 11469.7 | I15: =+Kadur!K3 -> 417039.13 | J15: =+Kadur!L35 -> 417000 | K15: =H15+I15-J15 -> 11508.831
A16: 16 | B16: Hiriyur(VJNL) | C16: Sri Balaji Agencies | D16: =+'Hiriyur(VJNL)'!E35 -> 2200 | E16: =+'Hiriyur(VJNL)'!G35 -> 202972 | F16: =+'Hiriyur(VJNL)'!H35 -> 280 | G16: =+'Hiriyur(VJNL)'!J35 -> 29159.2 | H16: =E16+G16 -> 232131.2 | I16: =+'Hiriyur(VJNL)'!K3 -> 191992.3 | J16: =+'Hiriyur(VJNL)'!L35 -> 349282.1 | K16: =H16+I16-J16 -> 74841.4
A17: 17 | B17: Chellakere(KUWSDB) | C17: Sri Vishnu Baba Petroleum | D17: =+'Chellakere (KUWSDB)'!E35 -> 4332.28 | E17: =+'Chellakere (KUWSDB)'!G35 -> 399641.44 | F17: =+'Chellakere (KUWSDB)'!H35 -> 260 | G17: =+'Chellakere (KUWSDB)'!J35 -> 24991.2 | H17: =E17+G17 -> 424632.64 | I17: 0 | J17: =+'Chellakere (KUWSDB)'!L35 -> 424632.64 | K17: =H17+I17-J17 -> 0
A18: 18 | B18: Molakalmuru | C18: Sri Lakshmi Venkateshwara Filling Station | D18: =+Molakamuru!E35 -> 2650 | E18: =+Molakamuru!G35 -> 244489 | F18: =+Molakamuru!H35 -> 50 | G18: =+Molakamuru!J35 -> 5206.5 | H18: =E18+G18 -> 249695.5 | I18: =+Molakamuru!K3 -> 0 | J18: =+Molakamuru!L35 -> 249695.5 | K18: =H18+I18-J18 -> 0
A19: 19 | B19: Khanapur(PKG-3) | C19: J K Makavi | D19: =+Khanapur!E35 -> 1822.61 | E19: =+Khanapur!G35 -> 161544.8 | F19: =+Khanapur!H35 -> 58.86 | G19: =+Khanapur!J35 -> 6049.0422 | H19: =E19+G19 -> 167593.84 | I19: 0 | J19: =+Khanapur!L35 -> 157423.09 | K19: =H19+I19-J19 -> 10170.75
A20: 20 | B20: Munavalli(PKG-3)-2 | C20: Shri Daneshwari | D20: =+'Munavali-2'!E37 -> 9465.14 | E20: =+'Munavali-2'!G37 -> 864311.88 | F20: =+'Munavali-2'!H37 -> 184.72 | G20: =+'Munavali-2'!J37 -> 19070.134 | H20: =E20+G20 -> 883382.01 | I20: =+'Munavali-2'!M3 -> 480082.77 | J20: =+'Munavali-2'!L37 -> 1158613.8 | K20: =H20+I20-J20 -> 204851.03
A21: 21 | B21: Borgaon(PKG-3) | C21: Aadisagar Petrolium | D21: =+Borgaon!E35 -> 393.5 | E21: =+Borgaon!G35 -> 36111.495 | F21: =+Borgaon!H35 -> 90.91 | G21: =+Borgaon!J35 -> 9510.5043 | H21: =E21+G21 -> 45621.999 | I21: =+Borgaon!K3 -> 38975.608 | J21: =+Borgaon!L35 -> 43000 | K21: =H21+I21-J21 -> 41597.607
A22: 22 | B22: Ugar,Kudichi(PKG-3) | C22: Shiri Bhrhmanath Petrolium | D22: =+'Ugar,Khagwad,Kudichi'!E35 -> 3544.61 | E22: =+'Ugar,Khagwad,Kudichi'!G35 -> 325856 | F22: =+'Ugar,Khagwad,Kudichi'!H35 -> 300 | G22: =+'Ugar,Khagwad,Kudichi'!J35 -> 31167 | H22: =E22+G22 -> 357023 | I22: =+'Ugar,Khagwad,Kudichi'!M3 -> 276896.24 | J22: =+'Ugar,Khagwad,Kudichi'!L35 -> 403000 | K22: =H22+I22-J22 -> 230919.24
A23: 23 | B23: Kabbur(PKG-3) | C23: Shri Jai Hanuman Petrolium | D23: =+Kabbur!E35 -> 425 | E23: =+Kabbur!G35 -> 38925.75 | F23: =+Kabbur!H35 -> 26.25 | G23: =+Kabbur!J35 -> 2717.6625 | H23: =E23+G23 -> 41643.412 | I23: 0 | J23: =+Kabbur!L35 -> 41643.413 | K23: =H23+I23-J23 -> 0
A24: 24 | B24: Kumta (PKG-1) | C24: Krishma fuel station | D24: =+kumta!E35 -> 708.42 | E24: =+kumta!G35 -> 65117.966 | F24: =+kumta!H35 -> 48.37 | G24: =+kumta!J35 -> 5028.5452 | H24: =E24+G24 -> 70146.512 | I24: 0 | J24: =+kumta!L35 -> 70146.511 | K24: =H24+I24-J24 -> 0.0004
A25: 25 | B25: Jalgaon | C25: Sri Sai Petrol Pump | D25: =+Jalgaon!E45 -> 10846.58 | E25: =+Jalgaon!G45 -> 994753.76 | F25: =+Jalgaon!H45 -> 34.18 | G25: =+Jalgaon!J45 -> 3069.4442 | H25: =E25+G25 -> 997823.2 | I25: =+Jalgaon!K3 -> 215765.12 | J25: =+Jalgaon!L45 -> 704000 | K25: =H25+I25-J25 -> 509588.32
A26: 26 | B26: MKBD | C26: Shree Sai Samarth Petroleum | D26: =+MKBD!E36 -> 3180 | E26: =+MKBD!G36 -> 290191.6 | F26: =+MKBD!H36 -> 60 | G26: =+MKBD!J36 -> 6276 | H26: =E26+G26 -> 296467.6 | I26: =+MKBD!K3 -> 1341625.6 | J26: =+MKBD!L36 -> 1529612.6 | K26: =H26+I26-J26 -> 108480.65
A27: 27 | B27: Haveri | C27: Shivalingeshwar Petroleum | D27: =+Haveri!E35 -> 3853.1 | E27: =+Haveri!G35 -> 352349.45 | F27: =+Haveri!H35 -> 108.91 | G27: =+Haveri!J35 -> 11261.294 | H27: =E27+G27 -> 363610.75 | I27: =+Haveri!M3 -> 166543.86 | J27: =+Haveri!L35 -> 429766 | K27: =H27+I27-J27 -> 100388.61
A28: 28 | B28: Guttal | C28: Taware filling station | D28: =+Guttal!E35 -> 1975.51 | E28: =+Guttal!G35 -> 181351.82 | F28: =+Guttal!H35 -> 132 | G28: =+Guttal!J35 -> 13696.32 | H28: =E28+G28 -> 195048.14 | I28: 0 | J28: =+Guttal!L35 -> 195048.14 | K28: =H28+I28-J28 -> -0.0019999999
A29: 29 | B29: Rattihali | C29: Shree Siri Gowari petroliam | D29: =+Rattihali!E35 -> 2721.88 | E29: =+Rattihali!G35 -> 250521.84 | F29: =+Rattihali!H35 -> 73.94 | G29: =+Rattihali!J35 -> 7691.2388 | H29: =E29+G29 -> 258213.07 | I29: =+Rattihali!M3 -> 266689.16 | J29: =+Rattihali!L35 -> 351026 | K29: =H29+I29-J29 -> 173876.23
A30: 30 | B30: Gajendragada | C30: Vanasri Petrol Pump | D30: =+Gajendragada!E35 -> 1750 | E30: =+Gajendragada!G35 -> 160702.5 | F30: =+Gajendragada!H35 -> 135 | G30: =+Gajendragada!J35 -> 14013 | H30: =E30+G30 -> 174715.5 | I30: =+Gajendragada!K3 -> 60128.512 | J30: =+Gajendragada!L35 -> 101172 | K30: =H30+I30-J30 -> 133672.01
A31: 32 | B31: Gokak(PKG-3) | C31: AJ Petrolinks | D31: =+'Gokak Dharwad PKG 3'!E40 -> 9359.68 | E31: =+'Gokak Dharwad PKG 3'!G40 -> 856223.53 | F31: =+'Gokak Dharwad PKG 3'!H40 -> 362 | G31: =+'Gokak Dharwad PKG 3'!J40 -> 37434.42 | H31: =E31+G31 -> 893657.95 | I31: =+'Gokak Dharwad PKG 3'!K3 -> 743234.15 | J31: =+'Gokak Dharwad PKG 3'!L40 -> 600000 | K31: =H31+I31-J31 -> 1036892.1
A32: 33 | B32: Ankaligi | C32: Shiv ganga | D32: =+Ankalgi!E35 -> 1622.61 | E32: =+Ankalgi!G35 -> 148160.52 | F32: =+Ankalgi!H35 -> 147 | G32: =+Ankalgi!J35 -> 15174.81 | H32: =E32+G32 -> 163335.33 | I32: =+Ankalgi!M3 -> 228405.77 | J32: =+Ankalgi!L35 -> 285745 | K32: =H32+I32-J32 -> 105996.1
A33: 34 | B33: ShankeshWAR | C33: SR Patil | D33: =+' Shankeshwar'!E35 -> 0 | E33: =+' Shankeshwar'!G35 -> 0 | F33: =+' Shankeshwar'!H35 -> 29 | G33: =+' Shankeshwar'!J35 -> 2993.38 | H33: =E33+G33 -> 2993.38 | J33: =+' Shankeshwar'!L35 -> 2993.38 | K33: =H33+I33-J33 -> 0
A34: 35 | B34: Talikote(PKG-1) | C34: Raykar Oil Agencies | D34: =+' Talikote'!E46 -> 1199.74 | E34: =+' Talikote'!G46 -> 109776.21 | F34: =+' Talikote'!H46 -> 103.21 | G34: =+' Talikote'!J46 -> 10673.848 | H34: =E34+G34 -> 120450.06 | I34: =+' Talikote'!N3 -> 40815.884 | J34: =+' Talikote'!L46 -> 140652 | K34: =H34+I34-J34 -> 20613.942
A35: 36 | B35: Chadchan(PKG-1) | C35: Khavekar Petrolium | D35: =+Chadchan!E35 -> 1396.21 | E35: =+Chadchan!G35 -> 127376.24 | F35: =+Chadchan!H35 -> 120.94 | G35: =+Chadchan!J35 -> 12476.17 | H35: =E35+G35 -> 139852.41 | I35: =+Chadchan!K3 -> 188963.52 | J35: =+Chadchan!L35 -> 235933.5 | K35: =H35+I35-J35 -> 92882.428
A36: 37 | B36: Sindagi | C36: G.P.PORWAL | D36: =+Sindagi!E44 -> 0 | E36: =+Sindagi!G44 -> 0 | F36: =+Sindagi!H44 -> 0 | G36: =+Sindagi!J44 -> 0 | H36: =E36+G36 -> 0 | I36: =+Sindagi!M3 -> 31876.861 | J36: =+Sindagi!L44 -> 31876.861 | K36: =H36+I36-J36 -> 0
A37: 38 | B37: Muddebihal(PKG-1) | C37: Bhosle Service Station | D37: =+Muddebihal!E47 -> 2309.1 | E37: =+Muddebihal!G47 -> 211167.19 | F37: =+Muddebihal!H47 -> 55.61 | G37: =+Muddebihal!J47 -> 5748.6332 | H37: =E37+G37 -> 216915.83 | I37: =+Muddebihal!M3 -> 45514.196 | J37: =+Muddebihal!L47 -> 232027 | K37: =H37+I37-J37 -> 30403.024
A38: 39 | B38: Almela(PKG-1) | C38: Shiddeshwar Petroleums | D38: =+Alemela!E43 -> 1365 | E38: =+Alemela!G43 -> 124634.45 | F38: =+Alemela!H43 -> 100.68 | G38: =+Alemela!J43 -> 10396.217 | H38: =E38+G38 -> 135030.67 | I38: =+Alemela!M3 -> 37173.474 | J38: =+Alemela!L43 -> 167807.32 | K38: =H38+I38-J38 -> 4396.8207
A39: 40 | B39: Nalatwad(PKG-1) | C39: Shri Pawad Basaweshwar Petroleums | D39: =+Nalatwad!E43 -> 468.66 | E39: =+Nalatwad!G43 -> 42959.584 | F39: =+Nalatwad!H43 -> 64.16 | G39: =+Nalatwad!J43 -> 6645.0512 | H39: =E39+G39 -> 49604.635 | I39: =+Nalatwad!M3 -> 119940 | J39: =+Nalatwad!L43 -> 150000 | K39: =H39+I39-J39 -> 19544.637
A40: 41 | B40: Srirangapatna | C40: Sri Chakra Fuel Station | D40: =+Srirangapatna!E35 -> 0 | E40: =+Srirangapatna!G35 -> 0 | F40: =+Srirangapatna!H35 -> 71.28 | G40: =+Srirangapatna!J35 -> 7303.3488 | H40: =E40+G40 -> 7303.3488 | I40: 0 | J40: =+Srirangapatna!L35 -> 7303.3488 | K40: =H40+I40-J40 -> 0
...

Sheet Khammam-1
A1: Divya laxmi ganapathi
A2: S.No | B2: Date | C2: GRN No | D2: Ind No/Bill No | E2: Diesel (Lts) | F2: Price | G2: Amount | H2: Petrol (Lts) | I2: Price | J2: Amount | K2: Total amount | L2: Amount paid | M2: As 0n Date | N2: Remarks
A3: Opening Balance | K3: 11063503 | M3: =+K3 -> 11063503 | O3: 14609972
A4: 1 | B4: 45901 | E4: 0 | F4: 0 | G4: =E4*F4 -> 0 | H4: 0 | I4: 0 | J4: =H4*I4 -> 0 | K4: =G4+J4 -> 0 | L4: 0 | M4: =M3+K4-L4 -> 11063503
A5: 2 | B5: 45902 | E5: 0 | F5: 0 | G5: =E5*F5 -> 0 | H5: 0 | I5: 0 | J5: =H5*I5 -> 0 | K5: =G5+J5 -> 0 | M5: =M4+K5-L5 -> 11063503
A6: 3 | B6: 45903 | E6: 2800 | F6: 95.68 | G6: =E6*F6 -> 267904 | H6: 0 | I6: 0 | J6: =H6*I6 -> 0 | K6: =G6+J6 -> 267904 | M6: =M5+K6-L6 -> 11331407
A7: 4 | B7: 45904 | E7: 8093.72 | F7: 95.68 | G7: =E7*F7 -> 774407.13 | H7: 40 | I7: 107.46 | J7: =H7*I7 -> 4298.4 | K7: =G7+J7 -> 778705.53 | M7: =M6+K7-L7 -> 12110113
A8: 5 | B8: 45905 | E8: 5695.37 | F8: 95.68 | G8: =E8*F8 -> 544933 | H8: 40 | I8: 107.46 | J8: =H8*I8 -> 4298.4 | K8: =G8+J8 -> 549231.4 | M8: =M7+K8-L8 -> 12659344
A9: 6 | B9: 45906 | E9: 2000 | F9: 95.68 | G9: =E9*F9 -> 191360 | H9: 0 | I9: 0 | J9: =H9*I9 -> 0 | K9: =G9+J9 -> 191360 | M9: =M8+K9-L9 -> 12850704
A10: 7 | B10: 45907 | E10: =2700+2208.37 -> 4908.37 | F10: 95.68 | G10: =E10*F10 -> 469632.84 | H10: 0 | I10: 0 | J10: =H10*I10 -> 0 | K10: =G10+J10 -> 469632.84 | M10: =M9+K10-L10 -> 13320337
A11: 8 | B11: 45908 | E11: 3799.19 | F11: 95.68 | G11: =E11*F11 -> 363506.5 | H11: 40 | I11: 107.46 | J11: =H11*I11 -> 4298.4 | K11: =G11+J11 -> 367804.9 | L11: 7500000 | M11: =M10+K11-L11 -> 6188142
A12: 9 | B12: 45909 | E12: 0 | F12: 0 | G12: =E12*F12 -> 0 | H12: 0 | I12: 0 | J12: =H12*I12 -> 0 | K12: =G12+J12 -> 0 | M12: =M11+K12-L12 -> 6188142
A13: 10 | B13: 45910 | E13: 8416.25 | F13: 95.68 | G13: =E13*F13 -> 805266.8 | H13: 60 | I13: 107.46 | J13: =H13*I13 -> 6447.6 | K13: =G13+J13 -> 811714.4 | M13: =M12+K13-L13 -> 6999856.4 | O13: 6999851.3 | P13: =M13-O13 -> 5.0597
A14: 11 | B14: 45911 | E14: 0 | F14: 0 | G14: =E14*F14 -> 0 | H14: 0 | I14: 0 | J14: =H14*I14 -> 0 | K14: =G14+J14 -> 0 | M14: =M13+K14-L14 -> 6999856.4
A15: 12 | B15: 45912 | E15: 3879.39 | F15: 95.68 | G15: =E15*F15 -> 371180.04 | H15: 0 | I15: 0 | J15: =H15*I15 -> 0 | K15: =G15+J15 -> 371180.04 | M15: =M14+K15-L15 -> 7371036.4
A16: 13 | B16: 45913 | E16: 5382.58 | F16: 95.68 | G16: =E16*F16 -> 515005.25 | H16: 0 | I16: 0 | J16: =H16*I16 -> 0 | K16: =G16+J16 -> 515005.25 | M16: =M15+K16-L16 -> 7886041.6
A17: 14 | B17: 45914 | E17: 0 | F17: 0 | G17: =E17*F17 -> 0 | H17: 0 | I17: 0 | J17: =H17*I17 -> 0 | K17: =G17+J17 -> 0 | M17: =M16+K17-L17 -> 7886041.6
A18: 15 | B18: 45915 | E18: 0 | F18: 0 | G18: =E18*F18 -> 0 | H18: 0 | I18: 0 | J18: =H18*I18 -> 0 | K18: =G18+J18 -> 0 | M18: =M17+K18-L18 -> 7886041.6
A19: 16 | B19: 45916 | E19: 5500 | F19: 95.68 | G19: =E19*F19 -> 526240 | H19: 40 | I19: 107.46 | J19: =H19*I19 -> 4298.4 | K19: =G19+J19 -> 530538.4 | M19: =M18+K19-L19 -> 8416580
A20: 17 | B20: 45917 | E20: 2700 | F20: 95.67 | G20: =E20*F20 -> 258309 | H20: 20 | I20: 107.45 | J20: =H20*I20 -> 2149 | K20: =G20+J20 -> 260458 | M20: =M19+K20-L20 -> 8677038
A21: 18 | B21: 45918 | E21: 5500 | F21: 95.68 | G21: =E21*F21 -> 526240 | H21: 55 | I21: 107.46 | J21: =H21*I21 -> 5910.3 | K21: =G21+J21 -> 532150.3 | M21: =M20+K21-L21 -> 9209188.3
A22: 19 | B22: 45919 | E22: 0 | F22: 0 | G22: =E22*F22 -> 0 | H22: 0 | I22: 0 | J22: =H22*I22 -> 0 | K22: =G22+J22 -> 0 | M22: =M21+K22-L22 -> 9209188.3
A23: 20 | B23: 45920 | E23: 5500 | F23: 95.68 | G23: =E23*F23 -> 526240 | H23: 40 | I23: 107.46 | J23: =H23*I23 -> 4298.4 | K23: =G23+J23 -> 530538.4 | M23: =M22+K23-L23 -> 9739726.7
A24: 21 | B24: 45921 | E24: 0 | F24: 0 | G24: =E24*F24 -> 0 | H24: 0 | I24: 0 | J24: =H24*I24 -> 0 | K24: =G24+J24 -> 0 | M24: =M23+K24-L24 -> 9739726.7
A25: 22 | B25: 45922 | E25: 2000 | F25: 95.67 | G25: =E25*F25 -> 191340 | H25: 0 | I25: 0 | J25: =H25*I25 -> 0 | K25: =G25+J25 -> 191340 | M25: =M24+K25-L25 -> 9931066.7
... A31: 28 | B31: 45928 | E31: 2800 | F31: 95.68 | G31: =E31*F31 -> 267904 | H31: 55 | I31: 107.46 | J31: =H31*I31 -> 5910.3 | K31: =G31+J31 -> 273814.3 | M31: =M30+K31-L31 -> 10917211
A32: 29 | B32: 45929 | E32: 2700 | F32: 95.68 | G32: =E32*F32 -> 258336 | H32: 20 | I32: 107.46 | J32: =H32*I32 -> 2149.2 | K32: =G32+J32 -> 260485.2 | M32: =M31+K32-L32 -> 11177697 | O32: 11177692 | P32: =M32-O32 -> 5.0597
A33: 30 | B33: 45930 | E33: 0 | F33: 0 | G33: =E33*F33 -> 0 | H33: 0 | I33: 0 | J33: =H33*I33 -> 0 | K33: =G33+J33 -> 0 | M33: =M32+K33-L33 -> 11177697
A34: 31 | E34: 0 | F34: 0 | G34: =E34*F34 -> 0 | H34: 0 | I34: 0 | J34: =H34*I34 -> 0 | K34: =G34+J34 -> 0 | M34: =M33+K34-L34 -> 11177697
A35: 32 | E35: 0 | F35: 0 | G35: =E35*F35 -> 0 | H35: 0 | I35: 0 | J35: =H35*I35 -> 0 | K35: =G35+J35 -> 0 | M35: =M34+K35-L35 -> 11177697
A36: 33 | E36: 0 | F36: 0 | G36: =E36*F36 -> 0 | H36: 0 | I36: 0 | J36: =H36*I36 -> 0 | K36: =G36+J36 -> 0
A37: 34 | E37: 0 | F37: 0 | G37: =E37*F37 -> 0 | H37: 0 | I37: 0 | J37: =H37*I37 -> 0 | K37: =G37+J37 -> 0
E38: =SUM(E3:E37) -> 79074.87 | G38: =SUM(G3:G37) -> 7565836.6 | H38: =SUM(H3:H37) -> 450 | J38: =SUM(J3:J37) -> 48356.8 | K38: =SUM(K4:K37) -> 7614193.4 | L38: =SUM(L3:L37) -> 7500000

Sheet Khammam-2
A1: Jayasai union bunk
A2: S.No | B2: Date | C2: GRN No | D2: Ind No/Bill No | E2: Diesel (Lts) | F2: Price | G2: Amount | H2: Petrol (Lts) | I2: Price | J2: Amount | K2: Total amount | L2: Amount paid | M2: As 0n Date | N2: Remarks | O2: 11748805 | P2: =K3-O2 -> 478.5796
A3: Opening Balance | K3: 11749284 | M3: 11749284 | O3: 12663588
A4: 1 | B4: 45901 | E4: 5457.77 | F4: 95.7 | G4: =E4*F4 -> 522308.59 | H4: 40 | I4: 107.48 | J4: =H4*I4 -> 4299.2 | K4: =G4+J4 -> 526607.79 | M4: =M3+K4-L4 -> 12275891
A5: 2 | B5: 45902 | E5: =2700+2310.74 -> 5010.74 | F5: 95.7 | G5: =E5*F5 -> 479527.82 | H5: 0 | I5: 0 | J5: =H5*I5 -> 0 | K5: =G5+J5 -> 479527.82 | M5: =M4+K5-L5 -> 12755419
A6: 3 | B6: 45903 | E6: 4200 | F6: 95.7 | G6: =E6*F6 -> 401940 | H6: 40 | I6: 107.48 | J6: =H6*I6 -> 4299.2 | K6: =G6+J6 -> 406239.2 | M6: =M5+K6-L6 -> 13161658
A7: 4 | B7: 45904 | E7: 0 | F7: 0 | G7: =E7*F7 -> 0 | H7: 0 | I7: 0 | J7: =H7*I7 -> 0 | K7: =G7+J7 -> 0 | M7: =M6+K7-L7 -> 13161658
A8: 5 | B8: 45905 | E8: 0 | F8: 0 | G8: =E8*F8 -> 0 | H8: 0 | I8: 0 | J8: =H8*I8 -> 0 | K8: =G8+J8 -> 0 | M8: =M7+K8-L8 -> 13161658
A9: 6 | B9: 45906 | E9: =2700+2800 -> 5500 | F9: 95.7 | G9: =E9*F9 -> 526350 | H9: 40 | I9: 107.48 | J9: =H9*I9 -> 4299.2 | K9: =G9+J9 -> 530649.2 | M9: =M8+K9-L9 -> 13692308
A10: 7 | B10: 45907 | E10: 1500 | F10: 95.7 | G10: =E10*F10 -> 143550 | H10: 0 | I10: 0 | J10: =H10*I10 -> 0 | K10: =G10+J10 -> 143550 | M10: =M9+K10-L10 -> 13835858
A11: 8 | B11: 45908 | E11: 4200 | F11: 95.7 | G11: =E11*F11 -> 401940 | H11: 0 | I11: 0 | J11: =H11*I11 -> 0 | K11: =G11+J11 -> 401940 | L11: 7500000 | M11: =M10+K11-L11 -> 6737797.6
A12: 9 | B12: 45909 | E12: 5400 | F12: 95.7 | G12: =E12*F12 -> 516780 | H12: 0 | I12: 0 | J12: =H12*I12 -> 0 | K12: =G12+J12 -> 516780 | M12: =M11+K12-L12 -> 7254577.6
A13: 10 | B13: 45910 | E13: 0 | F13: 0 | G13: =E13*F13 -> 0 | H13: 0 | I13: 0 | J13: =H13*I13 -> 0 | K13: =G13+J13 -> 0 | M13: =M12+K13-L13 -> 7254577.6
A14: 11 | B14: 45911 | E14: 2700 | F14: 95.7 | G14: =E14*F14 -> 258390 | H14: 55 | I14: 107.48 | J14: =H14*I14 -> 5911.4 | K14: =G14+J14 -> 264301.4 | M14: =M13+K14-L14 -> 7518879
A15: 12 | B15: 45912 | E15: 5400 | F15: 95.7 | G15: =E15*F15 -> 516780 | H15: 60 | I15: 107.48 | J15: =H15*I15 -> 6448.8 | K15: =G15+J15 -> 523228.8 | M15: =M14+K15-L15 -> 8042107.8
A16: 13 | B16: 45913 | E16: 2700 | F16: 95.7 | G16: =E16*F16 -> 258390 | H16: 40 | I16: 107.48 | J16: =H16*I16 -> 4299.2 | K16: =G16+J16 -> 262689.2 | M16: =M15+K16-L16 -> 8304797
A17: 14 | B17: 45914 | E17: 2274.85 | F17: 95.7 | G17: =E17*F17 -> 217703.14 | H17: 0 | I17: 0 | J17: =H17*I17 -> 0 | K17: =G17+J17 -> 217703.14 | M17: =M16+K17-L17 -> 8522500.1
A18: 15 | B18: 45915 | E18: 5990 | F18: 95.7 | G18: =E18*F18 -> 573243 | H18: 0 | I18: 0 | J18: =H18*I18 -> 0 | K18: =G18+J18 -> 573243 | M18: =M17+K18-L18 -> 9095743.1
A19: 16 | B19: 45916 | E19: 2755.94 | F19: 95.7 | G19: =E19*F19 -> 263743.46 | H19: 0 | I19: 0 | J19: =H19*I19 -> 0 | K19: =G19+J19 -> 263743.46 | M19: =M18+K19-L19 -> 9359486.6
A20: 17 | B20: 45917 | E20: 1038.28 | F20: 95.7 | G20: =E20*F20 -> 99363.396 | H20: 0 | I20: 0 | J20: =H20*I20 -> 0 | K20: =G20+J20 -> 99363.396 | M20: =M19+K20-L20 -> 9458850
A21: 18 | B21: 45918 | E21: 5115.36 | F21: 95.7 | G21: =E21*F21 -> 489539.95 | H21: 0 | I21: 0 | J21: =H21*I21 -> 0 | K21: =G21+J21 -> 489539.95 | M21: =M20+K21-L21 -> 9948389.9
A22: 19 | B22: 45919 | E22: 6907.62 | F22: 95.7 | G22: =E22*F22 -> 661059.23 | H22: 20 | I22: 107.48 | J22: =H22*I22 -> 2149.6 | K22: =G22+J22 -> 663208.83 | M22: =M21+K22-L22 -> 10611599
A23: 20 | B23: 45920 | E23: 0 | F23: 0 | G23: =E23*F23 -> 0 | H23: 0 | I23: 0 | J23: =H23*I23 -> 0 | K23: =G23+J23 -> 0 | M23: =M22+K23-L23 -> 10611599
... A34: 31 | B34: 45931 | E34: 0 | F34: 0 | G34: =E34*F34 -> 0 | H34: 0 | I34: 0 | J34: =H34*I34 -> 0 | K34: =G34+J34 -> 0 | M34: =M33+K34-L34 -> 13443331
E35: =SUM(E4:E34) -> 95538.08 | G35: =SUM(G4:G34) -> 9142994.3 | H35: =SUM(H4:H34) -> 475 | J35: =SUM(J4:J34) -> 51053 | K35: =SUM(K4:K34) -> 9194047.3 | L35: =SUM(L4:L34) -> 7500000

Sheet Jedcherla -1
A1: Sai Baba Fuel Station
A2: S.No | B2: Date | C2: GRN No | D2: Ind No/Bill No | E2: Diesel (Lts) | F2: Price | G2: Amount | H2: Petrol (Lts) | I2: Price | J2: Amount | K2: Total amount | L2: Amount paid | M2: As on date | N2: Remarks
A3: Opening Balance | M3: 3836229.1 | O3: 1388015.3
A4: 1 | B4: 45901 | E4: 1000 | F4: 96.42 | G4: =E4*F4 -> 96420 | H4: 5 | I4: 108.23 | J4: =H4*I4 -> 541.15 | K4: =G4+J4 -> 96961.15 | L4: 600000 | M4: =M3+K4-L4 -> 3333190.2 | O4: 1526163 | P4: =M4-O4 -> 1807027.2 | R4: 10
A5: 2 | B5: 45902 | E5: 1000 | F5: 96.42 | G5: =E5*F5 -> 96420 | H5: 15 | I5: 108.23 | J5: =H5*I5 -> 1623.45 | K5: =G5+J5 -> 98043.45 | L5: 0 | M5: =M4+K5-L5 -> 3431233.7 | Q5: 44.36 | R5: 20
A6: 3 | B6: 45903 | E6: 41.58 | F6: 96.42 | G6: =E6*F6 -> 4009.1436 | H6: 25 | I6: 108.23 | J6: =H6*I6 -> 2705.75 | K6: =G6+J6 -> 6714.8936 | L6: 0 | M6: =M5+K6-L6 -> 3437948.5 | R6: 58.27
A7: 4 | B7: 45904 | D7: 80.88 | E7: 0 | F7: 96.42 | G7: =E7*F7 -> 0 | H7: 5 | I7: 108.23 | J7: =H7*I7 -> 541.15 | K7: =G7+J7 -> 541.15 | L7: 0 | M7: =M6+K7-L7 -> 3438489.7
A8: 5 | B8: 45905 | E8: 0 | F8: 0 | G8: =E8*F8 -> 0 | H8: 48.26 | I8: 108.23 | J8: =H8*I8 -> 5223.1798 | K8: =G8+J8 -> 5223.1798 | L8: 0 | M8: =M7+K8-L8 -> 3443712.9
A9: 6 | B9: 45906 | E9: 0 | F9: 0 | G9: =E9*F9 -> 0 | H9: 47.46 | I9: 108.23 | J9: =H9*I9 -> 5136.5958 | K9: =G9+J9 -> 5136.5958 | L9: 0 | M9: =M8+K9-L9 -> 3448849.5 | R9: 52.46
A10: 7 | B10: 45907 | E10: 0 | F10: 0 | G10: =E10*F10 -> 0 | H10: 20 | I10: 108.23 | J10: =H10*I10 -> 2164.6 | K10: =G10+J10 -> 2164.6 | L10: 0 | M10: =M9+K10-L10 -> 3451014.1 | R10: 25
A11: 8 | B11: 45908 | E11: 46.36 | F11: 96.42 | G11: =E11*F11 -> 4470.0312 | H11: 25 | I11: 108.23 | J11: =H11*I11 -> 2705.75 | K11: =G11+J11 -> 7175.7812 | L11: 3450000 | M11: =M10+K11-L11 -> 8189.8567 | O11: 2862 | Q11: 46.36
L12: 5327.86 | M12: 2862
A13: 9 | B13: 45909 | E13: 2400 | F13: 96.42 | G13: =E13*F13 -> 231408 | H13: 20 | I13: 108.23 | J13: =H13*I13 -> 2164.6 | K13: =G13+J13 -> 233572.6 | L13: 0 | M13: =M12+K13-L13 -> 236434.6
A14: 10 | B14: 45910 | E14: 2500 | F14: 96.42 | G14: =E14*F14 -> 241050 | H14: 15 | I14: 108.23 | J14: =H14*I14 -> 1623.45 | K14: =G14+J14 -> 242673.45 | L14: 0 | M14: =M13+K14-L14 -> 479108.05 | V14: =8189.86-2862 -> 5327.86
A15: 11 | B15: 45911 | E15: 2400 | F15: 96.42 | G15: =E15*F15 -> 231408 | H15: 15 | I15: 108.23 | J15: =H15*I15 -> 1623.45 | K15: =G15+J15 -> 233031.45 | L15: 0 | M15: =M14+K15-L15 -> 712139.5
A16: 12 | B16: 45912 | E16: 0 | F16: 0 | G16: =E16*F16 -> 0 | H16: 35 | I16: 108.23 | J16: =H16*I16 -> 3788.05 | K16: =G16+J16 -> 3788.05 | L16: 0 | M16: =M15+K16-L16 -> 715927.55 | R16: 40
A17: 13 | B17: 45913 | E17: 0 | F17: 0 | G17: =E17*F17 -> 0 | H17: 10 | I17: 108.23 | J17: =H17*I17 -> 1082.3 | K17: =G17+J17 -> 1082.3 | L17: 0 | M17: =M16+K17-L17 -> 717009.85 | R17: 5
A18: 14 | B18: 45914 | E18: 2000 | F18: 96.42 | G18: =E18*F18 -> 192840 | H18: 10 | I18: 108.23 | J18: =H18*I18 -> 1082.3 | K18: =G18+J18 -> 193922.3 | L18: 0 | M18: =M17+K18-L18 -> 910932.15 | R18: 15
A19: 15 | B19: 45915 | E19: 0 | F19: 0 | G19: =E19*F19 -> 0 | H19: 20 | I19: 108.23 | J19: =H19*I19 -> 2164.6 | K19: =G19+J19 -> 2164.6 | L19: 0 | M19: =M18+K19-L19 -> 913096.75 | R19: 10
A20: 16 | B20: 45916 | D20: 94.59 | E20: 2527.05 | F20: 96.42 | G20: =E20*F20 -> 243658.16 | H20: 5 | I20: 108.23 | J20: =H20*I20 -> 541.15 | K20: =G20+J20 -> 244199.31 | L20: 0 | M20: =M19+K20-L20 -> 1157296.1 | Q20: 2527.05 | R20: 5
A21: 17 | B21: 45917 | D21: 32.46 | E21: 0 | F21: 0 | G21: =E21*F21 -> 0 | H21: 5 | I21: 108.23 | J21: =H21*I21 -> 541.15 | K21: =G21+J21 -> 541.15 | L21: 0 | M21: =M20+K21-L21 -> 1157837.2 | R21: 25
A22: 18 | B22: 45918 | E22: 2030 | F22: 96.42 | G22: =E22*F22 -> 195732.6 | H22: 35 | I22: 108.23 | J22: =H22*I22 -> 3788.05 | K22: =G22+J22 -> 199520.65 | L22: 0 | M22: =M21+K22-L22 -> 1357357.9 | R22: 24
A23: 19 | B23: 45919 | E23: 2000 | F23: 96.42 | G23: =E23*F23 -> 192840 | H23: 24 | I23: 108.23 | J23: =H23*I23 -> 2597.52 | K23: =G23+J23 -> 195437.52 | L23: 0 | M23: =M22+K23-L23 -> 1552795.4 | R23: 15
A24: 20 | B24: 45920 | E24: 2400 | F24: 96.42 | G24: =E24*F24 -> 231408 | H24: 20 | I24: 108.23 | J24: =H24*I24 -> 2164.6 | K24: =G24+J24 -> 233572.6 | L24: 0 | M24: =M23+K24-L24 -> 1786368 | R24: 20
A25: 21 | B25: 45921 | E25: 2400 | F25: 96.42 | G25: =E25*F25 -> 231408 | H25: 5 | I25: 108.23 | J25: =H25*I25 -> 541.15 | K25: =G25+J25 -> 231949.15 | L25: 0 | M25: =M24+K25-L25 -> 2018317.1 | Q25: 2440 | R25: 25
A26: 22 | B26: 45922 | D26: 40 | E26: 1840 | F26: 96.42 | G26: =E26*F26 -> 177412.8 | H26: 19 | I26: 108.23 | J26: =H26*I26 -> 2056.37 | K26: =G26+J26 -> 179469.17 | L26: 0 | M26: =M25+K26-L26 -> 2197786.3 | Q26: 1800 | R26: 10
A27: 23 | B27: 45923 | E27: 1400 | F27: 96.42 | G27: =E27*F27 -> 134988 | H27: 10 | I27: 108.23 | J27: =H27*I27 -> 1082.3 | K27: =G27+J27 -> 136070.3 | L27: 0 | M27: =M26+K27-L27 -> 2333856.6 | P27: 2440 | R27: 5
A28: 24 | B28: 45924 | E28: 0 | F28: 0 | G28: =E28*F28 -> 0 | H28: 24 | I28: 108.23 | J28: =H28*I28 -> 2597.52 | K28: =G28+J28 -> 2597.52 | L28: 0 | M28: =M27+K28-L28 -> 2336454.1 | R28: 29
A29: 25 | B29: 45925 | E29: 3400 | F29: 96.42 | G29: =E29*F29 -> 327828 | H29: 20 | I29: 108.23 | J29: =H29*I29 -> 2164.6 | K29: =G29+J29 -> 329992.6 | L29: 0 | M29: =M28+K29-L29 -> 2666446.7 | R29: 20
A30: 26 | B30: 45926 | E30: 0 | F30: 0 | G30: =E30*F30 -> 0 | H30: 10 | I30: 108.23 | J30: =H30*I30 -> 1082.3 | K30: =G30+J30 -> 1082.3 | L30: 0 | M30: =M29+K30-L30 -> 2667529 | Q30: 0
A31: 27 | B31: 45927 | E31: 45 | F31: 96.42 | G31: =E31*F31 -> 4338.9 | H31: 40 | I31: 108.23 | J31: =H31*I31 -> 4329.2 | K31: =G31+J31 -> 8668.1 | L31: 500000 | M31: =M30+K31-L31 -> 2176197.1 | Q31: 75 | R31: 5
A32: 28 | B32: 45928 | E32: 0 | F32: 0 | G32: =E32*F32 -> 0 | H32: 5 | I32: 108.23 | J32: =H32*I32 -> 541.15 | K32: =G32+J32 -> 541.15 | L32: 0 | M32: =M31+K32-L32 -> 2176738.3 | R32: 10
A33: 29 | B33: 45929 | E33: 3700 | F33: 96.42 | G33: =E33*F33 -> 356754 | H33: 15 | I33: 108.23 | J33: =H33*I33 -> 1623.45 | K33: =G33+J33 -> 358377.45 | L33: 0 | M33: =M32+K33-L33 -> 2535115.7 | Q33: 3742 | R33: 15
A34: 30 | B34: 45930 | D34: 42 | E34: 1042 | F34: 96.42 | G34: =E34*F34 -> 100469.64 | H34: 40 | I34: 108.23 | J34: =H34*I34 -> 4329.2 | K34: =G34+J34 -> 104798.84 | L34: 0 | M34: =M33+K34-L34 -> 2639914.6
A35: 31 | B35: 45931 | E35: 0 | F35: 0 | G35: =E35*F35 -> 0 | H35: 0 | I35: 0 | J35: =H35*I35 -> 0 | K35: =G35+J35 -> 0 | L35: 0 | M35: =M34+K35-L35 -> 2639914.6
E36: 0 | F36: 0 | G36: =E36*F36 -> 0 | H36: 0 | I36: 0 | J36: =H36*I36 -> 0 | K36: =G36+J36 -> 0 | M36: =M35+K36-L36 -> 2639914.6
E37: =SUM(E4:E35) -> 34171.99 | G37: =SUM(G4:G35) -> 3294863.3 | H37: =SUM(H4:H35) -> 592.72 | J37: =SUM(J4:J35) -> 64150.086 | K37: =SUM(K4:K35) -> 3359013.4 | L37: =SUM(L4:L35) -> 4555327.9
Q38: 04.9.2025
E39: 545.46 | H39: 365.04 | Q39: 5850
H40: 273 | K40: 3115380 | Q40: 19.09.2025
...

Sheet Jedcharla-2
A1: ADHOC FILLING STATION STATION
A2: S.No | B2: Date | C2: GRN No | D2: Ind No/Bill No | E2: Diesel (Lts) | F2: Price | G2: Amount | H2: Petrol (Lts) | I2: Price | J2: Amount | K2: Total amount | L2: Amount paid | M2: As on Date | N2: Remarks
A3: Opening Balance | K3: 0 | M3: =+K3 -> 0 | O3: 1400599.6
A4: 1 | B4: 45901 | E4: 2500 | F4: 96.43 | G4: =E4*F4 -> 241075 | J4: =H4*I4 -> 0 | K4: =G4+J4 -> 241075 | M4: =M3+K4-L4 -> 241075
A5: 2 | B5: 45902 | E5: 0 | F5: 0 | G5: =E5*F5 -> 0 | J5: =H5*I5 -> 0 | K5: =G5+J5 -> 0 | L5: 0 | M5: =M4+K5-L5 -> 241075
A6: 3 | B6: 45903 | E6: 2500 | F6: 96.43 | G6: =E6*F6 -> 241075 | J6: =H6*I6 -> 0 | K6: =G6+J6 -> 241075 | M6: =M5+K6-L6 -> 482150 | R6: 541.08
A7: 4 | B7: 45904 | E7: 2500 | F7: 96.43 | G7: =E7*F7 -> 241075 | J7: =H7*I7 -> 0 | K7: =G7+J7 -> 241075 | M7: =M6+K7-L7 -> 723225
A8: 5 | B8: 45905 | E8: 2500 | F8: 96.43 | G8: =E8*F8 -> 241075 | J8: =H8*I8 -> 0 | K8: =G8+J8 -> 241075 | M8: =M7+K8-L8 -> 964300
A9: 6 | B9: 45906 | E9: 2500 | F9: 96.43 | G9: =E9*F9 -> 241075 | J9: =H9*I9 -> 0 | K9: =G9+J9 -> 241075 | M9: =M8+K9-L9 -> 1205375
A10: 7 | B10: 45907 | E10: 2500 | F10: 96.43 | G10: =E10*F10 -> 241075 | J10: =H10*I10 -> 0 | K10: =G10+J10 -> 241075 | M10: =M9+K10-L10 -> 1446450
A11: 8 | B11: 45908 | E11: 2500 | F11: 96.43 | G11: =E11*F11 -> 241075 | J11: =H11*I11 -> 0 | K11: =G11+J11 -> 241075 | L11: 1446458 | M11: =M10+K11-L11 -> 241067
A12: 9 | B12: 45909 | E12: 0 | F12: 0 | G12: =E12*F12 -> 0 | J12: =H12*I12 -> 0 | K12: =G12+J12 -> 0 | M12: =M11+K12-L12 -> 241067
A13: 10 | B13: 45910 | E13: 1500 | F13: 96.43 | G13: =E13*F13 -> 144645 | J13: =H13*I13 -> 0 | K13: =G13+J13 -> 144645 | M13: =M12+K13-L13 -> 385712
A14: 11 | B14: 45911 | E14: 0 | F14: 0 | G14: =E14*F14 -> 0 | J14: =H14*I14 -> 0 | K14: =G14+J14 -> 0 | M14: =M13+K14-L14 -> 385712
A15: 12 | B15: 45912 | E15: 1000 | F15: 96.43 | G15: =E15*F15 -> 96430 | J15: =H15*I15 -> 0 | K15: =G15+J15 -> 96430 | M15: =M14+K15-L15 -> 482142
A16: 13 | B16: 45913 | E16: 0 | F16: 0 | G16: =E16*F16 -> 0 | J16: =H16*I16 -> 0 | K16: =G16+J16 -> 0 | M16: =M15+K16-L16 -> 482142
A17: 14 | B17: 45914 | E17: 0 | F17: 0 | G17: =E17*F17 -> 0 | J17: =H17*I17 -> 0 | K17: =G17+J17 -> 0 | M17: =M16+K17-L17 -> 482142
A18: 15 | B18: 45915 | E18: 0 | F18: 0 | G18: =E18*F18 -> 0 | J18: =H18*I18 -> 0 | K18: =G18+J18 -> 0 | M18: =M17+K18-L18 -> 482142
A19: 16 | B19: 45916 | E19: 0 | F19: 0 | G19: =E19*F19 -> 0 | J19: =H19*I19 -> 0 | K19: =G19+J19 -> 0 | M19: =M18+K19-L19 -> 482142
A20: 17 | B20: 45917 | E20: 0 | F20: 0 | G20: =E20*F20 -> 0 | J20: =H20*I20 -> 0 | K20: =G20+J20 -> 0 | M20: =M19+K20-L20 -> 482142
A21: 18 | B21: 45918 | E21: 0 | F21: 0 | G21: =E21*F21 -> 0 | J21: =H21*I21 -> 0 | K21: =G21+J21 -> 0 | M21: =M20+K21-L21 -> 482142
A22: 19 | B22: 45919 | E22: 2200 | F22: 96.43 | G22: =E22*F22 -> 212146 | J22: =H22*I22 -> 0 | K22: =G22+J22 -> 212146 | M22: =M21+K22-L22 -> 694288
A23: 20 | B23: 45920 | E23: 0 | F23: 0 | G23: =E23*F23 -> 0 | J23: =H23*I23 -> 0 | K23: =G23+J23 -> 0 | M23: =M22+K23-L23 -> 694288
... A29: 26 | B29: 45926 | E29: 0 | F29: 0 | G29: =E29*F29 -> 0 | J29: =H29*I29 -> 0 | K29: =G29+J29 -> 0 | M29: =M28+K29-L29 -> 838933
A30: 27 | B30: 45927 | E30: 0 | F30: 0 | G30: =E30*F30 -> 0 | J30: =H30*I30 -> 0 | K30: =G30+J30 -> 0 | L30: 600000 | M30: =M29+K30-L30 -> 238933
A31: 28 | B31: 45928 | E31: 0 | F31: 0 | G31: =E31*F31 -> 0 | J31: =H31*I31 -> 0 | K31: =G31+J31 -> 0 | M31: =M30+K31-L31 -> 238933
A32: 29 | B32: 45929 | E32: 0 | F32: 0 | G32: =E32*F32 -> 0 | J32: =H32*I32 -> 0 | K32: =G32+J32 -> 0 | M32: =M31+K32-L32 -> 238933
A33: 30 | B33: 45930 | E33: 0 | F33: 0 | G33: =E33*F33 -> 0 | J33: =H33*I33 -> 0 | K33: =G33+J33 -> 0 | M33: =M32+K33-L33 -> 238933
A34: 31 | E34: 0 | F34: 0 | G34: =E34*F34 -> 0 | J34: =H34*I34 -> 0 | K34: =G34+J34 -> 0 | M34: =M33+K34-L34 -> 238933 | O34: 1688453.6 | P34: 1900671 | Q34: =P34-O34 -> 212217.42
E35: =SUM(E4:E34) -> 23700 | G35: =SUM(G4:G34) -> 2285391 | H35: =SUM(H4:H34) -> 0 | J35: =SUM(J4:J34) -> 0 | K35: =SUM(K4:K34) -> 2285391 | L35: =SUM(L4:L34) -> 2046458

Sheet Devarakhadra
A1: Kurumurthy Swami F/S
A2: S.No | B2: Date | C2: GRN No | D2: Ind no/Bill No | E2: Diesel (Lts) | F2: Price | G2: Amount | H2: Petrol (Lts) | I2: Price | J2: Amount | K2: Total amount | L2: Amount paid | M2: As on Date | N2: Remarks
A3: Opening Balance | M3: 562989.59 | O3: 580925.58
A4: 1 | B4: 45901 | E4: 890 | F4: 97.1 | G4: =E4*F4 -> 86419 | H4: 5 | I4: 108.83 | J4: =H4*I4 -> 544.15 | K4: =G4+J4 -> 86963.15 | L4: 300000 | M4: =+M3+K4-L4 -> 349952.74
A5: 2 | B5: 45902 | E5: 768 | F5: 97.1 | G5: =E5*F5 -> 74572.8 | H5: 0 | I5: 0 | J5: =H5*I5 -> 0 | K5: =G5+J5 -> 74572.8 | L5: 0 | M5: =+M4+K5-L5 -> 424525.54
A6: 3 | B6: 45903 | E6: 655.38 | F6: 97.1 | G6: =E6*F6 -> 63637.398 | H6: 5 | I6: 108.83 | J6: =H6*I6 -> 544.15 | K6: =G6+J6 -> 64181.548 | L6: 0 | M6: =+M5+K6-L6 -> 488707.09
A7: 4 | B7: 45904 | E7: 887.52 | F7: 97.1 | G7: =E7*F7 -> 86178.192 | H7: 5 | I7: 108.83 | J7: =H7*I7 -> 544.15 | K7: =G7+J7 -> 86722.342 | L7: 0 | M7: =+M6+K7-L7 -> 575429.43
A8: 5 | B8: 45905 | E8: 1093 | F8: 97.1 | G8: =E8*F8 -> 106130.3 | H8: 0 | I8: 108.83 | J8: =H8*I8 -> 0 | K8: =G8+J8 -> 106130.3 | L8: 0 | M8: =+M7+K8-L8 -> 681559.73
A9: 6 | B9: 45906 | E9: 580 | F9: 97.1 | G9: =E9*F9 -> 56318 | H9: 1 | I9: 108.83 | J9: =H9*I9 -> 108.83 | K9: =G9+J9 -> 56426.83 | L9: 0 | M9: =+M8+K9-L9 -> 737986.56
A10: 7 | B10: 45907 | E10: 0 | F10: 0 | G10: =E10*F10 -> 0 | H10: 12 | I10: 108.83 | J10: =H10*I10 -> 1305.96 | K10: =G10+J10 -> 1305.96 | L10: 0 | M10: =+M9+K10-L10 -> 739292.52
A11: 8 | B11: 45908 | E11: 100 | F11: 97.1 | G11: =E11*F11 -> 9710 | H11: 9 | I11: 108.83 | J11: =H11*I11 -> 979.47 | K11: =G11+J11 -> 10689.47 | L11: 739000 | M11: =+M10+K11-L11 -> 10981.991
A12: 9 | B12: 45909 | E12: 0 | F12: 0 | G12: =E12*F12 -> 0 | H12: 0 | I12: 0 | J12: =H12*I12 -> 0 | K12: =G12+J12 -> 0 | L12: 0 | M12: =+M11+K12-L12 -> 10981.991
A13: 10 | B13: 45910 | E13: 653.24 | F13: 97.1 | G13: =E13*F13 -> 63429.604 | H13: 6 | I13: 108.83 | J13: =H13*I13 -> 652.98 | K13: =G13+J13 -> 64082.584 | L13: 0 | M13: =+M12+K13-L13 -> 75064.575
A14: 11 | B14: 45911 | E14: 36 | F14: 97.1 | G14: =E14*F14 -> 3495.6 | H14: 5 | I14: 108.83 | J14: =H14*I14 -> 544.15 | K14: =G14+J14 -> 4039.75 | L14: 0 | M14: =+M13+K14-L14 -> 79104.325
A15: 12 | B15: 45912 | E15: 255 | F15: 97.1 | G15: =E15*F15 -> 24760.5 | H15: 15 | I15: 108.83 | J15: =H15*I15 -> 1632.45 | K15: =G15+J15 -> 26392.95 | L15: 0 | M15: =+M14+K15-L15 -> 105497.27
... A18: 15 | B18: 45915 | E18: 1187 | F18: 97.1 | G18: =E18*F18 -> 115257.7 | H18: 7 | I18: 108.83 | J18: =H18*I18 -> 761.81 | K18: =G18+J18 -> 116019.51 | L18: 0 | M18: =+M17+K18-L18 -> 255505.82
A19: 16 | B19: 45916 | E19: 886.27 | F19: 97.1 | G19: =E19*F19 -> 86056.817 | H19: 0 | I19: 0 | J19: =H19*I19 -> 0 | K19: =G19+J19 -> 86056.817 | L19: 0 | M19: =+M18+K19-L19 -> 341562.64 | N19: Fuel bills
A20: 17 | B20: 45917 | E20: 140 | F20: 97.1 | G20: =E20*F20 -> 13594 | H20: 12 | I20: 108.83 | J20: =H20*I20 -> 1305.96 | K20: =G20+J20 -> 14899.96 | L20: 0 | M20: =+M19+K20-L20 -> 356462.6
A21: 18 | B21: 45918 | E21: 1035.9 | F21: 97.1 | G21: =E21*F21 -> 100585.89 | H21: 0 | I21: 0 | J21: =H21*I21 -> 0 | K21: =G21+J21 -> 100585.89 | L21: 200000 | M21: =+M20+K21-L21 -> 257048.49
A22: 19 | B22: 45919 | E22: 675 | F22: 97.1 | G22: =E22*F22 -> 65542.5 | H22: 9 | I22: 108.83 | J22: =H22*I22 -> 979.47 | K22: =G22+J22 -> 66521.97 | L22: 0 | M22: =+M21+K22-L22 -> 323570.46
A23: 20 | B23: 45920 | E23: 1177.88 | F23: 97.1 | G23: =E23*F23 -> 114372.15 | H23: 5 | I23: 108.83 | J23: =H23*I23 -> 544.15 | K23: =G23+J23 -> 114916.3 | L23: 0 | M23: =+M22+K23-L23 -> 438486.76
A24: 21 | B24: 45921 | E24: 410 | F24: 97.1 | G24: =E24*F24 -> 39811 | H24: 5 | I24: 108.83 | J24: =H24*I24 -> 544.15 | K24: =G24+J24 -> 40355.15 | L24: 0 | M24: =+M23+K24-L24 -> 478841.91
A25: 22 | B25: 45922 | E25: 730 | F25: 97.1 | G25: =E25*F25 -> 70883 | H25: 7 | I25: 108.83 | J25: =H25*I25 -> 761.81 | K25: =G25+J25 -> 71644.81 | L25: 0 | M25: =+M24+K25-L25 -> 550486.72
A26: 23 | B26: 45923 | E26: 707.3 | F26: 97.1 | G26: =E26*F26 -> 68678.83 | H26: 5 | I26: 108.83 | J26: =H26*I26 -> 544.15 | K26: =G26+J26 -> 69222.98 | L26: 0 | M26: =+M25+K26-L26 -> 619709.7
A27: 24 | B27: 45924 | E27: 1057.6 | F27: 97.1 | G27: =E27*F27 -> 102692.96 | H27: 10 | I27: 108.83 | J27: =H27*I27 -> 1088.3 | K27: =G27+J27 -> 103781.26 | L27: 0 | M27: =+M26+K27-L27 -> 723490.96
A28: 25 | B28: 45925 | E28: 1377 | F28: 97.1 | G28: =E28*F28 -> 133706.7 | H28: 10 | I28: 108.83 | J28: =H28*I28 -> 1088.3 | K28: =G28+J28 -> 134795 | L28: 0 | M28: =+M27+K28-L28 -> 858285.96
A29: 26 | B29: 45926 | E29: 0 | F29: 97.1 | G29: =E29*F29 -> 0 | H29: 0 | I29: 108.83 | J29: =H29*I29 -> 0 | K29: =G29+J29 -> 0 | L29: 800000 | M29: =+M28+K29-L29 -> 58285.96
A30: 27 | B30: 45927 | E30: 20 | F30: 97.1 | G30: =E30*F30 -> 1942 | H30: 10 | I30: 108.83 | J30: =H30*I30 -> 1088.3 | K30: =G30+J30 -> 3030.3 | L30: 0 | M30: =+M29+K30-L30 -> 61316.26
A31: 28 | B31: 45928 | E31: 105 | F31: 97.1 | G31: =E31*F31 -> 10195.5 | H31: 0 | I31: 0 | J31: =H31*I31 -> 0 | K31: =G31+J31 -> 10195.5 | L31: 0 | M31: =+M30+K31-L31 -> 71511.76
... A34: 31 | B34: 45931 | E34: 0 | F34: 0 | G34: =E34*F34 -> 0 | H34: 0 | I34: 0 | J34: =H34*I34 -> 0 | K34: =G34+J34 -> 0 | L34: 0 | M34: =+M33+K34-L34 -> 121213.37
E35: =SUM(E4:E34) -> 16286.75 | G35: =SUM(G4:G34) -> 1581443.4 | H35: =SUM(H4:H34) -> 145 | J35: =SUM(J4:J34) -> 15780.35 | K35: =SUM(K4:K34) -> 1597223.8 | L35: =SUM(L4:L34) -> 2039000

Sheet Devarakhadra-2
A1: Sri rama F/S
A2: S.No | B2: Date | C2: GRN No | D2: Ind no/Bill No | E2: Diesel (Lts) | F2: Price | G2: Amount | H2: Petrol (Lts) | I2: Price | J2: Amount | K2: Total amount | L2: Amount paid | M2: As on Date | N2: Remarks
A3: Opening Balance | M3: 134013.54
A4: 1 | B4: 45901 | E4: 0 | F4: 0 | G4: =E4*F4 -> 0 | H4: 0 | I4: 0 | J4: =H4*I4 -> 0 | K4: =G4+J4 -> 0 | L4: 0 | M4: =+M3+K4-L4 -> 134013.54
A5: 2 | B5: 45902 | E5: 0 | F5: 0 | G5: =E5*F5 -> 0 | H5: 0 | I5: 0 | J5: =H5*I5 -> 0 | K5: =G5+J5 -> 0 | L5: 0 | M5: =+M4+K5-L5 -> 134013.54
A6: 3 | B6: 45903 | E6: 0 | F6: 0 | G6: =E6*F6 -> 0 | H6: 0 | I6: 0 | J6: =H6*I6 -> 0 | K6: =G6+J6 -> 0 | L6: 0 | M6: =+M5+K6-L6 -> 134013.54
A7: 4 | B7: 45904 | E7: 0 | F7: 0 | G7: =E7*F7 -> 0 | H7: 0 | I7: 0 | J7: =H7*I7 -> 0 | K7: =G7+J7 -> 0 | L7: 0 | M7: =+M6+K7-L7 -> 134013.54
A8: 5 | B8: 45905 | E8: 0 | F8: 0 | G8: =E8*F8 -> 0 | H8: 0 | I8: 0 | J8: =H8*I8 -> 0 | K8: =G8+J8 -> 0 | L8: 0 | M8: =+M7+K8-L8 -> 134013.54
A9: 6 | B9: 45906 | E9: 600 | F9: 97.1 | G9: =E9*F9 -> 58260 | H9: 0 | I9: 0 | J9: =H9*I9 -> 0 | K9: =G9+J9 -> 58260 | L9: 0 | M9: =+M8+K9-L9 -> 192273.54
A10: 7 | B10: 45907 | E10: 0 | F10: 0 | G10: =E10*F10 -> 0 | H10: 0 | I10: 0 | J10: =H10*I10 -> 0 | K10: =G10+J10 -> 0 | L10: 0 | M10: =+M9+K10-L10 -> 192273.54
A11: 8 | B11: 45908 | E11: 600 | F11: 97.1 | G11: =E11*F11 -> 58260 | H11: 0 | I11: 0 | J11: =H11*I11 -> 0 | K11: =G11+J11 -> 58260 | L11: 60000 | M11: =+M10+K11-L11 -> 190533.54
A12: 9 | B12: 45909 | E12: 0 | F12: 0 | G12: =E12*F12 -> 0 | H12: 0 | I12: 0 | J12: =H12*I12 -> 0 | K12: =G12+J12 -> 0 | L12: 0 | M12: =+M11+K12-L12 -> 190533.54
A13: 10 | B13: 45910 | E13: 0 | F13: 0 | G13: =E13*F13 -> 0 | H13: 0 | I13: 0 | J13: =H13*I13 -> 0 | K13: =G13+J13 -> 0 | L13: 0 | M13: =+M12+K13-L13 -> 190533.54
A14: 11 | B14: 45911 | E14: 0 | F14: 0 | G14: =E14*F14 -> 0 | H14: 0 | I14: 0 | J14: =H14*I14 -> 0 | K14: =G14+J14 -> 0 | L14: 58260 | M14: =+M13+K14-L14 -> 132273.54
A15: 12 | B15: 45912 | E15: 0 | F15: 0 | G15: =E15*F15 -> 0 | H15: 0 | I15: 0 | J15: =H15*I15 -> 0 | K15: =G15+J15 -> 0 | L15: 0 | M15: =+M14+K15-L15 -> 132273.54
... A33: 30 | B33: 45930 | E33: 0 | F33: 0 | G33: =E33*F33 -> 0 | H33: 0 | I33: 0 | J33: =H33*I33 -> 0 | K33: =G33+J33 -> 0 | L33: 0 | M33: =+M32+K33-L33 -> 132273.54
A34: 31 | E34: 0 | F34: 0 | G34: =E34*F34 -> 0 | H34: 0 | I34: 0 | J34: =H34*I34 -> 0 | K34: =G34+J34 -> 0 | L34: 0 | M34: =+M33+K34-L34 -> 132273.54
E35: =SUM(E4:E34) -> 1200 | G35: =SUM(G4:G34) -> 116520 | H35: =SUM(H4:H34) -> 0 | J35: =SUM(J4:J34) -> 0 | K35: =SUM(K4:K34) -> 116520 | L35: =SUM(L4:L34) -> 118260
F38: /

Sheet Dindi
A1: Akarapu Balakistamma Fillling
A2: S.No | B2: Date | C2: GRN No | D2: Ind no/Bill No | E2: Diesel (Lts) | F2: Price | G2: Amount | H2: Petrol (Lts) | I2: Price | J2: Amount | K2: Total amount | L2: Amount paid | M2: As on Date | N2: Remarks
A3: Opening Balance | M3: 0
A4: 1 | B4: 45901 | E4: 0 | F4: 0 | G4: =E4*F4 -> 0 | H4: 0 | I4: 0 | J4: =H4*I4 -> 0 | K4: =G4+J4 -> 0 | L4: =+K4 -> 0 | M4: 0
A5: 2 | B5: 45902 | E5: 34.3 | F5: 96.83 | G5: =E5*F5 -> 3321.269 | H5: 0 | I5: 0 | J5: =H5*I5 -> 0 | K5: =G5+J5 -> 3321.269 | L5: =+K5 -> 3321.269 | M5: 0
A6: 3 | B6: 45903 | E6: 0 | F6: 0 | G6: =E6*F6 -> 0 | H6: 0 | I6: 0 | J6: =H6*I6 -> 0 | K6: =G6+J6 -> 0 | L6: =+K6 -> 0 | M6: 0
A7: 4 | B7: 45904 | E7: 0 | F7: 0 | G7: =E7*F7 -> 0 | H7: 0 | I7: 0 | J7: =H7*I7 -> 0 | K7: =G7+J7 -> 0 | L7: =+K7 -> 0 | M7: 0
A8: 5 | B8: 45905 | E8: 0 | F8: 0 | G8: =E8*F8 -> 0 | H8: 0 | I8: 0 | J8: =H8*I8 -> 0 | K8: =G8+J8 -> 0 | L8: =+K8 -> 0 | M8: 0
A9: 6 | B9: 45906 | E9: 0 | F9: 0 | G9: =E9*F9 -> 0 | H9: 0 | I9: 0 | J9: =H9*I9 -> 0 | K9: =G9+J9 -> 0 | L9: =+K9 -> 0 | M9: 0
A10: 7 | B10: 45907 | E10: 0 | F10: 0 | G10: =E10*F10 -> 0 | H10: 0 | I10: 0 | J10: =H10*I10 -> 0 | K10: =G10+J10 -> 0 | L10: =+K10 -> 0 | M10: 0
A11: 8 | B11: 45908 | E11: 45.18 | F11: 96.07 | G11: =E11*F11 -> 4340.4426 | H11: 0 | I11: 0 | J11: =H11*I11 -> 0 | K11: =G11+J11 -> 4340.4426 | L11: =+K11 -> 4340.4426 | M11: 0
A12: 9 | B12: 45909 | E12: 0 | F12: 0 | G12: =E12*F12 -> 0 | H12: 0 | I12: 0 | J12: =H12*I12 -> 0 | K12: =G12+J12 -> 0 | L12: =+K12 -> 0 | M12: 0
A13: 10 | B13: 45910 | E13: 0 | F13: 0 | G13: =E13*F13 -> 0 | H13: 0 | I13: 0 | J13: =H13*I13 -> 0 | K13: =G13+J13 -> 0 | L13: =+K13 -> 0 | M13: 0
A14: 11 | B14: 45911 | E14: 0 | F14: 0 | G14: =E14*F14 -> 0 | H14: 0 | I14: 0 | J14: =H14*I14 -> 0 | K14: =G14+J14 -> 0 | L14: =+K14 -> 0 | M14: 0
A15: 12 | B15: 45912 | E15: 0 | F15: 0 | G15: =E15*F15 -> 0 | H15: 0 | I15: 0 | J15: =H15*I15 -> 0 | K15: =G15+J15 -> 0 | L15: =+K15 -> 0 | M15: 0
... A33: 30 | B33: 45930 | E33: 0 | F33: 0 | G33: =E33*F33 -> 0 | H33: 0 | I33: 0 | J33: =H33*I33 -> 0 | K33: =G33+J33 -> 0 | L33: =+K33 -> 0 | M33: 0
A34: 31 | E34: 0 | F34: 0 | G34: =E34*F34 -> 0 | H34: 0 | I34: 0 | J34: =H34*I34 -> 0 | K34: =G34+J34 -> 0 | L34: =+K34 -> 0 | M34: 0
E35: =SUM(E4:E34) -> 118.69 | G35: =SUM(G4:G34) -> 11458.416 | H35: =SUM(H4:H34) -> 0 | J35: =SUM(J4:J34) -> 0 | K35: =SUM(K4:K34) -> 11458.416 | L35: =SUM(L4:L34) -> 11458.416

Sheet Amalapuram
A1: Sathya Filling Station
A2: S.No | B2: Date | C2: GRN No | D2: Ind no/Bill No | E2: Diesel (Lts) | F2: Price | G2: Amount | H2: Petrol (Lts) | I2: Price | J2: Amount | K2: Total amount | L2: Amount paid | M2: As on Date | N2: Remarks
A3: Opening Balance | M3: 0
A4: 1 | B4: 45901 | E4: 0 | F4: 0 | G4: =E4*F4 -> 0 | H4: 25 | I4: 109.01 | J4: =H4*I4 -> 2725.25 | K4: =G4+J4 -> 2725.25 | L4: 2725.25 | M4: =+M3+K4-L4 -> 0
A5: 2 | B5: 45902 | E5: 0 | F5: 0 | G5: =E5*F5 -> 0 | H5: 0 | I5: 0 | J5: =H5*I5 -> 0 | K5: =G5+J5 -> 0 | L5: 0 | M5: =+M4+K5-L5 -> 0
A6: 3 | B6: 45903 | E6: 0 | F6: 0 | G6: =E6*F6 -> 0 | H6: 0 | I6: 0 | J6: =H6*I6 -> 0 | K6: =G6+J6 -> 0 | L6: 0 | M6: =+M5+K6-L6 -> 0
A7: 4 | B7: 45904 | E7: 0 | F7: 0 | G7: =E7*F7 -> 0 | H7: 0 | I7: 0 | J7: =H7*I7 -> 0 | K7: =G7+J7 -> 0 | L7: 0 | M7: =+M6+K7-L7 -> 0
A8: 5 | B8: 45905 | E8: 0 | F8: 0 | G8: =E8*F8 -> 0 | H8: 0 | I8: 0 | J8: =H8*I8 -> 0 | K8: =G8+J8 -> 0 | L8: 0 | M8: =+M7+K8-L8 -> 0
A9: 6 | B9: 45906 | E9: 0 | F9: 0 | G9: =E9*F9 -> 0 | H9: 6 | I9: 109.94 | J9: =H9*I9 -> 659.64 | K9: =G9+J9 -> 659.64 | L9: 659.64 | M9: =+M8+K9-L9 -> 0
A10: 7 | B10: 45907 | E10: 0 | F10: 0 | G10: =E10*F10 -> 0 | H10: 0 | I10: 0 | J10: =H10*I10 -> 0 | K10: =G10+J10 -> 0 | L10: 0 | M10: =+M9+K10-L10 -> 0
A11: 8 | B11: 45908 | E11: 0 | F11: 0 | G11: =E11*F11 -> 0 | H11: 10 | I11: 109.94 | J11: =H11*I11 -> 1099.4 | K11: =G11+J11 -> 1099.4 | L11: 1099.4 | M11: =+M10+K11-L11 -> 0
A12: 9 | B12: 45909 | E12: 0 | F12: 0 | G12: =E12*F12 -> 0 | H12: 4.55 | I12: 109.94 | J12: =H12*I12 -> 500.227 | K12: =G12+J12 -> 500.227 | L12: 500.23 | M12: =+M11+K12-L12 -> -0.003
A13: 10 | B13: 45910 | E13: 0 | F13: 0 | G13: =E13*F13 -> 0 | H13: 0 | I13: 0 | J13: =H13*I13 -> 0 | K13: =G13+J13 -> 0 | L13: 0 | M13: =+M12+K13-L13 -> -0.003
A14: 11 | B14: 45911 | E14: 36 | F14: 97.91 | G14: =E14*F14 -> 3524.76 | H14: 5 | I14: 109.94 | J14: =H14*I14 -> 549.7 | K14: =G14+J14 -> 4074.46 | L14: 4074.46 | M14: =+M13+K14-L14 -> -0.003
A15: 12 | B15: 45912 | E15: 0 | F15: 0 | G15: =E15*F15 -> 0 | H15: 25 | I15: 109.94 | J15: =H15*I15 -> 2748.5 | K15: =G15+J15 -> 2748.5 | L15: 2748.5 | M15: =+M14+K15-L15 -> -0.003
... A31: 28 | B31: 45928 | E31: 0 | F31: 0 | G31: =E31*F31 -> 0 | H31: 0 | I31: 0 | J31: =H31*I31 -> 0 | K31: =G31+J31 -> 0 | L31: 0 | M31: =+M30+K31-L31 -> -0.0026
A32: 29 | B32: 45929 | E32: 10.25 | F32: 97.56 | G32: =E32*F32 -> 999.99 | H32: 0 | I32: 0 | J32: =H32*I32 -> 0 | K32: =G32+J32 -> 999.99 | L32: =H32+K32 -> 999.99 | M32: =+M31+K32-L32 -> -0.0026
B33: 45929 | E33: 40.26 | F33: 86.75 | G33: =E33*F33 -> 3492.555 | H33: 25 | I33: 96.92 | J33: =H33*I33 -> 2423 | K33: =G33+J33 -> 5915.555 | L33: =K33 -> 5915.555 | M33: =+M32+K33-L33 -> -0.0026
A34: 30 | B34: 45930 | E34: 0 | F34: 0 | G34: =E34*F34 -> 0 | H34: 0 | I34: 0 | J34: =H34*I34 -> 0 | K34: =G34+J34 -> 0 | L34: 0 | M34: =+M33+K34-L34 -> -0.0026
A35: 31 | E35: 0 | F35: 0 | G35: =E35*F35 -> 0 | H35: 0 | I35: 0 | J35: =H35*I35 -> 0 | K35: =G35+J35 -> 0 | L35: 0 | M35: =+M34+K35-L35 -> -0.0026
E36: =SUM(E4:E35) -> 148.48 | G36: =SUM(G4:G35) -> 14017.24 | H36: =SUM(H4:H35) -> 186.05 | J36: =SUM(J4:J35) -> 20075.552 | K36: =SUM(K4:K35) -> 34092.792 | L36: =SUM(L4:L35) -> 34092.795

Sheet Kadur
A1: Vishal Service Station
A2: S.No | B2: Date | C2: GRN No | D2: Ind No/Bill No | E2: Diesel (Lts) | F2: Price | G2: Amount | H2: Petrol (Lts) | I2: Price | J2: Amount | K2: Total amount | L2: Amount paid | M2: As on Date | N2: Remarks
A3: Opening Balance | K3: 417039.13 | M3: 417039.13 | O3: 207239.43
A4: 1 | B4: 45901 | F4: 0 | G4: =E4*F4 -> 0 | H4: 0 | I4: 0 | J4: =H4*I4 -> 0 | K4: =G4+J4 -> 0 | M4: =M3+K4-L4 -> 417039.13
A5: 2 | B5: 45902 | F5: 0 | G5: =E5*F5 -> 0 | H5: 0 | I5: 0 | J5: =H5*I5 -> 0 | K5: =G5+J5 -> 0 | M5: =M4+K5-L5 -> 417039.13
A6: 3 | B6: 45903 | F6: 0 | G6: =E6*F6 -> 0 | H6: 0 | I6: 0 | J6: =H6*I6 -> 0 | K6: =G6+J6 -> 0 | M6: =M5+K6-L6 -> 417039.13
A7: 4 | B7: 45904 | F7: 0 | G7: =E7*F7 -> 0 | H7: 0 | I7: 0 | J7: =H7*I7 -> 0 | K7: =G7+J7 -> 0 | M7: =M6+K7-L7 -> 417039.13
A8: 5 | B8: 45905 | F8: 0 | G8: =E8*F8 -> 0 | H8: 0 | I8: 0 | J8: =H8*I8 -> 0 | K8: =G8+J8 -> 0 | M8: =M7+K8-L8 -> 417039.13
A9: 6 | B9: 45906 | F9: 0 | G9: =E9*F9 -> 0 | H9: 0 | I9: 0 | J9: =H9*I9 -> 0 | K9: =G9+J9 -> 0 | M9: =M8+K9-L9 -> 417039.13
A10: 7 | B10: 45907 | F10: 0 | G10: =E10*F10 -> 0 | H10: 0 | I10: 0 | J10: =H10*I10 -> 0 | K10: =G10+J10 -> 0 | M10: =M9+K10-L10 -> 417039.13
A11: 8 | B11: 45908 | F11: 0 | G11: =E11*F11 -> 0 | H11: 0 | I11: 0 | J11: =H11*I11 -> 0 | K11: =G11+J11 -> 0 | L11: 417000 | M11: =M10+K11-L11 -> 39.131
A12: 9 | B12: 45909 | F12: 0 | G12: =E12*F12 -> 0 | H12: 0 | I12: 0 | J12: =H12*I12 -> 0 | K12: =G12+J12 -> 0 | M12: =M11+K12-L12 -> 39.131
A13: 10 | B13: 45910 | F13: 0 | G13: =E13*F13 -> 0 | H13: 0 | I13: 0 | J13: =H13*I13 -> 0 | K13: =G13+J13 -> 0 | M13: =M12+K13-L13 -> 39.131
A14: 11 | B14: 45911 | F14: 0 | G14: =E14*F14 -> 0 | H14: 0 | I14: 0 | J14: =H14*I14 -> 0 | K14: =G14+J14 -> 0 | M14: =M13+K14-L14 -> 39.131
A15: 12 | B15: 45912 | F15: 0 | G15: =E15*F15 -> 0 | H15: 0 | I15: 0 | J15: =H15*I15 -> 0 | K15: =G15+J15 -> 0 | M15: =M14+K15-L15 -> 39.131
A16: 13 | B16: 45913 | F16: 0 | G16: =E16*F16 -> 0 | H16: 0 | I16: 0 | J16: =H16*I16 -> 0 | K16: =G16+J16 -> 0 | M16: =M15+K16-L16 -> 39.131
A17: 14 | B17: 45914 | F17: 0 | G17: =E17*F17 -> 0 | H17: 0 | I17: 0 | J17: =H17*I17 -> 0 | K17: =G17+J17 -> 0 | M17: =M16+K17-L17 -> 39.131
A18: 15 | B18: 45915 | F18: 0 | G18: =E18*F18 -> 0 | H18: 0 | I18: 0 | J18: =H18*I18 -> 0 | K18: =G18+J18 -> 0 | M18: =M17+K18-L18 -> 39.131
A19: 16 | B19: 45916 | F19: 0 | G19: =E19*F19 -> 0 | H19: 0 | I19: 0 | J19: =H19*I19 -> 0 | K19: =G19+J19 -> 0 | M19: =M18+K19-L19 -> 39.131
A20: 17 | B20: 45917 | F20: 0 | G20: =E20*F20 -> 0 | H20: 0 | I20: 0 | J20: =H20*I20 -> 0 | K20: =G20+J20 -> 0 | M20: =M19+K20-L20 -> 39.131
A21: 18 | B21: 45918 | F21: 0 | G21: =E21*F21 -> 0 | H21: 0 | I21: 0 | J21: =H21*I21 -> 0 | K21: =G21+J21 -> 0 | M21: =M20+K21-L21 -> 39.131
A22: 19 | B22: 45919 | F22: 0 | G22: =E22*F22 -> 0 | H22: 0 | I22: 0 | J22: =H22*I22 -> 0 | K22: =G22+J22 -> 0 | M22: =M21+K22-L22 -> 39.131
A23: 20 | B23: 45920 | F23: 0 | G23: =E23*F23 -> 0 | H23: 0 | I23: 0 | J23: =H23*I23 -> 0 | K23: =G23+J23 -> 0 | M23: =M22+K23-L23 -> 39.131
... A33: 30 | B33: 45930 | F33: 0 | G33: =E33*F33 -> 0 | H33: 0 | I33: 0 | J33: =H33*I33 -> 0 | K33: =G33+J33 -> 0 | M33: =M32+K33-L33 -> 11508.831
A34: 31 | F34: 0 | G34: =E34*F34 -> 0 | J34: =H34*I34 -> 0 | K34: =G34+J34 -> 0
E35: =SUM(E4:E34) -> 0 | G35: =SUM(G4:G34) -> 0 | H35: =SUM(H4:H34) -> 110 | J35: =SUM(J4:J34) -> 11469.7 | K35: =SUM(K4:K34) -> 11469.7 | L35: =SUM(L4:L31) -> 417000

Sheet YG Gudda 
A1: Pallavi Petrolium
A2: S.No | B2: Date | C2: GRN No | D2: Ind No/Bill No | E2: Diesel (Lts) | F2: Price | G2: Amount | H2: Petrol (Lts) | I2: Price | J2: Amount | K2: Total amount | L2: Amount paid | M2: As on Date | N2: Remarks
A3: Opening Balance | K3: 284233.21 | M3: =+K3 -> 284233.21
A4: 1 | B4: 45901 | E4: 1000 | F4: 91.3 | G4: =E4*F4 -> 91300 | H4: 105 | I4: 103.24 | J4: =H4*I4 -> 10840.2 | K4: =G4+J4 -> 102140.2 | L4: 150000 | M4: =M3+K4-L4 -> 236373.41
A5: 2 | B5: 45902 | E5: 0 | F5: 0 | G5: =E5*F5 -> 0 | H5: 0 | I5: 0 | J5: =H5*I5 -> 0 | K5: =G5+J5 -> 0 | M5: =M4+K5-L5 -> 236373.41
A6: 3 | B6: 45903 | E6: 0 | F6: 0 | G6: =E6*F6 -> 0 | H6: 0 | I6: 0 | J6: =H6*I6 -> 0 | K6: =G6+J6 -> 0 | M6: =M5+K6-L6 -> 236373.41
A7: 4 | B7: 45904 | E7: 0 | F7: 0 | G7: =E7*F7 -> 0 | H7: 0 | I7: 0 | J7: =H7*I7 -> 0 | K7: =G7+J7 -> 0 | M7: =M6+K7-L7 -> 236373.41
A8: 5 | B8: 45905 | E8: 0 | F8: 0 | G8: =E8*F8 -> 0 | H8: 0 | I8: 0 | J8: =H8*I8 -> 0 | K8: =G8+J8 -> 0 | M8: =M7+K8-L8 -> 236373.41
A9: 6 | B9: 45906 | E9: 0 | F9: 0 | G9: =E9*F9 -> 0 | H9: 0 | I9: 0 | J9: =H9*I9 -> 0 | K9: =G9+J9 -> 0 | M9: =M8+K9-L9 -> 236373.41
A10: 7 | B10: 45907 | E10: 0 | F10: 0 | G10: =E10*F10 -> 0 | H10: 0 | I10: 0 | J10: =H10*I10 -> 0 | K10: =G10+J10 -> 0 | M10: =M9+K10-L10 -> 236373.41
A11: 8 | B11: 45908 | E11: 0 | F11: 0 | G11: =E11*F11 -> 0 | H11: 0 | I11: 0 | J11: =H11*I11 -> 0 | K11: =G11+J11 -> 0 | L11: 200000 | M11: =M10+K11-L11 -> 36373.415
A12: 9 | B12: 45909 | E12: 0 | F12: 0 | G12: =E12*F12 -> 0 | H12: 0 | I12: 0 | J12: =H12*I12 -> 0 | K12: =G12+J12 -> 0 | M12: =M11+K12-L12 -> 36373.415
A13: 10 | B13: 45910 | E13: 0 | F13: 0 | G13: =E13*F13 -> 0 | H13: 0 | I13: 0 | J13: =H13*I13 -> 0 | K13: =G13+J13 -> 0 | M13: =M12+K13-L13 -> 36373.415
A14: 11 | B14: 45911 | E14: 0 | F14: 0 | G14: =E14*F14 -> 0 | H14: 0 | I14: 0 | J14: =H14*I14 -> 0 | K14: =G14+J14 -> 0 | M14: =M13+K14-L14 -> 36373.415
A15: 12 | B15: 45912 | E15: 0 | F15: 0 | G15: =E15*F15 -> 0 | H15: 0 | I15: 0 | J15: =H15*I15 -> 0 | K15: =G15+J15 -> 0 | M15: =M14+K15-L15 -> 36373.415
A16: 13 | B16: 45913 | E16: 0 | F16: 0 | G16: =E16*F16 -> 0 | H16: 0 | I16: 0 | J16: =H16*I16 -> 0 | K16: =G16+J16 -> 0 | M16: =M15+K16-L16 -> 36373.415
A17: 14 | B17: 45914 | E17: 0 | F17: 0 | G17: =E17*F17 -> 0 | H17: 0 | I17: 0 | J17: =H17*I17 -> 0 | K17: =G17+J17 -> 0 | M17: =M16+K17-L17 -> 36373.415
A18: 15 | B18: 45915 | E18: 0 | F18: 0 | G18: =E18*F18 -> 0 | H18: 0 | I18: 0 | J18: =H18*I18 -> 0 | K18: =G18+J18 -> 0 | M18: =M17+K18-L18 -> 36373.415
A19: 16 | B19: 45916 | E19: 2000 | F19: 91.3 | G19: =E19*F19 -> 182600 | H19: 105 | I19: 103.25 | J19: =H19*I19 -> 10841.25 | K19: =G19+J19 -> 193441.25 | M19: =M18+K19-L19 -> 229814.66
A20: 17 | B20: 45917 | E20: 0 | F20: 0 | G20: =E20*F20 -> 0 | H20: 0 | I20: 0 | J20: =H20*I20 -> 0 | K20: =G20+J20 -> 0 | M20: =M19+K20-L20 -> 229814.66
A21: 18 | B21: 45918 | E21: 0 | F21: 0 | G21: =E21*F21 -> 0 | H21: 0 | I21: 0 | J21: =H21*I21 -> 0 | K21: =G21+J21 -> 0 | M21: =M20+K21-L21 -> 229814.66
A22: 19 | B22: 45919 | E22: 0 | F22: 0 | G22: =E22*F22 -> 0 | H22: 0 | I22: 0 | J22: =H22*I22 -> 0 | K22: =G22+J22 -> 0 | M22: =M21+K22-L22 -> 229814.66
A23: 20 | B23: 45920 | E23: 0 | F23: 0 | G23: =E23*F23 -> 0 | H23: 0 | I23: 0 | J23: =H23*I23 -> 0 | K23: =G23+J23 -> 0 | M23: =M22+K23-L23 -> 229814.66
... A29: 26 | B29: 45926 | E29: 0 | F29: 0 | G29: =E29*F29 -> 0 | H29: 0 | I29: 0 | J29: =H29*I29 -> 0 | K29: =G29+J29 -> 0 | M29: =M28+K29-L29 -> 229814.66
A30: 27 | B30: 45927 | E30: 0 | F30: 0 | G30: =E30*F30 -> 0 | H30: 0 | I30: 0 | J30: =H30*I30 -> 0 | K30: =G30+J30 -> 0 | L30: 120000 | M30: =M29+K30-L30 -> 109814.66
A31: 28 | B31: 45928 | E31: 0 | F31: 0 | G31: =E31*F31 -> 0 | H31: 0 | I31: 0 | J31: =H31*I31 -> 0 | K31: =G31+J31 -> 0 | M31: =M30+K31-L31 -> 109814.66
A32: 29 | B32: 45929 | E32: 0 | F32: 0 | G32: =E32*F32 -> 0 | H32: 0 | I32: 0 | J32: =H32*I32 -> 0 | K32: =G32+J32 -> 0 | M32: =M31+K32-L32 -> 109814.66
A33: 30 | B33: 45930 | E33: 0 | F33: 0 | G33: =E33*F33 -> 0 | H33: 0 | I33: 0 | J33: =H33*I33 -> 0 | K33: =G33+J33 -> 0 | M33: =M32+K33-L33 -> 109814.66
A34: 31 | B34: 45931 | E34: 0 | F34: 0 | G34: =E34*F34 -> 0 | H34: 0 | I34: 0 | J34: =H34*I34 -> 0 | K34: =G34+J34 -> 0 | M34: =M33+K34-L34 -> 109814.66
A35: 32 | E35: 0 | F35: 0 | G35: =E35*F35 -> 0 | H35: 0 | I35: 0 | J35: =H35*I35 -> 0 | K35: =G35+J35 -> 0 | M35: =M34+K35-L35 -> 109814.66
E36: =SUM(E4:E35) -> 3000 | G36: =SUM(G4:G35) -> 273900 | H36: =SUM(H4:H35) -> 210 | J36: =SUM(J4:J35) -> 21681.45 | K36: =SUM(K4:K35) -> 295581.45 | L36: =SUM(L4:L35) -> 470000

Sheet YG Gudda-2
A1: Pankaja HP Fuel Center
A2: S.No | B2: Date | C2: GRN No | D2: Ind No/Bill No | E2: Diesel (Lts) | F2: Price | G2: Amount | H2: Petrol (Lts) | I2: Price | J2: Amount | K2: Total amount | L2: Amount paid | M2: As on Date | N2: Remarks
A3: Opening Balance | K3: 230070.7 | M3: =+K3 -> 230070.7 | O3: 99992.615
A4: 1 | B4: 45901 | E4: 0 | F4: 0 | G4: =E4*F4 -> 0 | H4: 0 | I4: 0 | J4: =H4*I4 -> 0 | K4: =G4+J4 -> 0 | L4: 230000 | M4: =M3+K4-L4 -> 70.7
A5: 2 | B5: 45902 | E5: 0 | F5: 0 | G5: =E5*F5 -> 0 | H5: 0 | I5: 0 | J5: =H5*I5 -> 0 | K5: =G5+J5 -> 0 | M5: =M4+K5-L5 -> 70.7
A6: 3 | B6: 45903 | E6: 2400 | F6: 91.33 | G6: =E6*F6 -> 219192 | H6: 0 | I6: 0 | J6: =H6*I6 -> 0 | K6: =G6+J6 -> 219192 | M6: =M5+K6-L6 -> 219262.7
A7: 4 | B7: 45904 | E7: 0 | F7: 0 | G7: =E7*F7 -> 0 | H7: 0 | I7: 0 | J7: =H7*I7 -> 0 | K7: =G7+J7 -> 0 | M7: =M6+K7-L7 -> 219262.7
A8: 5 | B8: 45905 | E8: 0 | F8: 0 | G8: =E8*F8 -> 0 | H8: 0 | I8: 0 | J8: =H8*I8 -> 0 | K8: =G8+J8 -> 0 | M8: =M7+K8-L8 -> 219262.7
A9: 6 | B9: 45906 | E9: 0 | F9: 0 | G9: =E9*F9 -> 0 | H9: 0 | I9: 0 | J9: =H9*I9 -> 0 | K9: =G9+J9 -> 0 | M9: =M8+K9-L9 -> 219262.7
A10: 7 | B10: 45907 | E10: 0 | F10: 0 | G10: =E10*F10 -> 0 | H10: 105 | I10: 103.27 | J10: =H10*I10 -> 10843.35 | K10: =G10+J10 -> 10843.35 | M10: =M9+K10-L10 -> 230106.05
A11: 8 | B11: 45908 | E11: 0 | F11: 0 | G11: =E11*F11 -> 0 | H11: 0 | I11: 0 | J11: =H11*I11 -> 0 | K11: =G11+J11 -> 0 | L11: 230000 | M11: =M10+K11-L11 -> 106.05
A12: 9 | B12: 45909 | E12: 1200 | F12: 91.33 | G12: =E12*F12 -> 109596 | H12: 70 | I12: 103.27 | J12: =H12*I12 -> 7228.9 | K12: =G12+J12 -> 116824.9 | M12: =M11+K12-L12 -> 116930.95
A13: 10 | B13: 45910 | E13: 0 | F13: 0 | G13: =E13*F13 -> 0 | H13: 0 | I13: 0 | J13: =H13*I13 -> 0 | K13: =G13+J13 -> 0 | M13: =M12+K13-L13 -> 116930.95
A14: 11 | B14: 45911 | E14: 0 | F14: 0 | G14: =E14*F14 -> 0 | H14: 0 | I14: 0 | J14: =H14*I14 -> 0 | K14: =G14+J14 -> 0 | M14: =M13+K14-L14 -> 116930.95
A15: 12 | B15: 45912 | E15: 1500 | F15: 91.33 | G15: =E15*F15 -> 136995 | H15: 70 | I15: 103.27 | J15: =H15*I15 -> 7228.9 | K15: =G15+J15 -> 144223.9 | M15: =M14+K15-L15 -> 261154.85
A16: 13 | B16: 45913 | E16: 0 | F16: 0 | G16: =E16*F16 -> 0 | H16: 0 | I16: 0 | J16: =H16*I16 -> 0 | K16: =G16+J16 -> 0 | M16: =M15+K16-L16 -> 261154.85
A17: 14 | B17: 45914 | E17: 0 | F17: 0 | G17: =E17*F17 -> 0 | H17: 0 | I17: 0 | J17: =H17*I17 -> 0 | K17: =G17+J17 -> 0 | M17: =M16+K17-L17 -> 261154.85
A18: 15 | B18: 45915 | E18: 0 | F18: 0 | G18: =E18*F18 -> 0 | H18: 0 | I18: 0 | J18: =H18*I18 -> 0 | K18: =G18+J18 -> 0 | M18: =M17+K18-L18 -> 261154.85
A19: 16 | B19: 45916 | E19: 0 | F19: 0 | G19: =E19*F19 -> 0 | H19: 0 | I19: 0 | J19: =H19*I19 -> 0 | K19: =G19+J19 -> 0 | M19: =M18+K19-L19 -> 261154.85
A20: 17 | B20: 45917 | E20: 0 | F20: 0 | G20: =E20*F20 -> 0 | H20: 0 | I20: 0 | J20: =H20*I20 -> 0 | K20: =G20+J20 -> 0 | M20: =M19+K20-L20 -> 261154.85
A21: 18 | B21: 45918 | E21: 0 | F21: 0 | G21: =E21*F21 -> 0 | H21: 0 | I21: 0 | J21: =H21*I21 -> 0 | K21: =G21+J21 -> 0 | M21: =M20+K21-L21 -> 261154.85
A22: 19 | B22: 45919 | E22: 0 | F22: 0 | G22: =E22*F22 -> 0 | H22: 0 | I22: 0 | J22: =H22*I22 -> 0 | K22: =G22+J22 -> 0 | M22: =M21+K22-L22 -> 261154.85
A23: 20 | B23: 45920 | E23: 0 | F23: 0 | G23: =E23*F23 -> 0 | H23: 0 | I23: 0 | J23: =H23*I23 -> 0 | K23: =G23+J23 -> 0 | M23: =M22+K23-L23 -> 261154.85
... A29: 26 | B29: 45926 | E29: 0 | F29: 0 | G29: =E29*F29 -> 0 | H29: 0 | I29: 0 | J29: =H29*I29 -> 0 | K29: =G29+J29 -> 0 | M29: =M28+K29-L29 -> 461887.1
A30: 27 | B30: 45927 | E30: 0 | F30: 0 | G30: =E30*F30 -> 0 | H30: 0 | I30: 0 | J30: =H30*I30 -> 0 | K30: =G30+J30 -> 0 | L30: 300000 | M30: =M29+K30-L30 -> 161887.1
A31: 28 | B31: 45928 | E31: 0 | F31: 0 | G31: =E31*F31 -> 0 | H31: 0 | I31: 0 | J31: =H31*I31 -> 0 | K31: =G31+J31 -> 0 | M31: =M30+K31-L31 -> 161887.1
A32: 29 | B32: 45929 | E32: 1500 | F32: 91.33 | G32: =E32*F32 -> 136995 | H32: 70 | I32: 103.27 | J32: =H32*I32 -> 7228.9 | K32: =G32+J32 -> 144223.9 | M32: =M31+K32-L32 -> 306111
A33: 30 | B33: 45930 | E33: 0 | F33: 0 | G33: =E33*F33 -> 0 | H33: 0 | I33: 0 | J33: =H33*I33 -> 0 | K33: =G33+J33 -> 0 | M33: =M32+K33-L33 -> 306111
A34: 32 | E34: 0 | F34: 0 | G34: =E34*F34 -> 0 | H34: 0 | I34: 0 | J34: =H34*I34 -> 0 | K34: =G34+J34 -> 0
E35: =SUM(E4:E34) -> 8600 | G35: =SUM(G4:G34) -> 785438 | H35: =SUM(H4:H34) -> 490 | J35: =SUM(J4:J34) -> 50602.3 | K35: =SUM(K4:K34) -> 836040.3 | L35: =SUM(L4:L34) -> 760000

Sheet Hosadurga
A1: Merchant Petroliums
A2: S.No | B2: Date | C2: GRN No | D2: Ind No/Bill No | E2: Diesel (Lts) | F2: Price | G2: Amount | H2: Petrol (Lts) | I2: Price | J2: Amount | K2: Total amount | L2: Amount paid | M2: As on Date | N2: Remarks
A3: Opening Balance | K3: 7279.3 | M3: =+K3 -> 7279.3
A4: 1 | B4: 45901 | G4: =E4*F4 -> 0 | H4: 0 | J4: =H4*I4 -> 0 | K4: =G4+J4 -> 0 | L4: 0 | M4: =M3+K4-L4 -> 7279.3
A5: 2 | B5: 45902 | G5: =E5*F5 -> 0 | H5: 0 | I5: 0 | J5: =H5*I5 -> 0 | K5: =G5+J5 -> 0 | L5: 0 | M5: =M4+K5-L5 -> 7279.3
A6: 3 | B6: 45903 | G6: =E6*F6 -> 0 | H6: 0 | I6: 0 | J6: =H6*I6 -> 0 | K6: =G6+J6 -> 0 | L6: 0 | M6: =M5+K6-L6 -> 7279.3
