Workbook

Sheet Nov-25 
A1: S.no | B1: Site Name | C1: Bunk Name | D1: Diesel(Liters) | E1: Diesel Amount | F1: Petrol(Liters) | G1: Petrol Amount | H1: Total Amount | I1: Opening Blance | J1: Amount Paid | K1: Closing Balances
A2: 1 | B2: Khammam-1 | C2: Divya laxmi ganapathi | D2: =+'Khammam-1'!E38 -> 30400 | E2: =+'Khammam-1'!G38 -> 2908672 | F2: =+'Khammam-1'!H38 -> 175 | G2: =+'Khammam-1'!J38 -> 18805.5 | H2: =E2+G2 -> 2927477.5 | I2: =+'Khammam-1'!K3 -> 9147141.7 | J2: =+'Khammam-1'!L38 -> 7500000 | K2: =H2+I2-J2 -> 4574619.2
A3: 2 | B3: Khammam-2 | C3: Jayasai union bunk | D3: =+'Khammam-2'!E35 -> 31884.57 | E3: =+'Khammam-2'!G35 -> 3051353.3 | F3: =+'Khammam-2'!H35 -> 445 | G3: =+'Khammam-2'!J35 -> 47828.6 | H3: =E3+G3 -> 3099181.9 | I3: =+'Khammam-2'!K3 -> 24162763 | J3: =+'Khammam-2'!L35 -> 17700000 | K3: =H3+I3-J3 -> 9561944.8
A4: 3 | B4: Jadcherla-1 | C4: Sai Baba Fuel Station | D4: =+'Jadcherla -1'!E36 -> 1634.54 | E4: =+'Jadcherla -1'!G36 -> 157602.35 | F4: =+'Jadcherla -1'!H36 -> 300.33 | G4: =+'Jadcherla -1'!J36 -> 32504.716 | H4: =E4+G4 -> 190107.06 | I4: =+'Jadcherla -1'!M3 -> 1711783.1 | J4: =+'Jadcherla -1'!L36 -> 1100000 | K4: =H4+I4-J4 -> 801890.2
A5: 4 | B5: Jadcherla-2 | C5: ADHOC FILLING STATION STATION | D5: =+'Jadcharla-2'!E35 -> 14230 | E5: =+'Jadcharla-2'!G35 -> 1372198.9 | F5: =+'Jadcharla-2'!H35 -> 250 | G5: =+'Jadcharla-2'!J35 -> 27060 | H5: =E5+G5 -> 1399258.9 | I5: =+'Jadcharla-2'!K3 -> 2324364 | J5: =+'Jadcharla-2'!L35 -> 2600000 | K5: =H5+I5-J5 -> 1123622.9
A6: 5 | B6: Jadcherla-3 | C6: JSASFuel Genie India Pvt.Ltd | D6: =+'Jadcherla-3'!E35 -> 29750 | E6: =+'Jadcherla-3'!G35 -> 2839042.5 | F6: =+'Jadcherla-3'!H35 -> 0 | G6: =+'Jadcherla-3'!J35 -> 0 | H6: =E6+G6 -> 2839042.5 | I6: =+'Jadcherla-3'!M3 -> 0 | J6: =+'Jadcherla-3'!L35 -> 1000000 | K6: =H6+I6-J6 -> 1839042.5
A7: 6 | B7: Dindi | C7: Akarapu Balakistamma Fillling | D7: =+Dindi!E35 -> 0 | E7: =+Dindi!G35 -> 0 | F7: =+Dindi!H35 -> 0 | G7: =+Dindi!J35 -> 0 | H7: =E7+G7 -> 0 | I7: =+Dindi!M3 -> 0 | J7: =+Dindi!L35 -> 0 | K7: =H7+I7-J7 -> 0
A8: 7 | B8: Devarkhadra-1 | C8: Kurumurthy Swami F/S | D8: =+Devarakhadra!E35 -> 358.86 | E8: =+Devarakhadra!G35 -> 34845.306 | F8: =+Devarakhadra!H35 -> 55 | G8: =+Devarakhadra!J35 -> 5985.65 | H8: =E8+G8 -> 40830.956 | I8: =+Devarakhadra!M3 -> 193769.48 | J8: =+Devarakhadra!L35 -> 200000 | K8: =H8+I8-J8 -> 34600.433
A9: 8 | B9: Devarkhadra-3 | C9: JSASFuel Genie India Pvt.Ltd | D9: =+'Devarakhadra-2'!E35 -> 688.08 | E9: =+'Devarakhadra-2'!G35 -> 65938.706 | F9: =+'Devarakhadra-2'!H35 -> 0 | G9: =+'Devarakhadra-2'!I35 -> 0 | H9: =E9+G9 -> 65938.706 | I9: =+'Devarakhadra-2'!M3 -> 167115.06 | J9: =+'Devarakhadra-2'!L35 -> 167000 | K9: =+'Devarakhadra-2'!M34 -> 66053.768
A10: 9 | B10: Madanapalli | D10: =+'Madana palli'!E35 -> 723.33 | E10: =+'Madana palli'!G35 -> 70752.741 | F10: =+'Madana palli'!H35 -> 15.48 | G10: =+'Madana palli'!J35 -> 4381.2845 | H10: =E10+G10 -> 75134.025 | I10: =+'Madana palli'!M3 -> 0 | J10: =+'Madana palli'!L35 -> 75134.025 | K10: =+'Devarakhadra-2'!M35 -> 0
A11: 10 | B11: Amalapuram | C11: Sathya Filling Station | D11: =+Amalapuram!E37 -> 250.72 | E11: =+Amalapuram!G37 -> 24327.467 | F11: =+Amalapuram!H37 -> 93.18 | G11: =+Amalapuram!J37 -> 10152.28 | H11: =E11+G11 -> 34479.747 | I11: =+Amalapuram!M3 -> 0 | J11: =+Amalapuram!L37 -> 34479.74 | K11: =H11+I11-J11 -> 0.0072
A12: 11 | B12: YG Gudda-1 | C12: Pallavi Petrolium | D12: =+'YG Gudda '!E36 -> 164.29 | E12: =+'YG Gudda '!G36 -> 14999.677 | F12: =+'YG Gudda '!H36 -> 70 | G12: =+'YG Gudda '!J36 -> 7226.8 | H12: =E12+G12 -> 22226.477 | I12: ='YG Gudda '!K3 -> 102795.06 | J12: =+'YG Gudda '!L36 -> 100000 | K12: =H12+I12-J12 -> 25021.542
A13: 12 | B13: YG Gudda-2 | C13: Pankaja HP Fuel Center | D13: =+'YG Gudda-2'!E36 -> 7618.99 | E13: =+'YG Gudda-2'!G36 -> 695842.36 | F13: =+'YG Gudda-2'!H36 -> 385 | G13: =+'YG Gudda-2'!J36 -> 39758.95 | H13: =E13+G13 -> 735601.31 | I13: =+'YG Gudda-2'!M3 -> 324799.6 | J13: =+'YG Gudda-2'!L36 -> 720000 | K13: =H13+I13-J13 -> 340400.91
A14: 13 | B14: Hosadurga-1 | C14: Merchant Petroliums | D14: =+Hosadurga!E35 -> 0 | E14: =+Hosadurga!G35 -> 0 | F14: =+Hosadurga!H35 -> 0 | G14: =+Hosadurga!J35 -> 0 | H14: =E14+G14 -> 0 | I14: =+Hosadurga!K3 -> 2258.6 | J14: =+Hosadurga!L35 -> 0 | K14: =H14+I14-J14 -> 2258.6
A15: 14 | B15: Hosadurga-2 | C15: Shree Veeraprathap Fuel | D15: =+'Hosadurga -2'!E35 -> 4000 | E15: =+'Hosadurga -2'!G35 -> 366080 | F15: =+'Hosadurga -2'!H35 -> 275 | G15: =+'Hosadurga -2'!J35 -> 28509.25 | H15: =+'Hosadurga -2'!K35 -> 394589.25 | I15: =+'Hosadurga -2'!K3 -> 459638.79 | J15: =+'Hosadurga -2'!L35 -> 500000 | K15: =H15+I15-J15 -> 354228.04
A16: 15 | B16: Malebennuru(KUWSDB) | C16: Sri Ramanjuneya Service Station | D16: =+'Malebenur(KUWSDB)'!E36 -> 5000 | E16: =+'Malebenur(KUWSDB)'!G36 -> 460700 | F16: =+'Malebenur(KUWSDB)'!H36 -> 215 | G16: =+'Malebenur(KUWSDB)'!J36 -> 22353.55 | H16: =E16+G16 -> 483053.55 | I16: =+'Malebenur(KUWSDB)'!K3 -> 38935.405 | J16: =+'Malebenur(KUWSDB)'!L36 -> 370926 | K16: =H16+I16-J16 -> 151062.95
A17: 16 | B17: kadur | C17: Vishal Service Station | D17: =+Kadur!E35 -> 0 | E17: =+Kadur!G35 -> 0 | F17: =+Kadur!H35 -> 0 | G17: =+Kadur!J35 -> 0 | H17: =E17+G17 -> 0 | I17: =+Kadur!K3 -> 164331.63 | J17: =+Kadur!L35 -> 0 | K17: =H17+I17-J17 -> 164331.63
A18: 17 | B18: Hiriyur(VJNL) | C18: Sri Balaji Agencies | D18: =+'Hiriyur(VJNL)'!E35 -> 4800 | E18: =+'Hiriyur(VJNL)'!G35 -> 442704 | F18: =+'Hiriyur(VJNL)'!H35 -> 210 | G18: =+'Hiriyur(VJNL)'!J35 -> 21856.8 | H18: =E18+G18 -> 464560.8 | I18: =+'Hiriyur(VJNL)'!K3 -> 321350.8 | J18: =+'Hiriyur(VJNL)'!L35 -> 400000 | K18: =H18+I18-J18 -> 385911.6
A19: 18 | B19: Chellakere(KUWSDB) | C19: Shivaganga Service Station | D19: =+'Chellakere -1'!E35 -> 3510 | E19: =+'Chellakere -1'!G35 -> 323586.9 | F19: =+'Chellakere -1'!H35 -> 295 | G19: =+'Chellakere -1'!J35 -> 30688.85 | H19: =E19+G19 -> 354275.75 | I19: =+'Chellakere -1'!K3 -> 0 | J19: =+'Chellakere -1'!L35 -> 226271 | K19: =H19+I19-J19 -> 128004.75
A20: 19 | B20: Chellakere(KUWSDB)-09 | D20: =+' Chellakere-PKG-9'!E35 -> 704.99 | E20: =+' Chellakere-PKG-9'!G35 -> 64994.228 | F20: =+' Chellakere-PKG-9'!H35 -> 41 | G20: =+' Chellakere-PKG-9'!J35 -> 4265.23 | H20: =E20+G20 -> 69259.458 | I20: =+' Chellakere-PKG-9'!M3 -> 0 | J20: =+' Chellakere-PKG-9'!L35 -> 69259.458 | K20: =H20+I20-J20 -> 0
A21: 20 | B21: Molakalmuru | C21: Sri Lakshmi Venkateshwara Filling Station | D21: =+Molakamuru!E35 -> 580 | E21: =+Molakamuru!G35 -> 53470.6 | F21: =+Molakamuru!H35 -> 50 | G21: =+Molakamuru!J35 -> 5201 | H21: =E21+G21 -> 58671.6 | I21: =+Molakamuru!K3 -> 0 | J21: =+Molakamuru!L35 -> 58671.6 | K21: =H21+I21-J21 -> 0
A22: 21 | B22: Khanapur(PKG-3) | C22: V.V.Varde | D22: =+Khanapur!E35 -> 465.91 | E22: =+Khanapur!G35 -> 42341.901 | F22: =+Khanapur!H35 -> 66 | G22: =+Khanapur!J35 -> 6782.82 | H22: =E22+G22 -> 49124.721 | I22: =+Khanapur!M3 -> 50161.12 | J22: =+Khanapur!L35 -> 70267.58 | K22: =H22+I22-J22 -> 29018.261
A23: 22 | B23: Munavalli(PKG-3)-2 | C23: Shri Daneshwari | D23: =+'Munavali-2'!E37 -> 11813.5 | E23: =+'Munavali-2'!G37 -> 1078808.8 | F23: =+'Munavali-2'!H37 -> 157 | G23: =+'Munavali-2'!J37 -> 16208.68 | H23: =E23+G23 -> 1095017.5 | I23: =+'Munavali-2'!M3 -> 659195.2 | J23: =+'Munavali-2'!L37 -> 1200000 | K23: =H23+I23-J23 -> 554212.7
A24: 23 | B24: Borgaon(PKG-3) | C24: Aadisagar Petrolium | D24: =+Borgaon!E35 -> 660 | E24: =+Borgaon!G35 -> 60568.2 | F24: =+Borgaon!H35 -> 50 | G24: =+Borgaon!J35 -> 5185 | H24: =E24+G24 -> 65753.2 | I24: =+Borgaon!K3 -> 61661.701 | J24: =+Borgaon!L35 -> 60000 | K24: =H24+I24-J24 -> 67414.901
A25: 24 | B25: Ugar,Kudichi(PKG-3) | C25: Shiri Bhrhmanath Petrolium | D25: =+'Ugar,Khagwad,Kudichi'!E35 -> 3998.98 | E25: =+'Ugar,Khagwad,Kudichi'!G35 -> 367626.23 | F25: =+'Ugar,Khagwad,Kudichi'!H35 -> 255 | G25: =+'Ugar,Khagwad,Kudichi'!J35 -> 26817.75 | H25: =E25+G25 -> 394443.98 | I25: =+'Ugar,Khagwad,Kudichi'!M3 -> 235015.76 | J25: =+'Ugar,Khagwad,Kudichi'!L35 -> 235210 | K25: =H25+I25-J25 -> 394249.74
A26: 25 | B26: Kabbur(PKG-3) | C26: Shri Jai Hanuman Petrolium | D26: =+Kabbur!E35 -> 335 | E26: =+Kabbur!G35 -> 30682.65 | F26: =+Kabbur!H35 -> 41.86 | G26: =+Kabbur!J35 -> 4333.7658 | H26: =E26+G26 -> 35016.416 | I26: 0 | J26: =+Kabbur!L35 -> 35016.416 | K26: =H26+I26-J26 -> 0
A27: 26 | B27: Kumta (PKG-1) | C27: Krishma fuel station | D27: =+kumta!E35 -> 1516.29 | E27: =+kumta!G35 -> 139377.38 | F27: =+kumta!H35 -> 56.5 | G27: =+kumta!J35 -> 5873.74 | H27: =E27+G27 -> 145251.12 | I27: 0 | J27: =+kumta!L35 -> 145251.12 | K27: =H27+I27-J27 -> 0
A28: 27 | B28: Jalgaon | C28: Sri Sai Petrol Pump | D28: =+Jalgaon!E54 -> 15612.72 | E28: =+Jalgaon!G54 -> 1432343.5 | F28: =+Jalgaon!H54 -> 146.65 | G28: =+Jalgaon!J54 -> 15428.795 | H28: =E28+G28 -> 1447772.3 | I28: =+Jalgaon!K3 -> 705601.31 | J28: =+Jalgaon!L54 -> 1004912.8 | K28: =H28+I28-J28 -> 1148460.8
A29: 28 | B29: MKBD | C29: Shree Sai Samarth Petroleum | D29: =+MKBD!E36 -> 1700 | E29: =+MKBD!G36 -> 154938 | F29: =+MKBD!H36 -> 60 | G29: =+MKBD!J36 -> 6276 | H29: =E29+G29 -> 161214 | I29: =+MKBD!K3 -> 276716.65 | J29: =+MKBD!L36 -> 0 | K29: =H29+I29-J29 -> 437930.65
A30: 29 | B30: Haveri | C30: Shivalingeshwar Petroleum | D30: =+Haveri!E37 -> 4469.66 | E30: =+Haveri!G37 -> 408840.8 | F30: =+Haveri!H37 -> 138.73 | G30: =+Haveri!J37 -> 14344.682 | H30: =E30+G30 -> 423185.48 | I30: =+Haveri!M3 -> 127726.19 | J30: =+Haveri!L37 -> 325735.6 | K30: =H30+I30-J30 -> 225176.08
A31: 30 | B31: Guttal | C31: Taware filling station | D31: =+Guttal!E35 -> 1788.44 | E31: =+Guttal!G35 -> 164178.79 | F31: =+Guttal!H35 -> 119.19 | G31: =+Guttal!J35 -> 12367.154 | H31: =E31+G31 -> 176545.95 | I31: =+Guttal!M3 -> 36956.064 | J31: =+Guttal!L35 -> 155000 | K31: =H31+I31-J31 -> 58502.01
A32: 31 | B32: Rattihali | C32: Shree Siri Gowari petroliam | D32: =+Rattihali!E35 -> 1512.92 | E32: =+Rattihali!G35 -> 139249.16 | F32: =+Rattihali!H35 -> 61.99 | G32: =+Rattihali!J35 -> 6448.1998 | H32: =E32+G32 -> 145697.36 | I32: =+Rattihali!M3 -> 190300.91 | J32: =+Rattihali!L35 -> 200000 | K32: =H32+I32-J32 -> 135998.27
A33: 32 | B33: Gajendragada | C33: Vanasri Petrol Pump | D33: =+Gajendragada!E35 -> 0 | E33: =+Gajendragada!G35 -> 0 | F33: =+Gajendragada!H35 -> 10 | G33: =+Gajendragada!J35 -> 1038 | H33: =E33+G33 -> 1038 | I33: =+Gajendragada!K3 -> 98252.262 | J33: =+Gajendragada!L35 -> 98000 | K33: =H33+I33-J33 -> 1290.2615
A34: 33 | B34: Gokak(PKG-3) | C34: AJ Petrolinks | D34: =+'Gokak Dharwad PKG 3'!E40 -> 10624 | E34: =+'Gokak Dharwad PKG 3'!G40 -> 971883.52 | F34: =+'Gokak Dharwad PKG 3'!H40 -> 296 | G34: =+'Gokak Dharwad PKG 3'!J40 -> 30609.36 | H34: =E34+G34 -> 1002492.9 | I34: =+'Gokak Dharwad PKG 3'!K3 -> 1316713.4 | J34: =+'Gokak Dharwad PKG 3'!L40 -> 1700000 | K34: =H34+I34-J34 -> 619206.33
A35: 34 | B35: Ankaligi | C35: Shiv ganga | D35: =+Ankalgi!E35 -> 2846.96 | E35: =+Ankalgi!G35 -> 259955.92 | F35: =+Ankalgi!H35 -> 88 | G35: =+Ankalgi!J35 -> 8464.86 | H35: =E35+G35 -> 268420.78 | I35: =+Ankalgi!M3 -> 41443.572 | J35: =+Ankalgi!L35 -> 200000 | K35: =H35+I35-J35 -> 109864.35
A36: 35 | B36: ShankeshWAR | C36: SR Patil | D36: =+' Shankeshwar'!E35 -> 165 | E36: =+' Shankeshwar'!G35 -> 15064.5 | F36: =+' Shankeshwar'!H35 -> 53 | G36: =+' Shankeshwar'!J35 -> 5470.66 | H36: =E36+G36 -> 20535.16 | J36: =+' Shankeshwar'!L35 -> 20535.16 | K36: =H36+I36-J36 -> 0
A37: 36 | B37: Talikote(PKG-1) | C37: Raykar Oil Agencies | D37: =+' Talikote'!E46 -> 1054.08 | E37: =+' Talikote'!G46 -> 96440.199 | F37: =+' Talikote'!H46 -> 126.74 | G37: =+' Talikote'!J46 -> 13109.986 | H37: =E37+G37 -> 109550.18 | I37: =+' Talikote'!N3 -> 43124.265 | J37: =+' Talikote'!L46 -> 97000 | K37: =H37+I37-J37 -> 55674.449
A38: 37 | B38: Chadchan(PKG-1) | C38: Khavekar Petrolium | D38: =+Chadchan!E35 -> 1225.64 | E38: =+Chadchan!G35 -> 111815.14 | F38: =+Chadchan!H35 -> 153.78 | G38: =+Chadchan!J35 -> 15863.945 | H38: =E38+G38 -> 127679.08 | I38: =+Chadchan!K3 -> 143396.87 | J38: =+Chadchan!L35 -> 200000 | K38: =H38+I38-J38 -> 71075.955
A39: 38 | B39: Sindagi | C39: G.P.PORWAL | D39: =+Sindagi!E45 -> 515.01 | E39: =+Sindagi!G45 -> 46984.362 | F39: =+Sindagi!H45 -> 0 | G39: =+Sindagi!J45 -> 0 | H39: =E39+G39 -> 46984.362 | I39: =+Sindagi!M3 -> 0 | J39: =+Sindagi!L45 -> 18246 | K39: =H39+I39-J39 -> 28738.362
A40: 39 | B40: Muddebihal(PKG-1) | C40: Bhosle Service Station | D40: =+Muddebihal!E47 -> 48.56 | E40: =+Muddebihal!G47 -> 4440.812 | F40: =+Muddebihal!H47 -> 5 | G40: =+Muddebihal!J47 -> 516.95 | H40: =E40+G40 -> 4957.762 | I40: =+Muddebihal!M3 -> 3593.8248 | J40: =+Muddebihal!L47 -> 0 | K40: =H40+I40-J40 -> 8551.5868
...

Sheet Khammam-1
A1: Divya laxmi ganapathi
A2: S.No | B2: Date | C2: GRN No | D2: Ind No/Bill No | E2: Diesel (Lts) | F2: Price | G2: Amount | H2: Petrol (Lts) | I2: Price | J2: Amount | K2: Total amount | L2: Amount paid | M2: As 0n Date | N2: Remarks
A3: Opening Balance | K3: 9147141.7 | M3: =+K3 -> 9147141.7 | O3: 11178224
A4: 1 | B4: 45962 | E4: 3800 | F4: 95.68 | G4: =E4*F4 -> 363584 | J4: =H4*I4 -> 0 | K4: =G4+J4 -> 363584 | L4: 0 | M4: =M3+K4-L4 -> 9510725.7
A5: 2 | B5: 45963 | E5: 2600 | F5: 95.68 | G5: =E5*F5 -> 248768 | H5: 35 | I5: 107.46 | J5: =H5*I5 -> 3761.1 | K5: =G5+J5 -> 252529.1 | M5: =M4+K5-L5 -> 9763254.8
A6: 3 | B6: 45964 | E6: 2400 | F6: 95.68 | G6: =E6*F6 -> 229632 | H6: 20 | I6: 107.46 | J6: =H6*I6 -> 2149.2 | K6: =G6+J6 -> 231781.2 | M6: =M5+K6-L6 -> 9995036
A7: 4 | B7: 45965 | G7: =E7*F7 -> 0 | J7: =H7*I7 -> 0 | K7: =G7+J7 -> 0 | M7: =M6+K7-L7 -> 9995036
A8: 5 | B8: 45966 | G8: =E8*F8 -> 0 | J8: =H8*I8 -> 0 | K8: =G8+J8 -> 0 | M8: =M7+K8-L8 -> 9995036
A9: 6 | B9: 45967 | G9: =E9*F9 -> 0 | J9: =H9*I9 -> 0 | K9: =G9+J9 -> 0 | M9: =M8+K9-L9 -> 9995036
A10: 7 | B10: 45968 | G10: =E10*F10 -> 0 | J10: =H10*I10 -> 0 | K10: =G10+J10 -> 0 | M10: =M9+K10-L10 -> 9995036
A11: 8 | B11: 45969 | G11: =E11*F11 -> 0 | J11: =H11*I11 -> 0 | K11: =G11+J11 -> 0 | M11: =M10+K11-L11 -> 9995036
A12: 9 | B12: 45970 | G12: =E12*F12 -> 0 | J12: =H12*I12 -> 0 | K12: =G12+J12 -> 0 | M12: =M11+K12-L12 -> 9995036
A13: 10 | B13: 45971 | G13: =E13*F13 -> 0 | J13: =H13*I13 -> 0 | K13: =G13+J13 -> 0 | M13: =M12+K13-L13 -> 9995036
A14: 11 | B14: 45972 | G14: =E14*F14 -> 0 | J14: =H14*I14 -> 0 | K14: =G14+J14 -> 0 | M14: =M13+K14-L14 -> 9995036
A15: 12 | B15: 45973 | G15: =E15*F15 -> 0 | J15: =H15*I15 -> 0 | K15: =G15+J15 -> 0 | M15: =M14+K15-L15 -> 9995036
A16: 13 | B16: 45974 | G16: =E16*F16 -> 0 | J16: =H16*I16 -> 0 | K16: =G16+J16 -> 0 | M16: =M15+K16-L16 -> 9995036
A17: 14 | B17: 45975 | G17: =E17*F17 -> 0 | J17: =H17*I17 -> 0 | K17: =G17+J17 -> 0 | M17: =M16+K17-L17 -> 9995036
A18: 15 | B18: 45976 | G18: =E18*F18 -> 0 | J18: =H18*I18 -> 0 | K18: =G18+J18 -> 0 | M18: =M17+K18-L18 -> 9995036
... A22: 19 | B22: 45980 | G22: =E22*F22 -> 0 | J22: =H22*I22 -> 0 | K22: =G22+J22 -> 0 | M22: =M21+K22-L22 -> 9995036
A23: 20 | B23: 45981 | E23: 2500 | F23: 95.68 | G23: =E23*F23 -> 239200 | H23: 40 | I23: 107.46 | J23: =H23*I23 -> 4298.4 | K23: =G23+J23 -> 243498.4 | L23: 7500000 | M23: =M22+K23-L23 -> 2738534.4
A24: 21 | B24: 45982 | G24: =E24*F24 -> 0 | J24: =H24*I24 -> 0 | K24: =G24+J24 -> 0 | M24: =M23+K24-L24 -> 2738534.4
A25: 22 | B25: 45983 | G25: =E25*F25 -> 0 | J25: =H25*I25 -> 0 | K25: =G25+J25 -> 0 | M25: =M24+K25-L25 -> 2738534.4
A26: 23 | B26: 45984 | G26: =E26*F26 -> 0 | J26: =H26*I26 -> 0 | K26: =G26+J26 -> 0 | M26: =M25+K26-L26 -> 2738534.4
A27: 24 | B27: 45985 | E27: 5500 | F27: 95.68 | G27: =E27*F27 -> 526240 | H27: 40 | I27: 107.46 | J27: =H27*I27 -> 4298.4 | K27: =G27+J27 -> 530538.4 | M27: =M26+K27-L27 -> 3269072.8
A28: 25 | B28: 45986 | G28: =E28*F28 -> 0 | J28: =H28*I28 -> 0 | K28: =G28+J28 -> 0 | M28: =M27+K28-L28 -> 3269072.8
A29: 26 | B29: 45987 | G29: =E29*F29 -> 0 | J29: =H29*I29 -> 0 | K29: =G29+J29 -> 0 | M29: =M28+K29-L29 -> 3269072.8
A30: 27 | B30: 45988 | E30: 5500 | F30: 95.68 | G30: =E30*F30 -> 526240 | H30: 20 | I30: 107.46 | J30: =H30*I30 -> 2149.2 | K30: =G30+J30 -> 528389.2 | M30: =M29+K30-L30 -> 3797462
A31: 28 | B31: 45989 | E31: 2700 | F31: 95.68 | G31: =E31*F31 -> 258336 | J31: =H31*I31 -> 0 | K31: =G31+J31 -> 258336 | M31: =M30+K31-L31 -> 4055798
A32: 29 | B32: 45990 | E32: 2800 | F32: 95.68 | G32: =E32*F32 -> 267904 | J32: =H32*I32 -> 0 | K32: =G32+J32 -> 267904 | M32: =M31+K32-L32 -> 4323702 | O32: 11177692 | P32: =M32-O32 -> -6853989.5
A33: 30 | B33: 45991 | E33: 2600 | F33: 95.68 | G33: =E33*F33 -> 248768 | H33: 20 | I33: 107.46 | J33: =H33*I33 -> 2149.2 | K33: =G33+J33 -> 250917.2 | M33: =M32+K33-L33 -> 4574619.2
A34: 31 | G34: =E34*F34 -> 0 | J34: =H34*I34 -> 0 | K34: =G34+J34 -> 0 | M34: =M33+K34-L34 -> 4574619.2
A35: 32 | G35: =E35*F35 -> 0 | J35: =H35*I35 -> 0 | K35: =G35+J35 -> 0 | M35: =M34+K35-L35 -> 4574619.2
A36: 33 | E36: 0 | G36: =E36*F36 -> 0 | J36: =H36*I36 -> 0 | K36: =G36+J36 -> 0
A37: 34 | E37: 0 | F37: 0 | G37: =E37*F37 -> 0 | H37: 0 | I37: 0 | J37: =H37*I37 -> 0 | K37: =G37+J37 -> 0
E38: =SUM(E3:E37) -> 30400 | G38: =SUM(G3:G37) -> 2908672 | H38: =SUM(H3:H37) -> 175 | J38: =SUM(J3:J37) -> 18805.5 | K38: =SUM(K4:K37) -> 2927477.5 | L38: =SUM(L3:L37) -> 7500000

Sheet Khammam-2
A1: Jayasai union bunk
A2: S.No | B2: Date | C2: GRN No | D2: Ind No/Bill No | E2: Diesel (Lts) | F2: Price | G2: Amount | H2: Petrol (Lts) | I2: Price | J2: Amount | K2: Total amount | L2: Amount paid | M2: As 0n Date | N2: Remarks
A3: Opening Balance | K3: 24162763 | M3: 24162763
A4: 1 | B4: 45962 | G4: =E4*F4 -> 0 | J4: =H4*I4 -> 0 | K4: =G4+J4 -> 0 | M4: =M3+K4-L4 -> 24162763 | O4: =O3+M4-N4 -> 24162763
A5: 2 | B5: 45963 | G5: =E5*F5 -> 0 | J5: =H5*I5 -> 0 | K5: =G5+J5 -> 0 | M5: =M4+K5-L5 -> 24162763
A6: 3 | B6: 45964 | G6: =E6*F6 -> 0 | J6: =H6*I6 -> 0 | K6: =G6+J6 -> 0 | M6: =M5+K6-L6 -> 24162763
A7: 4 | B7: 45965 | G7: =E7*F7 -> 0 | J7: =H7*I7 -> 0 | K7: =G7+J7 -> 0 | M7: =M6+K7-L7 -> 24162763
A8: 5 | B8: 45966 | E8: 2700 | F8: 95.7 | G8: =E8*F8 -> 258390 | H8: 55 | I8: 107.48 | J8: =H8*I8 -> 5911.4 | K8: =G8+J8 -> 264301.4 | M8: =M7+K8-L8 -> 24427064
A9: 6 | B9: 45967 | E9: 752.35 | F9: 95.7 | G9: =E9*F9 -> 71999.895 | J9: =H9*I9 -> 0 | K9: =G9+J9 -> 71999.895 | M9: =M8+K9-L9 -> 24499064 | N9: 72000
A10: 7 | B10: 45968 | E10: 2504.7 | F10: 95.7 | G10: =E10*F10 -> 239699.79 | H10: 40 | I10: 107.48 | J10: =H10*I10 -> 4299.2 | K10: =G10+J10 -> 243998.99 | M10: =M9+K10-L10 -> 24743063 | N10: 244000
A11: 8 | B11: 45969 | E11: 1179.21 | F11: 95.7 | G11: =E11*F11 -> 112850.4 | H11: 20 | I11: 107.48 | J11: =H11*I11 -> 2149.6 | K11: =G11+J11 -> 115000 | M11: =M10+K11-L11 -> 24858063 | N11: 115000
A12: 9 | B12: 45970 | G12: =E12*F12 -> 0 | J12: =H12*I12 -> 0 | K12: =G12+J12 -> 0 | M12: =M11+K12-L12 -> 24858063
A13: 10 | B13: 45971 | E13: 626.96 | F13: 95.7 | G13: =E13*F13 -> 60000.072 | J13: =H13*I13 -> 0 | K13: =G13+J13 -> 60000.072 | M13: =M12+K13-L13 -> 24918063 | N13: 60000
A14: 11 | B14: 45972 | E14: 634.29 | F14: 95.7 | G14: =E14*F14 -> 60701.553 | H14: 40 | I14: 107.48 | J14: =H14*I14 -> 4299.2 | K14: =G14+J14 -> 65000.753 | M14: =M13+K14-L14 -> 24983064 | N14: 65000
A15: 12 | B15: 45973 | E15: 1253.92 | F15: 95.7 | G15: =E15*F15 -> 120000.14 | J15: =H15*I15 -> 0 | K15: =G15+J15 -> 120000.14 | M15: =M14+K15-L15 -> 25103064 | N15: 120000
A16: 13 | B16: 45974 | E16: 1626.97 | F16: 95.7 | G16: =E16*F16 -> 155701.03 | H16: 40 | I16: 107.48 | J16: =H16*I16 -> 4299.2 | K16: =G16+J16 -> 160000.23 | M16: =M15+K16-L16 -> 25263064 | N16: 160000.23
A17: 14 | B17: 45975 | G17: =E17*F17 -> 0 | J17: =H17*I17 -> 0 | K17: =G17+J17 -> 0 | M17: =M16+K17-L17 -> 25263064
A18: 15 | B18: 45976 | E18: 1156.75 | F18: 95.7 | G18: =E18*F18 -> 110700.98 | H18: 40 | I18: 107.48 | J18: =H18*I18 -> 4299.2 | K18: =G18+J18 -> 115000.18 | M18: =M17+K18-L18 -> 25378064 | N18: 115000.18
A19: 16 | B19: 45977 | G19: =E19*F19 -> 0 | J19: =H19*I19 -> 0 | K19: =G19+J19 -> 0 | M19: =M18+K19-L19 -> 25378064
A20: 17 | B20: 45978 | E20: 1462.91 | F20: 95.7 | G20: =E20*F20 -> 140000.49 | J20: =H20*I20 -> 0 | K20: =G20+J20 -> 140000.49 | M20: =M19+K20-L20 -> 25518065 | N20: 140000.09
A21: 18 | B21: 45979 | E21: 3886.51 | F21: 95.7 | G21: =E21*F21 -> 371939.01 | H21: 75 | I21: 107.48 | J21: =H21*I21 -> 8061 | K21: =G21+J21 -> 380000.01 | L21: 200000 | M21: =M20+K21-L21 -> 25698065 | N21: 380000
A22: 19 | B22: 45980 | G22: =E22*F22 -> 0 | J22: =H22*I22 -> 0 | K22: =G22+J22 -> 0 | M22: =M21+K22-L22 -> 25698065
A23: 20 | B23: 45981 | E23: 500 | F23: 95.7 | G23: =E23*F23 -> 47850 | H23: 20 | I23: 107.48 | J23: =H23*I23 -> 2149.6 | K23: =G23+J23 -> 49999.6 | L23: 17500000 | M23: =M22+K23-L23 -> 8248064.6 | N23: 17500000
A24: 21 | B24: 45982 | G24: =E24*F24 -> 0 | J24: =H24*I24 -> 0 | K24: =G24+J24 -> 0 | M24: =M23+K24-L24 -> 8248064.6
A25: 22 | B25: 45983 | G25: =E25*F25 -> 0 | J25: =H25*I25 -> 0 | K25: =G25+J25 -> 0 | M25: =M24+K25-L25 -> 8248064.6
A26: 23 | B26: 45984 | G26: =E26*F26 -> 0 | J26: =H26*I26 -> 0 | K26: =G26+J26 -> 0 | M26: =M25+K26-L26 -> 8248064.6
A27: 24 | B27: 45985 | E27: 2700 | F27: 95.7 | G27: =E27*F27 -> 258390 | H27: 35 | I27: 107.48 | J27: =H27*I27 -> 3761.8 | K27: =G27+J27 -> 262151.8 | M27: =M26+K27-L27 -> 8510216.4
A28: 25 | B28: 45986 | E28: 2800 | F28: 95.7 | G28: =E28*F28 -> 267960 | J28: =H28*I28 -> 0 | K28: =G28+J28 -> 267960 | M28: =M27+K28-L28 -> 8778176.4
A29: 26 | B29: 45987 | E29: 2700 | F29: 95.7 | G29: =E29*F29 -> 258390 | H29: 60 | I29: 107.48 | J29: =H29*I29 -> 6448.8 | K29: =G29+J29 -> 264838.8 | M29: =M28+K29-L29 -> 9043015.2
A30: 27 | B30: 45988 | G30: =E30*F30 -> 0 | J30: =H30*I30 -> 0 | K30: =G30+J30 -> 0 | M30: =M29+K30-L30 -> 9043015.2
A31: 28 | B31: 45989 | G31: =E31*F31 -> 0 | J31: =H31*I31 -> 0 | K31: =G31+J31 -> 0 | M31: =M30+K31-L31 -> 9043015.2
A32: 29 | B32: 45990 | E32: 2700 | F32: 95.7 | G32: =E32*F32 -> 258390 | H32: 20 | I32: 107.48 | J32: =H32*I32 -> 2149.6 | K32: =G32+J32 -> 260539.6 | M32: =M31+K32-L32 -> 9303554.8
A33: 30 | B33: 45991 | E33: 2700 | F33: 95.7 | G33: =E33*F33 -> 258390 | J33: =H33*I33 -> 0 | K33: =G33+J33 -> 258390 | M33: =M32+K33-L33 -> 9561944.8
A34: 31 | B34: 45992 | G34: =E34*F34 -> 0 | J34: =H34*I34 -> 0 | K34: =G34+J34 -> 0 | M34: =M33+K34-L34 -> 9561944.8
E35: =SUM(E4:E34) -> 31884.57 | G35: =SUM(G4:G34) -> 3051353.3 | H35: =SUM(H4:H34) -> 445 | J35: =SUM(J4:J34) -> 47828.6 | K35: =SUM(K4:K34) -> 3099181.9 | L35: =SUM(L4:L34) -> 17700000

Sheet Jadcherla -1
A1: Sai Baba Fuel Station
A2: S.No | B2: Date | C2: GRN No | D2: Ind No/Bill No | E2: Diesel (Lts) | F2: Price | G2: Amount | H2: Petrol (Lts) | I2: Price | J2: Amount | K2: Total amount | L2: Amount paid | M2: As on date | N2: Remarks
A3: Opening Balance | M3: 1711783.1 | O3: 2623243.4
A4: 1 | B4: 45962 | E4: 0 | F4: 96.42 | G4: =E4*F4 -> 0 | H4: 60 | I4: 108.23 | J4: =H4*I4 -> 6493.8 | K4: =G4+J4 -> 6493.8 | M4: =M3+K4-L4 -> 1718276.9
A5: 2 | B5: 45963 | G5: =E5*F5 -> 0 | J5: =H5*I5 -> 0 | K5: =G5+J5 -> 0 | M5: =M4+K5-L5 -> 1718276.9
A6: 3 | B6: 45964 | G6: =E6*F6 -> 0 | J6: =H6*I6 -> 0 | K6: =G6+J6 -> 0 | M6: =M5+K6-L6 -> 1718276.9
A7: 4 | B7: 45965 | G7: =E7*F7 -> 0 | J7: =H7*I7 -> 0 | K7: =G7+J7 -> 0 | M7: =M6+K7-L7 -> 1718276.9 | P7: 5679
A8: 5 | B8: 45966 | E8: 0 | F8: 96.42 | G8: =E8*F8 -> 0 | H8: 50 | I8: 108.23 | J8: =H8*I8 -> 5411.5 | K8: =G8+J8 -> 5411.5 | M8: =M7+K8-L8 -> 1723688.4
A9: 6 | B9: 45967 | E9: 1550.4 | F9: 96.42 | G9: =E9*F9 -> 149489.57 | H9: 90.33 | I9: 108.23 | J9: =H9*I9 -> 9776.4159 | K9: =G9+J9 -> 159265.98 | M9: =M8+K9-L9 -> 1882954.4
A10: 7 | B10: 45968 | G10: =E10*F10 -> 0 | J10: =H10*I10 -> 0 | K10: =G10+J10 -> 0 | M10: =M9+K10-L10 -> 1882954.4
A11: 8 | B11: 45969 | E11: 49.14 | F11: 96.42 | G11: =E11*F11 -> 4738.0788 | H11: 50 | I11: 108.23 | J11: =H11*I11 -> 5411.5 | K11: =G11+J11 -> 10149.579 | M11: =M10+K11-L11 -> 1893104
A12: 9 | B12: 45970 | G12: =E12*F12 -> 0 | J12: =H12*I12 -> 0 | K12: =G12+J12 -> 0 | M12: =M11+K12-L12 -> 1893104
A13: 10 | B13: 45971 | G13: =E13*F13 -> 0 | J13: =H13*I13 -> 0 | K13: =G13+J13 -> 0 | M13: =M12+K13-L13 -> 1893104
A14: 11 | B14: 45972 | G14: =E14*F14 -> 0 | H14: 50 | I14: 108.23 | J14: =H14*I14 -> 5411.5 | K14: =G14+J14 -> 5411.5 | M14: =M13+K14-L14 -> 1898515.5 | P14: 1905988 | Q14: =P14-M14 -> 7472.5044
A15: 12 | B15: 45973 | G15: =E15*F15 -> 0 | J15: =H15*I15 -> 0 | K15: =G15+J15 -> 0 | M15: =M14+K15-L15 -> 1898515.5
A16: 13 | B16: 45974 | E16: 35 | F16: 96.42 | G16: =E16*F16 -> 3374.7 | J16: =H16*I16 -> 0 | K16: =G16+J16 -> 3374.7 | M16: =M15+K16-L16 -> 1901890.2
A17: 14 | B17: 45975 | G17: =E17*F17 -> 0 | J17: =H17*I17 -> 0 | K17: =G17+J17 -> 0 | M17: =M16+K17-L17 -> 1901890.2
A18: 15 | B18: 45976 | G18: =E18*F18 -> 0 | J18: =H18*I18 -> 0 | K18: =G18+J18 -> 0 | L18: 500000 | M18: =M17+K18-L18 -> 1401890.2
A19: 16 | B19: 45977 | G19: =E19*F19 -> 0 | J19: =H19*I19 -> 0 | K19: =G19+J19 -> 0 | M19: =M18+K19-L19 -> 1401890.2
A20: 17 | B20: 45978 | G20: =E20*F20 -> 0 | J20: =H20*I20 -> 0 | K20: =G20+J20 -> 0 | M20: =M19+K20-L20 -> 1401890.2
A21: 18 | B21: 45979 | G21: =E21*F21 -> 0 | J21: =H21*I21 -> 0 | K21: =G21+J21 -> 0 | M21: =M20+K21-L21 -> 1401890.2
A22: 19 | B22: 45980 | G22: =E22*F22 -> 0 | J22: =H22*I22 -> 0 | K22: =G22+J22 -> 0 | M22: =M21+K22-L22 -> 1401890.2
A23: 20 | B23: 45981 | G23: =E23*F23 -> 0 | J23: =H23*I23 -> 0 | K23: =G23+J23 -> 0 | M23: =M22+K23-L23 -> 1401890.2
A24: 21 | B24: 45982 | G24: =E24*F24 -> 0 | J24: =H24*I24 -> 0 | K24: =G24+J24 -> 0 | M24: =M23+K24-L24 -> 1401890.2
A25: 22 | B25: 45983 | G25: =E25*F25 -> 0 | J25: =H25*I25 -> 0 | K25: =G25+J25 -> 0 | L25: 600000 | M25: =M24+K25-L25 -> 801890.2
A26: 23 | B26: 45984 | G26: =E26*F26 -> 0 | J26: =H26*I26 -> 0 | K26: =G26+J26 -> 0 | M26: =M25+K26-L26 -> 801890.2
A27: 24 | B27: 45985 | G27: =E27*F27 -> 0 | J27: =H27*I27 -> 0 | K27: =G27+J27 -> 0 | M27: =M26+K27-L27 -> 801890.2
A28: 25 | B28: 45986 | G28: =E28*F28 -> 0 | J28: =H28*I28 -> 0 | K28: =G28+J28 -> 0 | M28: =M27+K28-L28 -> 801890.2
A29: 26 | B29: 45987 | G29: =E29*F29 -> 0 | J29: =H29*I29 -> 0 | K29: =G29+J29 -> 0 | M29: =M28+K29-L29 -> 801890.2
A30: 27 | B30: 45988 | G30: =E30*F30 -> 0 | J30: =H30*I30 -> 0 | K30: =G30+J30 -> 0 | M30: =M29+K30-L30 -> 801890.2
A31: 28 | B31: 45989 | G31: =E31*F31 -> 0 | J31: =H31*I31 -> 0 | K31: =G31+J31 -> 0 | M31: =M30+K31-L31 -> 801890.2
A32: 29 | B32: 45990 | G32: =E32*F32 -> 0 | J32: =H32*I32 -> 0 | K32: =G32+J32 -> 0 | M32: =M31+K32-L32 -> 801890.2
A33: 30 | B33: 45991 | G33: =E33*F33 -> 0 | J33: =H33*I33 -> 0 | K33: =G33+J33 -> 0 | M33: =M32+K33-L33 -> 801890.2
A34: 31 | G34: =E34*F34 -> 0 | J34: =H34*I34 -> 0 | K34: =G34+J34 -> 0 | L34: 0 | M34: =M33+K34-L34 -> 801890.2 | O34: 2669494 | P34: =O34-M34 -> 1867603.8
E35: 0 | F35: 0 | G35: =E35*F35 -> 0 | J35: =H35*I35 -> 0 | K35: =G35+J35 -> 0 | M35: =M34+K35-L35 -> 801890.2
E36: =SUM(E4:E34) -> 1634.54 | G36: =SUM(G4:G34) -> 157602.35 | H36: =SUM(H4:H34) -> 300.33 | J36: =SUM(J4:J34) -> 32504.716 | K36: =SUM(K4:K34) -> 190107.06 | L36: =SUM(L4:L34) -> 1100000
M45: 2408309
M46: 5327.86
M47: =M45-M46 -> 2402981.1

Sheet Jadcharla-2
A1: Jadcherla FILLING STATION STATION
A2: S.No | B2: Date | C2: GRN No | D2: Ind No/Bill No | E2: Diesel (Lts) | F2: Price | G2: Amount | H2: Petrol (Lts) | I2: Price | J2: Amount | K2: Total amount | L2: Amount paid | M2: As on Date | N2: Remarks
A3: Opening Balance | K3: 2324364 | M3: =+K3 -> 2324364
A4: 1 | B4: 45962 | E4: 2000 | F4: 96.43 | G4: =E4*F4 -> 192860 | J4: =H4*I4 -> 0 | K4: =G4+J4 -> 192860 | M4: =M3+K4-L4 -> 2517224
A5: 2 | B5: 45963 | E5: 2300 | F5: 96.43 | G5: =E5*F5 -> 221789 | J5: =H5*I5 -> 0 | K5: =G5+J5 -> 221789 | M5: =M4+K5-L5 -> 2739013
A6: 3 | B6: 45964 | E6: 2000 | F6: 96.43 | G6: =E6*F6 -> 192860 | J6: =H6*I6 -> 0 | K6: =G6+J6 -> 192860 | M6: =M5+K6-L6 -> 2931873 | R6: 541.08
A7: 4 | B7: 45965 | E7: 0 | F7: 96.43 | G7: =E7*F7 -> 0 | J7: =H7*I7 -> 0 | K7: =G7+J7 -> 0 | M7: =M6+K7-L7 -> 2931873
A8: 5 | B8: 45966 | E8: 1300 | F8: 96.43 | G8: =E8*F8 -> 125359 | J8: =H8*I8 -> 0 | K8: =G8+J8 -> 125359 | M8: =M7+K8-L8 -> 3057232
A9: 6 | B9: 45967 | G9: =E9*F9 -> 0 | J9: =H9*I9 -> 0 | K9: =G9+J9 -> 0 | M9: =M8+K9-L9 -> 3057232
A10: 7 | B10: 45968 | E10: 1200 | F10: 96.43 | G10: =E10*F10 -> 115716 | J10: =H10*I10 -> 0 | K10: =G10+J10 -> 115716 | M10: =M9+K10-L10 -> 3172948
A11: 8 | B11: 45969 | E11: 2400 | F11: 96.43 | G11: =E11*F11 -> 231432 | J11: =H11*I11 -> 0 | K11: =G11+J11 -> 231432 | M11: =M10+K11-L11 -> 3404380
A12: 9 | B12: 45970 | E12: 1500 | F12: 96.43 | G12: =E12*F12 -> 144645 | J12: =H12*I12 -> 0 | K12: =G12+J12 -> 144645 | M12: =M11+K12-L12 -> 3549025
A13: 10 | B13: 45971 | E13: 1500 | F13: 96.43 | G13: =E13*F13 -> 144645 | J13: =H13*I13 -> 0 | K13: =G13+J13 -> 144645 | M13: =M12+K13-L13 -> 3693670
A14: 11 | B14: 45972 | G14: =E14*F14 -> 0 | J14: =H14*I14 -> 0 | K14: =G14+J14 -> 0 | M14: =M13+K14-L14 -> 3693670
A15: 12 | B15: 45973 | G15: =E15*F15 -> 0 | H15: 0 | I15: 0 | J15: =H15*I15 -> 0 | K15: =G15+J15 -> 0 | M15: =M14+K15-L15 -> 3693670
A16: 13 | B16: 45974 | G16: =E16*F16 -> 0 | H16: 50 | I16: 108.24 | J16: =H16*I16 -> 5412 | K16: =G16+J16 -> 5412 | M16: =M15+K16-L16 -> 3699082
A17: 14 | B17: 45975 | G17: =E17*F17 -> 0 | J17: =H17*I17 -> 0 | K17: =G17+J17 -> 0 | M17: =M16+K17-L17 -> 3699082
A18: 15 | B18: 45976 | G18: =E18*F18 -> 0 | J18: =H18*I18 -> 0 | K18: =G18+J18 -> 0 | L18: 1600000 | M18: =M17+K18-L18 -> 2099082
A19: 16 | B19: 45977 | G19: =E19*F19 -> 0 | H19: 50 | I19: 108.24 | J19: =H19*I19 -> 5412 | K19: =G19+J19 -> 5412 | M19: =M18+K19-L19 -> 2104494
A20: 17 | B20: 45978 | G20: =E20*F20 -> 0 | J20: =H20*I20 -> 0 | K20: =G20+J20 -> 0 | M20: =M19+K20-L20 -> 2104494
A21: 18 | B21: 45979 | G21: =E21*F21 -> 0 | J21: =H21*I21 -> 0 | K21: =G21+J21 -> 0 | M21: =M20+K21-L21 -> 2104494
A22: 19 | B22: 45980 | G22: =E22*F22 -> 0 | J22: =H22*I22 -> 0 | K22: =G22+J22 -> 0 | M22: =M21+K22-L22 -> 2104494
A23: 20 | B23: 45981 | G23: =E23*F23 -> 0 | J23: =H23*I23 -> 0 | K23: =G23+J23 -> 0 | L23: 1000000 | M23: =M22+K23-L23 -> 1104494
A24: 21 | B24: 45982 | G24: =E24*F24 -> 0 | J24: =H24*I24 -> 0 | K24: =G24+J24 -> 0 | M24: =M23+K24-L24 -> 1104494
A25: 22 | B25: 45983 | G25: =E25*F25 -> 0 | H25: 50 | I25: 108.24 | J25: =H25*I25 -> 5412 | K25: =G25+J25 -> 5412 | M25: =M24+K25-L25 -> 1109906
A26: 23 | B26: 45984 | G26: =E26*F26 -> 0 | J26: =H26*I26 -> 0 | K26: =G26+J26 -> 0 | M26: =M25+K26-L26 -> 1109906
A27: 24 | B27: 45985 | G27: =E27*F27 -> 0 | H27: 50 | I27: 108.24 | J27: =H27*I27 -> 5412 | K27: =G27+J27 -> 5412 | M27: =M26+K27-L27 -> 1115318
A28: 25 | B28: 45986 | E28: 30 | F28: 96.43 | G28: =E28*F28 -> 2892.9 | J28: =H28*I28 -> 0 | K28: =G28+J28 -> 2892.9 | M28: =M27+K28-L28 -> 1118210.9
A29: 26 | B29: 45987 | G29: =E29*F29 -> 0 | J29: =H29*I29 -> 0 | K29: =G29+J29 -> 0 | M29: =M28+K29-L29 -> 1118210.9
A30: 27 | B30: 45988 | G30: =E30*F30 -> 0 | H30: 50 | I30: 108.24 | J30: =H30*I30 -> 5412 | K30: =G30+J30 -> 5412 | M30: =M29+K30-L30 -> 1123622.9
A31: 28 | B31: 45989 | G31: =E31*F31 -> 0 | J31: =H31*I31 -> 0 | K31: =G31+J31 -> 0 | M31: =M30+K31-L31 -> 1123622.9
A32: 29 | B32: 45990 | G32: =E32*F32 -> 0 | J32: =H32*I32 -> 0 | K32: =G32+J32 -> 0 | M32: =M31+K32-L32 -> 1123622.9
A33: 30 | B33: 45991 | G33: =E33*F33 -> 0 | J33: =H33*I33 -> 0 | K33: =G33+J33 -> 0 | M33: =M32+K33-L33 -> 1123622.9
A34: 31 | E34: 0 | F34: 0 | G34: =E34*F34 -> 0 | J34: =H34*I34 -> 0 | K34: =G34+J34 -> 0 | M34: =M33+K34-L34 -> 1123622.9 | O34: 1688453.6 | P34: 1900671 | Q34: =P34-O34 -> 212217.42
E35: =SUM(E4:E34) -> 14230 | G35: =SUM(G4:G34) -> 1372198.9 | H35: =SUM(H4:H34) -> 250 | J35: =SUM(J4:J34) -> 27060 | K35: =SUM(K4:K34) -> 1399258.9 | L35: =SUM(L4:L34) -> 2600000

Sheet Jadcherla-3
A1: JSASFuel Genie India Pvt.Ltd
A2: S.No | B2: Date | C2: GRN No | D2: Ind no/Bill No | E2: Diesel (Lts) | F2: Price | G2: Amount | H2: Petrol (Lts) | I2: Price | J2: Amount | K2: Total amount | L2: Amount paid | M2: As on Date | N2: Remarks
A3: Opening Balance | M3: 0
A4: 1 | B4: 45962 | G4: =E4*F4 -> 0 | H4: 0 | I4: 0 | J4: =H4*I4 -> 0 | K4: =G4+J4 -> 0 | L4: 0 | M4: =+M3+K4-L4 -> 0
A5: 2 | B5: 45963 | G5: =E5*F5 -> 0 | H5: 0 | I5: 0 | J5: =H5*I5 -> 0 | K5: =G5+J5 -> 0 | L5: 0 | M5: =+M4+K5-L5 -> 0
A6: 3 | B6: 45964 | G6: =E6*F6 -> 0 | H6: 0 | I6: 0 | J6: =H6*I6 -> 0 | K6: =G6+J6 -> 0 | L6: 0 | M6: =+M5+K6-L6 -> 0
A7: 4 | B7: 45965 | E7: 2500 | F7: 95.43 | G7: =E7*F7 -> 238575 | H7: 0 | I7: 0 | J7: =H7*I7 -> 0 | K7: =G7+J7 -> 238575 | L7: 0 | M7: =+M6+K7-L7 -> 238575
A8: 5 | B8: 45966 | E8: 2000 | F8: 95.43 | G8: =E8*F8 -> 190860 | H8: 0 | I8: 0 | J8: =H8*I8 -> 0 | K8: =G8+J8 -> 190860 | L8: 0 | M8: =+M7+K8-L8 -> 429435
A9: 6 | B9: 45967 | G9: =E9*F9 -> 0 | H9: 0 | I9: 0 | J9: =H9*I9 -> 0 | K9: =G9+J9 -> 0 | L9: 0 | M9: =+M8+K9-L9 -> 429435
A10: 7 | B10: 45968 | G10: =E10*F10 -> 0 | H10: 0 | I10: 0 | J10: =H10*I10 -> 0 | K10: =G10+J10 -> 0 | L10: 0 | M10: =+M9+K10-L10 -> 429435
A11: 8 | B11: 45969 | G11: =E11*F11 -> 0 | H11: 0 | I11: 0 | J11: =H11*I11 -> 0 | K11: =G11+J11 -> 0 | L11: 0 | M11: =+M10+K11-L11 -> 429435
A12: 9 | B12: 45970 | G12: =E12*F12 -> 0 | H12: 0 | I12: 0 | J12: =H12*I12 -> 0 | K12: =G12+J12 -> 0 | L12: 0 | M12: =+M11+K12-L12 -> 429435
A13: 10 | B13: 45971 | E13: 2000 | F13: 95.43 | G13: =E13*F13 -> 190860 | H13: 0 | I13: 0 | J13: =H13*I13 -> 0 | K13: =G13+J13 -> 190860 | L13: 0 | M13: =+M12+K13-L13 -> 620295
A14: 11 | B14: 45972 | G14: =E14*F14 -> 0 | H14: 0 | I14: 0 | J14: =H14*I14 -> 0 | K14: =G14+J14 -> 0 | L14: 0 | M14: =+M13+K14-L14 -> 620295
A15: 12 | B15: 45973 | E15: 1500 | F15: 95.43 | G15: =E15*F15 -> 143145 | H15: 0 | I15: 0 | J15: =H15*I15 -> 0 | K15: =G15+J15 -> 143145 | L15: 0 | M15: =+M14+K15-L15 -> 763440
A16: 13 | B16: 45974 | E16: 2000 | F16: 95.43 | G16: =E16*F16 -> 190860 | H16: 0 | I16: 0 | J16: =H16*I16 -> 0 | K16: =G16+J16 -> 190860 | L16: 0 | M16: =+M15+K16-L16 -> 954300
A17: 14 | B17: 45975 | E17: 2000 | F17: 95.43 | G17: =E17*F17 -> 190860 | H17: 0 | I17: 0 | J17: =H17*I17 -> 0 | K17: =G17+J17 -> 190860 | L17: 0 | M17: =+M16+K17-L17 -> 1145160
A18: 15 | B18: 45976 | E18: 4000 | F18: 95.43 | G18: =E18*F18 -> 381720 | H18: 0 | I18: 0 | J18: =H18*I18 -> 0 | K18: =G18+J18 -> 381720 | L18: 0 | M18: =+M17+K18-L18 -> 1526880
A19: 16 | B19: 45977 | E19: 4250 | F19: 95.43 | G19: =E19*F19 -> 405577.5 | H19: 0 | I19: 0 | J19: =H19*I19 -> 0 | K19: =G19+J19 -> 405577.5 | L19: 0 | M19: =+M18+K19-L19 -> 1932457.5
A20: 17 | B20: 45978 | G20: =E20*F20 -> 0 | H20: 0 | I20: 0 | J20: =H20*I20 -> 0 | K20: =G20+J20 -> 0 | L20: 0 | M20: =+M19+K20-L20 -> 1932457.5
A21: 18 | B21: 45979 | E21: 2500 | F21: 95.43 | G21: =E21*F21 -> 238575 | H21: 0 | I21: 0 | J21: =H21*I21 -> 0 | K21: =G21+J21 -> 238575 | L21: 0 | M21: =+M20+K21-L21 -> 2171032.5
A22: 19 | B22: 45980 | G22: =E22*F22 -> 0 | H22: 0 | I22: 0 | J22: =H22*I22 -> 0 | K22: =G22+J22 -> 0 | L22: 0 | M22: =+M21+K22-L22 -> 2171032.5
A23: 20 | B23: 45981 | G23: =E23*F23 -> 0 | H23: 0 | I23: 0 | J23: =H23*I23 -> 0 | K23: =G23+J23 -> 0 | L23: 0 | M23: =+M22+K23-L23 -> 2171032.5
A24: 21 | B24: 45982 | G24: =E24*F24 -> 0 | H24: 0 | I24: 0 | J24: =H24*I24 -> 0 | K24: =G24+J24 -> 0 | L24: 1000000 | M24: =+M23+K24-L24 -> 1171032.5
A25: 22 | B25: 45983 | G25: =E25*F25 -> 0 | H25: 0 | I25: 0 | J25: =H25*I25 -> 0 | K25: =G25+J25 -> 0 | L25: 0 | M25: =+M24+K25-L25 -> 1171032.5
A26: 23 | B26: 45984 | G26: =E26*F26 -> 0 | H26: 0 | I26: 0 | J26: =H26*I26 -> 0 | K26: =G26+J26 -> 0 | L26: 0 | M26: =+M25+K26-L26 -> 1171032.5
A27: 24 | B27: 45985 | E27: 2000 | F27: 95.43 | G27: =E27*F27 -> 190860 | H27: 0 | I27: 0 | J27: =H27*I27 -> 0 | K27: =G27+J27 -> 190860 | L27: 0 | M27: =+M26+K27-L27 -> 1361892.5
A28: 25 | B28: 45986 | G28: =E28*F28 -> 0 | H28: 0 | I28: 0 | J28: =H28*I28 -> 0 | K28: =G28+J28 -> 0 | L28: 0 | M28: =+M27+K28-L28 -> 1361892.5
A29: 26 | B29: 45987 | E29: 3000 | F29: 95.43 | G29: =E29*F29 -> 286290 | H29: 0 | I29: 0 | J29: =H29*I29 -> 0 | K29: =G29+J29 -> 286290 | L29: 0 | M29: =+M28+K29-L29 -> 1648182.5
A30: 27 | B30: 45988 | G30: =E30*F30 -> 0 | H30: 0 | I30: 0 | J30: =H30*I30 -> 0 | K30: =G30+J30 -> 0 | L30: 0 | M30: =+M29+K30-L30 -> 1648182.5
A31: 28 | B31: 45989 | E31: 2000 | F31: 95.43 | G31: =E31*F31 -> 190860 | H31: 0 | I31: 0 | J31: =H31*I31 -> 0 | K31: =G31+J31 -> 190860 | L31: 0 | M31: =+M30+K31-L31 -> 1839042.5
A32: 29 | B32: 45990 | G32: =E32*F32 -> 0 | H32: 0 | I32: 0 | J32: =H32*I32 -> 0 | K32: =G32+J32 -> 0 | L32: 0 | M32: =+M31+K32-L32 -> 1839042.5
A33: 30 | B33: 45991 | G33: =E33*F33 -> 0 | H33: 0 | I33: 0 | J33: =H33*I33 -> 0 | K33: =G33+J33 -> 0 | L33: 0 | M33: =+M32+K33-L33 -> 1839042.5
A34: 31 | G34: =E34*F34 -> 0 | H34: 0 | I34: 0 | J34: =H34*I34 -> 0 | K34: =G34+J34 -> 0 | L34: 0 | M34: =+M33+K34-L34 -> 1839042.5
E35: =SUM(E4:E34) -> 29750 | G35: =SUM(G4:G34) -> 2839042.5 | H35: =SUM(H4:H34) -> 0 | J35: =SUM(J4:J34) -> 0 | K35: =SUM(K4:K34) -> 2839042.5 | L35: =SUM(L4:L34) -> 1000000
F38: /

Sheet Devarakhadra
A1: Kurumurthy Swami F/S
A2: S.No | B2: Date | C2: GRN No | D2: Ind no/Bill No | E2: Diesel (Lts) | F2: Price | G2: Amount | H2: Petrol (Lts) | I2: Price | J2: Amount | K2: Total amount | L2: Amount paid | M2: As on Date | N2: Remarks
A3: Opening Balance | M3: 193769.48 | O3: 121213.37
A4: 1 | B4: 45962 | D4: 1 | E4: 20 | F4: 97.1 | G4: =E4*F4 -> 1942 | J4: =H4*I4 -> 0 | K4: =G4+J4 -> 1942 | M4: =+M3+K4-L4 -> 195711.48
A5: 2 | B5: 45963 | D5: 2 | E5: 43.9 | F5: 97.1 | G5: =E5*F5 -> 4262.69 | J5: =H5*I5 -> 0 | K5: =G5+J5 -> 4262.69 | M5: =+M4+K5-L5 -> 199974.17
A6: 3 | B6: 45964 | D6: 3 | G6: =E6*F6 -> 0 | H6: 10 | I6: 108.83 | J6: =H6*I6 -> 1088.3 | K6: =G6+J6 -> 1088.3 | M6: =+M5+K6-L6 -> 201062.47
A7: 4 | B7: 45965 | D7: 4 | E7: 10 | F7: 97.1 | G7: =E7*F7 -> 971 | J7: =H7*I7 -> 0 | K7: =G7+J7 -> 971 | M7: =+M6+K7-L7 -> 202033.47
A8: 5 | B8: 45966 | D8: 5 | E8: 58 | F8: 97.1 | G8: =E8*F8 -> 5631.8 | J8: =H8*I8 -> 0 | K8: =G8+J8 -> 5631.8 | M8: =+M7+K8-L8 -> 207665.27
A9: 6 | B9: 45967 | D9: 6 | G9: =E9*F9 -> 0 | H9: 10 | I9: 108.83 | J9: =H9*I9 -> 1088.3 | K9: =G9+J9 -> 1088.3 | M9: =+M8+K9-L9 -> 208753.57
A10: 7 | B10: 45968 | D10: 7 | G10: =E10*F10 -> 0 | J10: =H10*I10 -> 0 | K10: =G10+J10 -> 0 | M10: =+M9+K10-L10 -> 208753.57
A11: 8 | B11: 45969 | D11: 8 | G11: =E11*F11 -> 0 | J11: =H11*I11 -> 0 | K11: =G11+J11 -> 0 | M11: =+M10+K11-L11 -> 208753.57
A12: 9 | B12: 45970 | D12: 9 | G12: =E12*F12 -> 0 | J12: =H12*I12 -> 0 | K12: =G12+J12 -> 0 | M12: =+M11+K12-L12 -> 208753.57
A13: 10 | B13: 45971 | D13: 10 | G13: =E13*F13 -> 0 | J13: =H13*I13 -> 0 | K13: =G13+J13 -> 0 | M13: =+M12+K13-L13 -> 208753.57
A14: 11 | B14: 45972 | D14: 11 | G14: =E14*F14 -> 0 | J14: =H14*I14 -> 0 | K14: =G14+J14 -> 0 | M14: =+M13+K14-L14 -> 208753.57
A15: 12 | B15: 45973 | D15: 12 | G15: =E15*F15 -> 0 | H15: 5 | I15: 108.83 | J15: =H15*I15 -> 544.15 | K15: =G15+J15 -> 544.15 | M15: =+M14+K15-L15 -> 209297.72
A16: 13 | B16: 45974 | D16: 13 | G16: =E16*F16 -> 0 | H16: 5 | I16: 108.83 | J16: =H16*I16 -> 544.15 | K16: =G16+J16 -> 544.15 | M16: =+M15+K16-L16 -> 209841.87
A17: 14 | B17: 45975 | D17: 14 | G17: =E17*F17 -> 0 | J17: =H17*I17 -> 0 | K17: =G17+J17 -> 0 | M17: =+M16+K17-L17 -> 209841.87
A18: 15 | B18: 45976 | D18: 15 | G18: =E18*F18 -> 0 | J18: =H18*I18 -> 0 | K18: =G18+J18 -> 0 | M18: =+M17+K18-L18 -> 209841.87
A19: 16 | B19: 45977 | D19: 16 | E19: 37.79 | F19: 97.1 | G19: =E19*F19 -> 3669.409 | J19: =H19*I19 -> 0 | K19: =G19+J19 -> 3669.409 | M19: =+M18+K19-L19 -> 213511.28 | N19: Fuel bills
A20: 17 | B20: 45978 | D20: 17 | G20: =E20*F20 -> 0 | H20: 5 | I20: 108.83 | J20: =H20*I20 -> 544.15 | K20: =G20+J20 -> 544.15 | M20: =+M19+K20-L20 -> 214055.43
A21: 18 | B21: 45979 | D21: 18 | G21: =E21*F21 -> 0 | H21: 5 | I21: 108.83 | J21: =H21*I21 -> 544.15 | K21: =G21+J21 -> 544.15 | M21: =+M20+K21-L21 -> 214599.58
A22: 19 | B22: 45980 | D22: 19 | E22: 43.17 | F22: 97.1 | G22: =E22*F22 -> 4191.807 | J22: =H22*I22 -> 0 | K22: =G22+J22 -> 4191.807 | M22: =+M21+K22-L22 -> 218791.38
A23: 20 | B23: 45981 | D23: 20 | G23: =E23*F23 -> 0 | J23: =H23*I23 -> 0 | K23: =G23+J23 -> 0 | L23: 200000 | M23: =+M22+K23-L23 -> 18791.383
A24: 21 | B24: 45982 | D24: 21 | E24: 65 | F24: 97.1 | G24: =E24*F24 -> 6311.5 | J24: =H24*I24 -> 0 | K24: =G24+J24 -> 6311.5 | M24: =+M23+K24-L24 -> 25102.883
A25: 22 | B25: 45983 | D25: 22 | G25: =E25*F25 -> 0 | J25: =H25*I25 -> 0 | K25: =G25+J25 -> 0 | M25: =+M24+K25-L25 -> 25102.883
A26: 23 | B26: 45984 | D26: 23 | G26: =E26*F26 -> 0 | J26: =H26*I26 -> 0 | K26: =G26+J26 -> 0 | M26: =+M25+K26-L26 -> 25102.883
A27: 24 | B27: 45985 | D27: 24 | G27: =E27*F27 -> 0 | J27: =H27*I27 -> 0 | K27: =G27+J27 -> 0 | M27: =+M26+K27-L27 -> 25102.883
A28: 25 | B28: 45986 | D28: 25 | G28: =E28*F28 -> 0 | J28: =H28*I28 -> 0 | K28: =G28+J28 -> 0 | M28: =+M27+K28-L28 -> 25102.883
A29: 26 | B29: 45987 | D29: 26 | E29: 35 | F29: 97.1 | G29: =E29*F29 -> 3398.5 | H29: 15 | I29: 108.83 | J29: =H29*I29 -> 1632.45 | K29: =G29+J29 -> 5030.95 | M29: =+M28+K29-L29 -> 30133.833
A30: 27 | B30: 45988 | D30: 27 | G30: =E30*F30 -> 0 | J30: =H30*I30 -> 0 | K30: =G30+J30 -> 0 | M30: =+M29+K30-L30 -> 30133.833
A31: 28 | B31: 45989 | D31: 28 | E31: 46 | F31: 97.1 | G31: =E31*F31 -> 4466.6 | J31: =H31*I31 -> 0 | K31: =G31+J31 -> 4466.6 | M31: =+M30+K31-L31 -> 34600.433
A32: 29 | B32: 45990 | D32: 29 | G32: =E32*F32 -> 0 | J32: =H32*I32 -> 0 | K32: =G32+J32 -> 0 | M32: =+M31+K32-L32 -> 34600.433
A33: 30 | B33: 45991 | D33: 30 | G33: =E33*F33 -> 0 | J33: =H33*I33 -> 0 | K33: =G33+J33 -> 0 | M33: =+M32+K33-L33 -> 34600.433
A34: 31 | B34: 45992 | D34: 31 | G34: =E34*F34 -> 0 | J34: =H34*I34 -> 0 | K34: =G34+J34 -> 0 | M34: =+M33+K34-L34 -> 34600.433
E35: =SUM(E4:E34) -> 358.86 | G35: =SUM(G4:G34) -> 34845.306 | H35: =SUM(H4:H34) -> 55 | J35: =SUM(J4:J34) -> 5985.65 | K35: =SUM(K4:K34) -> 40830.956 | L35: =SUM(L4:L34) -> 200000

Sheet Devarakhadra-2
A1: JSASFuel Genie India Pvt.Ltd
A2: S.No | B2: Date | C2: GRN No | D2: Ind no/Bill No | E2: Diesel (Lts) | F2: Price | G2: Amount | H2: Petrol (Lts) | I2: Price | J2: Amount | K2: Total amount | L2: Amount paid | M2: As on Date | N2: Remarks
A3: Opening Balance | M3: 167115.06
A4: 1 | B4: 45962 | G4: =E4*F4 -> 0 | H4: 0 | I4: 0 | J4: =H4*I4 -> 0 | K4: =G4+J4 -> 0 | L4: 0 | M4: =+M3+K4-L4 -> 167115.06
A5: 2 | B5: 45963 | G5: =E5*F5 -> 0 | H5: 0 | I5: 0 | J5: =H5*I5 -> 0 | K5: =G5+J5 -> 0 | L5: 0 | M5: =+M4+K5-L5 -> 167115.06
A6: 3 | B6: 45964 | G6: =E6*F6 -> 0 | H6: 0 | I6: 0 | J6: =H6*I6 -> 0 | K6: =G6+J6 -> 0 | L6: 0 | M6: =+M5+K6-L6 -> 167115.06
A7: 4 | B7: 45965 | G7: =E7*F7 -> 0 | H7: 0 | I7: 0 | J7: =H7*I7 -> 0 | K7: =G7+J7 -> 0 | L7: 0 | M7: =+M6+K7-L7 -> 167115.06
A8: 5 | B8: 45966 | E8: 688.08 | F8: 95.83 | G8: =E8*F8 -> 65938.706 | H8: 0 | I8: 0 | J8: =H8*I8 -> 0 | K8: =G8+J8 -> 65938.706 | L8: 0 | M8: =+M7+K8-L8 -> 233053.77
A9: 6 | B9: 45967 | G9: =E9*F9 -> 0 | H9: 0 | I9: 0 | J9: =H9*I9 -> 0 | K9: =G9+J9 -> 0 | L9: 0 | M9: =+M8+K9-L9 -> 233053.77
A10: 7 | B10: 45968 | G10: =E10*F10 -> 0 | H10: 0 | I10: 0 | J10: =H10*I10 -> 0 | K10: =G10+J10 -> 0 | L10: 0 | M10: =+M9+K10-L10 -> 233053.77
A11: 8 | B11: 45969 | G11: =E11*F11 -> 0 | H11: 0 | I11: 0 | J11: =H11*I11 -> 0 | K11: =G11+J11 -> 0 | L11: 0 | M11: =+M10+K11-L11 -> 233053.77
A12: 9 | B12: 45970 | G12: =E12*F12 -> 0 | H12: 0 | I12: 0 | J12: =H12*I12 -> 0 | K12: =G12+J12 -> 0 | L12: 0 | M12: =+M11+K12-L12 -> 233053.77
A13: 10 | B13: 45971 | G13: =E13*F13 -> 0 | H13: 0 | I13: 0 | J13: =H13*I13 -> 0 | K13: =G13+J13 -> 0 | L13: 0 | M13: =+M12+K13-L13 -> 233053.77
A14: 11 | B14: 45972 | G14: =E14*F14 -> 0 | H14: 0 | I14: 0 | J14: =H14*I14 -> 0 | K14: =G14+J14 -> 0 | L14: 0 | M14: =+M13+K14-L14 -> 233053.77
A15: 12 | B15: 45973 | G15: =E15*F15 -> 0 | H15: 0 | I15: 0 | J15: =H15*I15 -> 0 | K15: =G15+J15 -> 0 | L15: 0 | M15: =+M14+K15-L15 -> 233053.77
A16: 13 | B16: 45974 | G16: =E16*F16 -> 0 | H16: 0 | I16: 0 | J16: =H16*I16 -> 0 | K16: =G16+J16 -> 0 | L16: 0 | M16: =+M15+K16-L16 -> 233053.77
A17: 14 | B17: 45975 | H17: 0 | I17: 0 | J17: =H17*I17 -> 0 | K17: =G17+J17 -> 0 | L17: 0 | M17: =+M16+K17-L17 -> 233053.77
A18: 15 | B18: 45976 | H18: 0 | I18: 0 | J18: =H18*I18 -> 0 | K18: =G18+J18 -> 0 | L18: 167000 | M18: =+M17+K18-L18 -> 66053.768
A19: 16 | B19: 45977 | H19: 0 | I19: 0 | J19: =H19*I19 -> 0 | K19: =G19+J19 -> 0 | L19: 0 | M19: =+M18+K19-L19 -> 66053.768
A20: 17 | B20: 45978 | G20: =E20*F20 -> 0 | H20: 0 | I20: 0 | J20: =H20*I20 -> 0 | K20: =G20+J20 -> 0 | L20: 0 | M20: =+M19+K20-L20 -> 66053.768
A21: 18 | B21: 45979 | G21: =E21*F21 -> 0 | H21: 0 | I21: 0 | J21: =H21*I21 -> 0 | K21: =G21+J21 -> 0 | L21: 0 | M21: =+M20+K21-L21 -> 66053.768
A22: 19 | B22: 45980 | G22: =E22*F22 -> 0 | H22: 0 | I22: 0 | J22: =H22*I22 -> 0 | K22: =G22+J22 -> 0 | L22: 0 | M22: =+M21+K22-L22 -> 66053.768
A23: 20 | B23: 45981 | G23: =E23*F23 -> 0 | H23: 0 | I23: 0 | J23: =H23*I23 -> 0 | K23: =G23+J23 -> 0 | L23: 0 | M23: =+M22+K23-L23 -> 66053.768
A24: 21 | B24: 45982 | G24: =E24*F24 -> 0 | H24: 0 | I24: 0 | J24: =H24*I24 -> 0 | K24: =G24+J24 -> 0 | L24: 0 | M24: =+M23+K24-L24 -> 66053.768
A25: 22 | B25: 45983 | G25: =E25*F25 -> 0 | H25: 0 | I25: 0 | J25: =H25*I25 -> 0 | K25: =G25+J25 -> 0 | L25: 0 | M25: =+M24+K25-L25 -> 66053.768
A26: 23 | B26: 45984 | G26: =E26*F26 -> 0 | H26: 0 | I26: 0 | J26: =H26*I26 -> 0 | K26: =G26+J26 -> 0 | L26: 0 | M26: =+M25+K26-L26 -> 66053.768
A27: 24 | B27: 45985 | G27: =E27*F27 -> 0 | H27: 0 | I27: 0 | J27: =H27*I27 -> 0 | K27: =G27+J27 -> 0 | L27: 0 | M27: =+M26+K27-L27 -> 66053.768
A28: 25 | B28: 45986 | G28: =E28*F28 -> 0 | H28: 0 | I28: 0 | J28: =H28*I28 -> 0 | K28: =G28+J28 -> 0 | L28: 0 | M28: =+M27+K28-L28 -> 66053.768
A29: 26 | B29: 45987 | G29: =E29*F29 -> 0 | H29: 0 | I29: 0 | J29: =H29*I29 -> 0 | K29: =G29+J29 -> 0 | L29: 0 | M29: =+M28+K29-L29 -> 66053.768
A30: 27 | B30: 45988 | G30: =E30*F30 -> 0 | H30: 0 | I30: 0 | J30: =H30*I30 -> 0 | K30: =G30+J30 -> 0 | L30: 0 | M30: =+M29+K30-L30 -> 66053.768
A31: 28 | B31: 45989 | G31: =E31*F31 -> 0 | H31: 0 | I31: 0 | J31: =H31*I31 -> 0 | K31: =G31+J31 -> 0 | L31: 0 | M31: =+M30+K31-L31 -> 66053.768
... A33: 30 | B33: 45991 | G33: =E33*F33 -> 0 | H33: 0 | I33: 0 | J33: =H33*I33 -> 0 | K33: =G33+J33 -> 0 | L33: 0 | M33: =+M32+K33-L33 -> 66053.768
A34: 31 | G34: =E34*F34 -> 0 | H34: 0 | I34: 0 | J34: =H34*I34 -> 0 | K34: =G34+J34 -> 0 | L34: 0 | M34: =+M33+K34-L34 -> 66053.768
E35: =SUM(E4:E34) -> 688.08 | G35: =SUM(G4:G34) -> 65938.706 | H35: =SUM(H4:H34) -> 0 | J35: =SUM(J4:J34) -> 0 | K35: =SUM(K4:K34) -> 65938.706 | L35: =SUM(L4:L34) -> 167000
F38: /

Sheet Dindi
A1: Akarapu Balakistamma Fillling
A2: S.No | B2: Date | C2: GRN No | D2: Ind no/Bill No | E2: Diesel (Lts) | F2: Price | G2: Amount | H2: Petrol (Lts) | I2: Price | J2: Amount | K2: Total amount | L2: Amount paid | M2: As on Date | N2: Remarks
A3: Opening Balance | M3: 0
A4: 1 | B4: 45962 | G4: =E4*F4 -> 0 | H4: 0 | I4: 0 | J4: =H4*I4 -> 0 | K4: =G4+J4 -> 0 | L4: =+K4 -> 0 | M4: 0
A5: 2 | B5: 45963 | G5: =E5*F5 -> 0 | H5: 0 | I5: 0 | J5: =H5*I5 -> 0 | K5: =G5+J5 -> 0 | L5: =+K5 -> 0 | M5: 0
A6: 3 | B6: 45964 | G6: =E6*F6 -> 0 | H6: 0 | I6: 0 | J6: =H6*I6 -> 0 | K6: =G6+J6 -> 0 | L6: =+K6 -> 0 | M6: 0
A7: 4 | B7: 45965 | G7: =E7*F7 -> 0 | H7: 0 | I7: 0 | J7: =H7*I7 -> 0 | K7: =G7+J7 -> 0 | L7: =+K7 -> 0 | M7: 0
A8: 5 | B8: 45966 | G8: =E8*F8 -> 0 | H8: 0 | I8: 0 | J8: =H8*I8 -> 0 | K8: =G8+J8 -> 0 | L8: =+K8 -> 0 | M8: 0
A9: 6 | B9: 45967 | H9: 0 | I9: 0 | J9: =H9*I9 -> 0 | K9: =G9+J9 -> 0 | L9: =+K9 -> 0 | M9: 0
A10: 7 | B10: 45968 | H10: 0 | I10: 0 | J10: =H10*I10 -> 0 | K10: =G10+J10 -> 0 | L10: =+K10 -> 0 | M10: 0
A11: 8 | B11: 45969 | H11: 0 | I11: 0 | J11: =H11*I11 -> 0 | K11: =G11+J11 -> 0 | L11: =+K11 -> 0 | M11: 0
A12: 9 | B12: 45970 | H12: 0 | I12: 0 | J12: =H12*I12 -> 0 | K12: =G12+J12 -> 0 | L12: =+K12 -> 0 | M12: 0
A13: 10 | B13: 45971 | H13: 0 | I13: 0 | J13: =H13*I13 -> 0 | K13: =G13+J13 -> 0 | L13: =+K13 -> 0 | M13: 0
A14: 11 | B14: 45972 | H14: 0 | I14: 0 | J14: =H14*I14 -> 0 | K14: =G14+J14 -> 0 | L14: =+K14 -> 0 | M14: 0
A15: 12 | B15: 45973 | H15: 0 | I15: 0 | J15: =H15*I15 -> 0 | K15: =G15+J15 -> 0 | L15: =+K15 -> 0 | M15: 0
A16: 13 | B16: 45974 | H16: 0 | I16: 0 | J16: =H16*I16 -> 0 | K16: =G16+J16 -> 0 | L16: =+K16 -> 0 | M16: 0
A17: 14 | B17: 45975 | H17: 0 | I17: 0 | J17: =H17*I17 -> 0 | K17: =G17+J17 -> 0 | L17: =+K17 -> 0 | M17: 0
A18: 15 | B18: 45976 | H18: 0 | I18: 0 | J18: =H18*I18 -> 0 | K18: =G18+J18 -> 0 | L18: =+K18 -> 0 | M18: 0
A19: 16 | B19: 45977 | H19: 0 | I19: 0 | J19: =H19*I19 -> 0 | K19: =G19+J19 -> 0 | L19: =+K19 -> 0 | M19: 0
A20: 17 | B20: 45978 | H20: 0 | I20: 0 | J20: =H20*I20 -> 0 | K20: =G20+J20 -> 0 | L20: =+K20 -> 0 | M20: 0
... A28: 25 | B28: 45986 | H28: 0 | I28: 0 | J28: =H28*I28 -> 0 | K28: =G28+J28 -> 0 | L28: =+K28 -> 0 | M28: 0
A29: 26 | B29: 45987 | G29: =E29*F29 -> 0 | H29: 0 | I29: 0 | J29: =H29*I29 -> 0 | K29: =G29+J29 -> 0 | L29: =+K29 -> 0 | M29: 0
A30: 27 | B30: 45988 | G30: =E30*F30 -> 0 | H30: 0 | I30: 0 | J30: =H30*I30 -> 0 | K30: =G30+J30 -> 0 | L30: =+K30 -> 0 | M30: 0
A31: 28 | B31: 45989 | G31: =E31*F31 -> 0 | H31: 0 | I31: 0 | J31: =H31*I31 -> 0 | K31: =G31+J31 -> 0 | L31: =+K31 -> 0 | M31: 0
A32: 29 | B32: 45990 | G32: =E32*F32 -> 0 | H32: 0 | I32: 0 | J32: =H32*I32 -> 0 | K32: =G32+J32 -> 0 | L32: =+K32 -> 0 | M32: 0
A33: 30 | B33: 45991 | G33: =E33*F33 -> 0 | H33: 0 | I33: 0 | J33: =H33*I33 -> 0 | K33: =G33+J33 -> 0 | L33: =+K33 -> 0 | M33: 0
A34: 31 | G34: =E34*F34 -> 0 | H34: 0 | I34: 0 | J34: =H34*I34 -> 0 | K34: =G34+J34 -> 0 | L34: =+K34 -> 0 | M34: 0
E35: =SUM(E4:E34) -> 0 | G35: =SUM(G4:G34) -> 0 | H35: =SUM(H4:H34) -> 0 | J35: =SUM(J4:J34) -> 0 | K35: =SUM(K4:K34) -> 0 | L35: =SUM(L4:L34) -> 0

Sheet Amalapuram
A2: S.No | B2: Date | C2: GRN No | D2: Ind no/Bill No | E2: Diesel (Lts) | F2: Price | G2: Amount | H2: Petrol (Lts) | I2: Price | J2: Amount | K2: Total amount | L2: Amount paid | M2: As on Date | N2: Remarks
A3: Opening Balance | M3: 0
A4: 1 | G4: =E4*F4 -> 0 | J4: =H4*I4 -> 0 | K4: =G4+J4 -> 0 | M4: =+M3+K4-L4 -> 0
A5: 2 | G5: =E5*F5 -> 0 | J5: =H5*I5 -> 0 | K5: =G5+J5 -> 0 | M5: =+M4+K5-L5 -> 0
A6: 3 | G6: =E6*F6 -> 0 | J6: =H6*I6 -> 0 | K6: =G6+J6 -> 0 | M6: =+M5+K6-L6 -> 0
A7: 4 | G7: =E7*F7 -> 0 | J7: =H7*I7 -> 0 | K7: =G7+J7 -> 0 | M7: =+M6+K7-L7 -> 0
A8: 5 | B8: 05.11.2025 | C8: Sri Venkata Sitaram F/S | E8: 35.85 | F8: 97.64 | G8: =E8*F8 -> 3500.394 | J8: =H8*I8 -> 0 | K8: =G8+J8 -> 3500.394 | L8: 3500.39 | M8: =+M7+K8-L8 -> 0.004
A9: 6 | B9: 06.11.2025 | C9: Shiva Sri Sai Filling Station | D9: East Vippar | G9: =E9*F9 -> 0 | H9: 10 | I9: 108.66 | J9: =H9*I9 -> 1086.6 | K9: =G9+J9 -> 1086.6 | L9: 1086.6 | M9: =+M8+K9-L9 -> 0.004
A10: 7 | B10: 06.11.2025 | C10: Sri Venkata Sitha Rama Filling Station | D10: Bhimavaram | G10: =E10*F10 -> 0 | H10: 10 | I10: 109.83 | J10: =H10*I10 -> 1098.3 | K10: =G10+J10 -> 1098.3 | L10: 1098.3 | M10: =+M9+K10-L10 -> 0.004
A11: 8 | B11: 07.11.2025 | C11: Sri Suryaprakash Service Filling Station | D11: Rajahmundry | G11: =E11*F11 -> 0 | H11: 38.37 | I11: 108.86 | J11: =H11*I11 -> 4176.9582 | K11: =G11+J11 -> 4176.9582 | L11: 4176.96 | M11: =+M10+K11-L11 -> 0.0022
A12: 9 | B12: 08.11.2025 | C12: Buchibabu Filling Center | D12: Ethakota | E12: 39.14 | F12: 97.06 | G12: =E12*F12 -> 3798.9284 | J12: =H12*I12 -> 0 | K12: =G12+J12 -> 3798.9284 | L12: 3798.93 | M12: =+M11+K12-L12 -> 0.0006
A13: 10 | B13: 10.11.2025 | C13: Bhaskara Agencies-Morampudi | D13: Rajahmundry | G13: =E13*F13 -> 0 | H13: 24.81 | I13: 108.83 | J13: =H13*I13 -> 2700.0723 | K13: =G13+J13 -> 2700.0723 | L13: 2700.07 | M13: =+M12+K13-L13 -> 0.0029
A14: 11 | B14: 11.11.2025 | C14: Buchibabu Filling Center | D14: Ethakota | G14: =E14*F14 -> 0 | H14: 5 | I14: 109.21 | J14: =H14*I14 -> 546.05 | K14: =G14+J14 -> 546.05 | L14: 546.05 | M14: =+M13+K14-L14 -> 0.0029
A15: 12 | B15: 18.11.2025 | C15: Sri Surya Fuelling Station | D15: Rajahmundry | E15: 36.19 | F15: 96.71 | G15: =E15*F15 -> 3499.9349 | J15: =H15*I15 -> 0 | K15: =G15+J15 -> 3499.9349 | L15: 3499.93 | M15: =+M14+K15-L15 -> 0.0078
A16: 13 | B16: 22.11.2025 | C16: APSRTC Petrol Bunk | D16: Rangampeta(Peddapuram) | E16: 44.86 | F16: 96.67 | G16: =E16*F16 -> 4336.6162 | J16: =H16*I16 -> 0 | K16: =G16+J16 -> 4336.6162 | L16: 4336.62 | M16: =+M15+K16-L16 -> 0.004
B17: 25.11.2025 | C17: Sree Suryaprakash Service | D17: Rajahmundry | E17: 51.68 | F17: 96.74 | G17: =E17*F17 -> 4999.5232 | J17: =H17*I17 -> 0 | K17: =G17+J17 -> 4999.5232 | L17: 4999.52 | M17: =+M16+K17-L17 -> 0.0072
A18: 14 | B18: 26.11.2025 | C18: Sri Lakshmi Agencies | D18: Samalkot | E18: 43 | F18: 97.49 | G18: =E18*F18 -> 4192.07 | J18: =H18*I18 -> 0 | K18: =G18+J18 -> 4192.07 | L18: 4192.07 | M18: =+M16+K18-L18 -> 0.004
A19: 15 | C19: BP Lalacheruvu Jail Road | D19: Rajahmundry | G19: =E19*F19 -> 0 | H19: 5 | I19: 108.86 | J19: =H19*I19 -> 544.3 | K19: =G19+J19 -> 544.3 | L19: 544.3 | M19: =+M18+K19-L19 -> 0.004
A20: 16 | G20: =E20*F20 -> 0 | J20: =H20*I20 -> 0 | K20: =G20+J20 -> 0 | M20: =+M19+K20-L20 -> 0.004
A21: 17 | G21: =E21*F21 -> 0 | J21: =H21*I21 -> 0 | K21: =G21+J21 -> 0 | M21: =+M20+K21-L21 -> 0.004
A22: 18 | G22: =E22*F22 -> 0 | J22: =H22*I22 -> 0 | K22: =G22+J22 -> 0 | M22: =+M21+K22-L22 -> 0.004
A23: 19 | G23: =E23*F23 -> 0 | J23: =H23*I23 -> 0 | K23: =G23+J23 -> 0 | M23: =+M22+K23-L23 -> 0.004
A24: 20 | G24: =E24*F24 -> 0 | J24: =H24*I24 -> 0 | K24: =G24+J24 -> 0 | M24: =+M23+K24-L24 -> 0.004
A25: 21 | G25: =E25*F25 -> 0 | J25: =H25*I25 -> 0 | K25: =G25+J25 -> 0 | M25: =+M24+K25-L25 -> 0.004
A26: 22 | G26: =E26*F26 -> 0 | J26: =H26*I26 -> 0 | K26: =G26+J26 -> 0 | M26: =+M25+K26-L26 -> 0.004
A27: 23 | G27: =E27*F27 -> 0 | J27: =H27*I27 -> 0 | K27: =G27+J27 -> 0 | M27: =+M26+K27-L27 -> 0.004
A28: 24 | G28: =E28*F28 -> 0 | J28: =H28*I28 -> 0 | K28: =G28+J28 -> 0 | M28: =+M27+K28-L28 -> 0.004
A29: 25 | G29: =E29*F29 -> 0 | J29: =H29*I29 -> 0 | K29: =G29+J29 -> 0 | M29: =+M28+K29-L29 -> 0.004
A30: 26 | G30: =E30*F30 -> 0 | J30: =H30*I30 -> 0 | K30: =G30+J30 -> 0 | M30: =+M29+K30-L30 -> 0.004
A31: 27 | G31: =E31*F31 -> 0 | J31: =H31*I31 -> 0 | K31: =G31+J31 -> 0 | M31: =+M30+K31-L31 -> 0.004
... A33: 29 | G33: =E33*F33 -> 0 | J33: =H33*I33 -> 0 | K33: =G33+J33 -> 0 | M33: =+M32+K33-L33 -> 0.004
G34: =E34*F34 -> 0 | J34: =H34*I34 -> 0 | K34: =G34+J34 -> 0 | M34: 0
A35: 30 | G35: =E35*F35 -> 0 | J35: =H35*I35 -> 0 | K35: =G35+J35 -> 0 | M35: =+M33+K35-L35 -> 0.004
A36: 31 | G36: =E36*F36 -> 0 | J36: =H36*I36 -> 0 | K36: =G36+J36 -> 0 | L36: 0 | M36: =+M35+K36-L36 -> 0.004
E37: =SUM(E4:E36) -> 250.72 | G37: =SUM(G4:G36) -> 24327.467 | H37: =SUM(H4:H36) -> 93.18 | J37: =SUM(J4:J36) -> 10152.28 | K37: =SUM(K4:K36) -> 34479.747 | L37: =SUM(L4:L36) -> 34479.74

Sheet Madana palli
A2: S.No | B2: Date | C2: GRN No | D2: Ind no/Bill No | E2: Diesel (Lts) | F2: Price | G2: Amount | H2: Petrol (Lts) | I2: Price | J2: Amount | K2: Total amount | L2: Amount paid | M2: As on Date | N2: Remarks
A3: Opening Balance | M3: 0
A4: 1 | B4: 45962 | G4: =E4*F4 -> 0 | H4: 0 | I4: 0 | J4: =H4*I4 -> 0 | K4: =G4+J4 -> 0 | L4: =+K4 -> 0 | M4: 0
A5: 2 | B5: 45963 | G5: =E5*F5 -> 0 | H5: 0 | I5: 0 | J5: =H5*I5 -> 0 | K5: =G5+J5 -> 0 | L5: =+K5 -> 0 | M5: 0
A6: 3 | B6: 45964 | E6: 200 | F6: 97.96 | G6: =E6*F6 -> 19592 | H6: 0 | I6: 0 | J6: =H6*I6 -> 0 | K6: =G6+J6 -> 19592 | L6: =+K6 -> 19592 | M6: 0
A7: 4 | B7: 45965 | G7: =E7*F7 -> 0 | H7: 0 | I7: 0 | J7: =H7*I7 -> 0 | K7: =G7+J7 -> 0 | L7: =+K7 -> 0 | M7: 0
A8: 5 | B8: 45966 | E8: 200 | F8: 97.76 | G8: =E8*F8 -> 19552 | H8: 4.54 | I8: 110.07 | J8: =H8*I8 -> 499.7178 | K8: =G8+J8 -> 20051.718 | L8: =+K8 -> 20051.718 | M8: 0
A9: 6 | B9: 45967 | G9: =E9*F9 -> 0 | H9: 0 | I9: 0 | J9: =H9*I9 -> 0 | K9: =G9+J9 -> 0 | L9: =+K9 -> 0 | M9: 0
A10: 7 | B10: 45968 | E10: 249.99 | F10: 97.76 | G10: =E10*F10 -> 24439.022 | H10: 0 | I10: 0 | J10: =H10*I10 -> 0 | K10: =G10+J10 -> 24439.022 | L10: =+K10 -> 24439.022 | M10: 0 | O10: 169.99
A11: 8 | B11: 45969 | G11: =E11*F11 -> 0 | H11: 0 | I11: 0 | J11: =H11*I11 -> 0 | K11: =G11+J11 -> 0 | L11: =+K11 -> 0 | M11: 0 | O11: 80
A12: 9 | B12: 45970 | G12: =E12*F12 -> 0 | H12: 0 | I12: 0 | J12: =H12*I12 -> 0 | K12: =G12+J12 -> 0 | L12: =+K12 -> 0 | M12: 0 | O12: =SUM(O10:O11) -> 249.99 | P12: 97.76 | Q12: =O12*P12 -> 24439.022
A13: 10 | B13: 45971 | G13: =E13*F13 -> 0 | H13: 0 | I13: 0 | J13: =H13*I13 -> 0 | K13: =G13+J13 -> 0 | L13: =+K13 -> 0 | M13: 0
A14: 11 | B14: 45972 | E14: 30.89 | F14: 97.76 | G14: =E14*F14 -> 3019.8064 | H14: 5.47 | I14: 109.61 | J14: =H14*I14 -> 599.5667 | K14: =G14+J14 -> 3619.3731 | L14: =+K14 -> 3619.3731 | M14: 0
A15: 12 | B15: 45973 | G15: =E15*F15 -> 0 | H15: 0 | I15: 0 | J15: =H15*I15 -> 0 | K15: =G15+J15 -> 0 | L15: =+K15 -> 0 | M15: 0 | P15: 7820.8
A16: 13 | B16: 45974 | G16: =E16*F16 -> 0 | H16: 0 | I16: 0 | J16: =H16*I16 -> 0 | K16: =G16+J16 -> 0 | L16: =+K16 -> 0 | M16: 0 | P16: 16619.2
A17: 14 | B17: 45975 | G17: =E17*F17 -> 0 | H17: 0 | I17: 0 | J17: =H17*I17 -> 0 | K17: =G17+J17 -> 0 | L17: =+K17 -> 0 | M17: 0 | P17: =SUM(P15:P16) -> 24440
A18: 15 | B18: 45976 | G18: =E18*F18 -> 0 | H18: 0 | I18: 0 | J18: =H18*I18 -> 0 | K18: =G18+J18 -> 0 | L18: =+K18 -> 0 | M18: 0
A19: 16 | B19: 45977 | G19: =E19*F19 -> 0 | H19: 0 | I19: 0 | J19: =H19*I19 -> 0 | K19: =G19+J19 -> 0 | L19: =+K19 -> 0 | M19: 0
A20: 17 | B20: 45978 | E20: 42.45 | F20: 97.76 | G20: =E20*F20 -> 4149.912 | H20: 0 | I20: 0 | J20: =H20*I20 -> 0 | K20: =G20+J20 -> 4149.912 | L20: =+K20 -> 4149.912 | M20: 0
A21: 18 | B21: 45979 | G21: =E21*F21 -> 0 | H21: 0 | I21: 0 | J21: =H21*I21 -> 0 | K21: =G21+J21 -> 0 | L21: =+K21 -> 0 | M21: 0 | N21: IOCL
A22: 19 | B22: 45980 | G22: =E22*F22 -> 0 | H22: 5.47 | I22: 600 | J22: =H22*I22 -> 3282 | K22: =G22+J22 -> 3282 | L22: =+K22 -> 3282 | M22: 0
A23: 20 | B23: 45981 | G23: =E23*F23 -> 0 | H23: 0 | I23: 0 | J23: =H23*I23 -> 0 | K23: =G23+J23 -> 0 | L23: =+K23 -> 0 | M23: 0 | N23: IOCL
A24: 21 | B24: 45982 | G24: =E24*F24 -> 0 | H24: 0 | I24: 0 | J24: =H24*I24 -> 0 | K24: =G24+J24 -> 0 | L24: =+K24 -> 0 | M24: 0
A25: 22 | B25: 45983 | G25: =E25*F25 -> 0 | H25: 0 | I25: 0 | J25: =H25*I25 -> 0 | K25: =G25+J25 -> 0 | L25: =+K25 -> 0 | M25: 0
A26: 23 | B26: 45984 | G26: =E26*F26 -> 0 | H26: 0 | I26: 0 | J26: =H26*I26 -> 0 | K26: =G26+J26 -> 0 | L26: =+K26 -> 0 | M26: 0 | N26: HPCL
A27: 24 | B27: 45985 | G27: =E27*F27 -> 0 | H27: 0 | I27: 0 | J27: =H27*I27 -> 0 | K27: =G27+J27 -> 0 | L27: =+K27 -> 0 | M27: 0 | N27: IOCL
A28: 25 | B28: 45986 | G28: =E28*F28 -> 0 | H28: 0 | I28: 0 | J28: =H28*I28 -> 0 | K28: =G28+J28 -> 0 | L28: =+K28 -> 0 | M28: 0
A29: 26 | B29: 45987 | G29: =E29*F29 -> 0 | H29: 0 | I29: 0 | J29: =H29*I29 -> 0 | K29: =G29+J29 -> 0 | L29: =+K29 -> 0 | M29: 0
A30: 27 | B30: 45988 | G30: =E30*F30 -> 0 | H30: 0 | I30: 0 | J30: =H30*I30 -> 0 | K30: =G30+J30 -> 0 | L30: =+K30 -> 0 | M30: 0
A31: 28 | B31: 45989 | G31: =E31*F31 -> 0 | H31: 0 | I31: 0 | J31: =H31*I31 -> 0 | K31: =G31+J31 -> 0 | L31: =+K31 -> 0 | M31: 0
A32: 29 | B32: 45990 | G32: =E32*F32 -> 0 | H32: 0 | I32: 0 | J32: =H32*I32 -> 0 | K32: =G32+J32 -> 0 | L32: =+K32 -> 0 | M32: 0
A33: 30 | B33: 45991 | G33: =E33*F33 -> 0 | H33: 0 | I33: 0 | J33: =H33*I33 -> 0 | K33: =G33+J33 -> 0 | L33: =+K33 -> 0 | M33: 0
A34: 31 | G34: =E34*F34 -> 0 | H34: 0 | I34: 0 | J34: =H34*I34 -> 0 | K34: =G34+J34 -> 0 | L34: =+K34 -> 0 | M34: 0
E35: =SUM(E4:E34) -> 723.33 | G35: =SUM(G4:G34) -> 70752.741 | H35: =SUM(H4:H34) -> 15.48 | J35: =SUM(J4:J34) -> 4381.2845 | K35: =SUM(K4:K34) -> 75134.025 | L35: =SUM(L4:L34) -> 75134.025

Sheet Kadur
A1: Vishal Service Station
A2: S.No | B2: Date | C2: GRN No | D2: Ind No/Bill No | E2: Diesel (Lts) | F2: Price | G2: Amount | H2: Petrol (Lts) | I2: Price | J2: Amount | K2: Total amount | L2: Amount paid | M2: As on Date | N2: Remarks
A3: Opening Balance | K3: 164331.63 | M3: 164331.63 | O3: 207239.43
A4: 1 | B4: 45962 | F4: 0 | G4: =E4*F4 -> 0 | H4: 0 | I4: 0 | J4: =H4*I4 -> 0 | K4: =G4+J4 -> 0 | M4: =M3+K4-L4 -> 164331.63
A5: 2 | B5: 45963 | F5: 0 | G5: =E5*F5 -> 0 | H5: 0 | I5: 0 | J5: =H5*I5 -> 0 | K5: =G5+J5 -> 0 | M5: =M4+K5-L5 -> 164331.63
A6: 3 | B6: 45964 | F6: 0 | G6: =E6*F6 -> 0 | H6: 0 | I6: 0 | J6: =H6*I6 -> 0 | K6: =G6+J6 -> 0 | M6: =M5+K6-L6 -> 164331.63
