Workbook

Sheet Sheet1
A1: S.no | B1: Site Name | C1: Bunk Name | D1: Diesel(Liters) | E1: Diesel Amount | F1: Petrol(Liters) | G1: Petrol Amount | H1: Total Amount | I1: Opening Blance | J1: Amount Paid | K1: Closing Balances
A2: 1 | B2: Khammam-1 | C2: Sri Ramakotaiah Fuel Point | D2: 11984.26 | E2: 1146654 | F2: 130 | G2: 13969.8 | H2: =E2+G2 -> 1160623.8 | I2: 5140597 | J2: 2500000 | K2: =I2+H2-J2 -> 3801220.8
A3: 2 | B3: Khammam-2 | C3: Divya laxmi ganapathi | D3: 118512.26 | E3: 11339228 | F3: 535 | G3: 57491.1 | H3: =E3+G3 -> 11396719 | I3: 3730421 | J3: 1500000 | K3: =I3+H3-J3 -> 13627140
A4: 3 | B4: Khammam-3 | C4: Jayasai union bunk | D4: 33155.09 | E4: 3172942.1 | F4: 70 | G4: 7523.6 | H4: =E4+G4 -> 3180465.7 | I4: 8891075.4 | J4: 2000000 | K4: =I4+H4-J4 -> 10071541
A5: 4 | B5: Jadcherla-1 | C5: Sai Baba Fuel Station | D5: 6550.84 | E5: 631631.99 | F5: 305.75 | G5: 33091.323 | H5: =E5+G5 -> 664723.32 | I5: 1966837 | J5: 0 | K5: =I5+H5-J5 -> 2631560.3
A6: 5 | B6: Jadcherla-2 | C6: Uttara Enterprises | D6: 0 | E6: 0 | F6: 0 | G6: 0 | H6: =E6+G6 -> 0 | I6: 1832240.6 | J6: 0 | K6: =I6+H6-J6 -> 1832240.6
A7: 6 | B7: Jadcherla-3 | C7: Bhavani KSK Fuel Station-Nawabpet | D7: 4040 | E7: 389092.4 | F7: 0 | G7: 0 | H7: =E7+G7 -> 389092.4 | I7: 0 | J7: 0 | K7: =I7+H7-J7 -> 389092.4
A8: 7 | B8: Jadcherla-4 | C8: ADHOC FILLING STATION STATION | D8: 11600 | E8: 1118588 | F8: 0 | G8: 0 | H8: =E8+G8 -> 1118588 | I8: 0 | J8: 0 | K8: =I8+H8-J8 -> 1118588
A9: 8 | B9: Sangareddy-1 | C9: Shree lakshmi ganapathi F/S | D9: 4185.96 | E9: 403359.11 | F9: 62 | G9: 6706.54 | H9: =E9+G9 -> 410065.65 | I9: 1004532 | J9: 1414699.8 | K9: 0
A10: 9 | B10: Sangareddy-2 | C10: Sri Durgabhavani Filling Station | D10: 165 | E10: 15912 | F10: 16 | G10: 1732.96 | H10: =E10+G10 -> 17644.96 | I10: 0 | J10: 17644.96 | K10: =I10+H10-J10 -> 0
A11: 10 | B11: Sangareddy-3 | C11: Laxmi Narasimha Enterprises F/S | D11: 40 | E11: 3849 | F11: 0 | G11: 0 | H11: =E11+G11 -> 3849 | I11: 0 | J11: 3849 | K11: =I11+H11-J11 -> 0
A12: 11 | B12: Sangareddy-4 | C12: Sree Shiva Parvathi Filling Station | D12: 1459.79 | E12: 140476 | F12: 16 | G12: 1732.96 | H12: =E12+G12 -> 142208.96 | I12: 0 | J12: 142208.96 | K12: =I12+H12-J12 -> 0
A13: 12 | B13: YG Gudda | C13: Pallavi Petrolium | D13: 3800 | E13: 346940 | F13: 385 | G13: 39747.4 | H13: =E13+G13 -> 386687.4 | I13: 244365 | J13: 299920 | K13: =I13+H13-J13 -> 331132.4
A14: 13 | B14: Hosadurga-1 | C14: Merchant Petroliums | D14: 4500 | E14: 412380 | F14: 140 | G14: 14777 | H14: =E14+G14 -> 427157 | I14: 0 | J14: 150000 | K14: =I14+H14-J14 -> 277157
A15: 14 | B15: Hosadurga-2 | C15: Shree Veeraprathap Fuel | D15: 2000 | E15: 182780 | F15: 135 | G15: 13967.1 | H15: =E15+G15 -> 196747.1 | I15: 151569.4 | J15: 150000 | K15: =I15+H15-J15 -> 198316.5
A16: 15 | B16: Malebennuru(KUWSDB) | C16: Sri Ramanjuneya Service Station | D16: 3277.82 | E16: 301888 | F16: 138 | G16: 14332 | H16: =E16+G16 -> 316220 | I16: 96655 | J16: 385490 | K16: =I16+H16-J16 -> 27385
A17: 16 | B17: kadur | C17: Vishal Service Station | D17: 2000 | E17: 182300 | F17: 145 | G17: 15119.15 | H17: =E17+G17 -> 197419.15 | I17: 578097.65 | J17: 0 | K17: =I17+H17-J17 -> 775516.8
A18: 17 | B18: Hiriyur(VJNL) | C18: Sri Balaji Agencies | D18: 2400 | E18: 221040 | F18: 210 | G18: 21810.6 | H18: =E18+G18 -> 242850.6 | I18: 237520 | J18: 250000 | K18: =I18+H18-J18 -> 230370.6
A19: 18 | B19: Chellakere(KUWSDB) | C19: Sri Vishnu Baba Petroleum | D19: 2045 | E19: 188324.05 | F19: 125 | G19: 12982.5 | H19: =E19+G19 -> 201306.55 | I19: 0 | J19: 201306.55 | K19: =I19+H19-J19 -> 0
A20: 19 | B20: Khanapur(PKG-3) | C20: J K Makavi | D20: 169 | E20: 15411.11 | F20: 16.25 | G20: 1669.23 | H20: =E20+G20 -> 17080.34 | I20: 0 | J20: 17080.34 | K20: =I20+H20-J20 -> 0
A21: 20 | B21: Munavalli(PKG-3) | C21: Shahapur Petroleum | D21: 14283.35 | E21: 1303412.1 | F21: 127 | G21: 13103.86 | H21: =E21+G21 -> 1316516 | I21: 58857 | J21: 1134279.9 | K21: =I21+H21-J21 -> 241093.08
... A24: 23 | B24: Kabbur(PKG-3) | C24: Shri Jai Hanuman Petrolium | D24: 509.02 | E24: 46621.142 | F24: 11.56 | G24: 1196.8068 | H24: =E24+G24 -> 47817.949 | I24: 0 | J24: 47817.949 | K24: =I24+H24-J24 -> 0
A25: 24 | B25: Kumta (PKG-1) | C25: Krishma fuel station | D25: 760.33 | E25: 69889.534 | F25: 47.46 | G25: 4933.9416 | H25: =E25+G25 -> 74823.475 | J25: 74823.475 | K25: =I25+H25-J25 -> 0
A26: 25 | B26: Jalgaon | C26: Sri Sai Petrol Pump | D26: 597.14 | E26: 54712.182 | F26: 13.52 | G26: 1419.4272 | H26: =E26+G26 -> 56131.609 | I26: 4528.49 | J26: 49930.511 | K26: =I26+H26-J26 -> 10729.588
A27: 26 | B27: MKBD | C27: Shree Sai Samarth Petroleum | D27: 25450 | E27: 2319513 | F27: 75 | G27: 7845 | H27: =E27+G27 -> 2327358 | I27: 1668531 | J27: 2000000 | K27: =I27+H27-J27 -> 1995889
A28: 27 | B28: Haveri | C28: Shivalingeshwar Petroleum | D28: 944.46 | E28: 86389.756 | F28: 63.01 | G28: 6517.1243 | H28: =E28+G28 -> 92906.88 | I28: 90058 | J28: 115444 | K28: =I28+H28-J28 -> 67520.88
A29: 28 | B29: Guttal | C29: Taware filling station | D29: 935.89 | E29: 85914.702 | F29: 40 | G29: 4150.4 | H29: =E29+G29 -> 90065.102 | J29: 90065.102 | K29: =I29+H29-J29 -> 0
A30: 29 | B30: Rattihali | C30: Shree Siri Gowari petroliam | D30: 1032.57 | E30: 95037.743 | F30: 45 | G30: 4680.9 | H30: =E30+G30 -> 99718.643 | J30: 99718.643 | K30: =I30+H30-J30 -> 0
A31: 30 | B31: Gajendragada | C31: Vanasri Petrol Pump | D31: 60 | E31: 5509.8 | F31: 18 | G31: 1868.4 | H31: =E31+G31 -> 7378.2 | I31: 30323 | J31: 7378.2 | K31: =I31+H31-J31 -> 30323
A32: 31 | B32: Ghattaprabha(PKG-3) | C32: Vivek Petrol Pump | D32: 0 | E32: 0 | F32: 0 | G32: 0 | H32: =E32+G32 -> 0 | I32: 1036347.3 | J32: 400000 | K32: =I32+H32-J32 -> 636347.32
A33: 32 | B33: Gokak(PKG-3) | C33: AJ Petrolinks | D33: 11163.57 | E33: 1021243.4 | F33: 271 | G33: 28024.11 | H33: =E33+G33 -> 1049267.5 | I33: 473791 | J33: 300000 | K33: =I33+H33-J33 -> 1223058.5
A34: 33 | B34: Ghattaprabha-2(PKG-3) | C34: Manikeri Petroleums | D34: 0 | E34: 0 | F34: 4.82 | G34: 499.98 | H34: =E34+G34 -> 499.98 | I34: 0 | J34: 499.98 | K34: =I34+H34-J34 -> 0
A35: 34 | B35: Ankalgi(PKG-3) | C35: Nirwani Petroleums | D35: 152.92 | E35: 13949.929 | F35: 37.28 | G35: 3857.5144 | H35: =E35+G35 -> 17807.443 | I35: 0 | J35: 17807.443 | K35: =I35+H35-J35 -> 0
A36: 35 | B36: Talikote(PKG-1) | C36: Raykar Oil Agencies | D36: 637.8 | E36: 58358.7 | F36: 61.99 | G36: 5912.6304 | H36: =E36+G36 -> 64271.33 | I36: 0 | J36: 64271.33 | K36: =I36+H36-J36 -> 0
A37: 36 | B37: Chadchan(PKG-1) | C37: Khavekar Petrolium | D37: 577.29 | E37: 52088.877 | F37: 43.88 | G37: 4482.7808 | H37: =E37+G37 -> 56571.658 | I37: 192780 | J37: 192780 | K37: =I37+H37-J37 -> 56571.658
A38: 37 | B38: Sindagi | C38: G.P.PORWAL | D38: 138 | E38: 12589.74 | F38: 0 | G38: 0 | H38: =E38+G38 -> 12589.74 | I38: 0 | J38: 12589.74 | K38: =I38+H38-J38 -> 0
A39: 38 | B39: Muddebihal(PKG-1) | C39: Bhosle Service Station | D39: 98.41 | E39: 8999.5945 | F39: 33.81 | G39: 3495.6159 | H39: =E39+G39 -> 12495.21 | I39: 0 | J39: 12495.21 | K39: =I39+H39-J39 -> 0
A40: 39 | B40: Almela(PKG-1) | C40: Shiddeshwar Petroleums | D40: 35.03 | E40: 3199.2899 | F40: 30.92 | G40: 3192.7992 | H40: =E40+G40 -> 6392.0891 | I40: 0 | J40: 6392.0891 | K40: =I40+H40-J40 -> 0
A41: 40 | B41: Srirangapatna | C41: Sri Chakra Fuel Station | D41: 71.77 | E41: 6500.2089 | F41: 35.13 | G41: 3599.4198 | H41: =E41+G41 -> 10099.629 | I41: 0 | J41: 10099.629 | K41: =I41+H41-J41 -> 0
A42: 41 | B42: Nalatwad(PKG-1) | C42: Shri Pawad Basaweshwar Petroleums | D42: 436.89 | E42: 40027.862 | F42: 21.25 | G42: 2200.8625 | H42: =E42+G42 -> 42228.724 | I42: 48315 | J42: 90535.84 | K42: =I42+H42-J42 -> 7.8843
...

Sheet May-25
A1: S.no | B1: Site Name | C1: Bunk Name | D1: Diesel(Liters) | E1: Diesel Amount | F1: Petrol(Liters) | G1: Petrol Amount | H1: Total Amount | I1: Opening Blance | J1: Amount Paid | K1: Closing Balances
A2: 1 | B2: Khammam-1 | C2: Sri Ramakotaiah Fuel Point | D2: =+'Khammam-1'!E36 -> 11984.26 | E2: =+'Khammam-1'!G36 -> 1146654 | F2: =+'Khammam-1'!H36 -> 130 | G2: =+'Khammam-1'!J36 -> 13969.8 | H2: =E2+G2 -> 1160623.8 | I2: =+'Khammam-1'!K3 -> 5140597 | J2: =+'Khammam-1'!L36 -> 4000000 | K2: =H2+I2-J2 -> 2301220.8
A3: 2 | B3: Khammam-2 | C3: Divya laxmi ganapathi | D3: =+'Khammam-2'!E37 -> 146362.52 | E3: =+'Khammam-2'!G37 -> 14003941 | F3: =+'Khammam-2'!H37 -> 680 | G3: =+'Khammam-2'!J37 -> 73072.8 | H3: =E3+G3 -> 14077014 | I3: =+'Khammam-2'!K3 -> 3730421 | J3: =+'Khammam-2'!L37 -> 8500000 | K3: =H3+I3-J3 -> 9307434.7
A4: 3 | B4: Khammam-3 | C4: Jayasai union bunk | D4: =+'Khammam-3'!E35 -> 57904.99 | E4: =+'Khammam-3'!G35 -> 5541507.5 | F4: =+'Khammam-3'!H35 -> 230 | G4: =+'Khammam-3'!J35 -> 24720.4 | H4: =E4+G4 -> 5566227.9 | I4: =+'Khammam-3'!K3 -> 8891075.4 | J4: =+'Khammam-3'!L35 -> 7000000 | K4: =H4+I4-J4 -> 7457303.4
A5: 4 | B5: Jadcherla-1 | C5: Sai Baba Fuel Station | D5: =+'Jedcherla -1'!E35 -> 6568.06 | E5: =+'Jedcherla -1'!G35 -> 633292.35 | F5: =+'Jedcherla -1'!H35 -> 459.59 | G5: =+'Jedcherla -1'!J35 -> 49741.426 | H5: =E5+G5 -> 683033.77 | I5: =+'Jedcherla -1'!K3 -> 1966837 | J5: =+'Jedcherla -1'!L35 -> 1500000 | K5: =H5+I5-J5 -> 1149870.8
A6: 5 | B6: Jadcherla-2 | C6: Uttara Enterprises | D6: 0 | E6: 0 | F6: 0 | G6: 0 | H6: =E6+G6 -> 0 | I6: 1832240.6 | J6: 1500000 | K6: =H6+I6-J6 -> 332240.61
A7: 6 | B7: Jadcherla-3 | C7: Bhavani KSK Fuel Station-Nawabpet | D7: ='Jadcharla-3'!E35 -> 4040 | E7: =+'Jadcharla-3'!G35 -> 389092.4 | F7: 0 | G7: 0 | H7: =E7+G7 -> 389092.4 | I7: 0 | J7: 389092.4 | K7: =H7+I7-J7 -> 0
A8: 7 | B8: Jadcherla-4 | C8: ADHOC FILLING STATION STATION | D8: =+'Jedcharla-4'!E35 -> 18600 | E8: =+'Jedcharla-4'!G35 -> 1793598 | F8: 0 | G8: 0 | H8: =E8+G8 -> 1793598 | I8: 0 | J8: =+'Jedcharla-4'!L35 -> 1793598 | K8: =H8+I8-J8 -> 0
A9: 8 | B9: Sangareddy-1 | C9: Shree lakshmi ganapathi F/S | D9: 4186 | E9: 403359 | F9: 62 | G9: 6707 | H9: =E9+G9 -> 410066 | I9: 1004532 | J9: 1414700 | K9: =H9+I9-J9 -> -102
A10: 9 | B10: Sangareddy-2 | C10: Sri Durgabhavani Filling Station | D10: 165 | E10: 15912 | F10: 16 | G10: 1733 | H10: 17645 | I10: 0 | J10: 17645 | K10: =H10+I10-J10 -> 0
A11: 10 | B11: Sangareddy-3 | C11: Laxmi Narasimha Enterprises F/S | D11: 40 | E11: 3849 | F11: 0 | G11: 0 | H11: 3849 | J11: 3849 | K11: =H11+I11-J11 -> 0
A12: 11 | B12: Sangareddy-4 | C12: Sree Shiva Parvathi Filling Station | D12: 4154.79 | E12: 399815.85 | F12: 56.92 | G12: 6149.07 | H12: =E12+G12 -> 405964.92 | I12: 0 | J12: 405965 | K12: =H12+I12-J12 -> -0.08
A13: 12 | B13: Dindi | D13: =+Dindi!E35 -> 160.67 | E13: =+Dindi!G35 -> 15529.94 | F13: =+Dindi!H35 -> 0 | G13: =+Dindi!J35 -> 0 | H13: =E13+G13 -> 15529.94 | J13: =+Dindi!L35 -> 15529.94 | K13: =H13+I13-J13 -> 0
A14: 12 | B14: YG Gudda | C14: Pallavi Petrolium | D14: =+'YG Gudda '!E36 -> 6528.47 | E14: =+'YG Gudda '!G36 -> 596059.17 | F14: =+'YG Gudda '!H36 -> 595 | G14: =+'YG Gudda '!J36 -> 61427.8 | H14: =E14+G14 -> 657486.97 | I14: ='YG Gudda '!K3 -> 244365 | J14: =+'YG Gudda '!L36 -> 829920 | K14: =H14+I14-J14 -> 71931.965
A15: 13 | B15: Hosadurga-1 | C15: Merchant Petroliums | D15: =+Hosadurga!E35 -> 4500 | E15: =+Hosadurga!G35 -> 412380 | F15: =+Hosadurga!H35 -> 140 | G15: =+Hosadurga!J35 -> 14777 | H15: =E15+G15 -> 427157 | I15: 0 | J15: 427157 | K15: =H15+I15-J15 -> 0
A16: 14 | B16: Hosadurga-2 | C16: Shree Veeraprathap Fuel | D16: =+'Hosadurga -2'!E35 -> 3999.21 | E16: =+'Hosadurga -2'!G35 -> 365487.8 | F16: =+'Hosadurga -2'!H35 -> 205 | G16: =+'Hosadurga -2'!J35 -> 21209.3 | H16: =E16+G16 -> 386697.1 | I16: 151569.4 | J16: 150000 | K16: =H16+I16-J16 -> 388266.5
A17: 15 | B17: Malebennuru(KUWSDB) | C17: Sri Ramanjuneya Service Station | D17: =+'Malebenur(KUWSDB)'!E38 -> 4752.84 | E17: =+'Malebenur(KUWSDB)'!G38 -> 437736.26 | F17: =+'Malebenur(KUWSDB)'!H38 -> 193 | G17: =+'Malebenur(KUWSDB)'!J38 -> 20044.9 | H17: =E17+G17 -> 457781.16 | I17: 96655 | J17: =+'Malebenur(KUWSDB)'!L38 -> 517820.15 | K17: =H17+I17-J17 -> 36616.014
A18: 16 | B18: kadur | C18: Vishal Service Station | D18: =+Kadur!E35 -> 4011.04 | E18: =+Kadur!G35 -> 365606.3 | F18: =+Kadur!H35 -> 250 | G18: =+Kadur!J35 -> 26067.5 | H18: =E18+G18 -> 391673.8 | I18: 578097.65 | J18: 1006.3 | K18: =H18+I18-J18 -> 968765.15
A19: 17 | B19: Hiriyur(VJNL) | C19: Sri Balaji Agencies | D19: =+'Hiriyur(VJNL)'!E35 -> 2400 | E19: =+'Hiriyur(VJNL)'!G35 -> 221040 | F19: =+'Hiriyur(VJNL)'!H35 -> 280 | G19: =+'Hiriyur(VJNL)'!J35 -> 29080.8 | H19: =E19+G19 -> 250120.8 | I19: 237520 | J19: =+'Hiriyur(VJNL)'!L35 -> 400000 | K19: =H19+I19-J19 -> 87640.8
A20: 18 | B20: Chellakere(KUWSDB) | C20: Sri Vishnu Baba Petroleum | D20: =+'Chellakere (KUWSDB)'!E35 -> 2970 | E20: =+'Chellakere (KUWSDB)'!G35 -> 273507.3 | F20: =+'Chellakere (KUWSDB)'!H35 -> 165 | G20: =+'Chellakere (KUWSDB)'!J35 -> 17136.9 | H20: =E20+G20 -> 290644.2 | I20: 0 | J20: =+'Chellakere (KUWSDB)'!L35 -> 290644.2 | K20: =H20+I20-J20 -> 0
A21: 19 | B21: Khanapur(PKG-3) | C21: J K Makavi | D21: =+Khanapur!E35 -> 402.01 | E21: =+Khanapur!G35 -> 36587.059 | F21: =+Khanapur!H35 -> 21.25 | G21: =+Khanapur!J35 -> 2183.1814 | H21: =E21+G21 -> 38770.24 | I21: 0 | J21: =+Khanapur!M35 -> 38770.24 | K21: =H21+I21-J21 -> 0
A22: 20 | B22: Munavalli(PKG-3) | C22: Shahapur Petroleum | D22: =+'Munavalli(KUWSDB)'!E39 -> 16582.17 | E22: =+'Munavalli(KUWSDB)'!G39 -> 1513202.4 | F22: =+'Munavalli(KUWSDB)'!H39 -> 186.32 | G22: =+'Munavalli(KUWSDB)'!J39 -> 19224.498 | H22: =E22+G22 -> 1532426.9 | I22: 58857 | J22: =+'Munavalli(KUWSDB)'!L39 -> 1484279.9 | K22: =H22+I22-J22 -> 107004.03
A23: 21 | B23: Borgaon(PKG-3) | C23: Aadisagar Petrolium | D23: =+Borgaon!E35 -> 445.45 | E23: =+Borgaon!G35 -> 40880.476 | F23: =+Borgaon!H35 -> 46 | G23: =+Borgaon!J35 -> 4771.58 | H23: =E23+G23 -> 45652.056 | I23: 234525.22 | J23: =+Borgaon!L35 -> 257350.95 | K23: =H23+I23-J23 -> 22826.33
A24: 22 | B24: Ugar,Kudichi(PKG-3) | C24: Shiri Bhrhmanath Petrolium | D24: =+'Ugar,Khagwad,Kudichi'!E35 -> 2836.99 | E24: =+'Ugar,Khagwad,Kudichi'!G35 -> 260804.49 | F24: =+'Ugar,Khagwad,Kudichi'!H35 -> 168 | G24: =+'Ugar,Khagwad,Kudichi'!J35 -> 17453.52 | H24: =E24+G24 -> 278258.01 | I24: 273174.22 | J24: =+'Ugar,Khagwad,Kudichi'!L35 -> 310000 | K24: =H24+I24-J24 -> 241432.23
A25: 23 | B25: Kabbur(PKG-3) | C25: Shri Jai Hanuman Petrolium | D25: =+Kabbur!E35 -> 609.02 | E25: =+Kabbur!G35 -> 55780.142 | F25: =+Kabbur!H35 -> 11.56 | G25: =+Kabbur!J35 -> 1196.8068 | H25: =E25+G25 -> 56976.949 | I25: 0 | J25: =+Kabbur!L35 -> 56976.949 | K25: =H25+I25-J25 -> 0
A26: 24 | B26: Kumta (PKG-1) | C26: Krishma fuel station | D26: =+kumta!E35 -> 1080.33 | E26: =+kumta!G35 -> 99303.934 | F26: =+kumta!H35 -> 76.24 | G26: =+kumta!J35 -> 7925.6554 | H26: =E26+G26 -> 107229.59 | I26: 0 | J26: =+kumta!L35 -> 107229.59 | K26: =H26+I26-J26 -> 0
A27: 25 | B27: Jalgaon | C27: Sri Sai Petrol Pump | D27: =+Jalgaon!E39 -> 856.74 | E27: =+Jalgaon!G39 -> 78520.441 | F27: =+Jalgaon!H39 -> 13.52 | G27: =+Jalgaon!J39 -> 1419.4272 | H27: =E27+G27 -> 79939.868 | I27: 4528.49 | J27: =+Jalgaon!L39 -> 70742.446 | K27: =H27+I27-J27 -> 13725.912
A28: 26 | B28: MKBD | C28: Shree Sai Samarth Petroleum | D28: =+MKBD!E36 -> 34366.54 | E28: =+MKBD!G36 -> 3132158.8 | F28: =+MKBD!H36 -> 95 | G28: =+MKBD!J36 -> 9937 | H28: =E28+G28 -> 3142095.8 | I28: 1668531 | J28: =+MKBD!L36 -> 4361948.8 | K28: =H28+I28-J28 -> 448678
A29: 27 | B29: Haveri | C29: Shivalingeshwar Petroleum | D29: =+Haveri!E35 -> 1327.13 | E29: =+Haveri!G35 -> 121392.58 | F29: =+Haveri!H35 -> 74.68 | G29: =+Haveri!J35 -> 7723.8023 | H29: =E29+G29 -> 129116.38 | I29: 90058 | J29: =+Haveri!L35 -> 182855.23 | K29: =H29+I29-J29 -> 36319.153
A30: 28 | B30: Guttal | C30: Taware filling station | D30: =+Guttal!E35 -> 1295.79 | E30: =+Guttal!G35 -> 118953.52 | F30: =+Guttal!H35 -> 67 | G30: =+Guttal!J35 -> 6951.92 | H30: =E30+G30 -> 125905.44 | I30: 0 | J30: =+Guttal!L35 -> 125905.44 | K30: =H30+I30-J30 -> 0.002
A31: 29 | B31: Rattihali | C31: Shree Siri Gowari petroliam | D31: =+Rattihali!E35 -> 1382.42 | E31: =+Rattihali!G35 -> 127237.94 | F31: =+Rattihali!H35 -> 55 | G31: =+Rattihali!J35 -> 5722.9 | H31: =E31+G31 -> 132960.84 | I31: 0 | J31: =+Rattihali!L35 -> 132960.84 | K31: =H31+I31-J31 -> 0
A32: 30 | B32: Gajendragada | C32: Vanasri Petrol Pump | D32: =+Gajendragada!E35 -> 280 | E32: =+Gajendragada!G35 -> 25712.4 | F32: =+Gajendragada!H35 -> 33 | G32: =+Gajendragada!J35 -> 3425.4 | H32: =E32+G32 -> 29137.8 | I32: 30323 | J32: =+Gajendragada!L35 -> 0 | K32: =H32+I32-J32 -> 59460.8
A33: 31 | B33: Ghattaprabha(PKG-3) | C33: Vivek Petrol Pump | D33: =+Ghattaprabha!E35 -> 0 | E33: =+Ghattaprabha!G35 -> 0 | F33: =+Ghattaprabha!H35 -> 0 | G33: =+Ghattaprabha!J35 -> 0 | H33: =E33+G33 -> 0 | I33: 1036347.3 | J33: =+Ghattaprabha!L35 -> 1036347 | K33: =H33+I33-J33 -> 0.3179
A34: 32 | B34: Gokak(PKG-3) | C34: AJ Petrolinks | D34: =+'Gokak Dharwad PKG 3'!E35 -> 16586.07 | E34: =+'Gokak Dharwad PKG 3'!G35 -> 1517293.7 | F34: =+'Gokak Dharwad PKG 3'!H35 -> 452 | G34: =+'Gokak Dharwad PKG 3'!J35 -> 46904.28 | H34: =E34+G34 -> 1564198 | I34: 473791 | J34: =+'Gokak Dharwad PKG 3'!L35 -> 500000 | K34: =H34+I34-J34 -> 1537989
A35: 33 | B35: Ghattaprabha-2(PKG-3) | C35: Manikeri Petroleums | D35: 0 | E35: 0 | F35: 4.82 | G35: 499.98 | H35: =E35+G35 -> 499.98 | I35: 0 | J35: 499.98 | K35: =H35+I35-J35 -> 0
A36: 34 | B36: Ankalgi(PKG-3) | C36: Nirwani Petroleums | D36: 152.92 | E36: 13949.929 | F36: 37.28 | G36: 3857.5144 | H36: =E36+G36 -> 17807.443 | I36: 0 | J36: 17807.443 | K36: =H36+I36-J36 -> 0
A37: 35 | B37: ShankeshWAR | C37: SR Patil | D37: =+' Shankeshwar'!F35 -> 317 | E37: =+' Shankeshwar'!H35 -> 28942.1 | F37: =+' Shankeshwar'!I35 -> 9.68 | G37: =+' Shankeshwar'!K35 -> 999.1696 | H37: =E37+G37 -> 29941.27 | J37: 18442 | K37: =H37+I37-J37 -> 11499.27
A38: 36 | B38: Talikote(PKG-1) | C38: Raykar Oil Agencies | D38: =+' Talikote'!E44 -> 1084.75 | E38: =+' Talikote'!G44 -> 99250.544 | F38: =+' Talikote'!H44 -> 90.52 | G38: =+' Talikote'!J44 -> 9363.3888 | H38: =E38+G38 -> 108613.93 | I38: 0 | J38: =+' Talikote'!L44 -> 106125.19 | K38: =H38+I38-J38 -> 2488.7434
A39: 37 | B39: Chadchan(PKG-1) | C39: Khavekar Petrolium | D39: =+Chadchan!E35 -> 795.91 | E39: =+Chadchan!G35 -> 71814.959 | F39: =+Chadchan!H35 -> 60.36 | G39: =+Chadchan!J35 -> 6166.3776 | H39: =E39+G39 -> 77981.337 | I39: 192780 | J39: =+Chadchan!L35 -> 192780 | K39: =H39+I39-J39 -> 77981.337
A40: 38 | B40: Sindagi | C40: G.P.PORWAL | D40: =+Sindagi!E44 -> 607.7 | E40: =+Sindagi!G44 -> 55440.471 | F40: =+Sindagi!H44 -> 0 | G40: =+Sindagi!J44 -> 0 | H40: =E40+G40 -> 55440.471 | I40: 0 | J40: =+Sindagi!L44 -> 55440.471 | K40: =H40+I40-J40 -> 0
...

Sheet  May -2025 revised
A1: S.no | B1: Site Name | C1: Bunk Name | D1: Diesel(Liters) | E1: Diesel Amount | F1: Petrol(Liters) | G1: Petrol Amount | H1: Total Amount | I1: Opening Blance | J1: Amount Paid | K1: Closing Balances
A2: 1 | B2: Khammam-1 | C2: Sri Ramakotaiah Fuel Point | D2: ='Khammam-1'!E36 -> 11984.26 | E2: ='Khammam-1'!G36 -> 1146654 | F2: ='Khammam-1'!H36 -> 130 | G2: ='Khammam-1'!J36 -> 13969.8 | H2: =E2+G2 -> 1160623.8 | I2: ='Khammam-1'!K3 -> 5140597 | J2: =+'Khammam-1'!L36 -> 4000000 | K2: =I2+H2-J2 -> 2301220.8
A3: 2 | B3: Khammam-2 | C3: Divya laxmi ganapathi | D3: =+'Khammam-2'!E37 -> 146362.52 | E3: =+'Khammam-2'!G37 -> 14003941 | F3: =+'Khammam-2'!H37 -> 680 | G3: =+'Khammam-2'!J37 -> 73072.8 | H3: =E3+G3 -> 14077014 | I3: =+'Khammam-2'!K3 -> 3730421 | J3: =+'Khammam-2'!L37 -> 8500000 | K3: =I3+H3-J3 -> 9307434.7
A4: 3 | B4: Khammam-3 | C4: Jayasai union bunk | D4: =+'Khammam-3'!E35 -> 57904.99 | E4: =+'Khammam-3'!G35 -> 5541507.5 | F4: =+'Khammam-3'!H35 -> 230 | G4: =+'Khammam-3'!J35 -> 24720.4 | H4: =E4+G4 -> 5566227.9 | I4: =+'Khammam-3'!K3 -> 8891075.4 | J4: =+'Khammam-3'!L35 -> 7000000 | K4: =I4+H4-J4 -> 7457303.4
A5: 4 | B5: Jadcherla-1 | C5: Sai Baba Fuel Station | D5: =+'Jedcherla -1'!E35 -> 6568.06 | E5: =+'Jedcherla -1'!G35 -> 633292.35 | F5: =+'Jedcherla -1'!H35 -> 459.59 | G5: =+'Jedcherla -1'!J35 -> 49741.426 | H5: =E5+G5 -> 683033.77 | I5: =+'Jedcherla -1'!K3 -> 1966837 | J5: =+'Jedcherla -1'!L35 -> 1500000 | K5: =I5+H5-J5 -> 1149870.8
A6: 5 | B6: Jadcherla-2 | C6: Uttara Enterprises | D6: =+'Jedcherla-2'!E35 -> 0 | E6: =+'Jedcherla-2'!G35 -> 0 | F6: =+'Jedcherla-2'!H35 -> 0 | G6: =+'Jedcherla-2'!J35 -> 0 | H6: =E6+G6 -> 0 | I6: =+'Jedcherla-2'!K3 -> 1831699.5 | J6: =+'Jedcherla-2'!L35 -> 1500000 | K6: =I6+H6-J6 -> 331699.53
A7: 6 | B7: Jadcherla-3 | C7: Bhavani KSK Fuel Station-Nawabpet | D7: =+'Jadcharla-3'!E35 -> 4040 | E7: =+'Jadcharla-3'!G35 -> 389092.4 | F7: =+'Jadcharla-3'!H35 -> 0 | G7: =+'Jadcharla-3'!J35 -> 0 | H7: =E7+G7 -> 389092.4 | I7: =+'Jadcharla-3'!M3 -> 0 | J7: =+'Jadcharla-3'!L35 -> 389092.4 | K7: =I7+H7-J7 -> 0
A8: 7 | B8: Jadcherla-4 | C8: ADHOC FILLING STATION STATION | D8: =+'Jedcharla-4'!E35 -> 18600 | E8: =+'Jedcharla-4'!G35 -> 1793598 | F8: =+'Jedcharla-4'!H35 -> 0 | G8: =+'Jedcharla-4'!J35 -> 0 | H8: =E8+G8 -> 1793598 | I8: =+'Jedcharla-4'!M3 -> 0 | J8: =+'Jedcharla-4'!L35 -> 1793598 | K8: =I8+H8-J8 -> 0
A9: 8 | B9: Sangareddy-1 | C9: Shree lakshmi ganapathi F/S | D9: 4186 | E9: 403359 | F9: 62 | G9: 6707 | H9: 410066 | I9: 1004532 | J9: 1414700 | K9: =I9+H9-J9 -> -102
A10: 9 | B10: Sangareddy-2 | C10: Sri Durgabhavani Filling Station | D10: 165 | E10: 15912 | F10: 16 | G10: 1733 | H10: 17645 | I10: 0 | J10: 17645 | K10: =I10+H10-J10 -> 0
A11: 10 | B11: Sangareddy-3 | C11: Laxmi Narasimha Enterprises F/S | D11: 40 | E11: 3849 | F11: 0 | G11: 0 | H11: 3849 | I11: 0 | J11: 3849 | K11: =I11+H11-J11 -> 0
A12: 11 | B12: Sangareddy-4 | C12: Sree Shiva Parvathi Filling Station | D12: 4155 | E12: 399816 | F12: 57 | G12: 6149 | H12: 405965 | I12: 0 | J12: 405965 | K12: =I12+H12-J12 -> 0
A13: 12 | B13: Dindi | D13: =+Dindi!E35 -> 160.67 | E13: =+Dindi!G35 -> 15529.94 | F13: =+Dindi!H35 -> 0 | G13: =+Dindi!J35 -> 0 | H13: =E13+G13 -> 15529.94 | I13: =+Dindi!M3 -> 0 | J13: =+Dindi!L35 -> 15529.94 | K13: =I13+H13-J13 -> 0
A14: 12 | B14: YG Gudda | C14: Pallavi Petrolium | D14: =+'YG Gudda '!E36 -> 6528.47 | E14: =+'YG Gudda '!G36 -> 596059.17 | F14: =+'YG Gudda '!H36 -> 595 | G14: =+'YG Gudda '!J36 -> 61427.8 | H14: =E14+G14 -> 657486.97 | I14: =+'YG Gudda '!M3 -> 244365 | J14: =+'YG Gudda '!L36 -> 829920 | K14: =I14+H14-J14 -> 71931.965
A15: 13 | B15: Hosadurga-1 | C15: Merchant Petroliums | D15: =+Hosadurga!E35 -> 4500 | E15: =+Hosadurga!G35 -> 412380 | F15: =+Hosadurga!H35 -> 140 | G15: =+Hosadurga!J35 -> 14777 | H15: =E15+G15 -> 427157 | I15: =+Hosadurga!M3 -> 0 | J15: =+Hosadurga!L35 -> 427157 | K15: =I15+H15-J15 -> 0
A16: 14 | B16: Hosadurga-2 | C16: Shree Veeraprathap Fuel | D16: =+'Hosadurga -2'!E35 -> 3999.21 | E16: =+'Hosadurga -2'!G35 -> 365487.8 | F16: =+'Hosadurga -2'!H35 -> 205 | G16: =+'Hosadurga -2'!J35 -> 21209.3 | H16: =E16+G16 -> 386697.1 | I16: =+'Hosadurga -2'!M3 -> 151569.4 | J16: =+'Hosadurga -2'!L35 -> 150000 | K16: =I16+H16-J16 -> 388266.5
A17: 15 | B17: Malebennuru(KUWSDB) | C17: Sri Ramanjuneya Service Station | D17: =+'Malebenur(KUWSDB)'!E38 -> 4752.84 | E17: =+'Malebenur(KUWSDB)'!G38 -> 437736.26 | F17: =+'Malebenur(KUWSDB)'!H38 -> 193 | G17: =+'Malebenur(KUWSDB)'!J38 -> 20044.9 | H17: =E17+G17 -> 457781.16 | I17: =+'Malebenur(KUWSDB)'!M3 -> 96655 | J17: =+'Malebenur(KUWSDB)'!L38 -> 517820.15 | K17: =I17+H17-J17 -> 36616.014
A18: 16 | B18: kadur | C18: Vishal Service Station | D18: =+Kadur!E35 -> 4011.04 | E18: =+Kadur!G35 -> 365606.3 | F18: =+Kadur!H35 -> 250 | G18: =+Kadur!J35 -> 26067.5 | H18: =E18+G18 -> 391673.8 | I18: =+Kadur!K3 -> 776427.65 | J18: =+Kadur!L35 -> 1006.3 | K18: =I18+H18-J18 -> 1167095.1
A19: 17 | B19: Hiriyur(VJNL) | C19: Sri Balaji Agencies | D19: =+'Hiriyur(VJNL)'!E35 -> 2400 | E19: =+'Hiriyur(VJNL)'!G35 -> 221040 | F19: =+'Hiriyur(VJNL)'!H35 -> 280 | G19: =+'Hiriyur(VJNL)'!J35 -> 29080.8 | H19: =E19+G19 -> 250120.8 | I19: =+'Hiriyur(VJNL)'!M3 -> 237520 | J19: =+'Hiriyur(VJNL)'!L35 -> 400000 | K19: =I19+H19-J19 -> 87640.8
A20: 18 | B20: Chellakere(KUWSDB) | C20: Sri Vishnu Baba Petroleum | D20: =+'Chellakere (KUWSDB)'!E35 -> 2970 | E20: =+'Chellakere (KUWSDB)'!G35 -> 273507.3 | F20: =+'Chellakere (KUWSDB)'!H35 -> 165 | G20: =+'Chellakere (KUWSDB)'!J35 -> 17136.9 | H20: =E20+G20 -> 290644.2 | I20: =+'Chellakere (KUWSDB)'!L3 -> 0 | J20: =+'Chellakere (KUWSDB)'!L35 -> 290644.2 | K20: =I20+H20-J20 -> 0
A21: 19 | B21: Khanapur(PKG-3) | C21: J K Makavi | D21: =+Khanapur!E35 -> 402.01 | E21: =+Khanapur!G35 -> 36587.059 | F21: =+Khanapur!H35 -> 21.25 | G21: =+Khanapur!J35 -> 2183.1814 | H21: =E21+G21 -> 38770.24 | I21: =+Khanapur!M3 -> 0 | J21: =+Khanapur!M35 -> 38770.24 | K21: =I21+H21-J21 -> 0
A22: 20 | B22: Munavalli(PKG-3) | C22: Shahapur Petroleum | D22: ='Munavalli(KUWSDB)'!E39 -> 16582.17 | E22: ='Munavalli(KUWSDB)'!G39 -> 1513202.4 | F22: ='Munavalli(KUWSDB)'!H39 -> 186.32 | G22: ='Munavalli(KUWSDB)'!J39 -> 19224.498 | H22: =E22+G22 -> 1532426.9 | I22: ='Munavalli(KUWSDB)'!M3 -> 58857 | J22: ='Munavalli(KUWSDB)'!L39 -> 1484279.9 | K22: =I22+H22-J22 -> 107004.03
A23: 21 | B23: Borgaon(PKG-3) | C23: Aadisagar Petrolium | D23: =Borgaon!E35 -> 445.45 | E23: =Borgaon!G35 -> 40880.476 | F23: =Borgaon!H35 -> 46 | G23: =Borgaon!J35 -> 4771.58 | H23: =E23+G23 -> 45652.056 | I23: =Borgaon!M3 -> 234525.22 | J23: =Borgaon!L35 -> 257350.95 | K23: =I23+H23-J23 -> 22826.33
A24: 22 | B24: Ugar,Kudichi(PKG-3) | C24: Shiri Bhrhmanath Petrolium | D24: ='Ugar,Khagwad,Kudichi'!E35 -> 2836.99 | E24: ='Ugar,Khagwad,Kudichi'!G35 -> 260804.49 | F24: ='Ugar,Khagwad,Kudichi'!H35 -> 168 | G24: ='Ugar,Khagwad,Kudichi'!J35 -> 17453.52 | H24: =E24+G24 -> 278258.01 | I24: ='Ugar,Khagwad,Kudichi'!M3 -> 273179.62 | J24: ='Ugar,Khagwad,Kudichi'!L35 -> 310000 | K24: =I24+H24-J24 -> 241437.63
A25: 23 | B25: Kabbur(PKG-3) | C25: Shri Jai Hanuman Petrolium | D25: =Kabbur!E35 -> 609.02 | E25: =Kabbur!G35 -> 55780.142 | F25: =Kabbur!H35 -> 11.56 | G25: =Kabbur!J35 -> 1196.8068 | H25: =E25+G25 -> 56976.949 | I25: =Kabbur!K3 -> 0 | J25: =Kabbur!L35 -> 56976.949 | K25: =I25+H25-J25 -> 0
A26: 24 | B26: Kumta (PKG-1) | C26: Krishma fuel station | D26: =kumta!E35 -> 1080.33 | E26: =kumta!G35 -> 99303.934 | F26: =kumta!H35 -> 76.24 | G26: =kumta!J35 -> 7925.6554 | H26: =E26+G26 -> 107229.59 | I26: =kumta!M3 -> 0 | J26: =kumta!L35 -> 107229.59 | K26: =I26+H26-J26 -> 0
A27: 25 | B27: Jalgaon | C27: Sri Sai Petrol Pump | D27: =Jalgaon!E39 -> 856.74 | E27: =Jalgaon!G39 -> 78520.441 | F27: =Jalgaon!H39 -> 13.52 | G27: =Jalgaon!J39 -> 1419.4272 | H27: =E27+G27 -> 79939.868 | I27: =Jalgaon!M3 -> 4528.49 | J27: =Jalgaon!L39 -> 70742.446 | K27: =I27+H27-J27 -> 13725.912
A28: 26 | B28: MKBD | C28: Shree Sai Samarth Petroleum | D28: =MKBD!E36 -> 34366.54 | E28: =MKBD!G36 -> 3132158.8 | F28: =MKBD!H36 -> 95 | G28: =MKBD!J36 -> 9937 | H28: =E28+G28 -> 3142095.8 | I28: =MKBD!M3 -> 1670481.7 | J28: =MKBD!L36 -> 4361948.8 | K28: =I28+H28-J28 -> 450628.67
A29: 27 | B29: Haveri | C29: Shivalingeshwar Petroleum | D29: =Haveri!E35 -> 1327.13 | E29: =Haveri!G35 -> 121392.58 | F29: =Haveri!H35 -> 74.68 | G29: =Haveri!J35 -> 7723.8023 | H29: =E29+G29 -> 129116.38 | I29: =Haveri!M3 -> 90058 | J29: =Haveri!L35 -> 182855.23 | K29: =I29+H29-J29 -> 36319.153
A30: 28 | B30: Guttal | C30: Taware filling station | D30: =Guttal!E35 -> 1295.79 | E30: =Guttal!G35 -> 118953.52 | F30: =Guttal!H35 -> 67 | G30: =Guttal!J35 -> 6951.92 | H30: =E30+G30 -> 125905.44 | I30: =Guttal!M3 -> 0 | J30: =Guttal!L35 -> 125905.44 | K30: =I30+H30-J30 -> 0.002
A31: 29 | B31: Rattihali | C31: Shree Siri Gowari petroliam | D31: =Rattihali!E35 -> 1382.42 | E31: =Rattihali!G35 -> 127237.94 | F31: =Rattihali!H35 -> 55 | G31: =Rattihali!J35 -> 5722.9 | H31: =E31+G31 -> 132960.84 | I31: =Rattihali!M3 -> 0 | J31: =Rattihali!L35 -> 132960.84 | K31: =I31+H31-J31 -> 0
A32: 30 | B32: Gajendragada | C32: Vanasri Petrol Pump | D32: =Gajendragada!E35 -> 280 | E32: =Gajendragada!G35 -> 25712.4 | F32: =Gajendragada!H35 -> 33 | G32: =Gajendragada!J35 -> 3425.4 | H32: =E32+G32 -> 29137.8 | I32: =Gajendragada!M3 -> 30323 | J32: =Gajendragada!L35 -> 0 | K32: =I32+H32-J32 -> 59460.8
A33: 31 | B33: Ghattaprabha(PKG-3) | C33: Vivek Petrol Pump | D33: =Ghattaprabha!E35 -> 0 | E33: =Ghattaprabha!G35 -> 0 | F33: =Ghattaprabha!H35 -> 0 | G33: =Ghattaprabha!J35 -> 0 | H33: =E33+G33 -> 0 | I33: =Ghattaprabha!M3 -> 1036347.3 | J33: =Ghattaprabha!L35 -> 1036347 | K33: =I33+H33-J33 -> 0.3179
A34: 32 | B34: Gokak(PKG-3) | C34: AJ Petrolinks | D34: ='Gokak Dharwad PKG 3'!E35 -> 16586.07 | E34: ='Gokak Dharwad PKG 3'!G35 -> 1517293.7 | F34: ='Gokak Dharwad PKG 3'!H35 -> 452 | G34: ='Gokak Dharwad PKG 3'!J35 -> 46904.28 | H34: =E34+G34 -> 1564198 | I34: ='Gokak Dharwad PKG 3'!M3 -> 473791 | J34: ='Gokak Dharwad PKG 3'!L35 -> 500000 | K34: =I34+H34-J34 -> 1537989
A35: 33 | B35: Ghattaprabha-2(PKG-3) | C35: Manikeri Petroleums | D35: =+' Gokak'!F35 -> 0 | E35: =+' Gokak'!H35 -> 0 | F35: =+' Gokak'!I35 -> 4.82 | G35: =+' Gokak'!K35 -> 499.9786 | H35: =E35+G35 -> 499.9786 | I35: =+' Gokak'!M4 -> 0 | J35: =+' Gokak'!M35 -> 499.9786 | K35: =I35+H35-J35 -> 0
A36: 34 | B36: Ankalgi(PKG-3) | C36: Nirwani Petroleums | D36: =Ankalgi!E35 -> 132.92 | E36: =Ankalgi!G35 -> 12114.329 | F36: =Ankalgi!H35 -> 18 | G36: =Ankalgi!J35 -> 1857.6 | H36: =E36+G36 -> 13971.929 | I36: =Ankalgi!M3 -> 0 | J36: =Ankalgi!L35 -> 13971.929 | K36: =I36+H36-J36 -> 0
A37: 35 | B37: ShankeshWAR | C37: SR Patil | D37: =' Shankeshwar'!F35 -> 317 | E37: =' Shankeshwar'!H35 -> 28942.1 | F37: =' Shankeshwar'!I35 -> 9.68 | G37: =' Shankeshwar'!K35 -> 999.1696 | H37: =E37+G37 -> 29941.27 | I37: =' Shankeshwar'!M3 -> 0 | J37: =' Shankeshwar'!L35 -> 29941.27 | K37: =I37+H37-J37 -> 0
A38: 36 | B38: Talikote(PKG-1) | C38: Raykar Oil Agencies | D38: =' Talikote'!E44 -> 1084.75 | E38: =' Talikote'!G44 -> 99250.544 | F38: =' Talikote'!H44 -> 90.52 | G38: =' Talikote'!J44 -> 9363.3888 | H38: =E38+G38 -> 108613.93 | I38: =' Talikote'!M3 -> 0 | J38: =' Talikote'!L44 -> 106125.19 | K38: =I38+H38-J38 -> 2488.7434
A39: 37 | B39: Chadchan(PKG-1) | C39: Khavekar Petrolium | D39: =Chadchan!E35 -> 795.91 | E39: =Chadchan!G35 -> 71814.959 | F39: =Chadchan!H35 -> 60.36 | G39: =Chadchan!J35 -> 6166.3776 | H39: =E39+G39 -> 77981.337 | I39: =Chadchan!M3 -> 192780 | J39: =Chadchan!L35 -> 192780 | K39: =I39+H39-J39 -> 77981.337
A40: 38 | B40: Sindagi | C40: G.P.PORWAL | D40: =Sindagi!E44 -> 607.7 | E40: =Sindagi!G44 -> 55440.471 | F40: =Sindagi!H44 -> 0 | G40: =Sindagi!J44 -> 0 | H40: =E40+G40 -> 55440.471 | I40: 0 | J40: =Sindagi!L44 -> 55440.471 | K40: =I40+H40-J40 -> 0
...

Sheet Khammam-1
A1: Sri Ramakotaiah Fuel Point
A2: S.No | B2: Date | C2: GRN No | D2: Ind No/Bill No | E2: Diesel (Lts) | F2: Price | G2: Amount | H2: Petrol (Lts) | I2: Price | J2: Amount | K2: Total amount | L2: Amount paid | M2: As 0n Date | N2: Remarks
A3: Opening Balance | K3: 5140597 | M3: =+K3 -> 5140597 | P3: 220299.06
A4: 1 | B4: 45778 | E4: 2600 | F4: 95.68 | G4: =E4*F4 -> 248768 | H4: 20 | I4: 107.46 | J4: =H4*I4 -> 2149.2 | K4: =G4+J4 -> 250917.2 | L4: 0 | M4: =M3+K4-L4 -> 5391514.2
A5: 2 | B5: 45779 | E5: 0 | F5: 0 | G5: =E5*F5 -> 0 | H5: 0 | I5: 0 | J5: =H5*I5 -> 0 | K5: =G5+J5 -> 0 | L5: 0 | M5: =M4+K5-L5 -> 5391514.2
A6: 3 | B6: 45780 | E6: 0 | F6: 0 | G6: =E6*F6 -> 0 | H6: 0 | I6: 0 | J6: =H6*I6 -> 0 | K6: =G6+J6 -> 0 | L6: 0 | M6: =M5+K6-L6 -> 5391514.2
A7: 4 | B7: 45781 | E7: 2800 | F7: 95.68 | G7: =E7*F7 -> 267904 | H7: 35 | I7: 107.46 | J7: =H7*I7 -> 3761.1 | K7: =G7+J7 -> 271665.1 | L7: 0 | M7: =M6+K7-L7 -> 5663179.3
A8: 5 | B8: 45782 | E8: 2000 | F8: 95.68 | G8: =E8*F8 -> 191360 | H8: 20 | I8: 107.46 | J8: =H8*I8 -> 2149.2 | K8: =G8+J8 -> 193509.2 | L8: 0 | M8: =M7+K8-L8 -> 5856688.5
A9: 6 | B9: 45783 | E9: 0 | F9: 0 | G9: =E9*F9 -> 0 | H9: 0 | I9: 0 | J9: =H9*I9 -> 0 | K9: =G9+J9 -> 0 | L9: 0 | M9: =M8+K9-L9 -> 5856688.5
A10: 7 | B10: 45784 | E10: 2013.7 | F10: 95.68 | G10: =E10*F10 -> 192670.82 | H10: 55 | I10: 107.46 | J10: =H10*I10 -> 5910.3 | K10: =G10+J10 -> 198581.12 | L10: 0 | M10: =M9+K10-L10 -> 6055269.6
A11: 8 | B11: 45785 | E11: 0 | F11: 0 | G11: =E11*F11 -> 0 | H11: 0 | I11: 0 | J11: =H11*I11 -> 0 | K11: =G11+J11 -> 0 | L11: 0 | M11: =M10+K11-L11 -> 6055269.6
A12: 9 | B12: 45786 | E12: 0 | F12: 0 | G12: =E12*F12 -> 0 | H12: 0 | I12: 0 | J12: =H12*I12 -> 0 | K12: =G12+J12 -> 0 | L12: 0 | M12: =M11+K12-L12 -> 6055269.6
A13: 10 | B13: 45787 | E13: 0 | F13: 0 | G13: =E13*F13 -> 0 | H13: 0 | I13: 0 | J13: =H13*I13 -> 0 | K13: =G13+J13 -> 0 | L13: 1500000 | M13: =M12+K13-L13 -> 4555269.6
A14: 11 | B14: 45788 | E14: 0 | F14: 0 | G14: =E14*F14 -> 0 | H14: 0 | I14: 0 | J14: =H14*I14 -> 0 | K14: =G14+J14 -> 0 | L14: 0 | M14: =M13+K14-L14 -> 4555269.6
A15: 12 | B15: 45789 | E15: 0 | F15: 0 | G15: =E15*F15 -> 0 | H15: 0 | I15: 0 | J15: =H15*I15 -> 0 | K15: =G15+J15 -> 0 | L15: 0 | M15: =M14+K15-L15 -> 4555269.6
... A18: 15 | B18: 45792 | E18: 0 | F18: 0 | G18: =E18*F18 -> 0 | H18: 0 | I18: 0 | J18: =H18*I18 -> 0 | K18: =G18+J18 -> 0 | L18: 1000000 | M18: =M17+K18-L18 -> 3801220.8
A19: 16 | B19: 45793 | E19: 0 | F19: 0 | G19: =E19*F19 -> 0 | H19: 0 | I19: 0 | J19: =H19*I19 -> 0 | K19: =G19+J19 -> 0 | L19: 0 | M19: =M18+K19-L19 -> 3801220.8 | O19: .
A20: 17 | B20: 45794 | E20: 0 | F20: 0 | G20: =E20*F20 -> 0 | H20: 0 | I20: 0 | J20: =H20*I20 -> 0 | K20: =G20+J20 -> 0 | L20: 0 | M20: =M19+K20-L20 -> 3801220.8
A21: 18 | B21: 45795 | E21: 0 | F21: 0 | G21: =E21*F21 -> 0 | H21: 0 | I21: 0 | J21: =H21*I21 -> 0 | K21: =G21+J21 -> 0 | L21: 0 | M21: =M20+K21-L21 -> 3801220.8
A22: 19 | B22: 45796 | E22: 0 | F22: 0 | G22: =E22*F22 -> 0 | H22: 0 | I22: 0 | J22: =H22*I22 -> 0 | K22: =G22+J22 -> 0 | L22: 0 | M22: =M21+K22-L22 -> 3801220.8
A23: 20 | B23: 45797 | E23: 0 | F23: 0 | G23: =E23*F23 -> 0 | H23: 0 | I23: 0 | J23: =H23*I23 -> 0 | K23: =G23+J23 -> 0 | L23: 0 | M23: =M22+K23-L23 -> 3801220.8
A24: 21 | B24: 45798 | E24: 0 | F24: 0 | G24: =E24*F24 -> 0 | H24: 0 | I24: 0 | J24: =H24*I24 -> 0 | K24: =G24+J24 -> 0 | L24: 0 | M24: =M23+K24-L24 -> 3801220.8
A25: 22 | B25: 45799 | E25: 0 | F25: 0 | G25: =E25*F25 -> 0 | H25: 0 | I25: 0 | J25: =H25*I25 -> 0 | K25: =G25+J25 -> 0 | L25: 0 | M25: =M24+K25-L25 -> 3801220.8
A26: 23 | B26: 45800 | E26: 0 | F26: 0 | G26: =E26*F26 -> 0 | H26: 0 | I26: 0 | J26: =H26*I26 -> 0 | K26: =G26+J26 -> 0 | L26: 0 | M26: =M25+K26-L26 -> 3801220.8
A27: 24 | B27: 45801 | E27: 0 | F27: 0 | G27: =E27*F27 -> 0 | H27: 0 | I27: 0 | J27: =H27*I27 -> 0 | K27: =G27+J27 -> 0 | L27: 0 | M27: =M26+K27-L27 -> 3801220.8
A28: 25 | B28: 45802 | E28: 0 | F28: 0 | G28: =E28*F28 -> 0 | H28: 0 | I28: 0 | J28: =H28*I28 -> 0 | K28: =G28+J28 -> 0 | L28: 0 | M28: =M27+K28-L28 -> 3801220.8
A29: 26 | B29: 45803 | E29: 0 | F29: 0 | G29: =E29*F29 -> 0 | H29: 0 | I29: 0 | J29: =H29*I29 -> 0 | K29: =G29+J29 -> 0 | L29: 0 | M29: =M28+K29-L29 -> 3801220.8
A30: 27 | B30: 45804 | E30: 0 | F30: 0 | G30: =E30*F30 -> 0 | H30: 0 | I30: 0 | J30: =H30*I30 -> 0 | K30: =G30+J30 -> 0 | L30: 0 | M30: =M29+K30-L30 -> 3801220.8
A31: 28 | B31: 45805 | E31: 0 | F31: 0 | G31: =E31*F31 -> 0 | H31: 0 | I31: 0 | J31: =H31*I31 -> 0 | K31: =G31+J31 -> 0 | L31: 1500000 | M31: =M30+K31-L31 -> 2301220.8
A32: 29 | B32: 45806 | E32: 0 | F32: 0 | G32: =E32*F32 -> 0 | H32: 0 | I32: 0 | J32: =H32*I32 -> 0 | K32: =G32+J32 -> 0 | L32: 0 | M32: =M31+K32-L32 -> 2301220.8
A33: 30 | B33: 45807 | E33: 0 | F33: 0 | G33: =E33*F33 -> 0 | H33: 0 | I33: 0 | J33: =H33*I33 -> 0 | K33: =G33+J33 -> 0 | L33: 0 | M33: =M32+K33-L33 -> 2301220.8 | R33: 2584221.7
A34: 31 | B34: 45808 | E34: 0 | F34: 0 | G34: =E34*F34 -> 0 | H34: 0 | I34: 0 | J34: =H34*I34 -> 0 | K34: =G34+J34 -> 0 | L34: 0 | M34: =M33+K34-L34 -> 2301220.8
E35: 0 | F35: 0 | G35: =E35*F35 -> 0 | H35: 0 | I35: 0 | J35: =H35*I35 -> 0 | K35: =G35+J35 -> 0
E36: =SUM(E4:E35) -> 11984.26 | G36: =SUM(G4:G35) -> 1146654 | H36: =SUM(H4:H35) -> 130 | J36: =SUM(J3:J35) -> 13969.8 | K36: =SUM(K4:K35) -> 1160623.8 | L36: =SUM(L4:L35) -> 4000000
E42: =E36+H36 -> 12114.26

Sheet Khammam-2
A1: Divya laxmi ganapathi
A2: S.No | B2: Date | C2: GRN No | D2: Ind No/Bill No | E2: Diesel (Lts) | F2: Price | G2: Amount | H2: Petrol (Lts) | I2: Price | J2: Amount | K2: Total amount | L2: Amount paid | M2: As 0n Date | N2: Remarks
A3: Opening Balance | K3: 3730421 | M3: =+K3 -> 3730421
A4: 1 | B4: 45778 | E4: 5000 | F4: 95.68 | G4: =E4*F4 -> 478400 | H4: 0 | I4: 0 | J4: =H4*I4 -> 0 | K4: =G4+J4 -> 478400 | M4: =M3+K4-L4 -> 4208821
A5: 2 | B5: 45779 | E5: 6529.67 | F5: 95.68 | G5: =E5*F5 -> 624758.83 | H5: 35 | I5: 107.46 | J5: =H5*I5 -> 3761.1 | K5: =G5+J5 -> 628519.93 | M5: =M4+K5-L5 -> 4837340.9
A6: 3 | B6: 45780 | E6: 7183.16 | F6: 95.68 | G6: =E6*F6 -> 687284.75 | H6: 40 | I6: 107.46 | J6: =H6*I6 -> 4298.4 | K6: =G6+J6 -> 691583.15 | M6: =M5+K6-L6 -> 5528924.1
A7: 4 | B7: 45781 | E7: 2500.41 | F7: 95.68 | G7: =E7*F7 -> 239239.23 | H7: 0 | I7: 0 | J7: =H7*I7 -> 0 | K7: =G7+J7 -> 239239.23 | M7: =M6+K7-L7 -> 5768163.3
A8: 5 | B8: 45782 | E8: 5348.86 | F8: 95.68 | G8: =E8*F8 -> 511778.92 | H8: 35 | I8: 107.46 | J8: =H8*I8 -> 3761.1 | K8: =G8+J8 -> 515540.02 | M8: =M7+K8-L8 -> 6283703.3
A9: 6 | B9: 45783 | E9: 5000 | F9: 95.68 | G9: =E9*F9 -> 478400 | H9: 0 | I9: 0 | J9: 0 | K9: =G9+J9 -> 478400 | M9: =M8+K9-L9 -> 6762103.3
A10: 7 | B10: 45784 | E10: 9365.22 | F10: 95.68 | G10: =E10*F10 -> 896064.25 | H10: 0 | I10: 0 | J10: =H10*I10 -> 0 | K10: =G10+J10 -> 896064.25 | M10: =M9+K10-L10 -> 7658167.6
A11: 8 | B11: 45785 | E11: 6000 | F11: 95.68 | G11: =E11*F11 -> 574080 | H11: 20 | I11: 107.46 | J11: =H11*I11 -> 2149.2 | K11: =G11+J11 -> 576229.2 | M11: =M10+K11-L11 -> 8234396.8
A12: 9 | B12: 45786 | D12: 14016.8 | E12: 14016.8 | F12: 95.68 | G12: =E12*F12 -> 1341127.4 | H12: 55 | I12: 107.46 | J12: =H12*I12 -> 5910.3 | K12: =G12+J12 -> 1347037.7 | M12: =M11+K12-L12 -> 9581434.5
A13: 10 | B13: 45787 | E13: 2500 | F13: 95.68 | G13: =E13*F13 -> 239200 | H13: 0 | I13: 0 | J13: =H13*I13 -> 0 | K13: =G13+J13 -> 239200 | L13: 1500000 | M13: =M12+K13-L13 -> 8320634.5
A14: 11 | B14: 45787 | E14: 2500 | F14: 95.67 | G14: =E14*F14 -> 239175 | K14: =G14+J14 -> 239175 | M14: =M13+K14-L14 -> 8559809.5
A15: 12 | B15: 45788 | E15: 2500 | F15: 95.68 | G15: =E15*F15 -> 239200 | H15: 35 | I15: 107.46 | J15: =H15*I15 -> 3761.1 | K15: =G15+J15 -> 242961.1 | M15: =M14+K15-L15 -> 8802770.6
A16: 13 | B16: 45789 | E16: 6200 | F16: 95.68 | G16: =E16*F16 -> 593216 | H16: 20 | I16: 107.46 | J16: =H16*I16 -> 2149.2 | K16: =G16+J16 -> 595365.2 | M16: =M15+K16-L16 -> 9398135.8
A17: 14 | B17: 45790 | E17: 7500 | F17: 95.68 | G17: =E17*F17 -> 717600 | H17: 55 | I17: 107.46 | J17: =H17*I17 -> 5910.3 | K17: =G17+J17 -> 723510.3 | M17: =M16+K17-L17 -> 10121646
A18: 15 | B18: 45791 | E18: 4300 | F18: 95.68 | G18: =E18*F18 -> 411424 | H18: 20 | I18: 107.46 | J18: =H18*I18 -> 2149.2 | K18: =G18+J18 -> 413573.2 | M18: =M17+K18-L18 -> 10535219
A19: 16 | B19: 45792 | E19: 7210.93 | F19: 95.68 | G19: =E19*F19 -> 689941.78 | H19: 55 | I19: 107.46 | J19: =H19*I19 -> 5910.3 | K19: =G19+J19 -> 695852.08 | L19: 0 | M19: =M18+K19-L19 -> 11231071
A20: 17 | B20: 45793 | E20: 0 | F20: 0 | G20: =E20*F20 -> 0 | H20: 35 | I20: 107.46 | J20: =H20*I20 -> 3761.1 | K20: =G20+J20 -> 3761.1 | M20: =M19+K20-L20 -> 11234832
A21: 18 | B21: 45794 | E21: 9445.01 | F21: 95.68 | G21: =E21*F21 -> 903698.56 | H21: 20 | I21: 107.46 | J21: =H21*I21 -> 2149.2 | K21: =G21+J21 -> 905847.76 | M21: =M20+K21-L21 -> 12140680
A22: 19 | B22: 45795 | E22: 5000 | F22: 95.68 | G22: =E22*F22 -> 478400 | H22: 35 | I22: 107.46 | J22: =H22*I22 -> 3761.1 | K22: =G22+J22 -> 482161.1 | M22: =M21+K22-L22 -> 12622841
A23: 20 | B23: 45796 | E23: 1400 | F23: 95.68 | G23: =E23*F23 -> 133952 | H23: 0 | I23: 0 | J23: =H23*I23 -> 0 | K23: =G23+J23 -> 133952 | M23: =M22+K23-L23 -> 12756793
A24: 21 | B24: 45797 | E24: 5000 | F24: 95.68 | G24: =E24*F24 -> 478400 | H24: 55 | I24: 107.46 | J24: =H24*I24 -> 5910.3 | K24: =G24+J24 -> 484310.3 | M24: =M23+K24-L24 -> 13241104
A25: 22 | B25: 45798 | E25: 6529 | F25: 95.68 | G25: =E25*F25 -> 624694.72 | H25: 20 | I25: 107.46 | J25: =H25*I25 -> 2149.2 | K25: =G25+J25 -> 626843.92 | M25: =M24+K25-L25 -> 13867948
A26: 23 | B26: 45799 | E26: 6727 | F26: 95.68 | G26: =E26*F26 -> 643639.36 | H26: 0 | I26: 0 | J26: =H26*I26 -> 0 | K26: =G26+J26 -> 643639.36 | M26: =M25+K26-L26 -> 14511587
A27: 24 | B27: 45800 | E27: 1506 | F27: 95.68 | G27: =E27*F27 -> 144094.08 | H27: 55 | I27: 107.46 | J27: =H27*I27 -> 5910.3 | K27: =G27+J27 -> 150004.38 | M27: =M26+K27-L27 -> 14661591
A28: 25 | B28: 45801 | E28: 4100 | F28: 95.68 | G28: =E28*F28 -> 392288 | H28: 35 | I28: 107.46 | J28: =H28*I28 -> 3761.1 | K28: =G28+J28 -> 396049.1 | M28: =M27+K28-L28 -> 15057640
A29: 26 | B29: 45802 | E29: 2500 | F29: 95.68 | G29: =E29*F29 -> 239200 | H29: 0 | I29: 0 | J29: =H29*I29 -> 0 | K29: =G29+J29 -> 239200 | M29: =M28+K29-L29 -> 15296840
A30: 27 | B30: 45803 | E30: 6600.19 | F30: 95.68 | G30: =E30*F30 -> 631506.18 | H30: 55 | I30: 107.46 | J30: =H30*I30 -> 5910.3 | K30: =G30+J30 -> 637416.48 | L30: 7000000 | M30: =M29+K30-L30 -> 8934256.9
A31: 28 | B31: 45804 | E31: 2500 | F31: 95.68 | G31: =E31*F31 -> 239200 | H31: 0 | I31: 0 | J31: =H31*I31 -> 0 | K31: =G31+J31 -> 239200 | M31: =M30+K31-L31 -> 9173456.9
A32: 29 | B32: 45805 | E32: 0 | F32: 0 | G32: =E32*F32 -> 0 | H32: 0 | I32: 0 | J32: =H32*I32 -> 0 | K32: =G32+J32 -> 0 | M32: =M31+K32-L32 -> 9173456.9
A33: 30 | B33: 45806 | E33: 1400.27 | F33: 95.68 | G33: =E33*F33 -> 133977.83 | H33: 0 | I33: 0 | J33: =H33*I33 -> 0 | K33: =G33+J33 -> 133977.83 | M33: =M32+K33-L33 -> 9307434.7
A34: 31 | B34: 45807 | E34: 0 | F34: 0 | G34: =E34*F34 -> 0 | H34: 0 | I34: 0 | J34: =H34*I34 -> 0 | K34: =G34+J34 -> 0 | M34: =M33+K34-L34 -> 9307434.7
A35: 32 | B35: 45808 | E35: 0 | F35: 0 | G35: =E35*F35 -> 0 | H35: 0 | I35: 0 | J35: =H35*I35 -> 0 | K35: =G35+J35 -> 0
A36: 33
E37: =SUM(E3:E36) -> 146362.52 | G37: =SUM(G3:G36) -> 14003941 | H37: =SUM(H3:H36) -> 680 | J37: =SUM(J3:J36) -> 73072.8 | K37: =SUM(K4:K36) -> 14077014 | L37: =SUM(L3:L36) -> 8500000

Sheet Khammam-3
A1: Jayasai union bunk
A2: S.No | B2: Date | C2: GRN No | D2: Ind No/Bill No | E2: Diesel (Lts) | F2: Price | G2: Amount | H2: Petrol (Lts) | I2: Price | J2: Amount | K2: Total amount | L2: Amount paid | M2: As 0n Date | N2: Remarks
A3: Opening Balance | K3: 8891075.4 | M3: =+K3 -> 8891075.4
A4: 1 | B4: 45778 | E4: 4844.88 | F4: 95.7 | G4: =E4*F4 -> 463655.02 | H4: 0 | I4: 0 | J4: 0 | K4: =G4+J4 -> 463655.02 | M4: =M3+K4-L4 -> 9354730.5
A5: 2 | B5: 45779 | E5: 2871.69 | F5: 95.7 | G5: =E5*F5 -> 274820.73 | H5: 0 | I5: 0 | J5: 0 | K5: =G5+J5 -> 274820.73 | M5: =M4+K5-L5 -> 9629551.2
A6: 3 | B6: 45780 | E6: 7544.95 | F6: 95.7 | G6: =E6*F6 -> 722051.71 | H6: 0 | I6: 0 | J6: 0 | K6: =G6+J6 -> 722051.71 | M6: =M5+K6-L6 -> 10351603
A7: 4 | B7: 45781 | E7: 5393.57 | F7: 95.7 | G7: =E7*F7 -> 516164.65 | H7: 0 | I7: 0 | J7: 0 | K7: =G7+J7 -> 516164.65 | M7: =M6+K7-L7 -> 10867768
A8: 5 | B8: 45782 | E8: 0 | F8: 0 | G8: =E8*F8 -> 0 | H8: 0 | I8: 0 | J8: 0 | K8: =G8+J8 -> 0 | M8: =M7+K8-L8 -> 10867768
A9: 6 | B9: 45783 | E9: 2500 | F9: 95.7 | G9: =E9*F9 -> 239250 | H9: 35 | I9: 107.48 | J9: =H9*I9 -> 3761.8 | K9: =G9+J9 -> 243011.8 | M9: =M8+K9-L9 -> 11110779
A10: 7 | B10: 45784 | E10: 0 | F10: 0 | G10: =E10*F10 -> 0 | H10: 0 | I10: 0 | J10: =H10*I10 -> 0 | K10: =G10+J10 -> 0 | M10: =M9+K10-L10 -> 11110779
A11: 8 | B11: 45785 | E11: 2500 | F11: 95.7 | G11: =E11*F11 -> 239250 | H11: 0 | I11: 0 | J11: =H11*I11 -> 0 | K11: =G11+J11 -> 239250 | M11: =M10+K11-L11 -> 11350029
A12: 9 | B12: 45786 | E12: 0 | F12: 0 | G12: =E12*F12 -> 0 | H12: 0 | I12: 0 | J12: =H12*I12 -> 0 | K12: =G12+J12 -> 0 | M12: =M11+K12-L12 -> 11350029
A13: 10 | B13: 45787 | E13: 0 | F13: 0 | G13: =E13*F13 -> 0 | H13: 0 | I13: 0 | J13: =H13*I13 -> 0 | K13: =G13+J13 -> 0 | M13: =M12+K13-L13 -> 11350029
A14: 11 | B14: 45788 | E14: 0 | F14: 0 | G14: =E14*F14 -> 0 | H14: 0 | I14: 0 | J14: =H14*I14 -> 0 | K14: =G14+J14 -> 0 | M14: =M13+K14-L14 -> 11350029
A15: 12 | B15: 45789 | E15: 0 | F15: 0 | G15: =E15*F15 -> 0 | H15: 0 | I15: 0 | J15: =H15*I15 -> 0 | K15: =G15+J15 -> 0 | M15: =M14+K15-L15 -> 11350029
A16: 13 | B16: 45790 | E16: 0 | F16: 0 | G16: =E16*F16 -> 0 | H16: 0 | I16: 0 | J16: =H16*I16 -> 0 | K16: =G16+J16 -> 0 | M16: =M15+K16-L16 -> 11350029
A17: 14 | B17: 45791 | E17: 0 | F17: 0 | G17: =E17*F17 -> 0 | H17: 0 | I17: 0 | J17: =H17*I17 -> 0 | K17: =G17+J17 -> 0 | M17: =M16+K17-L17 -> 11350029
A18: 15 | B18: 45792 | E18: 0 | F18: 0 | G18: =E18*F18 -> 0 | H18: 0 | I18: 0 | J18: =H18*I18 -> 0 | K18: =G18+J18 -> 0 | M18: =M17+K18-L18 -> 11350029
A19: 16 | B19: 45793 | E19: 0 | F19: 0 | G19: =E19*F19 -> 0 | H19: 0 | I19: 0 | J19: =H19*I19 -> 0 | K19: =G19+J19 -> 0 | L19: 2000000 | M19: =M18+K19-L19 -> 9350029.4
A20: 17 | B20: 45794 | E20: 0 | F20: 0 | G20: =E20*F20 -> 0 | H20: 0 | I20: 0 | J20: =H20*I20 -> 0 | K20: =G20+J20 -> 0 | M20: =M19+K20-L20 -> 9350029.4
A21: 18 | B21: 45795 | E21: 0 | F21: 0 | G21: =E21*F21 -> 0 | H21: 0 | I21: 0 | J21: =H21*I21 -> 0 | K21: =G21+J21 -> 0 | M21: =M20+K21-L21 -> 9350029.4
A22: 19 | B22: 45796 | E22: 2500 | F22: 95.7 | G22: =E22*F22 -> 239250 | H22: 0 | I22: 0 | J22: =H22*I22 -> 0 | K22: =G22+J22 -> 239250 | M22: =M21+K22-L22 -> 9589279.4
A23: 20 | B23: 45797 | E23: 2500 | F23: 95.7 | G23: =E23*F23 -> 239250 | H23: 35 | I23: 107.48 | J23: =H23*I23 -> 3761.8 | K23: =G23+J23 -> 243011.8 | M23: =M22+K23-L23 -> 9832291.2 | O23: x
A24: 21 | B24: 45798 | E24: 2500 | F24: 95.7 | G24: =E24*F24 -> 239250 | H24: 0 | I24: 0 | J24: =H24*I24 -> 0 | K24: =G24+J24 -> 239250 | M24: =M23+K24-L24 -> 10071541
A25: 22 | B25: 45799 | E25: 0 | F25: 0 | G25: =E25*F25 -> 0 | H25: 0 | I25: 0 | J25: =H25*I25 -> 0 | K25: =G25+J25 -> 0 | M25: =M24+K25-L25 -> 10071541
A26: 23 | B26: 45800 | E26: 4750 | F26: 95.7 | G26: =E26*F26 -> 454575 | H26: 0 | I26: 0 | J26: =H26*I26 -> 0 | K26: =G26+J26 -> 454575 | M26: =M25+K26-L26 -> 10526116
A27: 24 | B27: 45801 | E27: 0 | F27: 0 | G27: =E27*F27 -> 0 | H27: 0 | I27: 0 | J27: =H27*I27 -> 0 | K27: =G27+J27 -> 0 | M27: =M26+K27-L27 -> 10526116
A28: 25 | B28: 45802 | E28: 0 | F28: 0 | G28: =E28*F28 -> 0 | H28: 0 | I28: 0 | J28: =H28*I28 -> 0 | K28: =G28+J28 -> 0 | M28: =M27+K28-L28 -> 10526116
A29: 26 | B29: 45803 | E29: 0 | F29: 0 | G29: =E29*F29 -> 0 | H29: 0 | I29: 0 | J29: =H29*I29 -> 0 | K29: =G29+J29 -> 0 | L29: 5000000 | M29: =M28+K29-L29 -> 5526116.2
A30: 27 | B30: 45804 | E30: 2500 | F30: 95.7 | G30: =E30*F30 -> 239250 | H30: 35 | I30: 107.48 | J30: =H30*I30 -> 3761.8 | K30: =G30+J30 -> 243011.8 | M30: =M29+K30-L30 -> 5769128
A31: 28 | B31: 45805 | E31: 2500 | F31: 95.7 | G31: =E31*F31 -> 239250 | H31: 35 | I31: 107.48 | J31: =H31*I31 -> 3761.8 | K31: =G31+J31 -> 243011.8 | M31: =M30+K31-L31 -> 6012139.8
A32: 29 | B32: 45806 | E32: 4999.9 | F32: 95.7 | G32: =E32*F32 -> 478490.43 | H32: 20 | I32: 107.48 | J32: =H32*I32 -> 2149.6 | K32: =G32+J32 -> 480640.03 | M32: =M31+K32-L32 -> 6492779.8
A33: 30 | B33: 45807 | E33: 5000 | F33: 95.7 | G33: =E33*F33 -> 478500 | H33: 35 | I33: 107.48 | J33: =H33*I33 -> 3761.8 | K33: =G33+J33 -> 482261.8 | M33: =M32+K33-L33 -> 6975041.6
A34: 31 | B34: 45808 | E34: 5000 | F34: 95.7 | G34: =E34*F34 -> 478500 | H34: 35 | I34: 107.48 | J34: =H34*I34 -> 3761.8 | K34: =G34+J34 -> 482261.8 | M34: =M33+K34-L34 -> 7457303.4
E35: =SUM(E4:E34) -> 57904.99 | G35: =SUM(G4:G34) -> 5541507.5 | H35: =SUM(H4:H34) -> 230 | J35: =SUM(J4:J34) -> 24720.4 | K35: =SUM(K4:K34) -> 5566227.9 | L35: =SUM(L4:L34) -> 7000000

Sheet Jedcherla -1
A1: Sai Baba Fuel Station
A2: S.No | B2: Date | C2: GRN No | D2: Ind No/Bill No | E2: Diesel (Lts) | F2: Price | G2: Amount | H2: Petrol (Lts) | I2: Price | J2: Amount | K2: Total amount | L2: Amount paid | M2: As on date | N2: Remarks
A3: Opening Balance | K3: 1966837 | M3: =+K3 -> 1966837
A4: 1 | B4: 45778 | E4: 1500 | F4: 96.42 | G4: =E4*F4 -> 144630 | H4: 0 | I4: 0 | J4: =H4*I4 -> 0 | K4: =G4+J4 -> 144630 | L4: 0 | M4: =M3+K4-L4 -> 2111467 | P4: 2259050
A5: 2 | B5: 45779 | E5: 1500 | F5: 96.42 | G5: =E5*F5 -> 144630 | H5: 20 | I5: 108.23 | J5: =H5*I5 -> 2164.6 | K5: =G5+J5 -> 146794.6 | L5: 0 | M5: =M4+K5-L5 -> 2258261.6
A6: 3 | B6: 45780 | E6: 1700 | F6: 96.42 | G6: =E6*F6 -> 163914 | H6: 20 | I6: 108.23 | J6: =H6*I6 -> 2164.6 | K6: =G6+J6 -> 166078.6 | L6: 0 | M6: =M5+K6-L6 -> 2424340.2
A7: 4 | B7: 45781 | E7: 0 | F7: 0 | G7: =E7*F7 -> 0 | H7: 20 | I7: 108.23 | J7: =H7*I7 -> 2164.6 | K7: =G7+J7 -> 2164.6 | L7: 0 | M7: =M6+K7-L7 -> 2426504.8
A8: 5 | B8: 45782 | E8: 1500 | F8: 96.42 | G8: =E8*F8 -> 144630 | H8: 20 | I8: 108.23 | J8: =H8*I8 -> 2164.6 | K8: =G8+J8 -> 146794.6 | L8: 0 | M8: =M7+K8-L8 -> 2573299.4
A9: 6 | B9: 45783 | E9: 0 | F9: 0 | G9: =E9*F9 -> 0 | H9: 15 | I9: 108.23 | J9: =H9*I9 -> 1623.45 | K9: =G9+J9 -> 1623.45 | L9: 0 | M9: =M8+K9-L9 -> 2574922.9
A10: 7 | B10: 45784 | E10: 93.69 | F10: 96.42 | G10: =E10*F10 -> 9033.5898 | H10: 10 | I10: 108.23 | J10: =H10*I10 -> 1082.3 | K10: =G10+J10 -> 10115.89 | L10: 0 | M10: =M9+K10-L10 -> 2585038.8
A11: 8 | B11: 45785 | E11: 33 | F11: 96.42 | G11: =E11*F11 -> 3181.86 | H11: 23 | I11: 108.23 | J11: =H11*I11 -> 2489.29 | K11: =G11+J11 -> 5671.15 | L11: 0 | M11: =M10+K11-L11 -> 2590709.9
A12: 9 | B12: 45786 | E12: 81.38 | F12: 96.42 | G12: =E12*F12 -> 7846.6596 | H12: 10 | I12: 108.23 | J12: =H12*I12 -> 1082.3 | K12: =G12+J12 -> 8928.9596 | L12: 0 | M12: =M11+K12-L12 -> 2599638.9
A13: 10 | B13: 45787 | E13: 33.06 | F13: 96.42 | G13: =E13*F13 -> 3187.6452 | H13: 15 | I13: 108.23 | J13: =H13*I13 -> 1623.45 | K13: =G13+J13 -> 4811.0952 | L13: 0 | M13: =M12+K13-L13 -> 2604450
A14: 11 | B14: 45788 | E14: 0 | F14: 0 | G14: =E14*F14 -> 0 | H14: 0 | I14: 0 | J14: =H14*I14 -> 0 | K14: =G14+J14 -> 0 | L14: 0 | M14: =M13+K14-L14 -> 2604450
A15: 12 | B15: 45789 | E15: 0 | F15: 0 | G15: =E15*F15 -> 0 | H15: 20 | I15: 108.23 | J15: =H15*I15 -> 2164.6 | K15: =G15+J15 -> 2164.6 | L15: 0 | M15: =M14+K15-L15 -> 2606614.6
A16: 13 | B16: 45790 | E16: 0 | F16: 0 | G16: =E16*F16 -> 0 | H16: 15 | I16: 108.23 | J16: =H16*I16 -> 1623.45 | K16: =G16+J16 -> 1623.45 | L16: 0 | M16: =M15+K16-L16 -> 2608238
... A21: 18 | B21: 45795 | E21: 0 | F21: 0 | G21: =E21*F21 -> 0 | H21: 5 | I21: 108.23 | J21: =H21*I21 -> 541.15 | K21: =G21+J21 -> 541.15 | L21: 0 | M21: =M20+K21-L21 -> 2624274.2
A22: 19 | B22: 45796 | E22: 0 | F22: 0 | G22: =E22*F22 -> 0 | H22: 5 | I22: 108.23 | J22: =H22*I22 -> 541.15 | K22: =G22+J22 -> 541.15 | L22: 0 | M22: =M21+K22-L22 -> 2624815.4 | P22: 2422641
A23: 20 | B23: 45797 | E23: 0 | F23: 0 | G23: =E23*F23 -> 0 | H23: 17.75 | I23: 108.23 | J23: =H23*I23 -> 1921.0825 | K23: =G23+J23 -> 1921.0825 | L23: 0 | M23: =M22+K23-L23 -> 2626736.5 | P23: 2419549
A24: 21 | B24: 45798 | E24: 27.58 | F24: 96.42 | G24: =E24*F24 -> 2659.2636 | H24: 20 | I24: 108.23 | J24: =H24*I24 -> 2164.6 | K24: =G24+J24 -> 4823.8636 | L24: 0 | M24: =M23+K24-L24 -> 2631560.3 | P24: =P23-P22 -> -3092
A25: 22 | B25: 45799 | E25: 0 | F25: 0 | G25: =E25*F25 -> 0 | H25: 10 | I25: 108.23 | J25: =H25*I25 -> 1082.3 | K25: =G25+J25 -> 1082.3 | L25: 0 | M25: =M24+K25-L25 -> 2632642.6
A26: 23 | B26: 45800 | E26: 0 | F26: 0 | G26: =E26*F26 -> 0 | H26: 27.84 | I26: 108.23 | J26: =H26*I26 -> 3013.1232 | K26: =G26+J26 -> 3013.1232 | L26: 0 | M26: =M25+K26-L26 -> 2635655.8
A27: 24 | B27: 45801 | E27: 0 | F27: 0 | G27: =E27*F27 -> 0 | H27: 25 | I27: 108.23 | J27: =H27*I27 -> 2705.75 | K27: =G27+J27 -> 2705.75 | L27: 0 | M27: =M26+K27-L27 -> 2638361.5
A28: 25 | B28: 45802 | E28: 0 | F28: 0 | G28: =E28*F28 -> 0 | H28: 10 | I28: 108.23 | J28: =H28*I28 -> 1082.3 | K28: =G28+J28 -> 1082.3 | L28: 0 | M28: =M27+K28-L28 -> 2639443.8
A29: 26 | B29: 45803 | E29: 17.22 | F29: 96.42 | G29: =E29*F29 -> 1660.3524 | H29: 5 | I29: 108.23 | J29: =H29*I29 -> 541.15 | K29: =G29+J29 -> 2201.5024 | L29: 0 | M29: =M28+K29-L29 -> 2641645.3
A30: 27 | B30: 45804 | E30: 0 | F30: 0 | G30: =E30*F30 -> 0 | H30: 7 | I30: 108.23 | J30: =H30*I30 -> 757.61 | K30: =G30+J30 -> 757.61 | L30: 0 | M30: =M29+K30-L30 -> 2642402.9
A31: 28 | B31: 45805 | E31: 0 | F31: 0 | G31: =E31*F31 -> 0 | H31: 24 | I31: 108.23 | J31: =H31*I31 -> 2597.52 | K31: =G31+J31 -> 2597.52 | L31: 1500000 | M31: =M30+K31-L31 -> 1145000.4
A32: 29 | B32: 45806 | E32: 0 | F32: 0 | G32: =E32*F32 -> 0 | H32: 20 | I32: 108.23 | J32: =H32*I32 -> 2164.6 | K32: =G32+J32 -> 2164.6 | L32: 0 | M32: =M31+K32-L32 -> 1147165
A33: 30 | B33: 45807 | E33: 0 | F33: 0 | G33: =E33*F33 -> 0 | H33: 20 | I33: 108.23 | J33: =H33*I33 -> 2164.6 | K33: =G33+J33 -> 2164.6 | L33: 0 | M33: =M32+K33-L33 -> 1149329.6
A34: 31 | B34: 45808 | E34: 0 | F34: 0 | G34: =E34*F34 -> 0 | H34: 5 | I34: 108.23 | J34: =H34*I34 -> 541.15 | K34: =G34+J34 -> 541.15 | L34: 0 | M34: =M33+K34-L34 -> 1149870.8
E35: =SUM(E4:E34) -> 6568.06 | G35: =SUM(G4:G34) -> 633292.35 | H35: =SUM(H4:H34) -> 459.59 | J35: =SUM(J4:J34) -> 49741.426 | K35: =SUM(K4:K34) -> 683033.77 | L35: =SUM(L4:L34) -> 1500000
H37: 3

Sheet Jedcherla-2
A1: Uttara Enterprises
A2: S.No | B2: Date | C2: GRN No | D2: Ind No/Bill No | E2: Diesel (Lts) | F2: Price | G2: Amount | H2: Petrol (Lts) | I2: Price | J2: Amount | K2: Total amount | L2: Amount paid | M2: As on Date | N2: Remarks
A3: Opening Balance | K3: 1831699.5 | M3: =+K3 -> 1831699.5
A4: 1 | B4: 45778 | G4: =E4*F4 -> 0 | J4: =H4*I4 -> 0 | K4: =G4+J4 -> 0 | M4: =M3+K4-L4 -> 1831699.5
A5: 2 | B5: 45779 | E5: 0 | F5: 0 | G5: =E5*F5 -> 0 | J5: =H5*I5 -> 0 | K5: =G5+J5 -> 0 | M5: =M4+K5-L5 -> 1831699.5
A6: 3 | B6: 45780 | E6: 0 | F6: 0 | G6: =E6*F6 -> 0 | J6: =H6*I6 -> 0 | K6: =G6+J6 -> 0 | M6: =M5+K6-L6 -> 1831699.5 | R6: 541.08
A7: 4 | B7: 45781 | E7: 0 | F7: 0 | G7: =E7*F7 -> 0 | J7: =H7*I7 -> 0 | K7: =G7+J7 -> 0 | M7: =M6+K7-L7 -> 1831699.5
A8: 5 | B8: 45782 | E8: 0 | F8: 0 | G8: =E8*F8 -> 0 | J8: =H8*I8 -> 0 | K8: =G8+J8 -> 0 | M8: =M7+K8-L8 -> 1831699.5
A9: 6 | B9: 45783 | E9: 0 | F9: 0 | G9: =E9*F9 -> 0 | J9: =H9*I9 -> 0 | K9: =G9+J9 -> 0 | M9: =M8+K9-L9 -> 1831699.5
A10: 7 | B10: 45784 | E10: 0 | F10: 0 | G10: =E10*F10 -> 0 | J10: =H10*I10 -> 0 | K10: =G10+J10 -> 0 | M10: =M9+K10-L10 -> 1831699.5
A11: 8 | B11: 45785 | E11: 0 | F11: 0 | G11: =E11*F11 -> 0 | J11: =H11*I11 -> 0 | K11: =G11+J11 -> 0 | M11: =M10+K11-L11 -> 1831699.5
A12: 9 | B12: 45786 | E12: 0 | F12: 0 | G12: =E12*F12 -> 0 | J12: =H12*I12 -> 0 | K12: =G12+J12 -> 0 | M12: =M11+K12-L12 -> 1831699.5
A13: 10 | B13: 45787 | E13: 0 | F13: 0 | G13: =E13*F13 -> 0 | J13: =H13*I13 -> 0 | K13: =G13+J13 -> 0 | M13: =M12+K13-L13 -> 1831699.5
A14: 11 | B14: 45788 | E14: 0 | F14: 0 | G14: =E14*F14 -> 0 | J14: =H14*I14 -> 0 | K14: =G14+J14 -> 0 | M14: =M13+K14-L14 -> 1831699.5
A15: 12 | B15: 45789 | E15: 0 | F15: 0 | G15: =E15*F15 -> 0 | J15: =H15*I15 -> 0 | K15: =G15+J15 -> 0 | M15: =M14+K15-L15 -> 1831699.5
A16: 13 | B16: 45790 | E16: 0 | F16: 0 | G16: =E16*F16 -> 0 | J16: =H16*I16 -> 0 | K16: =G16+J16 -> 0 | M16: =M15+K16-L16 -> 1831699.5
A17: 14 | B17: 45791 | E17: 0 | F17: 0 | G17: =E17*F17 -> 0 | J17: =H17*I17 -> 0 | K17: =G17+J17 -> 0 | M17: =M16+K17-L17 -> 1831699.5
A18: 15 | B18: 45792 | E18: 0 | F18: 0 | G18: =E18*F18 -> 0 | J18: =H18*I18 -> 0 | K18: =G18+J18 -> 0 | M18: =M17+K18-L18 -> 1831699.5
... A29: 26 | B29: 45803 | E29: 0 | F29: 0 | G29: =E29*F29 -> 0 | J29: =H29*I29 -> 0 | K29: =G29+J29 -> 0 | M29: =M28+K29-L29 -> 1831699.5
A30: 27 | B30: 45804 | E30: 0 | F30: 0 | G30: =E30*F30 -> 0 | J30: =H30*I30 -> 0 | K30: =G30+J30 -> 0 | M30: =M29+K30-L30 -> 1831699.5 | P30: =2939612.08-2939070.93 -> 541.15
A31: 28 | B31: 45805 | E31: 0 | F31: 0 | G31: =E31*F31 -> 0 | J31: =H31*I31 -> 0 | K31: =G31+J31 -> 0 | L31: 1500000 | M31: =M30+K31-L31 -> 331699.53
A32: 29 | B32: 45806 | E32: 0 | F32: 0 | G32: =E32*F32 -> 0 | J32: =H32*I32 -> 0 | K32: =G32+J32 -> 0
A33: 30 | B33: 45807 | E33: 0 | F33: 0 | G33: =E33*F33 -> 0 | J33: =H33*I33 -> 0 | K33: =G33+J33 -> 0
A34: 31 | B34: 45808 | E34: 0 | F34: 0 | G34: =E34*F34 -> 0 | J34: =H34*I34 -> 0 | K34: =G34+J34 -> 0
E35: =SUM(E4:E34) -> 0 | G35: =SUM(G4:G34) -> 0 | H35: =SUM(H4:H34) -> 0 | J35: =SUM(J4:J34) -> 0 | K35: =SUM(K4:K34) -> 0 | L35: =SUM(L4:L34) -> 1500000
P36: =170+165 -> 335

Sheet Jadcharla-3
A1: Bhavani KSK Fuel Station-Nawabpet
A2: S.No | B2: Date | C2: GRN No | D2: Ind No/Bill No | E2: Diesel (Lts) | F2: Price | G2: Amount | H2: Petrol (Lts) | I2: Price | J2: Amount | K2: Total amount | L2: Amount paid | M2: As on Date | N2: Remarks
A3: Opening Balance | K3: 0 | M3: =+K3 -> 0
A4: 1 | B4: 45778 | G4: 0 | J4: 0 | K4: 0 | L4: 0 | M4: =M3+K4-L4 -> 0
A5: 2 | B5: 45779 | E5: 0 | F5: 0 | G5: 0 | J5: 0 | K5: 0 | L5: 0 | M5: =M4+K5-L5 -> 0
A6: 3 | B6: 45780 | E6: 0 | F6: 0 | G6: 0 | J6: 0 | K6: 0 | L6: 0 | M6: =M5+K6-L6 -> 0 | R6: 541.08
A7: 4 | B7: 45781 | E7: 0 | F7: 0 | G7: 0 | J7: 0 | K7: 0 | L7: 0 | M7: =M6+K7-L7 -> 0
A8: 5 | B8: 45782 | E8: 20 | F8: 96.31 | G8: 1926.2 | J8: 0 | K8: 1926.2 | L8: 0 | M8: =M7+K8-L8 -> 1926.2
A9: 6 | B9: 45783 | E9: 3000 | F9: 96.31 | G9: 288930 | J9: 0 | K9: 288930 | L9: 0 | M9: =M8+K9-L9 -> 290856.2
A10: 7 | B10: 45784 | E10: 0 | F10: 0 | G10: 0 | J10: 0 | K10: 0 | L10: 0 | M10: =M9+K10-L10 -> 290856.2
A11: 8 | B11: 45785 | E11: 1020 | F11: 96.31 | G11: 98236.2 | J11: 0 | K11: 98236.2 | L11: 0 | M11: =M10+K11-L11 -> 389092.4
A12: 9 | B12: 45786 | E12: 0 | F12: 0 | G12: 0 | J12: 0 | K12: 0 | L12: 0 | M12: =M11+K12-L12 -> 389092.4
A13: 10 | B13: 45787 | E13: 0 | F13: 0 | G13: 0 | J13: 0 | K13: 0 | L13: 0 | M13: =M12+K13-L13 -> 389092.4
A14: 11 | B14: 45788 | E14: 0 | F14: 0 | G14: 0 | J14: 0 | K14: 0 | L14: 0 | M14: =M13+K14-L14 -> 389092.4
A15: 12 | B15: 45789 | E15: 0 | F15: 0 | G15: 0 | J15: 0 | K15: 0 | L15: 0 | M15: =M14+K15-L15 -> 389092.4
A16: 13 | B16: 45790 | E16: 0 | F16: 0 | G16: 0 | J16: 0 | K16: 0 | L16: 0 | M16: =M15+K16-L16 -> 389092.4
A17: 14 | B17: 45791 | E17: 0 | F17: 0 | G17: 0 | J17: 0 | K17: 0 | L17: 0 | M17: =M16+K17-L17 -> 389092.4
A18: 15 | B18: 45792 | E18: 0 | F18: 0 | G18: 0 | J18: 0 | K18: 0 | L18: 0 | M18: =M17+K18-L18 -> 389092.4
... A29: 26 | B29: 45803 | E29: 0 | F29: 0 | G29: 0 | J29: 0 | K29: 0 | L29: 389092.4 | M29: =M28+K29-L29 -> 0
A30: 27 | B30: 45804 | E30: 0 | F30: 0 | G30: 0 | J30: 0 | K30: 0 | L30: 0 | M30: =M29+K30-L30 -> 0 | P30: =2939612.08-2939070.93 -> 541.15
A31: 28 | B31: 45805 | E31: 0 | F31: 0 | G31: 0 | J31: 0 | K31: 0 | L31: 0 | M31: =M30+K31-L31 -> 0
A32: 29 | B32: 45806 | E32: 0 | F32: 0 | G32: 0 | J32: 0 | K32: 0
A33: 30 | B33: 45807 | E33: 0 | F33: 0 | G33: 0 | J33: 0 | K33: 0
A34: 31 | B34: 45808 | E34: 0 | F34: 0 | G34: 0 | J34: 0 | K34: 0
E35: =SUM(E4:E34) -> 4040 | G35: =SUM(G4:G34) -> 389092.4 | H35: =SUM(H4:H34) -> 0 | J35: =SUM(J4:J34) -> 0 | K35: =SUM(K4:K34) -> 389092.4 | L35: =SUM(L4:L34) -> 389092.4

Sheet Jedcharla-4
A1: ADHOC FILLING STATION STATION
A2: S.No | B2: Date | C2: GRN No | D2: Ind No/Bill No | E2: Diesel (Lts) | F2: Price | G2: Amount | H2: Petrol (Lts) | I2: Price | J2: Amount | K2: Total amount | L2: Amount paid | M2: As on Date | N2: Remarks
A3: Opening Balance | K3: 0 | M3: =+K3 -> 0
A4: 1 | B4: 45778 | G4: =E4*F4 -> 0 | J4: =H4*I4 -> 0 | K4: =G4+J4 -> 0 | M4: =M3+K4-L4 -> 0
A5: 2 | B5: 45779 | E5: 0 | F5: 0 | G5: =E5*F5 -> 0 | J5: =H5*I5 -> 0 | K5: =G5+J5 -> 0 | M5: =M4+K5-L5 -> 0
A6: 3 | B6: 45780 | E6: 0 | F6: 0 | G6: =E6*F6 -> 0 | J6: =H6*I6 -> 0 | K6: =G6+J6 -> 0 | M6: =M5+K6-L6 -> 0 | R6: 541.08
A7: 4 | B7: 45781 | E7: 0 | F7: 0 | G7: =E7*F7 -> 0 | J7: =H7*I7 -> 0 | K7: =G7+J7 -> 0 | M7: =M6+K7-L7 -> 0
A8: 5 | B8: 45782 | E8: 0 | F8: 0 | G8: =E8*F8 -> 0 | J8: =H8*I8 -> 0 | K8: =G8+J8 -> 0 | M8: =M7+K8-L8 -> 0
A9: 6 | B9: 45783 | E9: 0 | F9: 0 | G9: =E9*F9 -> 0 | J9: =H9*I9 -> 0 | K9: =G9+J9 -> 0 | M9: =M8+K9-L9 -> 0
A10: 7 | B10: 45784 | E10: 0 | F10: 0 | G10: =E10*F10 -> 0 | J10: =H10*I10 -> 0 | K10: =G10+J10 -> 0 | M10: =M9+K10-L10 -> 0
A11: 8 | B11: 45785 | E11: 0 | F11: 0 | G11: =E11*F11 -> 0 | J11: =H11*I11 -> 0 | K11: =G11+J11 -> 0 | M11: =M10+K11-L11 -> 0
A12: 9 | B12: 45786 | E12: 0 | F12: 0 | G12: =E12*F12 -> 0 | J12: =H12*I12 -> 0 | K12: =G12+J12 -> 0 | M12: =M11+K12-L12 -> 0
